<mujoco model="model">
  <compiler angle="radian"/>
  <asset>
    <mesh file="visuals/Body001.obj" name="Body001_vis"/>
    <mesh file="visuals/Button001.obj" name="Button001_vis"/>
    <mesh file="visuals/Button002.obj" name="Button002_vis"/>
    <mesh file="visuals/Button003.obj" name="Button003_vis"/>
    <mesh file="visuals/Button004.obj" name="Button004_vis"/>
    <mesh file="visuals/Button005.obj" name="Button005_vis"/>
    <texture file="visuals/T_BC001.png" name="Body001_material" type="2d"/>
    <material name="Body001_material" rgba="1 1 1 1.0" texture="Body001_material" shininess="0.6021478176116943" specular="0.3103448502657381"/>
    <texture file="visuals/T_BC001.png" name="Button001_material" type="2d"/>
    <material name="Button001_material" rgba="1 1 1 1.0" texture="Button001_material" shininess="0.6021478176116943" specular="0.3103448502657381"/>
    <texture file="visuals/T_BC001.png" name="Button002_material" type="2d"/>
    <material name="Button002_material" rgba="1 1 1 1.0" texture="Button002_material" shininess="0.6021478176116943" specular="0.3103448502657381"/>
    <texture file="visuals/T_BC001.png" name="Button003_material" type="2d"/>
    <material name="Button003_material" rgba="1 1 1 1.0" texture="Button003_material" shininess="0.6021478176116943" specular="0.3103448502657381"/>
    <texture file="visuals/T_BC001.png" name="Button004_material" type="2d"/>
    <material name="Button004_material" rgba="1 1 1 1.0" texture="Button004_material" shininess="0.6021478176116943" specular="0.3103448502657381"/>
    <texture file="visuals/T_BC001.png" name="Button005_material" type="2d"/>
    <material name="Button005_material" rgba="1 1 1 1.0" texture="Button005_material" shininess="0.6021478176116943" specular="0.3103448502657381"/>
  </asset>
  <default>
    <default class="visual">
      <geom conaffinity="0" contype="0" group="1" type="mesh"/>
    </default>
    <default class="collision">
      <geom group="0" rgba="0.5 0 0 0.5"/>
    </default>
    <default class="spawn">
      <geom group="0" rgba="1 1 1 0.5" contype="0" conaffinity="0"/>
      <site group="0" rgba="1 1 1 0.5"/>
    </default>
    <default class="region">
      <geom group="1" conaffinity="0" contype="0" rgba="0 1 0 0"/>
    </default>
  </default>
  <worldbody>
    <body>
      <body name="object">
        <geom mesh="Body001_vis" type="mesh" solimp="0.998 0.998 0.001" solref="0.001 1" density="100" friction="0.95 0.3 0.1" class="visual" material="Body001_material"/>
        <geom class="collision" type="box" pos="-0.006053 0.018385 0.041946" size="0.21228091418743134 0.08162669092416763 0.39915990829467773" quat="1.0 0.0 0.0 0.0"/>
        <geom class="collision" type="box" pos="0.000000 0.002028 -0.398821" size="0.4821198880672455 0.13750651478767395 0.04228421300649643" quat="1.0 0.0 0.0 0.0"/>
        <body name="Button001">
          <joint axis="0.0 1.0 0.0" pos="-0.060494 -0.137413 -0.424475" limited="true" name="Button001_joint" range="0.0 0.002" type="slide" damping="1" frictionloss="1" armature=".01" stiffness="0.05"/>
          <geom mesh="Button001_vis" type="mesh" solimp="0.998 0.998 0.001" solref="0.001 1" density="100" friction="0.95 0.3 0.1" class="visual" material="Button001_material"/>
          <geom class="collision" type="box" pos="-0.060470 -0.137695 -0.424438" size="0.007179344072937965 0.0018396058585494757 0.007121779024600983" quat="1.0 0.0 0.0 0.0"/>
        </body>
        <body name="Button002">
          <joint axis="0.0 1.0 0.0" pos="-0.030265 -0.137413 -0.424475" limited="true" name="Button002_joint" range="0.0 0.002" type="slide" damping="1" frictionloss="1" armature=".01" stiffness="0.05"/>
          <geom mesh="Button002_vis" type="mesh" solimp="0.998 0.998 0.001" solref="0.001 1" density="100" friction="0.95 0.3 0.1" class="visual" material="Button002_material"/>
          <geom class="collision" type="box" pos="-0.030237 -0.137695 -0.424438" size="0.007179344072937965 0.0018396058585494757 0.007121779024600983" quat="1.0 0.0 0.0 0.0"/>
        </body>
        <body name="Button003">
          <joint axis="0.0 1.0 0.0" pos="-0.000036 -0.137413 -0.424475" limited="true" name="Button003_joint" range="0.0 0.002" type="slide" damping="1" frictionloss="1" armature=".01" stiffness="0.05"/>
          <geom mesh="Button003_vis" type="mesh" solimp="0.998 0.998 0.001" solref="0.001 1" density="100" friction="0.95 0.3 0.1" class="visual" material="Button003_material"/>
          <geom class="collision" type="box" pos="-0.000014 -0.137695 -0.424438" size="0.007179344072937965 0.0018396058585494757 0.007121779024600983" quat="1.0 0.0 0.0 0.0"/>
        </body>
        <body name="Button004">
          <joint axis="0.0 1.0 0.0" pos="0.030193 -0.137413 -0.424475" limited="true" name="Button004_joint" range="0.0 0.002" type="slide" damping="1" frictionloss="1" armature=".01" stiffness="0.05"/>
          <geom mesh="Button004_vis" type="mesh" solimp="0.998 0.998 0.001" solref="0.001 1" density="100" friction="0.95 0.3 0.1" class="visual" material="Button004_material"/>
          <geom class="collision" type="box" pos="0.030210 -0.137695 -0.424438" size="0.007179344072937965 0.0018396058585494757 0.007121779024600983" quat="1.0 0.0 0.0 0.0"/>
        </body>
        <body name="Button005">
          <joint axis="0.0 1.0 0.0" pos="0.060422 -0.137413 -0.424475" limited="true" name="Button005_joint" range="0.0 0.002" type="slide" damping="1" frictionloss="1" armature=".01" stiffness="0.05"/>
          <geom mesh="Button005_vis" type="mesh" solimp="0.998 0.998 0.001" solref="0.001 1" density="100" friction="0.95 0.3 0.1" class="visual" material="Button005_material"/>
          <geom class="collision" type="box" pos="0.060425 -0.137695 -0.424438" size="0.007179344072937965 0.0018396058585494757 0.007121779024600983" quat="1.0 0.0 0.0 0.0"/>
        </body>
        <geom class="region" name="reg_main_body" type="box" pos="-3.649999999999487e-05 -0.00037049999999999583 0.00019700000000000273" size="0.4819825 0.1390345 0.440321"/>
      </body>
    </body>
  </worldbody>
  <actuator>
    <motor name="Button001_joint_actuator" joint="Button001_joint" gear="0.5"/>
    <motor name="Button002_joint_actuator" joint="Button002_joint" gear="0.5"/>
    <motor name="Button003_joint_actuator" joint="Button003_joint" gear="0.5"/>
    <motor name="Button004_joint_actuator" joint="Button004_joint" gear="0.5"/>
    <motor name="Button005_joint_actuator" joint="Button005_joint" gear="0.5"/>
  </actuator>
</mujoco>
