<mujoco model="model">
  <compiler angle="radian"/>
  <asset>
    <mesh file="visuals/Body001.obj" name="Body001_vis"/>
    <mesh file="visuals/Button001.obj" name="Button001_vis"/>
    <mesh file="visuals/Button002.obj" name="Button002_vis"/>
    <mesh file="visuals/Button003.obj" name="Button003_vis"/>
    <mesh file="visuals/Container001_Clear.obj" name="Container001_Clear_vis"/>
    <mesh file="visuals/Lid001.obj" name="Lid001_vis"/>
    <mesh file="visuals/Lid002.obj" name="Lid002_vis"/>
    <mesh file="visuals/Lid003.obj" name="Lid003_vis"/>
    <texture file="visuals/T_BC001.png" name="Body001_material" type="2d"/>
    <material name="Body001_material" rgba="1 1 1 1.0" texture="Body001_material" shininess="0.4472135901451111" specular="1"/>
    <texture file="visuals/T_BC001.png" name="Button001_material" type="2d"/>
    <material name="Button001_material" rgba="1 1 1 1.0" texture="Button001_material" shininess="0.4472135901451111" specular="1"/>
    <texture file="visuals/T_BC001.png" name="Button002_material" type="2d"/>
    <material name="Button002_material" rgba="1 1 1 1.0" texture="Button002_material" shininess="0.4472135901451111" specular="1"/>
    <texture file="visuals/T_BC001.png" name="Button003_material" type="2d"/>
    <material name="Button003_material" rgba="1 1 1 1.0" texture="Button003_material" shininess="0.4472135901451111" specular="1"/>
    <texture file="visuals/T_BC001.png" name="Container001_Clear_material" type="2d"/>
    <material name="Container001_Clear_material" rgba="1 1 1 0.30000001192092896" texture="Container001_Clear_material" shininess="0.4472135901451111" specular="1"/>
    <texture file="visuals/T_BC001.png" name="Lid002_material" type="2d"/>
    <material name="Lid002_material" rgba="1 1 1 1.0" texture="Lid002_material" shininess="0.4472135901451111" specular="1"/>
    <texture file="visuals/T_BC001.png" name="Lid001_material" type="2d"/>
    <material name="Lid001_material" rgba="1 1 1 1.0" texture="Lid001_material" shininess="0.4472135901451111" specular="1"/>
    <texture file="visuals/T_BC001.png" name="Lid003_material" type="2d"/>
    <material name="Lid003_material" rgba="1 1 1 1.0" texture="Lid003_material" shininess="0.4472135901451111" specular="1"/>
  </asset>
  <default>
    <default class="visual">
      <geom conaffinity="0" contype="0" group="1" type="mesh"/>
    </default>
    <default class="collision">
      <geom group="0" rgba="0.5 0 0 0.5"/>
    </default>
    <default class="spawn">
      <geom group="0" rgba="1 1 1 0.5" contype="0" conaffinity="0"/>
      <site group="0" rgba="1 1 1 0.5"/>
    </default>
    <default class="region">
      <geom group="1" conaffinity="0" contype="0" rgba="0 1 0 0"/>
    </default>
  </default>
  <worldbody>
    <body>
      <body name="object">
        <geom class="collision" type="box" pos="-0.024521537125110626 -0.18316082656383514 0.07442397624254227" size="0.006024941802024841 9.219245112035424e-05 0.006117886397987604" quat="1.0 0.0 0.0 0.0" name="start_button_1" rgba="0.0 0.5 0 0.5"/>
        <geom class="collision" type="box" pos="-4.6440400183200836e-05 -0.18316082656383514 0.07442397624254227" size="0.006024941802024841 9.219245112035424e-05 0.006117886397987604" quat="1.0 0.0 0.0 0.0" name="start_button_2" rgba="0.0 0.5 0 0.5"/>
        <site type="cylinder" rgba="0.8 0.5 0.25 1" size="0.001991123892366886 0.06470804661512375" pos="0.016826821491122246 -0.15180371701717377 -0.05810852721333504" name="coffee_liquid_right"/>
        <site rgba="0 0 0 0" size="0.009999999776482582 0.009999999776482582" pos="0.016826821491122246 -0.15180371701717377 -0.1255117505788803" name="receptacle_place_site002"/>
        <site type="cylinder" rgba="0.8 0.5 0.25 1" size="0.001991123892366886 0.06470804661512375" pos="-0.01745823211967945 -0.15180371701717377 -0.05810852721333504" name="coffee_liquid_left"/>
        <site rgba="0 0 0 0" size="0.009999999776482582 0.009999999776482582" pos="-0.01745823211967945 -0.15180371701717377 -0.1255117505788803" name="receptacle_place_site001"/>
        <geom mesh="Body001_vis" type="mesh" solimp="0.998 0.998 0.001" solref="0.001 1" density="100" friction="0.95 0.3 0.1" class="visual" material="Body001_material"/>
        <geom class="collision" type="box" pos="0.05843455344438553 0.020633870735764503 -0.11852828413248062" size="0.02300264872610569 0.10832887142896652 0.03451972454786301" quat="0.9994991421699524 0.0 0.0 0.0316457562148571"/>
        <geom class="collision" type="box" pos="0.057073332369327545 0.016555333510041237 -0.04636196419596672" size="0.019947463646531105 0.111720509827137 0.03797116130590439" quat="0.9987374544143677 0.0012352224439382553 -0.03901321068406105 0.031621746718883514"/>
        <geom class="collision" type="box" pos="0.055161505937576294 0.011243190616369247 0.023980574682354927" size="0.019947461783885956 0.11371100693941116 0.03451972454786301" quat="0.9977023601531982 0.0018966753268614411 -0.059904102236032486 0.03158910199999809"/>
        <geom class="collision" type="box" pos="0.056002210825681686 0.005776189733296633 0.09510742872953415" size="0.01093154028058052 0.11207497864961624 0.039635106921195984" quat="0.9882287383079529 0.004738956689834595 -0.14967460930347443 0.03128902241587639"/>
        <geom class="collision" type="box" pos="0.06803900748491287 -0.10458119213581085 -0.01115577481687069" size="0.014560054056346416 0.023803330957889557 0.14346478879451752" quat="0.999038577079773 0.03541722521185875 -0.025820208713412285 -0.0009153564460575581"/>
        <geom class="collision" type="box" pos="-0.06803900748491287 -0.10458119213581085 -0.011155773885548115" size="0.014560054056346416 0.023803334683179855 0.14346478879451752" quat="0.999038577079773 0.03541722521185875 0.025820208713412285 0.0009153566788882017"/>
        <geom class="collision" type="box" pos="-0.055940911173820496 0.005772309843450785 0.09508839249610901" size="0.010995840653777122 0.11207497864961624 0.039635103195905685" quat="0.9882287383079529 0.004738957155495882 0.14967460930347443 -0.03128902614116669"/>
        <geom class="collision" type="box" pos="-0.055572155863046646 0.011269217357039452 0.024030165746808052" size="0.019947461783885956 0.11371100693941116 0.03451972082257271" quat="0.9977023601531982 0.0018966745119541883 0.059904083609580994 -0.031589098274707794"/>
        <geom class="collision" type="box" pos="-0.05875157192349434 0.01531126257032156 -0.04623708128929138" size="0.019947463646531105 0.11037278175354004 0.03830539062619209" quat="0.9987374544143677 0.0012352215126156807 0.039013203233480453 -0.031621742993593216"/>
        <geom class="collision" type="box" pos="-0.058452058583498 0.020357763394713402 -0.11852828413248062" size="0.02300264872610569 0.10805220901966095 0.03451972454786301" quat="0.9994991421699524 0.0 -0.0 -0.0316457636654377"/>
        <geom class="collision" type="box" pos="0.0 -0.09804873913526535 -0.04738736152648926" size="0.06221529096364975 0.02399972639977932 0.10559824109077454" quat="0.9987459778785706 0.05006491765379906 0.0 0.0"/>
        <geom class="collision" type="box" pos="0.0 0.05902857705950737 0.09741136431694031" size="0.040640536695718765 0.053293950855731964 0.03922520577907562" quat="1.0 0.0 0.0 0.0"/>
        <geom class="collision" type="box" pos="0.0 0.0007351087406277657 -0.04555068165063858" size="0.040640536695718765 0.11266183853149414 0.10752008110284805" quat="1.0 0.0 0.0 0.0"/>
        <geom class="collision" type="box" pos="-0.04497283324599266 -0.06946190446615219 0.09808744490146637" size="0.0065611302852630615 0.07181483507156372 0.03517482057213783" quat="0.999821126461029 0.0 -0.0 -0.018913568928837776"/>
        <geom class="collision" type="box" pos="0.04184922203421593 -0.06958012282848358 0.09808744490146637" size="0.009272493422031403 0.07201159745454788 0.03517482057213783" quat="1.0 0.0 0.0 0.0"/>
        <geom class="collision" type="box" pos="-0.001039988244883716 -0.15859147906303406 0.10240641981363297" size="0.03657513111829758 0.01956840790808201 0.02083216793835163" quat="1.0 0.0 0.0 0.0"/>
        <geom class="collision" type="box" pos="-0.001039988244883716 -0.1541668027639389 0.04636054486036301" size="0.03657513111829758 0.023993084207177162 0.02083216793835163" quat="1.0 0.0 0.0 0.0"/>
        <geom class="collision" type="box" pos="0.0489550419151783 -0.15859147906303406 0.07522302865982056" size="0.013808858580887318 0.01956840790808201 0.02083216793835163" quat="1.0 0.0 0.0 0.0"/>
        <geom class="collision" type="box" pos="-0.04872816056013107 -0.15859147906303406 0.07522302865982056" size="0.01588883250951767 0.01956840790808201 0.02083216793835163" quat="1.0 0.0 0.0 0.0"/>
        <geom class="collision" type="box" pos="-0.041177477687597275 -0.15859147906303406 0.09949912875890732" size="0.013430683873593807 0.01956840790808201 0.021567746996879578" quat="0.9396926164627075 0.0 0.3420201539993286 0.0"/>
        <geom class="collision" type="box" pos="0.0395633764564991 -0.15859147906303406 0.09949912875890732" size="0.013430683873593807 0.01956840790808201 0.021567746996879578" quat="0.9396926164627075 0.0 -0.3420201539993286 0.0"/>
        <geom class="collision" type="box" pos="-0.042481545358896255 -0.1541668027639389 0.049720648676157" size="0.013430683873593807 0.023993084207177162 0.02156774513423443" quat="0.9238795042037964 0.0 -0.3826834559440613 0.0"/>
        <geom class="collision" type="box" pos="0.04220178350806236 -0.1541668027639389 0.05025429278612137" size="0.013430683873593807 0.023993084207177162 0.02156774513423443" quat="0.9238795042037964 0.0 0.3826834559440613 0.0"/>
        <geom class="collision" type="box" pos="-0.0004623840795829892 -0.15163926780223846 0.015381270088255405" size="0.030847812071442604 0.014439957216382027 0.010147105902433395" quat="1.0 0.0 0.0 0.0"/>
        <geom class="collision" type="box" pos="-0.001039988244883716 -0.14049771428108215 0.09966664016246796" size="0.06696514040231705 0.002789622638374567 0.03962075710296631" quat="0.9980223774909973 0.06285938620567322 0.0 0.0"/>
        <geom class="collision" type="box" pos="-0.001039988244883716 -0.12497343122959137 0.09706462174654007" size="0.04009480029344559 0.0027896228712052107 0.041176553815603256" quat="0.9765259027481079 0.21539998054504395 0.0 0.0"/>
        <geom class="collision" type="box" pos="-0.001039988244883716 -0.2150518298149109 -0.13752520084381104" size="0.019673490896821022 0.004876092541962862 0.014557481743395329" quat="1.0 0.0 0.0 0.0"/>
        <geom class="collision" type="box" pos="0.08615154027938843 -0.14814434945583344 -0.13752520084381104" size="0.00421953434124589 0.026311196386814117 0.014557481743395329" quat="1.0 0.0 0.0 0.0"/>
        <geom class="collision" type="box" pos="0.03710896521806717 -0.21179313957691193 -0.13752520084381104" size="0.017926936969161034 0.005231990944594145 0.014557483606040478" quat="0.9961947202682495 0.0 0.0 0.08715573698282242"/>
        <geom class="collision" type="box" pos="0.06204337254166603 -0.20279547572135925 -0.13752520084381104" size="0.013208909891545773 0.005231991410255432 0.014557483606040478" quat="0.9612616896629333 0.0 0.0 0.27563735842704773"/>
        <geom class="collision" type="box" pos="0.07885299623012543 -0.1860150843858719 -0.13752520084381104" size="0.015535338781774044 0.005231991410255432 0.01455747988075018" quat="0.8870107531547546 0.0 0.0 0.46174874901771545"/>
        <geom class="collision" type="box" pos="-0.07885301113128662 -0.1860150545835495 -0.13752520084381104" size="0.015535340644419193 0.005231995601207018 0.014557483606040478" quat="0.8870107531547546 0.0 -0.0 -0.46174874901771545"/>
        <geom class="collision" type="box" pos="-0.06204337999224663 -0.20279547572135925 -0.13752520084381104" size="0.013208911754190922 0.005231995601207018 0.014557483606040478" quat="0.9612616896629333 0.0 -0.0 -0.27563735842704773"/>
        <geom class="collision" type="box" pos="-0.03710898011922836 -0.21179313957691193 -0.13752520084381104" size="0.017926936969161034 0.005231995601207018 0.014557483606040478" quat="0.9961947202682495 0.0 -0.0 -0.08715575188398361"/>
        <geom class="collision" type="box" pos="-0.08615154772996902 -0.14814434945583344 -0.13752520084381104" size="0.00421953434124589 0.026311200112104416 0.014557483606040478" quat="1.0 0.0 0.0 0.0"/>
        <geom class="collision" type="box" pos="-0.001039988244883716 -0.19328707456588745 -0.14053919911384583" size="0.04468570277094841 0.016660097986459732 0.011543487198650837" quat="1.0 0.0 0.0 0.0"/>
        <geom class="collision" type="box" pos="0.00034792337100952864 -0.14682042598724365 -0.14053919911384583" size="0.08250676095485687 0.02994546853005886 0.011543487198650837" quat="1.0 0.0 0.0 0.0"/>
        <geom class="collision" type="box" pos="0.05526924878358841 -0.18467195332050323 -0.14053919911384583" size="0.023893576115369797 0.014690425246953964 0.011543487198650837" quat="0.9238795042037964 0.0 0.0 0.3826834559440613"/>
        <geom class="collision" type="box" pos="-0.05478034168481827 -0.18739482760429382 -0.14053919911384583" size="0.023893576115369797 0.014690425246953964 0.011543487198650837" quat="0.9238795042037964 0.0 -0.0 -0.3826834559440613"/>
        <geom class="collision" type="cylinder" pos="0.01691923290491104 -0.15179666876792908 0.001019718823954463" size="0.008306972682476044 0.0042175608687102795" quat="1.0 0.0 0.0 0.0"/>
        <geom class="collision" type="cylinder" pos="0.0 0.16888763010501862 -0.1333457976579666" size="0.03554733470082283 0.01612493209540844" quat="1.0 0.0 0.0 0.0"/>
        <geom class="collision" type="cylinder" pos="-0.017341062426567078 -0.15179666876792908 0.001019718823954463" size="0.008306972682476044 0.0042175608687102795" quat="1.0 0.0 0.0 0.0"/>
        <body name="Button001">
          <joint axis="0.0 1.0 0.0" pos="-0.024521537125110626 -0.1818879097700119 0.07442397624254227" limited="true" name="Button001_joint" range="0.0 0.0034999999999999996" type="slide" damping="1" frictionloss="1" armature=".01" stiffness="0.05"/>
          <geom mesh="Button001_vis" type="mesh" solimp="0.998 0.998 0.001" solref="0.001 1" density="100" friction="0.95 0.3 0.1" class="visual" material="Button001_material"/>
          <geom class="collision" type="cylinder" pos="-0.024521537125110626 -0.18106214702129364 0.07442397624254227" size="0.006024941802024841 0.0019775587134063244" quat="0.7071067094802856 0.7071068286895752 0.0 0.0"/>
        </body>
        <body name="Button002">
          <joint axis="0.0 1.0 0.0" pos="-4.644083310267888e-05 -0.1818879097700119 0.07442397624254227" limited="true" name="Button002_joint" range="0.0 0.0034999999999999996" type="slide" damping="1" frictionloss="1" armature=".01" stiffness="0.05"/>
          <geom mesh="Button002_vis" type="mesh" solimp="0.998 0.998 0.001" solref="0.001 1" density="100" friction="0.95 0.3 0.1" class="visual" material="Button002_material"/>
          <geom class="collision" type="cylinder" pos="-4.6440400183200836e-05 -0.18107661604881287 0.07442397624254227" size="0.006024941802024841 0.001992026111111045" quat="0.7071067094802856 0.7071068286895752 0.0 0.0"/>
        </body>
        <body name="Button003">
          <joint axis="0.0 1.0 0.0" pos="0.024428658187389374 -0.1818879097700119 0.07442397624254227" limited="true" name="Button003_joint" range="0.0 0.0034999999999999996" type="slide" damping="1" frictionloss="1" armature=".01" stiffness="0.05"/>
          <geom mesh="Button003_vis" type="mesh" solimp="0.998 0.998 0.001" solref="0.001 1" density="100" friction="0.95 0.3 0.1" class="visual" material="Button003_material"/>
          <geom class="collision" type="cylinder" pos="0.024428660050034523 -0.18122494220733643 0.07442397624254227" size="0.006024941802024841 0.002140346448868513" quat="0.7071067094802856 0.7071068286895752 0.0 0.0"/>
        </body>
        <body name="Container001_Clear">
          <joint axis="0.0 0.0 1.0" pos="0.0003075712302234024 0.1690853089094162 -0.046253517270088196" limited="true" name="Container001_Clear_joint" range="0.0 0.2" type="slide" damping="1" frictionloss="1" armature=".01" stiffness="0.05"/>
          <geom mesh="Container001_Clear_vis" type="mesh" solimp="0.998 0.998 0.001" solref="0.001 1" density="100" friction="0.95 0.3 0.1" class="visual" material="Container001_Clear_material"/>
          <geom class="collision" type="box" pos="-0.0004623840795829892 0.2153720259666443 -0.0109131233766675" size="0.010516506619751453 0.002814082195982337 0.13401581346988678" quat="0.9998857975006104 -0.015110909007489681 -0.0 0.0"/>
          <geom class="collision" type="box" pos="-0.0004623840795829892 0.12225232273340225 -0.009994575753808022" size="0.010516506619751453 0.002814082195982337 0.13401581346988678" quat="7.548928238065855e-08 -1.1408421984882011e-09 0.015110909007489681 -0.9998857975006104"/>
          <geom class="collision" type="box" pos="-0.04702223464846611 0.16881217062473297 -0.009994575753808022" size="0.010516506619751453 0.002814082195982337 0.13401581346988678" quat="0.7070260047912598 -0.010684972628951073 -0.010684972628951073 0.7070261240005493"/>
          <geom class="collision" type="box" pos="0.04609747603535652 0.16881217062473297 -0.0109131233766675" size="0.010516506619751453 0.002814082195982337 0.13401581346988678" quat="0.7070260047912598 -0.010684974491596222 0.010684974491596222 -0.7070261240005493"/>
          <geom class="collision" type="box" pos="0.016400909051299095 0.1254134476184845 -0.0109131233766675" size="0.010516506619751453 0.002814082195982337 0.13401581346988678" quat="0.18422594666481018 -0.0027841245755553246 0.014852131716907024 -0.9827677607536316"/>
          <geom class="collision" type="box" pos="-0.017325667664408684 0.21221089363098145 -0.009994575753808022" size="0.010516506619751453 0.002814082195982337 0.13401581346988678" quat="0.9827678203582764 -0.014852132648229599 -0.002784118754789233 0.18422554433345795"/>
          <geom class="collision" type="box" pos="-0.04386110603809357 0.15194888412952423 -0.009994575753808022" size="0.010516506619751453 0.002814082195982337 0.13401581346988678" quat="0.5646544098854065 -0.00853336974978447 -0.012470713816583157 0.8251891136169434"/>
          <geom class="collision" type="box" pos="0.04293634742498398 0.1856754720211029 -0.0109131233766675" size="0.010516506619751453 0.002814082195982337 0.13401581346988678" quat="0.8251891136169434 -0.012470713816583157 0.00853336974978447 -0.5646544098854065"/>
          <geom class="collision" type="box" pos="0.033372554928064346 0.20079682767391205 -0.0109131233766675" size="0.010516506619751453 0.002814082195982337 0.13401581346988678" quat="0.9183061718940735 -0.013877948746085167 0.005978259723633528 -0.3955824077129364"/>
          <geom class="collision" type="box" pos="-0.034297313541173935 0.1368275284767151 -0.009994575753808022" size="0.010516506619751453 0.002814082195982337 0.13401581346988678" quat="0.3955828845500946 -0.005978265777230263 -0.013877944089472294 0.9183059930801392"/>
          <geom class="collision" type="box" pos="-0.03244701772928238 0.2026471048593521 -0.009994575753808022" size="0.010516506619751453 0.002814082195982337 0.13401581346988678" quat="0.9290596842765808 -0.014040469191968441 -0.00558592239394784 0.3696211576461792"/>
          <geom class="collision" type="box" pos="0.03152225539088249 0.13497723639011383 -0.0109131233766675" size="0.010516506619751453 0.002814082195982337 0.13401581346988678" quat="0.36962124705314636 -0.005585921462625265 0.014040464535355568 -0.929059624671936"/>
          <geom class="collision" type="box" pos="0.04217557981610298 0.15010856091976166 -0.0109131233766675" size="0.010516506619751453 0.002814082195982337 0.13401581346988678" quat="0.5468785166740417 -0.008264729753136635 0.01265034731477499 -0.8370755910873413"/>
          <geom class="collision" type="box" pos="-0.04310033097863197 0.18751578032970428 -0.009994575753808022" size="0.010516506619751453 0.002814082195982337 0.13401581346988678" quat="0.8370756506919861 -0.012650350108742714 -0.00826472882181406 0.5468783974647522"/>
          <geom class="collision" type="box" pos="-0.01916598342359066 0.1261742264032364 -0.009994575753808022" size="0.010516506619751453 0.002814082195982337 0.13401581346988678" quat="0.20520029962062836 -0.0031011004466563463 -0.01478919479995966 0.9786033630371094"/>
          <geom class="collision" type="box" pos="0.01824122481048107 0.21145014464855194 -0.0109131233766675" size="0.010516506619751453 0.002814082195982337 0.13401581346988678" quat="0.9786033630371094 -0.01478919293731451 0.003101099282503128 -0.20520025491714478"/>
          <geom class="collision" type="cylinder" pos="0.000307571142911911 0.1690853089094162 -0.0973147600889206" size="0.03925098851323128 0.0062439944595098495" quat="1.0 0.0 0.0 0.0"/>
          <body name="Lid002">
            <joint axis="1.0 0.0 0.0" pos="0.00030757038621231914 0.1231178343296051 0.12284984439611435" limited="true" name="Lid002_joint" range="0.0 1.5707963267948966" type="hinge" damping="1" frictionloss="1" armature=".01" stiffness="0.05"/>
            <geom mesh="Lid002_vis" type="mesh" solimp="0.998 0.998 0.001" solref="0.001 1" density="100" friction="0.95 0.3 0.1" class="visual" material="Lid002_material"/>
            <geom class="collision" type="cylinder" pos="0.000307571142911911 0.1690853089094162 0.11756789684295654" size="0.04501838982105255 0.0071614645421504974" quat="1.0 0.0 0.0 0.0"/>
          </body>
        </body>
        <body name="Lid001">
          <joint axis="-1.0 0.0 0.0" pos="-0.0015179887413978577 0.0018491835799068213 0.13709257543087006" limited="true" name="Lid001_joint" range="0.0 1.5707963267948966" type="hinge" damping="1" frictionloss="1" armature=".01" stiffness="1" springref="-5"/>
          <geom mesh="Lid001_vis" type="mesh" solimp="0.998 0.998 0.001" solref="0.001 1" density="100" friction="0.95 0.3 0.1" class="visual" material="Lid001_material"/>
          <geom class="collision" type="box" pos="0.016897015273571014 -0.06201185658574104 0.14015266299247742" size="0.01856940984725952 0.05487756431102753 0.0038312412798404694" quat="0.9977044463157654 -0.022706760093569756 0.060022033751010895 0.021624905988574028"/>
          <geom class="collision" type="box" pos="0.018933799117803574 -0.13253159821033478 0.14438174664974213" size="0.019886229187250137 0.0162035059183836 0.0038312412798404694" quat="0.9891969561576843 -0.1264004111289978 0.06361585855484009 0.03827952593564987"/>
          <geom class="collision" type="box" pos="-0.018596138805150986 -0.06194085627794266 0.13994573056697845" size="0.019022297114133835 0.05487756431102753 0.003831243608146906" quat="0.9977281093597412 -0.02277410961687565 -0.059996530413627625 -0.0205038134008646"/>
          <geom class="collision" type="box" pos="-0.01982620544731617 -0.1324777752161026 0.14425945281982422" size="0.020343920215964317 0.01620350405573845 0.003831243608146906" quat="0.9891969561576843 -0.1264003962278366 -0.06361585855484009 -0.03827952221035957"/>
        </body>
        <body name="Lid003">
          <joint axis="0.0 0.0 1.0" pos="-0.0008072398486547172 -0.16065430641174316 -0.12303192168474197" limited="true" name="Lid003_joint" range="0.0 0.05" type="slide" damping="1" frictionloss="1" armature=".01" stiffness="0.05"/>
          <geom mesh="Lid003_vis" type="mesh" solimp="0.998 0.998 0.001" solref="0.001 1" density="100" friction="0.95 0.3 0.1" class="visual" material="Lid003_material"/>
          <geom class="collision" type="box" pos="-0.001039988244883716 -0.16279461979866028 -0.12317441403865814" size="0.03817063570022583 0.04083503410220146 0.0003699018561746925" quat="1.0 0.0 0.0 0.0"/>
          <geom class="collision" type="box" pos="0.04766416177153587 -0.1612086147069931 -0.12317441403865814" size="0.010533514432609081 0.035080842673778534 0.00036990115768276155" quat="1.0 0.0 0.0 0.0"/>
          <geom class="collision" type="box" pos="0.06436283886432648 -0.15736523270606995 -0.12317441403865814" size="0.006165160797536373 0.029379118233919144 0.0003699004591908306" quat="1.0 0.0 0.0 0.0"/>
          <geom class="collision" type="box" pos="-0.06438075751066208 -0.15736523270606995 -0.12317441403865814" size="0.006165160797536373 0.029379118233919144 0.0003698997898027301" quat="1.0 0.0 0.0 0.0"/>
          <geom class="collision" type="box" pos="-0.04986061528325081 -0.1612086147069931 -0.12317441403865814" size="0.010533514432609081 0.035080842673778534 0.0003698990913107991" quat="1.0 0.0 0.0 0.0"/>
        </body>
        <geom class="region" name="reg_main" type="box" pos="-1.862645149230957e-09 0.0 0.0" size="0.0905999019742012 0.21999847888946533 0.1524038016796112"/>
      </body>
    </body>
  </worldbody>
  <actuator>
    <motor name="Button001_joint_actuator" joint="Button001_joint" gear="0.3"/>
    <motor name="Button002_joint_actuator" joint="Button002_joint" gear="0.3"/>
    <motor name="Button003_joint_actuator" joint="Button003_joint" gear="0.3"/>
    <motor name="Container001_Clear_joint_actuator" joint="Container001_Clear_joint" gear="100"/>
    <motor name="Lid001_joint_actuator" joint="Lid001_joint" gear="10"/>
    <motor name="Lid003_joint_actuator" joint="Lid003_joint" gear="10"/>
    <motor name="Lid002_joint_actuator" joint="Lid002_joint" gear="10"/>
  </actuator>
</mujoco>
