<?xml version='1.0' encoding='UTF-8'?>
<mujoco model="model">
  <compiler angle="radian"/>
  <asset>
    <mesh file="visuals/Body001.obj" name="Body001_vis"/>
    <mesh file="visuals/Body002.obj" name="Body002_vis"/>
    <mesh file="visuals/Button001.obj" name="Button001_vis"/>
    <mesh file="visuals/Knob001.obj" name="Knob001_vis"/>
    <mesh file="visuals/Lever001.obj" name="Lever001_vis"/>
    <texture file="visuals/T_BC001.png" name="Body001_material" type="2d"/>
    <material name="Body001_material" rgba="1 1 1 1.0" texture="Body001_material" shininess="0.4472135901451111" specular="0.7"/>
    <texture file="visuals/T_BC001.png" name="Body002_material" type="2d"/>
    <material name="Body002_material" rgba="1 1 1 1.0" texture="Body002_material" shininess="0.4472135901451111" specular="0.7"/>
    <texture file="visuals/T_BC001.png" name="Button001_material" type="2d"/>
    <material name="Button001_material" rgba="1 1 1 1.0" texture="Button001_material" shininess="0.4472135901451111" specular="0.7"/>
    <texture file="visuals/T_BC001.png" name="Knob001_material" type="2d"/>
    <material name="Knob001_material" rgba="1 1 1 1.0" texture="Knob001_material" shininess="0.4472135901451111" specular="0.7"/>
    <texture file="visuals/T_BC001.png" name="Lever001_material" type="2d"/>
    <material name="Lever001_material" rgba="1 1 1 1.0" texture="Lever001_material" shininess="0.4472135901451111" specular="0.7"/>
  </asset>
  <default>
    <default class="visual">
      <geom conaffinity="0" contype="0" group="1" type="mesh"/>
    </default>
    <default class="collision">
      <geom group="0" rgba="0.5 0 0 0.5"/>
    </default>
    <default class="spawn">
      <geom group="0" rgba="1 1 1 0.5" contype="0" conaffinity="0"/>
      <site group="0" rgba="1 1 1 0.5"/>
    </default>
    <default class="region">
      <geom group="1" conaffinity="0" contype="0" rgba="0 1 0 0"/>
    </default>
  </default>
  <worldbody>
    <body>
      <body name="object">
        <geom mesh="Body001_vis" type="mesh" solimp="0.998 0.998 0.001" solref="0.001 1" density="100" friction="0.95 0.3 0.1" class="visual" material="Body001_material"/>
        <geom class="collision" type="box" pos="0.068138 0.004551 0.000201" size="0.008348358795046806 0.13344532251358032 0.09807537496089935" quat="1.0 0.0 0.0 0.0"/>
        <geom class="collision" type="box" pos="0.001020 -0.001908 0.000061" size="0.011282899416983128 0.09176366776227951 0.09820854663848877" quat="1.0 0.0 0.0 0.0"/>
        <geom class="collision" type="box" pos="0.001476 0.113644 -0.000253" size="0.057897262275218964 0.02387482486665249 0.09812276810407639" quat="1.0 0.0 0.0 0.0"/>
        <geom class="collision" type="box" pos="0.004189 -0.105335 -0.079438" size="0.0913849025964737 0.0267530158162117 0.018722539767622948" quat="1.0 0.0 0.0 0.0"/>
        <geom class="collision" type="box" pos="-0.065769 0.004551 0.000292" size="0.010383578017354012 0.13323767483234406 0.09801129996776581" quat="1.0 0.0 0.0 0.0"/>
        <geom class="collision" type="box" pos="-0.002098 0.006243 -0.082130" size="0.05969012528657913 0.09041440486907959 0.01581723429262638" quat="1.0 0.0 0.0 0.0"/>
        <geom class="collision" type="box" pos="-0.030094 -0.104027 0.017177" size="0.026154784485697746 0.024326661601662636 0.08100171387195587" quat="1.0 0.0 0.0 0.0"/>
        <geom class="collision" type="box" pos="0.032545 -0.102502 0.017967" size="0.027291320264339447 0.022801518440246582 0.08021790534257889" quat="1.0 0.0 0.0 0.0"/>
        <geom class="collision" type="box" pos="0.000333 -0.103784 -0.057431" size="0.004350475035607815 0.025201139971613884 0.004822122398763895" quat="1.0 0.0 0.0 0.0"/>
        <geom class="collision" type="box" pos="-0.084694 0.000367 -0.011033" size="0.00921536237001419 0.10965760052204132 0.08705183863639832" quat="1.0 0.0 0.0 0.0"/>
        <geom class="collision" type="box" pos="0.084392 0.000367 -0.010791" size="0.009439783170819283 0.10965762287378311 0.08680983632802963" quat="1.0 0.0 0.0 0.0"/>
        <geom class="collision" type="box" pos="-0.076690 0.117257 -0.011201" size="0.014619444496929646 0.012130013667047024 0.08721958100795746" quat="0.9034897089004517 0.0 0.0 0.42860978841781616"/>
        <geom class="collision" type="box" pos="0.076893 -0.112437 -0.010905" size="0.014619444496929646 0.00789739191532135 0.08692338317632675" quat="0.9259243011474609 0.0 0.0 0.37770912051200867"/>
        <geom class="collision" type="box" pos="-0.079726 -0.110723 -0.011034" size="0.014619444496929646 0.00789739191532135 0.08705200999975204" quat="0.37020304799079895 0.0 0.0 0.928950846195221"/>
        <geom class="collision" type="box" pos="0.079034 0.122015 -0.010889" size="0.014619444496929646 0.007897390983998775 0.08690701425075531" quat="0.39130401611328125 0.0 0.0 0.9202614426612854"/>
        <geom class="collision" type="box" pos="-0.092890 0.003423 -0.079349" size="0.004461574833840132 0.11271370947360992 0.00669081648811698" quat="1.0 0.0 0.0 0.0"/>
        <geom class="collision" type="box" pos="0.092868 0.004031 -0.079349" size="0.004627229180186987 0.11332177370786667 0.006690817419439554" quat="1.0 0.0 0.0 0.0"/>
        <geom class="collision" type="box" pos="0.001476 0.140558 -0.080060" size="0.07388576120138168 0.003776318160817027 0.0069085294380784035" quat="1.0 0.0 0.0 0.0"/>
        <geom class="collision" type="box" pos="0.082237 0.127885 -0.082571" size="0.012614376842975616 0.0078973937779665 0.009693946689367294" quat="0.39130401611328125 0.0 0.0 0.9202614426612854"/>
        <geom class="collision" type="box" pos="-0.080298 0.126756 -0.082571" size="0.016441063955426216 0.007897392846643925 0.009693946689367294" quat="0.4122016727924347 0.0 -0.0 -0.9110926389694214"/>
        <geom class="collision" type="box" pos="-0.079855 0.003423 0.081484" size="0.006238756701350212 0.11271379142999649 0.015457455068826675" quat="0.9224948287010193 3.011522147124422e-16 0.3860095143318176 5.186380036548144e-08"/>
        <geom class="collision" type="box" pos="0.081080 0.003423 0.082863" size="0.006238756701350212 0.11271379142999649 0.014129200018942356" quat="0.945044755935669 6.997293861005097e-15 -0.3269409239292145 -4.392740038383636e-08"/>
        <body name="Body002">
          <geom mesh="Body002_vis" type="mesh" solimp="0.998 0.998 0.001" solref="0.001 1" density="100" friction="0.95 0.3 0.1" class="visual" material="Body002_material"/>
          <geom class="collision" type="box" pos="-0.050086 0.004630 0.007062" size="0.002028566552326083 0.08008460700511932 0.07554154098033905" quat="1.0 0.0 0.0 0.0"/>
          <geom class="collision" type="box" pos="-0.016241 0.004630 0.007062" size="0.002852117642760277 0.08008510619401932 0.07554188370704651" quat="1.0 0.0 0.0 0.0"/>
          <geom class="collision" type="box" pos="0.017642 0.004630 0.007062" size="0.0026984047144651413 0.08008477836847305 0.07554186135530472" quat="1.0 0.0 0.0 0.0"/>
          <geom class="collision" type="box" pos="0.052164 0.004630 0.007062" size="0.002901066094636917 0.08008477836847305 0.07554154098033905" quat="1.0 0.0 0.0 0.0"/>
        </body>
        <body name="Button001">
          <joint axis="0.0 1.0 0.0" pos="0.040313 -0.130197 -0.046930" limited="true" name="Button001_joint" range="0.0 0.001" type="slide" damping="1" frictionloss="1" armature=".01" stiffness="0.05"/>
          <geom mesh="Button001_vis" type="mesh" solimp="0.998 0.998 0.001" solref="0.001 1" density="100" friction="0.95 0.3 0.1" class="visual" material="Button001_material"/>
          <geom class="collision" type="cylinder" pos="0.040367 -0.130872 -0.046940" size="0.007806489244103432 0.0018239460187032819" quat="0.7071067094802856 0.70710688829422 0.0 0.0"/>
        </body>
        <body name="Knob001">
          <joint axis="0.0 1.0 0.0" pos="-0.037787 -0.136904 -0.035596" limited="true" name="Knob001_joint" range="0.0 5.497787143782138" type="hinge" damping="0.05" armature="0.001"/>
          <geom mesh="Knob001_vis" type="mesh" solimp="0.998 0.998 0.001" solref="0.001 1" density="100" friction="0.95 0.3 0.1" class="visual" material="Knob001_material"/>
          <geom class="collision" type="cylinder" pos="-0.037668 -0.131675 -0.035256" size="0.016373874619603157 0.0019330427749082446" quat="0.7071067094802856 0.70710688829422 0.0 0.0"/>
          <geom class="collision" type="box" pos="-0.037750 -0.139205 -0.035577" size="0.006319499108940363 0.005593504291027784 0.01582489162683487" quat="1.0 0.0 0.0 0.0"/>
        </body>
        <body name="Lever001">
          <joint axis="0.0 0.0 -1.0" pos="0.000279 -0.122845 0.078272" limited="true" name="Lever001_joint" range="0.0 0.128" type="slide" damping="1" frictionloss="1" armature=".01" stiffness="1" springref="-1"/>
          <geom mesh="Lever001_vis" type="mesh" solimp="0.998 0.998 0.001" solref="0.001 1" density="100" friction="0.95 0.3 0.1" class="visual" material="Lever001_material"/>
          <geom class="collision" type="box" pos="-0.000003 -0.138094 0.081691" size="0.018643731251358986 0.005411902908235788 0.007104021031409502" quat="1.0 0.0 0.0 0.0" name="lever_knob"/>
          <geom class="collision" type="box" pos="0.000367 -0.118339 0.081673" size="0.002949710004031658 0.014109428972005844 0.0014008566504344344" quat="1.0 0.0 0.0 0.0"/>
          <geom class="collision" type="box" pos="-0.033588 0.003719 0.077434" size="0.013499999418854713 0.07910861819982529 0.0028953109867870808" quat="1.0 0.0 0.0 0.0" name="slotL_floor"/>
          <geom class="collision" type="box" pos="0.034799 0.003719 0.077434" size="0.013499999418854713 0.07910861819982529 0.0028953109867870808" quat="1.0 0.0 0.0 0.0" name="slotR_floor"/>
        </body>
        <geom class="region" name="reg_main" type="box" pos="0.0 0.006054500000000004 0.0" size="0.097575 0.13857049999999999 0.09847"/>
      </body>
    </body>
  </worldbody>
  <actuator>
    <motor name="Button001_joint_actuator" joint="Button001_joint" gear="0.5"/>
    <motor name="Knob001_joint_actuator" joint="Knob001_joint" gear="5"/>
    <motor name="Lever001_joint_actuator" joint="Lever001_joint" gear="0.5"/>
  </actuator>
</mujoco>
