<mujoco model="model">
  <compiler angle="radian"/>
  <asset>
    <mesh file="visuals/handle.obj" name="handle_vis"/>
    <mesh file="visuals/Body001.obj" name="Body001_vis"/>
    <mesh file="visuals/Funnel001.obj" name="Funnel001_vis"/>
    <mesh file="visuals/Funnel002.obj" name="Funnel002_vis"/>
    <mesh file="visuals/spout.obj" name="spout_vis"/>
    <texture file="visuals/T_BC001.png" name="Body001_material" type="2d"/>
    <material name="Body001_material" rgba="1 1 1 1.0" texture="Body001_material" shininess="0.4472135901451111" specular="0.3103448502657381"/>
    <texture file="visuals/T_BC001.png" name="handle_material" type="2d"/>
    <material name="handle_material" rgba="1 1 1 1.0" texture="handle_material" shininess="0.4472135901451111" specular="0.3103448502657381"/>
    <texture file="visuals/T_BC001.png" name="Funnel001_material" type="2d"/>
    <material name="Funnel001_material" rgba="1 1 1 1.0" texture="Funnel001_material" shininess="0.4472135901451111" specular="0.3103448502657381"/>
    <texture file="visuals/T_BC001.png" name="Funnel002_material" type="2d"/>
    <material name="Funnel002_material" rgba="1 1 1 1.0" texture="Funnel002_material" shininess="0.4472135901451111" specular="0.3103448502657381"/>
    <texture file="visuals/T_BC001.png" name="spout_material" type="2d"/>
    <material name="spout_material" rgba="1 1 1 1.0" texture="spout_material" shininess="0.4472135901451111" specular="0.3103448502657381"/>
  </asset>
  <default>
    <default class="visual">
      <geom conaffinity="0" contype="0" group="1" type="mesh"/>
    </default>
    <default class="collision">
      <geom group="0" rgba="0.5 0 0 0.5"/>
    </default>
    <default class="spawn">
      <geom group="0" rgba="1 1 1 0.5" contype="0" conaffinity="0"/>
      <site group="0" rgba="1 1 1 0.5"/>
    </default>
    <default class="region">
      <geom group="1" conaffinity="0" contype="0" rgba="0 1 0 0"/>
    </default>
  </default>
  <worldbody>
    <body>
      <body name="object">
        <geom mesh="Body001_vis" type="mesh" solimp="0.998 0.998 0.001" solref="0.001 1" density="100" friction="0.95 0.3 0.1" class="visual" material="Body001_material"/>
        <geom class="collision" type="box" pos="-0.393599 -0.000057 -0.152394" size="0.03231722488999367 0.25210869312286377 0.12578809261322021" quat="1.0 0.0 0.0 0.0"/>
        <geom class="collision" type="box" pos="0.000463 -0.000057 -0.152394" size="0.02948875166475773 0.25210869312286377 0.12578809261322021" quat="1.0 0.0 0.0 0.0"/>
        <geom class="collision" type="box" pos="0.303576 -0.000057 -0.152394" size="0.11784769594669342 0.25210869312286377 0.12578809261322021" quat="1.0 0.0 0.0 0.0"/>
        <geom class="collision" type="box" pos="-0.086141 0.222530 -0.152394" size="0.2771652936935425 0.029488762840628624 0.12578809261322021" quat="1.0 0.0 0.0 0.0"/>
        <geom class="collision" type="box" pos="-0.086141 -0.223226 -0.152394" size="0.2771652936935425 0.029488762840628624 0.12578809261322021" quat="1.0 0.0 0.0 0.0"/>
        <geom class="collision" type="box" pos="0.109079 -0.167166 -0.152394" size="0.08194547891616821 0.03034169226884842 0.12578809261322021" quat="1.0 0.0 0.0 0.0"/>
        <geom class="collision" type="box" pos="0.109079 0.165000 -0.152394" size="0.08194547891616821 0.03034169226884842 0.12578809261322021" quat="1.0 0.0 0.0 0.0"/>
        <geom class="collision" type="box" pos="-0.274527 -0.000369 -0.250090" size="0.08836553245782852 0.19444924592971802 0.028092036023736" quat="1.0 0.0 0.0 0.0"/>
        <geom class="collision" type="box" pos="-0.057293 -0.000733 -0.250090" size="0.0294963289052248 0.19408562779426575 0.028092036023736" quat="1.0 0.0 0.0 0.0"/>
        <geom class="collision" type="box" pos="-0.136239 0.118857 -0.250090" size="0.05127447471022606 0.07449623197317123 0.028092036023736" quat="1.0 0.0 0.0 0.0"/>
        <geom class="collision" type="box" pos="-0.136239 -0.118214 -0.250090" size="0.05127447471022606 0.07449623197317123 0.028092036023736" quat="1.0 0.0 0.0 0.0"/>
        <geom class="collision" type="box" pos="0.045072 -0.002129 -0.218055" size="0.01764518953859806 0.13783448934555054 0.05984923243522644" quat="1.0 0.0 0.0 0.0"/>
        <geom class="collision" type="box" pos="0.171935 -0.002129 -0.218055" size="0.01764518953859806 0.13783448934555054 0.05984923243522644" quat="1.0 0.0 0.0 0.0"/>
        <geom class="collision" type="box" pos="0.108581 0.088785 -0.218055" size="0.04652325436472893 0.04692062735557556 0.05984923243522644" quat="1.0 0.0 0.0 0.0"/>
        <geom class="collision" type="box" pos="0.108581 -0.089599 -0.218055" size="0.04652325436472893 0.04692062735557556 0.05984923243522644" quat="1.0 0.0 0.0 0.0"/>
        <geom class="collision" type="cylinder" pos="0.035790 0.187932 0.031431" size="0.02456476166844368 0.06040993332862854" quat="1.0 0.0 0.0 0.0"/>
        <geom class="collision" type="cylinder" pos="0.053787 0.188139 0.063028" size="0.026115644723176956 0.05618581548333168" quat="0.7071068286895752 -0.0 0.7071067690849304 0.0"/>
        <body name="handle">
          <joint axis="1.0 0.0 0.0" pos="0.123446 0.188001 0.063618" limited="true" name="handle_joint_hinge_0" type="hinge" range="-0.7853981633974483 0.7853981633974483" damping="1" frictionloss="1" armature=".01" stiffness="0.05"/>
          <joint axis="0.0 1.0 0.0" pos="0.123446 0.188001 0.063618" limited="true" name="handle_joint_hinge_1" type="hinge" range="0.0 0.17453292519943295" damping="1" frictionloss="1" armature=".01" stiffness="0.05"/>
          <geom mesh="handle_vis" type="mesh" solimp="0.998 0.998 0.001" solref="0.001 1" density="100" friction="0.95 0.3 0.1" class="visual" material="handle_material"/>
          <geom class="collision" type="box" pos="0.123607 0.188015 0.119955" size="0.007959337905049324 0.004582853987812996 0.03360467776656151" quat="1.0 0.0 0.0 0.0"/>
          <geom class="collision" type="cylinder" pos="0.124225 0.188139 0.063028" size="0.026115644723176956 0.007472321856766939" quat="0.7071068286895752 -0.0 0.7071067690849304 0.0"/>
        </body>
        <body name="Funnel001">
          <joint axis="0.0 0.0 1.0" pos="-0.135175 -0.000003 -0.249075" limited="true" name="Funnel001_joint" range="0.0 0.1" type="slide" damping="1" frictionloss="1" armature=".01" stiffness="0.05"/>
          <geom mesh="Funnel001_vis" type="mesh" solimp="0.998 0.998 0.001" solref="0.001 1" density="100" friction="0.95 0.3 0.1" class="visual" material="Funnel001_material"/>
          <geom class="collision" type="cylinder" pos="-0.134678 0.000483 -0.247243" size="0.04176432266831398 0.012595447711646557" quat="1.0 0.0 0.0 0.0"/>
        </body>
        <body name="Funnel002">
          <joint axis="0.0 0.0 1.0" pos="0.108112 -0.000000 -0.177778" limited="true" name="Funnel002_joint" range="0.0 0.1" type="slide" damping="1" frictionloss="1" armature=".01" stiffness="0.05"/>
          <geom mesh="Funnel002_vis" type="mesh" solimp="0.998 0.998 0.001" solref="0.001 1" density="100" friction="0.95 0.3 0.1" class="visual" material="Funnel002_material"/>
          <geom class="collision" type="cylinder" pos="0.108871 -0.000087 -0.175780" size="0.040251873433589935 0.012595447711646557" quat="1.0 0.0 0.0 0.0"/>
        </body>
        <body name="spout">
          <joint axis="0.0 0.0 1.0" pos="0.035690 0.188000 0.186114" limited="true" name="spout_joint" range="-0.7853981633974483 0.7853981633974483" type="hinge" damping="1" frictionloss="1" armature=".01" stiffness="0.05"/>
          <site type="cylinder" rgba="0.5 0.75 1 1" size="0.009254577569663525 0.24651148915290833" pos="0.035485 -0.035924 -0.003622" name="water"/>
          <geom mesh="spout_vis" type="mesh" solimp="0.998 0.998 0.001" solref="0.001 1" density="100" friction="0.95 0.3 0.1" class="visual" material="spout_material"/>
          <geom class="collision" type="cylinder" pos="0.035790 0.187932 0.157070" size="0.015719404444098473 0.06040984019637108" quat="1.0 0.0 0.0 0.0"/>
          <geom class="collision" type="cylinder" pos="0.035790 0.182112 0.224348" size="0.015719404444098473 0.022149622440338135" quat="0.9745777249336243 0.22404976189136505 0.0 0.0"/>
          <geom class="collision" type="cylinder" pos="0.035790 0.163359 0.247197" size="0.015719404444098473 0.022149620577692986" quat="0.9015616178512573 0.43265077471733093 0.0 0.0"/>
          <geom class="collision" type="cylinder" pos="0.035790 0.049872 0.260502" size="0.015719404444098473 0.10244826227426529" quat="0.7115802764892578 0.7026048302650452 0.0 0.0"/>
          <geom class="collision" type="cylinder" pos="0.035790 -0.036482 0.250809" size="0.015719404444098473 0.007953429594635963" quat="1.0 0.0 0.0 0.0"/>
        </body>
        <geom class="region" name="reg_main" type="box" pos="0.0 0.0 -0.15249600000000002" size="0.42173 0.25 0.12411400000000002"/>
        <geom class="region" name="reg_basin_left" type="box" pos="-0.1954725 -0.020340499999999997 -0.131879" size="0.1804535 0.1842515 0.091729"/>
        <geom class="region" name="reg_basin_right" type="box" pos="0.10692549999999999 -0.0010849999999999888 -0.0973305" size="0.0794555 0.140415 0.05383349999999999"/>
      </body>
    </body>
  </worldbody>
  <actuator>
    <motor name="handle_joint_hinge_0_actuator" joint="handle_joint_hinge_0" gear="10"/>
    <motor name="handle_joint_hinge_1_actuator" joint="handle_joint_hinge_1" gear="10"/>
    <motor name="Funnel001_joint_actuator" joint="Funnel001_joint" gear="10"/>
    <motor name="Funnel002_joint_actuator" joint="Funnel002_joint" gear="10"/>
    <motor name="spout_joint_actuator" joint="spout_joint" gear="10"/>
  </actuator>
</mujoco>
