<mujoco model="model">
  <asset>
    <texture file="visuals/material_0.png" name="tex-model" type="2d"/>
    <texture type="2d" name="image16" file="visuals/image16.png"/>
    <texture type="2d" name="image19" file="visuals/image19.png"/>
    <material name="model" reflectance="0.5" texrepeat="1 1" texture="tex-model" texuniform="false"/>
    <material name="TX_Stove_3_1.004" texture="image16" specular="0.5" shininess="0.25"/>
    <material name="TX_Stove_3_2.004" texture="image19" specular="0.5" shininess="0.25"/>
    <mesh file="visuals/model_0.obj" name="model_0_vis" scale="1 1 1"/>
    <mesh file="visuals/model_1.obj" name="model_1_vis" scale="1 1 1"/>
    <mesh file="visuals/knob_rear_right_0.obj" name="knob_rear_right_0_vis" scale="1 1 1"/>
    <mesh file="visuals/knob_front_left_0.obj" name="knob_front_left_0_vis" scale="1 1 1"/>
    <mesh file="visuals/knob_front_right_0.obj" name="knob_front_right_0_vis" scale="1 1 1"/>
    <mesh file="visuals/knob_rear_left_0.obj" name="knob_rear_left_0_vis" scale="1 1 1"/>
    <mesh file="visuals/knob_center_0.obj" name="knob_center_0_vis" scale="1 1 1"/>
  </asset>
  <default>
    <default class="visual">
      <geom conaffinity="0" contype="0" group="1" type="mesh"/>
    </default>
    <default class="collision">
      <geom group="0" rgba="0.5 0 0 0.5"/>
    </default>
    <default class="region">
      <geom group="1" conaffinity="0" contype="0" rgba="0 1 0 0"/>
    </default>
    <default class="region">
      <geom group="1" conaffinity="0" contype="0" rgba="0 1 0 0"/>
    </default>
  </default>
  <worldbody>
    <body>
      <body name="object">
        <geom solimp="0.998 0.998 0.001" solref="0.001 1" density="100" friction="0.95 0.3 0.1" type="mesh" mesh="model_0_vis" material="TX_Stove_3_2.004" class="visual"/>
        <geom solimp="0.998 0.998 0.001" solref="0.001 1" density="100" friction="0.95 0.3 0.1" type="mesh" mesh="model_1_vis" material="TX_Stove_3_1.004" class="visual"/>
        <!-- Burners -->
        <site name="burner_on_front_left" pos="-0.289 -0.12 0.005" size="0.06 0.007" rgba="0.3 0.4 1 0.5" type="cylinder"/>
        <site name="burner_on_front_right" pos="0.2875 -0.12 0.005" size="0.06 0.007" rgba="0.3 0.4 1 0.5" type="cylinder"/>
        <site name="burner_on_rear_left" pos="-0.289 0.158 0.005" size="0.07 0.007" rgba="0.3 0.4 1 0.5" type="cylinder"/>
        <site name="burner_on_rear_right" pos="0.2875 0.158 0.005" size="0.07 0.007" rgba="0.3 0.4 1 0.5" type="cylinder"/>
        <site name="burner_on_center" pos="-0.002 0.005 0.005" size="0.07 0.007" rgba="0.3 0.4 1 0.5" type="cylinder"/>
        <site name="burner_front_left_place_site" pos="-0.289 -0.12 0.032" size="0.06 0.001" rgba="0.3 0.4 1 0" type="cylinder"/>
        <site name="burner_front_right_place_site" pos="0.2875 -0.12 0.032" size="0.06 0.001" rgba="0.3 0.4 1 0" type="cylinder"/>
        <site name="burner_rear_left_place_site" pos="-0.289 0.158 0.032" size="0.07 0.001" rgba="0.3 0.4 1 0" type="cylinder"/>
        <site name="burner_rear_right_place_site" pos="0.2875 0.158 0.032" size="0.07 0.001" rgba="0.3 0.4 1 0" type="cylinder"/>
        <site name="burner_center_place_site" pos="-0.002 0.005 0.032" size="0.07 0.001" rgba="0.3 0.4 1 0" type="cylinder"/>
        <!-- Main -->
        <geom class="collision" type="box" pos="-0.289 0.0175 0" size="0.127 0.266 0.032"/>
        <geom class="collision" type="box" pos="0.2875 0.0175 0" size="0.127 0.266 0.032"/>
        <geom class="collision" type="box" pos="-0.002 0.005 0" size="0.127 0.126 0.032"/>
        <geom class="collision" type="box" pos="0 0.3205 -0.0105" size="0.485 0.0195 0.0088"/>
        <geom class="collision" type="box" pos="0 0 -0.025" size="0.5 0.355 0.006"/>
        <body name="knob_rear_right">
          <joint name="knob_rear_right_joint" type="hinge" pos="-0.087 -0.305 -0.01" damping="1" armature="2"/>
          <geom solimp="0.998 0.998 0.001" solref="0.001 1" density="100" friction="0.95 0.3 0.1" type="mesh" mesh="knob_rear_right_0_vis" material="TX_Stove_3_2.004" class="visual"/>
          <geom class="collision" type="cylinder" pos="-0.087 -0.305 -0.008" size="0.0245 0.008 0"/>
          <geom class="collision" type="box" pos="-0.087 -0.3005 0.0035" size="0.009 0.027 0.008" name="knob_rear_right_main"/>
        </body>
        <body name="knob_front_left">
          <joint name="knob_front_left_joint" type="hinge" pos="0.0785 -0.305 -0.01" damping="1" armature="2"/>
          <geom solimp="0.998 0.998 0.001" solref="0.001 1" density="100" friction="0.95 0.3 0.1" type="mesh" mesh="knob_front_left_0_vis" material="TX_Stove_3_2.004" class="visual"/>
          <geom class="collision" type="cylinder" pos="0.0785 -0.305 -0.008" size="0.0245 0.008 0"/>
          <geom class="collision" type="box" pos="0.0785 -0.3005 0.0035" size="0.009 0.027 0.008" name="knob_front_left_main"/>
        </body>
        <body name="knob_front_right">
          <joint name="knob_front_right_joint" type="hinge" pos="0.1635 -0.305 -0.01" damping="1" armature="2"/>
          <geom solimp="0.998 0.998 0.001" solref="0.001 1" density="100" friction="0.95 0.3 0.1" type="mesh" mesh="knob_front_right_0_vis" material="TX_Stove_3_2.004" class="visual"/>
          <geom class="collision" type="cylinder" pos="0.1635 -0.305 -0.008" size="0.0245 0.008 0"/>
          <geom class="collision" type="box" pos="0.1635 -0.3005 0.0035" size="0.009 0.027 0.008" name="knob_front_right_main"/>
        </body>
        <body name="knob_rear_left">
          <joint name="knob_rear_left_joint" type="hinge" pos="-0.165 -0.305 -0.01" damping="1" armature="2"/>
          <geom solimp="0.998 0.998 0.001" solref="0.001 1" density="100" friction="0.95 0.3 0.1" type="mesh" mesh="knob_rear_left_0_vis" material="TX_Stove_3_2.004" class="visual"/>
          <geom class="collision" type="cylinder" pos="-0.165 -0.305 -0.008" size="0.0245 0.008 0"/>
          <geom class="collision" type="box" pos="-0.165 -0.3005 0.0035" size="0.009 0.027 0.008" name="knob_rear_left_main"/>
        </body>
        <body name="knob_center">
          <joint name="knob_center_joint" type="hinge" pos="-0.002 -0.305 -0.01" damping="1" armature="2"/>
          <geom solimp="0.998 0.998 0.001" solref="0.001 1" density="100" friction="0.95 0.3 0.1" type="mesh" mesh="knob_center_0_vis" material="TX_Stove_3_2.004" class="visual"/>
          <geom class="collision" type="cylinder" pos="-0.002 -0.305 -0.008" size="0.0245 0.008 0"/>
          <geom class="collision" type="box" pos="-0.002 -0.3005 0.0035" size="0.009 0.027 0.008" name="knob_center_main"/>
        </body>
        <!-- exterior bounding box points -->
        <geom class="region" name="reg_main_body" type="box" pos="0.0 0.0 -0.025" size="0.5 0.354 0.006"/>
        <!-- interior bounding box points -->
        <geom class="region" name="reg_int" type="box" pos="0.0 0.0 0.0" size="0.0001 0.0001 0.0001"/>
      </body>
    </body>
  </worldbody>
</mujoco>
