<mujoco model="model">
  <compiler angle="radian"/>
  <asset>
    <mesh file="visuals/WallStackBody001.obj" name="WallStackBody001_vis"/>
    <mesh file="visuals/WallStackDoor001.obj" name="WallStackDoor001_vis"/>
    <mesh file="visuals/WallStackDoor001_Clear.obj" name="WallStackDoor001_Clear_vis"/>
    <mesh file="visuals/WallStackKnob001.obj" name="WallStackKnob001_vis"/>
    <mesh file="visuals/WallStackKnob002.obj" name="WallStackKnob002_vis"/>
    <mesh file="visuals/WallStackShelf001.obj" name="WallStackShelf001_vis"/>
    <texture file="visuals/T_WallStackBC001.png" name="WallStackBody001_material" type="2d"/>
    <material name="WallStackBody001_material" rgba="1 1 1 1.0" texture="WallStackBody001_material" shininess="1" specular="1"/>
    <texture file="visuals/T_WallStackBC001.png" name="WallStackDoor001_material" type="2d"/>
    <material name="WallStackDoor001_material" rgba="1 1 1 1.0" texture="WallStackDoor001_material" shininess="1" specular="1"/>
    <texture file="visuals/T_WallStackBC001.png" name="WallStackDoor001_Clear_material" type="2d"/>
    <material name="WallStackDoor001_Clear_material" rgba="1 1 1 0.7999999523162842" texture="WallStackDoor001_Clear_material" shininess="0.4472135901451111" specular="0.3103448502657381"/>
    <texture file="visuals/T_WallStackBC001.png" name="WallStackKnob001_material" type="2d"/>
    <material name="WallStackKnob001_material" rgba="1 1 1 1.0" texture="WallStackKnob001_material" shininess="0.4472135901451111" specular="0.3103448502657381"/>
    <texture file="visuals/T_WallStackBC001.png" name="WallStackKnob002_material" type="2d"/>
    <material name="WallStackKnob002_material" rgba="1 1 1 1.0" texture="WallStackKnob002_material" shininess="0.4472135901451111" specular="0.3103448502657381"/>
    <texture file="visuals/T_WallStackBC001.png" name="WallStackShelf001_material" type="2d"/>
    <material name="WallStackShelf001_material" rgba="1 1 1 1.0" texture="WallStackShelf001_material" shininess="0.4472135901451111" specular="0.3103448502657381"/>
  </asset>
  <default>
    <default class="visual">
      <geom conaffinity="0" contype="0" group="1" type="mesh"/>
    </default>
    <default class="collision">
      <geom group="0" rgba="0.5 0 0 0.5"/>
    </default>
    <default class="spawn">
      <geom group="0" rgba="1 1 1 0.5" contype="0" conaffinity="0"/>
      <site group="0" rgba="1 1 1 0.5"/>
    </default>
  </default>
  <worldbody>
    <body>
      <site rgba="0 0 0 0.5" size="0.01" pos="-0.302676 -0.206261 -0.298719" name="ext_p0"/>
      <site rgba="1 0 0 0.5" size="0.01" pos="0.302685 -0.206261 -0.298719" name="ext_px"/>
      <site rgba="0 1 0 0.5" size="0.01" pos="-0.302676 0.255556 -0.298719" name="ext_py"/>
      <site rgba="0 0 1 0.5" size="0.01" pos="-0.302676 -0.206261 0.292791" name="ext_pz"/>
      <site rgba="1 0.75 0.8 0.5" size="0.005171637050807476" pos="-0.234222 -0.187266 0.110273" name="int_pz"/>
      <site rgba="0 1 1 0.5" size="0.005171637050807476" pos="-0.242008 0.200392 -0.246864" name="int_py"/>
      <site rgba="1 1 0 0.5" size="0.005171637050807476" pos="0.239640 -0.189953 -0.247514" name="int_px"/>
      <site rgba="0.5 0.5 0.5 0.5" size="0.005171637050807476" pos="-0.242008 -0.189953 -0.246864" name="int_p0"/>
      <body name="object">
        <geom mesh="WallStackBody001_vis" type="mesh" solimp="0.998 0.998 0.001" solref="0.001 1" density="100" friction="0.95 0.3 0.1" class="visual" material="WallStackBody001_material"/>
        <geom class="collision" type="box" pos="-0.000111 0.031908 -0.267604" size="0.29171276092529297 0.2194117158651352 0.019484931603074074" quat="1.0 0.0 0.0 0.0"/>
        <geom class="collision" type="box" pos="0.000346 -0.141145 0.258247" size="0.29411524534225464 0.04925039783120155 0.024248898029327393" quat="1.0 0.0 0.0 0.0"/>
        <geom class="collision" type="box" pos="0.274134 0.016046 -0.018899" size="0.023398851975798607 0.20375710725784302 0.26818951964378357" quat="1.0 0.0 0.0 0.0"/>
        <geom class="collision" type="box" pos="-0.000111 0.228619 -0.018899" size="0.2917129397392273 0.03347042575478554 0.26818957924842834" quat="1.0 0.0 0.0 0.0"/>
        <geom class="collision" type="box" pos="-0.274425 0.016493 -0.018899" size="0.023942943662405014 0.20433248579502106 0.2681896388530731" quat="1.0 0.0 0.0 0.0"/>
        <geom class="collision" type="box" pos="0.000739 -0.198023 0.230930" size="0.3016512095928192 0.0051789721474051476 0.06386491656303406" quat="1.0 0.0 0.0 0.0"/>
        <geom class="collision" type="box" pos="-0.000559 0.059745 0.243233" size="0.29126429557800293 0.1580100655555725 0.009234687313437462" quat="1.0 0.0 0.0 0.0"/>
        <geom class="collision" type="box" pos="-0.000559 0.016883 0.180336" size="0.29126429557800293 0.20087198913097382 0.05729734152555466" quat="1.0 0.0 0.0 0.0"/>
        <body name="WallStackDoor001">
          <joint axis="1.0 0.0 0.0" pos="-0.000000 -0.200739 -0.281283" limited="true" name="WallStackDoor001_joint" range="0.0 1.5707963267948966" type="hinge" damping="1" frictionloss="1" armature=".01" stiffness="0.05"/>
          <geom mesh="WallStackDoor001_vis" type="mesh" solimp="0.998 0.998 0.001" solref="0.001 1" density="100" friction="0.95 0.3 0.1" class="visual" material="WallStackDoor001_material"/>
          <geom class="collision" type="box" pos="-0.000631 -0.197894 -0.053900" size="0.3020551800727844 0.008825544267892838 0.21300949156284332" quat="1.0 0.0 0.0 0.0"/>
          <geom class="collision" type="box" pos="0.000814 -0.179160 -0.064816" size="0.23558567464351654 0.015448496676981449 0.15735863149166107" quat="1.0 0.0 0.0 0.0"/>
          <geom class="collision" type="box" pos="-0.170618 -0.218124 0.118514" size="0.012437110766768456 0.012890174053609371 0.01561253797262907" quat="1.0 0.0 0.0 0.0"/>
          <geom class="collision" type="box" pos="0.000215 -0.242549 0.119178" size="0.2072993814945221 0.019436176866292953 0.01561255194246769" quat="1.0 0.0 0.0 0.0"/>
          <geom class="collision" type="box" pos="0.171075 -0.218124 0.118514" size="0.012437124736607075 0.01289020199328661 0.015612565912306309" quat="1.0 0.0 0.0 0.0"/>
          <body name="WallStackDoor001_Clear">
            <geom mesh="WallStackDoor001_Clear_vis" type="mesh" solimp="0.998 0.998 0.001" solref="0.001 1" density="100" friction="0.95 0.3 0.1" class="visual" material="WallStackDoor001_Clear_material"/>
            <geom class="collision" type="box" pos="-0.000111 -0.180967 -0.064988" size="0.16974835097789764 0.02312706783413887 0.11725851148366928" quat="1.0 0.0 0.0 0.0"/>
          </body>
        </body>
        <body name="WallStackKnob001">
          <joint axis="0.0 1.0 0.0" pos="-0.189085 -0.209444 0.227153" limited="true" name="WallStackKnob001_joint" range="0.0 5.061454830783556" type="hinge" damping="1" frictionloss="1" armature=".01" stiffness="0.05"/>
          <geom mesh="WallStackKnob001_vis" type="mesh" solimp="0.998 0.998 0.001" solref="0.001 1" density="100" friction="0.95 0.3 0.1" class="visual" material="WallStackKnob001_material"/>
          <geom class="collision" type="cylinder" pos="-0.188605 -0.205155 0.226011" size="0.01806890033185482 0.001686516567133367" quat="0.7071067094802856 0.7071068286895752 0.0 0.0"/>
          <geom class="collision" type="box" pos="-0.188924 -0.213548 0.226717" size="0.008250432088971138 0.006144003476947546 0.014450949616730213" quat="0.9671083092689514 -1.6025834825850183e-10 0.2543649971485138 -5.980698714047605e-10"/>
        </body>
        <body name="WallStackKnob002">
          <joint axis="0.0 -1.0 0.0" pos="0.187437 -0.209444 0.225280" limited="true" name="WallStackKnob002_joint" range="-1.0471975511965976 3.141592653589793" type="hinge" damping="1" frictionloss="1" armature=".01" stiffness="0.05"/>
          <geom mesh="WallStackKnob002_vis" type="mesh" solimp="0.998 0.998 0.001" solref="0.001 1" density="100" friction="0.95 0.3 0.1" class="visual" material="WallStackKnob002_material"/>
          <geom class="collision" type="cylinder" pos="0.187367 -0.205901 0.225033" size="0.017057839781045914 0.0015851097414270043" quat="0.7071067094802856 0.7071068286895752 0.0 0.0"/>
          <geom class="collision" type="box" pos="0.187504 -0.213540 0.225527" size="0.005599156953394413 0.00600207457318902 0.01411654893308878" quat="0.9999803304672241 -9.978440930184947e-16 -0.006273725535720587 -8.42934888556357e-10"/>
        </body>
        <body name="WallStackShelf001">
          <joint axis="0.0 -1.0 0.0" pos="-0.000159 -0.001673 -0.052350" limited="true" name="WallStackShelf001_joint" range="0.0 0.23" type="slide" damping="1" frictionloss="1" armature=".01" stiffness="0.05"/>
          <geom mesh="WallStackShelf001_vis" type="mesh" solimp="0.998 0.998 0.001" solref="0.001 1" density="100" friction="0.95 0.3 0.1" class="visual" material="WallStackShelf001_material"/>
          <geom class="collision" type="box" pos="0.000766 0.013277 -0.051562" size="0.22974561154842377 0.11763344705104828 0.004281292669475079" quat="1.0 0.0 0.0 0.0"/>
          <geom class="collision" type="box" pos="-0.232801 0.013277 -0.055469" size="0.003588530234992504 0.11763344705104828 0.008187798783183098" quat="1.0 0.0 0.0 0.0"/>
          <geom class="collision" type="box" pos="-0.240010 0.013277 -0.062678" size="0.009428150951862335 0.11763344705104828 0.003153639379888773" quat="1.0 0.0 0.0 0.0"/>
          <geom class="collision" type="box" pos="0.240862 0.013277 -0.062678" size="0.009428150951862335 0.11763344705104828 0.003153639379888773" quat="1.0 0.0 0.0 0.0"/>
          <geom class="collision" type="box" pos="0.233653 0.013277 -0.055469" size="0.003588530234992504 0.11763344705104828 0.008187798783183098" quat="1.0 0.0 0.0 0.0"/>
          <geom class="collision" type="box" pos="-0.000455 0.126780 -0.034183" size="0.13294032216072083 0.0013344165636226535 0.001764212385751307" quat="1.0 0.0 0.0 0.0"/>
          <geom class="collision" type="box" pos="0.131426 0.126780 -0.042405" size="0.0010602232068777084 0.0013344165636226535 0.00998667348176241" quat="1.0 0.0 0.0 0.0"/>
          <geom class="collision" type="box" pos="-0.132655 0.126780 -0.042405" size="0.0010602232068777084 0.0013344165636226535 0.00998667348176241" quat="1.0 0.0 0.0 0.0"/>
        </body>
      </body>
    </body>
  </worldbody>
  <actuator>
    <motor name="WallStackDoor001_joint_actuator" joint="WallStackDoor001_joint" gear="45"/>
    <motor name="WallStackKnob001_joint_actuator" joint="WallStackKnob001_joint" gear="10"/>
    <motor name="WallStackKnob002_joint_actuator" joint="WallStackKnob002_joint" gear="10"/>
    <motor name="WallStackShelf001_joint_actuator" joint="WallStackShelf001_joint" gear="10"/>
  </actuator>
</mujoco>