<mujoco model="model">
  <compiler angle="radian"/>
  <asset>
    <mesh file="visuals/knob_front_left.obj" name="knob_front_left_vis"/>
    <mesh file="visuals/knob_front_right.obj" name="knob_front_right_vis"/>
    <mesh file="visuals/knob_rear_left.obj" name="knob_rear_left_vis"/>
    <mesh file="visuals/knob_rear_right.obj" name="knob_rear_right_vis"/>
    <mesh file="visuals/Body001.obj" name="Body001_vis"/>
    <mesh file="visuals/Door001.obj" name="Door001_vis"/>
    <mesh file="visuals/Door001_Clear.obj" name="Door001_Clear_vis"/>
    <mesh file="visuals/Knob001.obj" name="Knob001_vis"/>
    <mesh file="visuals/Knob002.obj" name="Knob002_vis"/>
    <mesh file="visuals/Shelf001.obj" name="Shelf001_vis"/>
    <texture file="visuals/T_BC001.png" name="Body001_material" type="2d"/>
    <material name="Body001_material" rgba="1 1 1 1.0" texture="Body001_material" shininess="0.5" specular="0.5"/>
    <texture file="visuals/T_BC001.png" name="knob_front_left_material" type="2d"/>
    <material name="knob_front_left_material" rgba="1 1 1 1.0" texture="knob_front_left_material" shininess="0.5" specular="0.5"/>
    <texture file="visuals/T_BC001.png" name="knob_front_right_material" type="2d"/>
    <material name="knob_front_right_material" rgba="1 1 1 1.0" texture="knob_front_right_material" shininess="0.5" specular="0.5"/>
    <texture file="visuals/T_BC001.png" name="knob_rear_left_material" type="2d"/>
    <material name="knob_rear_left_material" rgba="1 1 1 1.0" texture="knob_rear_left_material" shininess="0.5" specular="0.5"/>
    <texture file="visuals/T_BC001.png" name="knob_rear_right_material" type="2d"/>
    <material name="knob_rear_right_material" rgba="1 1 1 1.0" texture="knob_rear_right_material" shininess="0.5" specular="0.5"/>
    <texture file="visuals/T_BC001.png" name="Door001_material" type="2d"/>
    <material name="Door001_material" rgba="1 1 1 1.0" texture="Door001_material" shininess="0.5" specular="0.5"/>
    <material name="Door001_Clear_material" rgba="0.057965464890003204 0.057965464890003204 0.057965464890003204 0.5" shininess="0.5962963700294495" specular="0.3103448502657381"/>
    <texture file="visuals/T_BC001.png" name="Knob001_material" type="2d"/>
    <material name="Knob001_material" rgba="1 1 1 1.0" texture="Knob001_material" shininess="0.5" specular="0.5"/>
    <texture file="visuals/T_BC001.png" name="Knob002_material" type="2d"/>
    <material name="Knob002_material" rgba="1 1 1 1.0" texture="Knob002_material" shininess="0.5" specular="0.5"/>
    <texture file="visuals/T_BC001.png" name="Shelf001_material" type="2d"/>
    <material name="Shelf001_material" rgba="1 1 1 1.0" texture="Shelf001_material" shininess="5" specular="5"/>
  </asset>
  <default>
    <default class="visual">
      <geom conaffinity="0" contype="0" group="1" type="mesh"/>
    </default>
    <default class="collision">
      <geom group="0" rgba="0.5 0 0 0.5"/>
    </default>
    <default class="spawn">
      <geom group="0" rgba="1 1 1 0.5" contype="0" conaffinity="0"/>
      <site group="0" rgba="1 1 1 0.5"/>
    </default>
    <default class="region">
      <geom group="1" conaffinity="0" contype="0" rgba="0 1 0 0"/>
    </default>
  </default>
  <worldbody>
    <body>
      <body name="object">
        <site type="cylinder" rgba="0 0 0.5 0.5" size="0.04923228919506073 0.009015648625791073" pos="-0.151201 -0.101681 0.125475" name="burner_on_front_left"/>
        <site type="cylinder" rgba="0 0 0.5 0.5" size="0.054413504898548126 0.008982528932392597" pos="0.161553 -0.103124 0.126011" name="burner_on_front_right"/>
        <site type="cylinder" rgba="0 0 0.5 0.5" size="0.041091740131378174 0.007806722540408373" pos="-0.148013 0.189980 0.126344" name="burner_on_rear_left"/>
        <site type="cylinder" rgba="0 0 0.5 0.5" size="0.052774783223867416 0.008349708281457424" pos="0.159633 0.191040 0.126691" name="burner_on_rear_right"/>
        <geom mesh="Body001_vis" type="mesh" solimp="0.998 0.998 0.001" solref="0.001 1" density="100" friction="0.95 0.3 0.1" class="visual" material="Body001_material"/>
        <geom class="collision" type="box" pos="0.001034 0.048281 -0.715015" size="0.4179702401161194 0.35472604632377625 0.07913621515035629" quat="1.0 0.0 0.0 0.0"/>
        <geom class="collision" type="box" pos="-0.001699 0.182819 0.759698" size="0.416999876499176 0.19425749778747559 0.02711104415357113" quat="1.0 0.0 0.0 0.0"/>
        <geom class="collision" type="box" pos="0.000883 -0.292789 0.009567" size="0.41463369131088257 0.018988171592354774 0.06398320198059082" quat="1.0 0.0 0.0 0.0"/>
        <geom class="collision" type="box" pos="-0.001385 0.051873 0.130396" size="0.39315736293792725 0.3247698247432709 0.015574473887681961" quat="1.0 0.0 0.0 0.0"/>
        <geom class="collision" type="box" pos="-0.405270 0.050001 -0.259757" size="0.012374521233141422 0.3246512711048126 0.3758624792098999" quat="1.0 0.0 0.0 0.0"/>
        <geom class="collision" type="box" pos="-0.000612 0.388223 0.079385" size="0.41839247941970825 0.013863617554306984 0.7147662043571472" quat="1.0 0.0 0.0 0.0"/>
        <geom class="collision" type="box" pos="0.000895 -0.314689 0.094924" size="0.4154462516307831 0.03909111022949219 0.021578671410679817" quat="1.0 0.0 0.0 0.0"/>
        <geom class="collision" type="box" pos="0.000895 -0.300493 -0.064270" size="0.4154462516307831 0.024894749745726585 0.011899186298251152" quat="1.0 0.0 0.0 0.0"/>
        <geom class="collision" type="box" pos="0.403476 0.050001 -0.259757" size="0.012374521233141422 0.32464995980262756 0.3758624792098999" quat="1.0 0.0 0.0 0.0"/>
        <body name="knob_front_left">
          <joint axis="0.0 -1.0 0.0" pos="-0.290989 -0.322028 0.002405" limited="true" name="knob_front_left_joint" range="0.0 3.6651914291880923" type="hinge" damping="0.05" armature="0.001" springref="-0.1"/>
          <geom mesh="knob_front_left_vis" type="mesh" solimp="0.998 0.998 0.001" solref="0.001 1" density="100" friction="0.95 0.3 0.1" class="visual" material="knob_front_left_material"/>
          <geom class="collision" type="cylinder" pos="-0.291072 -0.322987 0.002297" size="0.019701987504959106 0.010508212260901928" quat="0.7071067094802856 0.70710688829422 0.0 0.0"/>
          <geom class="collision" type="box" pos="-0.291087 -0.322519 0.024488" size="0.00182760925963521 0.007352376356720924 0.002636598888784647" quat="1.0 0.0 0.0 0.0"/>
        </body>
        <body name="knob_front_right">
          <joint axis="0.0 -1.0 0.0" pos="0.298339 -0.322028 0.002405" limited="true" name="knob_front_right_joint" range="0.0 3.6651914291880923" type="hinge" damping="0.05" armature="0.001" springref="-0.1"/>
          <geom mesh="knob_front_right_vis" type="mesh" solimp="0.998 0.998 0.001" solref="0.001 1" density="100" friction="0.95 0.3 0.1" class="visual" material="knob_front_right_material"/>
          <geom class="collision" type="cylinder" pos="0.298261 -0.322987 0.002297" size="0.019701987504959106 0.010508212260901928" quat="0.7071067094802856 0.70710688829422 0.0 0.0"/>
          <geom class="collision" type="box" pos="0.298245 -0.322519 0.024488" size="0.0018276103073731065 0.007352382875978947 0.002636598888784647" quat="1.0 0.0 0.0 0.0"/>
        </body>
        <body name="knob_rear_left">
          <joint axis="0.0 -1.0 0.0" pos="-0.179142 -0.322028 0.002405" limited="true" name="knob_rear_left_joint" range="0.0 3.6651914291880923" type="hinge" damping="0.05" armature="0.001" springref="-0.1"/>
          <geom mesh="knob_rear_left_vis" type="mesh" solimp="0.998 0.998 0.001" solref="0.001 1" density="100" friction="0.95 0.3 0.1" class="visual" material="knob_rear_left_material"/>
          <geom class="collision" type="cylinder" pos="-0.179223 -0.322987 0.002297" size="0.019701987504959106 0.010508212260901928" quat="0.7071067094802856 0.70710688829422 0.0 0.0"/>
          <geom class="collision" type="box" pos="-0.179238 -0.322519 0.024488" size="0.0018276087939739227 0.007352373097091913 0.002636598888784647" quat="1.0 0.0 0.0 0.0"/>
        </body>
        <body name="knob_rear_right">
          <joint axis="0.0 -1.0 0.0" pos="0.186492 -0.322028 0.002405" limited="true" name="knob_rear_right_joint" range="0.0 3.6651914291880923" type="hinge" damping="0.05" armature="0.001" springref="-0.1"/>
          <geom mesh="knob_rear_right_vis" type="mesh" solimp="0.998 0.998 0.001" solref="0.001 1" density="100" friction="0.95 0.3 0.1" class="visual" material="knob_rear_right_material"/>
          <geom class="collision" type="cylinder" pos="0.186412 -0.322987 0.002297" size="0.019701987504959106 0.010508212260901928" quat="0.7071067094802856 0.70710688829422 0.0 0.0"/>
          <geom class="collision" type="box" pos="0.186396 -0.322519 0.024488" size="0.0018276098417118192 0.0073523796163499355 0.002636598888784647" quat="1.0 0.0 0.0 0.0"/>
        </body>
        <body name="Door001">
          <joint axis="1.0 -9.906870881306695e-18 6.558495377762262e-17" pos="0.006183 -0.303008 -0.622111" limited="true" name="Door001_joint" range="0.0 1.5707963267948966" type="hinge" damping="1" frictionloss="1" armature=".01" stiffness="0.05"/>
          <geom mesh="Door001_vis" type="mesh" solimp="0.998 0.998 0.001" solref="0.001 1" density="100" friction="0.95 0.3 0.1" class="visual" material="Door001_material"/>
          <geom class="collision" type="box" pos="0.007498 -0.292237 -0.350157" size="0.40987834334373474 0.015568030066788197 0.2727501690387726" quat="1.0 0.0 0.0 0.0"/>
          <geom class="collision" type="box" pos="0.394811 -0.355041 -0.124837" size="0.017010247334837914 0.047742169350385666 0.023835355415940285" quat="0.9817447066307068 0.19020332396030426 1.885513952151855e-18 -3.484357192687612e-19"/>
          <geom class="collision" type="cylinder" pos="0.002925 -0.380943 -0.133391" size="0.017841864377260208 0.39096418023109436" quat="0.7071068286895752 -0.0 0.7071067690849304 0.0"/>
          <geom class="collision" type="box" pos="-0.383340 -0.351295 -0.122890" size="0.015407290309667587 0.05012974515557289 0.023835357278585434" quat="0.981132447719574 0.19333681464195251 1.630949532228967e-17 -2.4072798370107567e-18"/>
          <body name="Door001_Clear">
            <geom mesh="Door001_Clear_vis" type="mesh" solimp="0.998 0.998 0.001" solref="0.001 1" density="100" friction="0.95 0.3 0.1" class="visual" material="Door001_Clear_material"/>
            <geom class="collision" type="box" pos="0.008937 -0.292229 -0.305143" size="0.31197333335876465 0.01420478243380785 0.14276017248630524" quat="1.0 0.0 0.0 0.0"/>
          </body>
        </body>
        <body name="Knob001">
          <joint axis="0.0 1.0 0.0" pos="-0.035881 -0.322028 0.003875" limited="true" name="Knob001_joint" range="0.0 5.235987755982989" type="hinge" damping="0.05" armature="0.001" springref="-0.1"/>
          <geom mesh="Knob001_vis" type="mesh" solimp="0.998 0.998 0.001" solref="0.001 1" density="100" friction="0.95 0.3 0.1" class="visual" material="Knob001_material"/>
          <geom class="collision" type="cylinder" pos="-0.035761 -0.322987 0.003932" size="0.019701987504959106 0.010508212260901928" quat="0.7071067094802856 0.70710688829422 0.0 0.0"/>
          <geom class="collision" type="box" pos="-0.057913 -0.322519 0.003779" size="0.002636593533679843 0.007352386135607958 0.001827614614740014" quat="1.0 0.0 0.0 0.0"/>
        </body>
        <body name="Knob002">
          <joint axis="0.0 1.0 0.0" pos="0.070457 -0.322028 0.002405" limited="true" name="Knob002_joint" range="0.0 5.602506898901798" type="hinge" damping="0.05" armature="0.001" springref="-0.1"/>
          <geom mesh="Knob002_vis" type="mesh" solimp="0.998 0.998 0.001" solref="0.001 1" density="100" friction="0.95 0.3 0.1" class="visual" material="Knob002_material"/>
          <geom class="collision" type="cylinder" pos="0.070350 -0.322987 0.002297" size="0.019701987504959106 0.010508212260901928" quat="0.7071067094802856 0.70710688829422 0.0 0.0"/>
          <geom class="collision" type="box" pos="0.070334 -0.322519 -0.019599" size="0.001827611355111003 0.007352389395236969 0.002636598888784647" quat="1.0 0.0 0.0 0.0"/>
        </body>
        <body name="Shelf001">
          <joint axis="0.0 -1.0 0.0" pos="0.007324 0.052306 -0.304161" limited="true" name="Shelf001_joint" range="0.0 0.45" type="slide" damping="1" frictionloss="1" armature=".01" stiffness="0.05"/>
          <geom mesh="Shelf001_vis" type="mesh" solimp="0.998 0.998 0.001" solref="0.001 1" density="100" friction="0.95 0.3 0.1" class="visual" material="Shelf001_material"/>
          <geom class="collision" type="box" pos="0.007767 0.052451 -0.304247" size="0.36205050349235535 0.3125622570514679 0.006199238821864128" quat="1.0 0.0 0.0 0.0"/>
        </body>
        <geom class="region" name="reg_main" type="box" pos="-0.0014344999999999775 0.039354500000000014 -0.3352135" size="0.4166115 0.3624865 0.4552645"/>
        <geom class="region" name="reg_int" type="box" pos="0.00039500000000000646 0.050374500000000016 -0.351001" size="0.388097 0.3226605 0.27327199999999996"/>
      </body>
    </body>
  </worldbody>
  <actuator>
    <motor name="knob_front_left_joint_actuator" joint="knob_front_left_joint" gear="10"/>
    <motor name="knob_front_right_joint_actuator" joint="knob_front_right_joint" gear="10"/>
    <motor name="knob_rear_left_joint_actuator" joint="knob_rear_left_joint" gear="10"/>
    <motor name="knob_rear_right_joint_actuator" joint="knob_rear_right_joint" gear="10"/>
    <motor name="Door001_joint_actuator" joint="Door001_joint" gear="70"/>
    <motor name="Knob001_joint_actuator" joint="Knob001_joint" gear="50"/>
    <motor name="Knob002_joint_actuator" joint="Knob002_joint" gear="50"/>
    <motor name="Shelf001_joint_actuator" joint="Shelf001_joint" gear="50"/>
  </actuator>
</mujoco>
