<?xml version='1.0' encoding='UTF-8'?>
<mujoco model="model">
  <compiler angle="radian"/>
  <asset>
    <mesh file="visuals/Body001.obj" name="Body001_vis"/>
    <mesh file="visuals/Button001.obj" name="Button001_vis"/>
    <mesh file="visuals/Container001_Clear.obj" name="Container001_Clear_vis"/>
    <mesh file="visuals/Container002_Clear.obj" name="Container002_Clear_vis"/>
    <mesh file="visuals/Lever001.obj" name="Lever001_vis"/>
    <mesh file="visuals/Lever002.obj" name="Lever002_vis"/>
    <mesh file="visuals/Lid001.obj" name="Lid001_vis"/>
    <mesh file="visuals/Lid002.obj" name="Lid002_vis"/>
    <mesh file="visuals/Lid003.obj" name="Lid003_vis"/>
    <texture file="visuals/T_BC001.png" name="Body001_material" type="2d"/>
    <material name="Body001_material" rgba="1 1 1 1.0" texture="Body001_material" shininess="0.141421377658844" specular="0.3103448502657381"/>
    <texture file="visuals/T_BC001.png" name="Button001_material" type="2d"/>
    <material name="Button001_material" rgba="1 1 1 1.0" texture="Button001_material" shininess="0.141421377658844" specular="0.3103448502657381"/>
    <texture file="visuals/T_BC001.png" name="Container001_Clear_material" type="2d"/>
    <material name="Container001_Clear_material" rgba="1 1 1 0.15544039011001587" texture="Container001_Clear_material" shininess="0.141421377658844" specular="0.3103448502657381"/>
    <texture file="visuals/T_BC001.png" name="Lid003_material" type="2d"/>
    <material name="Lid003_material" rgba="1 1 1 1.0" texture="Lid003_material" shininess="0.141421377658844" specular="0.3103448502657381"/>
    <texture file="visuals/T_BC001.png" name="Container002_Clear_material" type="2d"/>
    <material name="Container002_Clear_material" rgba="1 1 1 0.15544039011001587" texture="Container002_Clear_material" shininess="0.141421377658844" specular="0.3103448502657381"/>
    <texture file="visuals/T_BC001.png" name="Lid002_material" type="2d"/>
    <material name="Lid002_material" rgba="1 1 1 1.0" texture="Lid002_material" shininess="0.141421377658844" specular="0.3103448502657381"/>
    <texture file="visuals/T_BC001.png" name="Lever001_material" type="2d"/>
    <material name="Lever001_material" rgba="1 1 1 1.0" texture="Lever001_material" shininess="0.141421377658844" specular="0.3103448502657381"/>
    <texture file="visuals/T_BC001.png" name="Lever002_material" type="2d"/>
    <material name="Lever002_material" rgba="1 1 1 1.0" texture="Lever002_material" shininess="0.141421377658844" specular="0.3103448502657381"/>
    <texture file="visuals/T_BC001.png" name="Lid001_material" type="2d"/>
    <material name="Lid001_material" rgba="1 1 1 1.0" texture="Lid001_material" shininess="0.141421377658844" specular="0.3103448502657381"/>
  </asset>
  <default>
    <default class="visual">
      <geom conaffinity="0" contype="0" group="1" type="mesh"/>
    </default>
    <default class="collision">
      <geom group="0" rgba="0.5 0 0 0.5"/>
    </default>
    <default class="spawn">
      <geom group="0" rgba="1 1 1 0.5" contype="0" conaffinity="0"/>
      <site group="0" rgba="1 1 1 0.5"/>
    </default>
    <default class="region">
      <geom group="1" conaffinity="0" contype="0" rgba="0 1 0 0"/>
    </default>
  </default>
  <worldbody>
    <body>
      <body name="object">
        <geom class="collision" type="box" pos="-0.09953698515892029 -0.09205584973096848 0.09219466149806976" size="0.010266819968819618 0.010266819968819618 0.0010093714809045196" quat="0.8337666988372803 0.5521169304847717 0.0 0.0" name="start_button" rgba="0.0 0.5 0 0.5"/>
        <site type="cylinder" rgba="0.8 0.5 0.25 1" size="0.002370622009038925 0.07503831386566162" pos="0.05007607862353325 -0.045918501913547516 -0.09016136080026627" name="coffee_liquid"/>
        <site rgba="0 0 0 0" size="0.009999999776482582 0.009999999776482582" pos="0.05007607862353325 -0.045918501913547516 -0.15159223973751068" name="receptacle_place_site"/>
        <geom mesh="Body001_vis" type="mesh" solimp="0.998 0.998 0.001" solref="0.001 1" density="100" friction="0.95 0.3 0.1" class="visual" material="Body001_material"/>
        <geom class="collision" type="box" pos="0.004251586273312569 0.034905076026916504 0.09054994583129883" size="0.15010659396648407 0.10419394820928574 0.046176742762327194" quat="1.0 0.0 0.0 0.0"/>
        <geom class="collision" type="box" pos="0.004251586273312569 0.08353205025196075 -0.07729153335094452" size="0.15010659396648407 0.055566973984241486 0.1236661747097969" quat="1.0 0.0 0.0 0.0"/>
        <geom class="collision" type="box" pos="0.004251586273312569 -0.037617094814777374 -0.18301598727703094" size="0.15010659396648407 0.07883471995592117 0.01794171705842018" quat="1.0 0.0 0.0 0.0"/>
        <geom class="collision" type="box" pos="0.004251586273312569 -0.0678786039352417 0.08943219482898712" size="0.15010659396648407 0.04236120730638504 0.015518431551754475" quat="0.8273626565933228 0.5616680979728699 0.0 0.0"/>
        <geom class="collision" type="box" pos="0.00463740061968565 -0.08949065953493118 0.04157225042581558" size="0.07325221598148346 0.01568031497299671 0.01794171892106533" quat="0.8273626565933228 0.5616680979728699 0.0 0.0"/>
        <geom class="collision" type="box" pos="0.0017035852652043104 -0.02856498211622238 0.03591998293995857" size="0.10334555804729462 0.056058935821056366 0.015401296317577362" quat="1.0 0.0 0.0 0.0"/>
        <geom class="collision" type="cylinder" pos="-0.033732231706380844 -0.03381001949310303 -0.010906064882874489" size="0.03773859143257141 0.03150390461087227" quat="1.0 0.0 0.0 0.0"/>
        <body name="Button001">
          <joint axis="0.0 0.9308611154556274 -0.36537331342697144" pos="-0.09953698515892029 -0.09081856161355972 0.09167009592056274" limited="true" name="Button001_joint" range="0.0 0.005" type="slide" damping="1" frictionloss="1" armature=".01" stiffness="0.2" springref="-0.1"/>
          <geom mesh="Button001_vis" type="mesh" solimp="0.998 0.998 0.001" solref="0.001 1" density="100" friction="0.95 0.3 0.1" class="visual" material="Button001_material"/>
          <geom class="collision" type="cylinder" pos="-0.09953698515892029 -0.08958203345537186 0.09114585071802139" size="0.010266819968819618 0.0010093714809045196" quat="0.8337666988372803 0.5521169304847717 0.0 0.0"/>
        </body>
        <body name="Container001_Clear">
          <joint axis="0.0 0.0 1.0" pos="0.003773098811507225 0.16324551403522491 -0.03832846134901047" limited="true" name="Container001_Clear_joint" range="0.0 0.1" type="slide" damping="1" frictionloss="1" armature=".01" stiffness="0.05"/>
          <geom mesh="Container001_Clear_vis" type="mesh" solimp="0.998 0.998 0.001" solref="0.001 1" density="100" friction="0.95 0.3 0.1" class="visual" material="Container001_Clear_material"/>
          <geom class="collision" type="box" pos="0.0032774843275547028 0.16226056218147278 -0.1977800577878952" size="0.1496579796075821 0.022839296609163284 0.003091417020186782" quat="1.0 0.0 0.0 0.0"/>
          <geom class="collision" type="box" pos="0.002547665499150753 0.18423816561698914 -0.03855401650071144" size="0.1493503749370575 0.0021811395417898893 0.16255491971969604" quat="1.0 0.0 0.0 0.0"/>
          <geom class="collision" type="box" pos="0.002547665499150753 0.14226122200489044 -0.03855401650071144" size="0.1493503749370575 0.0021811395417898893 0.16255491971969604" quat="1.0 0.0 0.0 0.0"/>
          <geom class="collision" type="box" pos="-0.14540432393550873 0.16110016405582428 -0.03855401277542114" size="0.0013983910903334618 0.021367941051721573 0.16255491971969604" quat="1.0 0.0 0.0 0.0"/>
          <geom class="collision" type="box" pos="0.15145157277584076 0.16110016405582428 -0.03855401277542114" size="0.0013983910903334618 0.021367941051721573 0.16255491971969604" quat="1.0 0.0 0.0 0.0"/>
          <body name="Lid003">
            <joint axis="0.0 0.0 1.0" pos="0.003773130476474762 0.16366788744926453 0.13069534301757812" limited="true" name="Lid003_joint" range="0.0 0.1" type="slide" damping="1" frictionloss="1" armature=".01" stiffness="0.05"/>
            <geom mesh="Lid003_vis" type="mesh" solimp="0.998 0.998 0.001" solref="0.001 1" density="100" friction="0.95 0.3 0.1" class="visual" material="Lid003_material"/>
            <geom class="collision" type="box" pos="0.0032774843275547028 0.16388192772865295 0.1311011165380478" size="0.1496579796075821 0.023143304511904716 0.006692893337458372" quat="1.0 0.0 0.0 0.0"/>
          </body>
        </body>
        <body name="Container002_Clear">
          <geom mesh="Container002_Clear_vis" type="mesh" solimp="0.998 0.998 0.001" solref="0.001 1" density="100" friction="0.95 0.3 0.1" class="visual" material="Container002_Clear_material"/>
          <geom class="collision" type="box" pos="-0.06037981063127518 -0.00711560994386673 0.1750819832086563" size="0.017435021698474884 0.0018557803705334663 0.011379191651940346" quat="1.0 0.0 0.0 0.0"/>
          <geom class="collision" type="box" pos="-0.06037980690598488 0.008043576963245869 0.15212053060531616" size="0.017435021698474884 0.0018557804869487882 0.019665980711579323" quat="0.8987211585044861 0.4385205805301666 0.0 0.0"/>
          <geom class="collision" type="box" pos="-0.09274667501449585 0.0019253119826316833 0.1750819832086563" size="0.017435021698474884 0.0018557803705334663 0.011379191651940346" quat="0.968171238899231 0.0 -0.0 -0.25028878450393677"/>
          <geom class="collision" type="box" pos="-0.08539984375238419 0.015185226686298847 0.15212053060531616" size="0.017435021698474884 0.0018557803705334663 0.019665978848934174" quat="0.8701158761978149 0.42456310987472534 -0.10975683480501175 -0.22493986785411835"/>
          <geom class="collision" type="box" pos="-0.10385355353355408 0.03360801935195923 0.15212053060531616" size="0.017435021698474884 0.0018557803705334663 0.019665978848934174" quat="0.7858774662017822 0.38345980644226074 -0.21274130046367645 -0.4360003173351288"/>
          <geom class="collision" type="box" pos="-0.11671523749828339 0.025584418326616287 0.1750819832086563" size="0.017435021698474884 0.0018557803705334663 0.011379191651940346" quat="0.8744396567344666 0.0 -0.0 -0.4851342439651489"/>
          <geom class="collision" type="box" pos="-0.12619364261627197 0.058469947427511215 0.1750819832086563" size="0.017435021698474884 0.0018557803705334663 0.011379191651940346" quat="0.7218979597091675 0.0 -0.0 -0.6919995546340942"/>
          <geom class="collision" type="box" pos="-0.11104800552129745 0.059110771864652634 0.15212053060531616" size="0.017435021698474884 0.0018557803705334663 0.019665978848934174" quat="0.6487849354743958 0.3165670931339264 -0.30345603823661804 -0.6219146251678467"/>
          <geom class="collision" type="box" pos="-0.1189955547451973 0.09028405696153641 0.1750819832086563" size="0.017435023561120033 0.0018557803705334663 0.011379191651940346" quat="0.5321621298789978 0.0 -0.0 -0.8466424942016602"/>
          <geom class="collision" type="box" pos="-0.10533557832241058 0.0837109237909317 0.15212053060531616" size="0.017435023561120033 0.0018557803705334663 0.019665978848934174" quat="0.4782653748989105 0.2333640456199646 -0.37127014994621277 -0.7608954906463623"/>
          <geom class="collision" type="box" pos="-0.08834408223628998 0.10296188294887543 0.15212053060531616" size="0.017435021698474884 0.0018557803705334663 0.019665980711579323" quat="0.27550870180130005 0.13443127274513245 -0.41740691661834717 -0.8554499745368958"/>
          <geom class="collision" type="box" pos="-0.09719087183475494 0.11527185142040253 0.1750819832086563" size="0.017435021698474884 0.0018557803705334663 0.011379191651940346" quat="0.30655637383461 0.0 -0.0 -0.9518525004386902"/>
          <geom class="collision" type="box" pos="0.007320038974285126 0.06992585957050323 0.1750819832086563" size="0.017435021698474884 0.0018557802541181445 0.011379191651940346" quat="0.6453961730003357 0.0 0.0 0.7638480067253113"/>
          <geom class="collision" type="box" pos="-0.007626452017575502 0.06739538162946701 0.15212053060531616" size="0.017435021698474884 0.0018557803705334663 0.019665978848934174" quat="0.5800312161445618 0.2830195128917694 0.3349630534648895 0.6864863634109497"/>
          <geom class="collision" type="box" pos="-0.017441436648368835 0.09112250804901123 0.15212053060531616" size="0.017435021698474884 0.0018557803705334663 0.019665980711579323" quat="0.39250025153160095 0.1915159523487091 0.39448946714401245 0.8084820508956909"/>
          <geom class="collision" type="box" pos="-0.005529932677745819 0.10049891471862793 0.1750819832086563" size="0.017435021698474884 0.0018557803705334663 0.011379191651940346" quat="0.4367319643497467 0.0 0.0 0.8995916843414307"/>
          <geom class="collision" type="box" pos="-0.03702148422598839 0.1070730984210968 0.15212053060531616" size="0.017435021698474884 0.0018557803705334663 0.019665980711579323" quat="0.1843346804380417 0.08994396775960922 0.42919737100601196 0.8796138167381287"/>
          <geom class="collision" type="box" pos="-0.030935153365135193 0.12095680832862854 0.1750819832086563" size="0.017435021698474884 0.0018557803705334663 0.011379191651940346" quat="0.20510774850845337 0.0 0.0 0.9787393808364868"/>
          <geom class="collision" type="box" pos="-0.06463778018951416 0.1269092857837677 0.1750819832086563" size="0.017435021698474884 0.0018557803705334663 0.011379191651940346" quat="0.0511426217854023 0.0 -0.0 -0.9986913800239563"/>
          <geom class="collision" type="box" pos="-0.06308925151824951 0.11182938516139984 0.15212053060531616" size="0.017435021698474884 0.0018557803705334663 0.019665980711579323" quat="0.04596295580267906 0.022427091374993324 -0.43794670701026917 -0.8975450396537781"/>
          <geom class="collision" type="box" pos="0.0033419467508792877 0.03529047966003418 0.1750819832086563" size="0.017435021698474884 0.0018557803705334663 0.011379191651940346" quat="0.8215954899787903 0.0 0.0 0.5700708627700806"/>
          <geom class="collision" type="box" pos="-0.010858201421797276 0.04059678316116333 0.15212053060531616" size="0.017435023561120033 0.0018557804869487882 0.019665980711579323" quat="0.7383853197097778 0.36028656363487244 0.24998779594898224 0.5123347043991089"/>
          <geom class="collision" type="box" pos="-0.0260324627161026 0.01988321542739868 0.15212053060531616" size="0.017435021698474884 0.0018557803705334663 0.019665978848934174" quat="0.8420522212982178 0.41086962819099426 0.15325286984443665 0.31408241391181946"/>
          <geom class="collision" type="box" pos="-0.01610499620437622 0.008426930755376816 0.1750819832086563" size="0.017435021698474884 0.0018557803705334663 0.011379191651940346" quat="0.9369449019432068 0.0 0.0 0.3494771122932434"/>
          <geom class="collision" type="box" pos="-0.038939040154218674 -0.0040366798639297485 0.1750819832086563" size="0.017435021698474884 0.0018557803705334663 0.011379191651940346" quat="0.9869014620780945 0.0 0.0 0.16132423281669617"/>
          <geom class="collision" type="box" pos="-0.04376605898141861 0.010333460755646229 0.15212053060531616" size="0.017435021698474884 0.0018557804869487882 0.019665978848934174" quat="0.8869492411613464 0.4327766001224518 0.07074397802352905 0.14498546719551086"/>
          <body name="Lid002">
            <joint axis="0.0 0.0 1.0" pos="-0.05907779559493065 0.06000583991408348 0.19072727859020233" limited="true" name="Lid002_joint" range="0.0 0.1" type="slide" damping="1" frictionloss="1" armature=".01" stiffness="0.05"/>
            <geom mesh="Lid002_vis" type="mesh" solimp="0.998 0.998 0.001" solref="0.001 1" density="100" friction="0.95 0.3 0.1" class="visual" material="Lid002_material"/>
            <geom class="collision" type="cylinder" pos="-0.05907779559493065 0.06000583991408348 0.1941232532262802" size="0.06853549182415009 0.007018524222075939" quat="1.0 0.0 0.0 0.0"/>
          </body>
        </body>
        <body name="Lever001">
          <joint axis="0.0 0.0 -1.0" pos="0.05020756274461746 -0.043985456228256226 0.022376716136932373" limited="true" name="Lever001_joint" range="0.0 1.0471975511965976" type="hinge" damping="1" frictionloss="1" armature=".01" stiffness="0.005"/>
          <geom mesh="Lever001_vis" type="mesh" solimp="0.998 0.998 0.001" solref="0.001 1" density="100" friction="0.95 0.3 0.1" class="visual" material="Lever001_material"/>
          <geom class="collision" type="cylinder" pos="0.05089174583554268 -0.04380524531006813 0.010718117468059063" size="0.038811095058918 0.006614522077143192" quat="1.0 0.0 0.0 0.0"/>
          <geom class="collision" type="cylinder" pos="0.05089174583554268 -0.04380524531006813 -0.0031957211904227734" size="0.032877806574106216 0.008945344015955925" quat="1.0 0.0 0.0 0.0"/>
          <geom class="collision" type="cylinder" pos="0.05028968304395676 -0.11444319039583206 -0.004454403184354305" size="0.009046882390975952 0.040013495832681656" quat="0.7071068286895752 -0.7071067690849304 -0.0 0.0"/>
          <geom class="collision" type="cylinder" pos="0.05028968304395676 -0.17021813988685608 -0.00445440411567688" size="0.011497272178530693 0.016860052943229675" quat="0.7071068286895752 -0.7071067690849304 -0.0 0.0"/>
        </body>
        <body name="Lever002">
          <joint axis="0.0 0.0 1.0" pos="0.11731132119894028 -0.011771619319915771 0.049101654440164566" limited="true" name="Lever002_joint" range="0.0 1.5707963267948966" type="hinge" damping="1" frictionloss="1" armature=".01" stiffness="0.005"/>
          <geom mesh="Lever002_vis" type="mesh" solimp="0.998 0.998 0.001" solref="0.001 1" density="100" friction="0.95 0.3 0.1" class="visual" material="Lever002_material"/>
          <geom class="collision" type="cylinder" pos="0.11736256629228592 -0.015233302488923073 0.01655789650976658" size="0.005837130825966597 0.02365570142865181" quat="0.9987954497337341 -0.04906829446554184 -0.0 0.0"/>
          <geom class="collision" type="cylinder" pos="0.11736256629228592 -0.02131441980600357 -0.012592257000505924" size="0.005837130825966597 0.010007442906498909" quat="0.9347220063209534 -0.3553798198699951 -0.0 0.0"/>
          <geom class="collision" type="cylinder" pos="0.11736256629228592 -0.04497971758246422 -0.024970028549432755" size="0.0058371322229504585 0.020111531019210815" quat="0.8053956031799316 -0.59273761510849 -0.0 0.0"/>
          <geom class="collision" type="cylinder" pos="0.11736256629228592 -0.07150457799434662 -0.037982307374477386" size="0.005837131291627884 0.012467369437217712" quat="0.9569002389907837 -0.2904168367385864 -0.0 0.0"/>
          <geom class="collision" type="cylinder" pos="0.11721059679985046 -0.08042599260807037 -0.07792060077190399" size="0.005837130825966597 0.03408563509583473" quat="0.9979275465011597 -0.06434770673513412 -0.0 0.0"/>
          <geom class="collision" type="box" pos="0.1172933280467987 -0.08265234529972076 -0.025484323501586914" size="0.0034983856603503227 0.014987933449447155 0.011212067678570747" quat="0.9185348749160767 -0.3953400254249573 -0.0 0.0"/>
        </body>
        <body name="Lid001">
          <joint axis="0.0 0.0 1.0" pos="0.0032636895775794983 -0.04068789631128311 -0.15955886244773865" limited="true" name="Lid001_joint" range="0.0 0.05" type="slide" damping="1" frictionloss="1" armature=".01" stiffness="0.05"/>
          <geom mesh="Lid001_vis" type="mesh" solimp="0.998 0.998 0.001" solref="0.001 1" density="100" friction="0.95 0.3 0.1" class="visual" material="Lid001_material"/>
          <geom class="collision" type="box" pos="0.003273582085967064 -0.04110733047127724 -0.15969455242156982" size="0.12849262356758118 0.054163858294487 0.002483558375388384" quat="1.0 0.0 0.0 0.0"/>
        </body>
        <geom class="region" name="reg_main" type="box" pos="0.0 0.03582325577735901 0.0" size="0.15284475684165955 0.15095151960849762 0.20082902908325195"/>
      </body>
    </body>
  </worldbody>
  <actuator>
    <motor name="Button001_joint_actuator" joint="Button001_joint" gear="0.5"/>
    <motor name="Container001_Clear_joint_actuator" joint="Container001_Clear_joint" gear="50"/>
    <motor name="Lever001_joint_actuator" joint="Lever001_joint" gear="10"/>
    <motor name="Lever002_joint_actuator" joint="Lever002_joint" gear="10"/>
    <motor name="Lid001_joint_actuator" joint="Lid001_joint" gear="10"/>
    <motor name="Lid003_joint_actuator" joint="Lid003_joint" gear="10"/>
    <motor name="Lid002_joint_actuator" joint="Lid002_joint" gear="10"/>
  </actuator>
</mujoco>
