<mujoco model="model">
  <compiler angle="radian"/>
  <asset>
    <texture type="2d" name="image7" file="visuals/image7.png"/>
    <texture type="2d" name="image0" file="visuals/image0.png"/>
    <texture type="2d" name="image10" file="visuals/image10.png"/>
    <texture type="2d" name="image5" file="visuals/image5.png"/>
    <texture type="2d" name="image3" file="visuals/image3.png"/>
    <material name="Mat_Back" texture="image7" specular="0.5" shininess="0.25"/>
    <material name="Mat_Decal" texture="image0" specular="0.5" shininess="0.25"/>
    <material name="Mat_Doors" texture="image10" specular="0.5" shininess="0.25"/>
    <material name="Mat_Interior" texture="image5" specular="0.5" shininess="0.25"/>
    <material name="Mat_Main" texture="image3" specular="0.5" shininess="0.25"/>
    <material name="Mat_Transparent" specular="0.5" shininess="0.8562316889999999" rgba="0.266520 0.266520 0.266520 0.475964"/>
    <mesh file="visuals/model_0.obj" name="model_0_vis" scale="1 1 1"/>
    <mesh file="visuals/model_1.obj" name="model_1_vis" scale="1 1 1"/>
    <mesh file="visuals/model_2.obj" name="model_2_vis" scale="1 1 1"/>
    <mesh file="visuals/model_3.obj" name="model_3_vis" scale="1 1 1"/>
    <mesh file="visuals/model_4.obj" name="model_4_vis" scale="1 1 1"/>
    <mesh file="visuals/model_5.obj" name="model_5_vis" scale="1 1 1"/>
    <mesh file="visuals/knob_rear_right_0.obj" name="knob_rear_right_0_vis" scale="1 1 1"/>
    <mesh file="visuals/knob_rear_right_1.obj" name="knob_rear_right_1_vis" scale="1 1 1"/>
    <mesh file="visuals/knob_front_left_0.obj" name="knob_front_left_0_vis" scale="1 1 1"/>
    <mesh file="visuals/knob_front_left_1.obj" name="knob_front_left_1_vis" scale="1 1 1"/>
    <mesh file="visuals/knob_front_right_0.obj" name="knob_front_right_0_vis" scale="1 1 1"/>
    <mesh file="visuals/knob_front_right_1.obj" name="knob_front_right_1_vis" scale="1 1 1"/>
    <mesh file="visuals/knob_rear_left_0.obj" name="knob_rear_left_0_vis" scale="1 1 1"/>
    <mesh file="visuals/knob_rear_left_1.obj" name="knob_rear_left_1_vis" scale="1 1 1"/>
    <mesh file="visuals/knob_center_0.obj" name="knob_center_0_vis" scale="1 1 1"/>
    <mesh file="visuals/knob_center_1.obj" name="knob_center_1_vis" scale="1 1 1"/>
  </asset>
  <default>
    <default class="visual">
      <geom conaffinity="0" contype="0" group="1" type="mesh"/>
    </default>
    <default class="collision">
      <geom group="0" rgba="0.5 0 0 0.5"/>
    </default>
    <default class="region">
      <geom group="1" conaffinity="0" contype="0" rgba="0 1 0 0"/>
    </default>
  </default>
  <worldbody>
    <body>
      <body name="object">
        <geom solimp="0.998 0.998 0.001" solref="0.001 1" density="100" friction="0.95 0.3 0.1" type="mesh" mesh="model_0_vis" material="Mat_Doors" class="visual"/>
        <geom solimp="0.998 0.998 0.001" solref="0.001 1" density="100" friction="0.95 0.3 0.1" type="mesh" mesh="model_1_vis" material="Mat_Interior" class="visual"/>
        <geom solimp="0.998 0.998 0.001" solref="0.001 1" density="100" friction="0.95 0.3 0.1" type="mesh" mesh="model_2_vis" material="Mat_Transparent" class="visual"/>
        <geom solimp="0.998 0.998 0.001" solref="0.001 1" density="100" friction="0.95 0.3 0.1" type="mesh" mesh="model_3_vis" material="Mat_Decal" class="visual"/>
        <geom solimp="0.998 0.998 0.001" solref="0.001 1" density="100" friction="0.95 0.3 0.1" type="mesh" mesh="model_4_vis" material="Mat_Main" class="visual"/>
        <geom solimp="0.998 0.998 0.001" solref="0.001 1" density="100" friction="0.95 0.3 0.1" type="mesh" mesh="model_5_vis" material="Mat_Back" class="visual"/>
        <!-- Burners -->
        <site name="burner_on_front_left" pos="-0.18 -0.125 0.235" size="0.035 0.005" rgba="0.3 0.4 1 0.5" type="cylinder"/>
        <site name="burner_on_front_right" pos="0.181 -0.126 0.235" size="0.050 0.01" rgba="0.3 0.4 1 0.5" type="cylinder"/>
        <site name="burner_on_rear_left" pos="-0.182 0.078 0.235" size="0.039 0.005" rgba="0.3 0.4 1 0.5" type="cylinder"/>
        <site name="burner_on_rear_right" pos="0.181 0.078 0.235" size="0.032 0.005" rgba="0.3 0.4 1 0.5" type="cylinder"/>
        <site name="burner_on_center" pos="0 -0.025 0.235" size="0.035 0.005" rgba="0.3 0.4 1 0.5" type="cylinder"/>
        <site name="burner_front_left_place_site" pos="-0.18 -0.125 0.268" size="0.035 0.001" rgba="0.3 0.4 1 0" type="cylinder"/>
        <site name="burner_front_right_place_site" pos="0.181 -0.126 0.268" size="0.050 0.001" rgba="0.3 0.4 1 0" type="cylinder"/>
        <site name="burner_rear_left_place_site" pos="-0.182 0.078 0.268" size="0.039 0.001" rgba="0.3 0.4 1 0" type="cylinder"/>
        <site name="burner_rear_right_place_site" pos="0.181 0.078 0.268" size="0.032 0.001" rgba="0.3 0.4 1 0" type="cylinder"/>
        <site name="burner_center_place_site" pos="0 -0.025 0.268" size="0.035 0.001" rgba="0.3 0.4 1 0" type="cylinder"/>
        <!-- Main -->
        <geom class="collision" type="box" pos="0 0.035 -0.112" size="0.32 0.3 0.38"/>
        <!-- Oven Handle -->
        <geom class="collision" type="box" pos="0 -0.29 0.112" size="0.31 0.03 0.015"/>
        <!-- Control Panel -->
        <geom class="collision" type="box" pos="0 -0.257 0.183" size="0.32 0.012 0.03" axisangle="1 0 0 -0.0873"/>
        <!-- Back Display Panel -->
        <geom class="collision" type="box" pos="0 0.26 0.385" size="0.32 0.05 0.12"/>
        <body name="knob_front_right">
          <joint axis="0 0.9962 -0.0872" name="knob_front_right_joint" damping="1" pos="0.199 -0.275 0.183"/>
          <geom solimp="0.998 0.998 0.001" solref="0.001 1" density="100" friction="0.95 0.3 0.1" type="mesh" mesh="knob_rear_right_0_vis" material="Mat_Decal" class="visual"/>
          <geom solimp="0.998 0.998 0.001" solref="0.001 1" density="100" friction="0.95 0.3 0.1" type="mesh" mesh="knob_rear_right_1_vis" material="Mat_Main" class="visual"/>
          <geom class="collision" type="cylinder" pos="0.199 -0.275 0.183" size="0.018 0.005 0" friction="100 0.0001 0.1" solref="0.001 5" solimp="0.999 0.99 0.001 0.5 2" axisangle="1 0 0 1.484"/>
          <geom class="collision" type="box" pos="0.199 -0.29 0.184" size="0.0065 0.008 0.016" friction="100 0.0001 0.1" solref="0.001 5" solimp="0.999 0.99 0.001 0.5 2" axisangle="1 0 0 -0.0873" name="knob_front_right_main"/>
        </body>
        <body name="knob_front_left">
          <joint axis="0 0.9962 -0.0872" name="knob_front_left_joint" damping="1" pos="-0.199 -0.275 0.183"/>
          <geom solimp="0.998 0.998 0.001" solref="0.001 1" density="100" friction="0.95 0.3 0.1" type="mesh" mesh="knob_front_left_0_vis" material="Mat_Decal" class="visual"/>
          <geom solimp="0.998 0.998 0.001" solref="0.001 1" density="100" friction="0.95 0.3 0.1" type="mesh" mesh="knob_front_left_1_vis" material="Mat_Main" class="visual"/>
          <geom class="collision" type="cylinder" pos="-0.199 -0.275 0.183" size="0.018 0.005 0" friction="100 0.0001 0.1" solref="0.001 5" solimp="0.999 0.99 0.001 0.5 2" axisangle="1 0 0 1.484"/>
          <geom class="collision" type="box" pos="-0.199 -0.29 0.184" size="0.0065 0.008 0.016" friction="100 0.0001 0.1" solref="0.001 5" solimp="0.999 0.99 0.001 0.5 2" axisangle="1 0 0 -0.0873" name="knob_front_left_main"/>
        </body>
        <body name="knob_rear_right">
          <joint axis="0 0.9962 -0.0872" name="knob_rear_right_joint" damping="1" pos="0.146 -0.275 0.183"/>
          <geom solimp="0.998 0.998 0.001" solref="0.001 1" density="100" friction="0.95 0.3 0.1" type="mesh" mesh="knob_front_right_0_vis" material="Mat_Decal" class="visual"/>
          <geom solimp="0.998 0.998 0.001" solref="0.001 1" density="100" friction="0.95 0.3 0.1" type="mesh" mesh="knob_front_right_1_vis" material="Mat_Main" class="visual"/>
          <geom class="collision" type="cylinder" pos="0.146 -0.275 0.183" size="0.018 0.005 0" friction="100 0.0001 0.1" solref="0.001 5" solimp="0.999 0.99 0.001 0.5 2" axisangle="1 0 0 1.484"/>
          <geom class="collision" type="box" pos="0.146 -0.29 0.184" size="0.0065 0.008 0.016" friction="100 0.0001 0.1" solref="0.001 5" solimp="0.999 0.99 0.001 0.5 2" axisangle="1 0 0 -0.0873" name="knob_rear_right_main"/>
        </body>
        <body name="knob_rear_left">
          <joint axis="0 0.9962 -0.0872" name="knob_rear_left_joint" damping="1" pos="-0.146 -0.275 0.183"/>
          <geom solimp="0.998 0.998 0.001" solref="0.001 1" density="100" friction="0.95 0.3 0.1" type="mesh" mesh="knob_rear_left_0_vis" material="Mat_Decal" class="visual"/>
          <geom solimp="0.998 0.998 0.001" solref="0.001 1" density="100" friction="0.95 0.3 0.1" type="mesh" mesh="knob_rear_left_1_vis" material="Mat_Main" class="visual"/>
          <geom class="collision" type="cylinder" pos="-0.146 -0.275 0.183" size="0.018 0.005 0" friction="100 0.0001 0.1" solref="0.001 5" solimp="0.999 0.99 0.001 0.5 2" axisangle="1 0 0 1.484"/>
          <geom class="collision" type="box" pos="-0.146 -0.29 0.184" size="0.0065 0.008 0.016" friction="100 0.0001 0.1" solref="0.001 5" solimp="0.999 0.99 0.001 0.5 2" axisangle="1 0 0 -0.0873" name="knob_rear_left_main"/>
        </body>
        <body name="knob_center">
          <joint axis="0 0.9962 -0.0872" name="knob_center_joint" damping="1" pos="0.0035 -0.275 0.183"/>
          <geom solimp="0.998 0.998 0.001" solref="0.001 1" density="100" friction="0.95 0.3 0.1" type="mesh" mesh="knob_center_0_vis" material="Mat_Decal" class="visual"/>
          <geom solimp="0.998 0.998 0.001" solref="0.001 1" density="100" friction="0.95 0.3 0.1" type="mesh" mesh="knob_center_1_vis" material="Mat_Main" class="visual"/>
          <geom class="collision" type="cylinder" pos="0.0035 -0.275 0.183" size="0.018 0.005 0" friction="100 0.0001 0.1" solref="0.001 5" solimp="0.999 0.99 0.001 0.5 2" axisangle="1 0 0 1.484"/>
          <geom class="collision" type="box" pos="0.0035 -0.29 0.184" size="0.0065 0.008 0.016" friction="100 0.0001 0.1" solref="0.001 5" solimp="0.999 0.99 0.001 0.5 2" axisangle="1 0 0 -0.0873" name="knob_center_main"/>
        </body>
        <!-- exterior bounding box points -->
        <geom class="region" name="reg_main_body" type="box" pos="0.0 0.017499999999999988 -0.12" size="0.32 0.2825 0.37"/>
        <!-- interior bounding box points -->
        <geom class="region" name="reg_int" type="box" pos="0.0 0.0 0.0" size="0.0001 0.0001 0.0001"/>
      </body>
    </body>
  </worldbody>
</mujoco>
