<?xml version='1.0' encoding='UTF-8'?>
<mujoco model="model">
  <option timestep="0.002" gravity="0.0 0.0 -9.81"/>
  <compiler angle="radian"/>
  <asset>
    <mesh file="visuals/Blender001.obj" name="Blender001_vis"/>
    <mesh file="visuals/Blender002.obj" name="Blender002_vis"/>
    <mesh file="visuals/Body001.obj" name="Body001_vis"/>
    <mesh file="visuals/Button001.obj" name="Button001_vis"/>
    <mesh file="visuals/Container001.obj" name="Container001_vis"/>
    <mesh file="visuals/Knob001.obj" name="Knob001_vis"/>
    <mesh file="visuals/Lid001.obj" name="Lid001_vis"/>
    <texture file="visuals/T_BC001.png" name="Body001_material" type="2d"/>
    <material name="Body001_material" rgba="1 1 1 1.0" texture="Body001_material" shininess="0.5" specular="0.3103448502657381"/>
    <texture file="visuals/T_BC001.png" name="Button001_material" type="2d"/>
    <material name="Button001_material" rgba="1 1 1 1.0" texture="Button001_material" shininess="0.5" specular="0.3103448502657381"/>
    <texture file="visuals/T_BC001.png" name="Container001_material" type="2d"/>
    <material name="Container001_material" rgba="1 1 1 1.0" texture="Container001_material" shininess="0.5" specular="2"/>
    <texture file="visuals/T_BC001.png" name="Lid001_material" type="2d"/>
    <material name="Lid001_material" rgba="1 1 1 1.0" texture="Lid001_material" shininess="0.5" specular="0.3103448502657381"/>
    <texture file="visuals/T_BC001.png" name="Blender001_material" type="2d"/>
    <material name="Blender001_material" rgba="1 1 1 1.0" texture="Blender001_material" shininess="0.5" specular="1"/>
    <texture file="visuals/T_BC001.png" name="Blender002_material" type="2d"/>
    <material name="Blender002_material" rgba="1 1 1 1.0" texture="Blender002_material" shininess="0.5" specular="1"/>
    <texture file="visuals/T_BC001.png" name="Knob001_material" type="2d"/>
    <material name="Knob001_material" rgba="1 1 1 1.0" texture="Knob001_material" shininess="0.5" specular="0.5"/>
  </asset>
  <default>
    <default class="visual">
      <geom conaffinity="0" contype="0" group="1" type="mesh"/>
    </default>
    <default class="collision">
      <geom group="0" rgba="0.5 0 0 0.5"/>
    </default>
    <default class="spawn">
      <geom group="0" rgba="1 1 1 0.5" contype="0" conaffinity="0"/>
      <site group="0" rgba="1 1 1 0.5"/>
    </default>
    <default class="region">
      <geom group="1" conaffinity="0" contype="0" rgba="0 1 0 0"/>
    </default>
  </default>
  <worldbody>
    <body>
      <body name="object">
        <geom mesh="Body001_vis" type="mesh" solimp="0.998 0.998 0.001" solref="0.001 1" friction="0.95 0.3 0.1" class="visual" material="Body001_material"/>
        <geom class="collision" type="cylinder" pos="0.000000 -0.128824 -0.220151" size="0.0993005633354187 0.009739317931234837" quat="0.7071067094802856 0.0 0.0 -0.7071068286895752" density="1000.0"/>
        <geom class="collision" type="cylinder" pos="0.001597 -0.070675 -0.250930" size="0.14353418350219727 0.01999838836491108" quat="0.7071067094802856 0.0 0.0 -0.7071068286895752" density="1000.0"/>
        <geom class="collision" type="box" pos="0.000000 0.000310 -0.251610" size="0.13999146223068237 0.048502832651138306 0.02011392079293728" quat="1.0 0.0 0.0 0.0" density="1000.0"/>
        <geom class="collision" type="box" pos="0.000000 0.096778 -0.248472" size="0.11802537739276886 0.048502132296562195 0.023700427263975143" quat="1.0 0.0 0.0 0.0" density="1000.0"/>
        <geom class="collision" type="box" pos="0.000000 0.185658 -0.252689" size="0.09285704791545868 0.0422094464302063 0.019484205171465874" quat="1.0 0.0 0.0 0.0" density="1000.0"/>
        <geom class="collision" type="box" pos="0.000000 0.135393 -0.203240" size="0.039346687495708466 0.07086953520774841 0.030786722898483276" quat="1.0 0.0 0.0 0.0" density="1000.0"/>
        <geom class="collision" type="box" pos="0.000000 0.134133 -0.152800" size="0.030359217897057533 0.05225202068686485 0.019947011023759842" quat="1.0 0.0 0.0 0.0" density="1000.0"/>
        <geom class="collision" type="box" pos="0.020409 0.135393 -0.211077" size="0.03934694454073906 0.07086953520774841 0.022950543090701103" quat="1.0 0.0 0.0 0.0" density="1000.0"/>
        <geom class="collision" type="box" pos="0.001605 0.134133 -0.143237" size="0.03636309504508972 0.0522521436214447 0.010446240194141865" quat="1.0 0.0 0.0 0.0" density="1000.0"/>
        <body name="Button001">
          <joint axis="-0.972398042678833 0.0 -0.23332831263542175" pos="0.040669 0.141369 -0.170450" limited="true" name="Button001_joint" range="0.0 0.003" type="slide" damping="1" frictionloss="1" armature=".01" stiffness="0.5" springref="-0.5"/>
          <geom mesh="Button001_vis" type="mesh" solimp="0.998 0.998 0.001" solref="0.001 1" friction="0.95 0.3 0.1" class="visual" material="Button001_material"/>
          <geom class="collision" type="cylinder" pos="0.043666 0.141795 -0.169974" size="0.015489477664232254 0.003840031800791621" quat="0.8005008101463318 -1.8275068125461758e-09 0.5993316769599915 2.5640383150005164e-09" density="1000.0"/>
        </body>
        <body name="Container001">
          <joint axis="0.0 0.0 1.0" pos="0.000000 -0.128824 -0.151364" limited="true" name="Container001_joint" range="0.0 0.05" type="slide" damping="1" frictionloss="1" armature=".01" stiffness="0.05"/>
          <geom mesh="Container001_vis" type="mesh" solimp="0.998 0.998 0.001" solref="0.001 1" friction="0.95 0.3 0.1" class="visual" material="Container001_material"/>
          <geom class="collision" type="cylinder" pos="0.000000 -0.128824 -0.204750" size="0.05979258567094803 0.0018684215610846877" quat="0.70710688829422 0.0 0.0 0.7071066498756409" density="1000.0"/>
          <geom class="collision" type="box" pos="0.002113 -0.231572 -0.092889" size="0.027677712962031364 0.005457268562167883 0.05090999975800514" quat="1.0 0.0 0.0 0.0" density="1000.0"/>
          <geom class="collision" type="box" pos="0.002113 -0.210162 -0.172863" size="0.005457259714603424 0.027677705511450768 0.037360746413469315" quat="0.6654353141784668 0.23915646970272064 -0.23915639519691467 0.6654353737831116" density="1000.0"/>
          <geom class="collision" type="box" pos="-0.049544 -0.218863 -0.092889" size="0.005457259714603424 0.027677711099386215 0.05090999975800514" quat="0.866025447845459 0.0 0.0 0.4999999701976776" density="1000.0"/>
          <geom class="collision" type="box" pos="-0.038839 -0.200321 -0.172863" size="0.005457259714603424 0.027677707374095917 0.037360746413469315" quat="0.8149885535240173 0.16910913586616516 -0.29290568828582764 0.4705337584018707" density="1000.0"/>
          <geom class="collision" type="box" pos="-0.087926 -0.182028 -0.092889" size="0.005457259714603424 0.027677709236741066 0.05091000348329544" quat="0.9659258127212524 0.0 0.0 0.2588190734386444" density="1000.0"/>
          <geom class="collision" type="box" pos="-0.069384 -0.171323 -0.172863" size="0.005457259714603424 0.027677705511450768 0.037360746413469315" quat="0.9090015888214111 0.08753731846809387 -0.3266938328742981 0.24356621503829956" density="1000.0"/>
          <geom class="collision" type="box" pos="-0.102748 -0.130937 -0.092889" size="0.005457266233861446 0.027677709236741066 0.05090999975800514" quat="1.0 0.0 0.0 0.0" density="1000.0"/>
          <geom class="collision" type="box" pos="-0.081338 -0.130937 -0.172863" size="0.005457259714603424 0.027677705511450768 0.037360746413469315" quat="0.9410676956176758 -1.4864680153436893e-08 -0.3382182717323303 -5.418909765353419e-08" density="1000.0"/>
          <geom class="collision" type="box" pos="-0.090039 -0.079280 -0.092889" size="0.005457259714603424 0.027677711099386215 0.05090999975800514" quat="0.9659258127212524 0.0 0.0 -0.2588191032409668" density="1000.0"/>
          <geom class="collision" type="box" pos="-0.071497 -0.089985 -0.172863" size="0.005457259714603424 0.027677705511450768 0.037360746413469315" quat="0.9090015888214111 -0.08753730356693268 -0.3266937732696533 -0.24356628954410553" density="1000.0"/>
          <geom class="collision" type="box" pos="-0.053204 -0.040898 -0.092889" size="0.005457259248942137 0.027677711099386215 0.05090999975800514" quat="0.8660253882408142 0.0 0.0 -0.5" density="1000.0"/>
          <geom class="collision" type="box" pos="-0.042499 -0.059440 -0.172863" size="0.005457259714603424 0.027677705511450768 0.037360746413469315" quat="0.8149885535240173 -0.16910910606384277 -0.2929055988788605 -0.4705338180065155" density="1000.0"/>
          <geom class="collision" type="box" pos="-0.002113 -0.026076 -0.092889" size="0.027677712962031364 0.005457268562167883 0.05090999975800514" quat="1.0 0.0 0.0 0.0" density="1000.0"/>
          <geom class="collision" type="box" pos="-0.002113 -0.047486 -0.172863" size="0.005457259714603424 0.027677705511450768 0.037360746413469315" quat="0.6654351949691772 -0.23915646970272064 -0.23915639519691467 -0.6654354929924011" density="1000.0"/>
          <geom class="collision" type="box" pos="0.049544 -0.038785 -0.092889" size="0.005457260180264711 0.027677711099386215 0.05091000348329544" quat="0.4999999701976776 0.0 0.0 -0.866025447845459" density="1000.0"/>
          <geom class="collision" type="box" pos="0.038839 -0.057327 -0.172863" size="0.005457259714603424 0.027677707374095917 0.037360746413469315" quat="0.4705338478088379 -0.2929055690765381 -0.16910910606384277 -0.8149885535240173" density="1000.0"/>
          <geom class="collision" type="box" pos="0.087926 -0.075620 -0.092889" size="0.005457259714603424 0.027677711099386215 0.05091000348329544" quat="0.25881895422935486 0.0 0.0 -0.9659258723258972" density="1000.0"/>
          <geom class="collision" type="box" pos="0.069384 -0.086325 -0.172863" size="0.005457259714603424 0.027677707374095917 0.037360746413469315" quat="0.24356628954410553 -0.32669374346733093 -0.08753740042448044 -0.9090015888214111" density="1000.0"/>
          <geom class="collision" type="box" pos="0.102748 -0.126711 -0.092889" size="0.0054572708904743195 0.027677712962031364 0.05090999975800514" quat="1.0 0.0 0.0 0.0" density="1000.0"/>
          <geom class="collision" type="box" pos="0.081338 -0.126711 -0.172863" size="0.005457259714603424 0.027677705511450768 0.037360746413469315" quat="5.555726190209498e-08 0.3382182717323303 1.7568849486337967e-08 0.9410676956176758" density="1000.0"/>
          <geom class="collision" type="box" pos="0.090039 -0.178368 -0.092889" size="0.005457260180264711 0.027677709236741066 0.05090999975800514" quat="0.2588190734386444 0.0 0.0 0.9659258127212524" density="1000.0"/>
          <geom class="collision" type="box" pos="0.071497 -0.167663 -0.172863" size="0.005457259714603424 0.027677707374095917 0.037360746413469315" quat="0.24356625974178314 0.32669374346733093 -0.08753732591867447 0.9090015888214111" density="1000.0"/>
          <geom class="collision" type="box" pos="0.053204 -0.216750 -0.092889" size="0.005457259248942137 0.027677711099386215 0.05090999975800514" quat="0.4999999701976776 0.0 0.0 0.866025447845459" density="1000.0"/>
          <geom class="collision" type="box" pos="0.042499 -0.198208 -0.172863" size="0.005457259714603424 0.027677707374095917 0.037360746413469315" quat="0.4705338776111603 0.29290571808815 -0.16910916566848755 0.8149884343147278" density="1000.0"/>
        </body>
        <body name="Lid001">
          <joint axis="-1.0 0.0 0.0" pos="0.002113 0.175892 -0.128950" limited="true" name="Lid001_joint" range="0.0 1.5707963267948966" type="hinge" damping="1" frictionloss="1" armature=".01" stiffness="0.05"/>
          <geom mesh="Lid001_vis" type="mesh" solimp="0.998 0.998 0.001" solref="0.001 1" friction="0.95 0.3 0.1" class="visual" material="Lid001_material"/>
          <geom class="collision" type="cylinder" pos="0.000000 0.069917 0.120765" size="0.07553092390298843 0.12249548733234406" quat="0.4969509541988373 -0.5030301213264465 0.5030722618103027 0.49690917134284973" density="1000.0"/>
          <geom class="collision" type="cylinder" pos="-0.001189 -0.085474 0.118385" size="0.06744355708360672 0.027656659483909607" quat="0.5000000596046448 -0.5 0.5 0.4999999701976776" density="1000.0"/>
          <geom class="collision" type="cylinder" pos="-0.001189 -0.124939 0.129266" size="0.05730089172720909 0.0234974455088377" quat="0.5000001788139343 -0.5000000596046448 0.4999999403953552 0.49999985098838806" density="1000.0"/>
          <geom class="collision" type="cylinder" pos="-0.028092 -0.127146 0.011325" size="0.015423283912241459 0.030910924077033997" quat="0.70710688829422 0.0 0.0 0.7071066498756409" density="1000.0"/>
          <geom class="collision" type="cylinder" pos="0.028292 -0.127146 0.011325" size="0.015423283912241459 0.030910924077033997" quat="0.70710688829422 0.0 0.0 0.7071066498756409" density="1000.0"/>
          <geom class="collision" type="cylinder" pos="-0.000215 -0.127146 -0.018024" size="0.011843170039355755 0.008213881403207779" quat="0.70710688829422 0.0 0.0 0.7071066498756409" density="1000.0"/>
          <geom class="collision" type="cylinder" pos="0.028948 -0.129402 0.182239" size="0.01828480139374733 0.022911718115210533" quat="0.7071067094802856 0.0 0.0 -0.7071068286895752" density="1000.0"/>
          <geom class="collision" type="box" pos="0.000000 0.065407 0.026446" size="0.03905344754457474 0.06689076125621796 0.028838833793997765" quat="1.0 0.0 0.0 0.0" density="1000.0"/>
          <geom class="collision" type="box" pos="0.000000 -0.049170 0.037921" size="0.0319354422390461 0.054699089378118515 0.023583194240927696" quat="1.0 0.0 0.0 0.0" density="1000.0"/>
          <geom class="collision" type="box" pos="0.000000 0.124150 -0.077709" size="0.031394146382808685 0.02908330224454403 0.037388209253549576" quat="0.69721919298172 0.11783666908740997 -0.11783668398857117 0.6972190737724304" density="1000.0"/>
          <geom class="collision" type="box" pos="0.000000 -0.128060 -0.022791" size="0.046673260629177094 0.015383935533463955 0.005404059775173664" quat="1.0 0.0 0.0 0.0" density="1000.0"/>
          <geom class="collision" type="box" pos="-0.000292 -0.128060 -0.031503" size="0.004436506889760494 0.004100261256098747 0.012434493750333786" quat="1.0 0.0 0.0 0.0" density="1000.0"/>
          <geom class="collision" type="box" pos="-0.028928 -0.128060 -0.039289" size="0.004436506889760494 0.004100264515727758 0.012434493750333786" quat="1.0 0.0 0.0 0.0" density="1000.0"/>
          <geom class="collision" type="box" pos="0.028563 -0.128060 -0.039289" size="0.004436506889760494 0.0041002677753567696 0.012434493750333786" quat="1.0 0.0 0.0 0.0" density="1000.0"/>
          <geom class="collision" type="box" pos="-0.000292 -0.136880 -0.043770" size="0.004100297577679157 0.004436505027115345 0.012434493750333786" quat="0.61094731092453 -0.3560101389884949 0.35600993037223816 0.6109477281570435" density="1000.0"/>
          <geom class="collision" type="box" pos="-0.000292 -0.157121 -0.054474" size="0.004100297577679157 0.004436505027115345 0.012434492819011211" quat="0.6206436157226562 -0.3388236165046692 0.3388236165046692 0.6206437349319458" density="1000.0"/>
          <geom class="collision" type="box" pos="-0.000292 -0.168840 -0.073244" size="0.004100297577679157 0.004436505027115345 0.012434493750333786" quat="0.6987792253494263 -0.10820181667804718 0.10820183902978897 0.6987791657447815" density="1000.0"/>
          <geom class="collision" type="box" pos="-0.000292 -0.171335 -0.125499" size="0.00443650595843792 0.004122056532651186 0.041983600705862045" quat="1.0 0.0 0.0 0.0" density="1000.0"/>
          <geom class="collision" type="box" pos="-0.000292 -0.169904 -0.175537" size="0.0041002980433404446 0.004436505027115345 0.012434493750333786" quat="0.6977085471153259 0.11490409821271896 -0.11490410566329956 0.6977083086967468" density="1000.0"/>
          <geom class="collision" type="box" pos="-0.000292 -0.158388 -0.187812" size="0.004100297577679157 0.004436505027115345 0.012434493750333786" quat="0.5595824122428894 0.4322817027568817 -0.4322812855243683 0.5595828294754028" density="1000.0"/>
          <geom class="collision" type="box" pos="0.000000 0.092874 -0.015681" size="0.04690190404653549 0.030521633103489876 0.02520126849412918" quat="0.6356257796287537 -0.30980589985847473 0.3098057508468628 0.6356261372566223" density="1000.0"/>
          <geom class="collision" type="box" pos="0.000000 -0.122283 0.067295" size="0.04467394948005676 0.01603887975215912 0.025931384414434433" quat="1.0 0.0 0.0 0.0" density="1000.0"/>
          <geom class="collision" type="box" pos="0.000000 -0.157058 0.129170" size="0.01267123781144619 0.01077638752758503 0.04105747863650322" quat="1.0 0.0 0.0 0.0" density="1000.0"/>
          <geom class="collision" type="box" pos="0.000000 0.139052 0.200354" size="0.029344329610466957 0.022228607907891273 0.018353836610913277" quat="0.6513049006462097 -0.27532148361206055 0.27532151341438293 0.6513049006462097" density="1000.0"/>
          <geom class="collision" type="box" pos="0.000000 0.094772 0.232856" size="0.025530321523547173 0.019339462742209435 0.015968309715390205" quat="0.6814349293708801 -0.18880237638950348 0.1888023316860199 0.6814351081848145" density="1000.0"/>
          <geom class="collision" type="box" pos="0.000000 0.049373 0.248672" size="0.025530319660902023 0.019339462742209435 0.015968309715390205" quat="0.7016568779945374 -0.08762177079916 0.08762177079916 0.7016569375991821" density="1000.0"/>
          <geom class="collision" type="box" pos="0.000000 0.003615 0.251011" size="0.025530319660902023 0.019339462742209435 0.015968309715390205" quat="0.7068054676055908 0.020641008391976357 -0.020641004666686058 0.7068054676055908" density="1000.0"/>
          <geom class="collision" type="box" pos="0.000000 -0.042265 0.244347" size="0.02553032711148262 0.019339462742209435 0.015968309715390205" quat="0.7023257613182068 0.0820889100432396 -0.0820889100432396 0.7023256421089172" density="1000.0"/>
          <geom class="collision" type="box" pos="0.000000 -0.081700 0.224357" size="0.025530319660902023 0.019339462742209435 0.015968309715390205" quat="0.6795504093170166 0.19547683000564575 -0.19547683000564575 0.6795504689216614" density="1000.0"/>
          <geom class="collision" type="box" pos="0.000000 -0.117967 0.195846" size="0.025530321523547173 0.019339462742209435 0.015968309715390205" quat="0.6572299599647522 0.26086151599884033 -0.2608613967895508 0.6572300791740417" density="1000.0"/>
          <body name="Blender001">
            <joint axis="0.0 0.0 1.0" pos="-0.028932 -0.128227 -0.124980" limited="false" name="Blender001_joint" range="0 360" type="hinge" damping="1" frictionloss="1" armature=".01" stiffness="0.05"/>
            <geom mesh="Blender001_vis" type="mesh" solimp="0.998 0.998 0.001" solref="0.001 1" friction="0.95 0.3 0.1" class="visual" material="Blender001_material"/>
            <geom class="collision" type="cylinder" pos="-0.028932 -0.128227 -0.124980" size="0.02816907875239849 0.06729777902364731" quat="0.70710688829422 0.0 0.0 0.7071066498756409" density="1000.0"/>
          </body>
          <body name="Blender002">
            <joint axis="0.0 0.0 1.0" pos="0.028826 -0.128227 -0.124971" limited="false" name="Blender002_joint" range="0 360" type="hinge" damping="1" frictionloss="1" armature=".01" stiffness="0.05"/>
            <geom mesh="Blender002_vis" type="mesh" solimp="0.998 0.998 0.001" solref="0.001 1" friction="0.95 0.3 0.1" class="visual" material="Blender002_material"/>
            <geom class="collision" type="cylinder" pos="0.028826 -0.128227 -0.124971" size="0.02816907875239849 0.06729777902364731" quat="0.70710688829422 0.0 0.0 0.7071066498756409" density="1000.0"/>
          </body>
          <body name="Knob001">
            <joint axis="0.0 -1.0 0.0" pos="-0.002570 -0.067443 0.117047" limited="true" name="Knob001_joint" range="0.0 0.8377580409572781" type="hinge" damping="0.05" armature="0.001" springref="-0.01"/>
            <geom mesh="Knob001_vis" type="mesh" solimp="0.998 0.998 0.001" solref="0.001 1" friction="0.95 0.3 0.1" class="visual" material="Knob001_material"/>
            <geom class="collision" type="box" pos="0.068034 -0.068413 0.147680" size="0.01002931222319603 0.0022196490317583084 0.005512468982487917" quat="0.6971321702003479 -0.11835025995969772 -0.11835024505853653 0.6971321105957031" density="1000.0"/>
            <geom class="collision" type="box" pos="0.070586 -0.068616 0.149980" size="0.010232232511043549 0.00208250992000103 0.003442030167207122" quat="0.5810648798942566 0.4029436707496643 0.4029437005519867 0.5810648798942566" density="1000.0"/>
          </body>
        </body>
        <geom class="region" name="reg_main" type="box" pos="0.0021130000000000038 0.006836999999999996 0.0" size="0.143724 0.22949799999999998 0.267996"/>
      </body>
    </body>
  </worldbody>
  <actuator>
    <motor name="Button001_joint_actuator" joint="Button001_joint" gear="0.5"/>
    <motor name="Container001_joint_actuator" joint="Container001_joint" gear="10"/>
    <motor name="Lid001_joint_actuator" joint="Lid001_joint" gear="10"/>
    <motor name="Blender001_joint_actuator" joint="Blender001_joint" gear="10"/>
    <motor name="Blender002_joint_actuator" joint="Blender002_joint" gear="10"/>
    <motor name="Knob001_joint_actuator" joint="Knob001_joint" gear="10"/>
  </actuator>
</mujoco>
