<mujoco model="model">
  <compiler angle="radian"/>
  <asset>
    <mesh file="visuals/knob_front_left.obj" name="knob_front_left_vis"/>
    <mesh file="visuals/knob_front_right.obj" name="knob_front_right_vis"/>
    <mesh file="visuals/knob_rear_left.obj" name="knob_rear_left_vis"/>
    <mesh file="visuals/knob_rear_right.obj" name="knob_rear_right_vis"/>
    <mesh file="visuals/Body001.obj" name="Body001_vis"/>
    <mesh file="visuals/Door001.obj" name="Door001_vis"/>
    <mesh file="visuals/Knob001.obj" name="Knob001_vis"/>
    <mesh file="visuals/Knob002.obj" name="Knob002_vis"/>
    <mesh file="visuals/Shelf001.obj" name="Shelf001_vis"/>
    <texture file="visuals/T_BC001.png" name="Body001_material" type="2d"/>
    <material name="Body001_material" rgba="1 1 1 1.0" texture="Body001_material" shininess="0.141421377658844" specular="2"/>
    <texture file="visuals/T_BC001.png" name="knob_front_left_material" type="2d"/>
    <material name="knob_front_left_material" rgba="1 1 1 1.0" texture="knob_front_left_material" shininess="0.141421377658844" specular="2"/>
    <texture file="visuals/T_BC001.png" name="knob_front_right_material" type="2d"/>
    <material name="knob_front_right_material" rgba="1 1 1 1.0" texture="knob_front_right_material" shininess="0.141421377658844" specular="2"/>
    <texture file="visuals/T_BC001.png" name="knob_rear_left_material" type="2d"/>
    <material name="knob_rear_left_material" rgba="1 1 1 1.0" texture="knob_rear_left_material" shininess="0.141421377658844" specular="2"/>
    <texture file="visuals/T_BC001.png" name="knob_rear_right_material" type="2d"/>
    <material name="knob_rear_right_material" rgba="1 1 1 1.0" texture="knob_rear_right_material" shininess="0.141421377658844" specular="2"/>
    <texture file="visuals/T_BC001.png" name="Door001_material" type="2d"/>
    <material name="Door001_material" rgba="1 1 1 1.0" texture="Door001_material" shininess="0.141421377658844" specular="2"/>
    <texture file="visuals/T_BC001.png" name="Knob001_material" type="2d"/>
    <material name="Knob001_material" rgba="1 1 1 1.0" texture="Knob001_material" shininess="0.141421377658844" specular="2"/>
    <texture file="visuals/T_BC001.png" name="Knob002_material" type="2d"/>
    <material name="Knob002_material" rgba="1 1 1 1.0" texture="Knob002_material" shininess="0.141421377658844" specular="2"/>
    <texture file="visuals/T_BC001.png" name="Shelf001_material" type="2d"/>
    <material name="Shelf001_material" rgba="1 1 1 1.0" texture="Shelf001_material" shininess="0.141421377658844" specular="3"/>
  </asset>
  <default>
    <default class="visual">
      <geom conaffinity="0" contype="0" group="1" type="mesh"/>
    </default>
    <default class="collision">
      <geom group="0" rgba="0.5 0 0 0.5"/>
    </default>
    <default class="spawn">
      <geom group="0" rgba="1 1 1 0.5" contype="0" conaffinity="0"/>
      <site group="0" rgba="1 1 1 0.5"/>
    </default>
    <default class="region">
      <geom group="1" conaffinity="0" contype="0" rgba="0 1 0 0"/>
    </default>
  </default>
  <worldbody>
    <body>
      <body name="object">
        <site type="cylinder" rgba="0 0 0.5 0.5" size="0.09297765791416168 0.01340059656649828" pos="-0.215011 0.226146 0.504186" name="burner_on_rear_left"/>
        <site type="cylinder" rgba="0 0 0.5 0.5" size="0.09297765791416168 0.01340059656649828" pos="-0.215011 -0.072055 0.504186" name="burner_on_front_left"/>
        <site type="cylinder" rgba="0 0 0.5 0.5" size="0.09297765791416168 0.01340059656649828" pos="0.182869 -0.073607 0.504186" name="burner_on_front_right"/>
        <site type="cylinder" rgba="0 0 0.5 0.5" size="0.09297765791416168 0.01340059656649828" pos="0.182869 0.223819 0.504186" name="burner_on_rear_right"/>
        <geom mesh="Body001_vis" type="mesh" solimp="0.998 0.998 0.001" solref="0.001 1" density="100" friction="0.95 0.3 0.1" class="visual" material="Body001_material"/>
        <geom class="collision" type="box" pos="-0.000545 0.020477 0.428417" size="0.40717947483062744 0.37442243099212646 0.04616615176200867" quat="1.0 0.0 0.0 0.0"/>
        <geom class="collision" type="box" pos="-0.000545 0.031695 0.251771" size="0.40717947483062744 0.3632049560546875 0.02052617073059082" quat="1.0 0.0 0.0 0.0"/>
        <geom class="collision" type="box" pos="-0.000545 0.040909 0.326659" size="0.40717947483062744 0.3539905846118927 0.06058862805366516" quat="1.0 0.0 0.0 0.0"/>
        <geom class="collision" type="box" pos="-0.391564 0.055396 -0.071292" size="0.016161248087882996 0.33950331807136536 0.3078221380710602" quat="1.0 0.0 0.0 0.0"/>
        <geom class="collision" type="box" pos="-0.000392 0.351605 -0.071292" size="0.3750259578227997 0.043294794857501984 0.3078221380710602" quat="1.0 0.0 0.0 0.0"/>
        <geom class="collision" type="box" pos="0.391429 0.055396 -0.071292" size="0.016295300796628 0.33950331807136536 0.3078221380710602" quat="1.0 0.0 0.0 0.0"/>
        <geom class="collision" type="box" pos="-0.000211 0.055110 0.216439" size="0.37412795424461365 0.33978936076164246 0.018022269010543823" quat="1.0 0.0 0.0 0.0"/>
        <geom class="collision" type="box" pos="-0.007217 0.055110 -0.431528" size="0.3886815905570984 0.33978936076164246 0.08460719883441925" quat="1.0 0.0 0.0 0.0"/>
        <geom class="collision" type="box" pos="-0.000545 0.074588 0.484779" size="0.40717947483062744 0.2971278429031372 0.010510548017919064" quat="1.0 0.0 0.0 0.0"/>
        <geom class="collision" type="box" pos="-0.310964 -0.074965 0.505372" size="0.053832389414310455 0.013457633554935455 0.010762471705675125" quat="1.0 0.0 0.0 0.0"/>
        <geom class="collision" type="box" pos="-0.121317 -0.074965 0.505372" size="0.053832389414310455 0.013457633554935455 0.010762471705675125" quat="1.0 0.0 0.0 0.0"/>
        <geom class="collision" type="box" pos="-0.319246 0.019273 0.505372" size="0.04842475429177284 0.013457633554935455 0.010762471705675125" quat="0.840238094329834 0.0 -0.0 -0.5422176122665405"/>
        <geom class="collision" type="box" pos="-0.216057 0.073858 0.505372" size="0.10882691293954849 0.01345763634890318 0.010762471705675125" quat="0.7071068286895752 0.0 0.0 0.7071067690849304"/>
        <geom class="collision" type="box" pos="-0.216057 -0.169229 0.505372" size="0.053810589015483856 0.01345763634890318 0.010762471705675125" quat="0.7071068286895752 0.0 0.0 0.7071067690849304"/>
        <geom class="collision" type="box" pos="-0.320143 -0.168085 0.505372" size="0.04842475429177284 0.013457633554935455 0.010762471705675125" quat="0.840238094329834 0.0 0.0 0.5422176122665405"/>
        <geom class="collision" type="box" pos="-0.110031 -0.168085 0.505372" size="0.04842475429177284 0.013457633554935455 0.010762471705675125" quat="0.840238094329834 0.0 -0.0 -0.5422176122665405"/>
        <geom class="collision" type="box" pos="-0.110928 0.019273 0.505372" size="0.04842475429177284 0.013457633554935455 0.010762471705675125" quat="0.840238094329834 0.0 0.0 0.5422176122665405"/>
        <geom class="collision" type="box" pos="-0.110928 0.316537 0.505372" size="0.04842475429177284 0.013457633554935455 0.010762471705675125" quat="0.840238094329834 0.0 0.0 0.5422176122665405"/>
        <geom class="collision" type="box" pos="-0.110031 0.129179 0.505372" size="0.04842475429177284 0.013457633554935455 0.010762471705675125" quat="0.840238094329834 0.0 -0.0 -0.5422176122665405"/>
        <geom class="collision" type="box" pos="-0.320143 0.129179 0.505372" size="0.04842475429177284 0.013457633554935455 0.010762471705675125" quat="0.840238094329834 0.0 0.0 0.5422176122665405"/>
        <geom class="collision" type="box" pos="-0.216057 0.318332 0.505372" size="0.053810589015483856 0.01345763634890318 0.010762471705675125" quat="0.7071068286895752 0.0 0.0 0.7071067690849304"/>
        <geom class="collision" type="box" pos="-0.319246 0.316537 0.505372" size="0.04842475429177284 0.013457633554935455 0.010762471705675125" quat="0.840238094329834 0.0 -0.0 -0.5422176122665405"/>
        <geom class="collision" type="box" pos="-0.121317 0.222298 0.505372" size="0.053832389414310455 0.013457633554935455 0.010762471705675125" quat="1.0 0.0 0.0 0.0"/>
        <geom class="collision" type="box" pos="-0.310964 0.222298 0.505372" size="0.053832389414310455 0.013457633554935455 0.010762471705675125" quat="1.0 0.0 0.0 0.0"/>
        <geom class="collision" type="box" pos="0.088058 0.222298 0.505372" size="0.053832389414310455 0.013457633554935455 0.010762471705675125" quat="1.0 0.0 0.0 0.0"/>
        <geom class="collision" type="box" pos="0.277706 0.222298 0.505372" size="0.053832389414310455 0.013457633554935455 0.010762471705675125" quat="1.0 0.0 0.0 0.0"/>
        <geom class="collision" type="box" pos="0.079776 0.316537 0.505372" size="0.04842475429177284 0.013457633554935455 0.010762471705675125" quat="0.840238094329834 0.0 -0.0 -0.5422176122665405"/>
        <geom class="collision" type="box" pos="0.182965 0.318332 0.505372" size="0.053810589015483856 0.01345763634890318 0.010762471705675125" quat="0.7071068286895752 0.0 0.0 0.7071067690849304"/>
        <geom class="collision" type="box" pos="0.078879 0.129179 0.505372" size="0.04842475429177284 0.013457633554935455 0.010762471705675125" quat="0.840238094329834 0.0 0.0 0.5422176122665405"/>
        <geom class="collision" type="box" pos="0.288992 0.129179 0.505372" size="0.04842475429177284 0.013457633554935455 0.010762471705675125" quat="0.840238094329834 0.0 -0.0 -0.5422176122665405"/>
        <geom class="collision" type="box" pos="0.288095 0.316537 0.505372" size="0.04842475429177284 0.013457633554935455 0.010762471705675125" quat="0.840238094329834 0.0 0.0 0.5422176122665405"/>
        <geom class="collision" type="box" pos="0.288095 0.019273 0.505372" size="0.04842475429177284 0.013457633554935455 0.010762471705675125" quat="0.840238094329834 0.0 0.0 0.5422176122665405"/>
        <geom class="collision" type="box" pos="0.288992 -0.168085 0.505372" size="0.04842475429177284 0.013457633554935455 0.010762471705675125" quat="0.840238094329834 0.0 -0.0 -0.5422176122665405"/>
        <geom class="collision" type="box" pos="0.078879 -0.168085 0.505372" size="0.04842475429177284 0.013457633554935455 0.010762471705675125" quat="0.840238094329834 0.0 0.0 0.5422176122665405"/>
        <geom class="collision" type="box" pos="0.182965 -0.169229 0.505372" size="0.053810589015483856 0.01345763634890318 0.010762471705675125" quat="0.7071068286895752 0.0 0.0 0.7071067690849304"/>
        <geom class="collision" type="box" pos="0.182965 0.073858 0.505372" size="0.10882691293954849 0.01345763634890318 0.010762471705675125" quat="0.7071068286895752 0.0 0.0 0.7071067690849304"/>
        <geom class="collision" type="box" pos="0.079776 0.019273 0.505372" size="0.04842475429177284 0.013457633554935455 0.010762471705675125" quat="0.840238094329834 0.0 -0.0 -0.5422176122665405"/>
        <geom class="collision" type="box" pos="0.277706 -0.074966 0.505372" size="0.053832389414310455 0.013457633554935455 0.010762471705675125" quat="1.0 0.0 0.0 0.0"/>
        <geom class="collision" type="box" pos="0.088058 -0.074966 0.505372" size="0.053832389414310455 0.013457633554935455 0.010762471705675125" quat="1.0 0.0 0.0 0.0"/>
        <body name="knob_front_left">
          <joint axis="0.0 -1.0 0.0" pos="-0.337646 -0.330690 0.327538" limited="true" name="knob_front_left_joint" range="0.0 3.141592653589793" type="hinge" damping="0.05" armature="0.001"/>
          <geom mesh="knob_front_left_vis" type="mesh" solimp="0.998 0.998 0.001" solref="0.001 1" density="100" friction="0.95 0.3 0.1" class="visual" material="knob_front_left_material"/>
          <geom class="collision" type="cylinder" pos="-0.337646 -0.324753 0.327538" size="0.036232754588127136 0.010816382244229317" quat="0.7071068286895752 0.7071067690849304 0.0 0.0"/>
          <geom class="collision" type="box" pos="-0.337646 -0.343787 0.327339" size="0.008053257130086422 0.008392240852117538 0.031496912240982056" quat="1.0 0.0 0.0 0.0"/>
        </body>
        <body name="knob_front_right">
          <joint axis="0.0 -1.0 0.0" pos="0.335850 -0.330690 0.327538" limited="true" name="knob_front_right_joint" range="0.0 3.141592653589793" type="hinge" damping="0.05" armature="0.001"/>
          <geom mesh="knob_front_right_vis" type="mesh" solimp="0.998 0.998 0.001" solref="0.001 1" density="100" friction="0.95 0.3 0.1" class="visual" material="knob_front_right_material"/>
          <geom class="collision" type="cylinder" pos="0.335880 -0.324753 0.327538" size="0.036232754588127136 0.010816382244229317" quat="0.7071068286895752 0.7071067690849304 0.0 0.0"/>
          <geom class="collision" type="box" pos="0.335880 -0.343787 0.327339" size="0.008053257130086422 0.008392240852117538 0.031496912240982056" quat="1.0 0.0 0.0 0.0"/>
        </body>
        <body name="knob_rear_left">
          <joint axis="0.0 -1.0 0.0" pos="-0.203008 -0.330690 0.327538" limited="true" name="knob_rear_left_joint" range="0.0 3.141592653589793" type="hinge" damping="0.05" armature="0.001"/>
          <geom mesh="knob_rear_left_vis" type="mesh" solimp="0.998 0.998 0.001" solref="0.001 1" density="100" friction="0.95 0.3 0.1" class="visual" material="knob_rear_left_material"/>
          <geom class="collision" type="cylinder" pos="-0.202941 -0.324753 0.327538" size="0.036232754588127136 0.010816382244229317" quat="0.7071068286895752 0.7071067690849304 0.0 0.0"/>
          <geom class="collision" type="box" pos="-0.202941 -0.343787 0.327339" size="0.008053257130086422 0.008392240852117538 0.031496912240982056" quat="1.0 0.0 0.0 0.0"/>
        </body>
        <body name="knob_rear_right">
          <joint axis="0.0 -1.0 0.0" pos="0.201313 -0.330690 0.327538" limited="true" name="knob_rear_right_joint" range="0.0 3.141592653589793" type="hinge" damping="0.05" armature="0.001"/>
          <geom mesh="knob_rear_right_vis" type="mesh" solimp="0.998 0.998 0.001" solref="0.001 1" density="100" friction="0.95 0.3 0.1" class="visual" material="knob_rear_right_material"/>
          <geom class="collision" type="cylinder" pos="0.201402 -0.324753 0.327538" size="0.036232754588127136 0.010816382244229317" quat="0.7071068286895752 0.7071067690849304 0.0 0.0"/>
          <geom class="collision" type="box" pos="0.201402 -0.343787 0.327339" size="0.008053257130086422 0.008392240852117538 0.031496912240982056" quat="1.0 0.0 0.0 0.0"/>
        </body>
        <body name="Door001">
          <joint axis="1.0 0.0 0.0" pos="0.000012 -0.284227 -0.373612" limited="true" name="Door001_joint" range="0.0 1.5707963267948966" type="hinge" damping="1" frictionloss="1" armature=".01" stiffness="0.2" springref="-20"/>
          <geom mesh="Door001_vis" type="mesh" solimp="0.998 0.998 0.001" solref="0.001 1" density="100" friction="0.95 0.3 0.1" class="visual" material="Door001_material"/>
          <geom class="collision" type="box" pos="0.000239 -0.300855 -0.072100" size="0.40654194355010986 0.013618663884699345 0.29955747723579407" quat="1.0 0.0 0.0 0.0"/>
          <geom class="collision" type="cylinder" pos="-0.000317 -0.385602 0.164850" size="0.012389549054205418 0.16732807457447052" quat="0.7071068286895752 -0.0 0.7071067690849304 0.0"/>
          <geom class="collision" type="cylinder" pos="-0.188220 -0.337961 0.164850" size="0.012389549054205418 0.024187367409467697" quat="0.5000000596046448 -0.5 0.5 0.4999999701976776"/>
          <geom class="collision" type="cylinder" pos="-0.177831 -0.373581 0.164850" size="0.012389549054205418 0.024187367409467697" quat="0.3057507872581482 -0.6375864744186401 0.3057507872581482 0.6375864148139954"/>
          <geom class="collision" type="cylinder" pos="0.177803 -0.373581 0.164850" size="0.012389549054205418 0.024187367409467697" quat="0.3057507872581482 -0.6375864744186401 -0.3057507872581482 -0.6375864148139954"/>
          <geom class="collision" type="cylinder" pos="0.188192 -0.337961 0.164850" size="0.012389549054205418 0.024187367409467697" quat="0.5000000596046448 -0.5 -0.5 -0.4999999701976776"/>
        </body>
        <body name="Knob001">
          <joint axis="0.0 1.0 0.0" pos="-0.067992 -0.330690 0.327500" limited="true" name="Knob001_joint" range="0.0 5.235987755982989" type="hinge" damping="0.05" armature="0.001"/>
          <geom mesh="Knob001_vis" type="mesh" solimp="0.998 0.998 0.001" solref="0.001 1" density="100" friction="0.95 0.3 0.1" class="visual" material="Knob001_material"/>
          <geom class="collision" type="cylinder" pos="-0.067896 -0.324753 0.327538" size="0.036232754588127136 0.010816382244229317" quat="0.7071068286895752 0.7071067690849304 0.0 0.0"/>
          <geom class="collision" type="box" pos="-0.067697 -0.343787 0.327538" size="0.008053257130086422 0.008392240852117538 0.031496912240982056" quat="0.7071068286895752 0.0 -0.7071067690849304 0.0"/>
        </body>
        <body name="Knob002">
          <joint axis="0.0 1.0 0.0" pos="0.066530 -0.330690 0.327505" limited="true" name="Knob002_joint" range="0.0 5.585053606381854" type="hinge" damping="0.05" armature="0.001"/>
          <geom mesh="Knob002_vis" type="mesh" solimp="0.998 0.998 0.001" solref="0.001 1" density="100" friction="0.95 0.3 0.1" class="visual" material="Knob002_material"/>
          <geom class="collision" type="cylinder" pos="0.066538 -0.324753 0.327538" size="0.036232754588127136 0.010816382244229317" quat="0.7071068286895752 0.7071067690849304 0.0 0.0"/>
          <geom class="collision" type="box" pos="0.066538 -0.343787 0.327339" size="0.008053257130086422 0.008392240852117538 0.031496912240982056" quat="1.0 0.0 0.0 0.0"/>
        </body>
        <body name="Shelf001">
          <joint axis="0.0 -1.0 0.0" pos="0.000705 0.006840 -0.074683" limited="true" name="Shelf001_joint" range="0.0 0.5" type="slide" damping="1" frictionloss="1" armature=".01" stiffness="0.05"/>
          <geom mesh="Shelf001_vis" type="mesh" solimp="0.998 0.998 0.001" solref="0.001 1" density="100" friction="0.95 0.3 0.1" class="visual" material="Shelf001_material"/>
          <geom class="collision" type="box" pos="0.000705 0.006840 -0.074683" size="0.36968109011650085 0.2670382261276245 0.004225022159516811" quat="1.0 0.0 0.0 0.0"/>
        </body>
        <geom class="region" name="reg_main" type="box" pos="-0.0004109999999999947 0.0411415 -0.021839000000000025" size="0.406403 0.3551085 0.494231"/>
        <geom class="region" name="reg_int" type="box" pos="-4.799999999999249e-05 0.015200999999999992 -0.07295200000000002" size="0.371435 0.29303999999999997 0.270125"/>
      </body>
    </body>
  </worldbody>
  <actuator>
    <motor name="knob_front_left_joint_actuator" joint="knob_front_left_joint" gear="10"/>
    <motor name="knob_front_right_joint_actuator" joint="knob_front_right_joint" gear="10"/>
    <motor name="knob_rear_left_joint_actuator" joint="knob_rear_left_joint" gear="10"/>
    <motor name="knob_rear_right_joint_actuator" joint="knob_rear_right_joint" gear="10"/>
    <motor name="Door001_joint_actuator" joint="Door001_joint" gear="70"/>
    <motor name="Knob001_joint_actuator" joint="Knob001_joint" gear="10"/>
    <motor name="Knob002_joint_actuator" joint="Knob002_joint" gear="10"/>
    <motor name="Shelf001_joint_actuator" joint="Shelf001_joint" gear="10"/>
  </actuator>
</mujoco>
