<mujoco model="model">
  <compiler angle="radian"/>
  <asset>
    <mesh file="visuals/Body001.obj" name="Body001_vis"/>
    <mesh file="visuals/Door001.obj" name="Door001_vis"/>
    <mesh file="visuals/Door001_Clear.obj" name="Door001_Clear_vis"/>
    <mesh file="visuals/Knob001.obj" name="Knob001_vis"/>
    <mesh file="visuals/Knob002.obj" name="Knob002_vis"/>
    <mesh file="visuals/Shelf001.obj" name="Shelf001_vis"/>
    <mesh file="visuals/Shelf002.obj" name="Shelf002_vis"/>
    <texture file="visuals/T_BC001.png" name="Body001_material" type="2d"/>
    <material name="Body001_material" rgba="1 1 1 1.0" texture="Body001_material" shininess="0.141421377658844" specular="0.3103448502657381"/>
    <texture file="visuals/T_BC001.png" name="Door001_material" type="2d"/>
    <material name="Door001_material" rgba="1 1 1 1.0" texture="Door001_material" shininess="0.141421377658844" specular="0.3103448502657381"/>
    <texture file="visuals/T_BC001.png" name="Door001_Clear_material" type="2d"/>
    <material name="Door001_Clear_material" rgba="1 1 1 0.6456692814826965" texture="Door001_Clear_material" shininess="0.5" specular="0.3103448502657381"/>
    <texture file="visuals/T_BC001.png" name="Knob001_material" type="2d"/>
    <material name="Knob001_material" rgba="1 1 1 1.0" texture="Knob001_material" shininess="0.141421377658844" specular="0.3103448502657381"/>
    <texture file="visuals/T_BC001.png" name="Knob002_material" type="2d"/>
    <material name="Knob002_material" rgba="1 1 1 1.0" texture="Knob002_material" shininess="0.141421377658844" specular="0.3103448502657381"/>
    <texture file="visuals/T_BC001.png" name="Shelf001_material" type="2d"/>
    <material name="Shelf001_material" rgba="1 1 1 1.0" texture="Shelf001_material" shininess="0.141421377658844" specular="0.3103448502657381"/>
    <texture file="visuals/T_BC001.png" name="Shelf002_material" type="2d"/>
    <material name="Shelf002_material" rgba="1 1 1 1.0" texture="Shelf002_material" shininess="0.141421377658844" specular="0.3103448502657381"/>
  </asset>
  <default>
    <default class="visual">
      <geom conaffinity="0" contype="0" group="1" type="mesh"/>
    </default>
    <default class="collision">
      <geom group="0" rgba="0.5 0 0 0.5"/>
    </default>
    <default class="spawn">
      <geom group="0" rgba="1 1 1 0.5" contype="0" conaffinity="0"/>
      <site group="0" rgba="1 1 1 0.5"/>
    </default>
    <default class="region">
      <geom group="1" conaffinity="0" contype="0" rgba="0 1 0 0"/>
    </default>
  </default>
  <worldbody>
    <body>
      <body name="object">
        <geom mesh="Body001_vis" type="mesh" solimp="0.998 0.998 0.001" solref="0.001 1" density="100" friction="0.95 0.3 0.1" class="visual" material="Body001_material"/>
        <geom class="collision" type="box" pos="-0.2557266056537628 0.029321052134037018 -0.08142778277397156" size="0.007219076156616211 0.19212980568408966 0.2130533903837204" quat="1.0 0.0 0.0 0.0"/>
        <geom class="collision" type="box" pos="-6.509595550596714e-06 -0.1163046732544899 0.17706026136875153" size="0.2923739552497864 0.04649493098258972 0.043837908655405045" quat="1.0 0.0 0.0 0.0"/>
        <geom class="collision" type="box" pos="-2.9103830456733704e-11 -0.17321911454200745 0.24082490801811218" size="0.2932053804397583 0.010303128510713577 0.05880128592252731" quat="1.0 0.0 0.0 0.0"/>
        <geom class="collision" type="box" pos="0.2545583248138428 0.029321052134037018 -0.08142778277397156" size="0.007219076156616211 0.19212980568408966 0.2130533903837204" quat="1.0 0.0 0.0 0.0"/>
        <geom class="collision" type="box" pos="-0.0002587692579254508 0.2155100405216217 -0.08142778277397156" size="0.2494407445192337 0.005964251700788736 0.2130533903837204" quat="1.0 0.0 0.0 0.0"/>
        <geom class="collision" type="box" pos="-0.0005369999562390149 0.029321052134037018 -0.29008376598358154" size="0.24735546112060547 0.19212980568408966 0.006446285638958216" quat="1.0 0.0 0.0 0.0"/>
        <geom class="collision" type="box" pos="-0.0005370043218135834 0.029321052134037018 0.12525540590286255" size="0.24735546112060547 0.19212980568408966 0.006446285638958216" quat="1.0 0.0 0.0 0.0"/>
        <geom class="collision" type="box" pos="-0.23759418725967407 0.018307354301214218 0.011513151228427887" size="0.017211025580763817 0.1721840351819992 0.007144071627408266" quat="1.0 0.0 0.0 0.0"/>
        <geom class="collision" type="box" pos="0.2374390959739685 0.018307354301214218 0.011513151228427887" size="0.017211025580763817 0.1721840351819992 0.007144071627408266" quat="1.0 0.0 0.0 0.0"/>
        <geom class="collision" type="box" pos="0.2374390959739685 0.018307354301214218 -0.1430685669183731" size="0.017211025580763817 0.1721840351819992 0.007144071627408266" quat="1.0 0.0 0.0 0.0"/>
        <geom class="collision" type="box" pos="-0.23759418725967407 0.018307354301214218 -0.1430685669183731" size="0.017211025580763817 0.1721840351819992 0.007144071627408266" quat="1.0 0.0 0.0 0.0"/>
        <body name="Door001">
          <joint axis="1.0 0.0 0.0" pos="0.0006216343608684838 -0.1831049919128418 -0.29941368103027344" limited="true" name="Door001_joint" range="0.0 1.15" type="hinge" damping="5" frictionloss="1" armature=".01" stiffness="0.05" springref="-0.1"/>
          <geom mesh="Door001_vis" type="mesh" solimp="0.998 0.998 0.001" solref="0.001 1" density="100" friction="0.95 0.3 0.1" class="visual" material="Door001_material"/>
          <geom class="collision" type="cylinder" pos="-8.794665336608887e-05 -0.21169334650039673 0.14926202595233917" size="0.009907918982207775 0.24421831965446472" quat="0.4999999701976776 0.5 0.5 0.5"/>
          <geom class="collision" type="box" pos="-1.2456439435482025e-08 -0.17467117309570312 -0.23719945549964905" size="0.2932053804397583 0.008851069957017899 0.052889686077833176" quat="1.0 0.0 0.0 0.0"/>
          <geom class="collision" type="box" pos="-0.25014397501945496 -0.20337994396686554 0.14951643347740173" size="0.004824848845601082 0.017637573182582855 0.009651458822190762" quat="1.0 0.0 0.0 0.0"/>
          <geom class="collision" type="box" pos="0.250265508890152 -0.20337994396686554 0.14951643347740173" size="0.004824848845601082 0.017637573182582855 0.009651458822190762" quat="1.0 0.0 0.0 0.0"/>
          <geom class="collision" type="box" pos="-0.26039251685142517 -0.17467117309570312 -0.05768945813179016" size="0.032812878489494324 0.008851069957017899 0.23239968717098236" quat="1.0 0.0 0.0 0.0"/>
          <geom class="collision" type="box" pos="-1.2456439435482025e-08 -0.17467117309570312 0.12527859210968018" size="0.2932053804397583 0.008851069957017899 0.049431636929512024" quat="1.0 0.0 0.0 0.0"/>
          <geom class="collision" type="box" pos="0.2616102993488312 -0.17467117309570312 -0.05768945813179016" size="0.03159508854150772 0.008851069957017899 0.23239968717098236" quat="1.0 0.0 0.0 0.0"/>
          <body name="Door001_Clear">
            <geom mesh="Door001_Clear_vis" type="mesh" solimp="0.998 0.998 0.001" solref="0.001 1" density="100" friction="0.95 0.3 0.1" class="visual" material="Door001_Clear_material"/>
            <geom class="collision" type="box" pos="-1.990207238122821e-05 -0.17772334814071655 -0.05382537841796875" size="0.23479610681533813 0.0013434074353426695 0.13202042877674103" quat="1.0 0.0 0.0 0.0"/>
          </body>
        </body>
        <body name="Knob001">
          <joint axis="0.0 1.0 0.0" pos="-0.23521986603736877 -0.1900043934583664 0.2394142597913742" limited="true" name="Knob001_joint" range="0.0 4.014257279586958" type="hinge" damping="0.05" armature="0.001"/>
          <geom mesh="Knob001_vis" type="mesh" solimp="0.998 0.998 0.001" solref="0.001 1" density="100" friction="0.95 0.3 0.1" class="visual" material="Knob001_material"/>
          <geom class="collision" type="cylinder" pos="-0.2349817454814911 -0.19150155782699585 0.23961703479290009" size="0.01495257019996643 0.005839786492288113" quat="0.7071068286895752 0.7071067690849304 0.0 0.0"/>
        </body>
        <body name="Knob002">
          <joint axis="0.0 1.0 0.0" pos="0.23979756236076355 -0.1900043934583664 0.2394142597913742" limited="true" name="Knob002_joint" range="0.0 3.2288591161895095" type="hinge" damping="0.05" armature="0.001"/>
          <geom mesh="Knob002_vis" type="mesh" solimp="0.998 0.998 0.001" solref="0.001 1" density="100" friction="0.95 0.3 0.1" class="visual" material="Knob002_material"/>
          <geom class="collision" type="cylinder" pos="0.23987719416618347 -0.19116546213626862 0.23961703479290009" size="0.01495257019996643 0.005529541056603193" quat="0.7071068286895752 0.7071067690849304 0.0 0.0"/>
        </body>
        <body name="Shelf001">
          <joint axis="0.0 -1.0 0.0" pos="1.2777924212059588e-06 0.03167494758963585 0.022441715002059937" limited="true" name="Shelf001_joint" range="0.0 0.25" type="slide" damping="1" frictionloss="1" armature=".01" stiffness="0.05"/>
          <geom mesh="Shelf001_vis" type="mesh" solimp="0.998 0.998 0.001" solref="0.001 1" density="100" friction="0.95 0.3 0.1" class="visual" material="Shelf001_material"/>
          <geom class="collision" type="box" pos="-0.00010812358232215047 0.030966006219387054 0.02371634542942047" size="0.2379271686077118 0.1573076695203781 0.002953834133222699" quat="1.0 0.0 0.0 0.0"/>
        </body>
        <body name="Shelf002">
          <joint axis="0.0 -1.0 0.0" pos="1.359748807772121e-06 0.009698130190372467 -0.13216164708137512" limited="true" name="Shelf002_joint" range="0.0 0.25" type="slide" damping="1" frictionloss="1" armature=".01" stiffness="0.05"/>
          <geom mesh="Shelf002_vis" type="mesh" solimp="0.998 0.998 0.001" solref="0.001 1" density="100" friction="0.95 0.3 0.1" class="visual" material="Shelf002_material"/>
          <geom class="collision" type="box" pos="-0.0005146542680449784 0.00798073597252369 -0.13109521567821503" size="0.23827512562274933 0.12442532181739807 0.0027252323925495148" quat="1.0 0.0 0.0 0.0"/>
        </body>
        <geom class="region" name="reg_main" type="box" pos="0.0 0.018976017832756042 0.0" size="0.2932053804397583 0.20249825716018677 0.2996262013912201"/>
        <geom class="region" name="reg_int" type="box" pos="-0.00048028677701950073 0.022313199937343597 -0.0817028246819973" size="0.24857208877801895 0.18341296166181564 0.20035028830170631"/>
      </body>
    </body>
  </worldbody>
  <actuator>
    <motor name="Door001_joint_actuator" joint="Door001_joint" gear="50"/>
    <motor name="Knob001_joint_actuator" joint="Knob001_joint" gear="15"/>
    <motor name="Knob002_joint_actuator" joint="Knob002_joint" gear="15"/>
    <motor name="Shelf001_joint_actuator" joint="Shelf001_joint" gear="10"/>
    <motor name="Shelf002_joint_actuator" joint="Shelf002_joint" gear="10"/>
  </actuator>
</mujoco>
