<?xml version='1.0' encoding='UTF-8'?>
<mujoco model="model">
  <compiler angle="radian"/>
  <asset>
    <mesh file="visuals/Body001.obj" name="Body001_vis"/>
    <mesh file="visuals/Button001.obj" name="Button001_vis"/>
    <mesh file="visuals/Handle001.obj" name="Handle001_vis"/>
    <mesh file="visuals/Lever001.obj" name="Lever001_vis"/>
    <mesh file="visuals/Lid001.obj" name="Lid001_vis"/>
    <texture file="visuals/T_BC001.png" name="Body001_material" type="2d"/>
    <material name="Body001_material" rgba="1 1 1 1.0" texture="Body001_material" shininess="0.5" specular="0.3103448502657381"/>
    <texture file="visuals/T_BC001.png" name="Handle001_material" type="2d"/>
    <material name="Handle001_material" rgba="1 1 1 1.0" texture="Handle001_material" shininess="0.5" specular="0.3103448502657381"/>
    <texture file="visuals/T_BC001.png" name="Button001_material" type="2d"/>
    <material name="Button001_material" rgba="1 1 1 1.0" texture="Button001_material" shininess="0.5" specular="0.3103448502657381"/>
    <texture file="visuals/T_BC001.png" name="Lever001_material" type="2d"/>
    <material name="Lever001_material" rgba="1 1 1 1.0" texture="Lever001_material" shininess="0.5" specular="0.3103448502657381"/>
    <texture file="visuals/T_BC001.png" name="Lid001_material" type="2d"/>
    <material name="Lid001_material" rgba="1 1 1 1.0" texture="Lid001_material" shininess="0.5" specular="0.3103448502657381"/>
  </asset>
  <default>
    <default class="visual">
      <geom conaffinity="0" contype="0" group="1" type="mesh"/>
    </default>
    <default class="collision">
      <geom group="0" rgba="0.5 0 0 0.5"/>
    </default>
    <default class="spawn">
      <geom group="0" rgba="1 1 1 0.5" contype="0" conaffinity="0"/>
      <site group="0" rgba="1 1 1 0.5"/>
    </default>
    <default class="region">
      <geom group="1" conaffinity="0" contype="0" rgba="0 1 0 0"/>
    </default>
  </default>
  <worldbody>
    <body>
      <body name="object">
        <geom mesh="Body001_vis" type="mesh" solimp="0.998 0.998 0.001" solref="0.001 1" density="100" friction="0.95 0.3 0.1" class="visual" material="Body001_material"/>
        <geom class="collision" type="cylinder" pos="-0.01461932621896267 0.0007243109866976738 -0.11814795434474945" size="0.11004693806171417 0.015182497911155224" quat="1.0 0.0 0.0 0.0"/>
        <body name="Handle001">
          <joint axis="0.0 0.0 1.0" pos="0.006025180220603943 -2.5331974029541016e-07 -0.004361510276794434" limited="true" name="Handle001_joint" range="0.0 0.1" type="slide" damping="1" frictionloss="1" armature=".01" stiffness="0.05"/>
          <geom mesh="Handle001_vis" type="mesh" solimp="0.998 0.998 0.001" solref="0.001 1" density="100" friction="0.95 0.3 0.1" class="visual" material="Handle001_material"/>
          <geom class="collision" type="cylinder" pos="-0.01461932621896267 0.0007243109866976738 -0.10015259683132172" size="0.0968940481543541 0.0019463932840153575" quat="1.0 0.0 0.0 0.0"/>
          <geom class="collision" type="box" pos="-0.013354918919503689 -0.06037257984280586 0.03936608135700226" size="0.01927150972187519 0.0056108939461410046 0.047147102653980255" quat="0.9755426645278931 -0.21981018781661987 -0.0 0.0"/>
          <geom class="collision" type="box" pos="-0.013354918919503689 -0.0878482535481453 -0.050580400973558426" size="0.01927150972187519 0.005610893480479717 0.05105685070157051" quat="0.9974405765533447 -0.07150019705295563 -0.0 0.0"/>
          <geom class="collision" type="box" pos="-0.04784507676959038 -0.08092913031578064 -0.050580404698848724" size="0.01927150972187519 0.005610893480479717 0.05105685070157051" quat="0.9772441983222961 -0.07005245238542557 0.0143154701218009 -0.1997033953666687"/>
          <geom class="collision" type="box" pos="-0.03706572949886322 -0.05565626174211502 0.03936608135700226" size="0.01927150972187519 0.005610893480479717 0.04714709892868996" quat="0.9557897448539734 -0.21535931527614594 0.04400944337248802 -0.1953190416097641"/>
          <geom class="collision" type="box" pos="-0.05806240439414978 -0.040918417274951935 0.03936608135700226" size="0.01927150972187519 0.005610893480479717 0.04714709892868996" quat="0.8924745917320251 -0.20109312236309052 0.08875828236341476 -0.39391955733299255"/>
          <geom class="collision" type="box" pos="-0.07836207002401352 -0.059434227645397186 -0.050580404698848724" size="0.01927150972187519 0.005610893480479717 0.05105685070157051" quat="0.912507951259613 -0.06541191786527634 0.028871437534689903 -0.4027617275714874"/>
          <geom class="collision" type="box" pos="-0.09745042026042938 -0.02642616257071495 -0.050580404698848724" size="0.01927150972187519 0.005610893480479717 0.05105685070157051" quat="0.8033521771430969 -0.05758723244071007 0.04237911477684975 -0.5911962389945984"/>
          <geom class="collision" type="box" pos="-0.07121779024600983 -0.01825539581477642 0.03936608135700226" size="0.01927150972187519 0.005610893480479717 0.04714709892868996" quat="0.7857152819633484 -0.1770380139350891 0.1302843540906906 -0.578217089176178"/>
          <geom class="collision" type="box" pos="-0.07348096370697021 0.008224783465266228 0.03936608135700226" size="0.01927150972187519 0.005610893480479717 0.04714709892868996" quat="0.6391790509223938 -0.14402034878730774 0.1660560518503189 -0.7369760274887085"/>
          <geom class="collision" type="box" pos="-0.10068050026893616 0.01211029663681984 -0.050580404698848724" size="0.01927150972187519 0.005610893480479717 0.05105685070157051" quat="0.6535266637802124 -0.04684718698263168 0.05401499196887016 -0.75351881980896"/>
          <geom class="collision" type="box" pos="-0.08778393268585205 0.047165397554636 -0.050580404698848724" size="0.01927150785923004 0.005610893480479717 0.05105685070157051" quat="0.4783940017223358 -0.034293025732040405 0.06273964792490005 -0.8752296566963196"/>
          <geom class="collision" type="box" pos="-0.06465733051300049 0.03233056887984276 0.03936608135700226" size="0.01927150785923004 0.005610893480479717 0.04714709892868996" quat="0.46789127588272095 -0.1054256483912468 0.19287791848182678 -0.8560147881507874"/>
          <geom class="collision" type="box" pos="-0.04682711511850357 0.050453394651412964 0.03936608135700226" size="0.01927150972187519 0.005610893480479717 0.04714709892868996" quat="0.2771659791469574 -0.06245126575231552 0.2107517570257187 -0.9353408813476562"/>
          <geom class="collision" type="box" pos="-0.06179620698094368 0.07349331676959991 -0.050580404698848724" size="0.01927150972187519 0.005610893480479717 0.05105685070157051" quat="0.28338751196861267 -0.020314252004027367 0.06855370104312897 -0.9563363790512085"/>
          <geom class="collision" type="box" pos="-0.027007251977920532 0.08683008700609207 -0.050580404698848724" size="0.01927150972187519 0.0056108939461410046 0.05105685070157051" quat="0.07414495199918747 -0.005314982030540705 0.0713023841381073 -0.9946810007095337"/>
          <geom class="collision" type="box" pos="-0.022933734580874443 0.05965806543827057 0.03936608135700226" size="0.01927150972187519 0.005610893480479717 0.04714709892868996" quat="0.07251717150211334 -0.01633962243795395 0.21920190751552582 -0.9728436470031738"/>
          <geom class="collision" type="box" pos="0.0017953524366021156 0.05835829675197601 0.03936608135700226" size="0.01927150972187519 0.005610893480479717 0.04714709892868996" quat="0.12853960692882538 -0.02896265871822834 -0.21789368987083435 0.9670372605323792"/>
          <geom class="collision" type="box" pos="0.008972728624939919 0.08487993478775024 -0.050580404698848724" size="0.01927150972187519 0.005610893480479717 0.05105685070157051" quat="0.1314249336719513 -0.009421017952263355 -0.07087679207324982 0.9887442588806152"/>
          <geom class="collision" type="box" pos="0.04186876863241196 0.06806397438049316 -0.050580404698848724" size="0.01927150972187519 0.005610893480479717 0.05105685070157051" quat="0.3363957703113556 -0.024114081636071205 -0.0673111230134964 0.9390024542808533"/>
          <geom class="collision" type="box" pos="0.02442174404859543 0.046838659793138504 0.03936608135700226" size="0.01927150972187519 0.005610893480479717 0.04714709892868996" quat="0.3290105164051056 -0.07413291931152344 -0.20693181455135345 0.9183875322341919"/>
          <geom class="collision" type="box" pos="0.040716614574193954 0.026209238916635513 0.03936608135700226" size="0.01927150972187519 0.005610893480479717 0.04714709892868996" quat="0.5210679769515991 -0.11740747839212418 -0.18582776188850403 0.8247252106666565"/>
          <geom class="collision" type="box" pos="0.0655301958322525 0.03800748661160469 -0.050580404698848724" size="0.01927150972187519 0.005610893480479717 0.05105685070157051" quat="0.5327644348144531 -0.03819049522280693 -0.060446351766586304 0.8432376980781555"/>
          <geom class="collision" type="box" pos="0.07188587635755539 0.0030217221938073635 -0.035045772790908813" size="0.01927151158452034 0.0056108939461410046 0.035361744463443756" quat="0.6940592527389526 -0.04975270852446556 -0.05135120823979378 0.716358482837677"/>
          <geom class="collision" type="box" pos="0.04666148126125336 0.0022239089012145996 0.03936608135700226" size="0.01927151158452034 0.005610893480479717 0.04714709892868996" quat="0.6788218021392822 -0.15295268595218658 -0.15786685049533844 0.7006314992904663"/>
          <geom class="collision" type="box" pos="0.042037226259708405 -0.023271363228559494 0.03936608135700226" size="0.01927151158452034 0.005610893480479717 0.04714709892868996" quat="0.813357949256897 -0.18326649069786072 -0.12136665731668472 0.5386393666267395"/>
          <geom class="collision" type="box" pos="0.06733403354883194 -0.03399444743990898 -0.050580404698848724" size="0.01927150972187519 0.005610893480479717 0.05105685070157051" quat="0.8316153287887573 -0.05961323529481888 -0.03947834670543671 0.5507301092147827"/>
          <geom class="collision" type="box" pos="0.045532673597335815 -0.06490273028612137 -0.050580404698848724" size="0.01927150972187519 0.005610893480479717 0.05105685070157051" quat="0.9306759834289551 -0.06671427190303802 -0.025719348341226578 0.3587895333766937"/>
          <geom class="collision" type="box" pos="0.02708921581506729 -0.044537290930747986 0.03936608135700226" size="0.01927150972187519 0.005610893480479717 0.04714709892868996" quat="0.9102438688278198 -0.20509688556194305 -0.07906793057918549 0.3509126305580139"/>
          <geom class="collision" type="box" pos="0.007277412340044975 -0.05662263557314873 0.03936609625816345" size="0.01927150972187519 0.005610893480479717 0.047147102653980255" quat="0.9607177376747131 -0.21646980941295624 -0.03817503899335861 0.16942518949508667"/>
          <geom class="collision" type="box" pos="0.016675930470228195 -0.08244085311889648 -0.050580404698848724" size="0.01927151158452034 0.005610893480479717 0.05105685070157051" quat="0.9822828769683838 -0.07041365653276443 -0.012417641468346119 0.17322824895381927"/>
          <geom class="collision" type="box" pos="-0.07533188164234161 0.00254449644125998 0.050541434437036514" size="0.016298513859510422 0.01895124651491642 0.030848830938339233" quat="0.9998403787612915 3.754018429447115e-09 -0.017866216599941254 2.0973017100800462e-08"/>
          <geom class="collision" type="box" pos="0.10458327829837799 0.00278834393247962 0.056553855538368225" size="0.013974262401461601 0.010425304993987083 0.011696386151015759" quat="0.8557707667350769 0.0 0.51735520362854 0.0"/>
          <geom class="collision" type="box" pos="0.051533207297325134 0.00278834393247962 0.0790233463048935" size="0.015717824921011925 0.010425304993987083 0.01086315419524908" quat="0.9884176254272461 0.0 -0.15175822377204895 0.0"/>
          <geom class="collision" type="box" pos="0.07131754606962204 0.00278834393247962 0.08053111284971237" size="0.014116673730313778 0.010425304993987083 0.010394532233476639" quat="0.9849125742912292 0.0 0.1730526238679886 0.0"/>
          <geom class="collision" type="box" pos="0.10692184418439865 0.00278834393247962 0.014505917206406593" size="0.029614944010972977 0.010425304993987083 0.012280195951461792" quat="0.6486070156097412 0.0 0.7611234784126282 0.0"/>
          <geom class="collision" type="box" pos="0.09363839030265808 0.00278834393247962 -0.039925891906023026" size="0.030212007462978363 0.010425304993987083 0.012280197814106941" quat="0.582497775554657 0.0 0.8128322958946228 0.0"/>
          <geom class="collision" type="box" pos="0.08776570111513138 0.002788345329463482 0.06953726708889008" size="0.014116673730313778 0.010425304993987083 0.008028846234083176" quat="0.9435935020446777 -3.7857370571714455e-09 0.3311062157154083 2.154616574046031e-08"/>
          <body name="Button001">
            <joint axis="-0.6293202638626099 0.0 -0.7771461606025696" pos="0.09966688603162766 0.0027082753367722034 0.08179624378681183" limited="true" name="Button001_joint" range="0.0 0.0015" type="slide" damping="1" frictionloss="1" armature=".01" stiffness="0.05" springref="-0.8"/>
            <geom mesh="Button001_vis" type="mesh" solimp="0.998 0.998 0.001" solref="0.001 1" density="100" friction="0.95 0.3 0.1" class="visual" material="Button001_material"/>
            <geom class="collision" type="box" pos="0.09987294673919678 0.002708274871110916 0.08204381167888641" size="0.007922406308352947 0.005134806036949158 0.0014202957972884178" quat="0.9435935020446777 -3.7857370571714455e-09 0.3311062157154083 2.154616574046031e-08"/>
          </body>
          <body name="Lever001">
            <joint axis="0.0 0.0 -1.0" pos="0.09705869108438492 0.003606777172535658 -0.07823503017425537" limited="true" name="Lever001_joint" range="0.0 0.01" type="slide" damping="1" frictionloss="1" armature=".01" stiffness="1" springref="-0.4"/>
            <geom mesh="Lever001_vis" type="mesh" solimp="0.998 0.998 0.001" solref="0.001 1" density="100" friction="0.95 0.3 0.1" class="visual" material="Lever001_material"/>
          </body>
          <body name="Lid001">
            <joint axis="0.0 1.0 0.0" pos="0.027506254613399506 -2.7567148208618164e-07 0.08271406590938568" limited="true" name="Lid001_joint" range="0.0 1.3962634015954636" type="hinge" damping="1" frictionloss="1" armature=".01" stiffness="0.05"/>
            <geom mesh="Lid001_vis" type="mesh" solimp="0.998 0.998 0.001" solref="0.001 1" density="100" friction="0.95 0.3 0.1" class="visual" material="Lid001_material"/>
            <geom class="collision" type="cylinder" pos="-0.013670741580426693 -2.7567148208618164e-07 0.09330868721008301" size="0.037384744733572006 0.004005928058177233" quat="1.0 0.0 0.0 0.0"/>
            <geom class="collision" type="cylinder" pos="-0.013670741580426693 -2.7567148208618164e-07 0.10119523853063583" size="0.03063269518315792 0.004041273146867752" quat="1.0 0.0 0.0 0.0"/>
            <geom class="collision" type="cylinder" pos="-0.013670741580426693 -2.7567148208618164e-07 0.10837311297655106" size="0.022812068462371826 0.0030095227994024754" quat="1.0 0.0 0.0 0.0"/>
            <geom class="collision" type="cylinder" pos="-0.013670741580426693 -2.7567148208618164e-07 0.11487813293933868" size="0.017764342948794365 0.0035840673372149467" quat="1.0 0.0 0.0 0.0"/>
            <geom class="collision" type="cylinder" pos="-0.013670741580426693 -2.7567148208618164e-07 0.12095686793327332" size="0.01356508582830429 0.0027368408627808094" quat="1.0 0.0 0.0 0.0"/>
            <geom class="collision" type="cylinder" pos="-0.013670741580426693 -2.7567148208618164e-07 0.12683629989624023" size="0.007063134573400021 0.0032757692970335484" quat="1.0 0.0 0.0 0.0"/>
            <geom class="collision" type="cylinder" pos="0.005034658592194319 0.001037760404869914 0.12239812314510345" size="0.01044171117246151 0.001178942620754242" quat="0.7071068286895752 0.7071067690849304 -1.5700924318127872e-16 -5.9269340452702814e-24"/>
          </body>
        </body>
        <geom class="region" name="reg_main" type="box" pos="1.862645149230957e-09 0.0 0.0" size="0.12172295898199081 0.10804611444473267 0.1327790915966034"/>
      </body>
    </body>
  </worldbody>
  <actuator>
    <motor name="Handle001_joint_actuator" joint="Handle001_joint" gear="10"/>
    <motor name="Button001_joint_actuator" joint="Button001_joint" gear="0.5"/>
    <motor name="Lever001_joint_actuator" joint="Lever001_joint" gear="0.5"/>
    <motor name="Lid001_joint_actuator" joint="Lid001_joint" gear="0.5"/>
  </actuator>
</mujoco>
