<mujoco model="model">
  <compiler angle="radian"/>
  <asset>
    <mesh file="visuals/Blade001.obj" name="Blade001_vis"/>
    <mesh file="visuals/Body001.obj" name="Body001_vis"/>
    <mesh file="visuals/Button001.obj" name="Button001_vis"/>
    <mesh file="visuals/Jug001.obj" name="Jug001_vis"/>
    <mesh file="visuals/Jug001_Clear.obj" name="Jug001_Clear_vis"/>
    <mesh file="visuals/Knob001.obj" name="Knob001_vis"/>
    <mesh file="visuals/Lid001.obj" name="Lid001_vis"/>
    <texture file="visuals/T_BC001.png" name="Body001_material" type="2d"/>
    <material name="Body001_material" rgba="1 1 1 1.0" texture="Body001_material" shininess="0.4472135901451111" specular="0.3103448502657381"/>
    <texture file="visuals/T_BC001.png" name="Button001_material" type="2d"/>
    <material name="Button001_material" rgba="1 1 1 1.0" texture="Button001_material" shininess="0.4472135901451111" specular="0.3103448502657381"/>
    <texture file="visuals/T_BC001.png" name="Jug001_material" type="2d"/>
    <material name="Jug001_material" rgba="1 1 1 1.0" texture="Jug001_material" shininess="0.4472135901451111" specular="0.3103448502657381"/>
    <texture file="visuals/T_BC001.png" name="Blade001_material" type="2d"/>
    <material name="Blade001_material" rgba="1 1 1 1.0" texture="Blade001_material" shininess="0.4472135901451111" specular="0.3103448502657381"/>
    <texture file="visuals/T_BC001.png" name="Jug001_Clear_material" type="2d"/>
    <material name="Jug001_Clear_material" rgba="1 1 1 0.05000000074505806" texture="Jug001_Clear_material" shininess="0.4472135901451111" specular="0.3103448502657381"/>
    <texture file="visuals/T_BC001.png" name="Lid001_material" type="2d"/>
    <material name="Lid001_material" rgba="1 1 1 1.0" texture="Lid001_material" shininess="0.4472135901451111" specular="0.3103448502657381"/>
    <texture file="visuals/T_BC001.png" name="Knob001_material" type="2d"/>
    <material name="Knob001_material" rgba="1 1 1 1.0" texture="Knob001_material" shininess="0.4472135901451111" specular="0.3103448502657381"/>
  </asset>
  <default>
    <default class="visual">
      <geom conaffinity="0" contype="0" group="1" type="mesh"/>
    </default>
    <default class="collision">
      <geom group="0" rgba="0.5 0 0 0.5"/>
    </default>
    <default class="spawn">
      <geom group="0" rgba="1 1 1 0.5" contype="0" conaffinity="0"/>
      <site group="0" rgba="1 1 1 0.5"/>
    </default>
    <default class="region">
      <geom group="1" conaffinity="0" contype="0" rgba="0 1 0 0"/>
    </default>
  </default>
  <worldbody>
    <body>
      <body name="object">
        <geom mesh="Body001_vis" type="mesh" solimp="0.998 0.998 0.001" solref="0.001 1" density="100" friction="0.95 0.3 0.1" class="visual" material="Body001_material"/>
        <geom class="collision" type="box" pos="-0.045048 -0.078712 -0.096466" size="0.006290201563388109 0.004342056345194578 0.09979216754436493" quat="0.9987657070159912 -0.04966913163661957 1.1028762711222566e-17 -3.0471712783511055e-24"/>
        <geom class="collision" type="box" pos="0.053350 -0.028974 -0.096466" size="0.031314998865127563 0.0043420568108558655 0.09979217499494553" quat="0.8261741399765015 -0.04108605533838272 -0.02790989726781845 0.5612212419509888"/>
        <geom class="collision" type="box" pos="0.038168 0.053296 -0.096466" size="0.03131500259041786 0.004342056345194578 0.09979217499494553" quat="0.40196719765663147 -0.01999003440141678 -0.04546890780329704 0.9143059253692627"/>
        <geom class="collision" type="box" pos="-0.052105 0.071913 -0.096466" size="0.03131500259041786 0.0043420568108558655 0.09979217499494553" quat="0.20901905000209808 -0.010394622571766376 0.04856926202774048 -0.9766494035720825"/>
        <geom class="collision" type="box" pos="-0.098557 0.003447 -0.096466" size="0.03131500259041786 0.0043420568108558655 0.09979218244552612" quat="0.6908359527587891 -0.034355610609054565 0.03587077558040619 -0.7213034629821777"/>
        <geom class="collision" type="box" pos="-0.084709 -0.044661 -0.096466" size="0.03131500259041786 0.004342056345194578 0.09979218244552612" quat="0.8842520713806152 -0.043974295258522034 0.023092910647392273 -0.46436113119125366"/>
        <geom class="collision" type="box" pos="-0.063739 -0.065362 -0.096466" size="0.027003925293684006 0.0043420568108558655 0.09979218244552612" quat="0.9555090069770813 -0.0475178100168705 0.014459053985774517 -0.2907498776912689"/>
        <geom class="collision" type="box" pos="-0.088077 0.039432 -0.096466" size="0.03131500259041786 0.0043420568108558655 0.09979217499494553" quat="0.4993739724159241 -0.024834129959344864 0.043014995753765106 -0.8649616241455078"/>
        <geom class="collision" type="box" pos="-0.003997 0.077196 -0.096466" size="0.03131500259041786 0.0043420568108558655 0.09979217499494553" quat="0.1011553704738617 -0.005030520260334015 -0.04941392317414284 0.9936299920082092"/>
        <geom class="collision" type="box" pos="0.057332 0.015653 -0.096466" size="0.031314998865127563 0.0043420568108558655 0.09979217499494553" quat="0.6324239373207092 -0.03145076334476471 -0.03844309598207474 0.7730284333229065"/>
        <geom class="collision" type="box" pos="0.026247 -0.063799 -0.096466" size="0.03131500259041786 0.0043420568108558655 0.09979217499494553" quat="0.9503158926963806 -0.04725975915789604 -0.015282206237316132 0.30729907751083374"/>
        <geom class="collision" type="cylinder" pos="-0.068142 -0.047207 -0.224548" size="0.007523544132709503 0.004609951749444008" quat="1.0 0.0 0.0 0.0"/>
        <geom class="collision" type="cylinder" pos="-0.019868 0.000050 -0.207706" size="0.09451781958341599 0.012371077202260494" quat="1.0 0.0 0.0 0.0"/>
        <geom class="collision" type="cylinder" pos="0.028424 -0.047207 -0.224548" size="0.007523566018790007 0.004609973169863224" quat="1.0 0.0 0.0 0.0"/>
        <geom class="collision" type="cylinder" pos="-0.068142 0.047503 -0.224548" size="0.007523576728999615 0.004609983880072832" quat="1.0 0.0 0.0 0.0"/>
        <geom class="collision" type="cylinder" pos="0.028424 0.047503 -0.224548" size="0.007523587439209223 0.00460999459028244" quat="1.0 0.0 0.0 0.0"/>
        <geom class="collision" type="cylinder" pos="-0.019868 0.000050 -0.025456" size="0.0683380588889122 0.0018439501291140914" quat="1.0 0.0 0.0 0.0"/>
        <geom class="collision" type="box" pos="0.003604 -0.078712 -0.096466" size="0.007842416875064373 0.0043420568108558655 0.09979217499494553" quat="0.9987657070159912 -0.04966913163661957 1.1028762711222566e-17 -3.0471712783511055e-24"/>
        <geom class="collision" type="box" pos="-0.018790 -0.079134 -0.100702" size="0.020939840003848076 0.0043420568108558655 0.018625587224960327" quat="0.9987657070159912 -0.04966913163661957 1.1028762711222566e-17 -3.0471712783511055e-24"/>
        <geom class="collision" type="box" pos="-0.018790 -0.086433 -0.173695" size="0.020939840003848076 0.004321036394685507 0.021655265241861343" quat="0.9987657070159912 -0.04966913163661957 1.1028762711222566e-17 -3.0471712783511055e-24"/>
        <geom class="collision" type="box" pos="-0.018790 -0.071571 -0.024851" size="0.020939840003848076 0.0043420568108558655 0.024897079914808273" quat="0.9987657070159912 -0.04966913163661957 1.1028762711222566e-17 -3.0471712783511055e-24"/>
        <body name="Button001">
          <joint axis="0.0 1.0 0.0" pos="-0.019868 -0.085988 -0.135663" limited="true" name="Button001_joint" range="0.0 0.004" type="slide" damping="1" frictionloss="1" armature=".01" stiffness="0.05"/>
          <geom mesh="Button001_vis" type="mesh" solimp="0.998 0.998 0.001" solref="0.001 1" density="100" friction="0.95 0.3 0.1" class="visual" material="Button001_material"/>
          <geom class="collision" type="cylinder" pos="-0.019868 -0.085983 -0.135664" size="0.014364420436322689 0.006613458041101694" quat="0.7555490732192993 0.6550920605659485 1.1152972152003528e-17 -1.115296967046169e-17"/>
        </body>
        <body name="Jug001">
          <joint axis="0.0 0.0 1.0" pos="-0.019868 0.000050 0.002149" limited="true" name="Jug001_joint" range="0.0 0.1" type="slide" damping="1" frictionloss="1" armature=".01" stiffness="0.05"/>
          <geom mesh="Jug001_vis" type="mesh" solimp="0.998 0.998 0.001" solref="0.001 1" density="100" friction="0.95 0.3 0.1" class="visual" material="Jug001_material"/>
          <geom class="collision" type="cylinder" pos="-0.019868 0.000050 0.003015" size="0.04143597558140755 0.007566837128251791" quat="1.0 0.0 0.0 0.0"/>
          <geom class="collision" type="cylinder" pos="-0.019868 0.000050 0.013563" size="0.01418313104659319 0.012319022789597511" quat="1.0 0.0 0.0 0.0"/>
          <body name="Blade001">
            <joint axis="0.0 0.0 1.0" pos="-0.019868 -0.000233 0.029500" limited="false" name="Blade001_joint" range="0 360" type="hinge" damping="1" frictionloss="1" armature=".01" stiffness="0.05"/>
            <geom mesh="Blade001_vis" type="mesh" solimp="0.998 0.998 0.001" solref="0.001 1" density="100" friction="0.95 0.3 0.1" class="visual" material="Blade001_material"/>
            <geom class="collision" type="box" pos="-0.001835 0.017866 0.032646" size="0.01079723984003067 0.005815119948238134 0.000714024412445724" quat="0.9160147905349731 0.0469263419508934 -0.11247249692678452 0.3821842074394226"/>
            <geom class="collision" type="box" pos="-0.013021 0.006596 0.029729" size="0.005312731955200434 0.005815119948238134 0.0007140241796150804" quat="0.9225776791572571 0.01007954590022564 -0.024158546701073647 0.3849223256111145"/>
            <geom class="collision" type="box" pos="-0.037837 -0.018418 0.032503" size="0.01079723984003067 0.005815119948238134 0.000714024412445724" quat="0.3842061460018158 -0.10841871798038483 -0.04944855719804764 -0.9155248999595642"/>
            <geom class="collision" type="box" pos="-0.026683 -0.007095 0.029674" size="0.005312731955200434 0.005815119948238134 0.0007140241796150804" quat="0.38717636466026306 -0.02017034962773323 -0.012396342121064663 -0.9217016696929932"/>
            <geom class="collision" type="box" pos="-0.037848 0.017922 0.026378" size="0.01079723984003067 0.005815119948238134 0.000714024412445724" quat="0.3805498480796814 -0.11204993724822998 0.046787749975919724 0.9167538285255432"/>
            <geom class="collision" type="box" pos="-0.013052 -0.007093 0.029318" size="0.005312731955200434 0.005815119948238134 0.0007140241796150804" quat="0.9242292642593384 0.0055139996111392975 0.023519013077020645 -0.38107314705848694"/>
            <geom class="collision" type="box" pos="-0.001806 -0.018323 0.026475" size="0.01079723984003067 0.005815119948238134 0.000714024412445724" quat="0.917720377445221 0.0420127734541893 0.11199421435594559 -0.37878960371017456"/>
            <geom class="collision" type="box" pos="-0.026650 0.006661 0.029281" size="0.005312731955200434 0.005815119948238134 0.0007140241796150804" quat="0.38328221440315247 -0.023667166009545326 0.010098296217620373 0.9232727885246277"/>
            <geom class="collision" type="box" pos="-0.013052 -0.007093 0.029318" size="0.005312731955200434 0.005815119948238134 0.0007140241796150804" quat="0.9242292642593384 0.0055139996111392975 0.023519013077020645 -0.38107314705848694"/>
            <geom class="collision" type="box" pos="-0.019832 -0.000241 0.029511" size="0.004505713935941458 0.004514103289693594 0.0007243526051752269" quat="0.9257199764251709 0.0 -0.0 -0.37820965051651"/>
          </body>
          <body name="Jug001_Clear">
            <geom mesh="Jug001_Clear_vis" type="mesh" solimp="0.998 0.998 0.001" solref="0.001 1" density="100" friction="0.95 0.3 0.1" class="visual" material="Jug001_Clear_material"/>
            <geom class="collision" type="box" pos="0.061255 0.000057 0.102898" size="0.004797820001840591 0.021256864070892334 0.09871997684240341" quat="0.9994385838508606 -1.2363918643713552e-15 0.03350444138050079 4.501618189323153e-09"/>
            <geom class="collision" type="box" pos="0.041852 0.052946 0.102898" size="0.004797819536179304 0.02125686965882778 0.09871996939182281" quat="0.9382874965667725 -0.0115397023037076 0.031454458832740784 0.3442296087741852"/>
            <geom class="collision" type="box" pos="-0.008679 0.080977 0.102898" size="0.004797815345227718 0.021256867796182632 0.09871996939182281" quat="0.7561712265014648 -0.021907974034547806 0.0253493282943964 0.6535155177116394"/>
            <geom class="collision" type="box" pos="-0.064897 0.068757 0.102898" size="0.004797819536179304 0.021256865933537483 0.09871996194124222" quat="0.47799187898635864 -0.02942420355975628 0.016023846343159676 0.8777250051498413"/>
            <geom class="collision" type="box" pos="-0.098497 0.024738 0.102898" size="0.00479781674221158 0.021256865933537483 0.09871996194124222" quat="0.15259899199008942 -0.03311140090227127 0.005115590989589691 0.9877201318740845"/>
            <geom class="collision" type="box" pos="-0.095653 -0.032263 0.102898" size="0.004797815345227718 0.021256865933537483 0.09871996939182281" quat="0.20162884891033173 0.032815542072057724 0.006759255193173885 -0.9788888096809387"/>
            <geom class="collision" type="box" pos="-0.060111 -0.071508 0.102898" size="0.004797820001840591 0.021256867796182632 0.09871996194124222" quat="0.5076490640640259 0.028860589489340782 0.01701805181801319 -0.8609122633934021"/>
            <geom class="collision" type="box" pos="-0.003900 -0.080017 0.102898" size="0.004797819536179304 0.021256867796182632 0.09871997684240341" quat="0.7752306461334229 0.021146109327673912 0.02598826214671135 -0.6307891011238098"/>
            <geom class="collision" type="box" pos="0.044068 -0.050101 0.102898" size="0.004797819536179304 0.021256867796182632 0.0987199917435646" quat="0.9454727172851562 0.010860658250749111 0.03169533982872963 -0.32397347688674927"/>
            <geom class="collision" type="box" pos="0.057693 0.023930 0.102898" size="0.004797820001840591 0.021256865933537483 0.09871996194124222" quat="0.9884965419769287 -0.004944205284118652 0.03313766047358513 0.14748571813106537"/>
            <geom class="collision" type="box" pos="0.055896 -0.029060 0.102898" size="0.004797819536179304 0.021256867796182632 0.09871997684240341" quat="0.9829298257827759 0.006064509507268667 0.03295101597905159 -0.18090449273586273"/>
            <geom class="collision" type="box" pos="0.018750 -0.071676 0.102898" size="0.004797819536179304 0.02125686965882778 0.09871996194124222" quat="0.8598279356956482 0.017079556360840797 0.028824234381318092 -0.5094834566116333"/>
            <geom class="collision" type="box" pos="-0.037496 -0.079946 0.102898" size="0.004797819536179304 0.021256867796182632 0.09871996939182281" quat="0.6291347146034241 0.02603328973054886 0.02109065093100071 -0.7765738368034363"/>
            <geom class="collision" type="box" pos="-0.082947 -0.052784 0.102898" size="0.004797820001840591 0.021256867796182632 0.09871996939182281" quat="0.34387457370758057 0.031458817422389984 0.011527794413268566 -0.9384176731109619"/>
            <geom class="collision" type="box" pos="-0.102305 0.000903 0.102898" size="0.0047978186048567295 0.021256865933537483 0.09871996939182281" quat="0.0051720221526920795 -0.03350399434566498 0.00017338321777060628 0.9994251728057861"/>
            <geom class="collision" type="box" pos="-0.083019 0.052813 0.102898" size="0.004797820001840591 0.021256865933537483 0.09871997684240341" quat="0.3432343602180481 -0.03146668151021004 0.011506336741149426 0.9386520385742188"/>
            <geom class="collision" type="box" pos="-0.032816 0.080911 0.102898" size="0.004797820001840591 0.021256865933537483 0.09871996194124222" quat="0.6514542698860168 -0.025408880785107613 0.021838875487446785 0.7579477429389954"/>
            <geom class="collision" type="box" pos="0.023697 0.068851 0.102898" size="0.004797819536179304 0.02125686965882778 0.09871996939182281" quat="0.8772175908088684 -0.016055047512054443 0.02940719574689865 0.4789225459098816"/>
            <geom class="collision" type="box" pos="0.036124 -0.021711 0.006674" size="0.014097915031015873 0.013783157803118229 0.0020905467681586742" quat="0.983661949634552 1.4869330766664746e-10 -2.7213188300012625e-11 -0.18002544343471527"/>
            <geom class="collision" type="box" pos="0.012561 -0.050934 0.006674" size="0.014097914099693298 0.013783156871795654 0.0020905453711748123" quat="0.8787503838539124 1.3283457667156995e-10 -7.214734365490472e-11 -0.4772816002368927"/>
            <geom class="collision" type="box" pos="-0.027435 -0.060225 0.006674" size="0.014097915031015873 0.013783157803118229 0.002090544207021594" quat="0.6637383699417114 1.0033272823672945e-10 -1.1306464098304048e-10 -0.7479647994041443"/>
            <geom class="collision" type="box" pos="-0.064886 -0.040910 0.006674" size="0.014097915031015873 0.013783157803118229 0.0020905467681586742" quat="0.3605376183986664 5.449997050877009e-11 -1.4099650613719206e-10 -0.9327446818351746"/>
            <geom class="collision" type="box" pos="-0.080392 -0.004881 0.006674" size="0.014097915962338448 0.013783158734440804 0.0020905453711748123" quat="0.0375555194914341 5.67707729784428e-12 -1.5105791617564535e-10 -0.9992945194244385"/>
            <geom class="collision" type="box" pos="-0.070275 0.033330 0.006674" size="0.014097915031015873 0.013783157803118229 0.0020905467681586742" quat="0.29206669330596924 4.414969084765019e-11 1.445720348991486e-10 0.9563979506492615"/>
            <geom class="collision" type="box" pos="-0.039741 0.056710 0.006674" size="0.014097915962338448 0.013783158734440804 0.0020905453711748123" quat="0.5818083882331848 8.794792671906748e-11 1.229448071127237e-10 0.8133258819580078"/>
            <geom class="collision" type="box" pos="-0.000538 0.056623 0.006674" size="0.014097915962338448 0.013783158734440804 0.0020905467681586742" quat="0.8146055936813354 1.2313829123034026e-10 8.767690740096867e-11 0.5800153017044067"/>
            <geom class="collision" type="box" pos="0.030424 0.032299 0.006674" size="0.014097915031015873 0.013783157803118229 0.002090544207021594" quat="0.959339439868927 1.450167208538744e-10 4.266653350071259e-11 0.2822549343109131"/>
            <geom class="collision" type="box" pos="0.039827 0.004617 0.006674" size="0.014097917824983597 0.013783160597085953 0.0020905467681586742" quat="0.9991481900215149 1.5103426842522083e-10 6.238013577908319e-12 0.0412667915225029"/>
            <geom class="collision" type="box" pos="0.034170 0.025577 0.006674" size="0.014097915031015873 0.013783157803118229 0.00209054839797318" quat="0.9753949642181396 1.47443668385705e-10 3.3326119641685636e-11 0.22046473622322083"/>
            <geom class="collision" type="box" pos="0.015574 0.048135 0.006674" size="0.014097917824983597 0.013783160597085953 0.0020905453711748123" quat="0.8928526639938354 1.349663159011527e-10 6.807611419024084e-11 0.4503489136695862"/>
            <geom class="collision" type="box" pos="-0.021997 0.059917 0.006674" size="0.01418222114443779 0.01448780857026577 0.002090529538691044" quat="1.0 0.0 0.0 0.0"/>
            <geom class="collision" type="box" pos="-0.058689 0.046113 0.006674" size="0.014097915031015873 0.013783157803118229 0.0020905467681586742" quat="0.42588338255882263 6.437782251733637e-11 1.3676898502623658e-10 0.9047780632972717"/>
            <geom class="collision" type="box" pos="-0.078964 0.013435 0.006674" size="0.014097915031015873 0.013783157803118229 0.0020905467681586742" quat="0.1151188462972641 1.74017154852546e-11 1.5015806653639885e-10 0.9933516979217529"/>
            <geom class="collision" type="box" pos="-0.074892 -0.025883 0.006674" size="0.014097915962338448 0.013783158734440804 0.0020905467681586742" quat="0.21684034168720245 3.2778245395714833e-11 -1.4756643129665292e-10 -0.9762070775032043"/>
            <geom class="collision" type="box" pos="-0.047631 -0.054085 0.006674" size="0.014097915031015873 0.013783157803118229 0.0020905453711748123" quat="0.5225650072097778 7.899250004106406e-11 -1.2888151657008962e-10 -0.8525994420051575"/>
            <geom class="collision" type="box" pos="-0.005766 -0.058883 0.006674" size="0.014097917824983597 0.013783160597085953 0.002090544207021594" quat="0.7875469326972961 1.1904797980744064e-10 -9.31549282157107e-11 -0.6162546873092651"/>
            <geom class="collision" type="box" pos="0.028346 -0.036030 0.006674" size="0.014097915031015873 0.013783157803118229 0.0020905467681586742" quat="0.9503161907196045 1.436526592124565e-10 -4.7054967561299677e-11 -0.31128624081611633"/>
            <geom class="collision" type="box" pos="0.040032 -0.000355 0.005684" size="0.014097685925662518 0.013782928697764874 0.002090518129989505" quat="1.0 0.0 0.0 0.0"/>
            <geom class="collision" type="box" pos="0.112248 0.000079 0.117078" size="0.005383961834013462 0.007043835241347551 0.038118090480566025" quat="1.0 0.0 0.0 0.0"/>
            <geom class="collision" type="box" pos="0.108581 0.000079 0.166454" size="0.008588218130171299 0.007043835241347551 0.014595777727663517" quat="0.9973220229148865 -8.794946379248741e-16 -0.07313574850559235 -9.826434776982751e-09"/>
            <geom class="collision" type="box" pos="0.094501 0.000079 0.184478" size="0.008588218130171299 0.007043835241347551 0.014595777727663517" quat="0.9171411991119385 -8.441334687725541e-15 -0.398562490940094 -5.355040144650047e-08"/>
            <geom class="collision" type="box" pos="0.077726 0.000079 0.190361" size="0.008588218130171299 0.007043835241347551 0.014595777727663517" quat="0.5457764863967896 -6.594723411020714e-14 0.8379307985305786 1.1258333643127116e-07"/>
            <geom class="collision" type="box" pos="0.080930 0.000079 0.036635" size="0.008588218130171299 0.007043835241347551 0.014595777727663517" quat="0.4469589293003082 -2.5602803432889232e-08 -0.8945544958114624 1.0351514134754325e-07"/>
            <geom class="collision" type="box" pos="0.096176 0.000079 0.048562" size="0.008588218130171299 0.007043835241347551 0.014595777727663517" quat="0.9753509759902954 1.995969256540775e-08 0.2206592708826065 -7.557726178220037e-08"/>
            <geom class="collision" type="box" pos="0.108083 0.000079 0.069281" size="0.008588218130171299 0.007043835241347551 0.014595777727663517" quat="0.9985536336898804 3.814508153787699e-10 0.05376478657126427 -1.2425408257854542e-08"/>
            <geom class="collision" type="box" pos="0.065855 0.000079 0.031173" size="0.008588218130171299 0.007043835241347551 0.014595777727663517" quat="0.503902018070221 -1.1074689609813504e-08 -0.8637608289718628 1.0884013335044074e-07"/>
            <geom class="collision" type="box" pos="0.026187 -0.017921 -0.008383" size="0.009812936186790466 0.011892476119101048 0.01440267264842987" quat="0.983661949634552 1.4869330766664746e-10 -2.7213188300012625e-11 -0.18002544343471527"/>
            <geom class="collision" type="box" pos="0.006769 -0.041985 -0.008383" size="0.00980029720813036 0.011892472393810749 0.01440267264842987" quat="0.8787503838539124 1.3283457667156995e-10 -7.214734365490472e-11 -0.4772816002368927"/>
            <geom class="collision" type="box" pos="-0.026216 -0.050002 -0.008383" size="0.010167481377720833 0.011892477981746197 0.014402669854462147" quat="0.6637383699417114 1.0033272823672945e-10 -1.1306464098304048e-10 -0.7479647994041443"/>
            <geom class="collision" type="box" pos="-0.057531 -0.034195 -0.008383" size="0.010493009351193905 0.011892473325133324 0.01440267264842987" quat="0.3605376183986664 5.449997050877009e-11 -1.4099650613719206e-10 -0.9327446818351746"/>
            <geom class="collision" type="box" pos="-0.070357 -0.004098 -0.008383" size="0.01036880910396576 0.011892478913068771 0.01440267264842987" quat="0.0375555194914341 5.67707729784428e-12 -1.5105791617564535e-10 -0.9992945194244385"/>
            <geom class="collision" type="box" pos="-0.061776 0.027632 -0.008383" size="0.010184808634221554 0.011892474256455898 0.01440267264842987" quat="0.29206669330596924 4.414969084765019e-11 1.445720348991486e-10 0.9563979506492615"/>
            <geom class="collision" type="box" pos="-0.036312 0.046684 -0.008383" size="0.00981199461966753 0.011892472393810749 0.01440267264842987" quat="0.5818083882331848 8.794792671906748e-11 1.229448071127237e-10 0.8133258819580078"/>
            <geom class="collision" type="box" pos="-0.004105 0.046356 -0.008383" size="0.00954082328826189 0.011892472393810749 0.01440267264842987" quat="0.8146055936813354 1.2313829123034026e-10 8.767690740096867e-11 0.5800153017044067"/>
            <geom class="collision" type="box" pos="0.020997 0.026255 -0.008383" size="0.009223192930221558 0.011892476119101048 0.01440267264842987" quat="0.959339439868927 1.450167208538744e-10 4.266653350071259e-11 0.2822549343109131"/>
            <geom class="collision" type="box" pos="0.029044 -0.000736 -0.008383" size="0.009248089045286179 0.011892478913068771 0.014402669854462147" quat="0.9991481900215149 1.5103426842522083e-10 6.238013577908319e-12 0.0412667915225029"/>
            <geom class="collision" type="box" pos="0.026060 0.017320 -0.008383" size="0.008628114126622677 0.011892474256455898 0.014402675442397594" quat="0.9753949642181396 1.47443668385705e-10 3.3326119641685636e-11 0.22046473622322083"/>
            <geom class="collision" type="box" pos="0.009051 0.039340 -0.008383" size="0.009464828297495842 0.011892473325133324 0.014402669854462147" quat="0.8928526639938354 1.349663159011527e-10 6.807611419024084e-11 0.4503489136695862"/>
            <geom class="collision" type="box" pos="-0.021762 0.048962 -0.008383" size="0.0122368223965168 0.00978539977222681 0.014402681961655617" quat="1.0 0.0 0.0 0.0"/>
            <geom class="collision" type="box" pos="-0.052176 0.038261 -0.008383" size="0.010209841653704643 0.011892473325133324 0.01440267264842987" quat="0.42588338255882263 6.437782251733637e-11 1.3676898502623658e-10 0.9047780632972717"/>
            <geom class="collision" type="box" pos="-0.068871 0.011091 -0.008383" size="0.010064947418868542 0.011892477981746197 0.014402673579752445" quat="0.1151188462972641 1.74017154852546e-11 1.5015806653639885e-10 0.9933516979217529"/>
            <geom class="collision" type="box" pos="-0.065796 -0.021603 -0.008383" size="0.010391995310783386 0.011892476119101048 0.01440267264842987" quat="0.21684034168720245 3.2778245395714833e-11 -1.4756643129665292e-10 -0.9762070775032043"/>
            <geom class="collision" type="box" pos="-0.043000 -0.044960 -0.008383" size="0.010226324200630188 0.011892476119101048 0.014402669854462147" quat="0.5225650072097778 7.899250004106406e-11 -1.2888151657008962e-10 -0.8525994420051575"/>
            <geom class="collision" type="box" pos="-0.008337 -0.048486 -0.008383" size="0.009752041660249233 0.011892474256455898 0.014402667991816998" quat="0.7875469326972961 1.1904797980744064e-10 -9.31549282157107e-11 -0.6162546873092651"/>
            <geom class="collision" type="box" pos="0.019713 -0.029668 -0.008383" size="0.009728861972689629 0.011892473325133324 0.014402669854462147" quat="0.9503161907196045 1.436526592124565e-10 -4.7054967561299677e-11 -0.31128624081611633"/>
          </body>
          <body name="Lid001">
            <joint axis="0.0 0.0 1.0" pos="-0.019869 -0.000089 0.206123" limited="true" name="Lid001_joint" range="0.0 0.1" type="slide" damping="1" frictionloss="1" armature=".01" stiffness="0.05"/>
            <geom mesh="Lid001_vis" type="mesh" solimp="0.998 0.998 0.001" solref="0.001 1" density="100" friction="0.95 0.3 0.1" class="visual" material="Lid001_material"/>
            <geom class="collision" type="cylinder" pos="-0.020316 -0.000089 0.193836" size="0.07600810378789902 0.010581719689071178" quat="1.0 0.0 0.0 0.0"/>
            <geom class="collision" type="cylinder" pos="-0.019869 -0.000089 0.217586" size="0.08795700967311859 0.014345938339829445" quat="1.0 0.0 0.0 0.0"/>
          </body>
        </body>
        <body name="Knob001">
          <joint axis="0.0 1.0 0.0" pos="-0.023416 -0.080210 -0.063036" limited="true" name="Knob001_joint" range="0.0 4.886921905584122" type="hinge" damping="1" frictionloss="1" armature=".01" stiffness="0.05"/>
          <geom mesh="Knob001_vis" type="mesh" solimp="0.998 0.998 0.001" solref="0.001 1" density="100" friction="0.95 0.3 0.1" class="visual" material="Knob001_material"/>
          <geom class="collision" type="cylinder" pos="-0.023184 -0.083068 -0.063345" size="0.013043073005974293 0.0027895476669073105" quat="0.7555490732192993 0.6550920605659485 1.1152972152003528e-17 -1.115296967046169e-17"/>
        </body>
        <geom class="region" name="reg_main" type="box" pos="-0.0004025000000000001 0.0 0.0" size="0.1172295 0.093117 0.229158"/>
      </body>
    </body>
  </worldbody>
  <actuator>
    <motor name="Button001_joint_actuator" joint="Button001_joint" gear="0.5"/>
    <motor name="Jug001_joint_actuator" joint="Jug001_joint" gear="39"/>
    <motor name="Knob001_joint_actuator" joint="Knob001_joint" gear="5"/>
    <motor name="Blade001_joint_actuator" joint="Blade001_joint" gear="5"/>
    <motor name="Lid001_joint_actuator" joint="Lid001_joint" gear="15"/>
  </actuator>
</mujoco>
