<?xml version='1.0' encoding='UTF-8'?>
<mujoco model="model">
  <option timestep="0.0005" gravity="0.0 0.0 -9.81"/>
  <compiler angle="radian"/>
  <asset>
    <mesh file="visuals/Body001.obj" name="Body001_vis"/>
    <mesh file="visuals/Body001_Clear.obj" name="Body001_Clear_vis"/>
    <mesh file="visuals/Body002.obj" name="Body002_vis"/>
    <mesh file="visuals/Button001.obj" name="Button001_vis"/>
    <mesh file="visuals/Button002.obj" name="Button002_vis"/>
    <mesh file="visuals/Knob001.obj" name="Knob001_vis"/>
    <mesh file="visuals/Knob002.obj" name="Knob002_vis"/>
    <mesh file="visuals/Lever001.obj" name="Lever001_vis"/>
    <mesh file="visuals/Lever002.obj" name="Lever002_vis"/>
    <texture file="visuals/T_BC001.png" name="Body001_material" type="2d"/>
    <material name="Body001_material" rgba="1 1 1 1.0" texture="Body001_material" shininess="0.5" specular="0.7"/>
    <texture file="visuals/T_BC001.png" name="Body001_Clear_material" type="2d"/>
    <material name="Body001_Clear_material" rgba="1 1 1 0.699999988079071" texture="Body001_Clear_material" shininess="0.5" specular="0.7"/>
    <texture file="visuals/T_BC001.png" name="Body002_material" type="2d"/>
    <material name="Body002_material" rgba="1 1 1 1.0" texture="Body002_material" shininess="0.5" specular="8"/>
    <texture file="visuals/T_BC001.png" name="Button001_material" type="2d"/>
    <material name="Button001_material" rgba="1 1 1 1.0" texture="Button001_material" shininess="0.5" specular="0.7"/>
    <texture file="visuals/T_BC001.png" name="Button002_material" type="2d"/>
    <material name="Button002_material" rgba="1 1 1 1.0" texture="Button002_material" shininess="0.5" specular="0.7"/>
    <texture file="visuals/T_BC001.png" name="Knob001_material" type="2d"/>
    <material name="Knob001_material" rgba="1 1 1 1.0" texture="Knob001_material" shininess="0.5" specular="0.7"/>
    <texture file="visuals/T_BC001.png" name="Knob002_material" type="2d"/>
    <material name="Knob002_material" rgba="1 1 1 1.0" texture="Knob002_material" shininess="0.5" specular="0.7"/>
    <texture file="visuals/T_BC001.png" name="Lever001_material" type="2d"/>
    <material name="Lever001_material" rgba="1 1 1 1.0" texture="Lever001_material" shininess="0.5" specular="0.7"/>
    <texture file="visuals/T_BC001.png" name="Lever002_material" type="2d"/>
    <material name="Lever002_material" rgba="1 1 1 1.0" texture="Lever002_material" shininess="0.5" specular="0.7"/>
  </asset>
  <default>
    <default class="visual">
      <geom conaffinity="0" contype="0" group="1" type="mesh"/>
    </default>
    <default class="collision">
      <geom group="0" rgba="0.5 0 0 0.5"/>
    </default>
    <default class="spawn">
      <geom group="0" rgba="1 1 1 0.5" contype="0" conaffinity="0"/>
      <site group="0" rgba="1 1 1 0.5"/>
    </default>
    <default class="region">
      <geom group="1" conaffinity="0" contype="0" rgba="0 1 0 0"/>
    </default>
  </default>
  <worldbody>
    <body>
      <body name="object">
        <geom mesh="Body001_vis" type="mesh" solimp="0.998 0.998 0.001" solref="0.001 1" friction="0.95 0.3 0.1" class="visual" material="Body001_material"/>
        <geom class="collision" type="box" pos="0.0 0.02383670210838318 -0.07956255972385406" size="0.1396121233701706 0.1427888572216034 0.021233486011624336" quat="1.0 0.0 0.0 0.0" density="1000.0"/>
        <geom class="collision" type="box" pos="-0.002511797472834587 0.024484198540449142 0.020840924233198166" size="0.012622779235243797 0.14278756082057953 0.07956822961568832" quat="1.0 0.0 0.0 0.0" density="1000.0"/>
        <geom class="collision" type="box" pos="-0.05631228908896446 0.024484198540449142 0.020840924233198166" size="0.009034966118633747 0.1427888572216034 0.07956815510988235" quat="1.0 0.0 0.0 0.0" density="1000.0"/>
        <geom class="collision" type="box" pos="0.05267892777919769 0.024484198540449142 0.020840924233198166" size="0.009521727450191975 0.1427888572216034 0.07956849783658981" quat="1.0 0.0 0.0 0.0" density="1000.0"/>
        <geom class="collision" type="box" pos="0.1164533868432045 0.024484198540449142 0.020840924233198166" size="0.021915441378951073 0.1427888572216034 0.07956811785697937" quat="1.0 0.0 0.0 0.0" density="1000.0"/>
        <geom class="collision" type="box" pos="-0.1181488037109375 0.024484198540449142 0.020840924233198166" size="0.02236456237733364 0.1427888572216034 0.07956814020872116" quat="1.0 0.0 0.0 0.0" density="1000.0"/>
        <geom class="collision" type="box" pos="-0.0024718253407627344 0.14158692955970764 0.020840924233198166" size="0.14278815686702728 0.02127535082399845 0.07956849783658981" quat="1.0 0.0 0.0 0.0" density="1000.0"/>
        <geom class="collision" type="box" pos="-0.0024718253407627344 -0.09994810074567795 0.020840924233198166" size="0.1427888721227646 0.017911167815327644 0.07956849783658981" quat="1.0 0.0 0.0 0.0" density="1000.0"/>
        <body name="Body001_Clear">
          <geom mesh="Body001_Clear_vis" type="mesh" solimp="0.998 0.998 0.001" solref="0.001 1" friction="0.95 0.3 0.1" class="visual" material="Body001_Clear_material"/>
          <geom class="collision" type="box" pos="-0.08873660862445831 -0.12673139572143555 -0.03657145798206329" size="0.02941889874637127 0.0005183819448575377 0.013261654414236546" quat="1.0 0.0 0.0 0.0" density="1000.0"/>
          <geom class="collision" type="box" pos="0.016700049862265587 -0.12673139572143555 -0.03657145798206329" size="0.02941889874637127 0.0005183819448575377 0.013261654414236546" quat="1.0 0.0 0.0 0.0" density="1000.0"/>
        </body>
        <body name="Body002">
          <geom mesh="Body002_vis" type="mesh" solimp="0.998 0.998 0.001" solref="0.001 1" friction="0.95 0.3 0.1" class="visual" material="Body002_material"/>
        </body>
        <body name="Button001">
          <joint axis="0.0 1.0 0.0" pos="-0.038676097989082336 -0.1279504895210266 -0.061730995774269104" limited="true" name="Button001_joint" range="0.0 0.002" type="slide" damping="1" frictionloss="1" armature=".01" stiffness="0.05"/>
          <geom mesh="Button001_vis" type="mesh" solimp="0.998 0.998 0.001" solref="0.001 1" friction="0.95 0.3 0.1" class="visual" material="Button001_material"/>
          <geom class="collision" type="box" pos="-0.03865706920623779 -0.1282956600189209 -0.06188366562128067" size="0.010698146186769009 0.0017508299788460135 0.0060849785804748535" quat="1.0 0.0 0.0 0.0" density="1000.0"/>
        </body>
        <body name="Button002">
          <joint axis="0.0 1.0 0.0" pos="0.07016493380069733 -0.1279504895210266 -0.061730995774269104" limited="true" name="Button002_joint" range="0.0 0.002" type="slide" damping="1" frictionloss="1" armature=".01" stiffness="0.05"/>
          <geom mesh="Button002_vis" type="mesh" solimp="0.998 0.998 0.001" solref="0.001 1" friction="0.95 0.3 0.1" class="visual" material="Button002_material"/>
          <geom class="collision" type="box" pos="0.07016493380069733 -0.1282956600189209 -0.06188366562128067" size="0.010698146186769009 0.0017508299788460135 0.0060849785804748535" quat="1.0 0.0 0.0 0.0" density="1000.0"/>
        </body>
        <body name="Knob001">
          <joint axis="9.010931023567537e-08 1.0 3.4696352457785906e-08" pos="-0.0881413146853447 -0.13498832285404205 -0.06467341631650925" limited="true" name="Knob001_joint" range="0.0 1.3613568165555772" type="hinge" damping="0.05" armature="0.001"/>
          <geom mesh="Knob001_vis" type="mesh" solimp="0.998 0.998 0.001" solref="0.001 1" friction="0.95 0.3 0.1" class="visual" material="Knob001_material"/>
          <geom class="collision" type="cylinder" pos="-0.08803896605968475 -0.12728014588356018 -0.06447699666023254" size="0.0105937160551548 0.007022842299193144" quat="0.7071067094802856 0.70710688829422 -1.5700925641616852e-16 1.2790027470567158e-23" density="1000.0"/>
          <geom class="collision" type="box" pos="-0.08849649131298065 -0.13935637474060059 -0.0644083321094513" size="0.009871277026832104 0.0052429018542170525 0.0041764602065086365" quat="0.913242757320404 -0.012167119421064854 0.4063149094581604 -0.027347063645720482" density="1000.0"/>
        </body>
        <body name="Knob002">
          <joint axis="9.010931023567537e-08 1.0 3.4696352457785906e-08" pos="0.019079558551311493 -0.13498832285404205 -0.06467341631650925" limited="true" name="Knob002_joint" range="0.0 1.3613568165555772" type="hinge" damping="0.05" armature="0.001"/>
          <geom mesh="Knob002_vis" type="mesh" solimp="0.998 0.998 0.001" solref="0.001 1" friction="0.95 0.3 0.1" class="visual" material="Knob002_material"/>
          <geom class="collision" type="cylinder" pos="0.019075173884630203 -0.12729212641716003 -0.06447699666023254" size="0.0105937160551548 0.007022842299193144" quat="0.7071067094802856 0.70710688829422 -1.5700925641616852e-16 1.2790027470567158e-23" density="1000.0"/>
          <geom class="collision" type="box" pos="0.01896749809384346 -0.1394963562488556 -0.06417219340801239" size="0.010065554641187191 0.00524289533495903 0.004181316588073969" quat="0.904408872127533 -0.012745060957968235 0.4256156384944916 -0.02708256058394909" density="1000.0"/>
        </body>
        <body name="Lever001">
          <joint axis="0.0 0.0 -1.0" pos="-0.05561074614524841 -0.11231432855129242 0.047188472002744675" limited="true" name="Lever001_joint" range="0.0 0.062" type="slide" damping="1" frictionloss="1" armature=".01" stiffness="1" springref="-2"/>
          <geom mesh="Lever001_vis" type="mesh" solimp="0.998 0.998 0.001" solref="0.001 1" friction="0.95 0.3 0.1" class="visual" material="Lever001_material"/>
          <geom class="collision" type="box" pos="-0.05582137405872345 -0.14965349435806274 0.042099479585886" size="0.029944511130452156 0.012194793671369553 0.006245047319680452" quat="1.0 0.0 0.0 0.0" name="sideL_lever_knob" density="1000.0"/>
          <geom class="collision" type="box" pos="-0.05582137405872345 -0.1374954879283905 0.044318266212940216" size="0.03413298353552818 0.0022110927384346724 0.008191992528736591" quat="1.0 0.0 0.0 0.0" density="1000.0"/>
          <geom class="collision" type="box" pos="-0.05582137405872345 -0.14618918299674988 0.05301307141780853" size="0.00586021738126874 0.010034876875579357 0.006292618345469236" quat="1.0 0.0 0.0 0.0" density="1000.0"/>
          <geom class="collision" type="box" pos="-0.05582137778401375 -0.13273417949676514 0.048948291689157486" size="0.0011697284644469619 0.003333111060783267 0.008165786974132061" quat="1.0 0.0 0.0 0.0" density="1000.0"/>
          <geom class="collision" type="box" pos="-0.07968541234731674 0.017848428338766098 0.08605487644672394" size="0.012999999336898327 0.09567824751138687 0.0028953137807548046" quat="1.0 0.0 0.0 0.0" name="sideL_slotL_floor" density="1000.0"/>
          <geom class="collision" type="box" pos="-0.03226739913225174 0.017848428338766098 0.08605487644672394" size="0.012999999336898327 0.09567819535732269 0.0028953133150935173" quat="1.0 0.0 0.0 0.0" name="sideL_slotR_floor" density="1000.0"/>
        </body>
        <body name="Lever002">
          <joint axis="0.0 0.0 -1.0" pos="0.05279482901096344 -0.11247250437736511 0.04718848690390587" limited="true" name="Lever002_joint" range="0.0 0.062" type="slide" damping="1" frictionloss="1" armature=".01" stiffness="1" springref="-2"/>
          <geom mesh="Lever002_vis" type="mesh" solimp="0.998 0.998 0.001" solref="0.001 1" friction="0.95 0.3 0.1" class="visual" material="Lever002_material"/>
          <geom class="collision" type="box" pos="0.05283983051776886 -0.14965349435806274 0.042099479585886" size="0.029944417998194695 0.012194799259305 0.0062450505793094635" quat="1.0 0.0 0.0 0.0" name="sideR_lever_knob" density="1000.0"/>
          <geom class="collision" type="box" pos="0.05283983051776886 -0.1374954879283905 0.044318266212940216" size="0.034132860600948334 0.0022110939025878906 0.008192007429897785" quat="1.0 0.0 0.0 0.0" density="1000.0"/>
          <geom class="collision" type="box" pos="0.05283983051776886 -0.14618918299674988 0.05301307141780853" size="0.00586021738126874 0.010034831240773201 0.006292618345469236" quat="1.0 0.0 0.0 0.0" density="1000.0"/>
          <geom class="collision" type="box" pos="0.05283983051776886 -0.13273417949676514 0.048948291689157486" size="0.0011697284644469619 0.003108852542936802 0.008165727369487286" quat="1.0 0.0 0.0 0.0" density="1000.0"/>
          <geom class="collision" type="box" pos="0.026323795318603516 0.017848428338766098 0.08605487644672394" size="0.012999999336898327 0.09567790478467941 0.0028953116852790117" quat="1.0 0.0 0.0 0.0" name="sideR_slotL_floor" density="1000.0"/>
          <geom class="collision" type="box" pos="0.07960101217031479 0.017848428338766098 0.08605487644672394" size="0.012999999336898327 0.09567785263061523 0.0028953112196177244" quat="1.0 0.0 0.0 0.0" name="sideR_slotR_floor" density="1000.0"/>
        </body>
        <geom class="region" name="reg_main" type="box" pos="0.0 0.01704566180706024 0.0" size="0.1402430683374405 0.14466173946857452 0.10115334391593933"/>
      </body>
    </body>
  </worldbody>
  <actuator>
    <motor name="Button001_joint_actuator" joint="Button001_joint" gear="0.1"/>
    <motor name="Button002_joint_actuator" joint="Button002_joint" gear="0.1"/>
    <motor name="Knob001_joint_actuator" joint="Knob001_joint" gear="5"/>
    <motor name="Knob002_joint_actuator" joint="Knob002_joint" gear="5"/>
    <motor name="Lever001_joint_actuator" joint="Lever001_joint" gear="2"/>
    <motor name="Lever002_joint_actuator" joint="Lever002_joint" gear="2"/>
  </actuator>
</mujoco>
