<mujoco model="model">
  <compiler angle="radian"/>
  <asset>
    <mesh file="visuals/handle.obj" name="handle_vis"/>
    <mesh file="visuals/Body001.obj" name="Body001_vis"/>
    <mesh file="visuals/Body002.obj" name="Body002_vis"/>
    <mesh file="visuals/Funnel001.obj" name="Funnel001_vis"/>
    <mesh file="visuals/Funnel002.obj" name="Funnel002_vis"/>
    <mesh file="visuals/spout.obj" name="spout_vis"/>
    <texture file="visuals/T_BC001.png" name="Body001_material" type="2d"/>
    <material name="Body001_material" rgba="1 1 1 1.0" texture="Body001_material" shininess="2" specular="2"/>
    <texture file="visuals/T_BC001.png" name="Body002_material" type="2d"/>
    <material name="Body002_material" rgba="1 1 1 1.0" texture="Body002_material" shininess="3" specular="3"/>
    <texture file="visuals/T_BC001.png" name="handle_material" type="2d"/>
    <material name="handle_material" rgba="1 1 1 1.0" texture="handle_material" shininess="3" specular="3"/>
    <texture file="visuals/T_BC001.png" name="spout_material" type="2d"/>
    <material name="spout_material" rgba="1 1 1 1.0" texture="spout_material" shininess="3" specular="3"/>
    <texture file="visuals/T_BC001.png" name="Funnel001_material" type="2d"/>
    <material name="Funnel001_material" rgba="1 1 1 1.0" texture="Funnel001_material" shininess="3" specular="3"/>
    <texture file="visuals/T_BC001.png" name="Funnel002_material" type="2d"/>
    <material name="Funnel002_material" rgba="1 1 1 1.0" texture="Funnel002_material" shininess="3" specular="3"/>
  </asset>
  <default>
    <default class="visual">
      <geom conaffinity="0" contype="0" group="1" type="mesh"/>
    </default>
    <default class="collision">
      <geom group="0" rgba="0.5 0 0 0.5"/>
    </default>
    <default class="spawn">
      <geom group="0" rgba="1 1 1 0.5" contype="0" conaffinity="0"/>
      <site group="0" rgba="1 1 1 0.5"/>
    </default>
    <default class="region">
      <geom group="1" conaffinity="0" contype="0" rgba="0 1 0 0"/>
    </default>
  </default>
  <worldbody>
    <body>
      <body name="object">
        <geom mesh="Body001_vis" type="mesh" solimp="0.998 0.998 0.001" solref="0.001 1" density="100" friction="0.95 0.3 0.1" class="visual" material="Body001_material"/>
        <geom class="collision" type="box" pos="-0.495080 0.002671 -0.228444" size="0.01909610442817211 0.34323060512542725 0.09792335331439972" quat="1.0 0.0 0.0 0.0"/>
        <geom class="collision" type="box" pos="0.494992 0.002671 -0.228444" size="0.019184201955795288 0.343230664730072 0.09792336821556091" quat="1.0 0.0 0.0 0.0"/>
        <geom class="collision" type="box" pos="0.066683 -0.052302 -0.233237" size="0.01861185021698475 0.25608429312705994 0.0931307002902031" quat="1.0 0.0 0.0 0.0"/>
        <geom class="collision" type="box" pos="0.000573 0.268425 -0.228444" size="0.4744337499141693 0.07427951693534851 0.0979233905673027" quat="1.0 0.0 0.0 0.0"/>
        <geom class="collision" type="box" pos="0.000573 -0.324044 -0.228444" size="0.4744338095188141 0.02185874432325363 0.0979233980178833" quat="1.0 0.0 0.0 0.0"/>
        <geom class="collision" type="box" pos="-0.367315 -0.052302 -0.307571" size="0.10149960964918137 0.25608471035957336 0.018796658143401146" quat="1.0 0.0 0.0 0.0"/>
        <geom class="collision" type="box" pos="-0.061074 -0.052302 -0.307571" size="0.10149960964918137 0.25608471035957336 0.01879665069282055" quat="1.0 0.0 0.0 0.0"/>
        <geom class="collision" type="box" pos="0.130572 -0.052302 -0.307571" size="0.10149960964918137 0.25608471035957336 0.018796661868691444" quat="1.0 0.0 0.0 0.0"/>
        <geom class="collision" type="box" pos="0.408901 -0.052302 -0.307571" size="0.07677695900201797 0.25608471035957336 0.018796660006046295" quat="1.0 0.0 0.0 0.0"/>
        <geom class="collision" type="box" pos="-0.214016 0.101381 -0.307571" size="0.050547897815704346 0.09694131463766098 0.018796652555465698" quat="1.0 0.0 0.0 0.0"/>
        <geom class="collision" type="box" pos="-0.214016 -0.204555 -0.307571" size="0.050547897815704346 0.09694131463766098 0.01879665069282055" quat="1.0 0.0 0.0 0.0"/>
        <geom class="collision" type="box" pos="0.283188 -0.204555 -0.307571" size="0.050547897815704346 0.09694131463766098 0.0187966451048851" quat="1.0 0.0 0.0 0.0"/>
        <geom class="collision" type="box" pos="0.283188 0.100093 -0.307571" size="0.050547897815704346 0.09694131463766098 0.018796643242239952" quat="1.0 0.0 0.0 0.0"/>
        <body name="Body002">
          <geom mesh="Body002_vis" type="mesh" solimp="0.998 0.998 0.001" solref="0.001 1" density="100" friction="0.95 0.3 0.1" class="visual" material="Body002_material"/>
          <geom class="collision" type="cylinder" pos="0.068510 0.290471 -0.049169" size="0.030319422483444214 0.08116674423217773" quat="1.0 0.0 0.0 0.0"/>
          <geom class="collision" type="cylinder" pos="0.103877 0.290471 -0.017297" size="0.030319426208734512 0.02635055221617222" quat="0.7071068286895752 -0.0 0.7071067690849304 0.0"/>
          <body name="handle">
            <joint axis="1.0 0.0 0.0" pos="0.153050 0.289294 -0.015799" limited="true" name="handle_joint_hinge_0" type="hinge" range="-0.7853981633974483 0.7853981633974483" damping="1" frictionloss="1" armature=".01" stiffness="0.05"/>
            <joint axis="0.0 1.0 0.0" pos="0.153050 0.289294 -0.015799" limited="true" name="handle_joint_hinge_1" type="hinge" range="0.0 0.17453292519943295" damping="1" frictionloss="1" armature=".01" stiffness="0.05"/>
            <geom mesh="handle_vis" type="mesh" solimp="0.998 0.998 0.001" solref="0.001 1" density="100" friction="0.95 0.3 0.1" class="visual" material="handle_material"/>
            <geom class="collision" type="cylinder" pos="0.161692 0.289213 -0.015962" size="0.03340867534279823 0.014485578052699566" quat="0.7071068286895752 -0.0 0.7071067690849304 0.0"/>
            <geom class="collision" type="cylinder" pos="0.162969 0.289251 0.053592" size="0.006227125413715839 0.04342131316661835" quat="1.0 0.0 0.0 0.0"/>
          </body>
          <body name="spout">
            <joint axis="0.0 0.0 1.0" pos="0.067555 0.293289 0.163738" limited="true" name="spout_joint" range="-0.7853981633974483 0.7853981633974483" type="hinge" damping="1" frictionloss="1" armature=".01" stiffness="0.05"/>
            <site type="cylinder" rgba="0.5 0.75 1 1" size="0.01151744183152914 0.21220138669013977" pos="0.067494 -0.020068 -0.097071" name="water"/>
            <geom mesh="spout_vis" type="mesh" solimp="0.998 0.998 0.001" solref="0.001 1" density="100" friction="0.95 0.3 0.1" class="visual" material="spout_material"/>
            <geom class="collision" type="cylinder" pos="0.068510 0.293824 0.113175" size="0.019380977377295494 0.08024422079324722" quat="1.0 0.0 0.0 0.0"/>
            <geom class="collision" type="cylinder" pos="0.068510 0.270080 0.241485" size="0.019380977377295494 0.05237458273768425" quat="0.94241863489151 0.33443546295166016 -7.425959024402132e-17 -1.0411755019580105e-24"/>
            <geom class="collision" type="cylinder" pos="0.068510 0.009594 0.237008" size="0.019380977377295494 0.03836783766746521" quat="0.94241863489151 -0.33443546295166016 -7.425958362657642e-17 2.1058400473437913e-23"/>
            <geom class="collision" type="cylinder" pos="0.068510 -0.015613 0.156993" size="0.019380979239940643 0.04354899376630783" quat="0.9991522431373596 -0.041167549788951874 9.141032328619375e-18 -1.094883716183399e-24"/>
            <geom class="collision" type="cylinder" pos="0.068510 0.181679 0.302015" size="0.019380977377295494 0.05733475089073181" quat="0.7834377288818359 0.6214703321456909 -1.740260556822788e-16 3.604969907408587e-17"/>
            <geom class="collision" type="cylinder" pos="0.068510 0.078115 0.290938" size="0.019380977377295494 0.049684420228004456" quat="0.5714645385742188 0.8206267356872559 -1.2698036348411727e-16 -5.526257353101829e-17"/>
          </body>
        </body>
        <body name="Funnel001">
          <joint axis="0.0 0.0 1.0" pos="-0.215447 -0.051217 -0.295605" limited="true" name="Funnel001_joint" range="0.0 0.05" type="slide" damping="0.5" frictionloss="0.5" armature=".01" stiffness="0.05"/>
          <geom mesh="Funnel001_vis" type="mesh" solimp="0.998 0.998 0.001" solref="0.001 1" density="100" friction="0.95 0.3 0.1" class="visual" material="Funnel001_material"/>
          <geom class="collision" type="cylinder" pos="-0.215912 -0.051729 -0.304772" size="0.04812832549214363 0.0062426915392279625" quat="1.0 0.0 0.0 0.0"/>
          <geom class="collision" type="cylinder" pos="-0.215912 -0.051729 -0.290755" size="0.00939252134412527 0.006242691073566675" quat="1.0 0.0 0.0 0.0"/>
        </body>
        <body name="Funnel002">
          <joint axis="0.0 0.0 1.0" pos="0.281548 -0.054275 -0.295605" limited="true" name="Funnel002_joint" range="0.0 0.05" type="slide" damping="0.5" frictionloss="0.5" armature=".01" stiffness="0.05"/>
          <geom mesh="Funnel002_vis" type="mesh" solimp="0.998 0.998 0.001" solref="0.001 1" density="100" friction="0.95 0.3 0.1" class="visual" material="Funnel002_material"/>
          <geom class="collision" type="cylinder" pos="0.281772 -0.054214 -0.304791" size="0.04812832549214363 0.0062426915392279625" quat="1.0 0.0 0.0 0.0"/>
          <geom class="collision" type="cylinder" pos="0.281772 -0.054214 -0.291142" size="0.009885367937386036 0.006242691073566675" quat="1.0 0.0 0.0 0.0"/>
        </body>
        <geom class="region" name="reg_main" type="box" pos="0.0 0.0 -0.2284445" size="0.514176 0.345902 0.0979235"/>
        <geom class="region" name="reg_basin_left" type="box" pos="-0.2177685 -0.049241499999999994 -0.2094835" size="0.2588625 0.2516945 0.06622850000000001"/>
        <geom class="region" name="reg_basin_right" type="box" pos="0.278985 -0.049241499999999994 -0.2094835" size="0.195964 0.2516945 0.06622850000000001"/>
      </body>
    </body>
  </worldbody>
  <actuator>
    <motor name="Funnel001_joint_actuator" joint="Funnel001_joint" gear="10"/>
    <motor name="Funnel002_joint_actuator" joint="Funnel002_joint" gear="10"/>
    <motor name="handle_joint_hinge_0_actuator" joint="handle_joint_hinge_0" gear="10"/>
    <motor name="handle_joint_hinge_1_actuator" joint="handle_joint_hinge_1" gear="10"/>
    <motor name="spout_joint_actuator" joint="spout_joint" gear="10"/>
  </actuator>
</mujoco>
