<mujoco model="model">
  <compiler angle="radian"/>
  <asset>
    <mesh file="visuals/handle.obj" name="handle_vis"/>
    <mesh file="visuals/Body001.obj" name="Body001_vis"/>
    <mesh file="visuals/Body002.obj" name="Body002_vis"/>
    <mesh file="visuals/Funnel001.obj" name="Funnel001_vis"/>
    <mesh file="visuals/Funnel002.obj" name="Funnel002_vis"/>
    <mesh file="visuals/spout.obj" name="spout_vis"/>
    <texture file="visuals/T_BC001.png" name="Body001_material" type="2d"/>
    <material name="Body001_material" rgba="1 1 1 1.0" texture="Body001_material" shininess="0.228035569190979" specular="0.3103448502657381"/>
    <texture file="visuals/T_BC001.png" name="Body002_material" type="2d"/>
    <material name="Body002_material" rgba="1 1 1 1.0" texture="Body002_material" shininess="0.228035569190979" specular="0.3103448502657381"/>
    <texture file="visuals/T_BC001.png" name="handle_material" type="2d"/>
    <material name="handle_material" rgba="1 1 1 1.0" texture="handle_material" shininess="0.228035569190979" specular="0.3103448502657381"/>
    <texture file="visuals/T_BC001.png" name="spout_material" type="2d"/>
    <material name="spout_material" rgba="1 1 1 1.0" texture="spout_material" shininess="0.228035569190979" specular="0.3103448502657381"/>
    <texture file="visuals/T_BC001.png" name="Funnel001_material" type="2d"/>
    <material name="Funnel001_material" rgba="1 1 1 1.0" texture="Funnel001_material" shininess="0.228035569190979" specular="0.3103448502657381"/>
    <texture file="visuals/T_BC001.png" name="Funnel002_material" type="2d"/>
    <material name="Funnel002_material" rgba="1 1 1 1.0" texture="Funnel002_material" shininess="0.228035569190979" specular="0.3103448502657381"/>
  </asset>
  <default>
    <default class="visual">
      <geom conaffinity="0" contype="0" group="1" type="mesh"/>
    </default>
    <default class="collision">
      <geom group="0" rgba="0.5 0 0 0.5"/>
    </default>
    <default class="spawn">
      <geom group="0" rgba="1 1 1 0.5" contype="0" conaffinity="0"/>
      <site group="0" rgba="1 1 1 0.5"/>
    </default>
    <default class="region">
      <geom group="1" conaffinity="0" contype="0" rgba="0 1 0 0"/>
    </default>
  </default>
  <worldbody>
    <body>
      <body name="object">
        <geom mesh="Body001_vis" type="mesh" solimp="0.998 0.998 0.001" solref="0.001 1" density="100" friction="0.95 0.3 0.1" class="visual" material="Body001_material"/>
        <geom class="collision" type="box" pos="-0.4952258765697479 0.0035230349749326706 -0.21309414505958557" size="0.019241660833358765 0.34408342838287354 0.09851182252168655" quat="1.0 0.0 0.0 0.0"/>
        <geom class="collision" type="box" pos="0.49504968523979187 0.0035230349749326706 -0.21309414505958557" size="0.019241660833358765 0.34408342838287354 0.09851182252168655" quat="1.0 0.0 0.0 0.0"/>
        <geom class="collision" type="box" pos="0.06668266654014587 -0.052302245050668716 -0.218265101313591" size="0.018611876294016838 0.25608471035957336 0.09334087371826172" quat="1.0 0.0 0.0 0.0"/>
        <geom class="collision" type="box" pos="0.0005729794502258301 0.26842501759529114 -0.2134183794260025" size="0.4744345247745514 0.07427961379289627 0.09818759560585022" quat="1.0 0.0 0.0 0.0"/>
        <geom class="collision" type="box" pos="0.0005729794502258301 -0.32549476623535156 -0.21344490349292755" size="0.4744345247745514 0.02330998331308365 0.09816106408834457" quat="1.0 0.0 0.0 0.0"/>
        <geom class="collision" type="box" pos="0.0008982345461845398 -0.052302245050668716 -0.30108609795570374" size="0.4697132110595703 0.25608471035957336 0.010519880801439285" quat="1.0 0.0 0.0 0.0"/>
        <body name="Body002">
          <geom mesh="Body002_vis" type="mesh" solimp="0.998 0.998 0.001" solref="0.001 1" density="100" friction="0.95 0.3 0.1" class="visual" material="Body002_material"/>
          <geom class="collision" type="cylinder" pos="0.0685095489025116 0.29047077894210815 -0.03398707136511803" size="0.030319422483444214 0.08116674423217773" quat="1.0 0.0 0.0 0.0"/>
          <geom class="collision" type="cylinder" pos="0.10387744009494781 0.29047077894210815 -0.0041183712892234325" size="0.030319426208734512 0.02635055221617222" quat="0.7071068286895752 -0.0 0.7071067690849304 0.0"/>
          <body name="handle">
            <joint axis="1.0 0.0 0.0" pos="0.1530504673719406 0.28929442167282104 -0.0006167417159304023" limited="true" name="handle_joint" range="-0.6981317007977318 0.6981317007977318" type="hinge" damping="1" frictionloss="1" armature=".01" stiffness="0.05"/>
            <geom mesh="handle_vis" type="mesh" solimp="0.998 0.998 0.001" solref="0.001 1" density="100" friction="0.95 0.3 0.1" class="visual" material="handle_material"/>
            <geom class="collision" type="cylinder" pos="0.15390191972255707 0.28921347856521606 -0.00411837175488472" size="0.03340867534279823 0.022664858028292656" quat="0.7071068286895752 -0.0 0.7071067690849304 0.0"/>
            <geom class="collision" type="cylinder" pos="0.1629687249660492 0.28925076127052307 0.06877436488866806" size="0.006227125413715839 0.04342131316661835" quat="1.0 0.0 0.0 0.0"/>
          </body>
          <body name="spout">
            <joint axis="0.0 0.0 1.0" pos="0.0675547644495964 0.29328861832618713 0.1789197325706482" limited="true" name="spout_joint" range="-0.7853981633974483 0.7853981633974483" type="hinge" damping="1" frictionloss="1" armature=".01" stiffness="0.05"/>
            <site type="cylinder" rgba="0.5 0.75 1 1" size="0.014671355485916138 0.20858049392700195" pos="0.06749372184276581 -0.020067904144525528 -0.07180438935756683" name="water"/>
            <geom mesh="spout_vis" type="mesh" solimp="0.998 0.998 0.001" solref="0.001 1" density="100" friction="0.95 0.3 0.1" class="visual" material="spout_material"/>
            <geom class="collision" type="cylinder" pos="0.0685095489025116 0.2938242554664612 0.12835738062858582" size="0.019380977377295494 0.08024422079324722" quat="1.0 0.0 0.0 0.0"/>
            <geom class="collision" type="cylinder" pos="0.0685095489025116 0.27561843395233154 0.24060632288455963" size="0.019380977377295494 0.05237458273768425" quat="0.94241863489151 0.33443546295166016 -7.425959024402132e-17 -1.0411755019580105e-24"/>
            <geom class="collision" type="cylinder" pos="0.0685095489025116 0.015685943886637688 0.2477596551179886" size="0.019380977377295494 0.03836783766746521" quat="0.94241863489151 -0.33443546295166016 -7.425958362657642e-17 2.1058400473437913e-23"/>
            <geom class="collision" type="cylinder" pos="0.0685095489025116 -0.015612573362886906 0.17217475175857544" size="0.019380979239940643 0.036071840673685074" quat="0.9991522431373596 -0.041167519986629486 9.141025711174474e-18 -1.4331116749938207e-24"/>
            <geom class="collision" type="cylinder" pos="0.0685095489025116 0.13958893716335297 0.2911669909954071" size="0.019380977377295494 0.0956864058971405" quat="0.7069326639175415 0.7072808742523193 -1.57047902294387e-16 8.271878700733557e-24"/>
          </body>
        </body>
        <body name="Funnel001">
          <joint axis="0.0 0.0 1.0" pos="-0.21544727683067322 -0.051216695457696915 -0.2804231643676758" limited="true" name="Funnel001_joint" range="0.0 0.05" type="slide" damping="1" frictionloss="1" armature=".01" stiffness="0.05"/>
          <geom mesh="Funnel001_vis" type="mesh" solimp="0.998 0.998 0.001" solref="0.001 1" density="100" friction="0.95 0.3 0.1" class="visual" material="Funnel001_material"/>
          <geom class="collision" type="cylinder" pos="-0.21591244637966156 -0.05172913148999214 -0.2832828164100647" size="0.04812832549214363 0.0062426915392279625" quat="1.0 0.0 0.0 0.0"/>
        </body>
        <body name="Funnel002">
          <joint axis="0.0 0.0 1.0" pos="0.28154847025871277 -0.054274559020996094 -0.2804231643676758" limited="true" name="Funnel002_joint" range="0.0 0.05" type="slide" damping="1" frictionloss="1" armature=".01" stiffness="0.05"/>
          <geom mesh="Funnel002_vis" type="mesh" solimp="0.998 0.998 0.001" solref="0.001 1" density="100" friction="0.95 0.3 0.1" class="visual" material="Funnel002_material"/>
          <geom class="collision" type="cylinder" pos="0.2817715108394623 -0.05421396717429161 -0.2832828164100647" size="0.04812832549214363 0.0062426915392279625" quat="1.0 0.0 0.0 0.0"/>
        </body>
        <geom class="region" name="reg_main_body" type="box" pos="0.0 0.0 -0.21241135895252228" size="0.5141764879226685 0.34590232372283936 0.09877459704875946"/>
        <geom class="region" name="reg_basin_left" type="box" pos="-0.2167725507169962 -0.05215606093406677 -0.1906469464302063" size="0.2604675944894552 0.23444026708602905 0.0579310804605484"/>
        <geom class="region" name="reg_basin_right" type="box" pos="0.2852066233754158 -0.05476856231689453 -0.18846673518419266" size="0.1832301840186119 0.24829807877540588 0.05648685246706009"/>
      </body>
    </body>
  </worldbody>
  <actuator>
    <motor name="Funnel001_joint_actuator" joint="Funnel001_joint" gear="10"/>
    <motor name="Funnel002_joint_actuator" joint="Funnel002_joint" gear="10"/>
    <motor name="handle_joint_actuator" joint="handle_joint" gear="10"/>
    <motor name="spout_joint_actuator" joint="spout_joint" gear="10"/>
  </actuator>
</mujoco>
