<?xml version='1.0' encoding='UTF-8'?>
<mujoco model="model">
  <compiler angle="radian"/>
  <asset>
    <mesh file="visuals/Blade001.obj" name="Blade001_vis"/>
    <mesh file="visuals/Body001.obj" name="Body001_vis"/>
    <mesh file="visuals/Button001.obj" name="Button001_vis"/>
    <mesh file="visuals/Container001.obj" name="Container001_vis"/>
    <mesh file="visuals/Knob001.obj" name="Knob001_vis"/>
    <mesh file="visuals/Lid001.obj" name="Lid001_vis"/>
    <texture file="visuals/T_BC001.png" name="Body001_material" type="2d"/>
    <material name="Body001_material" rgba="1 1 1 1.0" texture="Body001_material" shininess="0.6150577068328857" specular="0.5"/>
    <texture file="visuals/T_BC001.png" name="Button001_material" type="2d"/>
    <material name="Button001_material" rgba="1 1 1 1.0" texture="Button001_material" shininess="0.6150577068328857" specular="0.5"/>
    <texture file="visuals/T_BC001.png" name="Container001_material" type="2d"/>
    <material name="Container001_material" rgba="1 1 1 1.0" texture="Container001_material" shininess="0.6150577068328857" specular="0.5"/>
    <texture file="visuals/T_BC001.png" name="Knob001_material" type="2d"/>
    <material name="Knob001_material" rgba="1 1 1 1.0" texture="Knob001_material" shininess="0.6150577068328857" specular="0.5"/>
    <texture file="visuals/T_BC001.png" name="Lid001_material" type="2d"/>
    <material name="Lid001_material" rgba="1 1 1 1.0" texture="Lid001_material" shininess="0.6150577068328857" specular="0.5"/>
    <texture file="visuals/T_BC001.png" name="Blade001_material" type="2d"/>
    <material name="Blade001_material" rgba="1 1 1 1.0" texture="Blade001_material" shininess="0.6150577068328857" specular="1"/>
  </asset>
  <default>
    <default class="visual">
      <geom conaffinity="0" contype="0" group="1" type="mesh"/>
    </default>
    <default class="collision">
      <geom group="0" rgba="0.5 0 0 0.5"/>
    </default>
    <default class="spawn">
      <geom group="0" rgba="1 1 1 0.5" contype="0" conaffinity="0"/>
      <site group="0" rgba="1 1 1 0.5"/>
    </default>
    <default class="region">
      <geom group="1" conaffinity="0" contype="0" rgba="0 1 0 0"/>
    </default>
  </default>
  <worldbody>
    <body>
      <body name="object">
        <geom mesh="Body001_vis" type="mesh" solimp="0.998 0.998 0.001" solref="0.001 1" density="100" friction="0.95 0.3 0.1" class="visual" material="Body001_material"/>
        <geom class="collision" type="cylinder" pos="0.003460519015789032 -0.0849916860461235 -0.1610846072435379" size="0.10266918689012527 0.016178524121642113" quat="0.7071068286895752 0.0 0.0 0.7071067690849304"/>
        <geom class="collision" type="box" pos="0.0007541850209236145 0.08873350918292999 -0.16065005958080292" size="0.09872075170278549 0.08596987277269363 0.016632359474897385" quat="0.7071068286895752 0.0 0.0 0.7071067690849304"/>
        <geom class="collision" type="box" pos="0.0007541850209236145 0.10066592693328857 -0.11781147867441177" size="0.05685624107718468 0.08596987277269363 0.02410605363547802" quat="0.7071068286895752 0.0 0.0 0.7071067690849304"/>
        <geom class="collision" type="box" pos="-0.002644643187522888 0.10392031073570251 -0.028685398399829865" size="0.0402195043861866 0.08257105201482773 0.06867597997188568" quat="0.7071068286895752 0.0 0.0 0.7071067690849304"/>
        <body name="Button001">
          <joint axis="-1.0 0.0 0.0" pos="0.08683105558156967 0.10489334166049957 0.010110207833349705" limited="true" name="Button001_joint" range="0.0 0.004" type="slide" damping="1" frictionloss="1" armature=".01" stiffness="0.05"/>
          <geom mesh="Button001_vis" type="mesh" solimp="0.998 0.998 0.001" solref="0.001 1" density="100" friction="0.95 0.3 0.1" class="visual" material="Button001_material"/>
          <geom class="collision" type="box" pos="0.08823489397764206 0.1049036830663681 0.00974784791469574" size="0.006625826936215162 0.0011522299610078335 0.010949372313916683" quat="0.7071068286895752 0.0 0.0 0.7071067690849304"/>
        </body>
        <body name="Container001">
          <joint axis="0.0 0.0 1.0" pos="-1.2453834408177045e-08 -0.06627010554075241 -0.05105967074632645" limited="true" name="Container001_joint" range="0.0 0.03" type="slide" damping="1" frictionloss="1" armature=".01" stiffness="0.05"/>
          <geom mesh="Container001_vis" type="mesh" solimp="0.998 0.998 0.001" solref="0.001 1" density="100" friction="0.95 0.3 0.1" class="visual" material="Container001_material"/>
          <geom class="collision" type="box" pos="0.09577890485525131 -0.06873269379138947 -0.010495379567146301" size="0.03732758015394211 0.005964502226561308 0.05343107879161835" quat="0.7229249477386475 0.0 0.0 0.6909265518188477"/>
          <geom class="collision" type="box" pos="0.07019632309675217 -0.06757412850856781 -0.09441077709197998" size="0.03732758015394211 0.005964502226561308 0.05343107879161835" quat="0.6964244842529297 0.19394183158874512 0.1853574812412262 0.6655990481376648"/>
          <geom class="collision" type="box" pos="0.050625551491975784 -0.017625704407691956 -0.09441077709197998" size="0.03732758015394211 0.005964501760900021 0.05343107879161835" quat="0.38930678367614746 0.10841494798660278 0.24539148807525635 0.8811750411987305"/>
          <geom class="collision" type="box" pos="0.06955821067094803 -0.00038145482540130615 -0.010495379567146301" size="0.03732758015394211 0.005964502226561308 0.05343107879161835" quat="0.40412062406539917 0.0 0.0 0.9147056937217712"/>
          <geom class="collision" type="box" pos="0.0009639021009206772 0.029535599052906036 -0.010495379567146301" size="0.03732758015394211 0.005964502226561308 0.05343107879161835" quat="0.014805447310209274 0.0 0.0 0.9998903870582581"/>
          <geom class="collision" type="box" pos="0.00020568561740219593 0.003938035108149052 -0.09441077709197998" size="0.03732758015394211 0.005964502226561308 0.05343107879161835" quat="0.014262717217206955 0.003971923608332872 0.26824429631233215 0.9632371664047241"/>
          <geom class="collision" type="box" pos="-0.04840046539902687 -0.01541125401854515 -0.09441077709197998" size="0.03732758015394211 0.005964502226561308 0.05343107879161835" quat="0.3456428349018097 0.0962553396821022 -0.2504110634326935 -0.8991997838020325"/>
          <geom class="collision" type="box" pos="-0.06555350869894028 0.0036040879786014557 -0.010495379567146301" size="0.03732758015394211 0.005964502226561308 0.05343107879161835" quat="0.3587951958179474 0.0 -0.0 -0.9334163069725037"/>
          <geom class="collision" type="box" pos="-0.09579715132713318 -0.0646655336022377 -0.010495379567146301" size="0.03732758015394211 0.005964502226561308 0.05343107879161835" quat="0.6941573023796082 0.0 -0.0 -0.7198233604431152"/>
          <geom class="collision" type="box" pos="-0.07020523399114609 -0.06559489667415619 -0.09441077709197998" size="0.03732757642865181 0.005964502226561308 0.05343107879161835" quat="0.6687114238739014 0.18622416257858276 -0.1931096762418747 -0.6934365630149841"/>
          <geom class="collision" type="box" pos="-0.04966125637292862 -0.11589860916137695 -0.09441077709197998" size="0.03732758015394211 0.005964502226561308 0.05343107879161835" quat="0.8849525451660156 0.24644345045089722 -0.10600192099809647 -0.3806418180465698"/>
          <geom class="collision" type="box" pos="-0.06825187802314758 -0.13351109623908997 -0.010495379567146301" size="0.03732758015394211 0.005964502226561308 0.05343107879161835" quat="0.9186269044876099 0.0 -0.0 -0.3951260447502136"/>
          <geom class="collision" type="box" pos="-0.0016660839319229126 -0.16206619143486023 -0.010495379567146301" size="0.03732758015394211 0.005964502226561308 0.05343107879161835" quat="0.9998294115066528 0.0 -0.0 -0.018469497561454773"/>
          <geom class="collision" type="box" pos="-0.0007202774286270142 -0.1364748775959015 -0.09441076964139938" size="0.03732758015394211 0.005964502226561308 0.05343107879161835" quat="0.9631783962249756 0.2682279348373413 -0.00495489127933979 -0.017792504280805588"/>
          <geom class="collision" type="box" pos="0.048427045345306396 -0.11710363626480103 -0.09441076964139938" size="0.03732758015394211 0.005964502226561308 0.05343107879161835" quat="0.8991093635559082 0.2503858208656311 0.09632080048322678 0.345878005027771"/>
          <geom class="collision" type="box" pos="0.0655900239944458 -0.13611000776290894 -0.010495379567146301" size="0.03732758015394211 0.005964502226561308 0.05343107879161835" quat="0.9333224296569824 0.0 0.0 0.35903939604759216"/>
          <geom class="collision" type="box" pos="0.08426949381828308 -0.14564931392669678 0.0063903117552399635" size="0.0066782101057469845 0.01395743153989315 0.006678210571408272" quat="0.9218466281890869 0.0 0.0 0.38755494356155396"/>
          <geom class="collision" type="box" pos="0.09352481365203857 -0.15466591715812683 -0.03930659592151642" size="0.006678210571408272 0.04591038078069687 0.006678210571408272" quat="0.6440426111221313 0.6409761309623718 0.2982119619846344 0.29228127002716064"/>
          <geom class="collision" type="box" pos="0.07861623167991638 -0.1401141732931137 -0.08530610799789429" size="0.0066782101057469845 0.02186926268041134 0.006678210571408272" quat="0.9218466281890869 0.0 0.0 0.38755494356155396"/>
        </body>
        <body name="Knob001">
          <joint axis="-1.0 0.0 0.0" pos="0.09186919778585434 0.10499929636716843 -0.03084498643875122" limited="true" name="Knob001_joint" range="0.0 5.235987755982989" type="hinge" damping="0.05" armature="0.001"/>
          <geom mesh="Knob001_vis" type="mesh" solimp="0.998 0.998 0.001" solref="0.001 1" density="100" friction="0.95 0.3 0.1" class="visual" material="Knob001_material"/>
          <geom class="collision" type="cylinder" pos="0.08847013860940933 0.10506120324134827 -0.030731894075870514" size="0.02145657129585743 0.002870349446311593" quat="0.5000000596046448 0.5 0.4999999701976776 0.5"/>
          <geom class="collision" type="box" pos="0.10003703087568283 0.10141026228666306 -0.030731894075870514" size="0.009205687791109085 0.012417934834957123 0.009205687791109085" quat="1.0 0.0 0.0 0.0"/>
        </body>
        <body name="Lid001">
          <joint axis="-1.0 0.0 0.0" pos="1.0754204637919429e-08 0.14244376122951508 0.04130365327000618" limited="true" name="Lid001_joint" range="0.0 1.5707963267948966" type="hinge" damping="1" frictionloss="1" armature=".01" stiffness="0.05"/>
          <geom mesh="Lid001_vis" type="mesh" solimp="0.998 0.998 0.001" solref="0.001 1" density="100" friction="0.95 0.3 0.1" class="visual" material="Lid001_material"/>
          <geom class="collision" type="box" pos="0.00042625516653060913 -0.06595133244991302 0.036875221878290176" size="0.029734713956713676 0.010289303958415985 0.007034998387098312" quat="0.7071068286895752 0.0 0.0 0.7071067690849304"/>
          <geom class="collision" type="box" pos="-8.922815322875977e-05 0.11617272347211838 0.11218898743391037" size="0.05562294274568558 0.08439835906028748 0.06867597997188568" quat="0.7071068286895752 0.0 0.0 0.7071067690849304"/>
          <geom class="collision" type="cylinder" pos="0.00039145350456237793 -0.06626210361719131 0.056532151997089386" size="0.05091654881834984 0.0164863932877779" quat="0.7071068286895752 0.0 0.0 0.7071067690849304"/>
          <geom class="collision" type="box" pos="-8.924119174480438e-05 -0.027804773300886154 0.12384510040283203" size="0.08912068605422974 0.08439835906028748 0.05735771358013153" quat="0.7071068286895752 0.0 0.0 0.7071067690849304"/>
          <body name="Blade001">
            <joint axis="0.0 0.0 1.0" pos="-1.7672549802227877e-05 -0.06669911742210388 -0.026015812531113625" limited="false" name="Blade001_joint" range="0 360" type="hinge" damping="1" frictionloss="1" armature=".01" stiffness="0.05"/>
            <geom mesh="Blade001_vis" type="mesh" solimp="0.998 0.998 0.001" solref="0.001 1" density="100" friction="0.95 0.3 0.1" class="visual" material="Blade001_material"/>
            <geom class="collision" type="cylinder" pos="-8.93324613571167e-06 -0.06668905913829803 0.016672706231474876" size="0.044408053159713745 0.0015562321059405804" quat="0.7071068286895752 0.0 0.0 0.7071067690849304"/>
            <geom class="collision" type="cylinder" pos="-8.93324613571167e-06 -0.06668905913829803 0.010099751874804497" size="0.006662769243121147 0.022094683721661568" quat="0.7071068286895752 0.0 0.0 0.7071067690849304"/>
            <geom class="collision" type="box" pos="5.398690700531006e-05 -0.06601007282733917 -0.04471845179796219" size="0.04669037461280823 0.0030582635663449764 0.037796273827552795" quat="0.7071068286895752 0.0 0.0 0.7071067690849304"/>
          </body>
        </body>
        <geom class="region" name="reg_main" type="box" pos="1.564621925354004e-05 0.0 7.450580596923828e-09" size="0.09894803166389465 0.18722178041934967 0.17763414978981018"/>
      </body>
    </body>
  </worldbody>
  <actuator>
    <motor name="Button001_joint_actuator" joint="Button001_joint" gear="0.5"/>
    <motor name="Container001_joint_actuator" joint="Container001_joint" gear="10"/>
    <motor name="Knob001_joint_actuator" joint="Knob001_joint" gear="10"/>
    <motor name="Lid001_joint_actuator" joint="Lid001_joint" gear="10"/>
    <motor name="Blade001_joint_actuator" joint="Blade001_joint" gear="10"/>
  </actuator>
</mujoco>
