<?xml version='1.0' encoding='UTF-8'?>
<mujoco model="model">
  <compiler angle="radian"/>
  <asset>
    <mesh file="visuals/Body001.obj" name="Body001_vis"/>
    <mesh file="visuals/Button001.obj" name="Button001_vis"/>
    <mesh file="visuals/Button002.obj" name="Button002_vis"/>
    <mesh file="visuals/Container001.obj" name="Container001_vis"/>
    <mesh file="visuals/Lever001.obj" name="Lever001_vis"/>
    <mesh file="visuals/Lid001.obj" name="Lid001_vis"/>
    <mesh file="visuals/Lid002.obj" name="Lid002_vis"/>
    <texture file="visuals/T_BC001.png" name="Body001_material" type="2d"/>
    <material name="Body001_material" rgba="1 1 1 1.0" texture="Body001_material" shininess="0.141421377658844" specular="0.3103448502657381"/>
    <texture file="visuals/T_BC001.png" name="Button001_material" type="2d"/>
    <material name="Button001_material" rgba="1 1 1 1.0" texture="Button001_material" shininess="0.141421377658844" specular="0.3103448502657381"/>
    <texture file="visuals/T_BC001.png" name="Button002_material" type="2d"/>
    <material name="Button002_material" rgba="1 1 1 1.0" texture="Button002_material" shininess="0.141421377658844" specular="0.3103448502657381"/>
    <texture file="visuals/T_BC001.png" name="Container001_material" type="2d"/>
    <material name="Container001_material" rgba="1 1 1 0.10236221551895142" texture="Container001_material" shininess="0.5" specular="0.3103448502657381"/>
    <texture file="visuals/T_BC001.png" name="Lid002_material" type="2d"/>
    <material name="Lid002_material" rgba="1 1 1 1.0" texture="Lid002_material" shininess="0.141421377658844" specular="0.3103448502657381"/>
    <texture file="visuals/T_BC001.png" name="Lever001_material" type="2d"/>
    <material name="Lever001_material" rgba="1 1 1 1.0" texture="Lever001_material" shininess="0.141421377658844" specular="0.3103448502657381"/>
    <texture file="visuals/T_BC001.png" name="Lid001_material" type="2d"/>
    <material name="Lid001_material" rgba="1 1 1 1.0" texture="Lid001_material" shininess="0.141421377658844" specular="0.3103448502657381"/>
  </asset>
  <default>
    <default class="visual">
      <geom conaffinity="0" contype="0" group="1" type="mesh"/>
    </default>
    <default class="collision">
      <geom group="0" rgba="0.5 0 0 0.5"/>
    </default>
    <default class="spawn">
      <geom group="0" rgba="1 1 1 0.5" contype="0" conaffinity="0"/>
      <site group="0" rgba="1 1 1 0.5"/>
    </default>
    <default class="region">
      <geom group="1" conaffinity="0" contype="0" rgba="0 1 0 0"/>
    </default>
  </default>
  <worldbody>
    <body>
      <body name="object">
        <geom class="collision" type="cylinder" pos="0.090449 -0.048671 0.097544" size="0.011137444525957108 0.0008226927020587027" quat="0.7017298340797424 0.7017298340797424 0.08703598380088806 0.08703596144914627" name="start_button_2" rgba="0.0 0.5 0 0.5"/>
        <geom class="collision" type="cylinder" pos="-0.090480 -0.047437 0.097704" size="0.010598023422062397 0.0007483839290216565" quat="0.7017298340797424 0.7017298340797424 -0.08703597635030746 -0.08703596144914627" name="start_button_1" rgba="0.0 0.5 0 0.5"/>
        <site type="cylinder" rgba="0.8 0.5 0.25 1" size="0.0018364122370257974 0.06123407557606697" pos="0.000350 -0.047698 -0.095516" name="coffee_liquid"/>
        <site rgba="0 0 0 0" size="0.009999999776482582 0.009999999776482582" pos="0.000403 -0.047850 -0.142950" name="receptacle_place_site"/>
        <geom mesh="Body001_vis" type="mesh" solimp="0.998 0.998 0.001" solref="0.001 1" density="100" friction="0.95 0.3 0.1" class="visual" material="Body001_material"/>
        <geom class="collision" type="box" pos="-0.000032 0.173026 -0.018967" size="0.11273114383220673 0.0022655546199530363 0.14878633618354797" quat="1.0 0.0 0.0 0.0"/>
        <geom class="collision" type="box" pos="0.111902 0.094330 -0.019421" size="0.0011445436393842101 0.07677944749593735 0.1483321487903595" quat="1.0 0.0 0.0 0.0"/>
        <geom class="collision" type="box" pos="-0.112162 0.094330 -0.019421" size="0.0011445436393842101 0.07677944749593735 0.1483321487903595" quat="1.0 0.0 0.0 0.0"/>
        <geom class="collision" type="box" pos="0.000450 -0.000590 -0.014114" size="0.12807708978652954 0.019435109570622444 0.15363937616348267" quat="1.0 0.0 0.0 0.0"/>
        <geom class="collision" type="box" pos="0.000093 0.051148 0.132698" size="0.11322750896215439 0.0343429334461689 0.006827814970165491" quat="1.0 0.0 0.0 0.0"/>
        <geom class="collision" type="box" pos="-0.090140 -0.055218 -0.160338" size="0.04828904569149017 0.07455458492040634 0.007659596856683493" quat="1.0 0.0 0.0 0.0"/>
        <geom class="collision" type="box" pos="0.088155 -0.055218 -0.160338" size="0.047481801360845566 0.07455458492040634 0.007659596856683493" quat="1.0 0.0 0.0 0.0"/>
        <geom class="collision" type="box" pos="0.002571 -0.055218 -0.164359" size="0.047481801360845566 0.07455458492040634 0.003638563212007284" quat="1.0 0.0 0.0 0.0"/>
        <geom class="collision" type="cylinder" pos="-0.000128 -0.048285 0.086629" size="0.06338147819042206 0.05059664323925972" quat="1.0 0.0 0.0 0.0"/>
        <geom class="collision" type="cylinder" pos="-0.000128 -0.048285 0.024610" size="0.040189795196056366 0.016592320054769516" quat="1.0 0.0 0.0 0.0"/>
        <geom class="collision" type="box" pos="-0.082400 -0.020926 0.086467" size="0.04496154934167862 0.015863317996263504 0.05156942084431648" quat="0.9917343854904175 0.0 -0.0 -0.12830807268619537"/>
        <geom class="collision" type="box" pos="0.080596 -0.021905 0.086467" size="0.04496154934167862 0.013447819277644157 0.05156942084431648" quat="0.99053955078125 0.0 0.0 0.1372273564338684"/>
        <geom class="collision" type="box" pos="-0.000136 0.097057 -0.166278" size="0.1108209490776062 0.07455458492040634 0.0017192101804539561" quat="1.0 0.0 0.0 0.0"/>
        <body name="Button001">
          <joint axis="0.253505140542984 0.9673340320587158 0.0" pos="-0.089172 -0.042879 0.097302" limited="true" name="Button001_joint" range="0.0 0.003" type="slide" damping="1" frictionloss="1" armature=".01" stiffness="0.05"/>
          <geom mesh="Button001_vis" type="mesh" solimp="0.998 0.998 0.001" solref="0.001 1" density="100" friction="0.95 0.3 0.1" class="visual" material="Button001_material"/>
          <geom class="collision" type="cylinder" pos="-0.089460 -0.043386 0.097899" size="0.010598023422062397 0.0024867102038115263" quat="0.7017298340797424 0.7017298340797424 -0.08703597635030746 -0.08703596144914627"/>
        </body>
        <body name="Button002">
          <joint axis="-0.2837986648082733 0.9588838815689087 0.0" pos="0.089199 -0.042798 0.097302" limited="true" name="Button002_joint" range="0.0 0.003" type="slide" damping="1" frictionloss="1" armature=".01" stiffness="0.05"/>
          <geom mesh="Button002_vis" type="mesh" solimp="0.998 0.998 0.001" solref="0.001 1" density="100" friction="0.95 0.3 0.1" class="visual" material="Button002_material"/>
          <geom class="collision" type="cylinder" pos="0.089354 -0.044323 0.097544" size="0.011137444525957108 0.00261327950283885" quat="0.7017298340797424 0.7017298340797424 0.08703598380088806 0.08703596144914627"/>
        </body>
        <body name="Container001">
          <joint axis="0.0 0.0 1.0" pos="-0.000156 0.127895 -0.005753" limited="true" name="Container001_joint" range="0.0 0.08" type="slide" damping="1" frictionloss="1" armature=".01" stiffness="0.05"/>
          <geom mesh="Container001_vis" type="mesh" solimp="0.998 0.998 0.001" solref="0.001 1" density="100" friction="0.95 0.3 0.1" class="visual" material="Container001_material"/>
          <geom class="collision" type="box" pos="-0.108745 0.128394 -0.006294" size="0.0011445436393842101 0.03984048590064049 0.15463219583034515" quat="1.0 0.0 0.0 0.0"/>
          <geom class="collision" type="box" pos="0.108436 0.127816 -0.006294" size="0.0011445436393842101 0.039262186735868454 0.15463219583034515" quat="1.0 0.0 0.0 0.0"/>
          <geom class="collision" type="box" pos="-0.000004 0.167459 -0.005840" size="0.10761674493551254 0.0022655546199530363 0.15508638322353363" quat="1.0 0.0 0.0 0.0"/>
          <geom class="collision" type="box" pos="-0.000004 0.091286 -0.005840" size="0.10761674493551254 0.001458917511627078 0.15508638322353363" quat="1.0 0.0 0.0 0.0"/>
          <geom class="collision" type="box" pos="-0.000004 0.128790 -0.158367" size="0.10761674493551254 0.036772847175598145 0.002559768734499812" quat="1.0 0.0 0.0 0.0"/>
          <body name="Lid002">
            <joint axis="0.0 0.0 1.0" pos="0.003246 0.127898 0.144810" limited="true" name="Lid002_joint" range="0.0 0.08" type="slide" damping="1" frictionloss="1" armature=".01" stiffness="0.05"/>
            <geom mesh="Lid002_vis" type="mesh" solimp="0.998 0.998 0.001" solref="0.001 1" density="100" friction="0.95 0.3 0.1" class="visual" material="Lid002_material"/>
            <geom class="collision" type="box" pos="-0.000169 0.128938 0.159038" size="0.10886985808610916 0.040910542011260986 0.008760830387473106" quat="1.0 0.0 0.0 0.0"/>
            <geom class="collision" type="box" pos="0.000564 0.103579 0.136451" size="0.10489492863416672 0.009201103821396828 0.015179985202848911" quat="1.0 0.0 0.0 0.0"/>
          </body>
        </body>
        <body name="Lever001">
          <joint axis="0.0 0.0 1.0" pos="-0.000010 -0.047568 0.011542" limited="true" name="Lever001_joint" range="-0.7853981633974483 0.7853981633974483" type="hinge" damping="1" frictionloss="1" armature=".01" stiffness="1"/>
          <geom mesh="Lever001_vis" type="mesh" solimp="0.998 0.998 0.001" solref="0.001 1" density="100" friction="0.95 0.3 0.1" class="visual" material="Lever001_material"/>
          <geom class="collision" type="cylinder" pos="-0.000128 -0.048285 -0.006583" size="0.028990430757403374 0.013290840201079845" quat="1.0 0.0 0.0 0.0"/>
          <geom class="collision" type="cylinder" pos="-0.000128 -0.048285 -0.023946" size="0.00896037369966507 0.004774580243974924" quat="1.0 0.0 0.0 0.0"/>
          <geom class="collision" type="cylinder" pos="-0.000007 -0.047706 -0.031534" size="0.0068381293676793575 0.0032926544081419706" quat="1.0 0.0 0.0 0.0"/>
          <geom class="collision" type="cylinder" pos="0.000090 -0.132821 -0.004063" size="0.012957622297108173 0.04042704030871391" quat="0.7071067094802856 0.7071068286895752 0.0 0.0"/>
        </body>
        <body name="Lid001">
          <joint axis="0.0 0.0 1.0" pos="-0.000000 -0.085820 -0.155279" limited="true" name="Lid001_joint" range="0.0 0.06" type="slide" damping="1" frictionloss="1" armature=".01" stiffness="0.05"/>
          <geom mesh="Lid001_vis" type="mesh" solimp="0.998 0.998 0.001" solref="0.001 1" density="100" friction="0.95 0.3 0.1" class="visual" material="Lid001_material"/>
          <geom class="collision" type="box" pos="-0.000063 -0.080667 -0.154260" size="0.03887118771672249 0.054317377507686615 0.0012330027529969811" quat="1.0 0.0 0.0 0.0"/>
        </body>
        <geom class="region" name="reg_main" type="box" pos="0.0 0.013778499999999999 0.0" size="0.13795 0.1590935 0.167696"/>
      </body>
    </body>
  </worldbody>
  <actuator>
    <motor name="Button001_joint_actuator" joint="Button001_joint" gear="0.1"/>
    <motor name="Button002_joint_actuator" joint="Button002_joint" gear="0.1"/>
    <motor name="Container001_joint_actuator" joint="Container001_joint" gear="50"/>
    <motor name="Lever001_joint_actuator" joint="Lever001_joint" gear="50"/>
    <motor name="Lid001_joint_actuator" joint="Lid001_joint" gear="2"/>
    <motor name="Lid002_joint_actuator" joint="Lid002_joint" gear="10"/>
  </actuator>
</mujoco>
