<?xml version='1.0' encoding='UTF-8'?>
<mujoco model="model">
  <option timestep="0.002" gravity="0.0 0.0 -9.81"/>
  <compiler angle="radian"/>
  <asset>
    <mesh file="visuals/Body001.obj" name="Body001_vis"/>
    <mesh file="visuals/Container001.obj" name="Container001_vis"/>
    <mesh file="visuals/Door001.obj" name="Door001_vis"/>
    <mesh file="visuals/Door001_Clear.obj" name="Door001_Clear_vis"/>
    <mesh file="visuals/Knob001.obj" name="Knob001_vis"/>
    <mesh file="visuals/Knob002.obj" name="Knob002_vis"/>
    <texture file="visuals/T_BC001.png" name="Body001_material" type="2d"/>
    <material name="Body001_material" rgba="1 1 1 1.0" texture="Body001_material" shininess="0.4472135901451111" specular="1"/>
    <texture file="visuals/T_BC001.png" name="Container001_material" type="2d"/>
    <material name="Container001_material" rgba="1 1 1 1.0" texture="Container001_material" shininess="0.4472135901451111" specular="11"/>
    <texture file="visuals/T_BC001.png" name="Door001_material" type="2d"/>
    <material name="Door001_material" rgba="1 1 1 1.0" texture="Door001_material" shininess="0.4472135901451111" specular="2"/>
    <texture file="visuals/T_BC001.png" name="Door001_Clear_material" type="2d"/>
    <material name="Door001_Clear_material" rgba="1 1 1 0.699999988079071" texture="Door001_Clear_material" shininess="0.4472135901451111" specular="1"/>
    <texture file="visuals/T_BC001.png" name="Knob001_material" type="2d"/>
    <material name="Knob001_material" rgba="1 1 1 1.0" texture="Knob001_material" shininess="0.4472135901451111" specular="0.3103448502657381"/>
    <texture file="visuals/T_BC001.png" name="Knob002_material" type="2d"/>
    <material name="Knob002_material" rgba="1 1 1 1.0" texture="Knob002_material" shininess="0.4472135901451111" specular="0.3103448502657381"/>
  </asset>
  <default>
    <default class="visual">
      <geom conaffinity="0" contype="0" group="1" type="mesh"/>
    </default>
    <default class="collision">
      <geom group="0" rgba="0.5 0 0 0.5"/>
    </default>
    <default class="spawn">
      <geom group="0" rgba="1 1 1 0.5" contype="0" conaffinity="0"/>
      <site group="0" rgba="1 1 1 0.5"/>
    </default>
    <default class="region">
      <geom group="1" conaffinity="0" contype="0" rgba="0 1 0 0"/>
    </default>
  </default>
  <worldbody>
    <body>
      <body name="object">
        <geom mesh="Body001_vis" type="mesh" solimp="0.998 0.998 0.001" solref="0.001 1" friction="0.95 0.3 0.1" class="visual" material="Body001_material"/>
        <geom class="collision" type="box" pos="-0.000591 0.144889 0.005696" size="0.2506652772426605 0.010694536380469799 0.13638395071029663" quat="1.0 0.0 0.0 0.0" density="1000.0"/>
        <geom class="collision" type="box" pos="0.206856 0.015977 0.006473" size="0.044854067265987396 0.13960707187652588 0.13716137409210205" quat="1.0 0.0 0.0 0.0" density="1000.0"/>
        <geom class="collision" type="box" pos="-0.029866 0.024058 0.137175" size="0.20402953028678894 0.13152606785297394 0.006459514610469341" quat="1.0 0.0 0.0 0.0" density="1000.0"/>
        <geom class="collision" type="box" pos="-0.038773 0.030651 -0.114524" size="0.21293650567531586 0.12493230402469635 0.01616460084915161" quat="1.0 0.0 0.0 0.0" density="1000.0"/>
        <geom class="collision" type="box" pos="0.199090 0.023631 0.006473" size="0.044854067265987396 0.13195276260375977 0.13716138899326324" quat="1.0 0.0 0.0 0.0" density="1000.0"/>
        <geom class="collision" type="box" pos="-0.238409 0.028928 0.006473" size="0.0133005166426301 0.12665598094463348 0.13716137409210205" quat="1.0 0.0 0.0 0.0" density="1000.0"/>
        <geom class="collision" type="box" pos="-0.222577 0.025209 0.027683" size="0.0060947914607822895 0.10913117974996567 0.0057051172479987144" quat="1.0 0.0 0.0 0.0" density="1000.0"/>
        <geom class="collision" type="box" pos="-0.222577 0.025209 -0.017802" size="0.0060947914607822895 0.10913117974996567 0.0057051172479987144" quat="1.0 0.0 0.0 0.0" density="1000.0"/>
        <geom class="collision" type="box" pos="0.150567 0.025209 -0.017802" size="0.0060947914607822895 0.10913117974996567 0.0057051172479987144" quat="1.0 0.0 0.0 0.0" density="1000.0"/>
        <geom class="collision" type="box" pos="0.150567 0.025209 0.027683" size="0.0060947914607822895 0.10913117974996567 0.0057051172479987144" quat="1.0 0.0 0.0 0.0" density="1000.0"/>
        <geom class="collision" type="box" pos="-0.238613 0.015652 0.006473" size="0.013097071088850498 0.13993124663829803 0.13716137409210205" quat="1.0 0.0 0.0 0.0" density="1000.0"/>
        <geom class="collision" type="box" pos="-0.038773 0.016607 -0.126554" size="0.21293650567531586 0.12613962590694427 0.00413384148851037" quat="1.0 0.0 0.0 0.0" density="1000.0"/>
        <geom class="collision" type="box" pos="0.224487 0.126756 -0.133728" size="0.009973940439522266 0.009973940439522266 0.009906512685120106" quat="1.0 0.0 0.0 0.0" density="1000.0"/>
        <geom class="collision" type="box" pos="-0.226699 -0.083618 -0.133728" size="0.009973935782909393 0.009973935782909393 0.009906508028507233" quat="1.0 0.0 0.0 0.0" density="1000.0"/>
        <geom class="collision" type="box" pos="-0.226699 0.126756 -0.133728" size="0.00997393112629652 0.00997393112629652 0.00990650337189436" quat="1.0 0.0 0.0 0.0" density="1000.0"/>
        <geom class="collision" type="box" pos="0.224487 -0.083618 -0.133728" size="0.009973926469683647 0.009973926469683647 0.009906498715281487" quat="1.0 0.0 0.0 0.0" density="1000.0"/>
        <body name="Container001">
          <joint axis="0.0 -1.0 0.0" pos="-0.035610 0.022472 -0.017467" limited="true" name="Container001_joint" range="0.0 0.19" type="slide" damping="1" frictionloss="1" armature=".01" stiffness="0.05"/>
          <geom mesh="Container001_vis" type="mesh" solimp="0.998 0.998 0.001" solref="0.001 1" friction="0.95 0.3 0.1" class="visual" material="Container001_material"/>
          <geom class="collision" type="box" pos="0.136043 0.021269 -0.017378" size="0.09847038239240646 0.008824340999126434 0.0015168222598731518" quat="0.5913967490196228 0.3876209557056427 -0.38762110471725464 -0.5913964509963989" density="1000.0"/>
          <geom class="collision" type="box" pos="-0.034983 0.021269 -0.025562" size="0.17033974826335907 0.09847010672092438 0.0015168222598731518" quat="1.0 0.0 0.0 0.0" density="1000.0"/>
          <geom class="collision" type="box" pos="-0.034208 0.124664 -0.017891" size="0.1700173318386078 0.008824369870126247 0.001516826217994094" quat="1.7852143230356887e-07 1.0509911874123645e-07 0.6175944209098816 -0.7864967584609985" density="1000.0"/>
          <geom class="collision" type="box" pos="-0.207053 0.021269 -0.017378" size="0.09847038239240646 0.008824340999126434 0.0015168222598731518" quat="0.5913967490196228 -0.3876209557056427 0.38762110471725464 -0.5913964509963989" density="1000.0"/>
          <geom class="collision" type="box" pos="-0.034208 -0.079626 -0.017891" size="0.1700173318386078 0.008824369870126247 0.001516826217994094" quat="2.7227920895711577e-07 -3.147618343746217e-08 -0.6175944209098816 -0.7864967584609985" density="1000.0"/>
          <geom class="collision" type="box" pos="-0.030316 0.128913 -0.009095" size="0.16417618095874786 0.002867063507437706 0.0010925796814262867" quat="1.0 0.0 0.0 0.0" density="1000.0"/>
          <geom class="collision" type="box" pos="-0.030316 -0.083895 -0.009095" size="0.16417618095874786 0.002867063507437706 0.0010925796814262867" quat="1.0 0.0 0.0 0.0" density="1000.0"/>
          <geom class="collision" type="box" pos="0.143404 0.021546 -0.009095" size="0.004880692344158888 0.09095386415719986 0.0010925796814262867" quat="1.0 0.0 0.0 0.0" density="1000.0"/>
          <geom class="collision" type="box" pos="0.136165 -0.075995 -0.009095" size="0.01407044567167759 0.004880691412836313 0.0010925796814262867" quat="0.3579157590866089 0.0 -0.0 -0.9337539076805115" density="1000.0"/>
          <geom class="collision" type="box" pos="0.136472 0.120892 -0.009095" size="0.014070444740355015 0.004880690947175026 0.0010925796814262867" quat="0.35791587829589844 0.0 0.0 0.9337538480758667" density="1000.0"/>
          <geom class="collision" type="box" pos="-0.205810 0.120892 -0.009095" size="0.014070444740355015 0.004880690947175026 0.0010925796814262867" quat="0.35791587829589844 0.0 -0.0 -0.9337538480758667" density="1000.0"/>
          <geom class="collision" type="box" pos="-0.205504 -0.075995 -0.009095" size="0.014070444740355015 0.004880690947175026 0.0010925796814262867" quat="0.35791587829589844 0.0 0.0 0.9337538480758667" density="1000.0"/>
          <geom class="collision" type="box" pos="-0.212743 0.021546 -0.009095" size="0.004880692344158888 0.09095386415719986 0.0010925796814262867" quat="1.0 0.0 0.0 0.0" density="1000.0"/>
        </body>
        <body name="Door001">
          <joint axis="1.0 0.0 0.0" pos="-0.035425 -0.122561 -0.124826" limited="true" name="Door001_joint" range="0.0 1.5707963267948966" type="hinge" damping="1" frictionloss="1" armature=".01" stiffness="1" springref="-0.1"/>
          <geom mesh="Door001_vis" type="mesh" solimp="0.998 0.998 0.001" solref="0.001 1" friction="0.95 0.3 0.1" class="visual" material="Door001_material"/>
          <geom class="collision" type="box" pos="-0.035263 -0.117486 0.006399" size="0.1890205442905426 0.0064972518011927605 0.13636209070682526" quat="1.0 0.0 0.0 0.0" density="1000.0"/>
          <geom class="collision" type="box" pos="-0.212937 -0.138453 0.123513" size="0.008080609142780304 0.013857204467058182 0.01037103496491909" quat="1.0 0.0 0.0 0.0" density="1000.0"/>
          <geom class="collision" type="box" pos="0.144593 -0.137978 0.122990" size="0.008163787424564362 0.013382012024521828 0.011532559990882874" quat="1.0 0.0 0.0 0.0" density="1000.0"/>
          <geom class="collision" type="cylinder" pos="-0.035811 -0.141623 0.124343" size="0.008574376814067364 0.1726255565881729" quat="0.7071068286895752 -4.750302551315144e-08 -0.7071067094802856 -4.7503014855010406e-08" density="1000.0"/>
          <body name="Door001_Clear">
            <geom mesh="Door001_Clear_vis" type="mesh" solimp="0.998 0.998 0.001" solref="0.001 1" friction="0.95 0.3 0.1" class="visual" material="Door001_Clear_material"/>
            <geom class="collision" type="box" pos="-0.035409 -0.116732 0.013374" size="0.18871034681797028 0.0024410283658653498 0.10646211355924606" quat="1.0 0.0 0.0 0.0" density="1000.0"/>
          </body>
        </body>
        <body name="Knob001">
          <joint axis="0.0 1.0 0.0" pos="0.206391 -0.139787 0.068117" limited="true" name="Knob001_joint" range="0.0 4.4505895925855405" type="hinge" damping="0.05" armature="0.001" springref="-0.4"/>
          <geom mesh="Knob001_vis" type="mesh" solimp="0.998 0.998 0.001" solref="0.001 1" friction="0.95 0.3 0.1" class="visual" material="Knob001_material"/>
          <geom class="collision" type="cylinder" pos="0.206782 -0.131116 0.067967" size="0.027087995782494545 0.005860324949026108" quat="0.7071068286895752 0.7071067690849304 1.5700924318127872e-16 5.9269340452702814e-24" density="1000.0"/>
          <geom class="collision" type="box" pos="0.206096 -0.145827 0.068112" size="0.020894603803753853 0.009981375187635422 0.006096269004046917" quat="1.0 0.0 0.0 0.0" density="1000.0"/>
        </body>
        <body name="Knob002">
          <joint axis="0.0 1.0 0.0" pos="0.206391 -0.139787 -0.058605" limited="true" name="Knob002_joint" range="0.0 4.71238898038469" type="hinge" damping="0.05" armature="0.001" springref="-0.4"/>
          <geom mesh="Knob002_vis" type="mesh" solimp="0.998 0.998 0.001" solref="0.001 1" friction="0.95 0.3 0.1" class="visual" material="Knob002_material"/>
          <geom class="collision" type="box" pos="0.206096 -0.145827 -0.058324" size="0.020894603803753853 0.009981375187635422 0.006096269004046917" quat="1.0 0.0 0.0 0.0" density="1000.0"/>
          <geom class="collision" type="cylinder" pos="0.206579 -0.131116 -0.058490" size="0.027087995782494545 0.005860324949026108" quat="0.7071068286895752 0.7071067690849304 1.5700924318127872e-16 5.9269340452702814e-24" density="1000.0"/>
        </body>
        <geom class="region" name="reg_int" type="box" pos="-0.036181500000000005 0.018352 0.016140499999999995" size="0.1893995 0.11583099999999999 0.11470949999999999"/>
        <geom class="region" name="reg_main" type="box" pos="0.0 0.015573000000000004 0.0" size="0.251709 0.140011 0.143635"/>
      </body>
    </body>
  </worldbody>
  <actuator>
    <motor name="Container001_joint_actuator" joint="Container001_joint" gear="10"/>
    <motor name="Door001_joint_actuator" joint="Door001_joint" gear="10"/>
    <motor name="Knob001_joint_actuator" joint="Knob001_joint" gear="10"/>
    <motor name="Knob002_joint_actuator" joint="Knob002_joint" gear="10"/>
  </actuator>
</mujoco>
