<?xml version='1.0' encoding='UTF-8'?>
<mujoco model="model">
  <compiler angle="radian"/>
  <asset>
    <mesh file="visuals/Body001.obj" name="Body001_vis"/>
    <mesh file="visuals/Button001.obj" name="Button001_vis"/>
    <mesh file="visuals/Button002.obj" name="Button002_vis"/>
    <mesh file="visuals/Button003.obj" name="Button003_vis"/>
    <mesh file="visuals/Button004.obj" name="Button004_vis"/>
    <mesh file="visuals/Container001_Clear.obj" name="Container001_Clear_vis"/>
    <mesh file="visuals/Lid001.obj" name="Lid001_vis"/>
    <mesh file="visuals/Lid002.obj" name="Lid002_vis"/>
    <mesh file="visuals/Lid003.obj" name="Lid003_vis"/>
    <texture file="visuals/T_BC001.png" name="Body001_material" type="2d"/>
    <material name="Body001_material" rgba="1 1 1 1.0" texture="Body001_material" shininess="0.4472135901451111" specular="0.3103448502657381"/>
    <texture file="visuals/T_BC001.png" name="Button001_material" type="2d"/>
    <material name="Button001_material" rgba="1 1 1 1.0" texture="Button001_material" shininess="0.4472135901451111" specular="0.3103448502657381"/>
    <texture file="visuals/T_BC001.png" name="Button002_material" type="2d"/>
    <material name="Button002_material" rgba="1 1 1 1.0" texture="Button002_material" shininess="0.4472135901451111" specular="0.3103448502657381"/>
    <texture file="visuals/T_BC001.png" name="Button003_material" type="2d"/>
    <material name="Button003_material" rgba="1 1 1 1.0" texture="Button003_material" shininess="0.4472135901451111" specular="0.3103448502657381"/>
    <texture file="visuals/T_BC001.png" name="Button004_material" type="2d"/>
    <material name="Button004_material" rgba="1 1 1 1.0" texture="Button004_material" shininess="0.4472135901451111" specular="0.3103448502657381"/>
    <texture file="visuals/T_BC001.png" name="Container001_Clear_material" type="2d"/>
    <material name="Container001_Clear_material" rgba="1 1 1 0.08522725850343704" texture="Container001_Clear_material" shininess="0.4472135901451111" specular="0.3103448502657381"/>
    <texture file="visuals/T_BC001.png" name="Lid003_material" type="2d"/>
    <material name="Lid003_material" rgba="1 1 1 1.0" texture="Lid003_material" shininess="0.4472135901451111" specular="0.3103448502657381"/>
    <texture file="visuals/T_BC001.png" name="Lid001_material" type="2d"/>
    <material name="Lid001_material" rgba="1 1 1 1.0" texture="Lid001_material" shininess="0.4472135901451111" specular="0.3103448502657381"/>
    <texture file="visuals/T_BC001.png" name="Lid002_material" type="2d"/>
    <material name="Lid002_material" rgba="1 1 1 1.0" texture="Lid002_material" shininess="0.4472135901451111" specular="0.3103448502657381"/>
  </asset>
  <default>
    <default class="visual">
      <geom conaffinity="0" contype="0" group="1" type="mesh"/>
    </default>
    <default class="collision">
      <geom group="0" rgba="0.5 0 0 0.5"/>
    </default>
    <default class="spawn">
      <geom group="0" rgba="1 1 1 0.5" contype="0" conaffinity="0"/>
      <site group="0" rgba="1 1 1 0.5"/>
    </default>
    <default class="region">
      <geom group="1" conaffinity="0" contype="0" rgba="0 1 0 0"/>
    </default>
  </default>
  <worldbody>
    <body>
      <body name="object">
        <geom class="collision" type="box" pos="0.0023014722391963005 -0.08887161314487457 0.04597444459795952" size="0.008300304412841797 0.0010326285846531391 0.008300304412841797" quat="1.0 0.0 0.0 0.0" name="start_button_1" rgba="0.0 0.5 0 0.5"/>
        <geom class="collision" type="box" pos="0.05928201973438263 -0.08887161314487457 0.046440597623586655" size="0.008300304412841797 0.0010326285846531391 0.008300304412841797" quat="1.0 0.0 0.0 0.0" name="start_button_2" rgba="0.0 0.5 0 0.5"/>
        <site rgba="0 0 0 0" size="0.009999999776482582 0.009999999776482582" pos="-0.0447867214679718 -0.1068628579378128 -0.1122182235121727" name="receptacle_place_site"/>
        <site type="cylinder" rgba="0.8 0.5 0.25 1" size="0.001977270469069481 0.07593875378370285" pos="-0.0447867214679718 -0.1068628579378128 -0.055097322911024094" name="coffee_liquid"/>
        <geom mesh="Body001_vis" type="mesh" solimp="0.998 0.998 0.001" solref="0.001 1" density="100" friction="0.95 0.3 0.1" class="visual" material="Body001_material"/>
        <geom class="collision" type="box" pos="4.882787185306112e-18 0.013790412805974483 -0.061125073581933975" size="0.10008688271045685 0.10008688271045685 0.08089204132556915" quat="1.0 0.0 0.0 0.0"/>
        <geom class="collision" type="box" pos="-1.1089720959284048e-17 -0.1318216621875763 -0.13305886089801788" size="0.10008585453033447 0.045906733721494675 0.008728821761906147" quat="1.0 0.0 0.0 0.0"/>
        <geom class="collision" type="box" pos="-0.00031712139025330544 0.146804079413414 -0.13405242562294006" size="0.0702059268951416 0.0330178439617157 0.008667407557368279" quat="1.0 0.0 0.0 0.0"/>
        <geom class="collision" type="box" pos="-0.09768059849739075 0.013790412805974483 0.07078438252210617" size="0.003488542279228568 0.10008585453033447 0.05157922953367233" quat="1.0 0.0 0.0 0.0"/>
        <geom class="collision" type="box" pos="0.09741516411304474 0.013790412805974483 0.07078438252210617" size="0.003488542279228568 0.10008585453033447 0.05157922953367233" quat="1.0 0.0 0.0 0.0"/>
        <geom class="collision" type="box" pos="0.0007963106036186218 0.11079216748476028 0.07078438252210617" size="0.10008585453033447 0.003075146581977606 0.05157922953367233" quat="1.0 0.0 0.0 0.0"/>
        <geom class="collision" type="box" pos="0.0007963106036186218 -0.07727070152759552 0.07078438252210617" size="0.10008585453033447 0.0034885494969785213 0.05157922953367233" quat="1.0 0.0 0.0 0.0"/>
        <geom class="collision" type="cylinder" pos="-0.045015737414360046 -0.10933660715818405 0.06720112264156342" size="0.036918606609106064 0.02303718402981758" quat="0.7071068286895752 0.7071067690849304 -1.5700924318127872e-16 -5.9269340452702814e-24"/>
        <geom class="collision" type="cylinder" pos="-0.045015737414360046 -0.10694818943738937 0.025000233203172684" size="0.0059601073153316975 0.006257383152842522" quat="7.549790126404332e-08 1.0 -2.220446049250313e-16 -1.7645063234279917e-24"/>
        <body name="Button001">
          <joint axis="0.0 1.0 0.0" pos="0.0023014722391963005 -0.08683280646800995 0.10555990785360336" limited="true" name="Button001_joint" range="0.0 0.002" type="slide" damping="1" frictionloss="1" armature=".01" stiffness="0.05"/>
          <geom mesh="Button001_vis" type="mesh" solimp="0.998 0.998 0.001" solref="0.001 1" density="100" friction="0.95 0.3 0.1" class="visual" material="Button001_material"/>
          <geom class="collision" type="box" pos="0.0023014722391963005 -0.08740539103746414 0.10555990785360336" size="0.008300304412841797 0.0025703059509396553 0.008300304412841797" quat="1.0 0.0 0.0 0.0"/>
        </body>
        <body name="Button002">
          <joint axis="0.0 1.0 0.0" pos="0.0023014722391963005 -0.08683280646800995 0.04597444459795952" limited="true" name="Button002_joint" range="0.0 0.002" type="slide" damping="1" frictionloss="1" armature=".01" stiffness="0.05"/>
          <geom mesh="Button002_vis" type="mesh" solimp="0.998 0.998 0.001" solref="0.001 1" density="100" friction="0.95 0.3 0.1" class="visual" material="Button002_material"/>
          <geom class="collision" type="box" pos="0.0023014722391963005 -0.08586771786212921 0.04597444459795952" size="0.008300304412841797 0.0010326285846531391 0.008300304412841797" quat="1.0 0.0 0.0 0.0"/>
        </body>
        <body name="Button003">
          <joint axis="0.0 1.0 0.0" pos="0.05928201973438263 -0.08683280646800995 0.046440597623586655" limited="true" name="Button003_joint" range="0.0 0.002" type="slide" damping="1" frictionloss="1" armature=".01" stiffness="0.05"/>
          <geom mesh="Button003_vis" type="mesh" solimp="0.998 0.998 0.001" solref="0.001 1" density="100" friction="0.95 0.3 0.1" class="visual" material="Button003_material"/>
          <geom class="collision" type="box" pos="0.05928201973438263 -0.08586771786212921 0.046440597623586655" size="0.008300304412841797 0.0010326285846531391 0.008300304412841797" quat="1.0 0.0 0.0 0.0"/>
        </body>
        <body name="Button004">
          <joint axis="0.0 1.0 0.0" pos="0.05985260009765625 -0.08683280646800995 0.10551892220973969" limited="true" name="Button004_joint" range="0.0 0.002" type="slide" damping="1" frictionloss="1" armature=".01" stiffness="0.05"/>
          <geom mesh="Button004_vis" type="mesh" solimp="0.998 0.998 0.001" solref="0.001 1" density="100" friction="0.95 0.3 0.1" class="visual" material="Button004_material"/>
          <geom class="collision" type="box" pos="0.05985260009765625 -0.08740539103746414 0.10551892220973969" size="0.008300304412841797 0.0025703059509396553 0.008300304412841797" quat="1.0 0.0 0.0 0.0"/>
        </body>
        <body name="Container001_Clear">
          <joint axis="0.0 0.0 1.0" pos="2.980229396598588e-10 0.14678798615932465 -0.031096165999770164" limited="true" name="Container001_Clear_joint" range="0.0 0.1" type="slide" damping="1" frictionloss="1" armature=".01" stiffness="0.05"/>
          <geom mesh="Container001_Clear_vis" type="mesh" solimp="0.998 0.998 0.001" solref="0.001 1" density="100" friction="0.95 0.3 0.1" class="visual" material="Container001_Clear_material"/>
          <geom class="collision" type="box" pos="0.06621094048023224 0.14533287286758423 -0.02769089676439762" size="0.003281337907537818 0.03006349876523018 0.09629078209400177" quat="1.0 0.0 0.0 0.0"/>
          <geom class="collision" type="box" pos="-0.06711609661579132 0.14533287286758423 -0.02769089676439762" size="0.003281337907537818 0.03006349876523018 0.09629078209400177" quat="1.0 0.0 0.0 0.0"/>
          <geom class="collision" type="box" pos="0.0008054756326600909 0.17619913816452026 -0.02769089676439762" size="0.06483401358127594 0.003281342564150691 0.09629052132368088" quat="1.0 0.0 0.0 0.0"/>
          <geom class="collision" type="box" pos="-0.0002569332718849182 0.1161046102643013 -0.02769089676439762" size="0.06531772762537003 0.001457463251426816 0.09629078209400177" quat="1.0 0.0 0.0 0.0"/>
          <geom class="collision" type="box" pos="-0.00031712139025330544 0.147213876247406 -0.12145890295505524" size="0.0702059268951416 0.03260790929198265 0.0023581520654261112" quat="1.0 0.0 0.0 0.0"/>
          <body name="Lid003">
            <joint axis="0.0 0.0 1.0" pos="6.375278083226021e-09 0.14678798615932465 0.08263865113258362" limited="true" name="Lid003_joint" range="0.0 0.1" type="slide" damping="1" frictionloss="1" armature=".01" stiffness="0.05"/>
            <geom mesh="Lid003_vis" type="mesh" solimp="0.998 0.998 0.001" solref="0.001 1" density="100" friction="0.95 0.3 0.1" class="visual" material="Lid003_material"/>
            <geom class="collision" type="box" pos="-5.875591607650734e-17 0.14727617800235748 0.08293814957141876" size="0.0693642869591713 0.031903162598609924 0.013005714863538742" quat="1.0 0.0 0.0 0.0"/>
          </body>
        </body>
        <body name="Lid001">
          <joint axis="0.0 0.0 1.0" pos="3.993511299427155e-09 -0.1324775665998459 -0.12292581796646118" limited="true" name="Lid001_joint" range="0.0 0.1" type="slide" damping="1" frictionloss="1" armature=".01" stiffness="0.05"/>
          <geom mesh="Lid001_vis" type="mesh" solimp="0.998 0.998 0.001" solref="0.001 1" density="100" friction="0.95 0.3 0.1" class="visual" material="Lid001_material"/>
          <geom class="collision" type="box" pos="-1.1075371030017479e-17 -0.1325971633195877 -0.12209959328174591" size="0.09397474676370621 0.03802613541483879 0.001194323762319982" quat="1.0 0.0 0.0 0.0"/>
        </body>
        <body name="Lid002">
          <joint axis="-1.0 0.0 0.0" pos="-3.613531696089467e-09 0.11044695973396301 0.12317078560590744" limited="true" name="Lid002_joint" range="0.0 1.5707963267948966" type="hinge" damping="1" frictionloss="1" armature=".01" stiffness="0.05"/>
          <geom mesh="Lid002_vis" type="mesh" solimp="0.998 0.998 0.001" solref="0.001 1" density="100" friction="0.95 0.3 0.1" class="visual" material="Lid002_material"/>
          <geom class="collision" type="box" pos="-5.1300338692219886e-17 0.013338963501155376 0.12568268179893494" size="0.09676413983106613 0.09718197584152222 0.0022215046919882298" quat="1.0 0.0 0.0 0.0"/>
          <geom class="collision" type="box" pos="-0.045348159968853 -0.04886287450790405 0.13100895285606384" size="0.029819726943969727 0.028848541900515556 0.003581394674256444" quat="1.0 0.0 0.0 0.0"/>
          <geom class="collision" type="box" pos="-0.045348159968853 -0.0955483689904213 0.13635994493961334" size="0.029819726943969727 0.018413500860333443 0.002973356284201145" quat="0.9914448261260986 -0.1305263340473175 2.898265504095948e-17 -1.1035940224760099e-24"/>
        </body>
        <geom class="region" name="reg_main" type="box" pos="1.862645149230957e-09 0.0 0.0" size="0.10287211835384369 0.17996466159820557 0.14299067854881287"/>
      </body>
    </body>
  </worldbody>
  <actuator>
    <motor name="Button001_joint_actuator" joint="Button001_joint" gear="0.1"/>
    <motor name="Button002_joint_actuator" joint="Button002_joint" gear="0.1"/>
    <motor name="Button003_joint_actuator" joint="Button003_joint" gear="0.1"/>
    <motor name="Button004_joint_actuator" joint="Button004_joint" gear="0.1"/>
    <motor name="Container001_Clear_joint_actuator" joint="Container001_Clear_joint" gear="12"/>
    <motor name="Lid001_joint_actuator" joint="Lid001_joint" gear="5"/>
    <motor name="Lid002_joint_actuator" joint="Lid002_joint" gear="5"/>
    <motor name="Lid003_joint_actuator" joint="Lid003_joint" gear="10"/>
  </actuator>
</mujoco>
