<mujoco model="model">
  <asset>
    <texture type="2d" name="image0" file="visuals/image0.png"/>
    <material name="checker" texture="image0" specular="0.5" shininess="0.25"/>
    <mesh file="visuals/model_0.obj" name="model_0_vis" scale="1 1 1"/>
    <mesh file="visuals/knob_rear_right_0.obj" name="knob_rear_right_0_vis" scale="1 1 1"/>
    <mesh file="visuals/knob_front_left_0.obj" name="knob_front_left_0_vis" scale="1 1 1"/>
    <mesh file="visuals/knob_front_right_0.obj" name="knob_front_right_0_vis" scale="1 1 1"/>
    <mesh file="visuals/knob_rear_left_0.obj" name="knob_rear_left_0_vis" scale="1 1 1"/>
    <mesh file="visuals/knob_center_0.obj" name="knob_center_0_vis" scale="1 1 1"/>
  </asset>
  <default>
    <default class="visual">
      <geom conaffinity="0" contype="0" group="1" type="mesh"/>
    </default>
    <default class="collision">
      <geom group="0" rgba="0.5 0 0 0.5"/>
    </default>
    <default class="region">
      <geom group="1" conaffinity="0" contype="0" rgba="0 1 0 0"/>
    </default>
  </default>
  <worldbody>
    <body>
      <!-- exterior bounding box points -->
      <!-- interior bounding box points -->
      <body name="object">
        <geom solimp="0.998 0.998 0.001" solref="0.001 1" density="100" friction="0.95 0.3 0.1" type="mesh" mesh="model_0_vis" material="checker" class="visual"/>
        <geom class="collision" type="box" pos="0 0 -0.014" size="0.5 0.275 0.015"/>
        <geom class="collision" type="box" pos="-0.34 -0.141 0.014" size="0.1 0.1 0.016"/>
        <geom class="collision" type="box" pos="-0.34 0.142 0.014" size="0.1 0.1 0.016"/>
        <geom class="collision" type="box" pos="0.34 -0.141 0.014" size="0.1 0.1 0.016"/>
        <geom class="collision" type="box" pos="0.34 0.142 0.014" size="0.1 0.1 0.016"/>
        <geom class="collision" type="box" pos="0 0.04 0.014" size="0.12 0.12 0.016"/>
        <!-- Burners -->
        <site name="burner_on_front_left" pos="-0.34 -0.142 0.014" size="0.06 0.004" rgba="0.3 0.4 1 0.5" type="cylinder"/>
        <site name="burner_on_front_right" pos="0.34 -0.141 0.014" size="0.04 0.004" rgba="0.3 0.4 1 0.5" type="cylinder"/>
        <site name="burner_on_rear_left" pos="-0.34 0.142 0.014" size="0.06 0.004" rgba="0.3 0.4 1 0.5" type="cylinder"/>
        <site name="burner_on_rear_right" pos="0.34 0.142 0.014" size="0.07 0.004" rgba="0.3 0.4 1 0.5" type="cylinder"/>
        <site name="burner_on_center" pos="0 0.04 0.014" size="0.09 0.004" rgba="0.3 0.4 1 0.5" type="cylinder"/>
        <body name="knob_rear_right">
          <joint name="knob_rear_right_joint" type="hinge" axis="0 0 1" pos="0.06076 -0.205 0.0072" damping="1" armature="2"/>
          <geom solimp="0.998 0.998 0.001" solref="0.001 1" density="100" friction="0.95 0.3 0.1" type="mesh" mesh="knob_rear_right_0_vis" material="checker" class="visual"/>
          <geom class="collision" type="cylinder" pos="0.06076 -0.205 0.0075" size="0.0195 0.0062"/>
          <geom class="collision" type="box" pos="0.06076 -0.205 0.018" size="0.0074 0.0195 0.0046"/>
        </body>
        <body name="knob_front_left">
          <joint name="knob_front_left_joint" type="hinge" axis="0 0 1" pos="-0.1247 -0.205 0.0072" damping="1" armature="2"/>
          <geom solimp="0.998 0.998 0.001" solref="0.001 1" density="100" friction="0.95 0.3 0.1" type="mesh" mesh="knob_front_left_0_vis" material="checker" class="visual"/>
          <geom class="collision" type="cylinder" pos="-0.1247 -0.205 0.0075" size="0.0195 0.0062"/>
          <geom class="collision" type="box" pos="-0.1247 -0.205 0.018" size="0.0074 0.0195 0.0046"/>
        </body>
        <body name="knob_front_right">
          <joint name="knob_front_right_joint" type="hinge" axis="0 0 1" pos="0.1226 -0.205 0.0072" damping="1" armature="2"/>
          <geom solimp="0.998 0.998 0.001" solref="0.001 1" density="100" friction="0.95 0.3 0.1" type="mesh" mesh="knob_front_right_0_vis" material="checker" class="visual"/>
          <geom class="collision" type="cylinder" pos="0.1226 -0.205 0.0075" size="0.0195 0.0062"/>
          <geom class="collision" type="box" pos="0.1226 -0.205 0.018" size="0.0074 0.0195 0.0046"/>
        </body>
        <body name="knob_rear_left">
          <joint name="knob_rear_left_joint" type="hinge" axis="0 0 1" pos="-0.06285 -0.205 0.0072" damping="1" armature="2"/>
          <geom solimp="0.998 0.998 0.001" solref="0.001 1" density="100" friction="0.95 0.3 0.1" type="mesh" mesh="knob_rear_left_0_vis" material="checker" class="visual"/>
          <geom class="collision" type="cylinder" pos="-0.06285 -0.205 0.0075" size="0.0195 0.0062"/>
          <geom class="collision" type="box" pos="-0.06285 -0.205 0.018" size="0.0074 0.0195 0.0046"/>
        </body>
        <body name="knob_center">
          <joint name="knob_center" type="hinge" axis="0 0 1" pos="-0.001 -0.205 0.0072" damping="1" armature="2"/>
          <geom solimp="0.998 0.998 0.001" solref="0.001 1" density="100" friction="0.95 0.3 0.1" type="mesh" mesh="knob_center_0_vis" material="checker" class="visual"/>
          <geom class="collision" type="cylinder" pos="-0.001 -0.205 0.0075" size="0.0195 0.0062"/>
          <geom class="collision" type="box" pos="-0.001 -0.205 0.018" size="0.0074 0.0195 0.0046"/>
        </body>
        <geom class="region" name="reg_main" type="box" pos="0.0 0.0 -0.017499999999999998" size="0.5 0.27 0.012499999999999999"/>
        <geom class="region" name="reg_int" type="box" pos="0.0 0.0 0.0" size="0.0001 0.0001 0.0001"/>
      </body>
    </body>
  </worldbody>
</mujoco>
