<?xml version='1.0' encoding='UTF-8'?>
<mujoco model="model">
  <option timestep="0.002" gravity="0.0 0.0 -9.81"/>
  <compiler angle="radian"/>
  <asset>
    <mesh file="visuals/Blender001.obj" name="Blender001_vis"/>
    <mesh file="visuals/Body001.obj" name="Body001_vis"/>
    <mesh file="visuals/Container001.obj" name="Container001_vis"/>
    <mesh file="visuals/Konb001.obj" name="Konb001_vis"/>
    <mesh file="visuals/Lever001.obj" name="Lever001_vis"/>
    <mesh file="visuals/Lid001.obj" name="Lid001_vis"/>
    <texture file="visuals/T_BC001.png" name="Body001_material" type="2d"/>
    <material name="Body001_material" rgba="1 1 1 1.0" texture="Body001_material" shininess="0.5" specular="1"/>
    <texture file="visuals/T_BC001.png" name="Container001_material" type="2d"/>
    <material name="Container001_material" rgba="1 1 1 1.0" texture="Container001_material" shininess="0.5" specular="2"/>
    <texture file="visuals/T_BC001.png" name="Lever001_material" type="2d"/>
    <material name="Lever001_material" rgba="1 1 1 1.0" texture="Lever001_material" shininess="0.5" specular="0.3103448502657381"/>
    <texture file="visuals/T_BC001.png" name="Lid001_material" type="2d"/>
    <material name="Lid001_material" rgba="1 1 1 1.0" texture="Lid001_material" shininess="0.5" specular="2"/>
    <texture file="visuals/T_BC001.png" name="Blender001_material" type="2d"/>
    <material name="Blender001_material" rgba="1 1 1 1.0" texture="Blender001_material" shininess="0.5" specular="2"/>
    <texture file="visuals/T_BC001.png" name="Konb001_material" type="2d"/>
    <material name="Konb001_material" rgba="1 1 1 1.0" texture="Konb001_material" shininess="0.5" specular="0.3103448502657381"/>
  </asset>
  <default>
    <default class="visual">
      <geom conaffinity="0" contype="0" group="1" type="mesh"/>
    </default>
    <default class="collision">
      <geom group="0" rgba="0.5 0 0 0.5"/>
    </default>
    <default class="spawn">
      <geom group="0" rgba="1 1 1 0.5" contype="0" conaffinity="0"/>
      <site group="0" rgba="1 1 1 0.5"/>
    </default>
    <default class="region">
      <geom group="1" conaffinity="0" contype="0" rgba="0 1 0 0"/>
    </default>
  </default>
  <worldbody>
    <body>
      <body name="object">
        <geom mesh="Body001_vis" type="mesh" solimp="0.998 0.998 0.001" solref="0.001 1" friction="0.95 0.3 0.1" class="visual" material="Body001_material"/>
        <geom class="collision" type="box" pos="-0.002671 0.200073 -0.016867" size="0.1764032542705536 0.12497478723526001 0.17823748290538788" quat="1.0 0.0 0.0 0.0" density="1000.0"/>
        <geom class="collision" type="box" pos="-0.007459 0.005872 -0.258088" size="0.18950051069259644 0.3452455997467041 0.06353165209293365" quat="1.0 0.0 0.0 0.0" density="1000.0"/>
        <geom class="collision" type="box" pos="-0.007459 -0.214374 -0.342852" size="0.1895015686750412 0.12654121220111847 0.02537618577480316" quat="1.0 0.0 0.0 0.0" density="1000.0"/>
        <geom class="collision" type="box" pos="-0.007459 0.268037 -0.342736" size="0.1895015686750412 0.07797621935606003 0.02537618577480316" quat="1.0 0.0 0.0 0.0" density="1000.0"/>
        <geom class="collision" type="cylinder" pos="0.167860 0.148087 0.091847" size="0.022957801818847656 0.007240905426442623" quat="0.7071068286895752 -0.0 0.7071067690849304 0.0" density="1000.0"/>
        <body name="Container001">
          <joint axis="0.0 0.0 1.0" pos="-0.006700 -0.145994 -0.054640" limited="true" name="Container001_joint" range="0.0 0.1" type="slide" damping="1" frictionloss="1" armature=".01" stiffness="0.05"/>
          <geom mesh="Container001_vis" type="mesh" solimp="0.998 0.998 0.001" solref="0.001 1" friction="0.95 0.3 0.1" class="visual" material="Container001_material"/>
          <geom class="collision" type="cylinder" pos="-0.006700 -0.134893 -0.172188" size="0.1814662218093872 0.010760191828012466" quat="1.0 0.0 0.0 5.960464477539063e-08" density="1000.0"/>
          <geom class="collision" type="box" pos="-0.003157 0.042430 -0.043359" size="0.05319305509328842 0.0033536956179887056 0.13530996441841125" quat="1.0 0.0 0.0 0.0" density="1000.0"/>
          <geom class="collision" type="box" pos="0.085029 0.016902 -0.043359" size="0.05319305881857872 0.0033536935225129128 0.13530996441841125" quat="0.9659258127212524 0.0 0.0 -0.2588191628456116" density="1000.0"/>
          <geom class="collision" type="box" pos="0.148637 -0.049299 -0.043359" size="0.05319305881857872 0.003353693289682269 0.13530994951725006" quat="0.866025447845459 0.0 0.0 -0.4999999701976776" density="1000.0"/>
          <geom class="collision" type="box" pos="0.170623 -0.138436 -0.043359" size="0.003353703301399946 0.05319299176335335 0.13530996441841125" quat="1.0 0.0 0.0 0.0" density="1000.0"/>
          <geom class="collision" type="box" pos="0.145094 -0.226622 -0.043359" size="0.05319305881857872 0.0033536935225129128 0.13530996441841125" quat="0.49999988079071045 0.0 0.0 -0.8660255074501038" density="1000.0"/>
          <geom class="collision" type="box" pos="0.078893 -0.290230 -0.043359" size="0.05319306254386902 0.003353693289682269 0.13530996441841125" quat="0.2588190734386444 0.0 0.0 -0.9659258127212524" density="1000.0"/>
          <geom class="collision" type="box" pos="-0.010243 -0.312216 -0.043359" size="0.05319305509328842 0.003353709354996681 0.13530996441841125" quat="1.0 0.0 0.0 0.0" density="1000.0"/>
          <geom class="collision" type="box" pos="-0.098430 -0.286687 -0.043359" size="0.05319306254386902 0.0033536935225129128 0.13530996441841125" quat="0.2588190734386444 0.0 0.0 0.9659258127212524" density="1000.0"/>
          <geom class="collision" type="box" pos="-0.162038 -0.220486 -0.043359" size="0.05319305509328842 0.003353693289682269 0.13530996441841125" quat="0.5000000596046448 0.0 0.0 0.8660253882408142" density="1000.0"/>
          <geom class="collision" type="box" pos="-0.184023 -0.131350 -0.043359" size="0.003353716107085347 0.05319303646683693 0.13530996441841125" quat="1.0 0.0 0.0 0.0" density="1000.0"/>
          <geom class="collision" type="box" pos="-0.158495 -0.043163 -0.043359" size="0.05319305881857872 0.0033536935225129128 0.13530996441841125" quat="0.8660256266593933 0.0 0.0 0.49999964237213135" density="1000.0"/>
          <geom class="collision" type="box" pos="-0.092294 0.020445 -0.043359" size="0.05319305509328842 0.003353693289682269 0.13530996441841125" quat="0.9659258723258972 0.0 0.0 0.25881892442703247" density="1000.0"/>
        </body>
        <body name="Lever001">
          <joint axis="-1.0 0.0 0.0" pos="0.182530 0.149109 0.091107" limited="true" name="Lever001_joint" range="0.0 1.2566370614359172" type="hinge" damping="1" frictionloss="1" armature=".01" stiffness="0.0005"/>
          <geom mesh="Lever001_vis" type="mesh" solimp="0.998 0.998 0.001" solref="0.001 1" friction="0.95 0.3 0.1" class="visual" material="Lever001_material"/>
          <geom class="collision" type="cylinder" pos="0.192819 0.181370 0.116686" size="0.006224953569471836 0.0336981862783432" quat="0.896519124507904 -0.4430050551891327 2.6802243979773266e-08 -5.3240494679585026e-08" density="1000.0"/>
          <geom class="collision" type="cylinder" pos="0.193148 0.147999 0.091033" size="0.008919178508222103 0.0055654654279351234" quat="0.6339347958564758 -0.31325194239616394 -0.633934736251831 0.313251793384552" density="1000.0"/>
          <geom class="collision" type="cylinder" pos="0.181272 0.148087 0.091847" size="0.017771020531654358 0.005604991223663092" quat="0.7071068286895752 -0.0 0.7071067690849304 0.0" density="1000.0"/>
        </body>
        <body name="Lid001">
          <joint axis="-1.0 0.0 0.0" pos="0.003916 0.322977 0.171758" limited="true" name="Lid001_joint" range="0.0 1.5707963267948966" type="hinge" damping="1" frictionloss="1" armature=".01" stiffness="0.05"/>
          <geom mesh="Lid001_vis" type="mesh" solimp="0.998 0.998 0.001" solref="0.001 1" friction="0.95 0.3 0.1" class="visual" material="Lid001_material"/>
          <geom class="collision" type="box" pos="-0.005637 0.121329 0.237435" size="0.184238001704216 0.20407572388648987 0.06432920694351196" quat="1.0 0.0 0.0 0.0" density="1000.0"/>
          <geom class="collision" type="box" pos="-0.000110 -0.132796 0.231343" size="0.13936132192611694 0.04869908466935158 0.05530465021729469" quat="1.0 0.0 0.0 0.0" density="1000.0"/>
          <geom class="collision" type="box" pos="-0.000110 0.118885 0.315118" size="0.13787944614887238 0.16501151025295258 0.05209331586956978" quat="1.0 0.0 0.0 0.0" density="1000.0"/>
          <geom class="collision" type="box" pos="-0.000110 -0.083651 0.277629" size="0.11760880798101425 0.009555584751069546 0.014604005962610245" quat="1.0 0.0 0.0 0.0" density="1000.0"/>
          <geom class="collision" type="box" pos="-0.023869 -0.250660 0.177958" size="0.05469752103090286 0.0042932783253490925 0.0926520973443985" quat="0.9129106998443604 -0.4081593453884125 3.326717745721908e-08 1.4873649867297445e-08" density="1000.0"/>
          <geom class="collision" type="box" pos="-0.110678 -0.216964 0.181108" size="0.05469752103090286 0.00429327879101038 0.08732059597969055" quat="0.8775176405906677 -0.345663458108902 0.12181942909955978 -0.3092564344406128" density="1000.0"/>
          <geom class="collision" type="box" pos="-0.190229 -0.088317 0.193110" size="0.05469752103090286 0.00429327879101038 0.08266056329011917" quat="0.7065261006355286 -0.02865460142493248 0.028654610738158226 -0.7065258026123047" density="1000.0"/>
          <geom class="collision" type="box" pos="-0.139639 -0.158842 0.180499" size="0.05469752103090286 0.00429327879101038 0.08321232348680496" quat="0.5672957897186279 0.2008899748325348 0.2665899991989136 0.752826988697052" density="1000.0"/>
          <geom class="collision" type="box" pos="-0.061384 -0.250660 0.177958" size="0.05469752475619316 0.0042932783253490925 0.0926520973443985" quat="0.9145877361297607 -0.3882194459438324 0.044231995940208435 -0.10420416295528412" density="1000.0"/>
          <geom class="collision" type="box" pos="0.037335 -0.250660 0.177958" size="0.05469753220677376 0.0042932783253490925 0.0926520973443985" quat="0.38821929693222046 0.9145877957344055 0.10420418530702591 0.04423201084136963" density="1000.0"/>
          <geom class="collision" type="box" pos="0.117142 -0.159287 0.178505" size="0.05469752103090286 0.0042932783253490925 0.08577822893857956" quat="0.20089010894298553 -0.5672956109046936 0.752826988697052 -0.26659026741981506" density="1000.0"/>
          <geom class="collision" type="box" pos="0.179344 -0.093894 0.191208" size="0.05469752103090286 0.00429327879101038 0.08453971147537231" quat="0.0035106476861983538 0.7070980668067932 0.7070980668067932 0.0035105894785374403" density="1000.0"/>
          <geom class="collision" type="box" pos="0.087811 -0.218432 0.179088" size="0.05469752103090286 0.0042932783253490925 0.09008330851793289" quat="0.3456631302833557 0.8775177001953125 0.3092566430568695 0.1218193769454956" density="1000.0"/>
          <geom class="collision" type="box" pos="-0.000180 -0.250660 0.177958" size="0.05469752103090286 0.0042932783253490925 0.0926520973443985" quat="0.40815937519073486 0.9129106998443604 7.852231753702199e-09 -1.7562717502528358e-08" density="1000.0"/>
          <geom class="collision" type="cylinder" pos="0.180216 0.148849 0.233937" size="0.04312162473797798 0.003263219492509961" quat="0.7071068286895752 -0.0 0.7071067690849304 0.0" density="1000.0"/>
          <body name="Blender001">
            <joint axis="0.0 0.0 1.0" pos="-0.014854 -0.137357 0.168448" limited="false" name="Blender001_joint" range="0 360" type="hinge" damping="1" frictionloss="1" armature=".01" stiffness="0.05"/>
            <geom mesh="Blender001_vis" type="mesh" solimp="0.998 0.998 0.001" solref="0.001 1" friction="0.95 0.3 0.1" class="visual" material="Blender001_material"/>
            <geom class="collision" type="cylinder" pos="-0.014854 -0.137357 0.025271" size="0.03977133706212044 0.12904568016529083" quat="1.0 0.0 0.0 5.960464477539063e-08" density="1000.0"/>
            <geom class="collision" type="cylinder" pos="-0.014854 -0.137357 0.157530" size="0.04861937835812569 0.011234770528972149" quat="1.0 0.0 0.0 5.960464477539063e-08" density="1000.0"/>
          </body>
          <body name="Konb001">
            <joint axis="-1.0 0.0 0.0" pos="0.192056 0.148815 0.233582" limited="true" name="Konb001_joint" range="0.0 3.141592653589793" type="hinge" damping="1" frictionloss="1" armature=".01" stiffness="0.0005"/>
            <geom mesh="Konb001_vis" type="mesh" solimp="0.998 0.998 0.001" solref="0.001 1" friction="0.95 0.3 0.1" class="visual" material="Konb001_material"/>
            <geom class="collision" type="cylinder" pos="0.188190 0.149206 0.233844" size="0.023875655606389046 0.0037164839450269938" quat="0.2503162920475006 -0.6613181233406067 0.2503167986869812 -0.6613180637359619" density="1000.0"/>
            <geom class="collision" type="box" pos="0.198501 0.149735 0.232932" size="0.006722669582813978 0.006722669582813978 0.020335135981440544" quat="0.9984014630317688 0.05652029812335968 3.368872292242031e-09 5.9509360994525196e-08" density="1000.0"/>
          </body>
        </body>
        <geom class="region" name="reg_main" type="box" pos="-0.0064680000000000015 0.0 0.0" size="0.190088 0.345 0.365"/>
      </body>
    </body>
  </worldbody>
  <actuator>
    <motor name="Container001_joint_actuator" joint="Container001_joint" gear="100"/>
    <motor name="Lever001_joint_actuator" joint="Lever001_joint" gear="10"/>
    <motor name="Lid001_joint_actuator" joint="Lid001_joint" gear="100"/>
    <motor name="Blender001_joint_actuator" joint="Blender001_joint" gear="20"/>
    <motor name="Konb001_joint_actuator" joint="Konb001_joint" gear="10"/>
  </actuator>
</mujoco>
