<mujoco model="model">
  <compiler angle="radian"/>
  <asset>
    <mesh file="visuals/Blender001.obj" name="Blender001_vis"/>
    <mesh file="visuals/Body001.obj" name="Body001_vis"/>
    <mesh file="visuals/Button001.obj" name="Button001_vis"/>
    <mesh file="visuals/Container001.obj" name="Container001_vis"/>
    <mesh file="visuals/Knob001.obj" name="Knob001_vis"/>
    <mesh file="visuals/Lid001.obj" name="Lid001_vis"/>
    <texture file="visuals/T_BC001.png" name="Body001_material" type="2d"/>
    <material name="Body001_material" rgba="1 1 1 1.0" texture="Body001_material" shininess="0.141421377658844" specular="0.3103448502657381"/>
    <texture file="visuals/T_BC001.png" name="Button001_material" type="2d"/>
    <material name="Button001_material" rgba="1 1 1 1.0" texture="Button001_material" shininess="0.141421377658844" specular="0.3103448502657381"/>
    <texture file="visuals/T_BC001.png" name="Container001_material" type="2d"/>
    <material name="Container001_material" rgba="1 1 1 1.0" texture="Container001_material" shininess="0.141421377658844" specular="0.3103448502657381"/>
    <texture file="visuals/T_BC001.png" name="Knob001_material" type="2d"/>
    <material name="Knob001_material" rgba="1 1 1 1.0" texture="Knob001_material" shininess="0.141421377658844" specular="0.3103448502657381"/>
    <texture file="visuals/T_BC001.png" name="Lid001_material" type="2d"/>
    <material name="Lid001_material" rgba="1 1 1 1.0" texture="Lid001_material" shininess="0.141421377658844" specular="0.3103448502657381"/>
    <texture file="visuals/T_BC001.png" name="Blender001_material" type="2d"/>
    <material name="Blender001_material" rgba="1 1 1 1.0" texture="Blender001_material" shininess="0.141421377658844" specular="0.3103448502657381"/>
  </asset>
  <default>
    <default class="visual">
      <geom conaffinity="0" contype="0" group="1" type="mesh"/>
    </default>
    <default class="collision">
      <geom group="0" rgba="0.5 0 0 0.5"/>
    </default>
    <default class="spawn">
      <geom group="0" rgba="1 1 1 0.5" contype="0" conaffinity="0"/>
      <site group="0" rgba="1 1 1 0.5"/>
    </default>
    <default class="region">
      <geom group="1" conaffinity="0" contype="0" rgba="0 1 0 0"/>
    </default>
  </default>
  <worldbody>
    <body>
      <body name="object">
        <geom mesh="Body001_vis" type="mesh" solimp="0.998 0.998 0.001" solref="0.001 1" density="100" friction="0.95 0.3 0.1" class="visual" material="Body001_material"/>
        <geom class="collision" type="box" pos="-0.006571 0.127663 -0.069314" size="0.08200757205486298 0.07060243934392929 0.08966419845819473" quat="1.0 0.0 0.0 0.0"/>
        <geom class="collision" type="box" pos="-0.000883 0.002796 -0.193102" size="0.09473081678152084 0.20675715804100037 0.032987531274557114" quat="1.0 0.0 0.0 0.0"/>
        <body name="Button001">
          <joint axis="-1.0 0.0 0.0" pos="0.076695 0.091037 -0.003883" limited="true" name="Button001_joint" range="0.0 0.003" type="slide" damping="1" frictionloss="1" armature=".01" stiffness="0.05"/>
          <geom mesh="Button001_vis" type="mesh" solimp="0.998 0.998 0.001" solref="0.001 1" density="100" friction="0.95 0.3 0.1" class="visual" material="Button001_material"/>
          <geom class="collision" type="box" pos="0.081435 0.090984 -0.003692" size="0.0019145847763866186 0.016794392839074135 0.009193899109959602" quat="1.0 0.0 0.0 0.0"/>
        </body>
        <body name="Container001">
          <joint axis="0.0 0.0 1.0" pos="-0.000000 -0.088566 -0.067977" limited="true" name="Container001_joint" range="0.0 0.05" type="slide" damping="1" frictionloss="1" armature=".01" stiffness="0.05"/>
          <geom mesh="Container001_vis" type="mesh" solimp="0.998 0.998 0.001" solref="0.001 1" density="100" friction="0.95 0.3 0.1" class="visual" material="Container001_material"/>
          <geom class="collision" type="box" pos="0.000000 0.032403 -0.063128" size="0.04650513827800751 0.007986036129295826 0.09402856975793839" quat="0.9971979856491089 -0.07480743527412415 -0.0 0.0"/>
          <geom class="collision" type="cylinder" pos="0.000000 -0.087565 -0.149163" size="0.09687486290931702 0.009190688841044903" quat="1.0 0.0 0.0 0.0"/>
          <geom class="collision" type="box" pos="0.000000 -0.209611 -0.063128" size="0.04650513827800751 0.007986036129295826 0.09402856975793839" quat="0.9971979856491089 0.07480742782354355 0.0 0.0"/>
          <geom class="collision" type="box" pos="-0.121007 -0.088604 -0.063128" size="0.04650513827800751 0.007986036129295826 0.09402856975793839" quat="0.7051255106925964 0.05289683863520622 -0.052896834909915924 -0.7051254510879517"/>
          <geom class="collision" type="box" pos="0.121007 -0.088604 -0.063128" size="0.04650513827800751 0.007986036129295826 0.09402856975793839" quat="0.7051255106925964 -0.05289684981107712 0.05289684608578682 -0.7051254510879517"/>
          <geom class="collision" type="box" pos="0.085565 -0.174169 -0.063128" size="0.04650513827800751 0.007986036129295826 0.09402856975793839" quat="0.3816111385822296 -0.02862757444381714 0.06911307573318481 -0.9212908148765564"/>
          <geom class="collision" type="box" pos="-0.085565 -0.003039 -0.063128" size="0.04650513827800751 0.007986036129295826 0.09402856975793839" quat="0.3816111385822296 0.02862757071852684 -0.06911306083202362 -0.9212908148765564"/>
          <geom class="collision" type="box" pos="0.085565 -0.003039 -0.063128" size="0.04650513827800751 0.007986036129295826 0.09402858465909958" quat="0.38161104917526245 0.028627581894397736 0.06911315023899078 0.9212908744812012"/>
          <geom class="collision" type="box" pos="-0.085565 -0.174169 -0.063128" size="0.04650513827800751 0.007986036129295826 0.09402858465909958" quat="0.38161104917526245 -0.02862757071852684 -0.06911309063434601 0.9212908744812012"/>
        </body>
        <body name="Knob001">
          <joint axis="-1.0 0.0 0.0" pos="0.082509 0.126792 -0.055926" limited="true" name="Knob001_joint" range="0.0 4.537856055185257" type="hinge" damping="0.05" armature="0.001"/>
          <geom mesh="Knob001_vis" type="mesh" solimp="0.998 0.998 0.001" solref="0.001 1" density="100" friction="0.95 0.3 0.1" class="visual" material="Knob001_material"/>
          <geom class="collision" type="cylinder" pos="0.083565 0.126888 -0.055712" size="0.030419738963246346 0.006201711017638445" quat="0.7071068286895752 0.0 -0.7071067690849304 0.0"/>
        </body>
        <body name="Lid001">
          <joint axis="-0.9999999403953552 3.5762786865234375e-07 0.0" pos="0.000028 0.195894 0.015335" limited="true" name="Lid001_joint" range="0.0 1.5707963267948966" type="hinge" damping="1" frictionloss="1" armature=".01" stiffness="0.05"/>
          <geom mesh="Lid001_vis" type="mesh" solimp="0.998 0.998 0.001" solref="0.001 1" density="100" friction="0.95 0.3 0.1" class="visual" material="Lid001_material"/>
          <geom class="collision" type="box" pos="-0.001008 0.004028 0.150786" size="0.09463362395763397 0.20690122246742249 0.07530318200588226" quat="1.0 0.0 0.0 0.0"/>
          <geom class="collision" type="box" pos="-0.000012 0.127663 0.047664" size="0.07422233372926712 0.07060243934392929 0.026181209832429886" quat="1.0 0.0 0.0 0.0"/>
          <geom class="collision" type="cylinder" pos="0.000000 -0.089516 0.069981" size="0.07472942024469376 0.01424634363502264" quat="1.0 0.0 0.0 0.0"/>
          <body name="Blender001">
            <joint axis="0.0 0.0 1.0" pos="0.000025 -0.088566 0.047131" limited="false" name="Blender001_joint" range="0 360" type="hinge" damping="1" frictionloss="1" armature=".01" stiffness="0.05"/>
            <geom mesh="Blender001_vis" type="mesh" solimp="0.998 0.998 0.001" solref="0.001 1" density="100" friction="0.95 0.3 0.1" class="visual" material="Blender001_material"/>
            <geom class="collision" type="cylinder" pos="0.000000 -0.088642 0.032904" size="0.011517362669110298 0.014278058893978596" quat="1.0 0.0 0.0 0.0"/>
            <geom class="collision" type="cylinder" pos="0.000000 -0.088642 0.006794" size="0.029136326164007187 0.011821734718978405" quat="1.0 0.0 0.0 0.0"/>
            <geom class="collision" type="box" pos="0.000210 -0.030184 -0.048489" size="0.001835870323702693 0.0025987871922552586 0.045582305639982224" quat="0.9985114932060242 -0.05454152822494507 -0.0 0.0"/>
            <geom class="collision" type="box" pos="0.000210 -0.042147 0.003187" size="0.002012499375268817 0.0015198097098618746 0.01903446763753891" quat="0.788648784160614 0.6148439645767212 0.0 0.0"/>
            <geom class="collision" type="box" pos="0.000210 -0.046272 -0.111990" size="0.002012499375268817 0.0035720032174140215 0.02141435816884041" quat="0.9448762536048889 -0.32742759585380554 -0.0 0.0"/>
            <geom class="collision" type="box" pos="0.000210 -0.073762 -0.128676" size="0.002012499375268817 0.001950566889718175 0.013469599187374115" quat="0.742948055267334 -0.6693490743637085 -0.0 0.0"/>
            <geom class="collision" type="box" pos="0.000210 -0.102757 -0.128676" size="0.002012499375268817 0.001950566889718175 0.013469599187374115" quat="0.742948055267334 0.6693490743637085 0.0 0.0"/>
            <geom class="collision" type="box" pos="0.000210 -0.130637 -0.111990" size="0.002012499375268817 0.003572002984583378 0.02141435816884041" quat="0.9448762536048889 0.32742762565612793 0.0 0.0"/>
            <geom class="collision" type="box" pos="0.000210 -0.134372 0.003250" size="0.002012499375268817 0.0015198097098618746 0.01903446763753891" quat="0.788648784160614 -0.6148439645767212 -0.0 0.0"/>
            <geom class="collision" type="box" pos="0.000210 -0.146791 -0.048489" size="0.001835870323702693 0.0025987871922552586 0.045582305639982224" quat="0.9985114932060242 0.05454152822494507 0.0 0.0"/>
            <geom class="collision" type="box" pos="-0.034204 -0.135551 -0.048489" size="0.001835870323702693 0.0025987871922552586 0.045582301914691925" quat="0.9491671919822693 0.0518459752202034 -0.016933614388108253 -0.3100111484527588"/>
            <geom class="collision" type="box" pos="-0.026874 -0.125526 0.003250" size="0.0020124991424381733 0.0015198097098618746 0.01903446763753891" quat="0.7496753931045532 -0.584459662437439 0.19089266657829285 -0.24485443532466888"/>
            <geom class="collision" type="box" pos="-0.024669 -0.122511 -0.111990" size="0.0020124996080994606 0.003572002984583378 0.02141435816884041" quat="0.8981825113296509 0.31124675273895264 -0.10165751725435257 -0.29335883259773254"/>
            <geom class="collision" type="box" pos="-0.008213 -0.100006 -0.128676" size="0.002012499375268817 0.001950566889718175 0.013469599187374115" quat="0.7062328457832336 0.6362714767456055 -0.20781520009040833 -0.23066556453704834"/>
            <geom class="collision" type="box" pos="0.008902 -0.076601 -0.128676" size="0.002012499375268817 0.001950566889718175 0.013469599187374115" quat="0.7062328457832336 -0.6362714767456055 0.20781520009040833 -0.23066556453704834"/>
            <geom class="collision" type="box" pos="0.025128 -0.054410 -0.111990" size="0.0020124991424381733 0.003572002984583378 0.02141435816884041" quat="0.8981824517250061 -0.3112468719482422 0.10165760666131973 -0.2933588922023773"/>
            <geom class="collision" type="box" pos="0.027563 -0.051081 0.003187" size="0.0020124991424381733 0.0015198097098618746 0.01903446763753891" quat="0.7496753931045532 0.584459662437439 -0.19089266657829285 -0.24485443532466888"/>
            <geom class="collision" type="box" pos="0.034535 -0.041424 -0.048489" size="0.001835870323702693 0.0025987871922552586 0.045582301914691925" quat="0.9491671919822693 -0.0518459752202034 0.016933614388108253 -0.3100111484527588"/>
            <geom class="collision" type="box" pos="0.055759 -0.070781 -0.048489" size="0.0018358704401180148 0.002598786959424615 0.045582301914691925" quat="0.8061672449111938 -0.04403495788574219 0.03218192979693413 -0.5891686081886292"/>
            <geom class="collision" type="box" pos="0.044362 -0.074414 0.003187" size="0.002012499375268817 0.0015198095934465528 0.01903446950018406" quat="0.6367306709289551 0.4964059293270111 -0.3627866506576538 -0.465339720249176"/>
            <geom class="collision" type="box" pos="0.040432 -0.075667 -0.111990" size="0.002012499375268817 0.003572002984583378 0.02141435816884041" quat="0.76286381483078 -0.2643549144268036 0.19319762289524078 -0.5575212240219116"/>
            <geom class="collision" type="box" pos="0.014240 -0.084015 -0.128676" size="0.002012499375268817 0.001950566889718175 0.013469599187374115" quat="0.5998331904411316 -0.5404117703437805 0.3949473202228546 -0.4383741021156311"/>
            <geom class="collision" type="box" pos="-0.013386 -0.092821 -0.128676" size="0.002012499375268817 0.001950566889718175 0.013469599187374115" quat="0.5998331904411316 0.5404117703437805 -0.3949473202228546 -0.4383741021156311"/>
            <geom class="collision" type="box" pos="-0.039949 -0.101288 -0.111990" size="0.002012499375268817 0.0035720032174140215 0.02141435816884041" quat="0.7628638744354248 0.2643548548221588 -0.1931975781917572 -0.5575212240219116"/>
            <geom class="collision" type="box" pos="-0.043508 -0.102422 0.003250" size="0.002012499375268817 0.0015198095934465528 0.01903446950018406" quat="0.6367306709289551 -0.4964059293270111 0.3627866506576538 -0.465339720249176"/>
            <geom class="collision" type="box" pos="-0.055340 -0.106194 -0.048489" size="0.0018358704401180148 0.002598786959424615 0.045582301914691925" quat="0.8061672449111938 0.04403495788574219 -0.03218192979693413 -0.5891686081886292"/>
            <geom class="collision" type="box" pos="-0.055290 -0.070628 -0.048489" size="0.001835870323702693 0.0025987871922552586 0.045582301914691925" quat="0.5880523920059204 0.032120950520038605 -0.04407944902777672 -0.8069818019866943"/>
            <geom class="collision" type="box" pos="-0.043469 -0.074432 0.003250" size="0.002012499375268817 0.0015198095934465528 0.01903446950018406" quat="0.464458167552948 -0.36209937930107117 0.49690747261047363 -0.6373739838600159"/>
            <geom class="collision" type="box" pos="-0.039913 -0.075576 -0.111990" size="0.002012499375268817 0.003572002751752734 0.02141435816884041" quat="0.5564647316932678 0.1928316354751587 -0.26462212204933167 -0.7636348009109497"/>
            <geom class="collision" type="box" pos="-0.013374 -0.084116 -0.128676" size="0.002012499375268817 0.001950566889718175 0.01346959825605154" quat="0.4375436305999756 0.39419907331466675 -0.5409577488899231 -0.6004393100738525"/>
            <geom class="collision" type="box" pos="0.014228 -0.092998 -0.128676" size="0.002012499375268817 0.001950566889718175 0.01346959825605154" quat="0.4375436305999756 -0.39419907331466675 0.5409577488899231 -0.6004393100738525"/>
            <geom class="collision" type="box" pos="0.040396 -0.101419 -0.111990" size="0.002012499375268817 0.003572002984583378 0.02141435816884041" quat="0.5564650297164917 -0.1928316056728363 0.2646220326423645 -0.7636346220970154"/>
            <geom class="collision" type="box" pos="0.044322 -0.102683 0.003187" size="0.002012499375268817 0.0015198095934465528 0.01903446950018406" quat="0.464458167552948 0.36209937930107117 -0.49690747261047363 -0.6373739838600159"/>
            <geom class="collision" type="box" pos="0.055710 -0.106347 -0.048489" size="0.001835870323702693 0.0025987871922552586 0.045582301914691925" quat="0.5880523920059204 -0.032120950520038605 0.04407944902777672 -0.8069818019866943"/>
            <geom class="collision" type="box" pos="0.034392 -0.135486 -0.048489" size="0.001835870323702693 0.0025987871922552586 0.045582301914691925" quat="0.31089919805526733 -0.016982123255729675 0.05183011293411255 -0.948876678943634"/>
            <geom class="collision" type="box" pos="0.027451 -0.125843 0.003187" size="0.002012499375268817 0.0015198095934465528 0.01903446763753891" quat="0.2455557882785797 0.1914394199848175 -0.5842807292938232 -0.7494460344314575"/>
            <geom class="collision" type="box" pos="0.025010 -0.122518 -0.111990" size="0.002012499375268817 0.003572002984583378 0.02141435816884041" quat="0.2941991686820984 -0.10194873064756393 0.31115156412124634 -0.897907555103302"/>
            <geom class="collision" type="box" pos="0.008924 -0.100358 -0.128676" size="0.002012499375268817 0.001950566889718175 0.013469599187374115" quat="0.23132625222206116 -0.2084103226661682 0.6360765695571899 -0.7060168981552124"/>
            <geom class="collision" type="box" pos="-0.008235 -0.076984 -0.128676" size="0.002012499375268817 0.001950566889718175 0.013469599187374115" quat="0.23132625222206116 0.2084103226661682 -0.6360765695571899 -0.7060168981552124"/>
            <geom class="collision" type="box" pos="-0.024733 -0.054510 -0.111990" size="0.002012499375268817 0.003572002984583378 0.02141435816884041" quat="0.2941991984844208 0.10194870084524155 -0.31115150451660156 -0.8979076147079468"/>
            <geom class="collision" type="box" pos="-0.026943 -0.051499 0.003250" size="0.002012499375268817 0.0015198095934465528 0.01903446763753891" quat="0.2455557882785797 -0.1914394199848175 0.5842807292938232 -0.7494460344314575"/>
            <geom class="collision" type="box" pos="-0.034292 -0.041489 -0.048489" size="0.001835870323702693 0.0025987871922552586 0.045582301914691925" quat="0.31089919805526733 0.016982123255729675 -0.05183011293411255 -0.948876678943634"/>
          </body>
        </body>
        <geom class="region" name="reg_main" type="box" pos="0.0 0.0 0.0018159999999999982" size="0.133704 0.22227 0.223924"/>
      </body>
    </body>
  </worldbody>
  <actuator>
    <motor name="Button001_joint_actuator" joint="Button001_joint" gear="0.5"/>
    <motor name="Container001_joint_actuator" joint="Container001_joint" gear="50"/>
    <motor name="Knob001_joint_actuator" joint="Knob001_joint" gear="10"/>
    <motor name="Lid001_joint_actuator" joint="Lid001_joint" gear="50"/>
    <motor name="Blender001_joint_actuator" joint="Blender001_joint" gear="10"/>
  </actuator>
</mujoco>
