<?xml version='1.0' encoding='UTF-8'?>
<mujoco model="model">
  <compiler angle="radian"/>
  <asset>
    <mesh file="visuals/Body001.obj" name="Body001_vis"/>
    <mesh file="visuals/Button001.obj" name="Button001_vis"/>
    <mesh file="visuals/Button002.obj" name="Button002_vis"/>
    <mesh file="visuals/Container001_Clear.obj" name="Container001_Clear_vis"/>
    <mesh file="visuals/Lid001.obj" name="Lid001_vis"/>
    <mesh file="visuals/Lid002_Clear.obj" name="Lid002_Clear_vis"/>
    <mesh file="visuals/Lid003.obj" name="Lid003_vis"/>
    <texture file="visuals/T_BC001.png" name="Body001_material" type="2d"/>
    <material name="Body001_material" rgba="1 1 1 1.0" texture="Body001_material" shininess="0.4472135901451111" specular="0.3103448502657381"/>
    <texture file="visuals/T_BC001.png" name="Button001_material" type="2d"/>
    <material name="Button001_material" rgba="1 1 1 1.0" texture="Button001_material" shininess="0.4472135901451111" specular="0.3103448502657381"/>
    <texture file="visuals/T_BC001.png" name="Button002_material" type="2d"/>
    <material name="Button002_material" rgba="1 1 1 1.0" texture="Button002_material" shininess="0.4472135901451111" specular="0.3103448502657381"/>
    <texture file="visuals/T_BC001.png" name="Container001_Clear_material" type="2d"/>
    <material name="Container001_Clear_material" rgba="1 1 1 0.5" texture="Container001_Clear_material" shininess="0.4472135901451111" specular="0.3103448502657381"/>
    <texture file="visuals/T_BC001.png" name="Lid002_Clear_material" type="2d"/>
    <material name="Lid002_Clear_material" rgba="1 1 1 0.5" texture="Lid002_Clear_material" shininess="0.4472135901451111" specular="0.3103448502657381"/>
    <texture file="visuals/T_BC001.png" name="Lid001_material" type="2d"/>
    <material name="Lid001_material" rgba="1 1 1 1.0" texture="Lid001_material" shininess="0.4472135901451111" specular="0.3103448502657381"/>
    <texture file="visuals/T_BC001.png" name="Lid003_material" type="2d"/>
    <material name="Lid003_material" rgba="1 1 1 1.0" texture="Lid003_material" shininess="0.4472135901451111" specular="0.3103448502657381"/>
  </asset>
  <default>
    <default class="visual">
      <geom conaffinity="0" contype="0" group="1" type="mesh"/>
    </default>
    <default class="collision">
      <geom group="0" rgba="0.5 0 0 0.5"/>
    </default>
    <default class="spawn">
      <geom group="0" rgba="1 1 1 0.5" contype="0" conaffinity="0"/>
      <site group="0" rgba="1 1 1 0.5"/>
    </default>
    <default class="region">
      <geom group="1" conaffinity="0" contype="0" rgba="0 1 0 0"/>
    </default>
  </default>
  <worldbody>
    <body>
      <body name="object">
        <geom class="collision" type="box" pos="-0.030616149306297302 -0.216434508562088 0.11246190220117569" size="0.007607913576066494 0.000489116064272821 0.007607907056808472" quat="1.0 0.0 0.0 0.0" name="start_button_1" rgba="0.0 0.5 0 0.5"/>
        <geom class="collision" type="box" pos="0.03072347491979599 -0.216434508562088 0.11246190220117569" size="0.007607913576066494 0.000489116064272821 0.007607907056808472" quat="1.0 0.0 0.0 0.0" name="start_button_2" rgba="0.0 0.5 0 0.5"/>
        <site type="cylinder" rgba="0.8 0.5 0.25 1" size="0.0021251689177006483 0.1137041226029396" pos="0.0005083419382572174 -0.17765355110168457 -0.05330929532647133" name="coffee_liquid"/>
        <site rgba="0 0 0 0" size="0.009999999776482582 0.009999999776482582" pos="0.0 -0.17718325555324554 -0.14677682518959045" name="receptacle_place_site"/>
        <geom mesh="Body001_vis" type="mesh" solimp="0.998 0.998 0.001" solref="0.001 1" density="100" friction="0.95 0.3 0.1" class="visual" material="Body001_material"/>
        <geom class="collision" type="box" pos="-8.271806125530277e-25 0.016483120620250702 -0.05334841087460518" size="0.06600822508335114 0.13423846662044525 0.11875934898853302" quat="1.0 0.0 0.0 0.0"/>
        <geom class="collision" type="box" pos="-8.271806125530277e-25 -0.16104024648666382 0.10836664587259293" size="0.06600822508335114 0.04473061114549637 0.052359841763973236" quat="1.0 0.0 0.0 0.0"/>
        <geom class="collision" type="box" pos="-8.271806125530277e-25 0.19386471807956696 -0.1530047059059143" size="0.06600822508335114 0.03906860575079918 0.018554944545030594" quat="1.0 0.0 0.0 0.0"/>
        <geom class="collision" type="box" pos="0.0 -0.12081402540206909 -0.15943431854248047" size="0.06600822508335114 0.001609809696674347 0.012229759246110916" quat="1.0 0.0 0.0 0.0"/>
        <geom class="collision" type="box" pos="-8.271806125530277e-25 0.06766687333583832 0.10836654901504517" size="0.06600822508335114 0.08305472135543823 0.052359744906425476" quat="1.0 0.0 0.0 0.0"/>
        <geom class="collision" type="box" pos="0.05978389456868172 -0.07468283921480179 0.10836664587259293" size="0.006224330514669418 0.08350387960672379 0.052359841763973236" quat="1.0 0.0 0.0 0.0"/>
        <geom class="collision" type="box" pos="-0.059783875942230225 -0.05356161296367645 0.10836664587259293" size="0.00622435100376606 0.08640749752521515 0.052359841763973236" quat="1.0 0.0 0.0 0.0"/>
        <geom class="collision" type="box" pos="0.0 -0.1771990954875946 -0.1701851785182953" size="0.06600822508335114 0.05799488350749016 0.0014789002016186714" quat="1.0 0.0 0.0 0.0"/>
        <geom class="collision" type="box" pos="-0.06474342942237854 -0.1771990954875946 -0.15943431854248047" size="0.0017591975629329681 0.05799488350749016 0.012229759246110916" quat="1.0 0.0 0.0 0.0"/>
        <geom class="collision" type="box" pos="0.06474414467811584 -0.1771990954875946 -0.15943431854248047" size="0.0017591975629329681 0.05799488350749016 0.012229759246110916" quat="1.0 0.0 0.0 0.0"/>
        <geom class="collision" type="box" pos="0.0 -0.23299594223499298 -0.15943431854248047" size="0.06600822508335114 0.0017591938376426697 0.012229759246110916" quat="1.0 0.0 0.0 0.0"/>
        <body name="Button001">
          <joint axis="0.0 1.0 0.0" pos="-0.030695753172039986 -0.21127310395240784 0.11243197321891785" limited="true" name="Button001_joint" range="0.0 0.002" type="slide" damping="1" frictionloss="1" armature=".01" stiffness="0.05"/>
          <geom mesh="Button001_vis" type="mesh" solimp="0.998 0.998 0.001" solref="0.001 1" density="100" friction="0.95 0.3 0.1" class="visual" material="Button001_material"/>
          <geom class="collision" type="box" pos="-0.030616149306297302 -0.21367265284061432 0.11246190220117569" size="0.007607913576066494 0.0018707525450736284 0.007607907056808472" quat="1.0 0.0 0.0 0.0"/>
        </body>
        <body name="Button002">
          <joint axis="0.0 1.0 0.0" pos="-0.010228728875517845 -0.21127310395240784 0.11243197321891785" limited="true" name="Button002_joint" range="0.0 0.002" type="slide" damping="1" frictionloss="1" armature=".01" stiffness="0.05"/>
          <geom mesh="Button002_vis" type="mesh" solimp="0.998 0.998 0.001" solref="0.001 1" density="100" friction="0.95 0.3 0.1" class="visual" material="Button002_material"/>
          <geom class="collision" type="box" pos="0.031241320073604584 -0.2137511819601059 0.11246190220117569" size="0.007607912644743919 0.0018707525450736284 0.007607907056808472" quat="1.0 0.0 0.0 0.0"/>
        </body>
        <body name="Container001_Clear">
          <joint axis="0.0 0.0 1.0" pos="0.0 0.19485530257225037 -0.005329817533493042" limited="true" name="Container001_Clear_joint" range="0.0 0.08" type="slide" damping="1" frictionloss="1" armature=".01" stiffness="0.05"/>
          <geom mesh="Container001_Clear_vis" type="mesh" solimp="0.998 0.998 0.001" solref="0.001 1" density="100" friction="0.95 0.3 0.1" class="visual" material="Container001_Clear_material"/>
          <geom class="collision" type="box" pos="1.2940673237491907e-17 0.23374684154987335 0.014187321066856384" size="0.06600822508335114 0.0010084304958581924 0.1471361666917801" quat="1.0 0.0 0.0 0.0"/>
          <geom class="collision" type="box" pos="1.2940673237491907e-17 0.15572774410247803 0.014187321066856384" size="0.06600822508335114 0.0009316392242908478 0.1471361666917801" quat="1.0 0.0 0.0 0.0"/>
          <geom class="collision" type="box" pos="0.06524717807769775 0.19386471807956696 0.014187321066856384" size="0.0007610432803630829 0.03906860575079918 0.1471361666917801" quat="1.0 0.0 0.0 0.0"/>
          <geom class="collision" type="box" pos="-0.06565093994140625 0.19386471807956696 0.014187321066856384" size="0.0008520223200321198 0.03906860575079918 0.1471361666917801" quat="1.0 0.0 0.0 0.0"/>
          <geom class="collision" type="box" pos="-8.271806125530277e-25 0.19386471807956696 -0.13111083209514618" size="0.06600822508335114 0.03906860575079918 0.0016964892856776714" quat="1.0 0.0 0.0 0.0"/>
          <body name="Lid002_Clear">
            <joint axis="0.0 0.0 1.0" pos="2.086162353975851e-08 0.19485530257225037 0.15852975845336914" limited="true" name="Lid002_Clear_joint" range="0.0 0.08" type="slide" damping="1" frictionloss="1" armature=".01" stiffness="0.05"/>
            <geom mesh="Lid002_Clear_vis" type="mesh" solimp="0.998 0.998 0.001" solref="0.001 1" density="100" friction="0.95 0.3 0.1" class="visual" material="Lid002_Clear_material"/>
            <geom class="collision" type="box" pos="-8.271806125530277e-25 0.19386471807956696 0.16363339126110077" size="0.06600822508335114 0.03906860575079918 0.0016964892856776714" quat="1.0 0.0 0.0 0.0"/>
          </body>
        </body>
        <body name="Lid001">
          <joint axis="-1.0 0.0 0.0" pos="3.0219553082133643e-07 0.05478830635547638 0.16332246363162994" limited="true" name="Lid001_joint" range="0.0 1.5707963267948966" type="hinge" damping="1" frictionloss="1" armature=".01" stiffness="0.05"/>
          <geom mesh="Lid001_vis" type="mesh" solimp="0.998 0.998 0.001" solref="0.001 1" density="100" friction="0.95 0.3 0.1" class="visual" material="Lid001_material"/>
          <geom class="collision" type="box" pos="0.0 -0.016775110736489296 0.16355444490909576" size="0.061771005392074585 0.07097547501325607 0.002184169599786401" quat="1.0 0.0 0.0 0.0"/>
          <geom class="collision" type="box" pos="-6.685153252476867e-19 -0.10946334898471832 0.1665651649236679" size="0.061771005392074585 0.019445419311523438 0.002184169366955757" quat="0.9967008829116821 -0.08116225898265839 1.802158879106825e-17 -3.546500115402923e-24"/>
        </body>
        <body name="Lid003">
          <joint axis="0.0 0.0 1.0" pos="3.948807716369629e-07 -0.17683036625385284 -0.1449340581893921" limited="true" name="Lid003_joint" range="0.0 0.02" type="slide" damping="1" frictionloss="1" armature=".01" stiffness="0.05"/>
          <geom mesh="Lid003_vis" type="mesh" solimp="0.998 0.998 0.001" solref="0.001 1" density="100" friction="0.95 0.3 0.1" class="visual" material="Lid003_material"/>
          <geom class="collision" type="box" pos="1.5772807305975465e-17 -0.1771990954875946 -0.14394459128379822" size="0.06600822508335114 0.05799487978219986 0.002486852463334799" quat="1.0 0.0 0.0 0.0"/>
        </body>
        <geom class="region" name="reg_main" type="box" pos="0.0 0.0 0.0" size="0.06685127317905426 0.234755277633667 0.17198313772678375"/>
      </body>
    </body>
  </worldbody>
  <actuator>
    <motor name="Button001_joint_actuator" joint="Button001_joint" gear="0.5"/>
    <motor name="Button002_joint_actuator" joint="Button002_joint" gear="0.5"/>
    <motor name="Container001_Clear_joint_actuator" joint="Container001_Clear_joint" gear="40"/>
    <motor name="Lid001_joint_actuator" joint="Lid001_joint" gear="5"/>
    <motor name="Lid003_joint_actuator" joint="Lid003_joint" gear="5"/>
    <motor name="Lid002_Clear_joint_actuator" joint="Lid002_Clear_joint" gear="2"/>
  </actuator>
</mujoco>
