<mujoco model="model">
  <compiler angle="radian"/>
  <asset>
    <texture type="2d" name="image0" file="visuals/image0.png"/>
    <material name="kitchen_sink" texture="image0" specular="0.5" shininess="0.25"/>
    <mesh file="visuals/model_0.obj" name="model_0_vis" scale="1 1 1"/>
    <mesh file="visuals/spout_0.obj" name="spout_0_vis" scale="1 1 1"/>
    <mesh file="visuals/handle_0.obj" name="handle_0_vis" scale="1 1 1"/>
  </asset>
  <default>
    <default class="visual">
      <geom conaffinity="0" contype="0" group="1" type="mesh"/>
    </default>
    <default class="collision">
      <!-- <geom group="0" rgba="0.5 0 0 0.5"/> -->
      <geom group="0" rgba="0.5 0 0 0.5" solimp="0.998 0.998 0.001" solref="0.001 2"/>
    </default>
    <default class="region">
      <geom group="1" conaffinity="0" contype="0" rgba="0 1 0 0"/>
    </default>
  </default>
  <worldbody>
    <body>
      <!-- exterior bounding box points -->
      <!-- interior bounding box points -->
      <body name="object">
        <geom solimp="0.998 0.998 0.001" solref="0.001 1" density="100" friction="0.95 0.3 0.1" type="mesh" mesh="model_0_vis" material="kitchen_sink" class="visual"/>
        <!-- Bottom -->
        <geom class="collision" type="box" pos="0 -0.04 -0.26" size="0.42 0.32 0.015" name="bottom"/>
        <!-- Left Wall -->
        <geom class="collision" type="box" pos="-0.45 -0.04 -0.145" size="0.015 0.32 0.12" axisangle="0 1 0 -0.17"/>
        <!-- Right Wall -->
        <geom class="collision" type="box" pos="0.45 -0.04 -0.145" size="0.015 0.32 0.12" axisangle="0 1 0 0.17"/>
        <!-- Back Wall -->
        <geom class="collision" type="box" pos="0 0.29 -0.145" size="0.46 0.015 0.12" axisangle="1 0 0 -0.10"/>
        <!-- Front Wall -->
        <geom class="collision" type="box" pos="0 -0.375 -0.145" size="0.46 0.015 0.12" axisangle="1 0 0 0.10"/>
        <!-- Back Ledge -->
        <geom class="collision" type="box" pos="0 0.356 -0.035" size="0.5 0.068 0.007"/>
        <!-- Front Ledge -->
        <geom class="collision" type="box" pos="0 -0.405 -0.035" size="0.5 0.02 0.007"/>
        <!-- Right Ledge -->
        <geom class="collision" type="box" pos="0.48 0 -0.035" size="0.02 0.4 0.007"/>
        <!-- Left Ledge -->
        <geom class="collision" type="box" pos="-0.48 0 -0.035" size="0.02 0.4 0.007"/>
        <!-- Faucet Base -->
        <geom class="collision" type="box" pos="0 0.368 -0.0117" size="0.222 0.0446 0.0165"/>
        <body name="spout">
          <joint axis="0 0 1" limited="true" name="spout_joint" range="-1.57 1.57" pos="0 0.368 0.045" armature="2" damping="10"/>
          <geom solimp="0.998 0.998 0.001" solref="0.001 1" density="100" friction="0.95 0.3 0.1" type="mesh" mesh="spout_0_vis" material="kitchen_sink" class="visual"/>
          <geom class="collision" type="cylinder" pos="0 0.368 0.045" size="0.034 0.034 0"/>
          <geom class="collision" type="box" pos="0 0.215 0.1295" size="0.023 0.16 0.012" axisangle="1 0 0 -0.59" name="spout_top"/>
          <geom class="collision" type="box" pos="0 0.05 0.22" size="0.023 0.039 0.012"/>
          <geom class="collision" type="cylinder" pos="0 0.0335 0.2025" size="0.02 0.0055 0"/>
          <site type="cylinder" rgba="0.5 0.75 1 1" pos="0.0 0.03 -0.03" size="0.01 0.25" name="water"/>
        </body>
        <body name="handle">
          <joint axis="-1 0 0" limited="true" type="hinge" name="handle_joint" range="0 0.52" pos="0 0.368 0.11" armature="2" damping="10"/>
          <joint axis="0 0 1" limited="true" type="hinge" name="handle_temp_joint" range="-0.79 0.79" pos="0 0.368 0.1165" armature="2" damping="50"/>
          <geom solimp="0.998 0.998 0.001" solref="0.001 1" density="100" friction="0.95 0.3 0.1" type="mesh" mesh="handle_0_vis" material="kitchen_sink" class="visual"/>
          <geom class="collision" type="cylinder" pos="0 0.368 0.1165" size="0.034 0.0165 0" axisangle="1 0 0 0.17"/>
          <geom class="collision" type="box" pos="0 0.293 0.208" size="0.023 0.13 0.0065" axisangle="1 0 0 -0.63" name="handle_main"/>
        </body>
        <geom class="region" name="reg_main_body" type="box" pos="0.0 0.0 -0.14475000000000002" size="0.5 0.425 0.11675"/>
        <geom class="region" name="reg_basin" type="box" pos="0.0 -0.04250000000000001 -0.1365" size="0.45 0.3325 0.1085"/>
      </body>
    </body>
  </worldbody>
</mujoco>
