<mujoco model="model">
  <compiler angle="radian"/>
  <asset>
    <mesh file="visuals/Oven031_Door001.obj" name="Oven031_Door_vis"/>
    <mesh file="visuals/Oven031_Knob001.obj" name="Oven031_Knob001_vis"/>
    <mesh file="visuals/Oven031_Body001.obj" name="Oven031_Body_vis"/>
    <mesh file="visuals/Oven031_Button001.obj" name="Oven031_Button_vis"/>
    <mesh file="visuals/Oven031_Knob002.obj" name="Oven031_Knob002_vis"/>
    <mesh file="visuals/Oven031_Door001_Clear.obj" name="Oven031_Door_Clear_vis"/>
    <mesh file="visuals/Oven031_Container001.obj" name="Oven031_Container_vis"/>
    <texture file="visuals/T_Oven031_BC001.png" name="T_Oven031_BC001" type="2d"/>
    <material name="material" rgba="1 1 1 1" texture="T_Oven031_BC001"/>
    <material name="material_Clear" rgba="1 1 1 0.4" texture="T_Oven031_BC001"/>
  </asset>
  <default>
    <default class="visual">
      <geom conaffinity="0" contype="0" group="1" type="mesh"/>
    </default>
    <default class="collision">
      <geom group="0" rgba="0.5 0 0 0.5"/>
    </default>
  </default>
  <worldbody>
    <body>
      <geom name="reg_ext" conaffinity="0" contype="0" group="1" type="box" size="0.22445128858089447 0.15332135558128357 0.13810381293296814" pos="0.0 0.0 0.13810381293296814" rgba="0 0 1 0"/>
      <geom name="reg_int" conaffinity="0" contype="0" group="1" type="box" size="0.1450786218047142 0.13046935945749283 0.08663728833198547" pos="-0.029867731034755707 -0.0013633295893669128 0.1582796573638916" rgba="0 0 1 0"/>
      <body name="object">
        <geom mesh="Oven031_Body_vis" type="mesh" solimp="0.998 0.998 0.001" solref="0.001 1" density="100" friction="0.95 0.3 0.1" class="visual" material="material"/>
        <geom class="collision" type="box" pos="-0.0014766920357942581 -0.014175787568092346 0.25863978266716003" size="0.1281106173992157 0.22517129778862 0.018757104873657227" quat="0.7071067690849304 -9.974800008194507e-08 9.974800008194507e-08 -0.7071067690849304"/>
        <geom class="collision" type="box" pos="-0.21419605612754822 -0.011050879955291748 0.13953936100006104" size="0.12498609721660614 0.11685483157634735 0.01261381059885025" quat="0.49999988079071045 -0.5000000596046448 0.5000001192092896 -0.49999991059303284"/>
        <geom class="collision" type="box" pos="0.16839289665222168 -0.01107381284236908 0.13953933119773865" size="0.12500755488872528 0.11685483157634735 0.05523856356739998" quat="0.49999988079071045 -0.5000000596046448 0.5000001192092896 -0.49999991059303284"/>
        <geom class="collision" type="box" pos="-0.0014766901731491089 0.1213604211807251 0.13906507194042206" size="0.0256769098341465 0.22517129778862 0.138331800699234" quat="0.7071067690849304 -9.974800008194507e-08 9.974800008194507e-08 -0.7071067690849304"/>
        <geom class="collision" type="box" pos="-0.0015539908781647682 -0.010919224470853806 0.030553704127669334" size="0.12485408037900925 0.2250940054655075 0.030490662902593613" quat="0.7071067690849304 -9.974800008194507e-08 9.974800008194507e-08 -0.7071067690849304"/>
        <geom class="collision" type="box" pos="0.1800902932882309 -0.1447107344865799 0.1472194343805313" size="0.004168093204498291 0.1297832429409027 0.043541163206100464" quat="0.49999988079071045 -0.5000000596046448 0.5000001192092896 -0.49999991059303284"/>
        <body name="Oven031_Button">
          <joint axis="0 1 0" pos="0.16884446144104004 -0.15525871515274048 0.16628101468086243" limited="true" name="Oven031_Button_joint" range="0.0 0.002" type="slide" damping="2" frictionloss="2" armature=".01"/>
          <geom mesh="Oven031_Button_vis" type="mesh" solimp="0.998 0.998 0.001" solref="0.001 1" density="100" friction="0.95 0.3 0.1" class="visual" material="material"/>
          <geom class="collision" type="box" pos="0.168844535946846 -0.15525881946086884 0.16685688495635986" size="0.002120696008205414 0.01336456835269928 0.006437420845031738" quat="0.7071067690849304 -5.76011558450773e-08 5.76011558450773e-08 -0.7071067690849304"/>
        </body>
        <body name="Oven031_Door">
          <joint axis="1 0 0" pos="-0.03351595997810364 -0.1521720588207245 0.042903006076812744" limited="true" name="Oven031_Door_joint" range="0.0 1.5707963267948966" type="hinge" damping="2" frictionloss="2" armature=".01"/>
          <geom mesh="Oven031_Door_vis" type="mesh" solimp="0.998 0.998 0.001" solref="0.001 1" density="100" friction="0.95 0.3 0.1" class="visual" material="material"/>
          <geom class="collision" type="box" pos="-0.0356673002243042 -0.1502801477909088 0.15256483852863312" size="0.003124132752418518 0.16081230342388153 0.09399210661649704" quat="0.7071067690849304 -9.974800008194507e-08 9.974800008194507e-08 -0.7071067690849304"/>
          <geom class="collision" type="box" pos="-0.18607407808303833 -0.1704414337873459 0.23064222931861877" size="0.015711547806859016 0.008730672299861908 0.016565613448619843" quat="0.7071067690849304 0.0 -0.0 -0.7071067690849304"/>
          <geom class="collision" type="box" pos="0.11023642867803574 -0.17044144868850708 0.23064222931861877" size="0.015711547806859016 0.005056312307715416 0.016565613448619843" quat="0.7071067690849304 0.0 -0.0 -0.7071067690849304"/>
          <geom class="collision" type="box" pos="-0.03383904695510864 -0.1825212836265564 0.23064224421977997" size="0.14917047321796417 0.003578423522412777 0.016011571511626244" quat="-1.6292068494294654e-07 -0.0 0.0 -1.0"/>
          <body name="Oven031_Door_Clear">
            <geom mesh="Oven031_Door_Clear_vis" type="mesh" solimp="0.998 0.998 0.001" solref="0.001 1" density="100" friction="0.95 0.3 0.1" class="visual" material="material_Clear"/>
            <geom class="collision" type="box" pos="-0.0356673002243042 -0.1502801477909088 0.15256483852863312" size="0.003124132752418518 0.16081230342388153 0.09399210661649704" quat="0.7071067690849304 -9.974800008194507e-08 9.974800008194507e-08 -0.7071067690849304"/>
            <geom class="collision" type="box" pos="-0.18607407808303833 -0.1704414337873459 0.23064222931861877" size="0.015711547806859016 0.008730672299861908 0.016565613448619843" quat="0.7071067690849304 0.0 -0.0 -0.7071067690849304"/>
            <geom class="collision" type="box" pos="0.11023642867803574 -0.17044144868850708 0.23064222931861877" size="0.015711547806859016 0.005056312307715416 0.016565613448619843" quat="0.7071067690849304 0.0 -0.0 -0.7071067690849304"/>
            <geom class="collision" type="box" pos="-0.03383904695510864 -0.1825212836265564 0.23064224421977997" size="0.14917047321796417 0.003578423522412777 0.016011571511626244" quat="-1.6292068494294654e-07 -0.0 0.0 -1.0"/>
          </body>
        </body>
        <body name="Oven031_Knob001">
          <joint axis="0 1 0" pos="0.1690128892660141 -0.16939151287078857 0.12291479110717773" limited="true" name="Oven031_Knob001_joint" range="0.0 5.585053606381854" type="hinge" damping="2" frictionloss="2" armature=".01"/>
          <geom mesh="Oven031_Knob001_vis" type="mesh" solimp="0.998 0.998 0.001" solref="0.001 1" density="100" friction="0.95 0.3 0.1" class="visual" material="material"/>
          <geom class="collision" type="cylinder" pos="0.1690940260887146 -0.16324535012245178 0.12263505160808563" size="0.01717980019748211 0.009558044373989105" quat="0.4999999701976776 -0.5000000596046448 -0.4999999403953552 -0.5"/>
        </body>
        <body name="Oven031_Knob002">
          <joint axis="0 1 0" pos="0.1690128743648529 -0.1693914830684662 0.07035396993160248" limited="true" name="Oven031_Knob002_joint" range="0.0 4.014257279586958" type="hinge" damping="2" frictionloss="2" armature=".01"/>
          <geom mesh="Oven031_Knob002_vis" type="mesh" solimp="0.998 0.998 0.001" solref="0.001 1" density="100" friction="0.95 0.3 0.1" class="visual" material="material"/>
          <geom class="collision" type="cylinder" pos="0.1690940260887146 -0.1632453203201294 0.07046785205602646" size="0.01717980019748211 0.009558044373989105" quat="0.4999999701976776 -0.5000000596046448 -0.4999999403953552 -0.5"/>
        </body>
        <body name="Oven031_Container">
          <joint axis="0 -1 0" pos="-0.03350275009870529 -0.025123493745923042 0.08099598437547684" limited="true" name="Oven031_Container_joint" range="0.0 0.2" type="slide" damping="2" frictionloss="2" armature=".01"/>
          <geom mesh="Oven031_Container_vis" type="mesh" solimp="0.998 0.998 0.001" solref="0.001 1" density="100" friction="0.95 0.3 0.1" class="visual" material="material"/>
          <geom class="collision" type="box" pos="-0.03294401615858078 -0.02160477265715599 0.0821787565946579" size="0.08932340890169144 0.13245654106140137 0.004777330905199051" quat="0.7071067690849304 0.0 -0.0 -0.7071067690849304"/>
        </body>
      </body>
    </body>
  </worldbody>
  <actuator>
    <motor name="Oven031_Button_joint_actuator" joint="Oven031_Button_joint" gear="10"/>
    <motor name="Oven031_Door_joint_actuator" joint="Oven031_Door_joint" gear="10"/>
    <motor name="Oven031_Knob001_joint_actuator" joint="Oven031_Knob001_joint" gear="10"/>
    <motor name="Oven031_Knob002_joint_actuator" joint="Oven031_Knob002_joint" gear="10"/>
    <motor name="Oven031_Container_joint_actuator" joint="Oven031_Container_joint" gear="10"/>
  </actuator>
</mujoco>
