<mujoco model="model">
  <compiler angle="radian"/>
  <asset>
    <mesh file="visuals/WallStackBody001.obj" name="WallStackBody001_vis"/>
    <mesh file="visuals/WallStackBody001_Clear.obj" name="WallStackBody001_Clear_vis"/>
    <mesh file="visuals/WallStackButton001.obj" name="WallStackButton001_vis"/>
    <mesh file="visuals/WallStackButton002.obj" name="WallStackButton002_vis"/>
    <mesh file="visuals/WallStackButton003.obj" name="WallStackButton003_vis"/>
    <mesh file="visuals/WallStackDoor001.obj" name="WallStackDoor001_vis"/>
    <mesh file="visuals/WallStackDoor001_Clear.obj" name="WallStackDoor001_Clear_vis"/>
    <mesh file="visuals/WallStackKnob001.obj" name="WallStackKnob001_vis"/>
    <mesh file="visuals/WallStackKnob002.obj" name="WallStackKnob002_vis"/>
    <mesh file="visuals/WallStackShelf001.obj" name="WallStackShelf001_vis"/>
    <texture file="visuals/T_WallStackBC001.png" name="WallStackBody001_material" type="2d"/>
    <material name="WallStackBody001_material" rgba="1 1 1 1.0" texture="WallStackBody001_material" shininess="0.4472135901451111" specular="0.3103448502657381"/>
    <texture file="visuals/T_WallStackBC001.png" name="WallStackBody001_Clear_material" type="2d"/>
    <material name="WallStackBody001_Clear_material" rgba="1 1 1 0.3855290710926056" texture="WallStackBody001_Clear_material" shininess="0.452394962310791" specular="0.3103448502657381"/>
    <texture file="visuals/T_WallStackBC001.png" name="WallStackButton001_material" type="2d"/>
    <material name="WallStackButton001_material" rgba="1 1 1 1.0" texture="WallStackButton001_material" shininess="0.4472135901451111" specular="0.3103448502657381"/>
    <texture file="visuals/T_WallStackBC001.png" name="WallStackButton002_material" type="2d"/>
    <material name="WallStackButton002_material" rgba="1 1 1 1.0" texture="WallStackButton002_material" shininess="0.4472135901451111" specular="0.3103448502657381"/>
    <texture file="visuals/T_WallStackBC001.png" name="WallStackButton003_material" type="2d"/>
    <material name="WallStackButton003_material" rgba="1 1 1 1.0" texture="WallStackButton003_material" shininess="0.4472135901451111" specular="0.3103448502657381"/>
    <texture file="visuals/T_WallStackBC001.png" name="WallStackDoor001_material" type="2d"/>
    <material name="WallStackDoor001_material" rgba="1 1 1 1.0" texture="WallStackDoor001_material" shininess="0.4472135901451111" specular="0.3103448502657381"/>
    <texture file="visuals/T_WallStackBC001.png" name="WallStackDoor001_Clear_material" type="2d"/>
    <material name="WallStackDoor001_Clear_material" rgba="1 1 1 0.3855290710926056" texture="WallStackDoor001_Clear_material" shininess="0.452394962310791" specular="0.3103448502657381"/>
    <texture file="visuals/T_WallStackBC001.png" name="WallStackKnob001_material" type="2d"/>
    <material name="WallStackKnob001_material" rgba="1 1 1 1.0" texture="WallStackKnob001_material" shininess="0.4472135901451111" specular="0.3103448502657381"/>
    <texture file="visuals/T_WallStackBC001.png" name="WallStackKnob002_material" type="2d"/>
    <material name="WallStackKnob002_material" rgba="1 1 1 1.0" texture="WallStackKnob002_material" shininess="0.4472135901451111" specular="0.3103448502657381"/>
    <texture file="visuals/T_WallStackBC001.png" name="WallStackShelf001_material" type="2d"/>
    <material name="WallStackShelf001_material" rgba="1 1 1 1.0" texture="WallStackShelf001_material" shininess="0.4472135901451111" specular="0.3103448502657381"/>
  </asset>
  <default>
    <default class="visual">
      <geom conaffinity="0" contype="0" group="1" type="mesh"/>
    </default>
    <default class="collision">
      <geom group="0" rgba="0.5 0 0 0.5"/>
    </default>
    <default class="spawn">
      <geom group="0" rgba="1 1 1 0.5" contype="0" conaffinity="0"/>
      <site group="0" rgba="1 1 1 0.5"/>
    </default>
  </default>
  <worldbody>
    <body>
      <site rgba="0 0 0 0.5" size="0.01" pos="-0.326128 -0.252331 -0.287373" name="ext_p0"/>
      <site rgba="1 0 0 0.5" size="0.01" pos="0.325094 -0.252331 -0.287373" name="ext_px"/>
      <site rgba="0 1 0 0.5" size="0.01" pos="-0.326128 0.282640 -0.287373" name="ext_py"/>
      <site rgba="0 0 1 0.5" size="0.01" pos="-0.326128 -0.252331 0.305914" name="ext_pz"/>
      <site rgba="0.5 0.5 0.5 0.5" size="0.004999999888241291" pos="-0.285279 -0.215194 -0.271391" name="int_p0"/>
      <site rgba="1 1 0 0.5" size="0.004999999888241291" pos="0.285934 -0.215194 -0.271391" name="int_px"/>
      <site rgba="0 1 1 0.5" size="0.004999999888241291" pos="-0.285279 0.208946 -0.271391" name="int_py"/>
      <site rgba="1 0.75 0.8 0.5" size="0.004999999888241291" pos="-0.285279 -0.215194 0.176137" name="int_pz"/>
      <body name="object">
        <geom mesh="WallStackBody001_vis" type="mesh" solimp="0.998 0.998 0.001" solref="0.001 1" density="100" friction="0.95 0.3 0.1" class="visual" material="WallStackBody001_material"/>
        <geom class="collision" type="box" pos="-0.301296 0.023262 -0.024806" size="0.01478639803826809 0.24709907174110413 0.2611127495765686" quat="1.0 0.0 0.0 0.0"/>
        <geom class="collision" type="box" pos="0.299052 0.023262 -0.024806" size="0.01478639803826809 0.24709907174110413 0.26111167669296265" quat="1.0 0.0 0.0 0.0"/>
        <geom class="collision" type="box" pos="0.005487 0.028924 -0.278042" size="0.3116050958633423 0.2453157901763916 0.01175801083445549" quat="1.0 0.0 0.0 0.0"/>
        <geom class="collision" type="box" pos="-0.000915 -0.061673 0.237195" size="0.31520184874534607 0.18234699964523315 0.03673063591122627" quat="1.0 0.0 0.0 0.0"/>
        <geom class="collision" type="box" pos="-0.000574 0.246029 -0.024806" size="0.30928507447242737 0.03833812102675438 0.2611050009727478" quat="1.0 0.0 0.0 0.0"/>
        <geom class="collision" type="box" pos="-0.000807 0.175894 0.208440" size="0.31160783767700195 0.10427825152873993 0.03586871176958084" quat="1.0 0.0 0.0 0.0"/>
        <geom class="collision" type="box" pos="-0.001256 -0.242392 0.249331" size="0.32693126797676086 0.003147152718156576 0.06301714479923248" quat="1.0 0.0 0.0 0.0"/>
        <body name="WallStackBody001_Clear">
          <geom mesh="WallStackBody001_Clear_vis" type="mesh" solimp="0.998 0.998 0.001" solref="0.001 1" density="100" friction="0.95 0.3 0.1" class="visual" material="WallStackBody001_Clear_material"/>
        </body>
        <body name="WallStackButton001">
          <joint axis="0.0 1.0 0.0" pos="-0.033737 -0.252610 0.219693" limited="true" name="WallStackButton001_joint" range="0.0 0.002" type="slide" damping="1" frictionloss="1" armature=".01" stiffness="0.05"/>
          <geom mesh="WallStackButton001_vis" type="mesh" solimp="0.998 0.998 0.001" solref="0.001 1" density="100" friction="0.95 0.3 0.1" class="visual" material="WallStackButton001_material"/>
          <geom class="collision" type="box" pos="-0.033737 -0.249088 0.220038" size="0.016094965860247612 0.0005666011129505932 0.007126968819648027" quat="1.0 0.0 0.0 0.0"/>
        </body>
        <body name="WallStackButton002">
          <joint axis="0.0 1.0 0.0" pos="-0.000620 -0.252610 0.219693" limited="true" name="WallStackButton002_joint" range="0.0 0.002" type="slide" damping="1" frictionloss="1" armature=".01" stiffness="0.05"/>
          <geom mesh="WallStackButton002_vis" type="mesh" solimp="0.998 0.998 0.001" solref="0.001 1" density="100" friction="0.95 0.3 0.1" class="visual" material="WallStackButton002_material"/>
          <geom class="collision" type="box" pos="-0.000620 -0.249088 0.220038" size="0.016094965860247612 0.0005666011129505932 0.007126979064196348" quat="1.0 0.0 0.0 0.0"/>
        </body>
        <body name="WallStackButton003">
          <joint axis="0.0 1.0 0.0" pos="0.032496 -0.252610 0.219693" limited="true" name="WallStackButton003_joint" range="0.0 0.002" type="slide" damping="1" frictionloss="1" armature=".01" stiffness="0.05"/>
          <geom mesh="WallStackButton003_vis" type="mesh" solimp="0.998 0.998 0.001" solref="0.001 1" density="100" friction="0.95 0.3 0.1" class="visual" material="WallStackButton003_material"/>
          <geom class="collision" type="box" pos="0.032496 -0.249088 0.220038" size="0.016094965860247612 0.0005666011129505932 0.007126989308744669" quat="1.0 0.0 0.0 0.0"/>
        </body>
        <body name="WallStackDoor001">
          <joint axis="1.0 0.0 0.0" pos="0.000451 -0.243773 -0.304903" limited="true" name="WallStackDoor001_joint" range="0.0 1.5707963267948966" type="hinge" damping="1" frictionloss="1" armature=".01" stiffness="0.05"/>
          <geom mesh="WallStackDoor001_vis" type="mesh" solimp="0.998 0.998 0.001" solref="0.001 1" density="100" friction="0.95 0.3 0.1" class="visual" material="WallStackDoor001_material"/>
          <geom class="collision" type="box" pos="0.000451 -0.239699 -0.032811" size="0.31627267599105835 0.00658991327509284 0.21543464064598083" quat="1.0 0.0 0.0 0.0"/>
          <geom class="collision" type="box" pos="-0.271539 -0.260389 0.126812" size="0.018335489556193352 0.014004801400005817 0.015094383619725704" quat="1.0 0.0 0.0 0.0"/>
          <geom class="collision" type="box" pos="0.269226 -0.260389 0.126812" size="0.018335489556193352 0.014004801400005817 0.015094383619725704" quat="1.0 0.0 0.0 0.0"/>
          <geom class="collision" type="box" pos="-0.000042 -0.279793 0.127879" size="0.2860831916332245 0.005087323021143675 0.012259099632501602" quat="1.0 0.0 0.0 0.0"/>
          <geom class="collision" type="box" pos="-0.000042 -0.244599 -0.278879" size="0.32582762837409973 0.0036299205385148525 0.02445964887738228" quat="1.0 0.0 0.0 0.0"/>
          <body name="WallStackDoor001_Clear">
            <geom mesh="WallStackDoor001_Clear_vis" type="mesh" solimp="0.998 0.998 0.001" solref="0.001 1" density="100" friction="0.95 0.3 0.1" class="visual" material="WallStackDoor001_Clear_material"/>
          </body>
        </body>
        <body name="WallStackKnob001">
          <joint axis="0.0 1.0 0.0" pos="-0.132910 -0.260845 0.237662" limited="true" name="WallStackKnob001_joint" range="0.0 3.141592653589793" type="hinge" damping="1" frictionloss="1" armature=".01" stiffness="0.05"/>
          <geom mesh="WallStackKnob001_vis" type="mesh" solimp="0.998 0.998 0.001" solref="0.001 1" density="100" friction="0.95 0.3 0.1" class="visual" material="WallStackKnob001_material"/>
          <geom class="collision" type="cylinder" pos="-0.132910 -0.256572 0.237662" size="0.017478059977293015 0.008931512013077736" quat="0.7071067094802856 0.7071068286895752 0.0 0.0"/>
        </body>
        <body name="WallStackKnob002">
          <joint axis="0.0 1.0 0.0" pos="0.130672 -0.260845 0.237662" limited="true" name="WallStackKnob002_joint" range="0.0 3.141592653589793" type="hinge" damping="1" frictionloss="1" armature=".01" stiffness="0.05"/>
          <geom mesh="WallStackKnob002_vis" type="mesh" solimp="0.998 0.998 0.001" solref="0.001 1" density="100" friction="0.95 0.3 0.1" class="visual" material="WallStackKnob002_material"/>
          <geom class="collision" type="cylinder" pos="0.130672 -0.256572 0.237662" size="0.017478059977293015 0.008931512013077736" quat="0.7071067094802856 0.7071068286895752 0.0 0.0"/>
        </body>
        <body name="WallStackShelf001">
          <joint axis="0.0 -1.0 0.0" pos="-0.000356 -0.002430 -0.136759" limited="true" name="WallStackShelf001_joint" range="0.0 0.3" type="slide" damping="1" frictionloss="1" armature=".01" stiffness="0.05"/>
          <geom mesh="WallStackShelf001_vis" type="mesh" solimp="0.998 0.998 0.001" solref="0.001 1" density="100" friction="0.95 0.3 0.1" class="visual" material="WallStackShelf001_material"/>
          <geom class="collision" type="box" pos="-0.000517 -0.005107 -0.122556" size="0.27905774116516113 0.17288406193256378 0.0030593248084187508" quat="1.0 0.0 0.0 0.0"/>
        </body>
      </body>
    </body>
  </worldbody>
  <actuator>
    <motor name="WallStackButton001_joint_actuator" joint="WallStackButton001_joint" gear="0.5"/>
    <motor name="WallStackButton002_joint_actuator" joint="WallStackButton002_joint" gear="0.5"/>
    <motor name="WallStackButton003_joint_actuator" joint="WallStackButton003_joint" gear="0.5"/>
    <motor name="WallStackDoor001_joint_actuator" joint="WallStackDoor001_joint" gear="50"/>
    <motor name="WallStackKnob001_joint_actuator" joint="WallStackKnob001_joint" gear="50"/>
    <motor name="WallStackKnob002_joint_actuator" joint="WallStackKnob002_joint" gear="50"/>
    <motor name="WallStackShelf001_joint_actuator" joint="WallStackShelf001_joint" gear="50"/>
  </actuator>
</mujoco>