<mujoco model="model">
  <compiler angle="radian"/>
  <asset>
    <mesh file="visuals/handle.obj" name="handle_vis"/>
    <mesh file="visuals/Body001.obj" name="Body001_vis"/>
    <mesh file="visuals/Funnel001.obj" name="Funnel001_vis"/>
    <mesh file="visuals/spout.obj" name="spout_vis"/>
    <texture file="visuals/T_BC001.png" name="Body001_material" type="2d"/>
    <material name="Body001_material" rgba="1 1 1 1.0" texture="Body001_material" shininess="0.5" specular="0.3103448502657381"/>
    <texture file="visuals/T_BC001.png" name="handle_material" type="2d"/>
    <material name="handle_material" rgba="1 1 1 1.0" texture="handle_material" shininess="0.5" specular="0.3103448502657381"/>
    <texture file="visuals/T_BC001.png" name="Funnel001_material" type="2d"/>
    <material name="Funnel001_material" rgba="1 1 1 1.0" texture="Funnel001_material" shininess="0.5" specular="0.3103448502657381"/>
    <texture file="visuals/T_BC001.png" name="spout_material" type="2d"/>
    <material name="spout_material" rgba="1 1 1 1.0" texture="spout_material" shininess="0.5" specular="0.3103448502657381"/>
  </asset>
  <default>
    <default class="visual">
      <geom conaffinity="0" contype="0" group="1" type="mesh"/>
    </default>
    <default class="collision">
      <geom group="0" rgba="0.5 0 0 0.5"/>
    </default>
    <default class="spawn">
      <geom group="0" rgba="1 1 1 0.5" contype="0" conaffinity="0"/>
      <site group="0" rgba="1 1 1 0.5"/>
    </default>
  </default>
  <worldbody>
    <body>
      <site rgba="0 0 0 0.5" size="0.01" pos="-0.2387748621404171 -0.2387748658657074 -0.18003445863723755" name="ext_p0"/>
      <site rgba="1 0 0 0.5" size="0.01" pos="0.2387748695909977 -0.2387748658657074 -0.18003445863723755" name="ext_px"/>
      <site rgba="0 1 0 0.5" size="0.01" pos="-0.2387748621404171 0.2387748658657074 -0.18003445863723755" name="ext_py"/>
      <site rgba="0 0 1 0.5" size="0.01" pos="-0.2387748621404171 -0.2387748658657074 -0.03123718500137329" name="ext_pz"/>
      <site rgba="1 0.75 0.8 0.5" size="0.004999999888241291" pos="-0.12065501511096954 -0.14546671509742737 -0.0329282209277153" name="int_pz"/>
      <site rgba="0 1 1 0.5" size="0.004999999888241291" pos="-0.12065501511096954 0.14786691963672638 -0.16163881123065948" name="int_py"/>
      <site rgba="1 1 0 0.5" size="0.004999999888241291" pos="0.11325977742671967 -0.14546671509742737 -0.16163881123065948" name="int_px"/>
      <site rgba="0.5 0.5 0.5 0.5" size="0.004999999888241291" pos="-0.12065501511096954 -0.14546671509742737 -0.16163881123065948" name="int_p0"/>
      <body name="object">
        <geom mesh="Body001_vis" type="mesh" solimp="0.998 0.998 0.001" solref="0.001 1" density="100" friction="0.95 0.3 0.1" class="visual" material="Body001_material"/>
        <geom class="collision" type="box" pos="-2.8694557840935886e-10 -0.2150280922651291 -0.03745047748088837" size="0.033866215497255325 0.023684093728661537 0.00461614690721035" quat="1.0 0.0 0.0 0.0"/>
        <geom class="collision" type="box" pos="-2.8694557840935886e-10 -0.19462397694587708 -0.10632763803005219" size="0.033866215497255325 0.0025562462396919727 0.06660361588001251" quat="1.0 0.0 0.0 0.0"/>
        <geom class="collision" type="box" pos="-2.8694557840935886e-10 -0.11920654028654099 -0.17113912105560303" size="0.033866215497255325 0.07515937834978104 0.003272552974522114" quat="1.0 0.0 0.0 0.0"/>
        <geom class="collision" type="box" pos="-0.055643480271101 -0.20770055055618286 -0.03745047748088837" size="0.033866215497255325 0.023684000596404076 0.00461614690721035" quat="0.9914448261260986 0.0 -0.0 -0.1305263340473175"/>
        <geom class="collision" type="box" pos="-0.05036250874400139 -0.1879916787147522 -0.10632763803005219" size="0.033866215497255325 0.06660331785678864 0.0025562408845871687" quat="0.7010574340820312 0.7010573744773865 -0.09229595214128494 -0.09229595959186554"/>
        <geom class="collision" type="box" pos="-0.030843039974570274 -0.1151440367102623 -0.17113912105560303" size="0.033866215497255325 0.07515911757946014 0.003272552974522114" quat="0.9914448261260986 0.0 -0.0 -0.1305263340473175"/>
        <geom class="collision" type="box" pos="-0.10749445855617523 -0.18622110784053802 -0.03745047748088837" size="0.033866215497255325 0.023684000596404076 0.00461614690721035" quat="0.9659258127212524 0.0 -0.0 -0.2588191032409668"/>
        <geom class="collision" type="box" pos="-0.09729239344596863 -0.16855062544345856 -0.10632763803005219" size="0.033866215497255325 0.06660331785678864 0.0025562408845871687" quat="0.6830127239227295 0.6830126643180847 -0.1830126941204071 -0.1830127090215683"/>
        <geom class="collision" type="box" pos="-0.05958367511630058 -0.10323721170425415 -0.17113912105560303" size="0.033866215497255325 0.07515911012887955 0.003272552974522114" quat="0.9659258127212524 0.0 -0.0 -0.2588191032409668"/>
        <geom class="collision" type="box" pos="-0.15201935172080994 -0.15205354988574982 -0.03745047748088837" size="0.033866215497255325 0.023684000596404076 0.00461614690721035" quat="0.9238795042037964 0.0 -0.0 -0.3826834559440613"/>
        <geom class="collision" type="box" pos="-0.13759145140647888 -0.13762566447257996 -0.10632763803005219" size="0.033866215497255325 0.06660331785678864 0.0025562411174178123" quat="0.6532815098762512 0.6532814502716064 -0.27059802412986755 -0.27059805393218994"/>
        <geom class="collision" type="box" pos="-0.08426328748464584 -0.08429748564958572 -0.17113912105560303" size="0.033866215497255325 0.07515911757946014 0.003272552974522114" quat="0.9238795042037964 0.0 -0.0 -0.3826834559440613"/>
        <geom class="collision" type="box" pos="-0.186183899641037 -0.10752630233764648 -0.03745047748088837" size="0.033866215497255325 0.023684000596404076 0.00461614690721035" quat="0.8660253882408142 0.0 -0.0 -0.5"/>
        <geom class="collision" type="box" pos="-0.16851341724395752 -0.09732424467802048 -0.10632763803005219" size="0.033866215497255325 0.06660331785678864 0.0025562411174178123" quat="0.6123724579811096 0.6123723983764648 -0.3535533845424652 -0.3535534143447876"/>
        <geom class="collision" type="box" pos="-0.10320001095533371 -0.05961553007364273 -0.17113912105560303" size="0.033866215497255325 0.07515911757946014 0.003272552974522114" quat="0.8660253882408142 0.0 -0.0 -0.5"/>
        <geom class="collision" type="box" pos="-0.2076597809791565 -0.055673882365226746 -0.03745047748088837" size="0.033866215497255325 0.023684000596404076 0.00461614690721035" quat="0.7933533191680908 0.0 -0.0 -0.6087614297866821"/>
        <geom class="collision" type="box" pos="-0.18795092403888702 -0.05039290711283684 -0.10632763803005219" size="0.033866215497255325 0.06660331785678864 0.0025562408845871687" quat="0.5609855651855469 0.5609855055809021 -0.43045932054519653 -0.4304593503475189"/>
        <geom class="collision" type="box" pos="-0.11510328948497772 -0.030873436480760574 -0.17113912105560303" size="0.033866215497255325 0.07515911757946014 0.003272552974522114" quat="0.7933533191680908 0.0 -0.0 -0.6087614297866821"/>
        <geom class="collision" type="box" pos="-0.21498353779315948 -2.9911872843513265e-05 -0.03745047748088837" size="0.023684002459049225 0.03386629372835159 0.00461614690721035" quat="1.0 0.0 0.0 0.0"/>
        <geom class="collision" type="box" pos="-0.19457942247390747 -2.9910332159488462e-05 -0.10632763803005219" size="0.002556248800829053 0.03386622294783592 0.06660355627536774" quat="1.0 0.0 0.0 0.0"/>
        <geom class="collision" type="box" pos="-0.11916199326515198 -2.9904638722655363e-05 -0.17113912105560303" size="0.07515911757946014 0.03386632353067398 0.003272552974522114" quat="1.0 0.0 0.0 0.0"/>
        <geom class="collision" type="box" pos="-0.20765599608421326 0.05561358481645584 -0.03745047748088837" size="0.033866215497255325 0.023684000596404076 0.00461614690721035" quat="0.6087614297866821 0.0 -0.0 -0.7933533191680908"/>
        <geom class="collision" type="box" pos="-0.1879471242427826 0.05033261328935623 -0.10632763803005219" size="0.033866215497255325 0.06660331785678864 0.0025562408845871687" quat="0.4304593503475189 0.43045932054519653 -0.5609855055809021 -0.5609855651855469"/>
        <geom class="collision" type="box" pos="-0.11509948968887329 0.030813144519925117 -0.17113912105560303" size="0.033866215497255325 0.07515911757946014 0.003272552974522114" quat="0.6087614297866821 0.0 -0.0 -0.7933533191680908"/>
        <geom class="collision" type="box" pos="-0.1861765831708908 0.10746452212333679 -0.03745047748088837" size="0.033866215497255325 0.023684000596404076 0.00461614690721035" quat="0.5000000596046448 0.0 -0.0 -0.8660253882408142"/>
        <geom class="collision" type="box" pos="-0.16850610077381134 0.09726247191429138 -0.10632763803005219" size="0.033866215497255325 0.06660331785678864 0.0025562411174178123" quat="0.35355329513549805 0.35355344414711 -0.6123725771903992 -0.6123723387718201"/>
        <geom class="collision" type="box" pos="-0.10319267958402634 0.059553761035203934 -0.17113912105560303" size="0.033866215497255325 0.07515911757946014 0.003272552974522114" quat="0.5000000596046448 0.0 -0.0 -0.8660253882408142"/>
        <geom class="collision" type="box" pos="-0.1520090103149414 0.1519894301891327 -0.03745047748088837" size="0.033866215497255325 0.023684000596404076 0.00461614690721035" quat="0.38268354535102844 0.0 -0.0 -0.9238795042037964"/>
        <geom class="collision" type="box" pos="-0.13758112490177155 0.13756152987480164 -0.10632763803005219" size="0.033866215497255325 0.06660331785678864 0.0025562411174178123" quat="0.2705981433391571 0.2705981135368347 -0.6532814502716064 -0.6532814502716064"/>
        <geom class="collision" type="box" pos="-0.08425294607877731 0.0842333659529686 -0.17113912105560303" size="0.033866215497255325 0.07515911757946014 0.003272552974522114" quat="0.38268354535102844 0.0 -0.0 -0.9238795042037964"/>
        <geom class="collision" type="box" pos="-0.10748177766799927 0.18615399301052094 -0.03745047748088837" size="0.033866215497255325 0.023684000596404076 0.00461614690721035" quat="0.2588190734386444 0.0 -0.0 -0.9659258127212524"/>
        <geom class="collision" type="box" pos="-0.09727971255779266 0.16848351061344147 -0.10632763803005219" size="0.033866215497255325 0.06660331785678864 0.0025562411174178123" quat="0.1830127239227295 0.1830127090215683 -0.6830126643180847 -0.6830127239227295"/>
        <geom class="collision" type="box" pos="-0.05957099422812462 0.10317009687423706 -0.17113912105560303" size="0.033866215497255325 0.07515911757946014 0.003272552974522114" quat="0.2588190734386444 0.0 -0.0 -0.9659258127212524"/>
        <geom class="collision" type="box" pos="-0.05562934651970863 0.20762988924980164 -0.03745047748088837" size="0.033866215497255325 0.023684000596404076 0.00461614690721035" quat="0.13052624464035034 0.0 -0.0 -0.9914448261260986"/>
        <geom class="collision" type="box" pos="-0.050348371267318726 0.18792103230953217 -0.10632763803005219" size="0.033866215497255325 0.06660331785678864 0.0025562408845871687" quat="0.09229599684476852 0.09229598939418793 -0.7010573744773865 -0.7010574340820312"/>
        <geom class="collision" type="box" pos="-0.030828895047307014 0.11507339030504227 -0.17113912105560303" size="0.033866215497255325 0.07515911757946014 0.003272552974522114" quat="0.13052624464035034 0.0 -0.0 -0.9914448261260986"/>
        <geom class="collision" type="box" pos="1.46221682371106e-05 0.21495364606380463 -0.03745047748088837" size="0.033866219222545624 0.0236840657889843 0.00461614690721035" quat="1.0 0.0 0.0 0.0"/>
        <geom class="collision" type="box" pos="1.4625249605160207e-05 0.1945495307445526 -0.10632763803005219" size="0.033866215497255325 0.0025562515947967768 0.06660349667072296" quat="1.0 0.0 0.0 0.0"/>
        <geom class="collision" type="box" pos="1.4636637388321105e-05 0.11913209408521652 -0.17113912105560303" size="0.03386622667312622 0.07515927404165268 0.003272552974522114" quat="1.0 0.0 0.0 0.0"/>
        <geom class="collision" type="box" pos="0.055658143013715744 0.2076261043548584 -0.03745047748088837" size="0.033866215497255325 0.023684000596404076 0.00461614690721035" quat="0.13052624464035034 0.0 0.0 0.9914448261260986"/>
        <geom class="collision" type="box" pos="0.050377167761325836 0.18791723251342773 -0.10632763803005219" size="0.033866215497255325 0.06660331785678864 0.0025562408845871687" quat="0.09229599684476852 0.09229598939418793 0.7010573744773865 0.7010574340820312"/>
        <geom class="collision" type="box" pos="0.030857697129249573 0.11506959050893784 -0.17113912105560303" size="0.033866215497255325 0.07515911757946014 0.003272552974522114" quat="0.13052624464035034 0.0 0.0 0.9914448261260986"/>
        <geom class="collision" type="box" pos="0.10750909894704819 0.18614666163921356 -0.03745047748088837" size="0.033866215497255325 0.023684000596404076 0.00461614690721035" quat="0.25881895422935486 0.0 0.0 0.9659258723258972"/>
        <geom class="collision" type="box" pos="0.09730703383684158 0.1684761792421341 -0.10632763803005219" size="0.033866215497255325 0.06660331785678864 0.0025562411174178123" quat="0.1830127239227295 0.1830127090215683 0.6830126643180847 0.6830127239227295"/>
        <geom class="collision" type="box" pos="0.059598322957754135 0.10316276550292969 -0.17113912105560303" size="0.033866215497255325 0.07515911012887955 0.003272552974522114" quat="0.25881895422935486 0.0 0.0 0.9659258723258972"/>
        <geom class="collision" type="box" pos="0.1520339995622635 0.15197910368442535 -0.03745047748088837" size="0.033866215497255325 0.023684000596404076 0.00461614690721035" quat="0.38268330693244934 0.0 0.0 0.9238795638084412"/>
        <geom class="collision" type="box" pos="0.13760611414909363 0.1375512182712555 -0.10632763803005219" size="0.033866215497255325 0.06660331785678864 0.0025562411174178123" quat="0.27059805393218994 0.27059805393218994 0.6532814502716064 0.6532815098762512"/>
        <geom class="collision" type="box" pos="0.0842779204249382 0.08422303944826126 -0.17113912105560303" size="0.033866215497255325 0.07515911757946014 0.003272552974522114" quat="0.38268330693244934 0.0 0.0 0.9238795638084412"/>
        <geom class="collision" type="box" pos="0.18619856238365173 0.10745184868574142 -0.03745047748088837" size="0.033866215497255325 0.023684000596404076 0.00461614690721035" quat="0.5000000596046448 0.0 0.0 0.8660253882408142"/>
        <geom class="collision" type="box" pos="0.16852807998657227 0.09724979102611542 -0.10632763803005219" size="0.033866215497255325 0.06660331785678864 0.0025562411174178123" quat="0.35355329513549805 0.35355344414711 0.6123725771903992 0.6123723387718201"/>
        <geom class="collision" type="box" pos="0.10321465879678726 0.05954108014702797 -0.17113912105560303" size="0.033866215497255325 0.07515911757946014 0.003272552974522114" quat="0.5000000596046448 0.0 0.0 0.8660253882408142"/>
        <geom class="collision" type="box" pos="0.20767447352409363 0.05559941381216049 -0.03745047748088837" size="0.033866215497255325 0.023684000596404076 0.00461614690721035" quat="0.6087614297866821 0.0 0.0 0.7933533191680908"/>
        <geom class="collision" type="box" pos="0.18796560168266296 0.05031844601035118 -0.10632763803005219" size="0.033866215497255325 0.06660331785678864 0.0025562411174178123" quat="0.4304594099521637 0.43045932054519653 0.5609855055809021 0.5609855055809021"/>
        <geom class="collision" type="box" pos="0.11511795222759247 0.030798980966210365 -0.17113912105560303" size="0.033866215497255325 0.07515911757946014 0.003272552974522114" quat="0.6087614297866821 0.0 0.0 0.7933533191680908"/>
        <geom class="collision" type="box" pos="0.21499820053577423 -4.455312227946706e-05 -0.03745047748088837" size="0.023684006184339523 0.03386626020073891 0.00461614690721035" quat="1.0 0.0 0.0 0.0"/>
        <geom class="collision" type="box" pos="0.19459408521652222 -4.4552878534886986e-05 -0.10632763803005219" size="0.0025562497321516275 0.03386622667312622 0.06660344451665878" quat="1.0 0.0 0.0 0.0"/>
        <geom class="collision" type="box" pos="0.11917664110660553 -4.4551979954121634e-05 -0.17113912105560303" size="0.07515912503004074 0.0338662751019001 0.003272552974522114" quat="1.0 0.0 0.0 0.0"/>
        <geom class="collision" type="box" pos="0.2076706439256668 -0.055688124150037766 -0.03745047748088837" size="0.033866215497255325 0.023684000596404076 0.00461614690721035" quat="0.7933534979820251 0.0 0.0 0.6087612509727478"/>
        <geom class="collision" type="box" pos="0.18796177208423615 -0.05040713772177696 -0.10632763803005219" size="0.033866219222545624 0.06660331785678864 0.002556241350248456" quat="0.5609855651855469 0.5609856247901917 0.43045923113822937 0.43045923113822937"/>
        <geom class="collision" type="box" pos="0.11511413007974625 -0.03088764101266861 -0.17113912105560303" size="0.033866215497255325 0.07515911757946014 0.003272552974522114" quat="0.7933534979820251 0.0 0.0 0.6087612509727478"/>
        <geom class="collision" type="box" pos="0.18619123101234436 -0.10753899067640305 -0.03745047748088837" size="0.033866215497255325 0.023684002459049225 0.00461614690721035" quat="0.8660253882408142 0.0 0.0 0.5000000596046448"/>
        <geom class="collision" type="box" pos="0.1685207486152649 -0.09733692556619644 -0.10632763803005219" size="0.033866215497255325 0.06660331785678864 0.002556241350248456" quat="0.6123724579811096 0.6123723983764648 0.3535534143447876 0.35355344414711"/>
        <geom class="collision" type="box" pos="0.10320732742547989 -0.059628214687108994 -0.17113912105560303" size="0.033866215497255325 0.07515911757946014 0.003272552974522114" quat="0.8660253882408142 0.0 0.0 0.5000000596046448"/>
        <geom class="collision" type="box" pos="0.15202367305755615 -0.15206389129161835 -0.03745047748088837" size="0.033866215497255325 0.023684000596404076 0.00461614690721035" quat="0.9238795042037964 0.0 0.0 0.3826834559440613"/>
        <geom class="collision" type="box" pos="0.1375957727432251 -0.1376359760761261 -0.10632763803005219" size="0.033866215497255325 0.06660331785678864 0.002556241350248456" quat="0.6532815098762512 0.6532814502716064 0.27059808373451233 0.2705981135368347"/>
        <geom class="collision" type="box" pos="0.08426759392023087 -0.08430781960487366 -0.17113912105560303" size="0.033866215497255325 0.07515911757946014 0.003272552974522114" quat="0.9238795042037964 0.0 0.0 0.3826834559440613"/>
        <geom class="collision" type="box" pos="0.10749635845422745 -0.18622846901416779 -0.03745047748088837" size="0.033866215497255325 0.023684000596404076 0.00461614690721035" quat="0.9659258723258972 0.0 0.0 0.25881892442703247"/>
        <geom class="collision" type="box" pos="0.09729430824518204 -0.16855798661708832 -0.10632763803005219" size="0.033866219222545624 0.06660331785678864 0.0025562411174178123" quat="0.6830127239227295 0.6830127239227295 0.18301260471343994 0.18301260471343994"/>
        <geom class="collision" type="box" pos="0.05958561226725578 -0.10324456542730331 -0.17113912105560303" size="0.033866215497255325 0.07515911012887955 0.003272552974522114" quat="0.9659258723258972 0.0 0.0 0.25881892442703247"/>
        <geom class="collision" type="box" pos="0.05564393475651741 -0.2077043652534485 -0.03745047748088837" size="0.033866215497255325 0.023684000596404076 0.00461614690721035" quat="0.9914448857307434 0.0 0.0 0.1305261105298996"/>
        <geom class="collision" type="box" pos="0.0503629669547081 -0.18799549341201782 -0.10632763803005219" size="0.033866215497255325 0.06660331785678864 0.0025562411174178123" quat="0.7010574340820312 0.7010573744773865 0.09229589253664017 0.09229589253664017"/>
        <geom class="collision" type="box" pos="0.030843514949083328 -0.11514785140752792 -0.17113912105560303" size="0.033866215497255325 0.07515911757946014 0.003272552974522114" quat="0.9914448857307434 0.0 0.0 0.1305261105298996"/>
        <geom class="collision" type="cylinder" pos="-0.0023821163922548294 0.21908195316791534 -0.0021841649431735277" size="0.01463507954031229 0.028745269402861595" quat="1.0 0.0 0.0 0.0"/>
        <geom class="collision" type="cylinder" pos="0.012323866598308086 0.21908195316791534 -0.0035485276021063328" size="0.021804798394441605 0.013429159298539162" quat="1.0 0.0 0.0 0.0"/>
        <body name="handle">
          <joint axis="1.0 0.0 0.0" pos="0.035692039877176285 0.21887262165546417 -0.003822876140475273" limited="true" name="handle_joint" range="0.0 1.5707963267948966" type="hinge" damping="1" frictionloss="1" armature=".01" stiffness="0.05"/>
          <geom mesh="handle_vis" type="mesh" solimp="0.998 0.998 0.001" solref="0.001 1" density="100" friction="0.95 0.3 0.1" class="visual" material="handle_material"/>
          <geom class="collision" type="cylinder" pos="0.04494136944413185 0.2189115732908249 -0.0038228908088058233" size="0.009770733304321766 0.01543508842587471" quat="1.0 0.0 0.0 0.0"/>
          <geom class="collision" type="cylinder" pos="0.04487316682934761 0.21891160309314728 0.03312664479017258" size="0.0035054702311754227 0.022773226723074913" quat="1.0 0.0 0.0 0.0"/>
        </body>
        <body name="Funnel001">
          <joint axis="0.0 0.0 1.0" pos="7.327172170334961e-06 -3.7223100662231445e-05 -0.17349472641944885" limited="true" name="Funnel001_joint" range="0.0 0.05" type="slide" damping="0" frictionloss="0" armature="0" stiffness="0"/>
          <geom mesh="Funnel001_vis" type="mesh" solimp="0.998 0.998 0.001" solref="0.001 1" density="10000" friction="0.95 0.3 0.1" class="visual" material="Funnel001_material"/>
          <geom class="collision" type="cylinder" pos="7.327172170334961e-06 -3.7223100662231445e-05 -0.17349472641944885" size="0.042641691863536835 0.007699284236878157" quat="1.0 0.0 0.0 0.0"/>
        </body>
        <body name="spout">
          <joint axis="0.0 0.0 1.0" pos="-0.002206692937761545 0.2188722789287567 0.026012349873781204" limited="true" name="spout_joint" range="-1.5707963267948966 1.5707963267948966" type="hinge" damping="0" frictionloss="0" armature=".01" stiffness="0"/>
          <site type="cylinder" rgba="0.5 0.75 1 1" size="0.003897867165505886 0.16643905639648438" pos="-0.0021323910914361477 0.07603458315134048 -0.0060834214091300964" name="water"/>
          <geom mesh="spout_vis" type="mesh" solimp="0.998 0.998 0.001" solref="0.001 1" density="1000" friction="0.95 0.3 0.1" class="visual" material="spout_material"/>
          <geom class="collision" type="cylinder" pos="-0.002206692937761545 0.2188722789287567 0.07418204098939896" size="0.009113517589867115 0.04663829877972603" quat="1.0 0.0 0.0 0.0"/>
          <geom class="collision" type="cylinder" pos="-0.002206692937761545 0.11339418590068817 0.1710738092660904" size="0.009645307436585426 0.0096453120931983" quat="1.0 0.0 0.0 0.0"/>
          <geom class="collision" type="cylinder" pos="-0.002206692937761545 0.07610643655061722 0.1620166003704071" size="0.006267251912504435 0.0032119145616889" quat="1.0 0.0 0.0 0.0"/>
          <geom class="collision" type="cylinder" pos="-0.002206692937761545 0.2188722789287567 0.12755565345287323" size="0.00911351665854454 0.006880446337163448" quat="1.0 0.0 0.0 0.0"/>
          <geom class="collision" type="cylinder" pos="-0.002206692937761545 0.21673154830932617 0.13709719479084015" size="0.009113517589867115 0.006880446337163448" quat="0.9833017587661743 0.18198253214359283 -4.040823945308088e-17 -2.3274321405825955e-24"/>
          <geom class="collision" type="cylinder" pos="-0.002206692937761545 0.21189962327480316 0.1469445526599884" size="0.009113517589867115 0.006880446802824736" quat="0.9554436206817627 0.29517367482185364 -6.554172201008815e-17 -9.897835805655772e-25"/>
          <geom class="collision" type="cylinder" pos="-0.002206692937761545 0.20419299602508545 0.15624144673347473" size="0.009113517589867115 0.006880446337163448" quat="0.9210039377212524 0.3895533084869385 -8.64982038627762e-17 2.2436633560445836e-23"/>
          <geom class="collision" type="cylinder" pos="-0.002206692937761545 0.19471262395381927 0.16382575035095215" size="0.009113517589867115 0.006880445871502161" quat="0.8841060400009155 0.46728628873825073 -1.0375839936976899e-16 2.1039518298810542e-23"/>
          <geom class="collision" type="cylinder" pos="-0.002206692937761545 0.18480409681797028 0.1687188446521759" size="0.009113517589867115 0.006880446802824736" quat="0.8082178831100464 0.5888835787773132 -1.3075844806622667e-16 2.686716354953654e-23"/>
          <geom class="collision" type="cylinder" pos="-0.002206692937761545 0.1753237247467041 0.1709207445383072" size="0.009113517589867115 0.006880446337163448" quat="0.7533880472183228 0.6575762033462524 -1.4601126151501047e-16 3.086439196491197e-24"/>
        </body>
      </body>
    </body>
  </worldbody>
  <actuator>
    <motor name="handle_joint_actuator" joint="handle_joint" gear="10"/>
    <motor name="Funnel001_joint_actuator" joint="Funnel001_joint" gear="10"/>
    <motor name="spout_joint_actuator" joint="spout_joint" gear="10"/>
  </actuator>
</mujoco>