<?xml version='1.0' encoding='UTF-8'?>
<mujoco model="model">
  <option timestep="0.002" gravity="0.0 0.0 -9.81"/>
  <compiler angle="radian"/>
  <asset>
    <mesh file="visuals/Body001.obj" name="Body001_vis"/>
    <mesh file="visuals/Door001.obj" name="Door001_vis"/>
    <mesh file="visuals/Door001_Clear.obj" name="Door001_Clear_vis"/>
    <mesh file="visuals/Knob001.obj" name="Knob001_vis"/>
    <mesh file="visuals/Knob002.obj" name="Knob002_vis"/>
    <mesh file="visuals/Knob003.obj" name="Knob003_vis"/>
    <mesh file="visuals/Knob004.obj" name="Knob004_vis"/>
    <mesh file="visuals/Shelf001.obj" name="Shelf001_vis"/>
    <mesh file="visuals/Shelf002.obj" name="Shelf002_vis"/>
    <texture file="visuals/T_BC001.png" name="Body001_material" type="2d"/>
    <material name="Body001_material" rgba="1 1 1 1.0" texture="Body001_material" shininess="0.1" specular="4"/>
    <texture file="visuals/T_BC001.png" name="Door001_material" type="2d"/>
    <material name="Door001_material" rgba="1 1 1 1.0" texture="Door001_material" shininess="0.1" specular="4"/>
    <material name="Door001_Clear_material" rgba="0.1519247144460678 0.1519247144460678 0.1519247144460678 0.800000011920929" shininess="0.5" specular="0.3103448502657381"/>
    <texture file="visuals/T_BC001.png" name="Knob001_material" type="2d"/>
    <material name="Knob001_material" rgba="1 1 1 1.0" texture="Knob001_material" shininess="0.1" specular="4"/>
    <texture file="visuals/T_BC001.png" name="Knob002_material" type="2d"/>
    <material name="Knob002_material" rgba="1 1 1 1.0" texture="Knob002_material" shininess="0.1" specular="4"/>
    <texture file="visuals/T_BC001.png" name="Knob003_material" type="2d"/>
    <material name="Knob003_material" rgba="1 1 1 1.0" texture="Knob003_material" shininess="0.1" specular="4"/>
    <texture file="visuals/T_BC001.png" name="Knob004_material" type="2d"/>
    <material name="Knob004_material" rgba="1 1 1 1.0" texture="Knob004_material" shininess="0.1" specular="4"/>
    <texture file="visuals/T_BC001.png" name="Shelf001_material" type="2d"/>
    <material name="Shelf001_material" rgba="1 1 1 1.0" texture="Shelf001_material" shininess="0.1" specular="4"/>
    <texture file="visuals/T_BC001.png" name="Shelf002_material" type="2d"/>
    <material name="Shelf002_material" rgba="1 1 1 1.0" texture="Shelf002_material" shininess="0.1" specular="4"/>
  </asset>
  <default>
    <default class="visual">
      <geom conaffinity="0" contype="0" group="1" type="mesh"/>
    </default>
    <default class="collision">
      <geom group="0" rgba="0.5 0 0 0.5"/>
    </default>
    <default class="spawn">
      <geom group="0" rgba="1 1 1 0.5" contype="0" conaffinity="0"/>
      <site group="0" rgba="1 1 1 0.5"/>
    </default>
    <default class="region">
      <geom group="1" conaffinity="0" contype="0" rgba="0 1 0 0"/>
    </default>
  </default>
  <worldbody>
    <body>
      <body name="object">
        <geom mesh="Body001_vis" type="mesh" solimp="0.998 0.998 0.001" solref="0.001 1" friction="0.95 0.3 0.1" class="visual" material="Body001_material"/>
        <geom class="collision" type="box" pos="-0.296644 0.032179 0.000730" size="0.019728386774659157 0.21108181774616241 0.30643755197525024" quat="1.0 0.0 0.0 0.0"/>
        <geom class="collision" type="box" pos="0.297368 0.032179 0.001361" size="0.019333679229021072 0.2110818475484848 0.3058062791824341" quat="1.0 0.0 0.0 0.0"/>
        <geom class="collision" type="box" pos="0.003449 0.032179 0.295626" size="0.3056963384151459 0.21108189225196838 0.011541559360921383" quat="1.0 0.0 0.0 0.0"/>
        <geom class="collision" type="box" pos="0.003449 0.032179 -0.257869" size="0.3056963384151459 0.2110813707113266 0.04657629504799843" quat="1.0 0.0 0.0 0.0"/>
        <geom class="collision" type="box" pos="0.003449 -0.181188 0.225599" size="0.3056963384151459 0.010608079843223095 0.08002576977014542" quat="1.0 0.0 0.0 0.0"/>
        <geom class="collision" type="box" pos="-0.272263 0.039704 -0.015651" size="0.012897388078272343 0.18651673197746277 0.0038140853866934776" quat="1.0 0.0 0.0 0.0"/>
        <geom class="collision" type="box" pos="-0.272263 0.039704 -0.164739" size="0.012897388078272343 0.18651673197746277 0.0038140853866934776" quat="1.0 0.0 0.0 0.0"/>
        <geom class="collision" type="box" pos="0.273281 0.039704 -0.164739" size="0.012897388078272343 0.18651673197746277 0.0038140853866934776" quat="1.0 0.0 0.0 0.0"/>
        <geom class="collision" type="box" pos="0.273281 0.039704 -0.015651" size="0.012897388078272343 0.18651673197746277 0.0038140853866934776" quat="1.0 0.0 0.0 0.0"/>
        <geom class="collision" type="box" pos="0.003449 0.233230 0.035686" size="0.3056963384151459 0.010031049139797688 0.25294944643974304" quat="1.0 0.0 0.0 0.0"/>
        <body name="Door001">
          <joint axis="1.0 0.0 0.0" pos="-0.000001 -0.179608 -0.269650" limited="true" name="Door001_joint" range="0.0 1.5707963267948966" type="hinge" damping="1" frictionloss="1" armature=".01" stiffness="1" springref="-5"/>
          <geom mesh="Door001_vis" type="mesh" solimp="0.998 0.998 0.001" solref="0.001 1" friction="0.95 0.3 0.1" class="visual" material="Door001_material"/>
          <geom class="collision" type="box" pos="0.000000 -0.188517 -0.064301" size="0.3108488619327545 0.006727362051606178 0.19733445346355438" quat="1.0 0.0 0.0 0.0"/>
          <geom class="collision" type="box" pos="0.011013 -0.232668 0.107024" size="0.08317650109529495 0.00783295463770628 0.018378378823399544" quat="1.0 0.0 0.0 0.0"/>
          <geom class="collision" type="box" pos="0.169681 -0.225044 0.107024" size="0.08317650109529495 0.00783295463770628 0.018378378823399544" quat="0.9989672303199768 0.0 0.0 0.04543663188815117"/>
          <geom class="collision" type="box" pos="-0.155279 -0.223376 0.107024" size="0.08317650854587555 0.00783295463770628 0.018378378823399544" quat="0.9986017346382141 0.0 -0.0 -0.05286400392651558"/>
          <geom class="collision" type="box" pos="0.242344 -0.211464 0.107024" size="0.011957220733165741 0.013877608813345432 0.018470652401447296" quat="1.0 0.0 0.0 0.0"/>
          <geom class="collision" type="box" pos="-0.236296 -0.211087 0.107024" size="0.01195722445845604 0.013877608813345432 0.018470652401447296" quat="1.0 0.0 0.0 0.0"/>
          <body name="Door001_Clear">
            <geom mesh="Door001_Clear_vis" type="mesh" solimp="0.998 0.998 0.001" solref="0.001 1" friction="0.95 0.3 0.1" class="visual" material="Door001_Clear_material"/>
          </body>
        </body>
        <body name="Knob001">
          <joint axis="0.0 1.0 0.0" pos="-0.189668 -0.209612 0.219696" limited="true" name="Knob001_joint" range="0.0 4.71238898038469" type="hinge" damping="0.05" armature="0.001" springref="-0.01"/>
          <geom mesh="Knob001_vis" type="mesh" solimp="0.998 0.998 0.001" solref="0.001 1" friction="0.95 0.3 0.1" class="visual" material="Knob001_material"/>
          <geom class="collision" type="cylinder" pos="-0.189556 -0.205166 0.220154" size="0.03125251829624176 0.0081293024122715" quat="0.7071067094802856 0.7071068286895752 -1.5700929612083792e-16 2.2148510003422914e-23"/>
          <geom class="collision" type="box" pos="-0.190357 -0.218785 0.219061" size="0.00964608695358038 0.006053298246115446 0.027127230539917946" quat="1.0 0.0 0.0 0.0"/>
        </body>
        <body name="Knob002">
          <joint axis="0.0 1.0 0.0" pos="-0.062747 -0.209612 0.220585" limited="true" name="Knob002_joint" range="0.0 4.71238898038469" type="hinge" damping="0.05" armature="0.001" springref="-0.01"/>
          <geom mesh="Knob002_vis" type="mesh" solimp="0.998 0.998 0.001" solref="0.001 1" friction="0.95 0.3 0.1" class="visual" material="Knob002_material"/>
          <geom class="collision" type="cylinder" pos="-0.063686 -0.205166 0.220154" size="0.03125251829624176 0.0081293024122715" quat="0.7071067094802856 0.7071068286895752 -1.5700929612083792e-16 2.2148510003422914e-23"/>
          <geom class="collision" type="box" pos="-0.063698 -0.218785 0.219061" size="0.00964608695358038 0.006053298246115446 0.027127230539917946" quat="1.0 0.0 0.0 0.0"/>
        </body>
        <body name="Knob003">
          <joint axis="0.0 1.0 0.0" pos="0.062656 -0.209612 0.221326" limited="true" name="Knob003_joint" range="-1.5707963267948966 1.5707963267948966" type="hinge" damping="0.05" armature="0.001" springref="-0.01"/>
          <geom mesh="Knob003_vis" type="mesh" solimp="0.998 0.998 0.001" solref="0.001 1" friction="0.95 0.3 0.1" class="visual" material="Knob003_material"/>
          <geom class="collision" type="cylinder" pos="0.064964 -0.205166 0.220154" size="0.03125251829624176 0.0081293024122715" quat="0.7071067094802856 0.7071068286895752 -1.5700929612083792e-16 2.2148510003422914e-23"/>
          <geom class="collision" type="box" pos="0.061837 -0.218785 0.219061" size="0.00964608695358038 0.006053298246115446 0.027127230539917946" quat="1.0 0.0 0.0 0.0"/>
        </body>
        <body name="Knob004">
          <joint axis="0.0 1.0 0.0" pos="0.190466 -0.209612 0.221326" limited="true" name="Knob004_joint" range="0.0 4.71238898038469" type="hinge" damping="0.05" armature="0.001" springref="-0.01"/>
          <geom mesh="Knob004_vis" type="mesh" solimp="0.998 0.998 0.001" solref="0.001 1" friction="0.95 0.3 0.1" class="visual" material="Knob004_material"/>
          <geom class="collision" type="cylinder" pos="0.190835 -0.205166 0.220154" size="0.03125251829624176 0.0081293024122715" quat="0.7071067094802856 0.7071068286895752 -1.5700929612083792e-16 2.2148510003422914e-23"/>
          <geom class="collision" type="box" pos="0.189570 -0.218785 0.219061" size="0.00964608695358038 0.006053298246115446 0.027127230539917946" quat="1.0 0.0 0.0 0.0"/>
        </body>
        <body name="Shelf001">
          <joint axis="0.0 -1.0 0.0" pos="-0.001159 0.042269 -0.024239" limited="true" name="Shelf001_joint" range="0.0 0.3" type="slide" damping="1" frictionloss="1" armature=".01" stiffness="0.05"/>
          <geom mesh="Shelf001_vis" type="mesh" solimp="0.998 0.998 0.001" solref="0.001 1" friction="0.95 0.3 0.1" class="visual" material="Shelf001_material"/>
          <geom class="collision" type="box" pos="-0.000387 0.031700 -0.033248" size="0.2308759093284607 0.17696762084960938 0.0045929416082799435" quat="1.0 0.0 0.0 0.0"/>
          <geom class="collision" type="box" pos="0.237437 0.031700 -0.019786" size="0.020615795627236366 0.17696762084960938 0.004592908546328545" quat="0.8788831830024719 5.922530176650847e-15 -0.4770370125770569 1.6328288054978657e-08"/>
          <geom class="collision" type="box" pos="0.259033 0.031700 -0.006114" size="0.014445713721215725 0.1769687980413437 0.004766328725963831" quat="1.0 0.0 0.0 0.0"/>
          <geom class="collision" type="box" pos="-0.239362 0.031700 -0.019786" size="0.020615795627236366 0.17696762084960938 0.004592908546328545" quat="0.5048431754112244 2.8944284713146654e-14 -0.8632110953330994 2.9546406210556597e-08"/>
          <geom class="collision" type="box" pos="-0.260897 0.031700 -0.005998" size="0.014445713721215725 0.17696872353553772 0.004766328725963831" quat="1.0 0.0 0.0 0.0"/>
        </body>
        <body name="Shelf002">
          <joint axis="0.0 -1.0 0.0" pos="-0.001202 0.042959 -0.174116" limited="true" name="Shelf002_joint" range="0.0 0.3" type="slide" damping="1" frictionloss="1" armature=".01" stiffness="0.05"/>
          <geom mesh="Shelf002_vis" type="mesh" solimp="0.998 0.998 0.001" solref="0.001 1" friction="0.95 0.3 0.1" class="visual" material="Shelf002_material"/>
          <geom class="collision" type="box" pos="-0.000387 0.031700 -0.182818" size="0.2308759093284607 0.17696762084960938 0.004592934623360634" quat="1.0 0.0 0.0 0.0"/>
          <geom class="collision" type="box" pos="0.237437 0.031700 -0.171619" size="0.020615795627236366 0.17696762084960938 0.004592908546328545" quat="0.8788831830024719 5.922530176650847e-15 -0.4770370125770569 1.6328288054978657e-08"/>
          <geom class="collision" type="box" pos="0.259033 0.031700 -0.156446" size="0.014445713721215725 0.1769685447216034 0.003265595529228449" quat="1.0 0.0 0.0 0.0"/>
          <geom class="collision" type="box" pos="-0.239362 0.031700 -0.171619" size="0.020615795627236366 0.17696762084960938 0.004592908546328545" quat="0.5048431754112244 2.8944284713146654e-14 -0.8632110953330994 2.9546406210556597e-08"/>
          <geom class="collision" type="box" pos="-0.260897 0.031700 -0.156210" size="0.014445713721215725 0.17696847021579742 0.0031455443240702152" quat="1.0 0.0 0.0 0.0"/>
        </body>
        <geom class="region" name="reg_int" type="box" pos="0.00221650000000001 0.0273095 0.03838949999999999" size="0.2783385 0.2010055 0.2548055"/>
        <geom class="region" name="reg_main" type="box" pos="0.0001644999999999841 0.022880499999999998 -1.000000000001e-06" size="0.3165375 0.2203805 0.307168"/>
      </body>
    </body>
  </worldbody>
  <actuator>
    <motor name="Door001_joint_actuator" joint="Door001_joint" gear="50"/>
    <motor name="Knob001_joint_actuator" joint="Knob001_joint" gear="50"/>
    <motor name="Knob002_joint_actuator" joint="Knob002_joint" gear="50"/>
    <motor name="Knob003_joint_actuator" joint="Knob003_joint" gear="50"/>
    <motor name="Knob004_joint_actuator" joint="Knob004_joint" gear="50"/>
    <motor name="Shelf001_joint_actuator" joint="Shelf001_joint" gear="50"/>
    <motor name="Shelf002_joint_actuator" joint="Shelf002_joint" gear="50"/>
  </actuator>
</mujoco>
