<?xml version='1.0' encoding='UTF-8'?>
<mujoco model="model">
  <option timestep="0.002" gravity="0.0 0.0 -9.81"/>
  <compiler angle="radian"/>
  <asset>
    <mesh file="visuals/Body001.obj" name="Body001_vis"/>
    <mesh file="visuals/Door001.obj" name="Door001_vis"/>
    <mesh file="visuals/Door001_Clear.obj" name="Door001_Clear_vis"/>
    <mesh file="visuals/Knob001.obj" name="Knob001_vis"/>
    <mesh file="visuals/Knob002.obj" name="Knob002_vis"/>
    <mesh file="visuals/Shelf001.obj" name="Shelf001_vis"/>
    <texture file="visuals/T_BC001.png" name="Body001_material" type="2d"/>
    <material name="Body001_material" rgba="1 1 1 1.0" texture="Body001_material" shininess="1" specular="1"/>
    <texture file="visuals/T_BC001.png" name="Door001_material" type="2d"/>
    <material name="Door001_material" rgba="1 1 1 1.0" texture="Door001_material" shininess="0.2512328028678894" specular="0.3103448502657381"/>
    <material name="Door001_Clear_material" rgba="0.027718450874090195 0.027718450874090195 0.027718450874090195 0.75" shininess="0.2512328028678894" specular="0.3103448502657381"/>
    <texture file="visuals/T_BC001.png" name="Knob001_material" type="2d"/>
    <material name="Knob001_material" rgba="1 1 1 1.0" texture="Knob001_material" shininess="2" specular="2"/>
    <texture file="visuals/T_BC001.png" name="Knob002_material" type="2d"/>
    <material name="Knob002_material" rgba="1 1 1 1.0" texture="Knob002_material" shininess="2" specular="2"/>
    <texture file="visuals/T_BC001.png" name="Shelf001_material" type="2d"/>
    <material name="Shelf001_material" rgba="1 1 1 1.0" texture="Shelf001_material" shininess="15" specular="15"/>
  </asset>
  <default>
    <default class="visual">
      <geom conaffinity="0" contype="0" group="1" type="mesh"/>
    </default>
    <default class="collision">
      <geom group="0" rgba="0.5 0 0 0.5"/>
    </default>
    <default class="spawn">
      <geom group="0" rgba="1 1 1 0.5" contype="0" conaffinity="0"/>
      <site group="0" rgba="1 1 1 0.5"/>
    </default>
    <default class="region">
      <geom group="1" conaffinity="0" contype="0" rgba="0 1 0 0"/>
    </default>
  </default>
  <worldbody>
    <body>
      <body name="object">
        <geom mesh="Body001_vis" type="mesh" solimp="0.998 0.998 0.001" solref="0.001 1" friction="0.95 0.3 0.1" class="visual" material="Body001_material"/>
        <geom class="collision" type="box" pos="-0.038459669798612595 0.03006037324666977 -0.018339481204748154" size="0.1945507973432541 0.17155130207538605 0.002026360249146819" quat="1.0 0.0 0.0 0.0" density="1000.0"/>
        <geom class="collision" type="box" pos="-0.0007457605679519475 0.22536176443099976 0.013563407585024834" size="0.25858113169670105 0.005080300383269787 0.1686781346797943" quat="1.0 0.0 0.0 0.0" density="1000.0"/>
        <geom class="collision" type="box" pos="-0.0007457605679519475 0.024854116141796112 0.17399555444717407" size="0.25858113169670105 0.19542735815048218 0.008245944045484066" quat="1.0 0.0 0.0 0.0" density="1000.0"/>
        <geom class="collision" type="box" pos="-0.25257155299186707 0.024854116141796112 0.0056472220458090305" size="0.006755355279892683 0.19542735815048218 0.16010236740112305" quat="1.0 0.0 0.0 0.0" density="1000.0"/>
        <geom class="collision" type="box" pos="0.006009556353092194 0.02679711952805519 -0.14971891045570374" size="0.25182580947875977 0.1934843510389328 0.00789948832243681" quat="1.0 0.0 0.0 0.0" density="1000.0"/>
        <geom class="collision" type="box" pos="0.21715101599693298 0.024601221084594727 0.005647222977131605" size="0.041074566543102264 0.19568024575710297 0.16010236740112305" quat="1.0 0.0 0.0 0.0" density="1000.0"/>
        <geom class="collision" type="box" pos="-0.24223238229751587 0.031555432826280594 0.0056472220458090305" size="0.006755355279892683 0.1887260526418686 0.16010236740112305" quat="1.0 0.0 0.0 0.0" density="1000.0"/>
        <geom class="collision" type="box" pos="0.17393207550048828 0.031555432826280594 0.0056472220458090305" size="0.014827726408839226 0.1887260526418686 0.16010236740112305" quat="1.0 0.0 0.0 0.0" density="1000.0"/>
        <geom class="collision" type="box" pos="-0.03818636015057564 0.031555403023958206 0.16610950231552124" size="0.006755355279892683 0.1887260526418686 0.20359595119953156" quat="0.7071068286895752 -4.750302551315144e-08 0.7071067094802856 4.7503014855010406e-08" density="1000.0"/>
        <geom class="collision" type="box" pos="-0.03818632289767265 0.03155545890331268 -0.14332428574562073" size="0.010608116164803505 0.1887260526418686 0.20359595119953156" quat="0.7071068286895752 -4.750302551315144e-08 0.7071067094802856 4.7503014855010406e-08" density="1000.0"/>
        <geom class="collision" type="box" pos="-0.2320302426815033 -0.0837954431772232 0.008008696138858795" size="0.005274172406643629 0.04465195909142494 0.01684456877410412" quat="1.0 0.0 0.0 0.0" density="1000.0"/>
        <geom class="collision" type="box" pos="-0.2320302426815033 0.15107284486293793 0.008008696138858795" size="0.005274172406643629 0.04465195909142494 0.01684456877410412" quat="1.0 0.0 0.0 0.0" density="1000.0"/>
        <geom class="collision" type="box" pos="-0.2320302426815033 -0.0837954431772232 0.052791304886341095" size="0.005274172406643629 0.04465195909142494 0.01684456877410412" quat="1.0 0.0 0.0 0.0" density="1000.0"/>
        <geom class="collision" type="box" pos="-0.2320302426815033 0.15107284486293793 0.052791304886341095" size="0.005274172406643629 0.04465195909142494 0.01684456877410412" quat="1.0 0.0 0.0 0.0" density="1000.0"/>
        <geom class="collision" type="box" pos="-0.2320302426815033 -0.07709218561649323 0.09709606319665909" size="0.005274171940982342 0.035627953708171844 0.01684456877410412" quat="1.0 0.0 0.0 0.0" density="1000.0"/>
        <geom class="collision" type="box" pos="-0.2320302426815033 0.13946612179279327 0.09709606319665909" size="0.005274171940982342 0.03220980614423752 0.01684456877410412" quat="1.0 0.0 0.0 0.0" density="1000.0"/>
        <geom class="collision" type="box" pos="-0.2320302426815033 0.15107284486293793 -0.04028761386871338" size="0.005274172406643629 0.04465195909142494 0.01684456877410412" quat="7.549790126404332e-08 -1.0 -2.220446049250313e-16 -3.8083412071160693e-31" density="1000.0"/>
        <geom class="collision" type="box" pos="-0.2320302426815033 -0.0837954431772232 -0.04028765857219696" size="0.005274172406643629 0.04465195909142494 0.01684456877410412" quat="7.549790126404332e-08 -1.0 -2.220446049250313e-16 -3.8083412071160693e-31" density="1000.0"/>
        <geom class="collision" type="box" pos="-0.2320302426815033 0.14436958730220795 -0.08459237962961197" size="0.005274171940982342 0.035627953708171844 0.01684456877410412" quat="7.549790126404332e-08 -1.0 -2.220446049250313e-16 -3.8083412071160693e-31" density="1000.0"/>
        <geom class="collision" type="box" pos="-0.2320302426815033 -0.07218872010707855 -0.08459240943193436" size="0.005274171940982342 0.03220980614423752 0.01684456877410412" quat="7.549790126404332e-08 -1.0 -2.220446049250313e-16 -3.8083412071160693e-31" density="1000.0"/>
        <geom class="collision" type="box" pos="0.15681472420692444 -0.0837954431772232 0.008008696138858795" size="0.005274172406643629 0.04465195909142494 0.01684456877410412" quat="1.0 0.0 0.0 0.0" density="1000.0"/>
        <geom class="collision" type="box" pos="0.15681472420692444 0.15107284486293793 0.008008696138858795" size="0.005274172406643629 0.04465195909142494 0.01684456877410412" quat="1.0 0.0 0.0 0.0" density="1000.0"/>
        <geom class="collision" type="box" pos="0.15681472420692444 -0.0837954431772232 0.052791304886341095" size="0.005274172406643629 0.04465195909142494 0.01684456877410412" quat="1.0 0.0 0.0 0.0" density="1000.0"/>
        <geom class="collision" type="box" pos="0.15681472420692444 0.15107284486293793 0.052791304886341095" size="0.005274172406643629 0.04465195909142494 0.01684456877410412" quat="1.0 0.0 0.0 0.0" density="1000.0"/>
        <geom class="collision" type="box" pos="0.15681472420692444 -0.07709218561649323 0.09709606319665909" size="0.005274171940982342 0.035627953708171844 0.01684456877410412" quat="1.0 0.0 0.0 0.0" density="1000.0"/>
        <geom class="collision" type="box" pos="0.15681472420692444 0.13946612179279327 0.09709606319665909" size="0.005274171940982342 0.03220980614423752 0.01684456877410412" quat="1.0 0.0 0.0 0.0" density="1000.0"/>
        <geom class="collision" type="box" pos="0.15681472420692444 0.15107284486293793 -0.04028761386871338" size="0.005274172406643629 0.04465195909142494 0.01684456877410412" quat="7.549790126404332e-08 -1.0 -2.220446049250313e-16 -3.8083412071160693e-31" density="1000.0"/>
        <geom class="collision" type="box" pos="0.15681472420692444 -0.0837954431772232 -0.04028765857219696" size="0.005274172406643629 0.04465195909142494 0.01684456877410412" quat="7.549790126404332e-08 -1.0 -2.220446049250313e-16 -3.8083412071160693e-31" density="1000.0"/>
        <geom class="collision" type="box" pos="0.15681472420692444 0.14436958730220795 -0.08459237962961197" size="0.005274171940982342 0.035627953708171844 0.01684456877410412" quat="7.549790126404332e-08 -1.0 -2.220446049250313e-16 -3.8083412071160693e-31" density="1000.0"/>
        <geom class="collision" type="box" pos="0.15681472420692444 -0.07218872010707855 -0.08459240943193436" size="0.005274171940982342 0.03220980614423752 0.01684456877410412" quat="7.549790126404332e-08 -1.0 -2.220446049250313e-16 -3.8083412071160693e-31" density="1000.0"/>
        <geom class="collision" type="cylinder" pos="0.23314112424850464 -0.13210473954677582 -0.16843681037425995" size="0.01263634953647852 0.01263634953647852" quat="1.0 0.0 0.0 0.0" density="1000.0"/>
        <geom class="collision" type="cylinder" pos="0.23314112424850464 0.19582204520702362 -0.16843681037425995" size="0.01263634953647852 0.01263634953647852" quat="1.0 0.0 0.0 0.0" density="1000.0"/>
        <geom class="collision" type="cylinder" pos="-0.23202680051326752 -0.13210473954677582 -0.16843681037425995" size="0.01263634953647852 0.01263634953647852" quat="1.0 0.0 0.0 0.0" density="1000.0"/>
        <geom class="collision" type="cylinder" pos="-0.23202680051326752 0.19582204520702362 -0.16843681037425995" size="0.01263634953647852 0.01263634953647852" quat="1.0 0.0 0.0 0.0" density="1000.0"/>
        <body name="Door001">
          <joint axis="1.0 0.0 0.0" pos="-0.03550801798701286 -0.16757157444953918 -0.1321888566017151" limited="true" name="Door001_joint" range="0.0 1.5707963267948966" type="hinge" damping="1" frictionloss="1" armature=".01" stiffness="1" springref="-1"/>
          <geom mesh="Door001_vis" type="mesh" solimp="0.998 0.998 0.001" solref="0.001 1" friction="0.95 0.3 0.1" class="visual" material="Door001_material"/>
          <geom class="collision" type="box" pos="-0.035529397428035736 -0.17870929837226868 0.14865490794181824" size="0.20355772972106934 0.005889417137950659 0.012151091359555721" quat="1.0 0.0 0.0 0.0" density="1000.0"/>
          <geom class="collision" type="box" pos="-0.035529397428035736 -0.1645747274160385 -0.11987551301717758" size="0.20355837047100067 0.0039117601700127125 0.010819010436534882" quat="1.0 0.0 0.0 0.0" density="1000.0"/>
          <geom class="collision" type="box" pos="0.157125785946846 -0.1602473258972168 0.013051370158791542" size="0.010897890664637089 0.00302733457647264 0.12345529347658157" quat="1.0 0.0 0.0 0.0" density="1000.0"/>
          <geom class="collision" type="box" pos="-0.22930143773555756 -0.16048060357570648 0.013342132791876793" size="0.010897873900830746 0.0032606085296720266 0.12316428124904633" quat="1.0 0.0 0.0 0.0" density="1000.0"/>
          <geom class="collision" type="box" pos="-0.21602213382720947 -0.19494229555130005 0.14781418442726135" size="0.012606588192284107 0.01035165973007679 0.010810812935233116" quat="1.0 0.0 0.0 0.0" density="1000.0"/>
          <geom class="collision" type="box" pos="0.14512749016284943 -0.19494229555130005 0.14781418442726135" size="0.012606557458639145 0.010351643897593021 0.010810798034071922" quat="1.0 0.0 0.0 0.0" density="1000.0"/>
          <geom class="collision" type="box" pos="0.06947321444749832 -0.21327179670333862 0.14781418442726135" size="0.06452859193086624 0.010351533070206642 0.010810687206685543" quat="0.9969000220298767 0.0 0.0 0.07867899537086487" density="1000.0"/>
          <geom class="collision" type="box" pos="-0.14008602499961853 -0.2123119831085205 0.14781418442726135" size="0.06452859193086624 0.010351533070206642 0.010810687206685543" quat="0.9969000220298767 0.0 -0.0 -0.07867901772260666" density="1000.0"/>
          <geom class="collision" type="box" pos="-0.035306405276060104 -0.21971465647220612 0.14781418442726135" size="0.04197297990322113 0.010351628996431828 0.010810782201588154" quat="1.0 0.0 0.0 0.0" density="1000.0"/>
          <body name="Door001_Clear">
            <geom mesh="Door001_Clear_vis" type="mesh" solimp="0.998 0.998 0.001" solref="0.001 1" friction="0.95 0.3 0.1" class="visual" material="Door001_Clear_material"/>
            <geom class="collision" type="box" pos="-0.035523295402526855 -0.16724194586277008 0.012841787189245224" size="0.20578330755233765 0.001694351900368929 0.12130924314260483" quat="1.0 0.0 0.0 0.0" density="1000.0"/>
          </body>
        </body>
        <body name="Knob001">
          <joint axis="0.0 1.0 0.0" pos="0.21950900554656982 -0.18041422963142395 0.05478488653898239" limited="true" name="Knob001_joint" range="0.0 4.799655442984406" type="hinge" damping="0.05" armature="0.001"/>
          <geom mesh="Knob001_vis" type="mesh" solimp="0.998 0.998 0.001" solref="0.001 1" friction="0.95 0.3 0.1" class="visual" material="Knob001_material"/>
          <geom class="collision" type="cylinder" pos="0.21832531690597534 -0.1762993186712265 0.0544036328792572" size="0.02282606065273285 0.0021433064248412848" quat="0.7071067094802856 0.7071068286895752 0.0 0.0" density="1000.0"/>
          <geom class="collision" type="box" pos="0.21892495453357697 -0.18578949570655823 0.05496831238269806" size="0.006072560325264931 0.007540433201938868 0.019012343138456345" quat="1.0 0.0 0.0 0.0" density="1000.0"/>
        </body>
        <body name="Knob002">
          <joint axis="0.0 1.0 0.0" pos="0.21945226192474365 -0.18017637729644775 -0.050140537321567535" limited="true" name="Knob002_joint" range="0.0 4.014257279586958" type="hinge" damping="0.05" armature="0.001"/>
          <geom mesh="Knob002_vis" type="mesh" solimp="0.998 0.998 0.001" solref="0.001 1" friction="0.95 0.3 0.1" class="visual" material="Knob002_material"/>
          <geom class="collision" type="cylinder" pos="0.21832531690597534 -0.1762993186712265 -0.050196513533592224" size="0.02282606065273285 0.0021433064248412848" quat="0.7071067094802856 0.7071068286895752 0.0 0.0" density="1000.0"/>
          <geom class="collision" type="box" pos="0.21892495453357697 -0.18578949570655823 -0.0496320016682148" size="0.006072559859603643 0.007540433201938868 0.018874872475862503" quat="1.0 0.0 0.0 0.0" density="1000.0"/>
        </body>
        <body name="Shelf001">
          <joint axis="0.0 -1.0 0.0" pos="-0.037293076515197754 0.028795551508665085 -0.017761364579200745" limited="true" name="Shelf001_joint" range="0.0 0.25" type="slide" damping="1" frictionloss="1" armature=".01" stiffness="0.05"/>
          <geom mesh="Shelf001_vis" type="mesh" solimp="0.998 0.998 0.001" solref="0.001 1" friction="0.95 0.3 0.1" class="visual" material="Shelf001_material"/>
        </body>
        <geom class="region" name="reg_int" type="box" pos="-0.038324251770973206 0.032928816974163055 0.013854213058948517" size="0.1974797397851944 0.1889384612441063 0.14760901778936386"/>
        <geom class="region" name="reg_main" type="box" pos="0.0 0.029098711907863617 0.0" size="0.25932687520980835 0.20134538412094116 0.1822415292263031"/>
      </body>
    </body>
  </worldbody>
  <actuator>
    <motor name="Door001_joint_actuator" joint="Door001_joint" gear="30"/>
    <motor name="Knob001_joint_actuator" joint="Knob001_joint" gear="10"/>
    <motor name="Knob002_joint_actuator" joint="Knob002_joint" gear="10"/>
    <motor name="Shelf001_joint_actuator" joint="Shelf001_joint" gear="10"/>
  </actuator>
</mujoco>
