<mujoco model="model">
  <compiler angle="radian"/>
  <asset>
    <mesh file="visuals/handle.obj" name="handle_vis"/>
    <mesh file="visuals/Body001.obj" name="Body001_vis"/>
    <mesh file="visuals/Funnel001.obj" name="Funnel001_vis"/>
    <mesh file="visuals/spout.obj" name="spout_vis"/>
    <texture file="visuals/T_BC001.png" name="Body001_material" type="2d"/>
    <material name="Body001_material" rgba="1 1 1 1.0" texture="Body001_material" shininess="0.4472135901451111" specular="0.3103448502657381"/>
    <texture file="visuals/T_BC001.png" name="handle_material" type="2d"/>
    <material name="handle_material" rgba="1 1 1 1.0" texture="handle_material" shininess="0.4472135901451111" specular="0.3103448502657381"/>
    <texture file="visuals/T_BC001.png" name="Funnel001_material" type="2d"/>
    <material name="Funnel001_material" rgba="1 1 1 1.0" texture="Funnel001_material" shininess="0.4472135901451111" specular="0.3103448502657381"/>
    <texture file="visuals/T_BC001.png" name="spout_material" type="2d"/>
    <material name="spout_material" rgba="1 1 1 1.0" texture="spout_material" shininess="0.4472135901451111" specular="0.3103448502657381"/>
  </asset>
  <default>
    <default class="visual">
      <geom conaffinity="0" contype="0" group="1" type="mesh"/>
    </default>
    <default class="collision">
      <geom group="0" rgba="0.5 0 0 0.5"/>
    </default>
    <default class="spawn">
      <geom group="0" rgba="1 1 1 0.5" contype="0" conaffinity="0"/>
      <site group="0" rgba="1 1 1 0.5"/>
    </default>
    <default class="region">
      <geom group="1" conaffinity="0" contype="0" rgba="0 1 0 0"/>
    </default>
  </default>
  <worldbody>
    <body>
      <body name="object">
        <geom mesh="Body001_vis" type="mesh" solimp="0.998 0.998 0.001" solref="0.001 1" density="100" friction="0.95 0.3 0.1" class="visual" material="Body001_material"/>
        <geom class="collision" type="box" pos="1.4057150110602379e-08 -0.16959254443645477 -0.13596001267433167" size="0.27581730484962463 0.01626265048980713 0.07840858399868011" quat="1.0 0.0 0.0 0.0"/>
        <geom class="collision" type="box" pos="-0.2598166763782501 -0.00048828125 -0.13596001267433167" size="0.016000591218471527 0.1563325673341751 0.07840858399868011" quat="1.0 0.0 0.0 0.0"/>
        <geom class="collision" type="box" pos="1.4057150110602379e-08 0.16901056468486786 -0.13596001267433167" size="0.27581730484962463 0.016844628378748894 0.07840858399868011" quat="1.0 0.0 0.0 0.0"/>
        <geom class="collision" type="box" pos="-0.15590538084506989 0.137120321393013 -0.13596001267433167" size="0.09381996095180511 0.017615949735045433 0.07840858399868011" quat="1.0 0.0 0.0 0.0"/>
        <geom class="collision" type="box" pos="0.0037353523075580597 0.15152469277381897 -0.13596001267433167" size="0.08369666337966919 0.01544155739247799 0.07840858399868011" quat="0.9960950613021851 0.0 0.0 0.08828743547201157"/>
        <geom class="collision" type="box" pos="0.25998401641845703 -0.00048828125 -0.13596001267433167" size="0.015833253040909767 0.1563325673341751 0.07840857654809952" quat="1.0 0.0 0.0 0.0"/>
        <geom class="collision" type="box" pos="-0.2439178228378296 0.12083550542593002 -0.13596001267433167" size="0.014547471888363361 0.011633210815489292 0.07840857654809952" quat="0.9380559325218201 0.0 0.0 0.34648385643959045"/>
        <geom class="collision" type="box" pos="-0.23990249633789062 -0.14929364621639252 -0.13596001267433167" size="0.007563177030533552 0.01742745377123356 0.07840858399868011" quat="0.9380559325218201 0.0 0.0 0.34648385643959045"/>
        <geom class="collision" type="box" pos="0.23624864220619202 0.14649027585983276 -0.13596001267433167" size="0.02430211752653122 0.011633211746811867 0.07840857654809952" quat="0.9271064400672913 0.0 0.0 -0.37479814887046814"/>
        <geom class="collision" type="box" pos="0.001804158091545105 0.0025504976511001587 -0.19704565405845642" size="0.24809125065803528 0.15592600405216217 0.017322935163974762" quat="1.0 0.0 0.0 0.0"/>
        <geom class="collision" type="cylinder" pos="-0.030668478459119797 0.15602917969226837 -0.006646901369094849" size="0.01782768778502941 0.037851620465517044" quat="0.7071068286895752 0.0 -0.7071067690849304 0.0"/>
        <geom class="collision" type="cylinder" pos="-0.030807096511125565 0.15602917969226837 -0.023696957156062126" size="0.01782768778502941 0.034247539937496185" quat="1.0 0.0 0.0 0.0"/>
        <body name="handle">
          <joint axis="1.0 0.0 0.0" pos="0.0211646631360054 0.15571454167366028 -0.006675109267234802" limited="true" name="handle_joint_hinge_0" type="hinge" range="-0.7853981633974483 0.7853981633974483" damping="1" frictionloss="1" armature=".01" stiffness="0.01" springref="-0.01"/>
          <joint axis="0.0 1.0 0.0" pos="0.0211646631360054 0.15571454167366028 -0.006675109267234802" limited="true" name="handle_joint_hinge_1" type="hinge" range="0.0 0.17453292519943295" damping="1" frictionloss="1" armature=".01" stiffness="0.05"/>
          <geom mesh="handle_vis" type="mesh" solimp="0.998 0.998 0.001" solref="0.001 1" density="100" friction="0.95 0.3 0.1" class="visual" material="handle_material"/>
          <geom class="collision" type="cylinder" pos="0.023262593895196915 0.15571820735931396 -0.00680498918518424" size="0.01793336682021618 0.00752879586070776" quat="0.7071068286895752 0.0 -0.7071067690849304 0.0"/>
          <geom class="collision" type="cylinder" pos="0.0195927694439888 0.15583795309066772 0.03269347548484802" size="0.004669872112572193 0.023161819204688072" quat="1.0 0.0 0.0 0.0"/>
        </body>
        <body name="Funnel001">
          <joint axis="0.0 0.0 1.0" pos="0.0009632930159568787 0.031146809458732605 -0.17322100698947906" limited="true" name="Funnel001_joint" range="0.0 0.05" type="slide" damping="1" frictionloss="1" armature=".01" stiffness="0.05" springref="-18"/>
          <geom mesh="Funnel001_vis" type="mesh" solimp="0.998 0.998 0.001" solref="0.001 1" density="100" friction="0.95 0.3 0.1" class="visual" material="Funnel001_material"/>
          <geom class="collision" type="cylinder" pos="0.0010033994913101196 0.031286291778087616 -0.17625391483306885" size="0.023134859278798103 0.0028115231543779373" quat="1.0 0.0 0.0 0.0"/>
          <geom class="collision" type="cylinder" pos="0.0010033994913101196 0.031286291778087616 -0.17069317400455475" size="0.005248609464615583 0.00307882996276021" quat="1.0 0.0 0.0 0.0"/>
        </body>
        <body name="spout">
          <joint axis="0.0 0.0 1.0" pos="-0.030478890985250473 0.1558258831501007 0.10708253085613251" limited="true" name="spout_joint" range="-0.7853981633974483 0.7853981633974483" type="hinge" damping="1" frictionloss="1" armature=".01" stiffness="0.01" springref="-0.01"/>
          <site type="cylinder" rgba="0.5 0.75 1 1" size="0.006173485890030861 0.15829496085643768" pos="-0.030343852937221527 0.006556212902069092 -0.026110395789146423" name="water"/>
          <geom mesh="spout_vis" type="mesh" solimp="0.998 0.998 0.001" solref="0.001 1" density="100" friction="0.95 0.3 0.1" class="visual" material="spout_material"/>
          <geom class="collision" type="cylinder" pos="-0.03048618510365486 0.15583795309066772 0.07846492528915405" size="0.008071539923548698 0.06615273654460907" quat="1.0 0.0 0.0 0.0"/>
          <geom class="collision" type="cylinder" pos="-0.03048618510365486 0.14937466382980347 0.16299808025360107" size="0.008071539923548698 0.02138448879122734" quat="0.9780362844467163 0.20843477547168732 0.0 0.0"/>
          <geom class="collision" type="cylinder" pos="-0.03048618510365486 0.12654130160808563 0.19124218821525574" size="0.008071539923548698 0.02138448879122734" quat="0.902644693851471 0.43038657307624817 0.0 0.0"/>
          <geom class="collision" type="cylinder" pos="-0.03048618510365486 0.05284687131643295 0.20033225417137146" size="0.008071539923548698 0.02138448879122734" quat="0.5306106805801392 0.847615659236908 0.0 0.0"/>
          <geom class="collision" type="cylinder" pos="-0.03048618510365486 0.0910467728972435 0.20563477277755737" size="0.008071539923548698 0.02138449065387249" quat="0.7420269846916199 0.6703700423240662 0.0 0.0"/>
          <geom class="collision" type="cylinder" pos="-0.03048618510365486 0.023918822407722473 0.17762872576713562" size="0.008071539923548698 0.02138448879122734" quat="0.32088765501976013 0.947117269039154 0.0 0.0"/>
          <geom class="collision" type="cylinder" pos="-0.03048618510365486 0.009142711758613586 0.14683791995048523" size="0.008071539923548698 0.017457736656069756" quat="0.12741568684577942 0.991849422454834 0.0 0.0"/>
        </body>
        <geom class="region" name="reg_main" type="box" pos="0.0 0.0 -0.13596001267433167" size="0.27581727504730225 0.1858551949262619 0.07840857654809952"/>
        <geom class="region" name="reg_basin" type="box" pos="0.0009905323386192322 -0.017673082649707794 -0.12237532436847687" size="0.23980366438627243 0.1300724521279335 0.05823276937007904"/>
      </body>
    </body>
  </worldbody>
  <actuator>
    <motor name="handle_joint_hinge_0_actuator" joint="handle_joint_hinge_0" gear="10"/>
    <motor name="handle_joint_hinge_1_actuator" joint="handle_joint_hinge_1" gear="10"/>
    <motor name="Funnel001_joint_actuator" joint="Funnel001_joint" gear="10"/>
    <motor name="spout_joint_actuator" joint="spout_joint" gear="10"/>
  </actuator>
</mujoco>
