<?xml version='1.0' encoding='UTF-8'?>
<mujoco model="model">
  <option timestep="0.0005" gravity="0.0 0.0 -9.81"/>
  <compiler angle="radian"/>
  <asset>
    <mesh file="visuals/Blade001.obj" name="Blade001_vis"/>
    <mesh file="visuals/Body001.obj" name="Body001_vis"/>
    <mesh file="visuals/Button001.obj" name="Button001_vis"/>
    <mesh file="visuals/Jug001.obj" name="Jug001_vis"/>
    <mesh file="visuals/Jug001_Clear.obj" name="Jug001_Clear_vis"/>
    <mesh file="visuals/Knob001.obj" name="Knob001_vis"/>
    <mesh file="visuals/Lid001.obj" name="Lid001_vis"/>
    <texture file="visuals/T_BC001.png" name="Body001_material" type="2d"/>
    <material name="Body001_material" rgba="1 1 1 1.0" texture="Body001_material" shininess="0.141421377658844" specular="0.5"/>
    <texture file="visuals/T_BC001.png" name="Button001_material" type="2d"/>
    <material name="Button001_material" rgba="1 1 1 1.0" texture="Button001_material" shininess="0.141421377658844" specular="1"/>
    <texture file="visuals/T_BC001.png" name="Jug001_Clear_material" type="2d"/>
    <material name="Jug001_Clear_material" rgba="1 1 1 0.699999988079071" texture="Jug001_Clear_material" shininess="0.141421377658844" specular="0.3103448502657381"/>
    <texture file="visuals/T_BC001.png" name="Blade001_material" type="2d"/>
    <material name="Blade001_material" rgba="1 1 1 1.0" texture="Blade001_material" shininess="0.141421377658844" specular="5"/>
    <texture file="visuals/T_BC001.png" name="Jug001_material" type="2d"/>
    <material name="Jug001_material" rgba="1 1 1 1.0" texture="Jug001_material" shininess="0.141421377658844" specular="1"/>
    <texture file="visuals/T_BC001.png" name="Lid001_material" type="2d"/>
    <material name="Lid001_material" rgba="1 1 1 1.0" texture="Lid001_material" shininess="0.141421377658844" specular="1"/>
    <texture file="visuals/T_BC001.png" name="Knob001_material" type="2d"/>
    <material name="Knob001_material" rgba="1 1 1 1.0" texture="Knob001_material" shininess="0.141421377658844" specular="1"/>
  </asset>
  <default>
    <default class="visual">
      <geom conaffinity="0" contype="0" group="1" type="mesh"/>
    </default>
    <default class="collision">
      <geom group="0" rgba="0.5 0 0 0.5"/>
    </default>
    <default class="spawn">
      <geom group="0" rgba="1 1 1 0.5" contype="0" conaffinity="0"/>
      <site group="0" rgba="1 1 1 0.5"/>
    </default>
    <default class="region">
      <geom group="1" conaffinity="0" contype="0" rgba="0 1 0 0"/>
    </default>
  </default>
  <worldbody>
    <body>
      <body name="object">
        <geom mesh="Body001_vis" type="mesh" solimp="0.998 0.998 0.001" solref="0.001 1" friction="0.95 0.3 0.1" class="visual" material="Body001_material"/>
        <geom class="collision" type="box" pos="-0.000021 -0.004417 -0.174989" size="0.09426623582839966 0.12018150091171265 0.05047569051384926" quat="1.0 0.0 0.0 0.0" density="1000.0"/>
        <geom class="collision" type="box" pos="-0.000642 -0.065748 -0.121905" size="0.09364525973796844 0.053700391203165054 0.023921413347125053" quat="0.9748296737670898 0.22295093536376953 0.0 0.0" density="1000.0"/>
        <geom class="collision" type="box" pos="0.000181 0.025955 -0.069465" size="0.0737367644906044 0.0752071812748909 0.013908842578530312" quat="1.0 0.0 0.0 0.0" density="1000.0"/>
        <geom class="collision" type="box" pos="-0.000642 0.031699 -0.104046" size="0.09364525973796844 0.08006376773118973 0.02117438241839409" quat="1.0 0.0 0.0 0.0" density="1000.0"/>
        <body name="Button001">
          <joint axis="0.0 0.4999999403953552 -0.8660253882408142" pos="-0.043678 -0.065305 -0.088176" limited="true" name="Button001_joint" range="0.0 0.002" type="slide" damping="1" frictionloss="1" armature=".01" stiffness="0.5" springref="-0.5"/>
          <geom mesh="Button001_vis" type="mesh" solimp="0.998 0.998 0.001" solref="0.001 1" friction="0.95 0.3 0.1" class="visual" material="Button001_material"/>
          <geom class="collision" type="cylinder" pos="-0.043892 -0.066432 -0.086464" size="0.006768199615180492 0.0021915838588029146" quat="0.9639899730682373 0.2659386098384857 -4.0169945262216606e-17 -4.33204661115555e-18" density="1000.0"/>
        </body>
        <body name="Jug001_Clear">
          <geom class="region" name="reg_int" type="box" pos="0.004460499999999999 0.023549 0.10582849999999999" size="0.0410395 0.039783 0.1101075"/>
          <joint axis="0.0 0.0 1.0" pos="0.013737 0.039527 0.080513" limited="true" name="Jug001_Clear_joint" range="0.0 0.05" type="slide" damping="1" frictionloss="1" armature=".01" stiffness="0.05"/>
          <geom mesh="Jug001_Clear_vis" type="mesh" solimp="0.998 0.998 0.001" solref="0.001 1" friction="0.95 0.3 0.1" class="visual" material="Jug001_Clear_material"/>
          <geom class="collision" type="box" pos="-0.000332 -0.037001 0.072717" size="0.05070013180375099 0.006148476153612137 0.1268603503704071" quat="1.0 0.0 0.0 0.0" density="1000.0"/>
          <geom class="collision" type="box" pos="-0.055550 0.023775 0.072717" size="0.0061484710313379765 0.06666272133588791 0.1268603503704071" quat="1.0 0.0 0.0 0.0" density="1000.0"/>
          <geom class="collision" type="box" pos="0.054630 0.023775 0.072717" size="0.0061484710313379765 0.06666272133588791 0.1268603503704071" quat="1.0 0.0 0.0 0.0" density="1000.0"/>
          <geom class="collision" type="box" pos="-0.000332 0.084078 0.072717" size="0.05070013180375099 0.006148476153612137 0.1268603503704071" quat="1.0 0.0 0.0 0.0" density="1000.0"/>
          <geom class="collision" type="box" pos="0.074564 0.106045 0.173134" size="0.008146869018673897 0.014489687979221344 0.01081995852291584" quat="0.9147748947143555 -0.18078604340553284 0.07120805233716965 -0.35416480898857117" density="1000.0"/>
          <geom class="collision" type="box" pos="0.061665 0.092812 0.183201" size="0.008105769753456116 0.012879735790193081 0.01025380939245224" quat="0.9265184998512268 0.0 -0.0 -0.376249223947525" density="1000.0"/>
          <geom class="collision" type="box" pos="0.083431 0.115377 0.155256" size="0.008146869018673897 0.014489687979221344 0.01081995852291584" quat="0.8578605055809021 -0.36547520756721497 0.14268623292446136 -0.33187922835350037" density="1000.0"/>
          <geom class="collision" type="box" pos="0.081761 0.113306 0.103434" size="0.008295845240354538 0.020325474441051483 0.012872149236500263" quat="0.6699399948120117 -0.6485963463783264 0.2521308958530426 -0.2587145268917084" density="1000.0"/>
          <geom class="collision" type="box" pos="0.085916 0.117542 0.133615" size="0.008146869018673897 0.014489687979221344 0.01081995852291584" quat="0.7432904839515686 -0.5630417466163635 0.21907974779605865 -0.2872408926486969" density="1000.0"/>
          <geom class="collision" type="box" pos="0.066383 0.098005 0.064534" size="0.008534789085388184 0.029685476794838905 0.016163652762770653" quat="0.551007866859436 -0.7522546648979187 0.2921375334262848 -0.2125062644481659" density="1000.0"/>
          <geom class="collision" type="box" pos="0.000465 0.023775 -0.030182" size="0.058229099959135056 0.06666272133588791 0.02488800324499607" quat="1.0 0.0 0.0 0.0" density="1000.0"/>
          <body name="Blade001">
            <joint axis="0.0 0.0 1.0" pos="0.002837 0.022113 0.005594" limited="false" name="Blade001_joint" range="0 360" type="hinge" damping="1" frictionloss="1" armature=".01" stiffness="0.05"/>
            <geom mesh="Blade001_vis" type="mesh" solimp="0.998 0.998 0.001" solref="0.001 1" friction="0.95 0.3 0.1" class="visual" material="Blade001_material"/>
            <geom class="collision" type="cylinder" pos="0.002237 0.022239 0.002482" size="0.010992518626153469 0.0019860181491822004" quat="1.0 0.0 0.0 0.0" density="1000.0"/>
            <geom class="collision" type="box" pos="-0.006228 0.037537 0.004608" size="0.004382163751870394 0.009873579256236553 0.0014099429827183485" quat="0.9596688747406006 0.10713987052440643 0.02883859910070896 0.2583118677139282" density="1000.0"/>
            <geom class="collision" type="box" pos="-0.013313 0.049744 0.011198" size="0.004382163751870394 0.006865778472274542 0.0006997823365963995" quat="0.9061315655708313 0.33371978998184204 0.08982662111520767 0.24390141665935516" density="1000.0"/>
            <geom class="collision" type="box" pos="-0.015032 0.021994 0.009918" size="0.002498094690963626 0.003913902677595615 0.00039891761844046414" quat="0.657715380191803 0.2422304004430771 0.246499702334404 0.6693077087402344" density="1000.0"/>
            <geom class="collision" type="box" pos="-0.007445 0.022135 0.005486" size="0.002498094690963626 0.005628528073430061 0.000803751521743834" quat="0.6832320690155029 0.15710075199604034 0.1570800542831421 0.6955854892730713" density="1000.0"/>
            <geom class="collision" type="box" pos="-0.013687 -0.006275 0.011198" size="0.004382163751870394 0.006865778472274542 0.0006997823365963995" quat="0.24510179460048676 0.09026868641376495 0.33360037207603455 0.905807614326477" density="1000.0"/>
            <geom class="collision" type="box" pos="-0.006570 0.005913 0.004608" size="0.004382163751870394 0.009873579256236553 0.0014099429827183485" quat="0.2595832347869873 0.02898053452372551 0.10710156708955765 0.9593257904052734" density="1000.0"/>
            <geom class="collision" type="box" pos="0.021137 0.021731 0.004608" size="0.004382163751870394 0.009873579256236553 0.0014099429827183485" quat="0.7020411491394043 0.07837764918804169 -0.07853382080793381 -0.7034398317337036" density="1000.0"/>
            <geom class="collision" type="box" pos="0.035251 0.021703 0.011198" size="0.004382163751870394 0.006865778472274542 0.0006997823365963995" quat="0.6628762483596802 0.24413099884986877 -0.24461738765239716 -0.6641968488693237" density="1000.0"/>
            <geom class="collision" type="box" pos="0.009187 0.011806 0.005839" size="0.0024980942253023386 0.005628528073430061 0.000803751521743834" quat="0.26403868198394775 0.05822960287332535 -0.21439240872859955 -0.9385780692100525" density="1000.0"/>
            <geom class="collision" type="box" pos="0.013147 0.005333 0.010271" size="0.0024980942253023386 0.003913902677595615 0.00039891761844046414" quat="0.2539174556732178 0.09351541101932526 -0.33270493149757385 -0.903376042842865" density="1000.0"/>
            <geom class="collision" type="box" pos="0.012844 0.038601 0.010032" size="0.0024980944581329823 0.003913902677595615 0.00039891761844046414" quat="0.9036177396774292 0.3327938914299011 -0.09319815039634705 -0.25305595993995667" density="1000.0"/>
            <geom class="collision" type="box" pos="0.008910 0.032112 0.005600" size="0.0024980942253023386 0.005628528073430061 0.0008037514635361731" quat="0.9389471411705017 0.21339333057403564 -0.06179073452949524 -0.2627231776714325" density="1000.0"/>
          </body>
          <body name="Jug001">
            <geom mesh="Jug001_vis" type="mesh" solimp="0.998 0.998 0.001" solref="0.001 1" friction="0.95 0.3 0.1" class="visual" material="Jug001_material"/>
            <geom class="collision" type="box" pos="-0.000250 0.023589 -0.027340" size="0.053218137472867966 0.05842722952365875 0.02310650795698166" quat="1.0 0.0 0.0 0.0" density="1000.0"/>
            <geom class="collision" type="cylinder" pos="0.002936 0.021580 -0.003029" size="0.03135425224900246 0.0020198319107294083" quat="1.0 0.0 0.0 0.0" density="1000.0"/>
          </body>
          <body name="Lid001">
            <joint axis="0.0 0.0 1.0" pos="0.009085 0.033017 0.207958" limited="true" name="Lid001_joint" range="0.0 0.05" type="slide" damping="1" frictionloss="1" armature=".01" stiffness="0.05"/>
            <geom mesh="Lid001_vis" type="mesh" solimp="0.998 0.998 0.001" solref="0.001 1" friction="0.95 0.3 0.1" class="visual" material="Lid001_material"/>
            <geom class="collision" type="box" pos="0.071727 0.098670 0.212369" size="0.004358070436865091 0.014879566617310047 0.011254552751779556" quat="0.9234328269958496 0.0 -0.0 -0.38376015424728394" density="1000.0"/>
            <geom class="collision" type="box" pos="-0.000295 0.023566 0.212972" size="0.06565457582473755 0.06871627271175385 0.010651204735040665" quat="1.0 0.0 0.0 0.0" density="1000.0"/>
          </body>
        </body>
        <body name="Knob001">
          <joint axis="0.0 0.5 -0.8660253882408142" pos="0.000318 -0.094622 -0.094189" limited="true" name="Knob001_joint" range="0.0 3.141592653589793" type="hinge" damping="0.05" armature="0.001"/>
          <geom mesh="Knob001_vis" type="mesh" solimp="0.998 0.998 0.001" solref="0.001 1" friction="0.95 0.3 0.1" class="visual" material="Knob001_material"/>
          <geom class="collision" type="cylinder" pos="0.000413 -0.091335 -0.099543" size="0.022349528968334198 0.004747109953314066" quat="0.9639899730682373 0.2659386098384857 -4.0169945262216606e-17 -4.33204661115555e-18" density="1000.0"/>
          <geom class="collision" type="box" pos="0.000668 -0.096414 -0.090383" size="0.005063396412879229 0.017123965546488762 0.009264831431210041" quat="0.6668792963027954 0.21136312186717987 0.17960307002067566 -0.6916215419769287" density="1000.0"/>
        </body>
        <geom class="region" name="reg_main" type="box" pos="1.000000000001e-06 -0.004121 6.0000000000060005e-06" size="0.094212 0.119736 0.225516"/>
      </body>
    </body>
  </worldbody>
  <actuator>
    <motor name="Button001_joint_actuator" joint="Button001_joint" gear="0.2"/>
    <motor name="Jug001_Clear_joint_actuator" joint="Jug001_Clear_joint" gear="100"/>
    <motor name="Knob001_joint_actuator" joint="Knob001_joint" gear="10"/>
    <motor name="Blade001_joint_actuator" joint="Blade001_joint" gear="10"/>
    <motor name="Lid001_joint_actuator" joint="Lid001_joint" gear="15"/>
  </actuator>
</mujoco>
