<mujoco model="model">
  <asset>
    <texture file="visuals/material_0.png" name="tex-model" type="2d"/>
    <texture type="2d" name="image0" file="visuals/image0.png"/>
    <material name="model" reflectance="0.5" texrepeat="1 1" texture="tex-model" texuniform="false"/>
    <material name="Stove" texture="image0" specular="0.5" shininess="0.25"/>
    <mesh file="visuals/model_0.obj" name="model_0_vis" scale="1 1 1"/>
    <mesh file="visuals/knob_rear_right_0.obj" name="knob_rear_right_0_vis" scale="1 1 1"/>
    <mesh file="visuals/knob_front_left_0.obj" name="knob_front_left_0_vis" scale="1 1 1"/>
    <mesh file="visuals/knob_front_right_0.obj" name="knob_front_right_0_vis" scale="1 1 1"/>
    <mesh file="visuals/knob_rear_left_0.obj" name="knob_rear_left_0_vis" scale="1 1 1"/>
  </asset>
  <default>
    <default class="visual">
      <geom conaffinity="0" contype="0" group="1" type="mesh"/>
    </default>
    <default class="collision">
      <geom group="0" rgba="0.5 0 0 0.5"/>
    </default>
  </default>
  <worldbody>
    <body>
      <!-- exterior bounding box points -->
      <site rgba="0 0 0 1" size="0.01" pos="-0.315 -0.275 -0.49" name="ext_p0"/>
      <site rgba="1 0 0 1" size="0.01" pos="0.315 -0.275 -0.49" name="ext_px"/>
      <site rgba="0 1 0 1" size="0.01" pos="-0.315 0.312 -0.49" name="ext_py"/>
      <site rgba="0 0 1 1" size="0.01" pos="-0.315 -0.275 0.295" name="ext_pz"/>
      <!-- interior bounding box points -->
      <site rgba="0.5 0.5 0.5 1" size="0.01" pos="0 0 0" name="int_p0"/>
      <site rgba="1 1 0 1" size="0.01" pos="0 0 0" name="int_px"/>
      <site rgba="0 1 1 1" size="0.01" pos="0 0 0" name="int_py"/>
      <site rgba="1 0 1 1" size="0.01" pos="0 0 0" name="int_pz"/>
      <body name="object">
        <geom solimp="0.998 0.998 0.001" solref="0.001 1" density="100" friction="0.95 0.3 0.1" type="mesh" mesh="model_0_vis" material="Stove" class="visual"/>
        <site name="burner_on_front_left" pos="-0.139 -0.121 0.287" size="0.08 0.0001" rgba="1 0.4 0.4 0.5" type="cylinder"/>
        <site name="burner_on_front_right" pos="0.139 -0.121 0.287" size="0.08 0.0001" rgba="1 0.4 0.4 0.5" type="cylinder"/>
        <site name="burner_on_back_left" pos="-0.139 0.122 0.287" size="0.08 0.0001" rgba="1 0.4 0.4 0.5" type="cylinder"/>
        <site name="burner_on_back_right" pos="0.139 0.122 0.287" size="0.08 0.0001" rgba="1 0.4 0.4 0.5" type="cylinder"/>
        <!-- Main -->
        <geom class="collision" type="box" pos="0 0.017 -0.1" size="0.312 0.292 0.39"/>
        <!-- Oven Handle -->
        <geom class="collision" type="box" pos="0 -0.29 0.21" size="0.24 0.025 0.015"/>
        <!-- Back Display Panel -->
        <geom class="collision" type="box" pos="0 0.295 0.385" size="0.312 0.016 0.12"/>
        <!-- Control Panel -->
        <geom class="collision" type="box" pos="0 0.278 0.43" size="0.312 0.01 0.06" axisangle="1 0 0 -10"/>
        <body name="knob_rear_right">
          <joint axis="0 0.9848 -0.1736" name="knob_rear_right_joint" damping="1" pos="0.254 0.268 0.45"/>
          <geom solimp="0.998 0.998 0.001" solref="0.001 1" density="100" friction="0.95 0.3 0.1" type="mesh" mesh="knob_rear_right_0_vis" material="Stove" class="visual"/>
          <geom class="collision" type="cylinder" pos="0.254 0.268 0.45" size="0.023 0.006 0" axisangle="1 0 0 80"/>
          <geom class="collision" type="box" pos="0.254 0.258 0.452" size="0.0084 0.006 0.0205" axisangle="1 0 0 -10"/>
        </body>
        <body name="knob_front_left">
          <joint axis="0 0.9848 -0.1736" name="knob_front_left_joint" damping="1" pos="-0.172 0.268 0.45"/>
          <geom solimp="0.998 0.998 0.001" solref="0.001 1" density="100" friction="0.95 0.3 0.1" type="mesh" mesh="knob_front_left_0_vis" material="Stove" class="visual"/>
          <geom class="collision" type="cylinder" pos="-0.172 0.268 0.45" size="0.023 0.006 0" axisangle="1 0 0 80"/>
          <geom class="collision" type="box" pos="-0.172 0.258 0.452" size="0.0084 0.006 0.0205" axisangle="1 0 0 -10"/>
        </body>
        <body name="knob_front_right">
          <joint axis="0 0.9848 -0.1736" name="knob_front_right_joint" damping="1" pos="0.172 0.268 0.45"/>
          <geom solimp="0.998 0.998 0.001" solref="0.001 1" density="100" friction="0.95 0.3 0.1" type="mesh" mesh="knob_front_right_0_vis" material="Stove" class="visual"/>
          <geom class="collision" type="cylinder" pos="0.172 0.268 0.45" size="0.023 0.006 0" axisangle="1 0 0 80"/>
          <geom class="collision" type="box" pos="0.172 0.258 0.452" size="0.0084 0.006 0.0205" axisangle="1 0 0 -10"/>
        </body>
        <body name="knob_rear_left">
          <joint axis="0 0.9848 -0.1736" name="knob_rear_left_joint" damping="1" pos="-0.254 0.268 0.45"/>
          <geom solimp="0.998 0.998 0.001" solref="0.001 1" density="100" friction="0.95 0.3 0.1" type="mesh" mesh="knob_rear_left_0_vis" material="Stove" class="visual"/>
          <geom class="collision" type="cylinder" pos="-0.254 0.268 0.45" size="0.023 0.006 0" axisangle="1 0 0 80"/>
          <geom class="collision" type="box" pos="-0.254 0.258 0.452" size="0.0084 0.006 0.0205" axisangle="1 0 0 -10"/>
        </body>
      </body>
    </body>
  </worldbody>
</mujoco>