<mujoco model="model">
  <compiler angle="radian"/>
  <asset>
    <mesh file="visuals/Body001.obj" name="Body001_vis"/>
    <mesh file="visuals/Body001_Clear.obj" name="Body001_Clear_vis"/>
    <mesh file="visuals/Door001.obj" name="Door001_vis"/>
    <mesh file="visuals/Door002.obj" name="Door002_vis"/>
    <mesh file="visuals/Drawer001.obj" name="Drawer001_vis"/>
    <mesh file="visuals/Drawer002.obj" name="Drawer002_vis"/>
    <mesh file="visuals/Drawer003.obj" name="Drawer003_vis"/>
    <mesh file="visuals/Drawer004.obj" name="Drawer004_vis"/>
    <texture file="visuals/T_BC001.png" name="Body001_material" type="2d"/>
    <material name="Body001_material" rgba="1 1 1 1.0" texture="Body001_material" shininess="0.5" specular="0.8"/>
    <texture file="visuals/T_BC001.png" name="Body001_Clear_material" type="2d"/>
    <material name="Body001_Clear_material" rgba="1 1 1 0.5272727012634277" texture="Body001_Clear_material" shininess="0.5" specular="0.8"/>
    <texture file="visuals/T_BC001.png" name="Door001_material" type="2d"/>
    <material name="Door001_material" rgba="1 1 1 1.0" texture="Door001_material" shininess="0.5" specular="0.8"/>
    <texture file="visuals/T_BC001.png" name="Door002_material" type="2d"/>
    <material name="Door002_material" rgba="1 1 1 1.0" texture="Door002_material" shininess="0.5" specular="0.8"/>
    <texture file="visuals/T_BC001.png" name="Drawer001_material" type="2d"/>
    <material name="Drawer001_material" rgba="1 1 1 1.0" texture="Drawer001_material" shininess="0.5" specular="0.8"/>
    <texture file="visuals/T_BC001.png" name="Drawer002_material" type="2d"/>
    <material name="Drawer002_material" rgba="1 1 1 1.0" texture="Drawer002_material" shininess="0.5" specular="0.8"/>
    <texture file="visuals/T_BC001.png" name="Drawer003_material" type="2d"/>
    <material name="Drawer003_material" rgba="1 1 1 1.0" texture="Drawer003_material" shininess="0.5" specular="0.8"/>
    <texture file="visuals/T_BC001.png" name="Drawer004_material" type="2d"/>
    <material name="Drawer004_material" rgba="1 1 1 1.0" texture="Drawer004_material" shininess="0.5" specular="0.8"/>
  </asset>
  <default>
    <default class="visual">
      <geom conaffinity="0" contype="0" group="1" type="mesh"/>
    </default>
    <default class="collision">
      <geom group="0" rgba="0.5 0 0 0.5"/>
    </default>
    <default class="spawn">
      <geom group="0" rgba="1 1 1 0.5" contype="0" conaffinity="0"/>
      <site group="0" rgba="1 1 1 0.5"/>
    </default>
    <default class="region">
      <geom group="1" conaffinity="0" contype="0" rgba="0 1 0 0"/>
    </default>
  </default>
  <worldbody>
    <body>
      <body name="object">
        <geom mesh="Body001_vis" type="mesh" solimp="0.998 0.998 0.001" solref="0.001 1" density="100" friction="0.95 0.3 0.1" class="visual" material="Body001_material"/>
        <geom class="collision" type="box" pos="0.384447 0.039981 0.005188" size="0.035853948444128036 0.322449654340744 0.6934295892715454" quat="1.0 0.0 0.0 0.0"/>
        <geom class="collision" type="box" pos="-0.002146 0.026179 0.760373" size="0.4224463999271393 0.36914530396461487 0.029827851802110672" quat="1.0 0.0 0.0 0.0"/>
        <geom class="collision" type="box" pos="-0.000047 -0.313338 -0.751950" size="0.4249330759048462 0.029750250279903412 0.03825020417571068" quat="1.0 0.0 0.0 0.0"/>
        <geom class="collision" type="box" pos="-0.002146 0.039981 0.713600" size="0.4224463105201721 0.32244962453842163 0.01498262956738472" quat="1.0 0.0 0.0 0.0"/>
        <geom class="collision" type="box" pos="-0.002146 0.039981 -0.737989" size="0.4224463105201721 0.32244962453842163 0.049747247248888016" quat="1.0 0.0 0.0 0.0"/>
        <geom class="collision" type="box" pos="-0.041779 0.042129 0.005596" size="0.018529389053583145 0.32030245661735535 0.6938378810882568" quat="1.0 0.0 0.0 0.0"/>
        <geom class="collision" type="box" pos="-0.390564 0.039981 0.005188" size="0.03402850031852722 0.322449654340744 0.6934296488761902" quat="1.0 0.0 0.0 0.0"/>
        <geom class="collision" type="box" pos="-0.002146 0.058520 0.379201" size="0.38787147402763367 0.27719253301620483 0.009626409038901329" quat="1.0 0.0 0.0 0.0"/>
        <geom class="collision" type="box" pos="-0.002146 0.059233 0.034679" size="0.38787147402763367 0.276479035615921 0.009626412764191628" quat="1.0 0.0 0.0 0.0"/>
        <geom class="collision" type="box" pos="-0.002146 0.056787 -0.292049" size="0.38787147402763367 0.2789252698421478 0.00909482128918171" quat="1.0 0.0 0.0 0.0"/>
        <geom class="collision" type="box" pos="-0.002146 0.351071 0.004949" size="0.4224463105201721 0.0113602876663208 0.6936686038970947" quat="1.0 0.0 0.0 0.0"/>
        <geom class="collision" type="box" pos="-0.005694 0.056787 -0.486730" size="0.3503202795982361 0.2789252698421478 0.0028798189014196396" quat="1.0 0.0 0.0 0.0"/>
        <body name="Body001_Clear">
          <geom mesh="Body001_Clear_vis" type="mesh" solimp="0.998 0.998 0.001" solref="0.001 1" density="100" friction="0.95 0.3 0.1" class="visual" material="Body001_Clear_material"/>
        </body>
        <body name="Door001">
          <joint axis="0.0 0.0 -1.0" pos="-0.396190 -0.327607 0.008800" limited="true" name="Door001_joint" range="0.0 1.5707963267948966" type="hinge" damping="1" frictionloss="1" armature=".01" stiffness="0.05"/>
          <geom mesh="Door001_vis" type="mesh" solimp="0.998 0.998 0.001" solref="0.001 1" density="100" friction="0.95 0.3 0.1" class="visual" material="Door001_material"/>
          <geom class="collision" type="cylinder" pos="-0.069935 -0.382677 0.063737" size="0.012895453721284866 0.3521200120449066" quat="1.0 0.0 0.0 0.0"/>
          <geom class="collision" type="cylinder" pos="-0.069935 -0.358617 0.328316" size="0.008896256797015667 0.019566046074032784" quat="0.7071068286895752 -0.7071067690849304 1.5700924318127872e-16 -5.9269340452702814e-24"/>
          <geom class="collision" type="cylinder" pos="-0.069935 -0.358617 -0.235202" size="0.008896256797015667 0.019566046074032784" quat="0.7071068286895752 -0.7071067690849304 1.5700924318127872e-16 -5.9269340452702814e-24"/>
          <geom class="collision" type="cylinder" pos="-0.250494 -0.306395 0.197417" size="0.010181399993598461 0.010181399993598461" quat="1.0 0.0 0.0 0.0"/>
          <geom class="collision" type="cylinder" pos="-0.217067 -0.306395 0.197417" size="0.010181399993598461 0.010181399993598461" quat="1.0 0.0 0.0 0.0"/>
          <geom class="collision" type="box" pos="-0.070247 -0.313268 0.007730" size="0.03128736466169357 0.029820457100868225 0.7201703786849976" quat="1.0 0.0 0.0 0.0"/>
          <geom class="collision" type="box" pos="-0.216668 -0.257458 0.131649" size="0.11925533413887024 0.003282485529780388 0.23824262619018555" quat="1.0 0.0 0.0 0.0"/>
          <geom class="collision" type="box" pos="-0.234156 -0.318759 0.472571" size="0.13262173533439636 0.02432965114712715 0.2553291320800781" quat="1.0 0.0 0.0 0.0"/>
          <geom class="collision" type="box" pos="-0.234156 -0.318759 -0.405989" size="0.13262173533439636 0.02432965114712715 0.3064519762992859" quat="1.0 0.0 0.0 0.0"/>
          <geom class="collision" type="box" pos="-0.395722 -0.319683 0.007730" size="0.028943806886672974 0.02340586483478546 0.7201703786849976" quat="1.0 0.0 0.0 0.0"/>
          <geom class="collision" type="box" pos="-0.104125 -0.270755 0.131649" size="0.0067124078050255775 0.015388263389468193 0.23824262619018555" quat="1.0 0.0 0.0 0.0"/>
          <geom class="collision" type="box" pos="-0.346023 -0.270755 0.131649" size="0.006712410133332014 0.015388268046081066 0.23824262619018555" quat="1.0 0.0 0.0 0.0"/>
          <geom class="collision" type="box" pos="-0.232658 -0.270755 0.360391" size="0.12181933969259262 0.015388261526823044 0.00950080156326294" quat="1.0 0.0 0.0 0.0"/>
          <geom class="collision" type="box" pos="-0.233484 -0.306259 0.212625" size="0.04262097552418709 0.029891489073634148 0.0052091944962739944" quat="1.0 0.0 0.0 0.0"/>
          <geom class="collision" type="box" pos="-0.349764 -0.316251 0.057580" size="0.003867596387863159 0.029820457100868225 0.15966156125068665" quat="0.966834306716919 0.0 -0.0 -0.25540444254875183"/>
          <geom class="collision" type="box" pos="-0.306785 -0.277688 0.057580" size="0.003867596387863159 0.029820457100868225 0.15966156125068665" quat="0.8436958193778992 0.0 -0.0 -0.5368215441703796"/>
          <geom class="collision" type="box" pos="-0.253131 -0.263256 0.057580" size="0.003867596387863159 0.029820457100868225 0.15966156125068665" quat="0.7231791019439697 0.0 -0.0 -0.6906605362892151"/>
          <geom class="collision" type="box" pos="-0.196052 -0.267210 0.057580" size="0.003867596387863159 0.029820457100868225 0.15966156125068665" quat="0.6374496817588806 0.0 -0.0 -0.7704920172691345"/>
          <geom class="collision" type="box" pos="-0.145048 -0.288207 0.057580" size="0.003867596387863159 0.029820457100868225 0.15966156125068665" quat="0.4350873529911041 0.0 -0.0 -0.900388240814209"/>
          <geom class="collision" type="box" pos="-0.117706 -0.315255 0.057580" size="0.003867596387863159 0.029820457100868225 0.15966156125068665" quat="0.2398415058851242 0.0 -0.0 -0.9708120822906494"/>
          <geom class="collision" type="box" pos="-0.231216 -0.271984 -0.107197" size="0.12037744373083115 0.015388283878564835 0.00950080156326294" quat="1.0 0.0 0.0 0.0"/>
        </body>
        <body name="Door002">
          <joint axis="0.0 0.0 1.0" pos="0.394987 -0.323332 0.008801" limited="true" name="Door002_joint" range="0.0 1.5707963267948966" type="hinge" damping="1" frictionloss="1" armature=".01" stiffness="0.05"/>
          <geom mesh="Door002_vis" type="mesh" solimp="0.998 0.998 0.001" solref="0.001 1" density="100" friction="0.95 0.3 0.1" class="visual" material="Door002_material"/>
          <geom class="collision" type="cylinder" pos="0.036185 -0.382677 0.063737" size="0.012895453721284866 0.3521200120449066" quat="1.0 0.0 0.0 0.0"/>
          <geom class="collision" type="cylinder" pos="0.036185 -0.358617 0.328316" size="0.008896256797015667 0.019566046074032784" quat="0.7071068286895752 -0.7071067690849304 1.5700924318127872e-16 -5.9269340452702814e-24"/>
          <geom class="collision" type="cylinder" pos="0.036185 -0.358617 -0.235202" size="0.008896256797015667 0.019566046074032784" quat="0.7071068286895752 -0.7071067690849304 1.5700924318127872e-16 -5.9269340452702814e-24"/>
          <geom class="collision" type="box" pos="0.192527 -0.319772 0.007730" size="0.22564460337162018 0.023316770792007446 0.7201703786849976" quat="1.0 0.0 0.0 0.0"/>
          <geom class="collision" type="box" pos="0.179985 -0.263814 0.392539" size="0.14785245060920715 0.028714507818222046 0.006003677845001221" quat="1.0 0.0 0.0 0.0"/>
          <geom class="collision" type="box" pos="0.170222 -0.295476 0.007730" size="0.20486129820346832 0.007539153099060059 0.7201703786849976" quat="1.0 0.0 0.0 0.0"/>
          <geom class="collision" type="box" pos="0.179985 -0.232848 0.431091" size="0.14785245060920715 0.0055883899331092834 0.035769760608673096" quat="1.0 0.0 0.0 0.0"/>
          <geom class="collision" type="box" pos="0.333036 -0.263814 0.426698" size="0.005198165774345398 0.028714507818222046 0.04016253352165222" quat="1.0 0.0 0.0 0.0"/>
          <geom class="collision" type="box" pos="0.025692 -0.263814 0.426698" size="0.006441004574298859 0.028714507818222046 0.04016253352165222" quat="1.0 0.0 0.0 0.0"/>
          <geom class="collision" type="box" pos="0.179985 -0.263814 0.171327" size="0.14785245060920715 0.028714507818222046 0.006003677845001221" quat="1.0 0.0 0.0 0.0"/>
          <geom class="collision" type="box" pos="0.179985 -0.232848 0.209879" size="0.14785245060920715 0.0055883899331092834 0.035769760608673096" quat="1.0 0.0 0.0 0.0"/>
          <geom class="collision" type="box" pos="0.333036 -0.263814 0.205486" size="0.005198165774345398 0.028714507818222046 0.04016253352165222" quat="1.0 0.0 0.0 0.0"/>
          <geom class="collision" type="box" pos="0.025692 -0.263814 0.205486" size="0.006441004574298859 0.028714507818222046 0.04016253352165222" quat="1.0 0.0 0.0 0.0"/>
        </body>
        <body name="Drawer001">
          <joint axis="0.0 -1.0 0.0" pos="-0.221807 0.067204 -0.397627" limited="true" name="Drawer001_joint" range="0.0 0.4" type="slide" damping="1" frictionloss="1" armature=".01" stiffness="0.05"/>
          <geom mesh="Drawer001_vis" type="mesh" solimp="0.998 0.998 0.001" solref="0.001 1" density="100" friction="0.95 0.3 0.1" class="visual" material="Drawer001_material"/>
          <geom class="collision" type="box" pos="-0.075583 0.053689 -0.397243" size="0.014491543173789978 0.26361486315727234 0.0834193155169487" quat="1.0 0.0 0.0 0.0"/>
          <geom class="collision" type="box" pos="-0.339817 0.053689 -0.397243" size="0.014491543173789978 0.26361486315727234 0.0834193155169487" quat="1.0 0.0 0.0 0.0"/>
          <geom class="collision" type="box" pos="-0.207270 0.310766 -0.397243" size="0.1455812156200409 0.014491554349660873 0.0834193006157875" quat="1.0 0.0 0.0 0.0"/>
          <geom class="collision" type="box" pos="-0.207962 0.053689 -0.466983" size="0.14472800493240356 0.26361367106437683 0.014491483569145203" quat="1.0 0.0 0.0 0.0"/>
          <geom class="collision" type="box" pos="-0.207728 -0.207921 -0.331549" size="0.1183638945221901 0.002435504226014018 0.01742434874176979" quat="1.0 0.0 0.0 0.0"/>
          <geom class="collision" type="box" pos="-0.207728 -0.198197 -0.420944" size="0.11836452782154083 0.011783481575548649 0.03304709866642952" quat="1.0 0.0 0.0 0.0"/>
          <geom class="collision" type="box" pos="-0.207728 -0.184131 -0.383586" size="0.11836390942335129 0.002435503527522087 0.06916751712560654" quat="1.0 0.0 0.0 0.0"/>
          <geom class="collision" type="box" pos="-0.106545 -0.196284 -0.355394" size="0.017714573070406914 0.01419044379144907 0.0314192958176136" quat="1.0 0.0 0.0 0.0"/>
          <geom class="collision" type="box" pos="-0.310585 -0.196284 -0.355394" size="0.017714573070406914 0.014190444722771645 0.0314192958176136" quat="1.0 0.0 0.0 0.0"/>
          <geom class="collision" type="box" pos="-0.208689 -0.185103 -0.359549" size="0.08508295565843582 0.0032333543058484793 0.030308986082673073" quat="1.0 0.0 0.0 0.0"/>
          <geom class="collision" type="box" pos="-0.207728 -0.196354 -0.323737" size="0.11836446821689606 0.009998190216720104 0.009799218736588955" quat="1.0 0.0 0.0 0.0"/>
        </body>
        <body name="Drawer002">
          <joint axis="0.0 -1.0 0.0" pos="-0.221807 0.067204 -0.578172" limited="true" name="Drawer002_joint" range="0.0 0.4" type="slide" damping="1" frictionloss="1" armature=".01" stiffness="0.05"/>
          <geom mesh="Drawer002_vis" type="mesh" solimp="0.998 0.998 0.001" solref="0.001 1" density="100" friction="0.95 0.3 0.1" class="visual" material="Drawer002_material"/>
          <geom class="collision" type="box" pos="-0.075583 0.053689 -0.576869" size="0.014491543173789978 0.26361486315727234 0.0834193155169487" quat="1.0 0.0 0.0 0.0"/>
          <geom class="collision" type="box" pos="-0.339817 0.053689 -0.576869" size="0.014491543173789978 0.26361486315727234 0.0834193155169487" quat="1.0 0.0 0.0 0.0"/>
          <geom class="collision" type="box" pos="-0.207270 0.310766 -0.576869" size="0.1455812156200409 0.014491554349660873 0.0834193006157875" quat="1.0 0.0 0.0 0.0"/>
          <geom class="collision" type="box" pos="-0.207962 0.053689 -0.646608" size="0.14472800493240356 0.2636139392852783 0.014491499401628971" quat="1.0 0.0 0.0 0.0"/>
          <geom class="collision" type="box" pos="-0.207728 -0.207921 -0.511175" size="0.1183638945221901 0.002435500267893076 0.017424333840608597" quat="1.0 0.0 0.0 0.0"/>
          <geom class="collision" type="box" pos="-0.207728 -0.198197 -0.600570" size="0.1183643713593483 0.011783481575548649 0.03304706886410713" quat="1.0 0.0 0.0 0.0"/>
          <geom class="collision" type="box" pos="-0.207728 -0.184131 -0.563212" size="0.11836390942335129 0.002435499569401145 0.06916751712560654" quat="1.0 0.0 0.0 0.0"/>
          <geom class="collision" type="box" pos="-0.106545 -0.196284 -0.535019" size="0.017714573070406914 0.014190453104674816 0.0314192958176136" quat="1.0 0.0 0.0 0.0"/>
          <geom class="collision" type="box" pos="-0.310585 -0.196284 -0.535019" size="0.017714573070406914 0.01419045403599739 0.0314192958176136" quat="1.0 0.0 0.0 0.0"/>
          <geom class="collision" type="box" pos="-0.208689 -0.185103 -0.539175" size="0.08508295565843582 0.0032333543058484793 0.030308986082673073" quat="1.0 0.0 0.0 0.0"/>
          <geom class="collision" type="box" pos="-0.207728 -0.196354 -0.503363" size="0.11836431175470352 0.009998190216720104 0.009799210354685783" quat="1.0 0.0 0.0 0.0"/>
        </body>
        <body name="Drawer003">
          <joint axis="0.0 -1.0 0.0" pos="0.175621 0.067204 -0.397627" limited="true" name="Drawer003_joint" range="0.0 0.4" type="slide" damping="1" frictionloss="1" armature=".01" stiffness="0.05"/>
          <geom mesh="Drawer003_vis" type="mesh" solimp="0.998 0.998 0.001" solref="0.001 1" density="100" friction="0.95 0.3 0.1" class="visual" material="Drawer003_material"/>
          <geom class="collision" type="box" pos="0.321901 0.053689 -0.396298" size="0.014491543173789978 0.26361486315727234 0.0834193155169487" quat="1.0 0.0 0.0 0.0"/>
          <geom class="collision" type="box" pos="-0.001311 0.053689 -0.396298" size="0.014491543173789978 0.26361486315727234 0.0834193155169487" quat="1.0 0.0 0.0 0.0"/>
          <geom class="collision" type="box" pos="0.165343 0.310766 -0.396298" size="0.1455812156200409 0.014491554349660873 0.0834193006157875" quat="1.0 0.0 0.0 0.0"/>
          <geom class="collision" type="box" pos="0.164651 0.053689 -0.466038" size="0.14472800493240356 0.2636142373085022 0.014491516165435314" quat="1.0 0.0 0.0 0.0"/>
          <geom class="collision" type="box" pos="0.164885 -0.207921 -0.330604" size="0.1183638945221901 0.002435496309772134 0.017424317076802254" quat="1.0 0.0 0.0 0.0"/>
          <geom class="collision" type="box" pos="0.164885 -0.198197 -0.419999" size="0.14797642827033997 0.011783466674387455 0.03304697945713997" quat="1.0 0.0 0.0 0.0"/>
          <geom class="collision" type="box" pos="0.164885 -0.184131 -0.382641" size="0.11836390942335129 0.002435495611280203 0.06916751712560654" quat="1.0 0.0 0.0 0.0"/>
          <geom class="collision" type="box" pos="0.278398 -0.196284 -0.354449" size="0.027425065636634827 0.014190511777997017 0.03141935169696808" quat="1.0 0.0 0.0 0.0"/>
          <geom class="collision" type="box" pos="0.032389 -0.196284 -0.354449" size="0.017714573070406914 0.014190463349223137 0.0314192958176136" quat="1.0 0.0 0.0 0.0"/>
          <geom class="collision" type="box" pos="0.163924 -0.185103 -0.358604" size="0.10063748806715012 0.0032333543058484793 0.030308986082673073" quat="1.0 0.0 0.0 0.0"/>
          <geom class="collision" type="box" pos="0.164885 -0.196354 -0.322792" size="0.14914390444755554 0.009998197667300701 0.009799190796911716" quat="1.0 0.0 0.0 0.0"/>
        </body>
        <body name="Drawer004">
          <joint axis="0.0 -1.0 0.0" pos="0.175621 0.067204 -0.578172" limited="true" name="Drawer004_joint" range="0.0 0.4" type="slide" damping="1" frictionloss="1" armature=".01" stiffness="0.05"/>
          <geom mesh="Drawer004_vis" type="mesh" solimp="0.998 0.998 0.001" solref="0.001 1" density="100" friction="0.95 0.3 0.1" class="visual" material="Drawer004_material"/>
          <geom class="collision" type="box" pos="0.321901 0.053689 -0.575748" size="0.014491543173789978 0.26361486315727234 0.0834193155169487" quat="1.0 0.0 0.0 0.0"/>
          <geom class="collision" type="box" pos="-0.001311 0.053689 -0.575748" size="0.014491543173789978 0.26361486315727234 0.0834193155169487" quat="1.0 0.0 0.0 0.0"/>
          <geom class="collision" type="box" pos="0.165343 0.310766 -0.575748" size="0.1455812156200409 0.014491554349660873 0.0834193006157875" quat="1.0 0.0 0.0 0.0"/>
          <geom class="collision" type="box" pos="0.164651 0.053689 -0.645487" size="0.14472800493240356 0.2636145055294037 0.014491531997919083" quat="1.0 0.0 0.0 0.0"/>
          <geom class="collision" type="box" pos="0.164885 -0.207921 -0.510054" size="0.1183638945221901 0.0024354923516511917 0.01742430217564106" quat="1.0 0.0 0.0 0.0"/>
          <geom class="collision" type="box" pos="0.164885 -0.198197 -0.599449" size="0.14797642827033997 0.011783475987613201 0.03304697945713997" quat="1.0 0.0 0.0 0.0"/>
          <geom class="collision" type="box" pos="0.164885 -0.184131 -0.562090" size="0.11836390942335129 0.0024354916531592607 0.06916751712560654" quat="1.0 0.0 0.0 0.0"/>
          <geom class="collision" type="box" pos="0.278398 -0.196284 -0.533898" size="0.027425037696957588 0.014190496876835823 0.03141932189464569" quat="1.0 0.0 0.0 0.0"/>
          <geom class="collision" type="box" pos="0.032389 -0.196284 -0.533898" size="0.017714573070406914 0.014190473593771458 0.0314192958176136" quat="1.0 0.0 0.0 0.0"/>
          <geom class="collision" type="box" pos="0.147891 -0.185103 -0.538053" size="0.10239453613758087 0.0032333526760339737 0.030308986082673073" quat="1.0 0.0 0.0 0.0"/>
          <geom class="collision" type="box" pos="0.164885 -0.196354 -0.502241" size="0.14914390444755554 0.009998197667300701 0.009799190796911716" quat="1.0 0.0 0.0 0.0"/>
        </body>
        <geom class="region" name="reg_main" type="box" pos="0.0 0.0246875 0.0" size="0.42502 0.37063650000000004 0.7902"/>
      </body>
    </body>
  </worldbody>
  <actuator>
    <motor name="Door001_joint_actuator" joint="Door001_joint" gear="50"/>
    <motor name="Door002_joint_actuator" joint="Door002_joint" gear="50"/>
    <motor name="Drawer001_joint_actuator" joint="Drawer001_joint" gear="50"/>
    <motor name="Drawer002_joint_actuator" joint="Drawer002_joint" gear="50"/>
    <motor name="Drawer003_joint_actuator" joint="Drawer003_joint" gear="50"/>
    <motor name="Drawer004_joint_actuator" joint="Drawer004_joint" gear="50"/>
  </actuator>
</mujoco>
