<mujoco model="model">
  <asset>
    <material name="01_PBR_Snow-white" specular="0.5" shininess="0.36" rgba="0.800000 0.800000 0.800000 1.000000"/>
    <material name="PBR_Black" specular="0.5" shininess="0.36" rgba="0.800000 0.800000 0.800000 1.000000"/>
    <material name="PBR_Metal" specular="0.5" shininess="0.36" rgba="0.800000 0.800000 0.800000 1.000000"/>
    <mesh file="visuals/model_0.obj" name="model_0_vis" scale="1 1 1"/>
    <mesh file="visuals/model_1.obj" name="model_1_vis" scale="1 1 1"/>
    <mesh file="visuals/model_2.obj" name="model_2_vis" scale="1 1 1"/>
    <material name="05_PBR_Safari" specular="0.5" shininess="0.36" rgba="0.800000 0.800000 0.800000 1.000000"/>
    <material name="PBR_Filter" specular="0.5" shininess="0.36" rgba="0.800000 0.800000 0.800000 1.000000"/>
    <mesh file="visuals/spout_0.obj" name="spout_0_vis" scale="1 1 1"/>
    <mesh file="visuals/spout_1.obj" name="spout_1_vis" scale="1 1 1"/>
    <mesh file="visuals/spout_2.obj" name="spout_2_vis" scale="1 1 1"/>
    <mesh file="visuals/handle_0.obj" name="handle_0_vis" scale="1 1 1"/>
  </asset>
  <default>
    <default class="visual">
      <geom conaffinity="0" contype="0" group="1" type="mesh"/>
    </default>
    <default class="collision">
      <!-- <geom group="0" rgba="0.5 0 0 0.5"/> -->
      <geom group="0" rgba="0.5 0 0 0.5" solimp="0.998 0.998 0.001" solref="0.001 2"/>
    </default>
    <default class="region">
      <geom group="1" conaffinity="0" contype="0" rgba="0 1 0 0"/>
    </default>
  </default>
  <worldbody>
    <body>
      <!-- exterior bounding box points -->
      <!-- interior bounding box points -->
      <body name="object">
        <geom solimp="0.998 0.998 0.001" solref="0.001 1" density="100" friction="0.95 0.3 0.1" type="mesh" mesh="model_0_vis" material="PBR_Black" class="visual"/>
        <geom solimp="0.998 0.998 0.001" solref="0.001 1" density="100" friction="0.95 0.3 0.1" type="mesh" mesh="model_1_vis" material="PBR_Metal" class="visual"/>
        <geom solimp="0.998 0.998 0.001" solref="0.001 1" density="100" friction="0.95 0.3 0.1" type="mesh" mesh="model_2_vis" material="01_PBR_Snow-white" class="visual"/>
        <!-- Bottom -->
        <geom class="collision" type="box" pos="0.23 0 -0.36" size="0.2 0.25 0.01"/>
        <!-- Left Wall -->
        <geom class="collision" type="box" pos="0.02 0 -0.255" size="0.01 0.265 0.11" axisangle="0 1 0 -8"/>
        <!-- Right Wall -->
        <geom class="collision" type="box" pos="0.44 0 -0.255" size="0.01 0.265 0.11" axisangle="0 1 0 8"/>
        <!-- Back Wall -->
        <geom class="collision" type="box" pos="0.23 0.26 -0.255" size="0.215 0.01 0.11" axisangle="1 0 0 -8"/>
        <!-- Front Wall -->
        <geom class="collision" type="box" pos="0.23 -0.26 -0.255" size="0.215 0.01 0.11" axisangle="1 0 0 8"/>
        <!-- Storage -->
        <geom class="collision" type="box" pos="-0.25 0 -0.148" size="0.25 0.32 0.01"/>
        <!-- Back Ledge -->
        <geom class="collision" type="box" pos="0.25 0.295 -0.148" size="0.25 0.025 0.01"/>
        <!-- Front Ledge -->
        <geom class="collision" type="box" pos="0.25 -0.295 -0.148" size="0.25 0.025 0.01"/>
        <!-- Right Ledge -->
        <geom class="collision" type="box" pos="0.475 0 -0.148" size="0.025 0.3 0.01"/>
        <!-- Faucet Base -->
        <geom class="collision" type="cylinder" pos="-0.039 0.2245 -0.059" size="0.0298 0.08 0"/>
        <!-- Handle Attach Point-->
        <geom class="collision" type="cylinder" pos="-0.0385 0.19 -0.06" size="0.03 0.028 0" axisangle="1 0 0 90"/>
        <body name="spout">
          <joint axis="0 0 1" limited="true" name="faucet_joint" range="-130 50" pos="-0.039 0.2245 0"/>
          <geom solimp="0.998 0.998 0.001" solref="0.001 1" density="100" friction="0.95 0.3 0.1" type="mesh" mesh="spout_0_vis" material="PBR_Filter" class="visual"/>
          <geom solimp="0.998 0.998 0.001" solref="0.001 1" density="100" friction="0.95 0.3 0.1" type="mesh" mesh="spout_1_vis" material="05_PBR_Safari" class="visual"/>
          <geom solimp="0.998 0.998 0.001" solref="0.001 1" density="100" friction="0.95 0.3 0.1" type="mesh" mesh="spout_2_vis" material="PBR_Metal" class="visual"/>
          <!-- Faucet -->
          <geom class="collision" type="cylinder" pos="-0.039 0.2245 0.18" size="0.018 0.16 0"/>
          <geom class="collision" type="cylinder" pos="-0.002 0.18 0.37" size="0.018 0.07 0" axisangle="45 40 0 45"/>
          <geom class="collision" type="cylinder" pos="0.067 0.1 0.385" size="0.018 0.07 0" axisangle="45 40 0 -70"/>
          <geom class="collision" type="cylinder" pos="0.13 0.024 0.28" size="0.018 0.1 0" axisangle="45 40 0 -18"/>
          <geom class="collision" type="cylinder" pos="0.15 0 0.175" size="0.036 0.01 0" axisangle="45 40 0 -16"/>
          <geom class="collision" type="cylinder" pos="0.15 0 0.175" size="0.036 0.01 0" axisangle="45 40 0 -16"/>
        </body>
        <body name="handle">
          <joint axis="0 1 0" limited="true" name="knob_joint" range="-90 90" pos="-0.0385 0.162 -0.06"/>
          <joint axis="1 0 0" type="hinge" limited="true" name="knob_hinge_joint" range="0 22" pos="-0.0385 0.16 -0.06"/>
          <geom solimp="0.998 0.998 0.001" solref="0.001 1" density="100" friction="0.95 0.3 0.1" type="mesh" mesh="handle_0_vis" material="05_PBR_Safari" class="visual"/>
          <!-- Main -->
          <geom class="collision" type="cylinder" pos="-0.0385 0.145 -0.06" size="0.03 0.017 0" axisangle="1 0 0 90"/>
          <!-- Handle -->
          <geom class="collision" type="cylinder" pos="-0.0385 0.143 0.004" size="0.006 0.036 0"/>
        </body>
        <geom class="region" name="reg_main" type="box" pos="0.0 0.0 -0.27" size="0.5 0.32 0.13"/>
        <geom class="region" name="reg_basin" type="box" pos="0.0 0.0 0.0" size="0.0001 0.0001 0.0001"/>
      </body>
    </body>
  </worldbody>
</mujoco>
