<mujoco model="model">
  <compiler angle="radian"/>
  <asset>
    <mesh file="visuals/Body001.obj" name="Body001_vis"/>
    <mesh file="visuals/Button001.obj" name="Button001_vis"/>
    <mesh file="visuals/Button002.obj" name="Button002_vis"/>
    <mesh file="visuals/Knob001.obj" name="Knob001_vis"/>
    <mesh file="visuals/Knob002.obj" name="Knob002_vis"/>
    <mesh file="visuals/Lever001.obj" name="Lever001_vis"/>
    <mesh file="visuals/Lever002.obj" name="Lever002_vis"/>
    <texture file="visuals/T_BC001.png" name="Body001_material" type="2d"/>
    <material name="Body001_material" rgba="1 1 1 1.0" texture="Body001_material" shininess="0.5" specular="0.5103448502657381"/>
    <texture file="visuals/T_BC001.png" name="Button001_material" type="2d"/>
    <material name="Button001_material" rgba="1 1 1 1.0" texture="Button001_material" shininess="0.5" specular="0.83103448502657381"/>
    <texture file="visuals/T_BC001.png" name="Button002_material" type="2d"/>
    <material name="Button002_material" rgba="1 1 1 1.0" texture="Button002_material" shininess="0.5" specular="0.83103448502657381"/>
    <texture file="visuals/T_BC001.png" name="Knob001_material" type="2d"/>
    <material name="Knob001_material" rgba="1 1 1 1.0" texture="Knob001_material" shininess="0.5" specular="0.83103448502657381"/>
    <texture file="visuals/T_BC001.png" name="Knob002_material" type="2d"/>
    <material name="Knob002_material" rgba="1 1 1 1.0" texture="Knob002_material" shininess="0.5" specular="0.83103448502657381"/>
    <texture file="visuals/T_BC001.png" name="Lever001_material" type="2d"/>
    <material name="Lever001_material" rgba="1 1 1 1.0" texture="Lever001_material" shininess="0.5" specular="0.83103448502657381"/>
    <texture file="visuals/T_BC001.png" name="Lever002_material" type="2d"/>
    <material name="Lever002_material" rgba="1 1 1 1.0" texture="Lever002_material" shininess="0.5" specular="0.83103448502657381"/>
  </asset>
  <default>
    <default class="visual">
      <geom conaffinity="0" contype="0" group="1" type="mesh"/>
    </default>
    <default class="collision">
      <geom group="0" rgba="0.5 0 0 0.5"/>
    </default>
    <default class="spawn">
      <geom group="0" rgba="1 1 1 0.5" contype="0" conaffinity="0"/>
      <site group="0" rgba="1 1 1 0.5"/>
    </default>
    <default class="region">
      <geom group="1" conaffinity="0" contype="0" rgba="0 1 0 0"/>
    </default>
  </default>
  <worldbody>
    <body>
      <body name="object">
        <geom mesh="Body001_vis" type="mesh" solimp="0.998 0.998 0.001" solref="0.001 1" density="100" friction="0.95 0.3 0.1" class="visual" material="Body001_material"/>
        <geom class="collision" type="box" pos="0.072925 0.142047 -0.019639" size="0.045860979706048965 0.011319047771394253 0.036982305347919464" quat="0.9996153712272644 0.0 -0.0 -0.027732810005545616"/>
        <geom class="collision" type="box" pos="0.000646 0.128346 0.044403" size="0.11699801683425903 0.010309722274541855 0.02927190251648426" quat="0.9929261803627014 0.11873321980237961 2.6364074191218734e-17 -5.4317475168317796e-24"/>
        <geom class="collision" type="box" pos="-0.001578 0.094757 0.016706" size="0.11432112008333206 0.07125259190797806 0.01251814141869545" quat="0.732119619846344 0.6811761260032654 1.512514970176482e-16 -2.5655157654754976e-23"/>
        <geom class="collision" type="box" pos="-0.001565 0.115072 0.072274" size="0.11313483864068985 0.01030972134321928 0.010597869753837585" quat="0.8860620260238647 0.46356672048568726 1.0293246945430214e-16 -2.890941714807063e-23"/>
        <geom class="collision" type="box" pos="-0.013349 0.144233 -0.019639" size="0.04300162196159363 0.011788892559707165 0.03698223829269409" quat="1.0 0.0 0.0 0.0"/>
        <geom class="collision" type="box" pos="-0.087338 0.140016 -0.019639" size="0.03333843871951103 0.011318840086460114 0.036982305347919464" quat="0.9964933395385742 0.0 0.0 0.08367206156253815"/>
        <geom class="collision" type="box" pos="0.070855 0.142331 -0.067907" size="0.04390943422913551 0.009132260456681252 0.01508585549890995" quat="0.960905909538269 -0.27548277378082275 -0.007642848417162895 -0.0266588032245636"/>
        <geom class="collision" type="box" pos="-0.013325 0.143976 -0.069238" size="0.04288007691502571 0.009157956577837467 0.01534316223114729" quat="0.9612611532211304 -0.2755846381187439 0.0015121030155569315 0.005274335853755474"/>
        <geom class="collision" type="box" pos="-0.086523 0.140534 -0.066972" size="0.03287868574261665 0.009147867560386658 0.015244589187204838" quat="0.9579047560691833 -0.27462249994277954 0.02305901050567627 0.08043168485164642"/>
        <geom class="collision" type="box" pos="0.000599 0.004107 0.025885" size="0.019645124673843384 0.1002863422036171 0.05946194380521774" quat="1.0 0.0 0.0 0.0"/>
        <geom class="collision" type="box" pos="0.050653 0.004105 0.027483" size="0.013687477447092533 0.1002863422036171 0.05946194380521774" quat="1.0 0.0 0.0 0.0"/>
        <geom class="collision" type="box" pos="0.000944 0.004737 0.081182" size="0.014616125263273716 0.029005499556660652 0.012524447403848171" quat="1.0 0.0 0.0 0.0"/>
        <geom class="collision" type="box" pos="0.000204 -0.046699 0.079130" size="0.029005495831370354 0.014616142027080059 0.012524447403848171" quat="0.706587553024292 0.027090901508927345 0.027090897783637047 -0.7065877318382263"/>
        <geom class="collision" type="box" pos="0.000876 -0.090371 0.075048" size="0.015702756121754646 0.014615214429795742 0.01242124568670988" quat="0.7045238018035889 0.06038447842001915 0.06038448587059975 -0.7045237421989441"/>
        <geom class="collision" type="box" pos="0.001760 0.061910 0.079006" size="0.029005495831370354 0.014616142027080059 0.012524446472525597" quat="0.7066655158996582 -0.024975739419460297 -0.024975739419460297 -0.7066656351089478"/>
        <geom class="collision" type="box" pos="-0.050384 0.005522 0.080860" size="0.009727951139211655 0.0290036890655756 0.01252242736518383" quat="1.0 0.0 0.0 0.0"/>
        <geom class="collision" type="box" pos="-0.050384 -0.045914 0.078809" size="0.029004137963056564 0.00972794834524393 0.01252224575728178" quat="0.7065876722335815 0.027090901508927345 0.027090895920991898 -0.7065876126289368"/>
        <geom class="collision" type="box" pos="-0.050384 -0.089996 0.074645" size="0.0161244198679924 0.009727331809699535 0.01241886056959629" quat="0.7045238018035889 0.06038447842001915 0.06038448587059975 -0.7045237421989441"/>
        <geom class="collision" type="box" pos="-0.050384 0.062694 0.078685" size="0.029003292322158813 0.00972794834524393 0.012522609904408455" quat="0.7066655158996582 -0.024975739419460297 -0.024975739419460297 -0.7066656351089478"/>
        <geom class="collision" type="box" pos="0.051336 0.004016 0.081253" size="0.009727951139211655 0.02900369092822075 0.01252242736518383" quat="1.0 0.0 0.0 0.0"/>
        <geom class="collision" type="box" pos="0.051336 -0.047421 0.079201" size="0.029004137963056564 0.00972794834524393 0.01252224575728178" quat="0.7065876722335815 0.027090901508927345 0.027090895920991898 -0.7065876126289368"/>
        <geom class="collision" type="box" pos="0.051336 -0.091139 0.075100" size="0.01575544849038124 0.009727331809699535 0.01241886056959629" quat="0.7045238018035889 0.06038447842001915 0.06038448587059975 -0.7045237421989441"/>
        <geom class="collision" type="box" pos="0.051336 0.061187 0.079077" size="0.029003292322158813 0.00972794834524393 0.012522609904408455" quat="0.7066655158996582 -0.024975739419460297 -0.024975739419460297 -0.7066656351089478"/>
        <geom class="collision" type="box" pos="0.103038 0.003316 0.081605" size="0.01594114489853382 0.02900371327996254 0.012522444128990173" quat="1.0 0.0 0.0 0.0"/>
        <geom class="collision" type="box" pos="0.103038 -0.048121 0.079553" size="0.029004141688346863 0.015941143035888672 0.012522244825959206" quat="0.7065876722335815 0.027090901508927345 0.027090895920991898 -0.7065876126289368"/>
        <geom class="collision" type="box" pos="0.103039 -0.089998 0.073454" size="0.01656382717192173 0.01594013161957264 0.013484420254826546" quat="0.7045238018035889 0.06038447842001915 0.06038448587059975 -0.7045237421989441"/>
        <geom class="collision" type="box" pos="0.103038 0.060488 0.079430" size="0.029003290459513664 0.015941143035888672 0.012522609904408455" quat="0.7066655158996582 -0.024975739419460297 -0.024975739419460297 -0.7066656351089478"/>
        <geom class="collision" type="box" pos="0.000599 0.004107 -0.075426" size="0.12469083070755005 0.1285419464111328 0.011757205240428448" quat="1.0 0.0 0.0 0.0"/>
        <geom class="collision" type="box" pos="-0.099453 0.005522 0.081554" size="0.015073917806148529 0.02900368720293045 0.01252242736518383" quat="1.0 0.0 0.0 0.0"/>
        <geom class="collision" type="box" pos="-0.099453 -0.045914 0.079502" size="0.029004141688346863 0.01507391594350338 0.012522244825959206" quat="0.7065876722335815 0.027090901508927345 0.027090895920991898 -0.7065876126289368"/>
        <geom class="collision" type="box" pos="-0.099453 -0.087691 0.075736" size="0.013785207644104958 0.015072958543896675 0.012418858706951141" quat="0.7045238018035889 0.06038447842001915 0.06038448587059975 -0.7045237421989441"/>
        <geom class="collision" type="box" pos="-0.099453 0.062694 0.079378" size="0.029003290459513664 0.01507391594350338 0.012522609904408455" quat="0.7066655158996582 -0.024975739419460297 -0.024975739419460297 -0.7066656351089478"/>
        <geom class="collision" type="box" pos="-0.086131 0.004140 0.013807" size="0.003048656275495887 0.08163037896156311 0.07607842236757278" quat="1.0 0.0 0.0 0.0"/>
        <geom class="collision" type="box" pos="-0.050981 0.004105 0.027483" size="0.01268647238612175 0.10028634965419769 0.05946194380521774" quat="1.0 0.0 0.0 0.0"/>
        <geom class="collision" type="box" pos="0.001031 -0.093456 0.084164" size="0.016104744747281075 0.0024242340587079525 0.0882149264216423" quat="0.5688297152519226 -0.4200344979763031 0.5688363313674927 -0.4200344979763031"/>
        <geom class="collision" type="box" pos="-0.056891 -0.113150 0.069472" size="0.016104742884635925 0.05469455569982529 0.002424237783998251" quat="0.5913437604904175 0.3811352849006653 0.37233296036720276 -0.6053235530853271"/>
        <geom class="collision" type="box" pos="-0.066916 -0.122952 0.037325" size="0.01733967289328575 0.04701436311006546 0.00242423452436924" quat="0.5432335138320923 0.4456195533275604 0.42652446031570435 -0.5695589780807495"/>
        <geom class="collision" type="box" pos="-0.059458 -0.133114 -0.066198" size="0.016104742884635925 0.002424234291538596 0.05601351335644722" quat="0.6924258470535278 0.11927058547735214 0.7058899998664856 0.08966754376888275"/>
        <geom class="collision" type="box" pos="0.054908 -0.132625 -0.066894" size="0.016104742884635925 0.0024242340587079525 0.058831434696912766" quat="0.6974658966064453 0.08476696908473969 0.6993010640144348 0.13165821135044098"/>
        <geom class="collision" type="box" pos="0.054947 -0.113194 0.069472" size="0.016104742884635925 0.056639399379491806 0.002424240577965975" quat="0.5913495421409607 0.38113173842430115 -0.37233662605285645 0.6053178906440735"/>
        <geom class="collision" type="box" pos="0.066597 -0.122746 0.037821" size="0.016832325607538223 0.04733683913946152 0.002424230333417654" quat="0.5438448190689087 0.4451959729194641 -0.42696887254714966 0.5689736008644104"/>
        <geom class="collision" type="box" pos="0.066316 -0.134664 -0.031336" size="0.021207712590694427 0.046898044645786285 0.0024242415092885494" quat="0.5049710869789124 0.4865931272506714 -0.4677930176258087 0.5379600524902344"/>
        <geom class="collision" type="box" pos="0.085529 0.004105 0.027483" size="0.0029718466103076935 0.10028635710477829 0.05946194380521774" quat="1.0 0.0 0.0 0.0"/>
        <geom class="collision" type="box" pos="0.000599 0.004107 -0.038028" size="0.08741746842861176 0.10028636455535889 0.008646897040307522" quat="1.0 0.0 0.0 0.0"/>
        <geom class="collision" type="box" pos="0.000024 -0.139174 -0.040005" size="0.0014719790779054165 0.013052025809884071 0.013424964621663094" quat="0.7064796090126038 -0.029773812741041183 -0.02977381832897663 -0.7064797282218933"/>
        <geom class="collision" type="box" pos="0.000346 -0.136737 -0.013009" size="0.0014719790779054165 0.013052025809884071 0.013424964621663094" quat="0.7064796090126038 -0.029773812741041183 -0.02977381832897663 -0.7064797282218933"/>
        <geom class="collision" type="box" pos="0.000346 -0.132928 0.013535" size="0.0014514552894979715 0.012870040722191334 0.013237778097391129" quat="0.7041632533073425 -0.0644516572356224 -0.0644516721367836 -0.7041633725166321"/>
        <geom class="collision" type="box" pos="-0.000116 -0.126312 0.041486" size="0.0014514552894979715 0.012870040722191334 0.01420574076473713" quat="0.7020131945610046 -0.08471930027008057 -0.08471930027008057 -0.702013373374939"/>
        <geom class="collision" type="box" pos="-0.016439 -0.124590 0.047473" size="0.0014514555223286152 0.0034552181605249643 0.008107281289994717" quat="0.7020131945610046 -0.08471930027008057 -0.08471930027008057 -0.702013373374939"/>
        <geom class="collision" type="box" pos="0.015887 -0.124590 0.047473" size="0.0014514555223286152 0.0034552181605249643 0.008107281289994717" quat="0.7020131945610046 -0.08471930027008057 -0.08471930027008057 -0.702013373374939"/>
        <geom class="collision" type="box" pos="-0.066054 -0.129978 0.005923" size="0.016104742884635925 0.047861624509096146 0.0024242396466434" quat="0.5208864212036133 0.4715471863746643 0.4537562131881714 -0.5481112003326416"/>
        <geom class="collision" type="box" pos="-0.065978 -0.134120 -0.031526" size="0.021207710728049278 0.048002585768699646 0.002424243837594986" quat="0.5146521925926208 0.47834324836730957 0.46091026067733765 -0.5421094298362732"/>
        <geom class="collision" type="box" pos="0.067026 -0.129988 0.005921" size="0.016104742884635925 0.04808758944272995 0.0024242415092885494" quat="0.5208864212036133 0.4715471863746643 -0.4537562131881714 0.5481112003326416"/>
        <geom class="collision" type="box" pos="0.123199 -0.113738 0.033390" size="0.013241260312497616 0.03169574216008186 0.0034925348591059446" quat="0.7373143434524536 0.6024975180625916 0.21775461733341217 0.21435299515724182"/>
        <geom class="collision" type="box" pos="0.124433 -0.122015 -0.031216" size="0.013241256587207317 0.03287624940276146 0.003492526477202773" quat="0.6675412058830261 0.6141428351402283 0.3240535855293274 0.2687129080295563"/>
        <geom class="collision" type="box" pos="0.132912 0.069929 0.040111" size="0.03358568996191025 0.03653613477945328 0.007371116895228624" quat="0.5046805143356323 0.4523944556713104 0.4907858073711395 0.5475090146064758"/>
        <geom class="collision" type="box" pos="0.137137 -0.006723 0.040127" size="0.0365382544696331 0.04288007318973541 0.007378631737083197" quat="0.0055539971217513084 -0.6674211025238037 -0.00497799925506115 -0.7446431517601013"/>
        <geom class="collision" type="box" pos="0.131779 -0.075851 0.040127" size="0.028341569006443024 0.036538224667310715 0.0073785032145679" quat="0.562498152256012 0.5041662454605103 0.43737080693244934 0.4879744052886963"/>
        <geom class="collision" type="box" pos="0.130478 0.088703 -0.035413" size="0.03871198743581772 0.05106126144528389 0.007378666661679745" quat="0.05947708338499069 -0.7098848819732666 -0.05946817621588707 -0.6992778182029724"/>
        <geom class="collision" type="box" pos="0.140418 -0.003473 -0.033762" size="0.03653757646679878 0.04288008436560631 0.007378634065389633" quat="0.005848493427038193 -0.7121397852897644 -0.004623092710971832 -0.7019981145858765"/>
        <geom class="collision" type="box" pos="0.133821 -0.080798 -0.033485" size="0.03333844989538193 0.03653821721673012 0.007378493435680866" quat="0.5344098806381226 0.5333434343338013 0.47127848863601685 0.4559028744697571"/>
        <geom class="collision" type="box" pos="0.119537 0.124559 0.040299" size="0.006499781738966703 0.036533769220113754 0.007362739183008671" quat="0.16748973727226257 0.18874789774417877 0.6277307868003845 0.7363935708999634"/>
        <geom class="collision" type="box" pos="0.124719 0.111108 0.040930" size="0.010736622847616673 0.03653202950954437 0.007356568705290556" quat="0.39171677827835083 0.4041488766670227 0.5350667238235474 0.630020022392273"/>
        <geom class="collision" type="box" pos="0.121591 0.084319 -0.072761" size="0.01468718983232975 0.04179774597287178 0.011757192201912403" quat="0.0784950777888298 -0.21379134058952332 -0.009843681007623672 -0.9736708402633667"/>
        <geom class="collision" type="box" pos="0.128089 0.004107 -0.074338" size="0.0146871916949749 0.041797738522291183 0.011757195927202702" quat="6.602014934742328e-08 -0.21417465806007385 1.906587421274253e-08 -0.9767953753471375"/>
        <geom class="collision" type="box" pos="0.120103 -0.077798 -0.072971" size="0.01468720007687807 0.04179774969816208 0.011757195927202702" quat="0.09398642182350159 0.21630989015102386 0.006197112146764994 0.9717706441879272"/>
        <geom class="collision" type="box" pos="0.126272 0.006549 0.085363" size="0.013358077965676785 0.029003718867897987 0.002542859176173806" quat="4.513291784746798e-08 -0.31964632868766785 5.4137899496708997e-08 -0.9475369453430176"/>
        <geom class="collision" type="box" pos="0.125442 -0.052947 0.082175" size="0.013358077965676785 0.029003717005252838 0.0025428496301174164" quat="0.017029879614710808 0.30914226174354553 -0.03724353015422821 0.9501336812973022"/>
        <geom class="collision" type="box" pos="0.124952 0.065776 0.082864" size="0.013358082622289658 0.029003722593188286 0.0025428493972867727" quat="0.015770697966217995 -0.32475802302360535 -0.03882738575339317 -0.9448682069778442"/>
        <geom class="collision" type="box" pos="0.120403 -0.093285 0.080773" size="0.008495884947478771 0.011557872407138348 0.002193313091993332" quat="0.7361759543418884 0.3175431489944458 0.1714431494474411 0.5725544095039368"/>
        <geom class="collision" type="box" pos="0.117786 -0.106007 0.073261" size="0.008117185905575752 0.015379797667264938 0.001694690901786089" quat="0.8055134415626526 0.5018001198768616 0.15257470309734344 0.2758001387119293"/>
        <geom class="collision" type="box" pos="0.122611 0.102598 0.079746" size="0.008495884947478771 0.011557867750525475 0.0021933196112513542" quat="0.6100724935531616 0.10540375858545303 0.32175377011299133 0.7163631319999695"/>
        <geom class="collision" type="box" pos="-0.124444 -0.121988 -0.030944" size="0.013241257518529892 0.03314945846796036 0.0034925255458801985" quat="0.6675411462783813 0.614142894744873 -0.3240535855293274 -0.2687129080295563"/>
        <geom class="collision" type="box" pos="-0.117786 -0.106007 0.073261" size="0.008117185905575752 0.015379797667264938 0.001694690901786089" quat="0.8055134415626526 0.5018001198768616 -0.15257470309734344 -0.2758001387119293"/>
        <geom class="collision" type="box" pos="-0.132912 0.069929 0.040111" size="0.03358568996191025 0.03653613477945328 0.007371116895228624" quat="0.5046805143356323 0.4523944556713104 -0.4907858073711395 -0.5475090146064758"/>
        <geom class="collision" type="box" pos="-0.137137 -0.006723 0.040127" size="0.0365382581949234 0.04288008436560631 0.00737863639369607" quat="0.0055539971217513084 -0.6674211025238037 0.00497799925506115 0.7446431517601013"/>
        <geom class="collision" type="box" pos="-0.131779 -0.075851 0.040127" size="0.028341569006443024 0.036538224667310715 0.0073785032145679" quat="0.562498152256012 0.5041662454605103 -0.43737080693244934 -0.4879744052886963"/>
        <geom class="collision" type="box" pos="-0.130478 0.088703 -0.035413" size="0.03871198743581772 0.05106126144528389 0.007378666661679745" quat="0.05947708338499069 -0.7098848819732666 0.05946817621588707 0.6992778182029724"/>
        <geom class="collision" type="box" pos="-0.140418 -0.003473 -0.033762" size="0.03653757646679878 0.04288008436560631 0.007378634065389633" quat="0.005848493427038193 -0.7121397852897644 0.004623092710971832 0.7019981145858765"/>
        <geom class="collision" type="box" pos="-0.133821 -0.080798 -0.033485" size="0.03333844989538193 0.03653821721673012 0.007378493435680866" quat="0.5344098806381226 0.5333434343338013 -0.47127848863601685 -0.4559028744697571"/>
        <geom class="collision" type="box" pos="-0.121591 0.084319 -0.072761" size="0.01468718983232975 0.04179774597287178 0.011757192201912403" quat="0.0784950777888298 -0.21379134058952332 0.009843681007623672 0.9736708402633667"/>
        <geom class="collision" type="box" pos="-0.128089 0.004107 -0.074338" size="0.0146871916949749 0.041797738522291183 0.011757195927202702" quat="6.602014934742328e-08 -0.21417465806007385 -1.906587421274253e-08 0.9767953753471375"/>
        <geom class="collision" type="box" pos="-0.120103 -0.077798 -0.072971" size="0.01468720007687807 0.04179774969816208 0.011757195927202702" quat="0.09398642182350159 0.21630989015102386 -0.006197112146764994 -0.9717706441879272"/>
        <geom class="collision" type="box" pos="-0.126272 0.006549 0.085363" size="0.013358077965676785 0.029003718867897987 0.002542859176173806" quat="4.513291784746798e-08 -0.31964632868766785 -5.4137899496708997e-08 0.9475369453430176"/>
        <geom class="collision" type="box" pos="-0.124952 0.065776 0.082864" size="0.013358082622289658 0.029003722593188286 0.0025428493972867727" quat="0.015770697966217995 -0.32475802302360535 0.03882738575339317 0.9448682069778442"/>
        <geom class="collision" type="box" pos="-0.125442 -0.052947 0.082175" size="0.013358077965676785 0.029003717005252838 0.0025428496301174164" quat="0.017029879614710808 0.30914226174354553 0.03724353015422821 -0.9501336812973022"/>
        <geom class="collision" type="box" pos="-0.120403 -0.093285 0.080773" size="0.008495884947478771 0.011557872407138348 0.002193313091993332" quat="0.7361759543418884 0.3175431489944458 -0.1714431494474411 -0.5725544095039368"/>
        <geom class="collision" type="box" pos="-0.119537 0.124559 0.040299" size="0.006499781738966703 0.036533769220113754 0.007362739183008671" quat="0.16748973727226257 0.18874789774417877 -0.6277307868003845 -0.7363935708999634"/>
        <geom class="collision" type="box" pos="-0.124719 0.111108 0.040930" size="0.010736622847616673 0.03653202950954437 0.007356568705290556" quat="0.39171677827835083 0.4041488766670227 -0.5350667238235474 -0.630020022392273"/>
        <geom class="collision" type="box" pos="-0.122611 0.102598 0.079746" size="0.008495884947478771 0.011557867750525475 0.0021933196112513542" quat="0.6100724935531616 0.10540375858545303 -0.32175377011299133 -0.7163631319999695"/>
        <geom class="collision" type="box" pos="-0.123305 -0.112514 0.034896" size="0.013241260312497616 0.03169574588537216 0.003492534626275301" quat="0.7559158205986023 0.588578999042511 -0.19327609241008759 -0.21168452501296997"/>
        <body name="Button001">
          <joint axis="5.4484054601289245e-08 1.0 7.4505797087454084e-09" pos="-0.045311 -0.136791 -0.002013" limited="true" name="Button001_joint" range="0.0 0.002" type="slide" damping="1" frictionloss="1" armature=".01" stiffness="0.05"/>
          <geom mesh="Button001_vis" type="mesh" solimp="0.998 0.998 0.001" solref="0.001 1" density="100" friction="0.95 0.3 0.1" class="visual" material="Button001_material"/>
          <geom class="collision" type="cylinder" pos="-0.045321 -0.136959 -0.001918" size="0.0049980077892541885 0.0010298885172232985" quat="0.672938883304596 -0.7393617033958435 0.0030973360408097506 -0.02209004946053028"/>
        </body>
        <body name="Button002">
          <joint axis="5.4484054601289245e-08 1.0 7.4505797087454084e-09" pos="-0.045311 -0.136791 -0.002013" limited="true" name="Button002_joint" range="0.0 0.002" type="slide" damping="1" frictionloss="1" armature=".01" stiffness="0.05"/>
          <geom mesh="Button002_vis" type="mesh" solimp="0.998 0.998 0.001" solref="0.001 1" density="100" friction="0.95 0.3 0.1" class="visual" material="Button002_material"/>
          <geom class="collision" type="cylinder" pos="0.045321 -0.136959 -0.001918" size="0.005051110405474901 0.001294005662202835" quat="0.672938883304596 -0.7393617033958435 0.0030973360408097506 -0.02209004946053028"/>
        </body>
        <body name="Knob001">
          <joint axis="0.05303703248500824 0.986242413520813 -0.1565660834312439" pos="-0.078145 -0.145584 -0.007998" limited="true" name="Knob001_joint" range="0.0 4.363323129985823" type="hinge" damping="0.05" armature="0.001"/>
          <geom mesh="Knob001_vis" type="mesh" solimp="0.998 0.998 0.001" solref="0.001 1" density="100" friction="0.95 0.3 0.1" class="visual" material="Knob001_material"/>
          <geom class="collision" type="cylinder" pos="-0.077689 -0.140793 -0.007982" size="0.01729784719645977 0.0048811291344463825" quat="0.7575387358665466 0.651417076587677 -0.04188086465001106 0.006074876058846712"/>
        </body>
        <body name="Knob002">
          <joint axis="-0.08777428418397903 0.9839770197868347 -0.15519365668296814" pos="0.078145 -0.145584 -0.007998" limited="true" name="Knob002_joint" range="0.0 4.4505895925855405" type="hinge" damping="0.05" armature="0.001"/>
          <geom mesh="Knob002_vis" type="mesh" solimp="0.998 0.998 0.001" solref="0.001 1" density="100" friction="0.95 0.3 0.1" class="visual" material="Knob002_material"/>
          <geom class="collision" type="cylinder" pos="0.077476 -0.141627 -0.008555" size="0.01714215613901615 0.004297501407563686" quat="0.758222222328186 0.6504478454589844 0.040635641664266586 0.019116215407848358"/>
        </body>
        <body name="Lever001">
          <joint axis="0.0 0.0 -1.0" pos="-0.000050 -0.144987 0.034858" limited="true" name="Lever001_joint" range="0.0 0.081" type="slide" damping="1" frictionloss="1" armature=".01" stiffness="1" springref="-0.26"/>
          <geom mesh="Lever001_vis" type="mesh" solimp="0.998 0.998 0.001" solref="0.001 1" density="100" friction="0.95 0.3 0.1" class="visual" material="Lever001_material"/>
          <geom class="collision" type="box" pos="-0.015642 -0.147288 0.036076" size="0.012798125855624676 0.006338323932141066 0.002866016235202551" quat="0.9910058379173279 -0.1338185966014862 -2.971369741399914e-17 -2.240158486485732e-24" name="sideL_lever_knob"/>
          <geom class="collision" type="box" pos="-0.073221 0.003742 0.087554" size="0.007070660591125488 0.07763006538152695 0.00268406979739666" quat="1.0 0.0 0.0 0.0" name="sideL_slotL_floor"/>
          <geom class="collision" type="box" pos="-0.028738 0.003742 0.087554" size="0.007070661522448063 0.07763006538152695 0.00268406979739666" quat="1.0 0.0 0.0 0.0" name="sideL_slotR_floor"/>
          <geom class="collision" type="box" pos="-0.015834 -0.137470 0.033453" size="0.0014539575204253197 0.0041389563120901585 0.0014539575204253197" quat="0.9923955798149109 -0.12308938056230545 -2.733138085389947e-17 -1.0360813932195005e-23"/>
        </body>
        <body name="Lever002">
          <joint axis="0.0 0.0 -1.0" pos="-0.000050 -0.144987 0.034858" limited="true" name="Lever002_joint" range="0.0 0.081" type="slide" damping="1" frictionloss="1" armature=".01" stiffness="1" springref="-0.26"/>
          <geom mesh="Lever002_vis" type="mesh" solimp="0.998 0.998 0.001" solref="0.001 1" density="100" friction="0.95 0.3 0.1" class="visual" material="Lever002_material"/>
          <geom class="collision" type="box" pos="0.015913 -0.147288 0.036076" size="0.012798125855624676 0.006338323932141066 0.002866016235202551" quat="0.9910058379173279 -0.1338185966014862 -2.971369741399914e-17 -2.240158486485732e-24" name="sideR_lever_knob"/>
          <geom class="collision" type="box" pos="0.073746 0.003742 0.087554" size="0.007070661522448063 0.07763006538152695 0.00268406979739666" quat="1.0 0.0 0.0 0.0" name="sideR_slotR_floor"/>
          <geom class="collision" type="box" pos="0.028308 0.003742 0.087554" size="0.006357132922858 0.07763006538152695 0.0026840700302273035" quat="1.0 0.0 0.0 0.0" name="sideR_slotL_floor"/>
          <geom class="collision" type="box" pos="0.016166 -0.137456 0.033429" size="0.0014539575204253197 0.0041389563120901585 0.0014539574040099978" quat="0.9941444993019104 -0.1080588549375534 -2.3993885753260315e-17 1.3343983544798946e-24"/>
        </body>
        <geom class="region" name="reg_main" type="box" pos="-1.7500000000003624e-05 0.007454000000000002 -3.399999999999931e-05" size="0.1475575 0.146936 0.093495"/>
      </body>
    </body>
  </worldbody>
  <actuator>
    <motor name="Button001_joint_actuator" joint="Button001_joint" gear="0.5"/>
    <motor name="Button002_joint_actuator" joint="Button002_joint" gear="0.5"/>
    <motor name="Knob001_joint_actuator" joint="Knob001_joint" gear="5"/>
    <motor name="Knob002_joint_actuator" joint="Knob002_joint" gear="5"/>
    <motor name="Lever001_joint_actuator" joint="Lever001_joint" gear="2"/>
    <motor name="Lever002_joint_actuator" joint="Lever002_joint" gear="2"/>
  </actuator>
</mujoco>
