<?xml version='1.0' encoding='UTF-8'?>
<mujoco model="model">
  <compiler angle="radian"/>
  <asset>
    <mesh file="visuals/Body001.obj" name="Body001_vis"/>
    <mesh file="visuals/Button001.obj" name="Button001_vis"/>
    <mesh file="visuals/Container001.obj" name="Container001_vis"/>
    <mesh file="visuals/Container002.obj" name="Container002_vis"/>
    <mesh file="visuals/Container003.obj" name="Container003_vis"/>
    <mesh file="visuals/Door001.obj" name="Door001_vis"/>
    <mesh file="visuals/Door001_Clear.obj" name="Door001_Clear_vis"/>
    <mesh file="visuals/Knob001.obj" name="Knob001_vis"/>
    <mesh file="visuals/Knob002.obj" name="Knob002_vis"/>
    <mesh file="visuals/Knob003.obj" name="Knob003_vis"/>
    <texture file="visuals/T_BC001.png" name="Body001_material" type="2d"/>
    <material name="Body001_material" rgba="1 1 1 1.0" texture="Body001_material" shininess="0.46335369348526" specular="1"/>
    <texture file="visuals/T_BC001.png" name="Button001_material" type="2d"/>
    <material name="Button001_material" rgba="1 1 1 1.0" texture="Button001_material" shininess="0.46335369348526" specular="0.3103448502657381"/>
    <texture file="visuals/T_BC001.png" name="Container001_material" type="2d"/>
    <material name="Container001_material" rgba="1 1 1 1.0" texture="Container001_material" shininess="0.46335369348526" specular="2"/>
    <texture file="visuals/T_BC001.png" name="Container002_material" type="2d"/>
    <material name="Container002_material" rgba="1 1 1 1.0" texture="Container002_material" shininess="0.46335369348526" specular="2"/>
    <texture file="visuals/T_BC001.png" name="Container003_material" type="2d"/>
    <material name="Container003_material" rgba="1 1 1 1.0" texture="Container003_material" shininess="0.46335369348526" specular="2"/>
    <texture file="visuals/T_BC001.png" name="Door001_material" type="2d"/>
    <material name="Door001_material" rgba="1 1 1 1.0" texture="Door001_material" shininess="0.46335369348526" specular="0.5"/>
    <texture file="visuals/T_BC001.png" name="Door001_Clear_material" type="2d"/>
    <material name="Door001_Clear_material" rgba="1 1 1 0.800000011920929" texture="Door001_Clear_material" shininess="0.46335369348526" specular="0.3103448502657381"/>
    <texture file="visuals/T_BC001.png" name="Knob001_material" type="2d"/>
    <material name="Knob001_material" rgba="1 1 1 1.0" texture="Knob001_material" shininess="0.46335369348526" specular="0.3103448502657381"/>
    <texture file="visuals/T_BC001.png" name="Knob002_material" type="2d"/>
    <material name="Knob002_material" rgba="1 1 1 1.0" texture="Knob002_material" shininess="0.46335369348526" specular="0.3103448502657381"/>
    <texture file="visuals/T_BC001.png" name="Knob003_material" type="2d"/>
    <material name="Knob003_material" rgba="1 1 1 1.0" texture="Knob003_material" shininess="0.46335369348526" specular="0.3103448502657381"/>
  </asset>
  <default>
    <default class="visual">
      <geom conaffinity="0" contype="0" group="1" type="mesh"/>
    </default>
    <default class="collision">
      <geom group="0" rgba="0.5 0 0 0.5"/>
    </default>
    <default class="spawn">
      <geom group="0" rgba="1 1 1 0.5" contype="0" conaffinity="0"/>
      <site group="0" rgba="1 1 1 0.5"/>
    </default>
    <default class="region">
      <geom group="1" conaffinity="0" contype="0" rgba="0 1 0 0"/>
    </default>
  </default>
  <worldbody>
    <body>
      <body name="object">
        <geom mesh="Body001_vis" type="mesh" solimp="0.998 0.998 0.001" solref="0.001 1" density="100" friction="0.95 0.3 0.1" class="visual" material="Body001_material"/>
        <geom class="collision" type="box" pos="0.000780 0.030345 0.109925" size="0.16061347723007202 0.14468711614608765 0.07012737542390823" quat="1.0 0.0 0.0 0.0"/>
        <geom class="collision" type="box" pos="-0.137577 0.030345 -0.044540" size="0.02375228889286518 0.1446872055530548 0.08284192532300949" quat="1.0 0.0 0.0 0.0"/>
        <geom class="collision" type="box" pos="0.143967 0.030345 -0.044540" size="0.01742846518754959 0.14468730986118317 0.08284202963113785" quat="1.0 0.0 0.0 0.0"/>
        <geom class="collision" type="box" pos="0.000288 0.010473 -0.163519" size="0.16161443293094635 0.16455820202827454 0.01666225492954254" quat="1.0 0.0 0.0 0.0"/>
        <geom class="collision" type="box" pos="0.006494 0.140180 -0.044540" size="0.11938363313674927 0.03485395759344101 0.08284222334623337" quat="1.0 0.0 0.0 0.0"/>
        <geom class="collision" type="box" pos="0.000545 -0.139501 0.103502" size="0.1298017054796219 0.02530284784734249 0.03628608584403992" quat="1.0 0.0 0.0 0.0"/>
        <geom class="collision" type="box" pos="-0.008158 -0.134620 0.160787" size="0.15167555212974548 0.020421400666236877 0.019265707582235336" quat="1.0 0.0 0.0 0.0"/>
        <geom class="collision" type="box" pos="0.000288 0.030827 -0.137046" size="0.16161522269248962 0.14420586824417114 0.009902648627758026" quat="1.0 0.0 0.0 0.0"/>
        <body name="Button001">
          <joint axis="0.0 0.9974946975708008 -0.07074242830276489" pos="-0.039324 -0.171251 0.069007" limited="true" name="Button001_joint" range="0.0 0.001" type="slide" damping="1" frictionloss="1" armature=".01" stiffness="0.2" springref="-0.1"/>
          <geom mesh="Button001_vis" type="mesh" solimp="0.998 0.998 0.001" solref="0.001 1" density="100" friction="0.95 0.3 0.1" class="visual" material="Button001_material"/>
          <geom class="collision" type="box" pos="-0.039368 -0.171318 0.069089" size="0.008868260309100151 0.0014868775615468621 0.0035575367510318756" quat="0.9989315271377563 -0.04621449112892151 -0.0 0.0"/>
        </body>
        <body name="Container001">
          <joint axis="0.0 -1.0 0.0" pos="0.005731 -0.002453 -0.022143" limited="true" name="Container001_joint" range="0.0 0.15" type="slide" damping="1" frictionloss="1" armature=".01" stiffness="0.05"/>
          <geom mesh="Container001_vis" type="mesh" solimp="0.998 0.998 0.001" solref="0.001 1" density="100" friction="0.95 0.3 0.1" class="visual" material="Container001_material"/>
          <geom class="collision" type="box" pos="0.005384 -0.002396 -0.016364" size="0.11825599521398544 0.10547793656587601 0.00403330335393548" quat="1.0 0.0 0.0 0.0"/>
          <geom class="collision" type="box" pos="0.005644 0.001194 -0.025210" size="0.09416749328374863 0.0793447196483612 0.004907288588583469" quat="1.0 0.0 0.0 0.0"/>
        </body>
        <body name="Container002">
          <joint axis="0.0 -1.0 0.0" pos="0.005731 -0.002453 -0.097409" limited="true" name="Container002_joint" range="0.0 0.15" type="slide" damping="1" frictionloss="1" armature=".01" stiffness="0.05"/>
          <geom mesh="Container002_vis" type="mesh" solimp="0.998 0.998 0.001" solref="0.001 1" density="100" friction="0.95 0.3 0.1" class="visual" material="Container002_material"/>
          <geom class="collision" type="box" pos="0.005384 -0.002396 -0.092863" size="0.11825652420520782 0.10547840595245361 0.004033319652080536" quat="1.0 0.0 0.0 0.0"/>
          <geom class="collision" type="box" pos="0.005644 0.001194 -0.101709" size="0.09416777640581131 0.07934508472681046 0.004907308612018824" quat="1.0 0.0 0.0 0.0"/>
        </body>
        <body name="Container003">
          <joint axis="0.0 -1.0 0.0" pos="0.005731 -0.002453 -0.067855" limited="true" name="Container003_joint" range="0.0 0.15" type="slide" damping="1" frictionloss="1" armature=".01" stiffness="0.05"/>
          <geom mesh="Container003_vis" type="mesh" solimp="0.998 0.998 0.001" solref="0.001 1" density="100" friction="0.95 0.3 0.1" class="visual" material="Container003_material"/>
          <geom class="collision" type="box" pos="0.005644 0.001194 -0.071730" size="0.094167560338974 0.07934480905532837 0.00490729371085763" quat="1.0 0.0 0.0 0.0"/>
          <geom class="collision" type="box" pos="0.005384 -0.002396 -0.062884" size="0.11825640499591827 0.10547828674316406 0.00403331546112895" quat="1.0 0.0 0.0 0.0"/>
        </body>
        <body name="Door001">
          <joint axis="1.0 0.0 0.0" pos="0.000002 -0.153725 -0.143995" limited="true" name="Door001_joint" range="0.0 1.5707963267948966" type="hinge" damping="1" frictionloss="1" armature=".01" stiffness="0.05"/>
          <geom mesh="Door001_vis" type="mesh" solimp="0.998 0.998 0.001" solref="0.001 1" density="100" friction="0.95 0.3 0.1" class="visual" material="Door001_material"/>
          <geom class="collision" type="box" pos="0.132284 -0.140621 -0.044935" size="0.025965455919504166 0.013554784469306469 0.09866119176149368" quat="1.0 0.0 0.0 0.0"/>
          <geom class="collision" type="box" pos="-0.132047 -0.140621 -0.044935" size="0.025965480133891106 0.013554798439145088 0.09866128116846085" quat="1.0 0.0 0.0 0.0"/>
          <geom class="collision" type="box" pos="0.000841 -0.141223 -0.131636" size="0.10678219050168991 0.014157172292470932 0.011961422860622406" quat="1.0 0.0 0.0 0.0"/>
          <geom class="collision" type="box" pos="0.000841 -0.140621 0.037532" size="0.10678228735923767 0.013554824516177177 0.016924336552619934" quat="1.0 0.0 0.0 0.0"/>
          <geom class="collision" type="box" pos="0.000165 -0.169141 0.048514" size="0.12886179983615875 0.015012511983513832 0.005942168179899454" quat="1.0 0.0 0.0 0.0"/>
          <geom class="collision" type="box" pos="0.000165 -0.180388 0.044267" size="0.12886181473731995 0.0037650850135833025 0.010189743712544441" quat="1.0 0.0 0.0 0.0"/>
          <geom class="collision" type="box" pos="-0.116655 -0.168975 0.044267" size="0.012041772715747356 0.01517821941524744 0.010189744643867016" quat="1.0 0.0 0.0 0.0"/>
          <geom class="collision" type="box" pos="0.116460 -0.168975 0.044267" size="0.012041773647069931 0.015178222209215164 0.010189746506512165" quat="1.0 0.0 0.0 0.0"/>
          <body name="Door001_Clear">
            <geom mesh="Door001_Clear_vis" type="mesh" solimp="0.998 0.998 0.001" solref="0.001 1" density="100" friction="0.95 0.3 0.1" class="visual" material="Door001_Clear_material"/>
            <geom class="collision" type="box" pos="0.000522 -0.151707 -0.049569" size="0.11034350842237473 0.0024680648930370808 0.07375513762235641" quat="1.0 0.0 0.0 0.0"/>
          </body>
        </body>
        <body name="Knob001">
          <joint axis="0.0 0.9961931109428406 -0.08717270940542221" pos="-0.075229 -0.176559 0.096388" limited="true" name="Knob001_joint" range="0.0 4.71238898038469" type="hinge" damping="0.05" armature="0.001"/>
          <geom mesh="Knob001_vis" type="mesh" solimp="0.998 0.998 0.001" solref="0.001 1" density="100" friction="0.95 0.3 0.1" class="visual" material="Knob001_material"/>
          <geom class="collision" type="cylinder" pos="-0.075120 -0.171560 0.095874" size="0.012214718386530876 0.0014650241937488317" quat="0.7384907603263855 0.674263596534729 0.0 0.0"/>
          <geom class="collision" type="box" pos="-0.075076 -0.179148 0.096679" size="0.004723309073597193 0.006342465057969093 0.011634760536253452" quat="0.9989585280418396 -0.04562760144472122 -0.0 0.0"/>
        </body>
        <body name="Knob002">
          <joint axis="0.0 0.9959583282470703 -0.08981510996818542" pos="0.000022 -0.176559 0.096388" limited="true" name="Knob002_joint" range="0.0 5.410520681182422" type="hinge" damping="0.05" armature="0.001"/>
          <geom mesh="Knob002_vis" type="mesh" solimp="0.998 0.998 0.001" solref="0.001 1" density="100" friction="0.95 0.3 0.1" class="visual" material="Knob002_material"/>
          <geom class="collision" type="cylinder" pos="0.000058 -0.171564 0.095874" size="0.012114203535020351 0.0014273510314524174" quat="0.7384907603263855 0.674263596534729 0.0 0.0"/>
          <geom class="collision" type="box" pos="0.000003 -0.179148 0.096679" size="0.004723309073597193 0.006342465057969093 0.011634760536253452" quat="0.9989585280418396 -0.04562760144472122 -0.0 0.0"/>
        </body>
        <body name="Knob003">
          <joint axis="0.0 0.9960722327232361 -0.08854477107524872" pos="0.075060 -0.176559 0.096388" limited="true" name="Knob003_joint" range="0.0 4.71238898038469" type="hinge" damping="0.05" armature="0.001"/>
          <geom mesh="Knob003_vis" type="mesh" solimp="0.998 0.998 0.001" solref="0.001 1" density="100" friction="0.95 0.3 0.1" class="visual" material="Knob003_material"/>
          <geom class="collision" type="cylinder" pos="0.075140 -0.171620 0.095880" size="0.012140058912336826 0.0014937188243493438" quat="0.7384907603263855 0.674263596534729 0.0 0.0"/>
          <geom class="collision" type="box" pos="0.074992 -0.179148 0.096679" size="0.004723309073597193 0.006342465057969093 0.011634760536253452" quat="0.9989585280418396 -0.04562760144472122 -0.0 0.0"/>
        </body>
        <geom class="region" name="reg_main" type="box" pos="4.000000000004e-06 0.014935500000000004 0.0" size="0.162939 0.17118450000000002 0.182033"/>
        <geom class="region" name="reg_int" type="box" pos="0.005472999999999992 -0.0031999999999999945 -0.04321749999999999" size="0.121345 0.110208 0.0831335"/>
      </body>
    </body>
  </worldbody>
  <actuator>
    <motor name="Button001_joint_actuator" joint="Button001_joint" gear="0.5"/>
    <motor name="Container001_joint_actuator" joint="Container001_joint" gear="10"/>
    <motor name="Container002_joint_actuator" joint="Container002_joint" gear="10"/>
    <motor name="Container003_joint_actuator" joint="Container003_joint" gear="10"/>
    <motor name="Door001_joint_actuator" joint="Door001_joint" gear="50"/>
    <motor name="Knob001_joint_actuator" joint="Knob001_joint" gear="50"/>
    <motor name="Knob002_joint_actuator" joint="Knob002_joint" gear="50"/>
    <motor name="Knob003_joint_actuator" joint="Knob003_joint" gear="50"/>
  </actuator>
</mujoco>
