<mujoco model="model">
  <compiler angle="radian"/>
  <asset>
    <mesh file="visuals/Blade001.obj" name="Blade001_vis"/>
    <mesh file="visuals/Body001.obj" name="Body001_vis"/>
    <mesh file="visuals/Button001.obj" name="Button001_vis"/>
    <mesh file="visuals/Jug001.obj" name="Jug001_vis"/>
    <mesh file="visuals/Jug001_Clear.obj" name="Jug001_Clear_vis"/>
    <mesh file="visuals/Knob001.obj" name="Knob001_vis"/>
    <mesh file="visuals/Lid001.obj" name="Lid001_vis"/>
    <texture file="visuals/T_BC001.png" name="Body001_material" type="2d"/>
    <material name="Body001_material" rgba="1 1 1 1.0" texture="Body001_material" shininess="0.4472135901451111" specular="1"/>
    <texture file="visuals/T_BC001.png" name="Button001_material" type="2d"/>
    <material name="Button001_material" rgba="1 1 1 1.0" texture="Button001_material" shininess="0.4472135901451111" specular="0.3103448502657381"/>
    <texture file="visuals/T_BC001.png" name="Jug001_Clear_material" type="2d"/>
    <material name="Jug001_Clear_material" rgba="1 1 1 0.4000000059604645" texture="Jug001_Clear_material" shininess="0.4472135901451111" specular="0.8"/>
    <texture file="visuals/T_BC001.png" name="Blade001_material" type="2d"/>
    <material name="Blade001_material" rgba="1 1 1 1.0" texture="Blade001_material" shininess="0.4472135901451111" specular="0.3103448502657381"/>
    <texture file="visuals/T_BC001.png" name="Jug001_material" type="2d"/>
    <material name="Jug001_material" rgba="1 1 1 1.0" texture="Jug001_material" shininess="0.4472135901451111" specular="2"/>
    <texture file="visuals/T_BC001.png" name="Lid001_material" type="2d"/>
    <material name="Lid001_material" rgba="1 1 1 1.0" texture="Lid001_material" shininess="0.4472135901451111" specular="0.3103448502657381"/>
    <texture file="visuals/T_BC001.png" name="Knob001_material" type="2d"/>
    <material name="Knob001_material" rgba="1 1 1 1.0" texture="Knob001_material" shininess="0.4472135901451111" specular="0.3"/>
  </asset>
  <default>
    <default class="visual">
      <geom conaffinity="0" contype="0" group="1" type="mesh"/>
    </default>
    <default class="collision">
      <geom group="0" rgba="0.5 0 0 0.5"/>
    </default>
    <default class="spawn">
      <geom group="0" rgba="1 1 1 0.5" contype="0" conaffinity="0"/>
      <site group="0" rgba="1 1 1 0.5"/>
    </default>
    <default class="region">
      <geom group="1" conaffinity="0" contype="0" rgba="0 1 0 0"/>
    </default>
  </default>
  <worldbody>
    <body>
      <body name="object">
        <geom mesh="Body001_vis" type="mesh" solimp="0.998 0.998 0.001" solref="0.001 1" density="100" friction="0.95 0.3 0.1" class="visual" material="Body001_material"/>
        <geom class="collision" type="cylinder" pos="-0.000004 0.000702 -0.099760" size="0.05027838423848152 0.050639983266592026" quat="1.0 0.0 0.0 0.0"/>
        <geom class="collision" type="box" pos="-0.000433 -0.053805 -0.111410" size="0.02084752358496189 0.00483823474496603 0.020090635865926743" quat="1.0 0.0 0.0 0.0"/>
        <geom class="collision" type="box" pos="-0.000175 -0.048544 -0.043204" size="0.02063511684536934 0.00401512673124671 0.008426142856478691" quat="1.0 0.0 0.0 0.0"/>
        <geom class="collision" type="box" pos="-0.053646 0.000702 -0.138536" size="0.004174570087343454 0.010854005813598633 0.010854005813598633" quat="0.985356867313385 5.595070839132361e-16 -0.17050467431545258 -2.290881262467792e-08"/>
        <geom class="collision" type="box" pos="-0.054054 0.000702 -0.082171" size="0.004025053698569536 0.010854005813598633 0.047436073422431946" quat="0.9993108510971069 3.921987009518433e-16 0.03711973503232002 4.987374513376608e-09"/>
        <geom class="collision" type="box" pos="-0.050305 0.019337 -0.138536" size="0.004174570087343454 0.010854005813598633 0.010854005813598633" quat="0.9698918461799622 -0.030089758336544037 -0.16782867908477783 -0.17389050126075745"/>
        <geom class="collision" type="box" pos="-0.041065 0.035219 -0.138536" size="0.004174570087343454 0.010854005813598633 0.010854004882276058" quat="0.9257819652557373 -0.05838760733604431 -0.16019588708877563 -0.33742547035217285"/>
        <geom class="collision" type="box" pos="-0.026516 0.047334 -0.138536" size="0.004174570087343454 0.010854005813598633 0.010854004882276058" quat="0.8517047762870789 -0.08574175089597702 -0.14737769961357117 -0.4955069422721863"/>
        <geom class="collision" type="box" pos="-0.010051 -0.051992 -0.138536" size="0.004174570087343454 0.010854005813598633 0.010854004882276058" quat="0.7592028379440308 0.1086895614862442 -0.13137130439281464 0.6281235814094543"/>
        <geom class="collision" type="box" pos="-0.027731 -0.045219 -0.138536" size="0.004174570087343454 0.010854005813598633 0.010854004882276058" quat="0.8581354022026062 0.08379990607500076 -0.14849039912223816 0.4842848777770996"/>
        <geom class="collision" type="box" pos="-0.041601 -0.033169 -0.138536" size="0.004174570087343454 0.010854004882276058 0.010854004882276058" quat="0.9283958673477173 0.057131316512823105 -0.1606481820344925 0.33016547560691833"/>
        <geom class="collision" type="box" pos="-0.050777 -0.016608 -0.138536" size="0.004174570087343454 0.010854005813598633 0.010854005813598633" quat="0.9720907211303711 0.02788436971604824 -0.1682092845439911 0.1611451357603073"/>
        <geom class="collision" type="box" pos="0.049844 -0.019117 -0.138536" size="0.004174570087343454 0.010854004882276058 0.010854004882276058" quat="0.18532882630825043 0.16746164858341217 -0.03206900879740715 0.9677713513374329"/>
        <geom class="collision" type="box" pos="0.039854 -0.035200 -0.138536" size="0.004174570087343454 0.010854005813598633 0.010854004882276058" quat="0.35320740938186646 0.15917399525642395 -0.06111845746636391 0.9198764562606812"/>
        <geom class="collision" type="box" pos="0.025401 -0.046544 -0.138536" size="0.004174570087343454 0.010854005813598633 0.010854004882276058" quat="0.5055273175239563 0.14635516703128815 -0.08747565746307373 0.8457956910133362"/>
        <geom class="collision" type="box" pos="0.007405 -0.052427 -0.138536" size="0.004174570087343454 0.010854005813598633 0.010854004882276058" quat="0.646854817867279 0.12862089276313782 -0.1119307428598404 0.7433081865310669"/>
        <geom class="collision" type="box" pos="0.029170 0.045717 -0.138536" size="0.004174570087343454 0.010854004882276058 0.010854005813598633" quat="0.4705747365951538 -0.1498044729232788 -0.08142750710248947 -0.8657295107841492"/>
        <geom class="collision" type="box" pos="0.042992 0.032778 -0.138536" size="0.004174570087343454 0.010854006744921207 0.010854005813598633" quat="0.3104095458984375 -0.16182319819927216 -0.05371277779340744 -0.9351866841316223"/>
        <geom class="collision" type="box" pos="0.051295 0.016387 -0.138536" size="0.004174570087343454 0.010854005813598633 0.010854004882276058" quat="0.145663321018219 -0.16863130033016205 -0.02520536258816719 -0.9745308756828308"/>
        <geom class="collision" type="box" pos="0.053549 -0.002411 -0.138536" size="0.004174570087343454 0.010854005813598633 0.010854006744921207" quat="0.028603164479136467 0.17043240368366241 -0.004949431866407394 0.9849417209625244"/>
        <geom class="collision" type="box" pos="-0.019830 0.050546 -0.138536" size="0.004174570087343454 0.010854005813598633 0.010854004882276058" quat="0.8154098391532898 -0.09572560340166092 -0.14109724760055542 -0.5532042980194092"/>
        <geom class="collision" type="box" pos="-0.001847 0.054312 -0.138536" size="0.004174570087343454 0.010854004882276058 0.010854004882276058" quat="0.7086209058761597 -0.11847569048404694 -0.1226186603307724 -0.6846784949302673"/>
        <geom class="collision" type="box" pos="0.016893 0.051613 -0.138536" size="0.004174570087343454 0.010854005813598633 0.010854005813598633" quat="0.5766705870628357 -0.13825532793998718 -0.0997861847281456 -0.7989863753318787"/>
        <geom class="collision" type="box" pos="-0.027756 -0.045680 -0.082171" size="0.004025053698569536 0.010854003950953484 0.04743606224656105" quat="0.8693017959594727 -0.018308410421013832 0.0322905033826828 0.49288591742515564"/>
        <geom class="collision" type="box" pos="-0.041645 -0.033759 -0.082171" size="0.004025053698569536 0.010854006744921207 0.047436073422431946" quat="0.9402043223381042 -0.012576751410961151 0.034924205392599106 0.33858224749565125"/>
        <geom class="collision" type="box" pos="-0.050955 -0.017338 -0.082171" size="0.004025053698569536 0.010854006744921207 0.047436073422431946" quat="0.9848824739456177 -0.0062849693931639194 0.03658372536301613 0.16919994354248047"/>
        <geom class="collision" type="box" pos="-0.011973 0.053410 -0.082171" size="0.004025053698569536 0.010854005813598633 0.047436073422431946" quat="0.7809489965438843 0.023159775882959366 0.029008612036705017 -0.6234908103942871"/>
        <geom class="collision" type="box" pos="-0.051380 0.017494 -0.082171" size="0.004025053698569536 0.010854004882276058 0.047436073422431946" quat="0.9868703484535217 0.005838927812874317 0.03665770962834358 -0.1571912169456482"/>
        <geom class="collision" type="box" pos="-0.042829 0.033678 -0.082171" size="0.004025053698569536 0.010854005813598633 0.047436073422431946" quat="0.9460065364837646 0.011961388401687145 0.035139743238687515 -0.3220151960849762"/>
        <geom class="collision" type="box" pos="-0.028878 0.046394 -0.082171" size="0.004025053698569536 0.010854005813598633 0.047436073422431946" quat="0.8752408027648926 0.01791374571621418 0.032511115074157715 -0.48226097226142883"/>
        <geom class="collision" type="box" pos="0.037899 0.039236 -0.082171" size="0.004025053698569536 0.010854004882276058 0.047436073422431946" quat="0.3862343728542328 0.034235093742609024 0.014346794225275517 -0.9216535091400146"/>
        <geom class="collision" type="box" pos="0.004629 0.054553 -0.082171" size="0.004025053698569536 0.010854005813598633 0.047436073422431946" quat="0.6756603717803955 0.027349242940545082 0.02509756200015545 -0.7362779378890991"/>
        <geom class="collision" type="box" pos="0.022865 0.049676 -0.082171" size="0.004025053698569536 0.010854004882276058 0.047436073422431946" quat="0.5367090106010437 0.031311675906181335 0.019936243072152138 -0.8429505228996277"/>
        <geom class="collision" type="box" pos="0.045968 -0.027727 -0.082171" size="0.004025053698569536 0.010854005813598633 0.047436073422431946" quat="0.2732015550136566 -0.03570559248328209 0.010148162953555584 0.9612403512001038"/>
        <geom class="collision" type="box" pos="0.047995 0.025553 -0.082171" size="0.004025053698569536 0.010854005813598633 0.047436073422431946" quat="0.23645034432411194 0.03606566786766052 0.008783024735748768 -0.970934271812439"/>
        <geom class="collision" type="box" pos="0.053537 0.008109 -0.082171" size="0.004025053698569536 0.010854005813598633 0.04743606969714165" quat="0.06864112615585327 0.03703197091817856 0.002549691591411829 -0.996950626373291"/>
        <geom class="collision" type="box" pos="0.052819 -0.010754 -0.082171" size="0.004025053698569536 0.010854004882276058 0.047436073422431946" quat="0.10650292783975601 -0.03690831735730171 0.003956086467951536 0.9936192631721497"/>
        <geom class="collision" type="box" pos="0.034532 -0.040877 -0.082171" size="0.004025053698569536 0.010854005813598633 0.047436073422431946" quat="0.4245893955230713 -0.033602576702833176 0.01577151007950306 0.9046247601509094"/>
        <geom class="collision" type="box" pos="0.022509 -0.048438 -0.082171" size="0.004025053698569536 0.010854005813598633 0.04743606597185135" quat="0.5397603511810303 -0.031239204108715057 0.0200495645403862 0.840999960899353"/>
        <geom class="collision" type="box" pos="-0.021988 -0.048676 -0.082171" size="0.004025051835924387 0.010854003019630909 0.047436054795980453" quat="0.838092565536499 -0.02021685428917408 0.031131206080317497 0.5442637205123901"/>
        <body name="Button001">
          <joint axis="0.0 1.0 0.0" pos="-0.000039 -0.051427 -0.057225" limited="true" name="Button001_joint" range="0.0 0.002" type="slide" damping="1" frictionloss="1" armature=".01" stiffness="0.05"/>
          <geom mesh="Button001_vis" type="mesh" solimp="0.998 0.998 0.001" solref="0.001 1" density="100" friction="0.95 0.3 0.1" class="visual" material="Button001_material"/>
          <geom class="collision" type="box" pos="-0.000233 -0.052200 -0.057080" size="0.00738384947180748 0.0018029806669801474 0.003648989135399461" quat="1.0 0.0 0.0 0.0"/>
        </body>
        <body name="Jug001_Clear">
          <joint axis="0.0 0.0 1.0" pos="-0.000083 0.000814 0.050167" limited="true" name="Jug001_Clear_joint" range="0.0 0.05" type="slide" damping="1" frictionloss="1" armature=".01" stiffness="0.05"/>
          <geom mesh="Jug001_Clear_vis" type="mesh" solimp="0.998 0.998 0.001" solref="0.001 1" density="100" friction="0.95 0.3 0.1" class="visual" material="Jug001_Clear_material"/>
          <geom class="collision" type="box" pos="0.043332 0.000702 0.012597" size="0.0035044727846980095 0.012674807570874691 0.04332708194851875" quat="0.9983056783676147 1.9805163436440072e-15 -0.05818738788366318 -7.81798892290908e-09"/>
          <geom class="collision" type="box" pos="0.041321 0.000702 0.101358" size="0.0035068036522716284 0.012674807570874691 0.048212192952632904" quat="0.9992659687995911 2.693093398433528e-15 0.03830773010849953 5.146990389448547e-09"/>
          <geom class="collision" type="box" pos="0.037968 0.021586 0.012597" size="0.003504473017528653 0.012674807570874691 0.04332708567380905" quat="0.9669170379638672 0.014476297423243523 -0.05635787919163704 0.24836596846580505"/>
          <geom class="collision" type="box" pos="0.036206 0.020617 0.101358" size="0.003506803885102272 0.012674806639552116 0.0482121966779232" quat="0.9678471684455872 -0.009530461393296719 0.03710317239165306 0.248604878783226"/>
          <geom class="collision" type="box" pos="0.023699 0.036981 0.012597" size="0.003504473017528653 0.012674807570874691 0.04332708194851875" quat="0.8779835104942322 0.02769414521753788 -0.05117426812648773 0.4751411974430084"/>
          <geom class="collision" type="box" pos="0.022599 0.035297 0.101358" size="0.003506803885102272 0.012674807570874691 0.0482121966779232" quat="0.8788281083106995 -0.018232425674796104 0.03369055688381195 0.47559821605682373"/>
          <geom class="collision" type="box" pos="0.003281 0.043913 0.012597" size="0.003504473017528653 0.012674807570874691 0.04332708194851875" quat="0.732168972492218 0.0395549014210701 -0.04267530143260956 0.6786330938339233"/>
          <geom class="collision" type="box" pos="0.003128 0.041907 0.101358" size="0.003506803885102272 0.012674807570874691 0.0482121966779232" quat="0.7328732013702393 -0.02604093588888645 0.028095250949263573 0.6792859435081482"/>
          <geom class="collision" type="box" pos="-0.016928 0.040596 0.012597" size="0.003504473017528653 0.012674807570874691 0.04332708194851875" quat="0.5510849952697754 0.048518408089876175 -0.032120585441589355 0.832417905330658"/>
          <geom class="collision" type="box" pos="-0.016143 0.038744 0.101358" size="0.0035068036522716284 0.012674807570874691 0.0482121966779232" quat="0.5516152381896973 -0.03194207698106766 0.02114659734070301 0.8332185745239258"/>
          <geom class="collision" type="box" pos="-0.034059 0.027501 0.012597" size="0.003504473017528653 0.012674807570874691 0.04332708194851875" quat="0.3266628086566925 0.054984088987112045 -0.019039904698729515 0.9433481097221375"/>
          <geom class="collision" type="box" pos="-0.032479 0.026257 0.101358" size="0.003506803885102272 0.012674807570874691 0.0482121966779232" quat="0.3269769251346588 -0.03619876131415367 0.012534912675619125 0.9442555904388428"/>
          <geom class="collision" type="box" pos="-0.042659 0.008353 0.012597" size="0.003504473017528653 0.012674807570874691 0.04332708939909935" quat="0.08847763389348984 0.057958297431468964 -0.005157009232789278 0.9943771958351135"/>
          <geom class="collision" type="box" pos="-0.040679 0.007998 0.101358" size="0.0035068036522716284 0.012674807570874691 0.048212192952632904" quat="0.0885627493262291 -0.03815671056509018 0.0033951106015592813 0.995333731174469"/>
          <geom class="collision" type="box" pos="-0.041066 -0.013151 0.012597" size="0.003504473017528653 0.012674807570874691 0.04332708194851875" quat="0.16169296205043793 -0.057419054210186005 -0.009424450807273388 -0.9851241707801819"/>
          <geom class="collision" type="box" pos="-0.039160 -0.012508 0.101358" size="0.003506803885102272 0.012674807570874691 0.0482121966779232" quat="0.1618485003709793 0.03780173510313034 0.006204575765877962 -0.9860718250274658"/>
          <geom class="collision" type="box" pos="-0.030333 -0.030252 0.012597" size="0.003504473017528653 0.012674807570874691 0.04332708194851875" quat="0.3867202699184418 -0.053644176572561264 -0.022540420293807983 -0.9203595519065857"/>
          <geom class="collision" type="box" pos="-0.028926 -0.028815 0.101358" size="0.0035068041179329157 0.012674807570874691 0.0482121966779232" quat="0.38709238171577454 0.03531663864850998 0.014839478768408298 -0.9212448000907898"/>
          <geom class="collision" type="box" pos="-0.011662 -0.041037 0.012597" size="0.0035044727846980095 0.012674808502197266 0.04332708194851875" quat="0.6035350561141968 -0.04634973034262657 -0.035177696496248245 -0.7952104806900024"/>
          <geom class="collision" type="box" pos="-0.011121 -0.039100 0.101358" size="0.0035068036522716284 0.012674807570874691 0.0482121966779232" quat="0.6041155457496643 0.03051433339715004 0.023159237578511238 -0.7959754467010498"/>
          <geom class="collision" type="box" pos="0.009321 -0.041620 0.012597" size="0.003504473017528653 0.012674807570874691 0.04332708194851875" quat="0.7781533598899841 -0.0364505834877491 -0.04535554721951485 -0.6253731846809387"/>
          <geom class="collision" type="box" pos="0.008888 -0.039655 0.101358" size="0.0035068041179329157 0.012674807570874691 0.0482121966779232" quat="0.7789018750190735 0.023997221142053604 0.029859796166419983 -0.6259747743606567"/>
          <geom class="collision" type="box" pos="0.028562 -0.031887 0.012597" size="0.0035044727846980095 0.012674806639552116 0.04332708194851875" quat="0.9092717170715332 -0.024020615965127945 -0.052997905761003494 -0.41211551427841187"/>
          <geom class="collision" type="box" pos="0.027236 -0.030375 0.101358" size="0.003506803885102272 0.012674806639552116 0.0482121966779232" quat="0.9101463556289673 0.01581396348774433 0.03489115461707115 -0.41251200437545776"/>
          <geom class="collision" type="box" pos="0.039590 -0.016916 0.012597" size="0.003504473017528653 0.012674807570874691 0.04332708194851875" quat="0.9765130281448364 -0.012091603130102158 -0.05691717192530632 -0.20745247602462769"/>
          <geom class="collision" type="box" pos="0.037752 -0.016099 0.101358" size="0.0035068041179329157 0.012674807570874691 0.0482121966779232" quat="0.9774523973464966 0.007960498332977295 0.03747131675481796 -0.2076520472764969"/>
          <body name="Blade001">
            <joint axis="0.0 0.0 1.0" pos="-0.000002 0.000680 -0.027644" limited="false" name="Blade001_joint" range="0 360" type="hinge" damping="1" frictionloss="1" armature=".01" stiffness="0.05"/>
            <geom mesh="Blade001_vis" type="mesh" solimp="0.998 0.998 0.001" solref="0.001 1" density="100" friction="0.95 0.3 0.1" class="visual" material="Blade001_material"/>
            <geom class="collision" type="cylinder" pos="-0.000004 0.000702 -0.023459" size="0.031703922897577286 0.010557914152741432" quat="1.0 0.0 0.0 0.0"/>
          </body>
          <body name="Jug001">
            <geom mesh="Jug001_vis" type="mesh" solimp="0.998 0.998 0.001" solref="0.001 1" density="100" friction="0.95 0.3 0.1" class="visual" material="Jug001_material"/>
            <geom class="collision" type="cylinder" pos="-0.000004 0.000702 -0.043055" size="0.044104933738708496 0.004458223003894091" quat="1.0 0.0 0.0 0.0"/>
          </body>
          <body name="Lid001">
            <joint axis="0.0 0.0 1.0" pos="-0.000110 0.000814 0.145474" limited="true" name="Lid001_joint" range="0.0 0.05" type="slide" damping="1" frictionloss="1" armature=".01" stiffness="0.05"/>
            <geom mesh="Lid001_vis" type="mesh" solimp="0.998 0.998 0.001" solref="0.001 1" density="100" friction="0.95 0.3 0.1" class="visual" material="Lid001_material"/>
            <geom class="collision" type="cylinder" pos="-0.000004 0.000702 0.148340" size="0.03886698558926582 0.002786661498248577" quat="1.0 0.0 0.0 0.0"/>
          </body>
        </body>
        <body name="Knob001">
          <joint axis="0.0 1.0 0.0" pos="-0.000054 -0.053382 -0.079618" limited="true" name="Knob001_joint" range="0.0 4.537856055185257" type="hinge" damping="0.05" armature="0.001"/>
          <geom mesh="Knob001_vis" type="mesh" solimp="0.998 0.998 0.001" solref="0.001 1" density="100" friction="0.95 0.3 0.1" class="visual" material="Knob001_material"/>
          <geom class="collision" type="cylinder" pos="-0.000054 -0.054912 -0.079618" size="0.010512183420360088 0.0045489780604839325" quat="0.7071067094802856 0.7071068286895752 0.0 0.0"/>
        </body>
        <geom class="region" name="reg_main" type="box" pos="0.0 0.0 0.0" size="0.057867 0.058565 0.150246"/>
      </body>
    </body>
  </worldbody>
  <actuator>
    <motor name="Button001_joint_actuator" joint="Button001_joint" gear="0.5"/>
    <motor name="Jug001_Clear_joint_actuator" joint="Jug001_Clear_joint" gear="10"/>
    <motor name="Knob001_joint_actuator" joint="Knob001_joint" gear="5"/>
    <motor name="Blade001_joint_actuator" joint="Blade001_joint" gear="20"/>
    <motor name="Lid001_joint_actuator" joint="Lid001_joint" gear="2"/>
  </actuator>
</mujoco>
