<mujoco model="model">
  <compiler angle="radian"/>
  <asset>
    <mesh file="visuals/Body001.obj" name="Body001_vis"/>
    <mesh file="visuals/Body001_Clear.obj" name="Body001_Clear_vis"/>
    <mesh file="visuals/Door001.obj" name="Door001_vis"/>
    <mesh file="visuals/Door001_Clear.obj" name="Door001_Clear_vis"/>
    <mesh file="visuals/Drawer001.obj" name="Drawer001_vis"/>
    <mesh file="visuals/Drawer002.obj" name="Drawer002_vis"/>
    <mesh file="visuals/Drawer003.obj" name="Drawer003_vis"/>
    <texture file="visuals/T_BC001.png" name="Body001_material" type="2d"/>
    <material name="Body001_material" rgba="1 1 1 1.0" texture="Body001_material" shininess="0.141421377658844" specular="0.3103448502657381"/>
    <texture file="visuals/T_BC001.png" name="Body001_Clear_material" type="2d"/>
    <material name="Body001_Clear_material" rgba="1 1 1 0.3700787425041199" texture="Body001_Clear_material" shininess="0.5" specular="0.3103448502657381"/>
    <texture file="visuals/T_BC001.png" name="Door001_material" type="2d"/>
    <material name="Door001_material" rgba="1 1 1 1.0" texture="Door001_material" shininess="0.141421377658844" specular="0.3103448502657381"/>
    <texture file="visuals/T_BC001.png" name="Door001_Clear_material" type="2d"/>
    <material name="Door001_Clear_material" rgba="1 1 1 0.3700787425041199" texture="Door001_Clear_material" shininess="0.5" specular="0.3103448502657381"/>
    <texture file="visuals/T_BC001.png" name="Drawer001_material" type="2d"/>
    <material name="Drawer001_material" rgba="1 1 1 1.0" texture="Drawer001_material" shininess="0.141421377658844" specular="0.3103448502657381"/>
    <texture file="visuals/T_BC001.png" name="Drawer002_material" type="2d"/>
    <material name="Drawer002_material" rgba="1 1 1 1.0" texture="Drawer002_material" shininess="0.141421377658844" specular="0.3103448502657381"/>
    <texture file="visuals/T_BC001.png" name="Drawer003_material" type="2d"/>
    <material name="Drawer003_material" rgba="1 1 1 1.0" texture="Drawer003_material" shininess="0.141421377658844" specular="0.3103448502657381"/>
  </asset>
  <default>
    <default class="visual">
      <geom conaffinity="0" contype="0" group="1" type="mesh"/>
    </default>
    <default class="collision">
      <geom group="0" rgba="0.5 0 0 0.5"/>
    </default>
    <default class="spawn">
      <geom group="0" rgba="1 1 1 0.5" contype="0" conaffinity="0"/>
      <site group="0" rgba="1 1 1 0.5"/>
    </default>
    <default class="region">
      <geom group="1" conaffinity="0" contype="0" rgba="0 1 0 0"/>
    </default>
  </default>
  <worldbody>
    <body>
      <body name="object">
        <geom mesh="Body001_vis" type="mesh" solimp="0.998 0.998 0.001" solref="0.001 1" density="100" friction="0.95 0.3 0.1" class="visual" material="Body001_material"/>
        <geom class="collision" type="box" pos="-0.395007 0.053950 0.018018" size="0.009432611986994743 0.37056872248649597 0.9119754433631897" quat="1.0 0.0 0.0 0.0"/>
        <geom class="collision" type="box" pos="0.005401 0.053950 0.917801" size="0.3973832428455353 0.37056872248649597 0.012193256057798862" quat="1.0 0.0 0.0 0.0"/>
        <geom class="collision" type="box" pos="0.393167 0.053950 0.018018" size="0.01032690517604351 0.37056872248649597 0.9119754433631897" quat="1.0 0.0 0.0 0.0"/>
        <geom class="collision" type="box" pos="0.005401 0.063423 0.052184" size="0.3973832428455353 0.36109575629234314 0.023275410756468773" quat="1.0 0.0 0.0 0.0"/>
        <geom class="collision" type="box" pos="0.005401 0.054998 -0.897075" size="0.3973832428455353 0.36952078342437744 0.030046092346310616" quat="1.0 0.0 0.0 0.0"/>
        <geom class="collision" type="box" pos="0.005401 0.409895 0.018503" size="0.3973832428455353 0.014623885974287987 0.89103764295578" quat="1.0 0.0 0.0 0.0"/>
        <body name="Body001_Clear">
          <geom mesh="Body001_Clear_vis" type="mesh" solimp="0.998 0.998 0.001" solref="0.001 1" density="100" friction="0.95 0.3 0.1" class="visual" material="Body001_Clear_material"/>
          <geom class="collision" type="box" pos="0.005401 0.063423 0.588727" size="0.3973832428455353 0.36109575629234314 0.009213412180542946" quat="1.0 0.0 0.0 0.0"/>
          <geom class="collision" type="box" pos="0.005401 0.063423 0.252512" size="0.3973832428455353 0.36109575629234314 0.009213412180542946" quat="1.0 0.0 0.0 0.0"/>
        </body>
        <body name="Door001">
          <joint axis="0.0 0.0 1.0" pos="0.382911 -0.342220 0.487948" limited="true" name="Door001_joint" range="0.0 1.5707963267948966" type="hinge" damping="1" frictionloss="1" armature=".01" stiffness="0.05"/>
          <geom mesh="Door001_vis" type="mesh" solimp="0.998 0.998 0.001" solref="0.001 1" density="100" friction="0.95 0.3 0.1" class="visual" material="Door001_material"/>
          <geom class="collision" type="box" pos="-0.003158 -0.349392 0.484867" size="0.3936440944671631 0.014511649496853352 0.445126473903656" quat="1.0 0.0 0.0 0.0"/>
          <geom class="collision" type="cylinder" pos="-0.348223 -0.412659 0.536995" size="0.013434533961117268 0.31531861424446106" quat="1.0 0.0 0.0 0.0"/>
          <geom class="collision" type="box" pos="-0.348316 -0.383619 0.232319" size="0.005130494944751263 0.022282758727669716 0.005130494944751263" quat="1.0 0.0 0.0 0.0"/>
          <geom class="collision" type="box" pos="-0.348316 -0.383619 0.840019" size="0.005130494944751263 0.022282758727669716 0.005130494944751263" quat="1.0 0.0 0.0 0.0"/>
          <body name="Door001_Clear">
            <geom mesh="Door001_Clear_vis" type="mesh" solimp="0.998 0.998 0.001" solref="0.001 1" density="100" friction="0.95 0.3 0.1" class="visual" material="Door001_Clear_material"/>
            <geom class="collision" type="box" pos="-0.175564 -0.205116 0.733024" size="0.1400785744190216 0.0052366615273058414 0.05930408090353012" quat="1.0 0.0 0.0 0.0"/>
            <geom class="collision" type="box" pos="-0.175564 -0.275800 0.681127" size="0.140078604221344 0.07298263162374496 0.007407377474009991" quat="1.0 0.0 0.0 0.0"/>
            <geom class="collision" type="box" pos="-0.313044 -0.275800 0.736022" size="0.005144244059920311 0.07298265397548676 0.059030089527368546" quat="1.0 0.0 0.0 0.0"/>
            <geom class="collision" type="box" pos="-0.037455 -0.275800 0.736022" size="0.00514424592256546 0.07298266142606735 0.05903010070323944" quat="1.0 0.0 0.0 0.0"/>
            <geom class="collision" type="box" pos="0.281671 -0.275800 0.736022" size="0.005144247319549322 0.07298268377780914 0.059030115604400635" quat="1.0 0.0 0.0 0.0"/>
            <geom class="collision" type="box" pos="0.008203 -0.275800 0.736022" size="0.005144248716533184 0.07298269122838974 0.05903013050556183" quat="1.0 0.0 0.0 0.0"/>
            <geom class="collision" type="box" pos="0.144622 -0.275800 0.681127" size="0.13901875913143158 0.07298270612955093 0.007407385855913162" quat="1.0 0.0 0.0 0.0"/>
            <geom class="collision" type="box" pos="0.144622 -0.205116 0.733024" size="0.13901880383491516 0.005236674100160599 0.05930417776107788" quat="1.0 0.0 0.0 0.0"/>
            <geom class="collision" type="box" pos="-0.021544 -0.209527 0.453475" size="0.3051843047142029 0.005236675962805748 0.059304188936948776" quat="1.0 0.0 0.0 0.0"/>
            <geom class="collision" type="box" pos="-0.021544 -0.278006 0.401578" size="0.30518433451652527 0.07077692449092865 0.007407390978187323" quat="1.0 0.0 0.0 0.0"/>
            <geom class="collision" type="box" pos="-0.324130 -0.278006 0.456473" size="0.005144257564097643 0.07077693939208984 0.0590301975607872" quat="1.0 0.0 0.0 0.0"/>
            <geom class="collision" type="box" pos="0.281671 -0.278006 0.456473" size="0.005144259426742792 0.07077694684267044 0.059030212461948395" quat="1.0 0.0 0.0 0.0"/>
          </body>
        </body>
        <body name="Drawer001">
          <joint axis="0.0 -1.0 0.0" pos="-0.000001 -0.029404 -0.176872" limited="true" name="Drawer001_joint" range="0.0 0.45" type="slide" damping="1" frictionloss="1" armature=".01" stiffness="0.05"/>
          <geom mesh="Drawer001_vis" type="mesh" solimp="0.998 0.998 0.001" solref="0.001 1" density="100" friction="0.95 0.3 0.1" class="visual" material="Drawer001_material"/>
          <geom class="collision" type="box" pos="-0.000899 -0.343637 -0.178380" size="0.39962247014045715 0.01995452307164669 0.21172763407230377" quat="1.0 0.0 0.0 0.0"/>
          <geom class="collision" type="box" pos="-0.027157 0.328123 -0.189678" size="0.3364948630332947 0.013647232204675674 0.1492374986410141" quat="1.0 0.0 0.0 0.0"/>
          <geom class="collision" type="box" pos="-0.009671 -0.315124 -0.158733" size="0.35103321075439453 0.020465156063437462 0.18018293380737305" quat="1.0 0.0 0.0 0.0"/>
          <geom class="collision" type="box" pos="-0.333259 0.008059 -0.189678" size="0.030393287539482117 0.310696542263031 0.14923758804798126" quat="1.0 0.0 0.0 0.0"/>
          <geom class="collision" type="box" pos="0.313057 0.020650 -0.189678" size="0.031079553067684174 0.3232879042625427 0.14923764765262604" quat="1.0 0.0 0.0 0.0"/>
          <geom class="collision" type="box" pos="-0.017196 0.008059 -0.319117" size="0.299781858921051 0.31069672107696533 0.019799286499619484" quat="1.0 0.0 0.0 0.0"/>
          <geom class="collision" type="cylinder" pos="0.001860 -0.415005 -0.057822" size="0.013434533961117268 0.31531861424446106" quat="0.7071068286895752 -0.0 0.7071067690849304 0.0"/>
          <geom class="collision" type="box" pos="-0.300499 -0.383619 -0.057882" size="0.005130494944751263 0.022282758727669716 0.005130494944751263" quat="1.0 0.0 0.0 0.0"/>
          <geom class="collision" type="box" pos="0.307147 -0.383619 -0.057882" size="0.005130494944751263 0.022282758727669716 0.005130494944751263" quat="1.0 0.0 0.0 0.0"/>
        </body>
        <body name="Drawer002">
          <joint axis="0.0 -1.0 0.0" pos="-0.000001 -0.029404 -0.641283" limited="true" name="Drawer002_joint" range="0.0 0.45" type="slide" damping="1" frictionloss="1" armature=".01" stiffness="0.05"/>
          <geom mesh="Drawer002_vis" type="mesh" solimp="0.998 0.998 0.001" solref="0.001 1" density="100" friction="0.95 0.3 0.1" class="visual" material="Drawer002_material"/>
          <geom class="collision" type="box" pos="-0.017196 0.008059 -0.819210" size="0.2997819483280182 0.3106967806816101 0.01979929208755493" quat="1.0 0.0 0.0 0.0"/>
          <geom class="collision" type="box" pos="0.313057 0.020650 -0.690613" size="0.03107956051826477 0.3232880234718323 0.1483958661556244" quat="1.0 0.0 0.0 0.0"/>
          <geom class="collision" type="box" pos="-0.333259 0.008059 -0.690613" size="0.030393237248063087 0.31069695949554443 0.14839589595794678" quat="1.0 0.0 0.0 0.0"/>
          <geom class="collision" type="box" pos="-0.009671 -0.315124 -0.662204" size="0.3510338068008423 0.020465193316340446 0.17680495977401733" quat="1.0 0.0 0.0 0.0"/>
          <geom class="collision" type="box" pos="-0.025865 0.328123 -0.690613" size="0.334839791059494 0.013647256419062614 0.14839598536491394" quat="1.0 0.0 0.0 0.0"/>
          <geom class="collision" type="box" pos="-0.000899 -0.343637 -0.643924" size="0.39962342381477356 0.019954580813646317 0.24627697467803955" quat="1.0 0.0 0.0 0.0"/>
          <geom class="collision" type="cylinder" pos="0.001860 -0.415005 -0.461229" size="0.013434533961117268 0.31531861424446106" quat="0.7071068286895752 -0.0 0.7071067690849304 0.0"/>
          <geom class="collision" type="box" pos="-0.300499 -0.383619 -0.462430" size="0.005130494944751263 0.022282758727669716 0.005130494944751263" quat="1.0 0.0 0.0 0.0"/>
          <geom class="collision" type="box" pos="0.307147 -0.383619 -0.462430" size="0.005130494944751263 0.022282758727669716 0.005130494944751263" quat="1.0 0.0 0.0 0.0"/>
        </body>
        <body name="Drawer003">
          <joint axis="0.0 -1.0 0.0" pos="0.001754 0.039656 0.201148" limited="true" name="Drawer003_joint" range="0.0 0.4" type="slide" damping="1" frictionloss="1" armature=".01" stiffness="0.05"/>
          <geom mesh="Drawer003_vis" type="mesh" solimp="0.998 0.998 0.001" solref="0.001 1" density="100" friction="0.95 0.3 0.1" class="visual" material="Drawer003_material"/>
          <geom class="collision" type="box" pos="-0.001996 0.335252 0.152234" size="0.35589125752449036 0.006798130925744772 0.07002135366201401" quat="1.0 0.0 0.0 0.0"/>
          <geom class="collision" type="box" pos="-0.347725 0.041658 0.152234" size="0.01123232115060091 0.28192782402038574 0.07002135366201401" quat="1.0 0.0 0.0 0.0"/>
          <geom class="collision" type="box" pos="0.345161 0.041658 0.152234" size="0.012115423567593098 0.28192782402038574 0.07002135366201401" quat="1.0 0.0 0.0 0.0"/>
          <geom class="collision" type="box" pos="0.001713 0.041658 0.094460" size="0.34323397278785706 0.28192782402038574 0.012246621772646904" quat="1.0 0.0 0.0 0.0"/>
          <geom class="collision" type="box" pos="0.293435 -0.248012 0.152234" size="0.060460224747657776 0.006798130925744772 0.07002135366201401" quat="1.0 0.0 0.0 0.0"/>
          <geom class="collision" type="box" pos="-0.001996 -0.248012 0.126077" size="0.35589125752449036 0.006798130925744772 0.043863922357559204" quat="1.0 0.0 0.0 0.0"/>
          <geom class="collision" type="box" pos="-0.000290 -0.248012 0.152234" size="0.0964420735836029 0.006798130925744772 0.07002135366201401" quat="1.0 0.0 0.0 0.0"/>
          <geom class="collision" type="box" pos="-0.296915 -0.248012 0.152234" size="0.061095669865608215 0.006798130925744772 0.07002135366201401" quat="1.0 0.0 0.0 0.0"/>
        </body>
        <geom class="region" name="reg_main" type="box" pos="0.0 0.03151700000000002 0.0" size="0.406869 0.396017 0.93707"/>
      </body>
    </body>
  </worldbody>
  <actuator>
    <motor name="Door001_joint_actuator" joint="Door001_joint" gear="50"/>
    <motor name="Drawer001_joint_actuator" joint="Drawer001_joint" gear="50"/>
    <motor name="Drawer002_joint_actuator" joint="Drawer002_joint" gear="50"/>
    <motor name="Drawer003_joint_actuator" joint="Drawer003_joint" gear="50"/>
  </actuator>
</mujoco>
