<?xml version='1.0' encoding='UTF-8'?>
<mujoco model="model">
  <compiler angle="radian"/>
  <asset>
    <mesh file="visuals/Body001.obj" name="Body001_vis"/>
    <mesh file="visuals/Button001.obj" name="Button001_vis"/>
    <mesh file="visuals/Handle001.obj" name="Handle001_vis"/>
    <mesh file="visuals/Handle001_Clear.obj" name="Handle001_Clear_vis"/>
    <mesh file="visuals/Lever001.obj" name="Lever001_vis"/>
    <mesh file="visuals/Lid001.obj" name="Lid001_vis"/>
    <texture file="visuals/T_BC001.png" name="Body001_material" type="2d"/>
    <material name="Body001_material" rgba="1 1 1 1.0" texture="Body001_material" shininess="0.4472135901451111" specular="0.3103448502657381"/>
    <texture file="visuals/T_BC001.png" name="Handle001_material" type="2d"/>
    <material name="Handle001_material" rgba="1 1 1 1.0" texture="Handle001_material" shininess="0.4472135901451111" specular="0.3103448502657381"/>
    <texture file="visuals/T_BC001.png" name="Button001_material" type="2d"/>
    <material name="Button001_material" rgba="1 1 1 1.0" texture="Button001_material" shininess="0.4472135901451111" specular="0.3103448502657381"/>
    <material name="Handle001_Clear_material" rgba="0.23014912009239197 0.23014912009239197 0.23014912009239197 0.800000011920929" shininess="0.4472135901451111" specular="0.3103448502657381"/>
    <texture file="visuals/T_BC001.png" name="Lever001_material" type="2d"/>
    <material name="Lever001_material" rgba="1 1 1 1.0" texture="Lever001_material" shininess="0.4472135901451111" specular="0.3103448502657381"/>
    <texture file="visuals/T_BC001.png" name="Lid001_material" type="2d"/>
    <material name="Lid001_material" rgba="1 1 1 1.0" texture="Lid001_material" shininess="0.4472135901451111" specular="0.3103448502657381"/>
  </asset>
  <default>
    <default class="visual">
      <geom conaffinity="0" contype="0" group="1" type="mesh"/>
    </default>
    <default class="collision">
      <geom group="0" rgba="0.5 0 0 0.5"/>
    </default>
    <default class="spawn">
      <geom group="0" rgba="1 1 1 0.5" contype="0" conaffinity="0"/>
      <site group="0" rgba="1 1 1 0.5"/>
    </default>
    <default class="region">
      <geom group="1" conaffinity="0" contype="0" rgba="0 1 0 0"/>
    </default>
  </default>
  <worldbody>
    <body>
      <body name="object">
        <geom mesh="Body001_vis" type="mesh" solimp="0.998 0.998 0.001" solref="0.001 1" density="100" friction="0.95 0.3 0.1" class="visual" material="Body001_material"/>
        <geom class="collision" type="cylinder" pos="-0.02140013873577118 1.846825625761994e-08 -0.13956037163734436" size="0.10144243389368057 0.010628825053572655" quat="1.0 0.0 0.0 0.0"/>
        <body name="Handle001">
          <joint axis="0.0 0.0 1.0" pos="0.000561889261007309 -1.0567769948011119e-07 0.006772026419639587" limited="true" name="Handle001_joint" range="0.0 0.1" type="slide" damping="1" frictionloss="1" armature=".01" stiffness="0.05"/>
          <geom mesh="Handle001_vis" type="mesh" solimp="0.998 0.998 0.001" solref="0.001 1" density="100" friction="0.95 0.3 0.1" class="visual" material="Handle001_material"/>
          <geom class="collision" type="box" pos="-0.09903597831726074 1.8466380424797535e-08 0.009497753344476223" size="0.010966354049742222 0.02403128147125244 0.13442876935005188" quat="0.99945467710495 0.0 0.03302085027098656 0.0"/>
          <geom class="collision" type="box" pos="-0.08993858098983765 -0.03646644204854965 0.009497768245637417" size="0.010966352187097073 0.02403128147125244 0.13442876935005188" quat="0.969733715057373 -0.00799283105880022 0.03203893080353737 0.24192188680171967"/>
          <geom class="collision" type="box" pos="-0.0644911676645279 -0.06457929313182831 0.009497753344476223" size="0.010966353118419647 0.02403128147125244 0.13442876935005188" quat="0.8812901973724365 -0.015575189143419266 0.029116835445165634 0.47142040729522705"/>
          <geom class="collision" type="box" pos="-0.029108095914125443 -0.07725223898887634 0.009497768245637417" size="0.010966354049742222 0.024031279608607292 0.13442876935005188" quat="0.740973949432373 -0.022159896790981293 0.02448096312582493 0.6707214117050171"/>
          <geom class="collision" type="box" pos="0.007555481046438217 -0.07203397899866104 0.009497753344476223" size="0.010966353118419647 0.02403128147125244 0.13442876935005188" quat="0.5596200227737427 -0.027359191328287125 0.01848922111093998 0.8280912041664124"/>
          <geom class="collision" type="box" pos="0.037997666746377945 -0.04999222978949547 0.009497753344476223" size="0.010966353118419647 0.02403128147125244 0.13442875444889069" quat="0.3425358533859253 -0.031020907685160637 0.011316977441310883 0.9389243125915527"/>
          <geom class="collision" type="box" pos="0.05690263211727142 -0.016666358336806297 0.009497768245637417" size="0.010966352187097073 0.024031275883316994 0.13442876935005188" quat="0.10286465287208557 -0.032845523208379745 0.003398534609004855 0.9941471219062805"/>
          <geom class="collision" type="box" pos="0.05507916584610939 0.022046076133847237 0.009497753344476223" size="0.010966353118419647 0.024031275883316994 0.13442875444889069" quat="0.14083148539066315 0.0326913557946682 0.004652907606214285 -0.9894827604293823"/>
          <geom class="collision" type="box" pos="0.034857127815485 0.053501829504966736 0.009497753344476223" size="0.010966353118419647 0.02403128333389759 0.13442876935005188" quat="0.3708568811416626 0.030663464218378067 0.012252697721123695 -0.9281027913093567"/>
          <geom class="collision" type="box" pos="0.003134481841698289 0.07365716993808746 0.009497768245637417" size="0.010966354981064796 0.02403128333389759 0.13442876935005188" quat="0.5844793915748596 0.026785830035805702 0.01931055262684822 -0.810736358165741"/>
          <geom class="collision" type="box" pos="-0.03467915207147598 0.07649178802967072 0.009497768245637417" size="0.010966354049742222 0.024031279608607292 0.13442876935005188" quat="0.7647762298583984 0.021258847787976265 0.025267360731959343 -0.6434492468833923"/>
          <geom class="collision" type="box" pos="-0.06905218958854675 0.0612911656498909 0.009497768245637417" size="0.010966353118419647 0.02403128333389759 0.13442876935005188" quat="0.8977832794189453 0.014510611072182655 0.029661765322089195 -0.4391978979110718"/>
          <geom class="collision" type="box" pos="-0.0905359536409378 0.03532087802886963 0.009497768245637417" size="0.010966354049742222 0.024031277745962143 0.13442876935005188" quat="0.971713125705719 0.007725966162979603 0.032104335725307465 -0.23384450376033783"/>
          <geom class="collision" type="box" pos="0.07385481894016266 5.230364763519901e-08 0.11226815730333328" size="0.01648845709860325 0.017016258090734482 0.016007598489522934" quat="0.9347493648529053 -7.063327279023621e-15 0.3553078770637512 4.7738694775034674e-08"/>
          <geom class="collision" type="box" pos="0.09374883770942688 4.9565247906002696e-08 0.09188690781593323" size="0.015378513373434544 0.01523592695593834 0.014528315514326096" quat="0.89105224609375 -1.1071457539277817e-15 0.4539007842540741 6.098557747691302e-08"/>
          <geom class="collision" type="box" pos="0.10668070614337921 4.707880663090691e-08 0.07338094711303711" size="0.013809528201818466 0.013338612392544746 0.012176656164228916" quat="0.7718415260314941 -6.316572156821187e-13 0.6358149647712708 8.542713914039268e-08"/>
          <geom class="collision" type="box" pos="0.11019238084554672 4.3652047310160924e-08 0.04787641391158104" size="0.013809528201818466 0.012982138432562351 0.012176656164228916" quat="0.7224703431129456 5.194416945186742e-13 0.6914019584655762 9.289927049849211e-08"/>
          <geom class="collision" type="box" pos="0.10802468657493591 4.067714343136686e-08 0.0257349144667387" size="0.013809527270495892 0.012982138432562351 0.012176656164228916" quat="0.6056534051895142 1.248006960361675e-13 0.7957285642623901 1.0691379515037625e-07"/>
          <geom class="collision" type="box" pos="0.09780552983283997 3.788946756344558e-08 0.004986935295164585" size="0.013809528201818466 0.012982138432562351 0.012176656164228916" quat="0.42706602811813354 1.042267129807567e-13 0.904220461845398 1.2149008910000703e-07"/>
          <geom class="collision" type="box" pos="0.0810832753777504 3.6141969417258224e-08 -0.008019260130822659" size="0.013809528201818466 0.0162392295897007 0.012176656164228916" quat="0.19089354574680328 1.3938955783880658e-13 0.9816107749938965 1.318877593803336e-07"/>
          <geom class="collision" type="box" pos="-0.11125688999891281 5.122003798874175e-08 0.12386609613895416" size="0.017446836456656456 0.018521806225180626 0.0031074355356395245" quat="0.8592998385429382 7.504623821246587e-15 0.5114721655845642 6.872084412634649e-08"/>
          <geom class="collision" type="box" pos="-0.09880809485912323 0.02768467739224434 0.12386609613895416" size="0.01796913705766201 0.019870679825544357 0.0034132993314415216" quat="0.8059025406837463 0.17748861014842987 0.4796890318393707 -0.29819002747535706"/>
          <geom class="collision" type="box" pos="-0.0978790894150734 -0.02935680001974106 0.12386609613895416" size="0.017780296504497528 0.02099858969449997 0.0033049522899091244" quat="0.8133487701416016 -0.16501648724079132 0.4841212034225464 0.27723637223243713"/>
          <geom class="collision" type="box" pos="0.019734248518943787 0.046822380274534225 0.13526983559131622" size="0.00792024563997984 0.006481490097939968 0.0136916134506464" quat="0.7088853716850281 1.3549768945742002e-11 0.7053236961364746 9.477420093162436e-08"/>
          <geom class="collision" type="box" pos="0.019734248518943787 -0.04636294022202492 0.13526983559131622" size="0.00792024563997984 0.006481490097939968 0.0136916134506464" quat="0.7088853716850281 1.3549768945742002e-11 0.7053236961364746 9.477420093162436e-08"/>
          <geom class="collision" type="box" pos="0.022422587499022484 0.0008610598742961884 0.13526983559131622" size="0.007920284755527973 0.04444905370473862 0.016122248023748398" quat="0.7088853716850281 1.3549768945742002e-11 0.7053236961364746 9.477420093162436e-08"/>
          <geom class="collision" type="cylinder" pos="-0.02140013873577118 1.846825625761994e-08 -0.10030791163444519" size="0.10144243389368057 0.027324313297867775" quat="1.0 0.0 0.0 0.0"/>
          <body name="Button001">
            <joint axis="0.0 0.0 -1.0" pos="0.03302505239844322 -0.00012869331112597138 0.14388996362686157" limited="true" name="Button001_joint" range="0.0 0.003" type="slide" damping="1" frictionloss="1" armature=".01" stiffness="0.05" springref="-1"/>
            <geom mesh="Button001_vis" type="mesh" solimp="0.998 0.998 0.001" solref="0.001 1" density="100" friction="0.95 0.3 0.1" class="visual" material="Button001_material"/>
            <geom class="collision" type="cylinder" pos="0.0332854688167572 5.699007843418258e-08 0.1473071575164795" size="0.01602855511009693 0.0022176748607307673" quat="1.0 0.0 0.0 0.0"/>
          </body>
          <body name="Handle001_Clear">
            <geom mesh="Handle001_Clear_vis" type="mesh" solimp="0.998 0.998 0.001" solref="0.001 1" density="100" friction="0.95 0.3 0.1" class="visual" material="Handle001_Clear_material"/>
          </body>
          <body name="Lever001">
            <joint axis="0.0 1.0 0.0" pos="0.06654553860425949 8.888504817150533e-05 -0.0937604308128357" limited="true" name="Lever001_joint" range="0.0 0.5235987755982988" type="hinge" damping="1" frictionloss="1" armature=".01" stiffness="1"/>
            <geom mesh="Lever001_vis" type="mesh" solimp="0.998 0.998 0.001" solref="0.001 1" density="100" friction="0.95 0.3 0.1" class="visual" material="Lever001_material"/>
            <geom class="collision" type="cylinder" pos="0.09637433290481567 2.4545443011447787e-08 -0.09392611682415009" size="0.016050945967435837 0.0028899218887090683" quat="0.9999985098838806 -1.267926458270452e-10 0.0017247503856197 4.243003726145389e-09"/>
          </body>
          <body name="Lid001">
            <joint axis="0.0 1.0 0.0" pos="0.00656600296497345 2.2099002308095805e-06 0.1405380368232727" limited="true" name="Lid001_joint" range="0.0 1.5707963267948966" type="hinge" damping="1" frictionloss="1" armature=".01" stiffness="0.05"/>
            <geom mesh="Lid001_vis" type="mesh" solimp="0.998 0.998 0.001" solref="0.001 1" density="100" friction="0.95 0.3 0.1" class="visual" material="Lid001_material"/>
            <geom class="collision" type="box" pos="-0.019954202696681023 0.0008610598742961884 0.13598430156707764" size="0.007448194082826376 0.049891840666532516 0.02352394163608551" quat="0.7088853716850281 1.3549768945742002e-11 0.7053236961364746 9.477420093162436e-08"/>
            <geom class="collision" type="box" pos="-0.050080280750989914 0.0008610598742961884 0.13598430156707764" size="0.007448107004165649 0.043040934950113297 0.00686289556324482" quat="0.7088853716850281 1.3549768945742002e-11 0.7053236961364746 9.477420093162436e-08"/>
            <geom class="collision" type="box" pos="-0.061233263462781906 -3.201467916369438e-05 0.13598430156707764" size="0.007448045536875725 0.03734284266829491 0.004071222618222237" quat="0.7088853716850281 1.3549768945742002e-11 0.7053236961364746 9.477420093162436e-08"/>
            <geom class="collision" type="box" pos="-0.06941977888345718 0.0002160615404136479 0.13598430156707764" size="0.007448045536875725 0.022494012489914894 0.004071222618222237" quat="0.7088853716850281 1.3549768945742002e-11 0.7053236961364746 9.477420093162436e-08"/>
          </body>
        </body>
        <geom class="region" name="reg_main" type="box" pos="3.725290298461914e-09 0.0 1.4901161193847656e-08" size="0.12092986702919006 0.09945522248744965 0.14914216101169586"/>
      </body>
    </body>
  </worldbody>
  <actuator>
    <motor name="Handle001_joint_actuator" joint="Handle001_joint" gear="10"/>
    <motor name="Button001_joint_actuator" joint="Button001_joint" gear="0.5"/>
    <motor name="Lever001_joint_actuator" joint="Lever001_joint" gear="0.5"/>
    <motor name="Lid001_joint_actuator" joint="Lid001_joint" gear="0.5"/>
  </actuator>
</mujoco>
