<?xml version='1.0' encoding='UTF-8'?>
<mujoco model="model">
  <compiler angle="radian"/>
  <asset>
    <mesh file="visuals/Body001.obj" name="Body001_vis"/>
    <mesh file="visuals/Body002.obj" name="Body002_vis"/>
    <mesh file="visuals/Button001.obj" name="Button001_vis"/>
    <mesh file="visuals/Knob001.obj" name="Knob001_vis"/>
    <mesh file="visuals/Lever001.obj" name="Lever001_vis"/>
    <texture file="visuals/T_BC001.png" name="Body001_material" type="2d"/>
    <material name="Body001_material" rgba="1 1 1 1.0" texture="Body001_material" shininess="0.141421377658844" specular="0.3103448502657381"/>
    <texture file="visuals/T_BC001.png" name="Body002_material" type="2d"/>
    <material name="Body002_material" rgba="1 1 1 1.0" texture="Body002_material" shininess="0.141421377658844" specular="8"/>
    <texture file="visuals/T_BC001.png" name="Button001_material" type="2d"/>
    <material name="Button001_material" rgba="1 1 1 1.0" texture="Button001_material" shininess="0.141421377658844" specular="0.3103448502657381"/>
    <texture file="visuals/T_BC001.png" name="Knob001_material" type="2d"/>
    <material name="Knob001_material" rgba="1 1 1 1.0" texture="Knob001_material" shininess="0.141421377658844" specular="0.3103448502657381"/>
    <texture file="visuals/T_BC001.png" name="Lever001_material" type="2d"/>
    <material name="Lever001_material" rgba="1 1 1 1.0" texture="Lever001_material" shininess="0.141421377658844" specular="0.3103448502657381"/>
  </asset>
  <default>
    <default class="visual">
      <geom conaffinity="0" contype="0" group="1" type="mesh"/>
    </default>
    <default class="collision">
      <geom group="0" rgba="0.5 0 0 0.5"/>
    </default>
    <default class="spawn">
      <geom group="0" rgba="1 1 1 0.5" contype="0" conaffinity="0"/>
      <site group="0" rgba="1 1 1 0.5"/>
    </default>
    <default class="region">
      <geom group="1" conaffinity="0" contype="0" rgba="0 1 0 0"/>
    </default>
  </default>
  <worldbody>
    <body>
      <body name="object">
        <geom mesh="Body001_vis" type="mesh" solimp="0.998 0.998 0.001" solref="0.001 1" density="100" friction="0.95 0.3 0.1" class="visual" material="Body001_material"/>
        <geom class="collision" type="box" pos="-0.007900 0.084302 -0.032943" size="0.08576202392578125 0.02806827612221241 0.11694221943616867" quat="1.0 0.0 0.0 0.0"/>
        <geom class="collision" type="box" pos="-0.007900 -0.058649 -0.032943" size="0.08576203137636185 0.029883073642849922 0.11694221943616867" quat="1.0 0.0 0.0 0.0"/>
        <geom class="collision" type="box" pos="-0.130845 0.012725 -0.032943" size="0.03641093149781227 0.09091868251562119 0.11694221943616867" quat="1.0 0.0 0.0 0.0"/>
        <geom class="collision" type="box" pos="0.111085 0.012725 -0.032943" size="0.03222068026661873 0.09091868251562119 0.11694221943616867" quat="1.0 0.0 0.0 0.0"/>
        <geom class="collision" type="box" pos="0.160215 0.011298 -0.106289" size="0.01553725078701973 0.04710160940885544 0.006863311864435673" quat="1.0 0.0 0.0 0.0"/>
        <geom class="collision" type="box" pos="-0.169933 0.011298 -0.106289" size="0.015537269413471222 0.04710164666175842 0.006863316521048546" quat="1.0 0.0 0.0 0.0"/>
        <body name="Body002">
          <geom mesh="Body002_vis" type="mesh" solimp="0.998 0.998 0.001" solref="0.001 1" density="100" friction="0.95 0.3 0.1" class="visual" material="Body002_material"/>
          <geom class="collision" type="box" pos="-0.007900 0.013928 -0.032943" size="0.08576202392578125 0.008868694305419922 0.11694221943616867" quat="1.0 0.0 0.0 0.0"/>
          <geom class="collision" type="box" pos="0.078717 0.013411 0.102807" size="0.001743199536576867 0.03209192678332329 0.017710207030177116" quat="1.0 0.0 0.0 0.0"/>
          <geom class="collision" type="box" pos="0.090652 0.013411 0.118789" size="0.010049453936517239 0.03209192678332329 0.0017431998858228326" quat="1.0 0.0 0.0 0.0"/>
          <geom class="collision" type="box" pos="0.120622 0.013411 0.117415" size="0.019743118435144424 0.03209192678332329 0.005702401977032423" quat="1.0 0.0 0.0 0.0"/>
          <geom class="collision" type="box" pos="0.146884 0.013411 0.117093" size="0.0060719153843820095 0.022055963054299355 0.005380160640925169" quat="1.0 0.0 0.0 0.0"/>
          <geom class="collision" type="box" pos="-0.089354 0.013411 0.102807" size="0.001743199536576867 0.03209192678332329 0.017710207030177116" quat="1.0 0.0 0.0 0.0"/>
          <geom class="collision" type="box" pos="-0.099963 0.013411 0.118789" size="0.008588558994233608 0.03209192678332329 0.001743199652992189" quat="1.0 0.0 0.0 0.0"/>
          <geom class="collision" type="box" pos="-0.128638 0.013411 0.115818" size="0.019743118435144424 0.03209192678332329 0.005702401977032423" quat="1.0 0.0 0.0 0.0"/>
          <geom class="collision" type="box" pos="-0.155247 0.013411 0.115017" size="0.0060719153843820095 0.022055963054299355 0.005380160640925169" quat="1.0 0.0 0.0 0.0"/>
          <geom class="collision" type="box" pos="-0.001982 -0.035362 0.148252" size="0.10886382311582565 0.0015534975100308657 0.0015460416907444596" quat="1.0 0.0 0.0 0.0"/>
          <geom class="collision" type="box" pos="-0.001982 0.063248 0.148252" size="0.10886382311582565 0.0015534975100308657 0.0015460416907444596" quat="1.0 0.0 0.0 0.0"/>
          <geom class="collision" type="box" pos="0.107293 0.053758 0.134977" size="0.01359183806926012 0.0015534976264461875 0.0015460456488654017" quat="0.6703130602836609 -0.22512316703796387 0.6703130006790161 -0.22512316703796387"/>
          <geom class="collision" type="box" pos="0.107293 -0.025800 0.135078" size="0.01359183806926012 0.0015534976264461875 0.0015460456488654017" quat="0.2204134166240692 -0.6718761324882507 0.22041507065296173 -0.6718761920928955"/>
          <geom class="collision" type="box" pos="-0.115119 0.053758 0.134977" size="0.01359183806926012 0.0015534976264461875 0.0015460456488654017" quat="0.6703130602836609 -0.22512316703796387 0.6703130006790161 -0.22512316703796387"/>
          <geom class="collision" type="box" pos="-0.115119 -0.025800 0.135078" size="0.01359183806926012 0.0015534976264461875 0.0015460456488654017" quat="0.2204134166240692 -0.6718761324882507 0.22041507065296173 -0.6718761920928955"/>
          <geom class="collision" type="box" pos="-0.007900 0.012066 -0.141239" size="0.08576202392578125 0.04851778224110603 0.007821197621524334" quat="1.0 0.0 0.0 0.0"/>
        </body>
        <body name="Button001">
          <joint axis="0.0 1.0 0.0" pos="-0.000986 -0.097061 -0.097301" limited="true" name="Button001_joint" range="0.0 0.003" type="slide" damping="1" frictionloss="1" armature=".01" stiffness="0.05"/>
          <geom mesh="Button001_vis" type="mesh" solimp="0.998 0.998 0.001" solref="0.001 1" density="100" friction="0.95 0.3 0.1" class="visual" material="Button001_material"/>
          <geom class="collision" type="box" pos="-0.006253 -0.093512 -0.097197" size="0.017054395750164986 0.002297984668985009 0.006246058735996485" quat="1.0 0.0 0.0 0.0"/>
        </body>
        <body name="Knob001">
          <joint axis="0.0 1.0 0.0" pos="-0.005320 -0.094480 -0.034590" limited="true" name="Knob001_joint" range="0.0 5.497787143782138" type="hinge" damping="0.05" frictionloss="1" armature="0.001"/>
          <geom mesh="Knob001_vis" type="mesh" solimp="0.998 0.998 0.001" solref="0.001 1" density="100" friction="0.95 0.3 0.1" class="visual" material="Knob001_material"/>
          <geom class="collision" type="cylinder" pos="-0.005182 -0.094167 -0.034395" size="0.029119739308953285 0.0044754380360245705" quat="0.7071069478988647 0.7071065902709961 0.0 0.0" density="0.001"/>
          <geom class="collision" type="box" pos="-0.005493 -0.105027 -0.035519" size="0.007064640522003174 0.008776964619755745 0.019527440890669823" quat="1.0 0.0 0.0 0.0" density="0.001"/>
        </body>
        <body name="Lever001">
          <joint axis="0.0 0.0 -1.0" pos="0.165659 0.012752 0.026086" limited="true" name="Lever001_joint" range="0.0 0.1" type="slide" damping="1" frictionloss="1" armature=".01" stiffness="2" springref="-1.5"/>
          <geom mesh="Lever001_vis" type="mesh" solimp="0.998 0.998 0.001" solref="0.001 1" density="100" friction="0.95 0.3 0.1" class="visual" material="Lever001_material"/>
          <geom class="collision" type="box" pos="-0.005955 0.037636 0.059300" size="0.07907406240701675 0.014000018127262592 0.0029164692386984825" quat="1.0 0.0 0.0 0.0" name="slotR_floor"/>
          <geom class="collision" type="box" pos="-0.005955 -0.011259 0.059300" size="0.07907406240701675 0.013999986462295055 0.0029164664447307587" quat="1.0 0.0 0.0 0.0" name="slotL_floor"/>
          <geom class="collision" type="box" pos="0.173019 0.012686 0.026038" size="0.014526644721627235 0.021635927259922028 0.0059326267801225185" quat="1.0 0.0 0.0 0.0" name="lever_knob"/>
        </body>
        <geom class="region" name="reg_main" type="box" pos="-0.004602999999999996 0.010112499999999996 0.0" size="0.183305 0.1046555 0.149886"/>
      </body>
    </body>
  </worldbody>
  <actuator>
    <motor name="Button001_joint_actuator" joint="Button001_joint" gear="0.2"/>
    <motor name="Knob001_joint_actuator" joint="Knob001_joint" gear="10"/>
    <motor name="Lever001_joint_actuator" joint="Lever001_joint" gear="1.5"/>
  </actuator>
</mujoco>
