<?xml version='1.0' encoding='UTF-8'?>
<mujoco model="model">
  <compiler angle="radian"/>
  <asset>
    <mesh file="visuals/Body001.obj" name="Body001_vis"/>
    <mesh file="visuals/Button001.obj" name="Button001_vis"/>
    <mesh file="visuals/Button002.obj" name="Button002_vis"/>
    <mesh file="visuals/Knob001.obj" name="Knob001_vis"/>
    <mesh file="visuals/Knob002.obj" name="Knob002_vis"/>
    <mesh file="visuals/Lever001.obj" name="Lever001_vis"/>
    <mesh file="visuals/Lever002.obj" name="Lever002_vis"/>
    <texture file="visuals/T_BC001.png" name="Body001_material" type="2d"/>
    <material name="Body001_material" rgba="1 1 1 1.0" texture="Body001_material" shininess="1" specular="1"/>
    <texture file="visuals/T_BC001.png" name="Button001_material" type="2d"/>
    <material name="Button001_material" rgba="1 1 1 1.0" texture="Button001_material" shininess="1" specular="1"/>
    <texture file="visuals/T_BC001.png" name="Button002_material" type="2d"/>
    <material name="Button002_material" rgba="1 1 1 1.0" texture="Button002_material" shininess="1" specular="1"/>
    <texture file="visuals/T_BC001.png" name="Knob001_material" type="2d"/>
    <material name="Knob001_material" rgba="1 1 1 1.0" texture="Knob001_material" shininess="1" specular="1"/>
    <texture file="visuals/T_BC001.png" name="Knob002_material" type="2d"/>
    <material name="Knob002_material" rgba="1 1 1 1.0" texture="Knob002_material" shininess="1" specular="1"/>
    <texture file="visuals/T_BC001.png" name="Lever001_material" type="2d"/>
    <material name="Lever001_material" rgba="1 1 1 1.0" texture="Lever001_material" shininess="1" specular="1"/>
    <texture file="visuals/T_BC001.png" name="Lever002_material" type="2d"/>
    <material name="Lever002_material" rgba="1 1 1 1.0" texture="Lever002_material" shininess="1" specular="1"/>
  </asset>
  <default>
    <default class="visual">
      <geom conaffinity="0" contype="0" group="1" type="mesh"/>
    </default>
    <default class="collision">
      <geom group="0" rgba="0.5 0 0 0.5"/>
    </default>
    <default class="spawn">
      <geom group="0" rgba="1 1 1 0.5" contype="0" conaffinity="0"/>
      <site group="0" rgba="1 1 1 0.5"/>
    </default>
    <default class="region">
      <geom group="1" conaffinity="0" contype="0" rgba="0 1 0 0"/>
    </default>
  </default>
  <worldbody>
    <body>
      <body name="object">
        <geom mesh="Body001_vis" type="mesh" solimp="0.998 0.998 0.001" solref="0.001 1" density="100" friction="0.95 0.3 0.1" class="visual" material="Body001_material"/>
        <geom class="collision" type="box" pos="0.005864 -0.091764 0.002966" size="0.12068044394254684 0.01329335942864418 0.10116154700517654" quat="0.9983316659927368 -0.05774020031094551 -0.0 0.0"/>
        <geom class="collision" type="box" pos="-0.139388 0.002271 0.000958" size="0.03474479541182518 0.08551330864429474 0.10106659680604935" quat="1.0 0.0 0.0 0.0"/>
        <geom class="collision" type="box" pos="-0.000414 0.114326 0.000958" size="0.17371876537799835 0.027405505999922752 0.10106659680604935" quat="1.0 0.0 0.0 0.0"/>
        <geom class="collision" type="box" pos="-0.000827 0.113434 0.000958" size="0.15057894587516785 0.02829725481569767 0.10106659680604935" quat="1.0 0.0 0.0 0.0"/>
        <geom class="collision" type="box" pos="0.139612 0.002271 0.000958" size="0.034438926726579666 0.08551330864429474 0.10106659680604935" quat="1.0 0.0 0.0 0.0"/>
        <geom class="collision" type="box" pos="0.061946 0.008871 0.000958" size="0.016589537262916565 0.07891321182250977 0.10106659680604935" quat="1.0 0.0 0.0 0.0"/>
        <geom class="collision" type="box" pos="0.000705 0.008871 0.000958" size="0.01772632636129856 0.07891321182250977 0.10106659680604935" quat="1.0 0.0 0.0 0.0"/>
        <geom class="collision" type="box" pos="-0.060726 0.008871 0.000958" size="0.016954509541392326 0.07891321182250977 0.10106659680604935" quat="1.0 0.0 0.0 0.0"/>
        <geom class="collision" type="box" pos="0.004063 0.032068 -0.084425" size="0.16998794674873352 0.10637714713811874 0.019420022144913673" quat="1.0 0.0 0.0 0.0"/>
        <geom class="collision" type="box" pos="-0.152404 -0.097798 -0.001305" size="0.02033948339521885 0.02756650559604168 0.10008889436721802" quat="0.9968189597129822 -0.07969891279935837 1.1240806790636566e-19 -1.4059238353779242e-18"/>
        <geom class="collision" type="box" pos="0.150923 -0.097798 -0.001305" size="0.01866787299513817 0.02756650559604168 0.10008889436721802" quat="0.9968189597129822 -0.07969891279935837 1.1240806790636566e-19 -1.4059238353779242e-18"/>
        <geom class="collision" type="box" pos="0.000074 -0.116366 0.003306" size="0.04902131110429764 0.008501855656504631 0.10169165581464767" quat="0.9968189597129822 -0.07969891279935837 1.1240806790636566e-19 -1.4059238353779242e-18"/>
        <geom class="collision" type="box" pos="-0.091714 -0.110277 -0.078845" size="0.04615263268351555 0.02756650559604168 0.021551545709371567" quat="0.9968189597129822 -0.07969891279935837 1.1240806790636566e-19 -1.4059238353779242e-18"/>
        <geom class="collision" type="box" pos="0.093960 -0.110277 -0.078845" size="0.04615263268351555 0.02756650559604168 0.021551545709371567" quat="0.9968189597129822 -0.07969891279935837 1.1240806790636566e-19 -1.4059238353779242e-18"/>
        <geom class="collision" type="box" pos="-0.109999 -0.099766 0.026760" size="0.026092931628227234 0.01714228093624115 0.037459731101989746" quat="0.9968189597129822 -0.07969891279935837 1.1240806790636566e-19 -1.4059238353779242e-18"/>
        <geom class="collision" type="box" pos="0.108754 -0.098463 0.026844" size="0.023988958448171616 0.02243715152144432 0.037749990820884705" quat="0.9968189597129822 -0.07969891279935837 1.1240806790636566e-19 -1.4059238353779242e-18"/>
        <body name="Button001">
          <joint axis="0.0 0.9848077893257141 -0.1736481934785843" pos="-0.099544 -0.103566 0.076228" limited="true" name="Button001_joint" range="0.0 0.002" type="slide" damping="1" frictionloss="1" armature=".01" stiffness="0.05" springref="-0.1"/>
          <geom mesh="Button001_vis" type="mesh" solimp="0.998 0.998 0.001" solref="0.001 1" density="100" friction="0.95 0.3 0.1" class="visual" material="Button001_material"/>
          <geom class="collision" type="box" pos="-0.099955 -0.103711 0.076456" size="0.012103825807571411 0.0042469920590519905 0.006305795628577471" quat="0.9961947202682495 -0.08715574443340302 0.0 0.0"/>
        </body>
        <body name="Button002">
          <joint axis="0.0 0.9848077893257141 -0.1736481934785843" pos="0.099641 -0.103561 0.076183" limited="true" name="Button002_joint" range="0.0 0.002" type="slide" damping="1" frictionloss="1" armature=".01" stiffness="0.05" springref="-0.1"/>
          <geom mesh="Button002_vis" type="mesh" solimp="0.998 0.998 0.001" solref="0.001 1" density="100" friction="0.95 0.3 0.1" class="visual" material="Button002_material"/>
          <geom class="collision" type="box" pos="0.099680 -0.103711 0.076456" size="0.012103825807571411 0.0042469920590519905 0.006305795628577471" quat="0.9961947202682495 -0.08715574443340302 0.0 0.0"/>
        </body>
        <body name="Knob001">
          <joint axis="0.0 0.9848077893257141 -0.1736481934785843" pos="-0.108220 -0.128575 -0.029211" limited="true" name="Knob001_joint" range="0.0 5.497787143782138" type="hinge" damping="0.05" armature="0.001" springref="-0.01"/>
          <geom mesh="Knob001_vis" type="mesh" solimp="0.998 0.998 0.001" solref="0.001 1" density="100" friction="0.95 0.3 0.1" class="visual" material="Knob001_material"/>
          <geom class="collision" type="cylinder" pos="-0.108259 -0.128431 -0.029146" size="0.015343800187110901 0.00347314914688468" quat="0.6425108313560486 -0.7662765979766846 1.7014759769591977e-16 1.5647564081481731e-23"/>
          <geom class="collision" type="box" pos="-0.108195 -0.136972 -0.027975" size="0.0037898283917456865 0.005474586505442858 0.013624683022499084" quat="0.9958509206771851 -0.09099959582090378 -2.020596930239011e-17 1.4671993407845521e-24"/>
        </body>
        <body name="Knob002">
          <joint axis="0.0 0.9848077893257141 -0.1736481934785843" pos="0.108306 -0.128508 -0.029305" limited="true" name="Knob002_joint" range="0.0 5.497787143782138" type="hinge" damping="0.05" armature="0.001" springref="-0.01"/>
          <geom mesh="Knob002_vis" type="mesh" solimp="0.998 0.998 0.001" solref="0.001 1" density="100" friction="0.95 0.3 0.1" class="visual" material="Knob002_material"/>
          <geom class="collision" type="box" pos="0.108220 -0.137040 -0.027963" size="0.0037898283917456865 0.005723741836845875 0.013624683022499084" quat="0.9958509206771851 -0.09099959582090378 -2.020596930239011e-17 1.4671993407845521e-24"/>
          <geom class="collision" type="cylinder" pos="0.108155 -0.128431 -0.029146" size="0.015343800187110901 0.00347314914688468" quat="0.6425108313560486 -0.7662765979766846 1.7014759769591977e-16 1.5647564081481731e-23"/>
        </body>
        <body name="Lever001">
          <joint axis="0.0 -0.1736481934785843 -0.9848077893257141" pos="-0.066174 -0.113658 0.052015" limited="true" name="Lever001_joint" range="0.0 0.085" type="slide" damping="1" frictionloss="1" armature=".01" stiffness="1" springref="-1"/>
          <geom mesh="Lever001_vis" type="mesh" solimp="0.998 0.998 0.001" solref="0.001 1" density="100" friction="0.95 0.3 0.1" class="visual" material="Lever001_material"/>
          <geom class="collision" type="box" pos="-0.066265 -0.124472 0.052263" size="0.015014486387372017 0.015014486387372017 0.0041434005834162235" quat="1.0 0.0 0.0 0.0" name="sideL_lever_knob"/>
          <geom class="collision" type="box" pos="-0.066129 -0.105243 0.053615" size="0.0038251569494605064 0.0053746867924928665 0.001966531155630946" quat="1.0 0.0 0.0 0.0"/>
          <geom class="collision" type="box" pos="-0.030504 0.008184 0.080562" size="0.012500000186264515 0.06999997794628143 0.0015526621136814356" quat="1.0 0.0 0.0 0.0" name="sideL_slotR_floor"/>
          <geom class="collision" type="box" pos="-0.091229 0.008184 0.080562" size="0.012499996460974216 0.06999998539686203 0.0015526621136814356" quat="1.0 0.0 0.0 0.0" name="sideL_slotL_floor"/>
        </body>
        <body name="Lever002">
          <joint axis="0.0 -0.1736481934785843 -0.9848077893257141" pos="0.066072 -0.113658 0.052015" limited="true" name="Lever002_joint" range="0.0 0.085" type="slide" damping="1" frictionloss="1" armature=".01" stiffness="1" springref="-1"/>
          <geom mesh="Lever002_vis" type="mesh" solimp="0.998 0.998 0.001" solref="0.001 1" density="100" friction="0.95 0.3 0.1" class="visual" material="Lever002_material"/>
          <geom class="collision" type="box" pos="0.065907 -0.105243 0.053615" size="0.0038251569494605064 0.0053746867924928665 0.001966531155630946" quat="1.0 0.0 0.0 0.0"/>
          <geom class="collision" type="box" pos="0.065772 -0.124472 0.052263" size="0.015014486387372017 0.015014486387372017 0.0041434005834162235" quat="1.0 0.0 0.0 0.0" name="sideR_lever_knob"/>
          <geom class="collision" type="box" pos="0.091596 0.008184 0.080562" size="0.01249998901039362 0.07000000029802322 0.0015526621136814356" quat="1.0 0.0 0.0 0.0" name="sideR_slotR_floor"/>
          <geom class="collision" type="box" pos="0.031798 0.008184 0.080562" size="0.01249999925494194 0.07000000029802322 0.0015526621136814356" quat="1.0 0.0 0.0 0.0" name="sideR_slotL_floor"/>
        </body>
        <geom class="region" name="reg_main" type="box" pos="0.00013499999999999623 0.005583500000000005 -0.00035400000000000015" size="0.171955 0.13907750000000002 0.101742"/>
      </body>
    </body>
  </worldbody>
  <actuator>
    <motor name="Button001_joint_actuator" joint="Button001_joint" gear="0.5"/>
    <motor name="Button002_joint_actuator" joint="Button002_joint" gear="0.5"/>
    <motor name="Knob001_joint_actuator" joint="Knob001_joint" gear="0.5"/>
    <motor name="Knob002_joint_actuator" joint="Knob002_joint" gear="0.5"/>
    <motor name="Lever001_joint_actuator" joint="Lever001_joint" gear="0.5"/>
    <motor name="Lever002_joint_actuator" joint="Lever002_joint" gear="0.5"/>
  </actuator>
</mujoco>
