<?xml version='1.0' encoding='UTF-8'?>
<mujoco model="model">
  <compiler angle="radian"/>
  <asset>
    <mesh file="visuals/Body001.obj" name="Body001_vis"/>
    <mesh file="visuals/Body002.obj" name="Body002_vis"/>
    <mesh file="visuals/Button001.obj" name="Button001_vis"/>
    <mesh file="visuals/Knob001.obj" name="Knob001_vis"/>
    <mesh file="visuals/Lever001.obj" name="Lever001_vis"/>
    <texture file="visuals/T_BC001.png" name="Body001_material" type="2d"/>
    <material name="Body001_material" rgba="1 1 1 1.0" texture="Body001_material" shininess="0.141421377658844" specular="0.7"/>
    <texture file="visuals/T_BC001.png" name="Body002_material" type="2d"/>
    <material name="Body002_material" rgba="1 1 1 1.0" texture="Body002_material" shininess="0.141421377658844" specular="0.3103448502657381"/>
    <texture file="visuals/T_BC001.png" name="Button001_material" type="2d"/>
    <material name="Button001_material" rgba="1 1 1 1.0" texture="Button001_material" shininess="0.141421377658844" specular="0.3103448502657381"/>
    <texture file="visuals/T_BC001.png" name="Knob001_material" type="2d"/>
    <material name="Knob001_material" rgba="1 1 1 1.0" texture="Knob001_material" shininess="0.141421377658844" specular="0.3103448502657381"/>
    <texture file="visuals/T_BC001.png" name="Lever001_material" type="2d"/>
    <material name="Lever001_material" rgba="1 1 1 1.0" texture="Lever001_material" shininess="0.141421377658844" specular="0.3103448502657381"/>
  </asset>
  <default>
    <default class="visual">
      <geom conaffinity="0" contype="0" group="1" type="mesh"/>
    </default>
    <default class="collision">
      <geom group="0" rgba="0.5 0 0 0.5"/>
    </default>
    <default class="spawn">
      <geom group="0" rgba="1 1 1 0.5" contype="0" conaffinity="0"/>
      <site group="0" rgba="1 1 1 0.5"/>
    </default>
    <default class="region">
      <geom group="1" conaffinity="0" contype="0" rgba="0 1 0 0"/>
    </default>
  </default>
  <worldbody>
    <body>
      <body name="object">
        <geom mesh="Body001_vis" type="mesh" solimp="0.998 0.998 0.001" solref="0.001 1" density="100" friction="0.95 0.3 0.1" class="visual" material="Body001_material"/>
        <geom class="collision" type="box" pos="0.071819 -0.000128 -0.018121" size="0.017897849902510643 0.07558272033929825 0.11121884733438492" quat="1.0 0.0 0.0 0.0"/>
        <geom class="collision" type="box" pos="0.000888 -0.111558 0.128056" size="0.045503027737140656 0.012207301333546638 0.002414036775007844" quat="1.0 0.0 0.0 0.0"/>
        <geom class="collision" type="box" pos="0.000063 0.087372 -0.018121" size="0.08984652906656265 0.011873370967805386 0.11121884733438492" quat="1.0 0.0 0.0 0.0"/>
        <geom class="collision" type="box" pos="-0.070155 -0.000128 -0.018121" size="0.019018039107322693 0.07558272033929825 0.11121884733438492" quat="1.0 0.0 0.0 0.0"/>
        <geom class="collision" type="box" pos="0.000157 -0.000128 -0.113915" size="0.041732896119356155 0.07558272033929825 0.015424847602844238" quat="1.0 0.0 0.0 0.0"/>
        <geom class="collision" type="box" pos="0.039572 -0.138604 -0.018121" size="0.010807800106704235 0.007547955960035324 0.11121699213981628" quat="1.0 0.0 0.0 0.0"/>
        <geom class="collision" type="box" pos="-0.045072 -0.138406 -0.112407" size="0.014666675589978695 0.008579140529036522 0.016932453960180283" quat="1.0 0.0 0.0 0.0"/>
        <geom class="collision" type="box" pos="-0.000579 -0.138385 0.081130" size="0.03038119524717331 0.008556865155696869 0.008924510329961777" quat="1.0 0.0 0.0 0.0"/>
        <geom class="collision" type="box" pos="-0.000579 -0.138842 -0.104235" size="0.030382825061678886 0.007743623107671738 0.026408197358250618" quat="1.0 0.0 0.0 0.0"/>
        <geom class="collision" type="box" pos="0.001135 -0.000128 -0.018121" size="0.005468219053000212 0.07558751851320267 0.11122364550828934" quat="1.0 0.0 0.0 0.0"/>
        <geom class="collision" type="box" pos="0.000030 -0.103089 -0.018121" size="0.08960377424955368 0.028282539919018745 0.11121305078268051" quat="1.0 0.0 0.0 0.0"/>
        <geom class="collision" type="box" pos="0.000952 -0.005598 0.124478" size="0.0017291133990511298 0.10349177569150925 0.0015544283669441938" quat="1.0 0.0 0.0 0.0"/>
        <geom class="collision" type="box" pos="-0.050385 -0.005598 0.124478" size="0.0017291144467890263 0.10349177569150925 0.0015544283669441938" quat="1.0 0.0 0.0 0.0"/>
        <geom class="collision" type="box" pos="0.053547 -0.005598 0.124478" size="0.0017291196854785085 0.10349177569150925 0.0015544283669441938" quat="1.0 0.0 0.0 0.0"/>
        <geom class="collision" type="box" pos="-0.002158 0.084997 0.122745" size="0.07560911029577255 0.001729295589029789 0.0015544859925284982" quat="1.0 0.0 0.0 0.0"/>
        <geom class="collision" type="box" pos="0.080345 0.085665 0.113849" size="0.001554414862766862 0.0017291834810748696 0.008288615383207798" quat="1.0 0.0 0.0 0.0"/>
        <geom class="collision" type="box" pos="0.069592 0.085730 0.102701" size="0.008288619108498096 0.0017291851108893752 0.0015544130001217127" quat="1.0 0.0 0.0 0.0"/>
        <geom class="collision" type="box" pos="0.059937 0.085745 0.097397" size="0.0015544689958915114 0.0017292702104896307 0.004351865034550428" quat="1.0 0.0 0.0 0.0"/>
        <geom class="collision" type="box" pos="0.077156 0.085665 0.122270" size="0.001729181269183755 0.005066163372248411 0.0015544126508757472" quat="0.09229595214128494 0.7010574340820312 -0.7010573148727417 -0.09229602664709091"/>
        <geom class="collision" type="box" pos="0.078372 0.085730 0.104131" size="0.001729181269183755 0.0035548803862184286 0.001554418238811195" quat="0.6644629240036011 0.24184469878673553 -0.2418447732925415 -0.6644631624221802"/>
        <geom class="collision" type="box" pos="0.078372 -0.086262 0.104131" size="0.001729181269183755 0.0035548803862184286 0.0015544155612587929" quat="0.6644629240036011 0.24184469878673553 -0.2418447732925415 -0.6644631624221802"/>
        <geom class="collision" type="box" pos="0.077156 -0.086327 0.122270" size="0.001729181269183755 0.005066165700554848 0.0015544126508757472" quat="0.09229595214128494 0.7010574340820312 -0.7010573148727417 -0.09229602664709091"/>
        <geom class="collision" type="box" pos="0.059937 -0.086247 0.097397" size="0.0015544637572020292 0.0017292611300945282 0.004351865034550428" quat="1.0 0.0 0.0 0.0"/>
        <geom class="collision" type="box" pos="0.069592 -0.086262 0.102701" size="0.008288617245852947 0.0017291851108893752 0.0015544239431619644" quat="1.0 0.0 0.0 0.0"/>
        <geom class="collision" type="box" pos="0.080345 -0.086327 0.113849" size="0.001554414862766862 0.0017291834810748696 0.008288615383207798" quat="1.0 0.0 0.0 0.0"/>
        <geom class="collision" type="box" pos="-0.080425 -0.087136 0.113849" size="0.001729181269183755 0.00828862190246582 0.001554418122395873" quat="0.47771456837654114 0.4777144491672516 0.5213338136672974 0.521333634853363"/>
        <geom class="collision" type="box" pos="-0.069707 -0.086263 0.102701" size="0.001729181269183755 0.00828862190246582 0.0015544126508757472" quat="0.6755902767181396 1.6573051198065514e-07 6.911207606208336e-08 0.7372772693634033"/>
        <geom class="collision" type="box" pos="-0.060088 -0.085437 0.097397" size="0.001729181269183755 0.004351858515292406 0.001554418122395873" quat="0.4777144491672516 -0.4777143895626068 -0.5213338732719421 0.5213337540626526"/>
        <geom class="collision" type="box" pos="-0.077247 -0.086858 0.122270" size="0.001729181269183755 0.005066166631877422 0.0015544126508757472" quat="0.08818227052688599 0.6698103547096252 0.7309699058532715 0.0962340235710144"/>
        <geom class="collision" type="box" pos="-0.078453 -0.087029 0.104131" size="0.001729181269183755 0.0035548803862184286 0.0015544176567345858" quat="0.6348472237586975 0.23106549680233002 0.25216373801231384 0.6928139925003052"/>
        <geom class="collision" type="box" pos="-0.000255 -0.087321 0.124478" size="0.07181192189455032 0.0017291909316554666 0.0015544130001217127" quat="1.0 0.0 0.0 0.0"/>
        <geom class="collision" type="box" pos="-0.080425 0.084863 0.113849" size="0.001729181269183755 0.00828862190246582 0.001554418122395873" quat="0.47771456837654114 0.4777144491672516 0.5213338136672974 0.521333634853363"/>
        <geom class="collision" type="box" pos="-0.069707 0.085735 0.102701" size="0.001729181269183755 0.008288617245852947 0.0015544126508757472" quat="0.6755902767181396 1.6573051198065514e-07 6.911207606208336e-08 0.7372772693634033"/>
        <geom class="collision" type="box" pos="-0.060088 0.086561 0.097397" size="0.001729181269183755 0.004351858515292406 0.001554418122395873" quat="0.4777144491672516 -0.4777143895626068 -0.5213338732719421 0.5213337540626526"/>
        <geom class="collision" type="box" pos="-0.077247 0.085141 0.122270" size="0.001729181269183755 0.005066162906587124 0.0015544126508757472" quat="0.08818227052688599 0.6698103547096252 0.7309699058532715 0.0962340235710144"/>
        <geom class="collision" type="box" pos="-0.078453 0.084970 0.104131" size="0.001729181269183755 0.0035548803862184286 0.0015544156776741147" quat="0.6348472237586975 0.23106549680233002 0.25216373801231384 0.6928139925003052"/>
        <geom class="collision" type="box" pos="-0.035258 -0.138379 -0.002503" size="0.006606541108340025 0.00855177640914917 0.09632734954357147" quat="1.0 0.0 0.0 0.0"/>
        <geom class="collision" type="box" pos="-0.051286 -0.138254 0.079705" size="0.011028056032955647 0.008426363579928875 0.013121865689754486" quat="1.0 0.0 0.0 0.0"/>
        <geom class="collision" type="box" pos="-0.000579 -0.138281 0.046575" size="0.030382825061678886 0.008454016409814358 0.00663308659568429" quat="1.0 0.0 0.0 0.0"/>
        <geom class="collision" type="box" pos="0.020912 -0.138417 0.062767" size="0.008266915567219257 0.008590007200837135 0.009143780916929245" quat="1.0 0.0 0.0 0.0"/>
        <geom class="collision" type="box" pos="-0.009237 -0.138352 0.062767" size="0.0234342273324728 0.00852483045309782 0.009143763221800327" quat="1.0 0.0 0.0 0.0"/>
        <geom class="collision" type="box" pos="-0.000579 -0.138871 -0.048779" size="0.030382569879293442 0.008155247196555138 0.03149619698524475" quat="1.0 0.0 0.0 0.0"/>
        <geom class="collision" type="box" pos="0.049690 -0.111448 0.128056" size="0.0035432500299066305 0.012207640334963799 0.0024140961468219757" quat="1.0 0.0 0.0 0.0"/>
        <geom class="collision" type="box" pos="0.056652 -0.106462 0.128056" size="0.003543225349858403 0.006820063106715679 0.002414117567241192" quat="1.0 0.0 0.0 0.0"/>
        <geom class="collision" type="box" pos="0.053887 -0.114904 0.128056" size="0.003543225349858403 0.006820063106715679 0.0024140961468219757" quat="0.9250949621200562 0.0 -0.0 -0.37973588705062866"/>
        <geom class="collision" type="box" pos="0.062920 -0.102049 0.128056" size="0.003543225349858403 0.0020794805604964495 0.0024140961468219757" quat="0.9948719143867493 0.0 -0.0 -0.1011427640914917"/>
        <geom class="collision" type="box" pos="0.058954 -0.107549 0.128056" size="0.0035432251170277596 0.006820063106715679 0.0024140961468219757" quat="0.9510329365730286 0.0 -0.0 -0.3090895712375641"/>
        <geom class="collision" type="box" pos="0.035046 -0.126275 0.128056" size="0.003543225349858403 0.012207720428705215 0.0024140961468219757" quat="0.8435781598091125 0.0 -0.0 -0.5370064377784729"/>
        <geom class="collision" type="box" pos="0.015430 -0.125815 0.128056" size="0.003543225349858403 0.012207720428705215 0.0024140961468219757" quat="0.5103968977928162 0.0 -0.0 -0.8599389791488647"/>
        <geom class="collision" type="box" pos="0.025247 -0.124035 0.128056" size="0.0035432251170277596 0.006820063106715679 0.0024140961468219757" quat="0.7473390698432922 0.0 -0.0 -0.6644428968429565"/>
        <geom class="collision" type="box" pos="-0.013949 -0.125815 0.128056" size="0.003543225349858403 0.012207720428705215 0.0024140961468219757" quat="0.8435781598091125 0.0 -0.0 -0.5370064377784729"/>
        <geom class="collision" type="box" pos="-0.034653 -0.125930 0.128056" size="0.003543225349858403 0.012207720428705215 0.0024140961468219757" quat="0.5552929043769836 0.0 -0.0 -0.8316548466682434"/>
        <geom class="collision" type="box" pos="-0.023748 -0.123574 0.128056" size="0.0035432251170277596 0.006820063106715679 0.0024140961468219757" quat="0.7473390698432922 0.0 -0.0 -0.6644428968429565"/>
        <geom class="collision" type="box" pos="-0.048300 -0.106353 0.128056" size="0.003543225349858403 0.006820063106715679 0.0024141164030879736" quat="1.0 0.0 0.0 0.0"/>
        <geom class="collision" type="box" pos="-0.049520 -0.114955 0.128056" size="0.004441085737198591 0.008548281155526638 0.0021612581331282854" quat="0.9103667736053467 0.0 0.0 0.41380226612091064"/>
        <geom class="collision" type="box" pos="-0.058501 -0.105849 0.128056" size="0.006284430157393217 0.00368826393969357 0.0024433673825114965" quat="0.8612894415855408 0.0 -0.0 -0.5081146359443665"/>
        <geom class="collision" type="box" pos="-0.055484 -0.106374 0.128056" size="0.003543225349858403 0.0068200621753931046 0.0024140961468219757" quat="0.9997301697731018 0.0 -0.0 -0.02322978712618351"/>
        <geom class="collision" type="box" pos="0.000596 0.108979 0.127938" size="0.04550359770655632 0.01220759842544794 0.0024140768218785524" quat="1.0 0.0 0.0 0.0"/>
        <geom class="collision" type="box" pos="-0.048128 0.107411 0.127938" size="0.003543228842318058 0.010384543798863888 0.0024140961468219757" quat="1.0 0.0 0.0 0.0"/>
        <geom class="collision" type="box" pos="-0.055167 0.103883 0.127938" size="0.0035432276781648397 0.006820064038038254 0.002414113376289606" quat="1.0 0.0 0.0 0.0"/>
        <geom class="collision" type="box" pos="-0.049409 0.113630 0.127938" size="0.003916915971785784 0.007539349142462015 0.0022580712102353573" quat="0.40163373947143555 0.0 0.0 0.9158003926277161"/>
        <geom class="collision" type="box" pos="-0.061435 0.099470 0.127938" size="0.003543225349858403 0.0020794805604964495 0.0024140961468219757" quat="0.10114292800426483 0.0 0.0 0.9948719143867493"/>
        <geom class="collision" type="box" pos="-0.057470 0.104971 0.127938" size="0.0035432251170277596 0.006820063106715679 0.0024140961468219757" quat="0.3090897500514984 0.0 0.0 0.9510328769683838"/>
        <geom class="collision" type="box" pos="-0.033562 0.123696 0.127938" size="0.003543225349858403 0.012207720428705215 0.0024140961468219757" quat="0.5370064973831177 0.0 0.0 0.8435781002044678"/>
        <geom class="collision" type="box" pos="-0.013945 0.123236 0.127938" size="0.0035432251170277596 0.012207720428705215 0.0024140961468219757" quat="0.8599390387535095 0.0 0.0 0.5103967785835266"/>
        <geom class="collision" type="box" pos="-0.023763 0.121456 0.127789" size="0.0035432251170277596 0.006820063106715679 0.0024140961468219757" quat="0.6644429564476013 0.0 0.0 0.7473390102386475"/>
        <geom class="collision" type="box" pos="0.015434 0.123236 0.127938" size="0.003543225349858403 0.012207720428705215 0.0024140961468219757" quat="0.5370064973831177 0.0 0.0 0.8435781002044678"/>
        <geom class="collision" type="box" pos="0.036137 0.123351 0.127938" size="0.003543225349858403 0.012207720428705215 0.0024140961468219757" quat="0.8316548466682434 0.0 0.0 0.5552929043769836"/>
        <geom class="collision" type="box" pos="0.025233 0.120995 0.127789" size="0.0035432251170277596 0.006820063106715679 0.0024140961468219757" quat="0.6644429564476013 0.0 0.0 0.7473390102386475"/>
        <geom class="collision" type="box" pos="0.049785 0.103774 0.127938" size="0.0035432276781648397 0.006820064038038254 0.002414112212136388" quat="1.0 0.0 0.0 0.0"/>
        <geom class="collision" type="box" pos="0.051004 0.112376 0.128408" size="0.004441085737198591 0.008548281155526638 0.0021612581331282854" quat="0.41380226612091064 0.0 -0.0 -0.9103667736053467"/>
        <geom class="collision" type="box" pos="0.059986 0.103270 0.127938" size="0.006284430157393217 0.00368826393969357 0.0024433673825114965" quat="0.5081146359443665 0.0 0.0 0.8612894415855408"/>
        <geom class="collision" type="box" pos="0.056969 0.103796 0.127938" size="0.003543225349858403 0.006820063106715679 0.0024140961468219757" quat="0.023229969665408134 0.0 0.0 0.9997301697731018"/>
        <geom class="collision" type="box" pos="0.058581 -0.134957 -0.018121" size="0.01080799289047718 0.006625041831284761 0.11121884733438492" quat="0.9966905117034912 0.0 0.0 0.08128968626260757"/>
        <geom class="collision" type="box" pos="0.074716 -0.131973 -0.018121" size="0.00738156121224165 0.004729794804006815 0.11121884733438492" quat="0.956101655960083 0.0 0.0 0.2930351197719574"/>
        <geom class="collision" type="box" pos="-0.078315 -0.127887 -0.018121" size="0.009443521499633789 0.006625041831284761 0.11121884733438492" quat="0.952153205871582 0.0 -0.0 -0.30562111735343933"/>
        <geom class="collision" type="box" pos="-0.066296 -0.135669 -0.018121" size="0.007381560280919075 0.004729794804006815 0.11121884733438492" quat="0.9958137273788452 0.0 -0.0 -0.09140605479478836"/>
        <geom class="collision" type="box" pos="0.000550 0.109830 -0.018121" size="0.059643153101205826 0.011873292736709118 0.11121822893619537" quat="1.0 0.0 0.0 0.0"/>
        <geom class="collision" type="box" pos="0.000892 0.144894 -0.016704" size="0.023797927424311638 0.005012699868530035 0.11121886223554611" quat="0.9965649247169495 0.08246416598558426 -0.005023703910410404 -0.005724199116230011"/>
        <geom class="collision" type="box" pos="-0.038772 0.143604 -0.016823" size="0.017651716247200966 0.004196143709123135 0.11121886968612671" quat="0.9943920969963074 0.08288129419088364 -0.004864959977567196 0.06550908088684082"/>
        <geom class="collision" type="box" pos="-0.067504 0.132924 -0.018581" size="0.017651716247200966 0.00588522432371974 0.11121886223554611" quat="0.9567350745201111 0.07987119257450104 -0.02266186662018299 0.2788638472557068"/>
        <geom class="collision" type="box" pos="-0.080556 0.112851 -0.018800" size="0.01464123371988535 0.0040429821237921715 0.11121886968612671" quat="0.8164798021316528 0.053202804177999496 -0.032888736575841904 0.5739760994911194"/>
        <geom class="collision" type="box" pos="0.041695 0.142667 -0.016482" size="0.017651716247200966 0.00588522432371974 0.11121886968612671" quat="0.9946147203445435 0.08319374173879623 -0.00017087708692997694 -0.061809103935956955"/>
        <geom class="collision" type="box" pos="0.070251 0.133918 -0.015541" size="0.017651716247200966 0.005885224789381027 0.11121886968612671" quat="0.9847123026847839 0.08285678178071976 0.0074824681505560875 -0.1530374139547348"/>
        <geom class="collision" type="box" pos="0.081588 0.109676 -0.016168" size="0.01453572977334261 0.00509297801181674 0.11121886968612671" quat="0.7479175329208374 0.04382636025547981 0.03129924088716507 -0.6616033315658569"/>
        <geom class="collision" type="box" pos="0.066116 0.109394 -0.018024" size="0.014535728842020035 0.017348647117614746 0.11121886968612671" quat="0.718610942363739 0.05031517520546913 0.024392085149884224 -0.6931606531143188"/>
        <geom class="collision" type="box" pos="-0.068364 0.107191 -0.016942" size="0.01622443087399006 0.009179049171507359 0.11121886968612671" quat="0.9683212637901306 0.017481839284300804 0.00994997937232256 0.24889615178108215"/>
        <geom class="collision" type="box" pos="-0.000679 0.138377 -0.117588" size="0.059643544256687164 0.018674883991479874 0.012905346229672432" quat="1.0 0.0 0.0 0.0"/>
        <geom class="collision" type="box" pos="0.067990 0.141628 -0.117588" size="0.010031410492956638 0.018674764782190323 0.012905276380479336" quat="0.6182823181152344 0.0 -0.0 -0.785956084728241"/>
        <geom class="collision" type="box" pos="-0.068768 0.132754 -0.117588" size="0.010031410492956638 0.018674764782190323 0.012905276380479336" quat="0.9473262429237366 0.0 -0.0 -0.3202701807022095"/>
        <geom class="collision" type="box" pos="0.071548 0.107967 -0.067560" size="0.01774711161851883 0.010160927660763264 0.06114324927330017" quat="1.0 0.0 0.0 0.0"/>
        <body name="Body002">
          <geom mesh="Body002_vis" type="mesh" solimp="0.998 0.998 0.001" solref="0.001 1" density="100" friction="0.95 0.3 0.1" class="visual" material="Body002_material"/>
          <geom class="collision" type="box" pos="-0.045642 -0.000128 -0.018121" size="0.0029905959963798523 0.07558871805667877 0.11122484505176544" quat="1.0 0.0 0.0 0.0"/>
          <geom class="collision" type="box" pos="0.048161 -0.000128 -0.018121" size="0.0029905959963798523 0.07558850944042206 0.11122463643550873" quat="1.0 0.0 0.0 0.0"/>
          <geom class="collision" type="box" pos="-0.008872 -0.000128 -0.018121" size="0.0029905959963798523 0.07558796554803848 0.11122409999370575" quat="1.0 0.0 0.0 0.0"/>
          <geom class="collision" type="box" pos="0.011076 -0.000128 -0.018121" size="0.0029905959963798523 0.07558794319629669 0.11122407764196396" quat="1.0 0.0 0.0 0.0"/>
        </body>
        <body name="Button001">
          <joint axis="0.0 0.9999999403953552 0.0" pos="-0.001536 -0.158594 0.061499" limited="true" name="Button001_joint" range="0.0 0.003" type="slide" damping="1" frictionloss="1" armature=".01" stiffness="0.05"/>
          <geom mesh="Button001_vis" type="mesh" solimp="0.998 0.998 0.001" solref="0.001 1" density="100" friction="0.95 0.3 0.1" class="visual" material="Button001_material"/>
          <geom class="collision" type="box" pos="-0.001361 -0.149868 0.061782" size="0.01158258505165577 0.0013246641028672457 0.005231217015534639" quat="1.0 0.0 0.0 0.0"/>
        </body>
        <body name="Knob001">
          <joint axis="0.0 0.9999999403953552 0.0" pos="0.000165 -0.159622 -0.053204" limited="true" name="Knob001_joint" range="0.0 5.759586531581287" type="hinge" damping="0.05" armature="0.001"/>
          <geom mesh="Knob001_vis" type="mesh" solimp="0.998 0.998 0.001" solref="0.001 1" density="100" friction="0.95 0.3 0.1" class="visual" material="Knob001_material"/>
          <geom class="collision" type="cylinder" pos="-0.000357 -0.153158 -0.053124" size="0.02352958545088768 0.004277204629033804" quat="0.7071068286895752 0.7071067690849304 0.0 0.0"/>
          <geom class="collision" type="box" pos="0.000002 -0.159891 -0.052954" size="0.004684708081185818 0.0038145422004163265 0.02036171965301037" quat="1.0 0.0 0.0 0.0"/>
        </body>
        <body name="Lever001">
          <joint axis="0.0 0.0 -1.0" pos="-0.050061 -0.153447 0.059548" limited="true" name="Lever001_joint" range="0.0 0.15" type="slide" damping="1" frictionloss="1" armature=".01" stiffness="1" springref="-1"/>
          <geom mesh="Lever001_vis" type="mesh" solimp="0.998 0.998 0.001" solref="0.001 1" density="100" friction="0.95 0.3 0.1" class="visual" material="Lever001_material"/>
          <geom class="collision" type="box" pos="-0.027229 -0.000128 0.087615" size="0.014000000432133675 0.07249999791383743 0.0021634597796946764" quat="1.0 0.0 0.0 0.0" name="slotL_floor"/>
          <geom class="collision" type="box" pos="0.030215 -0.000128 0.087615" size="0.0139999995008111 0.07249999791383743 0.0021634597796946764" quat="1.0 0.0 0.0 0.0" name="slotR_floor"/>
          <geom class="collision" type="box" pos="-0.049869 -0.159451 0.059730" size="0.010252031497657299 0.009677259251475334 0.004635241813957691" quat="1.0 0.0 0.0 0.0" name="lever_knob"/>
          <geom class="collision" type="box" pos="-0.050200 -0.143653 0.059730" size="0.002658987184986472 0.005694423336535692 0.0022419183515012264" quat="1.0 0.0 0.0 0.0"/>
        </body>
        <geom class="region" name="reg_main" type="box" pos="0.0 0.011066500000000007 0.0004590000000000011" size="0.09 0.1581245 0.13018400000000002"/>
      </body>
    </body>
  </worldbody>
  <actuator>
    <motor name="Button001_joint_actuator" joint="Button001_joint" gear="0.5"/>
    <motor name="Knob001_joint_actuator" joint="Knob001_joint" gear="5"/>
    <motor name="Lever001_joint_actuator" joint="Lever001_joint" gear="5"/>
  </actuator>
</mujoco>
