<mujoco model="model">
  <compiler angle="radian"/>
  <asset>
    <mesh file="visuals/Body001.obj" name="Body001_vis"/>
    <mesh file="visuals/Button001.obj" name="Button001_vis"/>
    <mesh file="visuals/Button002.obj" name="Button002_vis"/>
    <mesh file="visuals/Container001_Clear.obj" name="Container001_Clear_vis"/>
    <mesh file="visuals/Lever001.obj" name="Lever001_vis"/>
    <mesh file="visuals/Lever002.obj" name="Lever002_vis"/>
    <mesh file="visuals/Lid001.obj" name="Lid001_vis"/>
    <mesh file="visuals/Lid002.obj" name="Lid002_vis"/>
    <mesh file="visuals/Lid003.obj" name="Lid003_vis"/>
    <texture file="visuals/T_BC001.png" name="Body001_material" type="2d"/>
    <material name="Body001_material" rgba="1 1 1 1.0" texture="Body001_material" shininess="0.4472135901451111" specular="3"/>
    <texture file="visuals/T_BC001.png" name="Button001_material" type="2d"/>
    <material name="Button001_material" rgba="1 1 1 1.0" texture="Button001_material" shininess="0.4472135901451111" specular="0.3103448502657381"/>
    <texture file="visuals/T_BC001.png" name="Button002_material" type="2d"/>
    <material name="Button002_material" rgba="1 1 1 1.0" texture="Button002_material" shininess="0.4472135901451111" specular="0.3103448502657381"/>
    <texture file="visuals/T_BC001.png" name="Container001_Clear_material" type="2d"/>
    <material name="Container001_Clear_material" rgba="1 1 1 0.13636359572410583" texture="Container001_Clear_material" shininess="0.4472135901451111" specular="0.3103448502657381"/>
    <texture file="visuals/T_BC001.png" name="Lid003_material" type="2d"/>
    <material name="Lid003_material" rgba="1 1 1 1.0" texture="Lid003_material" shininess="0.4472135901451111" specular="0.3103448502657381"/>
    <texture file="visuals/T_BC001.png" name="Lever001_material" type="2d"/>
    <material name="Lever001_material" rgba="1 1 1 1.0" texture="Lever001_material" shininess="0.4472135901451111" specular="3"/>
    <texture file="visuals/T_BC001.png" name="Lever002_material" type="2d"/>
    <material name="Lever002_material" rgba="1 1 1 1.0" texture="Lever002_material" shininess="0.4472135901451111" specular="6"/>
    <texture file="visuals/T_BC001.png" name="Lid001_material" type="2d"/>
    <material name="Lid001_material" rgba="1 1 1 1.0" texture="Lid001_material" shininess="0.4472135901451111" specular="0.3103448502657381"/>
    <texture file="visuals/T_BC001.png" name="Lid002_material" type="2d"/>
    <material name="Lid002_material" rgba="1 1 1 1.0" texture="Lid002_material" shininess="0.4472135901451111" specular="0.3103448502657381"/>
  </asset>
  <default>
    <default class="visual">
      <geom conaffinity="0" contype="0" group="1" type="mesh"/>
    </default>
    <default class="collision">
      <geom group="0" rgba="0.5 0 0 0.5"/>
    </default>
    <default class="spawn">
      <geom group="0" rgba="1 1 1 0.5" contype="0" conaffinity="0"/>
      <site group="0" rgba="1 1 1 0.5"/>
    </default>
    <default class="region">
      <geom group="1" conaffinity="0" contype="0" rgba="0 1 0 0"/>
    </default>
  </default>
  <worldbody>
    <body>
      <body name="object">
        <geom class="collision" type="box" pos="0.039583224803209305 -0.1312839239835739 0.07921957969665527" size="0.007719576824456453 0.0006592688732780516 0.007719576824456453" quat="1.0 0.0 0.0 0.0" name="start_button_2" rgba="0.0 0.5 0 0.5"/>
        <geom class="collision" type="box" pos="-0.022556018084287643 -0.1312839239835739 0.07933254539966583" size="0.007719576824456453 0.0006592688732780516 0.007719576824456453" quat="1.0 0.0 0.0 0.0" name="start_button_1" rgba="0.0 0.5 0 0.5"/>
        <site type="cylinder" rgba="0.8 0.5 0.25 1" size="0.002471896121278405 0.08510515093803406" pos="0.007965503260493279 -0.040124084800481796 -0.12177497893571854" name="coffee_liquid"/>
        <site rgba="0 0 0 0" size="0.009999999776482582 0.009999999776482582" pos="0.00811292976140976 -0.0405646413564682 -0.18187128007411957" name="receptacle_place_site"/>
        <geom mesh="Body001_vis" type="mesh" solimp="0.998 0.998 0.001" solref="0.001 1" density="100" friction="0.95 0.3 0.1" class="visual" material="Body001_material"/>
        <geom class="collision" type="box" pos="0.007972228340804577 0.023939594626426697 -0.21091483533382416" size="0.13606508076190948 0.15155373513698578 0.01878664642572403" quat="1.0 0.0 0.0 0.0"/>
        <geom class="collision" type="box" pos="-0.11179772019386292 -0.0533299520611763 -0.18670199811458588" size="0.016294386237859726 0.07307751476764679 0.003998314030468464" quat="1.0 0.0 0.0 0.0"/>
        <geom class="collision" type="box" pos="0.12763404846191406 -0.0533299520611763 -0.18670199811458588" size="0.01629439927637577 0.07307756692171097 0.003998317290097475" quat="1.0 0.0 0.0 0.0"/>
        <geom class="collision" type="box" pos="0.007972228340804577 0.09959402680397034 -0.0447087436914444" size="0.13606508076190948 0.07589931041002274 0.1474127173423767" quat="1.0 0.0 0.0 0.0"/>
        <geom class="collision" type="box" pos="0.007972228340804577 -0.03670744225382805 0.0955081433057785" size="0.13606508076190948 0.08800991624593735 0.06361173093318939" quat="1.0 0.0 0.0 0.0"/>
        <geom class="collision" type="box" pos="0.007911131717264652 0.2001836597919464 -0.08268803358078003" size="0.06947555392980576 0.022279180586338043 0.005434736143797636" quat="1.0 0.0 0.0 0.0"/>
        <geom class="collision" type="box" pos="0.010076425038278103 0.23640437424182892 -0.08268803358078003" size="0.053830429911613464 0.01223550271242857 0.005434736143797636" quat="1.0 0.0 0.0 0.0"/>
        <geom class="collision" type="box" pos="0.007899260148406029 -0.10106587409973145 0.18981927633285522" size="0.0930277407169342 0.0030366566497832537 0.0030366566497832537" quat="1.0 0.0 0.0 0.0"/>
        <geom class="collision" type="box" pos="-0.08749401569366455 -0.08634346723556519 0.18861307203769684" size="0.01507650502026081 0.0030366566497832537 0.0030366566497832537" quat="0.6579318046569824 -0.056131310760974884 0.06383802741765976 0.748264491558075"/>
        <geom class="collision" type="box" pos="-0.08749401569366455 -0.07302220910787582 0.17341583967208862" size="0.003036648267880082 0.0030366491992026567 0.01507644448429346" quat="1.0 0.0 0.0 0.0"/>
        <geom class="collision" type="box" pos="0.10279612243175507 -0.08634346723556519 0.18861307203769684" size="0.01507650502026081 0.0030366566497832537 0.0030366566497832537" quat="0.7533503174781799 -0.04695308580994606 0.07086201012134552 0.6521022319793701"/>
        <geom class="collision" type="box" pos="0.10362353920936584 -0.07302220910787582 0.17341583967208862" size="0.003036650363355875 0.0030366505961865187 0.01507645659148693" quat="1.0 0.0 0.0 0.0"/>
        <geom class="collision" type="box" pos="0.09795491397380829 0.09959401935338974 0.1309119164943695" size="0.04608239233493805 0.07589931041002274 0.028207950294017792" quat="1.0 0.0 0.0 0.0"/>
        <geom class="collision" type="box" pos="-0.08313673734664917 0.09959401935338974 0.1309119164943695" size="0.04495612159371376 0.07589931041002274 0.028207950294017792" quat="1.0 0.0 0.0 0.0"/>
        <geom class="collision" type="box" pos="0.006901388056576252 0.1583334505558014 0.1309119164943695" size="0.0506950207054615 0.017159875482320786 0.028207950294017792" quat="1.0 0.0 0.0 0.0"/>
        <body name="Button001">
          <joint axis="0.0 1.0 0.0" pos="-0.022446535527706146 -0.13093294203281403 0.07912077754735947" limited="true" name="Button001_joint" range="0.0 0.0015" type="slide" damping="1" frictionloss="1" armature=".01" stiffness="0.05"/>
          <geom mesh="Button001_vis" type="mesh" solimp="0.998 0.998 0.001" solref="0.001 1" density="100" friction="0.95 0.3 0.1" class="visual" material="Button001_material"/>
          <geom class="collision" type="box" pos="-0.022556018084287643 -0.12932269275188446 0.07933254539966583" size="0.007719576824456453 0.0006592688732780516 0.007719576824456453" quat="1.0 0.0 0.0 0.0"/>
        </body>
        <body name="Button002">
          <joint axis="0.0 1.0 0.0" pos="0.03956078737974167 -0.13093294203281403 0.07912077754735947" limited="true" name="Button002_joint" range="0.0 0.0015" type="slide" damping="1" frictionloss="1" armature=".01" stiffness="0.05"/>
          <geom mesh="Button002_vis" type="mesh" solimp="0.998 0.998 0.001" solref="0.001 1" density="100" friction="0.95 0.3 0.1" class="visual" material="Button002_material"/>
          <geom class="collision" type="box" pos="0.039583224803209305 -0.12932269275188446 0.07921957969665527" size="0.007719576824456453 0.0006592688732780516 0.007719576824456453" quat="1.0 0.0 0.0 0.0"/>
        </body>
        <body name="Container001_Clear">
          <joint axis="0.0 0.0 1.0" pos="0.00797213800251484 0.21707592904567719 0.025129862129688263" limited="true" name="Container001_Clear_joint" range="0.0 0.1" type="slide" damping="1" frictionloss="1" armature=".01" stiffness="0.05"/>
          <geom mesh="Container001_Clear_vis" type="mesh" solimp="0.998 0.998 0.001" solref="0.001 1" density="100" friction="0.95 0.3 0.1" class="visual" material="Container001_Clear_material"/>
          <geom class="collision" type="box" pos="0.07384487241506577 0.2001836597919464 0.04256868734955788" size="0.003541779238730669 0.022279180586338043 0.11773624271154404" quat="1.0 0.0 0.0 0.0"/>
          <geom class="collision" type="box" pos="0.010076389648020267 0.24613457918167114 0.04161379858851433" size="0.03716644272208214 0.003595772199332714 0.11678135395050049" quat="1.0 0.0 0.0 0.0"/>
          <geom class="collision" type="box" pos="0.007911130785942078 0.2001836597919464 -0.06947944313287735" size="0.06947555392980576 0.022279180586338043 0.005688115488737822" quat="1.0 0.0 0.0 0.0"/>
          <geom class="collision" type="box" pos="0.010076424106955528 0.23640437424182892 -0.0704343393445015" size="0.053830429911613464 0.01223550271242857 0.00473322719335556" quat="1.0 0.0 0.0 0.0"/>
          <geom class="collision" type="box" pos="-0.0585189089179039 0.2001836597919464 0.04256868734955788" size="0.003541779238730669 0.022279180586338043 0.11773624271154404" quat="1.0 0.0 0.0 0.0"/>
          <geom class="collision" type="box" pos="0.06208522990345955 0.23333798348903656 0.04256868734955788" size="0.003541779238730669 0.022279180586338043 0.11773624271154404" quat="0.9279055595397949 0.0 0.0 0.37281534075737"/>
          <geom class="collision" type="box" pos="-0.04214711859822273 0.23333798348903656 0.04256868734955788" size="0.003541779238730669 0.022279180586338043 0.11773624271154404" quat="0.9279055595397949 0.0 -0.0 -0.3728153705596924"/>
          <geom class="collision" type="box" pos="0.010156135074794292 0.18199697136878967 0.04117928445339203" size="0.07094264030456543 0.003595771500840783 0.1167813390493393" quat="1.0 0.0 0.0 0.0"/>
          <body name="Lid003">
            <joint axis="0.0 0.0 1.0" pos="0.007972081191837788 0.2178983986377716 0.1601223349571228" limited="true" name="Lid003_joint" range="0.0 0.05" type="slide" damping="1" frictionloss="1" armature=".01" stiffness="0.05"/>
            <geom mesh="Lid003_vis" type="mesh" solimp="0.998 0.998 0.001" solref="0.001 1" density="100" friction="0.95 0.3 0.1" class="visual" material="Lid003_material"/>
            <geom class="collision" type="box" pos="0.007911136373877525 0.20084577798843384 0.1648629754781723" size="0.06947555392980576 0.021617062389850616 0.003998309373855591" quat="1.0 0.0 0.0 0.0"/>
            <geom class="collision" type="box" pos="0.010076429694890976 0.23640437424182892 0.1648629754781723" size="0.053830429911613464 0.01223550271242857 0.003998309373855591" quat="1.0 0.0 0.0 0.0"/>
          </body>
        </body>
        <body name="Lever001">
          <joint axis="0.0 0.0 1.0" pos="0.007972147315740585 -0.04036591947078705 0.004816548898816109" limited="true" name="Lever001_joint" range="-0.5235987755982988 0.5235987755982988" type="hinge" damping="1" frictionloss="1" armature=".01" stiffness="1"/>
          <geom mesh="Lever001_vis" type="mesh" solimp="0.998 0.998 0.001" solref="0.001 1" density="100" friction="0.95 0.3 0.1" class="visual" material="Lever001_material"/>
          <geom class="collision" type="cylinder" pos="0.00813333224505186 -0.21323803067207336 0.0077765220776200294" size="0.020122921094298363 0.03700771555304527" quat="0.7071068286895752 0.7071067690849304 0.0 0.0"/>
          <geom class="collision" type="cylinder" pos="0.00813333224505186 -0.12211866676807404 0.0077765146270394325" size="0.018018677830696106 0.05480995401740074" quat="0.7071068286895752 0.7071067690849304 0.0 0.0"/>
          <geom class="collision" type="cylinder" pos="0.007997777312994003 -0.04040057957172394 -0.029380930587649345" size="0.008313307538628578 0.008313307538628578" quat="1.0 0.0 0.0 0.0"/>
          <geom class="collision" type="cylinder" pos="0.007997776381671429 -0.040340933948755264 0.016485633328557014" size="0.03726630285382271 0.012563414871692657" quat="1.0 0.0 0.0 0.0"/>
          <geom class="collision" type="cylinder" pos="0.00799777451902628 -0.040340933948755264 -0.00227895169518888" size="0.03065260872244835 0.007361642085015774" quat="1.0 0.0 0.0 0.0"/>
          <geom class="collision" type="cylinder" pos="0.007997777312994003 -0.040340933948755264 -0.014595048502087593" size="0.02383929118514061 0.005725330673158169" quat="1.0 0.0 0.0 0.0"/>
          <geom class="collision" type="box" pos="0.007959139533340931 -0.16368088126182556 0.03170967474579811" size="0.013275433331727982 0.001972730038687587 0.006394472438842058" quat="1.0 0.0 0.0 0.0"/>
        </body>
        <body name="Lever002">
          <joint axis="0.0 0.0 1.0" pos="-0.04476284235715866 -0.013405725359916687 0.027409031987190247" limited="true" name="Lever002_joint" range="-0.5235987755982988 0.5235987755982988" type="hinge" damping="1" frictionloss="1" armature=".01" stiffness="1"/>
          <geom mesh="Lever002_vis" type="mesh" solimp="0.998 0.998 0.001" solref="0.001 1" density="100" friction="0.95 0.3 0.1" class="visual" material="Lever002_material"/>
          <geom class="collision" type="cylinder" pos="-0.12982988357543945 -0.05151864141225815 -0.043371934443712234" size="0.0038898633792996407 0.04914293438196182" quat="0.9920128583908081 -0.052596431225538254 0.11448700726032257 -0.006070064380764961"/>
          <geom class="collision" type="cylinder" pos="-0.08035501092672348 -0.029051540419459343 0.010298892855644226" size="0.003889863146468997 0.04027672857046127" quat="0.7357292175292969 -0.14064598083496094 0.6426465511322021 0.1610175371170044"/>
          <geom class="collision" type="cylinder" pos="-0.04450255259871483 -0.013831159099936485 0.022630218416452408" size="0.0038898633792996407 0.007651560939848423" quat="1.0 0.0 0.0 0.0"/>
          <geom class="collision" type="cylinder" pos="-0.12425584346055984 -0.04899906367063522 -0.019677970558404922" size="0.008620746433734894 0.011520910076797009" quat="0.9920128583908081 -0.052596431225538254 0.11448700726032257 -0.006070064380764961"/>
        </body>
        <body name="Lid001">
          <joint axis="0.0 0.0 1.0" pos="0.00797216221690178 -0.05953061208128929 -0.18362975120544434" limited="true" name="Lid001_joint" range="0.0 0.05" type="slide" damping="1" frictionloss="1" armature=".01" stiffness="0.05"/>
          <geom mesh="Lid001_vis" type="mesh" solimp="0.998 0.998 0.001" solref="0.001 1" density="100" friction="0.95 0.3 0.1" class="visual" material="Lid001_material"/>
          <geom class="collision" type="box" pos="0.007722922135144472 -0.05387892946600914 -0.18640482425689697" size="0.10106132924556732 0.07362643629312515 0.004295484162867069" quat="1.0 0.0 0.0 0.0"/>
        </body>
        <body name="Lid002">
          <joint axis="0.0 0.0 1.0" pos="0.00825733132660389 0.0947655588388443 0.2012258917093277" limited="true" name="Lid002_joint" range="0.0 0.05" type="slide" damping="1" frictionloss="1" armature=".01" stiffness="0.05"/>
          <geom mesh="Lid002_vis" type="mesh" solimp="0.998 0.998 0.001" solref="0.001 1" density="100" friction="0.95 0.3 0.1" class="visual" material="Lid002_material"/>
          <geom class="collision" type="cylinder" pos="0.00882868841290474 0.09479297697544098 0.1954895555973053" size="0.05190379172563553 0.029139190912246704" quat="1.0 0.0 0.0 0.0"/>
        </body>
        <geom class="region" name="reg_main" type="box" pos="0.0 0.0 7.450580596923828e-09" size="0.14403730630874634 0.2527812123298645 0.23317193984985352"/>
      </body>
    </body>
  </worldbody>
  <actuator>
    <motor name="Button001_joint_actuator" joint="Button001_joint" gear="0.5"/>
    <motor name="Button002_joint_actuator" joint="Button002_joint" gear="0.5"/>
    <motor name="Container001_Clear_joint_actuator" joint="Container001_Clear_joint" gear="100"/>
    <motor name="Lever001_joint_actuator" joint="Lever001_joint" gear="10"/>
    <motor name="Lever002_joint_actuator" joint="Lever002_joint" gear="10"/>
    <motor name="Lid001_joint_actuator" joint="Lid001_joint" gear="10"/>
    <motor name="Lid002_joint_actuator" joint="Lid002_joint" gear="10"/>
    <motor name="Lid003_joint_actuator" joint="Lid003_joint" gear="10"/>
  </actuator>
</mujoco>
