<mujoco model="model">
  <compiler angle="radian"/>
  <asset>
    <mesh file="visuals/handle.obj" name="handle_vis"/>
    <mesh file="visuals/Body001.obj" name="Body001_vis"/>
    <mesh file="visuals/Funnel001.obj" name="Funnel001_vis"/>
    <mesh file="visuals/spout.obj" name="spout_vis"/>
    <texture file="visuals/T_BC001.png" name="Body001_material" type="2d"/>
    <material name="Body001_material" rgba="1 1 1 1.0" texture="Body001_material" shininess="0.141421377658844" specular="0.3103448502657381"/>
    <texture file="visuals/T_BC001.png" name="handle_material" type="2d"/>
    <material name="handle_material" rgba="1 1 1 1.0" texture="handle_material" shininess="0.141421377658844" specular="0.3103448502657381"/>
    <texture file="visuals/T_BC001.png" name="Funnel001_material" type="2d"/>
    <material name="Funnel001_material" rgba="1 1 1 1.0" texture="Funnel001_material" shininess="0.141421377658844" specular="0.3103448502657381"/>
    <texture file="visuals/T_BC001.png" name="spout_material" type="2d"/>
    <material name="spout_material" rgba="1 1 1 1.0" texture="spout_material" shininess="0.141421377658844" specular="0.3103448502657381"/>
  </asset>
  <default>
    <default class="visual">
      <geom conaffinity="0" contype="0" group="1" type="mesh"/>
    </default>
    <default class="collision">
      <geom group="0" rgba="0.5 0 0 0.5"/>
    </default>
    <default class="spawn">
      <geom group="0" rgba="1 1 1 0.5" contype="0" conaffinity="0"/>
      <site group="0" rgba="1 1 1 0.5"/>
    </default>
    <default class="region">
      <geom group="1" conaffinity="0" contype="0" rgba="0 1 0 0"/>
    </default>
  </default>
  <worldbody>
    <body>
      <body name="object">
        <geom mesh="Body001_vis" type="mesh" solimp="0.998 0.998 0.001" solref="0.001 1" density="100" friction="0.95 0.3 0.1" class="visual" material="Body001_material"/>
        <geom class="collision" type="box" pos="0.0004361170285847038 0.2123851329088211 -0.15302921831607819" size="0.2912743091583252 0.03833097219467163 0.12881487607955933" quat="1.0 0.0 0.0 0.0"/>
        <geom class="collision" type="box" pos="-0.2768246531486511 0.00023259222507476807 -0.15302921831607819" size="0.014013539999723434 0.25048351287841797 0.12881487607955933" quat="1.0 0.0 0.0 0.0"/>
        <geom class="collision" type="box" pos="-0.17628233134746552 -0.006911349017173052 -0.24843457341194153" size="0.11455585807561874 0.2449672371149063 0.03340951353311539" quat="1.0 0.0 0.0 0.0"/>
        <geom class="collision" type="box" pos="0.2778264582157135 0.00023259222507476807 -0.15302921831607819" size="0.014013539999723434 0.25048351287841797 0.12881487607955933" quat="1.0 0.0 0.0 0.0"/>
        <geom class="collision" type="box" pos="0.0004361170285847038 -0.23778802156448364 -0.15302921831607819" size="0.2912743091583252 0.011451894417405128 0.12881487607955933" quat="1.0 0.0 0.0 0.0"/>
        <geom class="collision" type="box" pos="0.00947922095656395 -0.13789765536785126 -0.24843457341194153" size="0.264898419380188 0.11398094147443771 0.03340951353311539" quat="1.0 0.0 0.0 0.0"/>
        <geom class="collision" type="box" pos="0.1598217934370041 -0.006911349017173052 -0.24843457341194153" size="0.11455585807561874 0.2449672371149063 0.03340951353311539" quat="1.0 0.0 0.0 0.0"/>
        <geom class="collision" type="box" pos="0.00947922095656395 0.13114690780639648 -0.24843457341194153" size="0.264898419380188 0.045668892562389374 0.03340951353311539" quat="1.0 0.0 0.0 0.0"/>
        <geom class="collision" type="box" pos="0.00947922095656395 0.030766069889068604 -0.2589940130710602" size="0.264898419380188 0.05664733797311783 0.022850066423416138" quat="1.0 0.0 0.0 0.0"/>
        <geom class="collision" type="cylinder" pos="-0.23102819919586182 0.21956892311573029 -0.015700601041316986" size="0.018706005066633224 0.009212618693709373" quat="1.0 0.0 0.0 0.0"/>
        <geom class="collision" type="cylinder" pos="-0.008521336130797863 0.22017937898635864 0.003657592460513115" size="0.016683461144566536 0.02757469192147255" quat="0.7071068286895752 0.0 0.0 0.7071067690849304"/>
        <geom class="collision" type="cylinder" pos="0.012675931677222252 0.2198953628540039 0.009904640726745129" size="0.012313892133533955 0.013861095532774925" quat="0.49999770522117615 0.5000000596046448 0.5000022649765015 0.4999999403953552"/>
        <body name="handle">
          <joint axis="1.0 0.0 0.0" pos="0.026260405778884888 0.21996662020683289 0.010362421162426472" limited="true" name="handle_joint_hinge_0" type="hinge" range="-0.7853981633974483 0.7853981633974483" damping="1" frictionloss="1" armature=".01" stiffness="0.05"/>
          <joint axis="0.0 1.0 0.0" pos="0.026260405778884888 0.21996662020683289 0.010362421162426472" limited="true" name="handle_joint_hinge_1" type="hinge" range="0.0 0.2617993877991494" damping="1" frictionloss="1" armature=".01" stiffness="0.05"/>
          <geom mesh="handle_vis" type="mesh" solimp="0.998 0.998 0.001" solref="0.001 1" density="100" friction="0.95 0.3 0.1" class="visual" material="handle_material"/>
          <geom class="collision" type="cylinder" pos="0.03340592980384827 0.21956302225589752 0.05337700992822647" size="0.0040099951438605785 0.030342772603034973" quat="0.7071068286895752 0.0 0.0 0.7071067690849304"/>
          <geom class="collision" type="cylinder" pos="0.03601875528693199 0.2199769765138626 0.00971183367073536" size="0.014395428821444511 0.0036695136222988367" quat="0.49999770522117615 0.5000000596046448 0.5000022649765015 0.4999999403953552"/>
        </body>
        <body name="Funnel001">
          <joint axis="0.0 0.0 1.0" pos="-0.009145500138401985 0.02786899544298649 -0.22682301700115204" limited="true" name="Funnel001_joint" range="0.0 0.1" type="slide" damping="1" frictionloss="1" armature=".01" stiffness="0.05"/>
          <geom mesh="Funnel001_vis" type="mesh" solimp="0.998 0.998 0.001" solref="0.001 1" density="100" friction="0.95 0.3 0.1" class="visual" material="Funnel001_material"/>
          <geom class="collision" type="cylinder" pos="-0.009288927540183067 0.028217310085892677 -0.23071512579917908" size="0.03858840838074684 0.0014626639895141125" quat="1.0 0.0 0.0 0.0"/>
          <geom class="collision" type="cylinder" pos="-0.009020810015499592 0.027589844539761543 -0.2263965755701065" size="0.009702772833406925 0.002236995380371809" quat="1.0 0.0 0.0 0.0"/>
          <geom class="collision" type="box" pos="-0.009514469653367996 -0.013568460941314697 -0.22389210760593414" size="0.007504936307668686 0.0063612330704927444 0.0054296813905239105" quat="1.0 0.0 0.0 0.0"/>
          <geom class="collision" type="box" pos="0.003389945952221751 -0.011668737046420574 -0.22389210760593414" size="0.007504936307668686 0.006361232604831457 0.0054296813905239105" quat="0.9889285564422607 0.0 0.0 0.1483922302722931"/>
          <geom class="collision" type="box" pos="0.015097168274223804 -0.0059336102567613125 -0.22389210760593414" size="0.007504936773329973 0.006361233536154032 0.0054296813905239105" quat="0.9506728649139404 0.0 0.0 0.31019535660743713"/>
          <geom class="collision" type="box" pos="0.024593353271484375 0.003409360069781542 -0.22389210760593414" size="0.007504935842007399 0.0063612330704927444 0.0054296813905239105" quat="0.9016807675361633 0.0 0.0 0.4324023127555847"/>
          <geom class="collision" type="box" pos="0.030434563755989075 0.014565115794539452 -0.22389210760593414" size="0.007504936307668686 0.0063612330704927444 0.0054296813905239105" quat="0.8065516948699951 0.0 0.0 0.5911635756492615"/>
          <geom class="collision" type="box" pos="0.03296256437897682 0.027779659256339073 -0.22389210760593414" size="0.007504936307668686 0.006361233536154032 0.0054296813905239105" quat="0.7310456037521362 0.0 0.0 0.6823286414146423"/>
          <geom class="collision" type="box" pos="0.031169984489679337 0.040120892226696014 -0.22389210760593414" size="0.007504936307668686 0.0063612330704927444 0.0054296813905239105" quat="0.586713433265686 0.0 0.0 0.8097946047782898"/>
          <geom class="collision" type="box" pos="0.024964893236756325 0.05186919867992401 -0.22389210760593414" size="0.007504936307668686 0.006361232604831457 0.0054296813905239105" quat="0.4251607060432434 0.0 0.0 0.9051178693771362"/>
          <geom class="collision" type="box" pos="0.015450422652065754 0.06080453097820282 -0.22389210760593414" size="0.007504936307668686 0.0063612330704927444 0.0054296813905239105" quat="0.2755248546600342 0.0 0.0 0.9612939357757568"/>
          <geom class="collision" type="box" pos="0.0037021192256361246 0.06750603020191193 -0.22389210760593414" size="0.007504936307668686 0.006361233536154032 0.0054296813905239105" quat="0.14602966606616974 0.0 0.0 0.9892802238464355"/>
          <geom class="collision" type="box" pos="-0.009204467758536339 0.06916072219610214 -0.22389210760593414" size="0.007504936307668686 0.0063612330704927444 0.0054296813905239105" quat="-0.022832240909337997 0.0 0.0 0.9997392892837524"/>
          <geom class="collision" type="box" pos="-0.021780116483569145 0.0672578290104866 -0.22389210760593414" size="0.007504936773329973 0.006361233536154032 0.0054296813905239105" quat="-0.1851990967988968 0.0 0.0 0.9827010035514832"/>
          <geom class="collision" type="box" pos="-0.03526584431529045 0.060556329786777496 -0.22389210760593414" size="0.007504935842007399 0.006361232604831457 0.0054296813905239105" quat="-0.3314373791217804 0.0 0.0 0.943477213382721"/>
          <geom class="collision" type="box" pos="-0.04494578391313553 0.05013177543878555 -0.22389210760593414" size="0.007504936307668686 0.006361233536154032 0.0054296813905239105" quat="-0.4811118245124817 0.0 0.0 0.8766592144966125"/>
          <geom class="collision" type="box" pos="-0.04999259114265442 0.03796979784965515 -0.22389210760593414" size="0.007504936307668686 0.0063612330704927444 0.0054296813905239105" quat="-0.606969952583313 0.0 0.0 0.7947247624397278"/>
          <geom class="collision" type="box" pos="-0.05159212648868561 0.024442700669169426 -0.22389210760593414" size="0.007504935842007399 0.0063612330704927444 0.0054296813905239105" quat="-0.7313275337219238 0.0 0.0 0.6820263862609863"/>
          <geom class="collision" type="box" pos="-0.047938019037246704 0.010515724308788776 -0.22389210760593414" size="0.007504935842007399 0.0063612330704927444 0.0054296813905239105" quat="-0.8123117685317993 0.0 0.0 0.5832234621047974"/>
          <geom class="collision" type="box" pos="-0.04262922331690788 0.0012080922024324536 -0.22389210760593414" size="0.007504936307668686 0.006361233536154032 0.0054296813905239105" quat="-0.8933490514755249 0.0 0.0 0.44936347007751465"/>
          <geom class="collision" type="box" pos="-0.033114753663539886 -0.007065359503030777 -0.22389210760593414" size="0.007504936307668686 0.0063612330704927444 0.0054296813905239105" quat="-0.9493938684463501 0.0 0.0 0.31408795714378357"/>
          <geom class="collision" type="box" pos="-0.02277293987572193 -0.011960484087467194 -0.22389210760593414" size="0.007504936307668686 0.0063612330704927444 0.0054296813905239105" quat="-0.9924213290214539 0.0 0.0 0.12288180738687515"/>
        </body>
        <body name="spout">
          <joint axis="0.0 0.0 1.0" pos="-0.008934499695897102 0.21987931430339813 0.15196599066257477" limited="true" name="spout_joint" range="-0.7853981633974483 0.7853981633974483" type="hinge" damping="1" frictionloss="1" armature=".01" stiffness="0.05"/>
          <site type="cylinder" rgba="0.5 0.75 1 1" size="0.006065879482775927 0.2152324616909027" pos="-0.009099733084440231 0.027332251891493797 -0.03505042940378189" name="water"/>
          <geom mesh="spout_vis" type="mesh" solimp="0.998 0.998 0.001" solref="0.001 1" density="100" friction="0.95 0.3 0.1" class="visual" material="spout_material"/>
          <geom class="collision" type="cylinder" pos="-0.00886296946555376 0.21938465535640717 0.11024174839258194" size="0.010048693045973778 0.0785842090845108" quat="1.0 0.0 0.0 0.0"/>
          <geom class="collision" type="cylinder" pos="-0.00886296946555376 0.20319879055023193 0.22848886251449585" size="0.010048693045973778 0.017451457679271698" quat="0.9656886458396912 0.25970259308815 5.766556629770934e-17 -1.7851537715460202e-24"/>
          <geom class="collision" type="cylinder" pos="-0.00886296946555376 0.18345436453819275 0.25120916962623596" size="0.010048693045973778 0.019898122176527977" quat="0.8884070515632629 0.459056556224823 1.0193105151752095e-16 1.3295278680864922e-23"/>
          <geom class="collision" type="cylinder" pos="-0.00886296946555376 0.14356428384780884 0.2693922221660614" size="0.010048693045973778 0.020374983549118042" quat="0.7983346581459045 0.6022140383720398 1.3371837823062722e-16 1.0411496667633645e-23"/>
          <geom class="collision" type="cylinder" pos="-0.00886296946555376 0.09494275599718094 0.26721125841140747" size="0.010048693045973778 0.018348298966884613" quat="0.5963873863220215 0.8026967644691467 1.782344991760424e-16 -4.541982032717364e-25"/>
          <geom class="collision" type="cylinder" pos="-0.00886296946555376 0.05173811689019203 0.23765726387500763" size="0.010048693045973778 0.017533086240291595" quat="0.33013781905174255 0.9439327120780945 2.0959678078574952e-16 8.835709775219947e-23"/>
          <geom class="collision" type="cylinder" pos="-0.00886296946555376 0.03132658079266548 0.19109773635864258" size="0.010048693045973778 0.023006346076726913" quat="0.10297983139753342 0.9946834444999695 2.2086407922457523e-16 2.1929968316975463e-24"/>
          <geom class="collision" type="cylinder" pos="-0.00886296946555376 0.0715356096625328 0.2561853229999542" size="0.010048693045973778 0.018348298966884613" quat="0.4717880189418793 0.881712019443512 1.9577941024987594e-16 2.2470153838030487e-23"/>
          <geom class="collision" type="cylinder" pos="-0.00886296946555376 0.037656936794519424 0.2161986231803894" size="0.010048693045973778 0.017533086240291595" quat="0.1843382567167282 0.9828628897666931 2.1823940205371997e-16 2.4115640377952806e-23"/>
          <geom class="collision" type="cylinder" pos="-0.00886296946555376 0.12046951055526733 0.27161917090415955" size="0.010048693045973778 0.020374981686472893" quat="0.7158699631690979 0.6982336044311523 1.550390048412958e-16 -7.198455945476696e-24"/>
          <geom class="collision" type="cylinder" pos="-0.00886296946555376 0.1646672785282135 0.2623564898967743" size="0.010048693045973778 0.019898122176527977" quat="0.8523038625717163 0.5230469703674316 1.1613975789247092e-16 1.8351938614482215e-23"/>
          <geom class="collision" type="cylinder" pos="-0.00886296946555376 0.21559345722198486 0.20255321264266968" size="0.010048693045973778 0.017451457679271698" quat="0.9905076622962952 0.13745738565921783 3.052168081889604e-17 -1.780933119184055e-25"/>
        </body>
        <geom class="region" name="reg_main" type="box" pos="-7.450580596923828e-09 -1.4901161193847656e-08 -0.15333902835845947" size="0.28999999165534973 0.24990250170230865 0.12788501381874084"/>
        <geom class="region" name="reg_basin" type="box" pos="-0.0024650096893310547 -0.025816358625888824 -0.12526441924273968" size="0.2623489797115326 0.19807863980531693 0.09292957372963428"/>
      </body>
    </body>
  </worldbody>
  <actuator>
    <motor name="handle_joint_hinge_0_actuator" joint="handle_joint_hinge_0" gear="10"/>
    <motor name="handle_joint_hinge_1_actuator" joint="handle_joint_hinge_1" gear="10"/>
    <motor name="Funnel001_joint_actuator" joint="Funnel001_joint" gear="10"/>
    <motor name="spout_joint_actuator" joint="spout_joint" gear="10"/>
  </actuator>
</mujoco>
