<mujoco model="model">
  <compiler angle="radian"/>
  <asset>
    <texture file="visuals/material_0.png" name="tex-model" type="2d"/>
    <texture type="2d" name="image7" file="visuals/image7.png"/>
    <texture type="2d" name="image2" file="visuals/image2.png"/>
    <texture type="2d" name="image5" file="visuals/image5.png"/>
    <material name="model" reflectance="0.5" texrepeat="1 1" texture="tex-model" texuniform="false"/>
    <material name="TX_Microwave_3_1" texture="image7" specular="0.5" shininess="0.25"/>
    <material name="TX_Microwave_3_2" texture="image2" specular="0.5" shininess="0.25"/>
    <material name="TX_Microwave_3_3" texture="image5" specular="0.5" shininess="0.25"/>
    <mesh file="visuals/model_0.obj" name="model_0_vis" scale="1 1 1"/>
    <mesh file="visuals/model_1.obj" name="model_1_vis" scale="1 1 1"/>
    <mesh file="visuals/model_2.obj" name="model_2_vis" scale="1 1 1"/>
    <mesh file="visuals/door_0.obj" name="door_0_vis" scale="1 1 1"/>
    <mesh file="visuals/door_1.obj" name="door_1_vis" scale="1 1 1"/>
    <mesh file="visuals/door_2.obj" name="door_2_vis" scale="1 1 1"/>
  </asset>
  <default>
    <default class="visual">
      <geom conaffinity="0" contype="0" group="1" type="mesh"/>
    </default>
    <default class="collision">
      <geom group="0" rgba="0.5 0 0 0.5"/>
    </default>
  </default>
  <worldbody>
    <body>
      <body name="object">
        <geom solimp="0.998 0.998 0.001" solref="0.001 1" density="100" friction="0.95 0.3 0.1" type="mesh" mesh="model_0_vis" material="TX_Microwave_3_2" class="visual"/>
        <geom solimp="0.998 0.998 0.001" solref="0.001 1" density="100" friction="0.95 0.3 0.1" type="mesh" mesh="model_1_vis" material="TX_Microwave_3_3" class="visual"/>
        <geom solimp="0.998 0.998 0.001" solref="0.001 1" density="100" friction="0.95 0.3 0.1" type="mesh" mesh="model_2_vis" material="TX_Microwave_3_1" class="visual"/>
        <!-- Numpad inside fix -->
        <geom class="visual" type="box" rgba="0.4 0.4 0.4 1" pos="0.36 -0.369 0.029" size="0.095 0.033 0.25"/>
        <geom class="visual" type="box" rgba="0.4 0.4 0.4 1" pos="0.36 -0.362 0.29" size="0.095 0.03 0.011"/>
        <geom class="visual" type="box" rgba="0.4 0.4 0.4 1" pos="0.36 -0.363 -0.238" size="0.095 0.03 0.017"/>
        <!-- Back -->
        <geom class="collision" type="box" pos="0 0.42 0" size="0.485 0.09 0.302"/>
        <!-- Bottom -->
        <geom class="collision" type="box" pos="0 0 -0.248" size="0.485 0.334 0.055"/>
        <!-- Left -->
        <geom class="collision" type="box" pos="-0.46 0 0" size="0.025 0.334 0.302"/>
        <!-- Right -->
        <geom class="collision" type="box" pos="0.335 0 0" size="0.148 0.334 0.302"/>
        <!-- Top -->
        <geom class="collision" type="box" pos="0 0 0.273" size="0.485 0.334 0.029"/>
        <!-- Numpad -->
        <geom class="collision" type="box" pos="0.374 -0.369 0.023" size="0.109 0.037 0.279"/>
        <!-- start/stop buttons -->
        <geom class="collision" type="box" pos="0.425 -0.385 -0.13" size="0.03 0.0216 0.025" name="start_button" rgba="0.0 0.5 0 0.5"/>
        <geom class="collision" type="box" pos="0.30 -0.385 -0.13" size="0.03 0.0216 0.025" name="stop_button" rgba="0.0 0.5 0 0.5"/>
        <geom class="collision" type="cylinder" pos="-0.12 -0.02 -0.195" size="0.22 0.005" rgba="0 1 0 0.5" name="tray"/>
        <body name="door">
          <joint axis="0 0 1" limited="true" name="microjoint" range="-1.57 0" damping="2" frictionloss="2" armature=".01" pos="-0.485 -0.334 0" ref="0"/>
          <geom solimp="0.998 0.998 0.001" solref="0.001 1" density="100" friction="0.95 0.3 0.1" type="mesh" mesh="door_0_vis" material="TX_Microwave_3_2" class="visual"/>
          <geom solimp="0.998 0.998 0.001" solref="0.001 1" density="100" friction="0.95 0.3 0.1" type="mesh" mesh="door_1_vis" material="TX_Microwave_3_3" class="visual"/>
          <geom solimp="0.998 0.998 0.001" solref="0.001 1" density="100" friction="0.95 0.3 0.1" type="mesh" mesh="door_2_vis" material="TX_Microwave_3_1" class="visual"/>
          <!-- Door Main -->
          <geom class="collision" type="box" pos="-0.09 -0.371 0.023" size="0.3519 0.037 0.279"/>
          <!-- Handle Top -->
          <geom class="collision" type="box" pos="0.204 -0.453 0.236" size="0.027 0.047 0.021"/>
          <!-- Handle Bottom -->
          <geom class="collision" type="box" pos="0.204 -0.453 -0.159" size="0.027 0.047 0.021"/>
          <!-- Handle Main -->
          <geom class="collision" type="cylinder" pos="0.204 -0.474 0.039" size="0.022 0.18 0" name="door_handle"/>
          <!-- door sites -->
          <site rgba="1 0 0 0" size="0.005" pos="-0.075 -0.40 0.01" name="door_p1"/>
          <site rgba="0 1 0 0" size="0.005" pos="-0.025 -0.40 0.01" name="door_p2"/>
          <site rgba="0 0 1 0" size="0.005" pos="-0.075 -0.40 0.06" name="door_p3"/>
        </body>
        <!-- exterior bounding box points -->
        <geom name="reg_main_body" conaffinity="0" contype="0" group="1" type="box" size="0.485 0.4365 0.2825" pos="0.0 0.028500000000000025 0.022499999999999992" rgba="1 1 0 0"/>
        <!-- interior bounding box points -->
        <geom name="reg_int" conaffinity="0" contype="0" group="1" type="box" size="0.311 0.332 0.222" pos="-0.124 -0.0020000000000000018 0.021999999999999992" rgba="0 1 0 0"/>
      </body>
    </body>
  </worldbody>
</mujoco>
