<mujoco model="model">
  <compiler angle="radian"/>
  <asset>
    <mesh file="visuals/Body001.obj" name="Body001_vis"/>
    <mesh file="visuals/Body001_Clear.obj" name="Body001_Clear_vis"/>
    <mesh file="visuals/Door001.obj" name="Door001_vis"/>
    <mesh file="visuals/Door001_Clear.obj" name="Door001_Clear_vis"/>
    <mesh file="visuals/Door002.obj" name="Door002_vis"/>
    <mesh file="visuals/Door002_Clear.obj" name="Door002_Clear_vis"/>
    <mesh file="visuals/Drawer001.obj" name="Drawer001_vis"/>
    <mesh file="visuals/Drawer002.obj" name="Drawer002_vis"/>
    <mesh file="visuals/Drawer003.obj" name="Drawer003_vis"/>
    <mesh file="visuals/Drawer004.obj" name="Drawer004_vis"/>
    <mesh file="visuals/Drawer005.obj" name="Drawer005_vis"/>
    <mesh file="visuals/Drawer006.obj" name="Drawer006_vis"/>
    <texture file="visuals/T_BC001.png" name="Body001_material" type="2d"/>
    <material name="Body001_material" rgba="1 1 1 1.0" texture="Body001_material" shininess="0.141421377658844" specular="0.3103448502657381"/>
    <material name="Body001_Clear_material" rgba="0.5879999995231628 0.5879999995231628 0.5879999995231628 0.29741376638412476" shininess="0.141421377658844" specular="0.3103448502657381"/>
    <texture file="visuals/T_BC001.png" name="Door001_material" type="2d"/>
    <material name="Door001_material" rgba="1 1 1 1.0" texture="Door001_material" shininess="0.141421377658844" specular="0.3103448502657381"/>
    <material name="Door001_Clear_material" rgba="0.5879999995231628 0.5879999995231628 0.5879999995231628 0.29741376638412476" shininess="0.141421377658844" specular="0.3103448502657381"/>
    <texture file="visuals/T_BC001.png" name="Door002_material" type="2d"/>
    <material name="Door002_material" rgba="1 1 1 1.0" texture="Door002_material" shininess="0.141421377658844" specular="0.3103448502657381"/>
    <material name="Door002_Clear_material" rgba="0.5879999995231628 0.5879999995231628 0.5879999995231628 0.29741376638412476" shininess="0.141421377658844" specular="0.3103448502657381"/>
    <texture file="visuals/T_BC001.png" name="Drawer001_material" type="2d"/>
    <material name="Drawer001_material" rgba="1 1 1 1.0" texture="Drawer001_material" shininess="0.141421377658844" specular="0.3103448502657381"/>
    <texture file="visuals/T_BC001.png" name="Drawer002_material" type="2d"/>
    <material name="Drawer002_material" rgba="1 1 1 1.0" texture="Drawer002_material" shininess="0.141421377658844" specular="0.3103448502657381"/>
    <texture file="visuals/T_BC001.png" name="Drawer003_material" type="2d"/>
    <material name="Drawer003_material" rgba="1 1 1 1.0" texture="Drawer003_material" shininess="0.141421377658844" specular="0.3103448502657381"/>
    <texture file="visuals/T_BC001.png" name="Drawer004_material" type="2d"/>
    <material name="Drawer004_material" rgba="1 1 1 1.0" texture="Drawer004_material" shininess="0.141421377658844" specular="0.3103448502657381"/>
    <texture file="visuals/T_BC001.png" name="Drawer005_material" type="2d"/>
    <material name="Drawer005_material" rgba="1 1 1 1.0" texture="Drawer005_material" shininess="0.141421377658844" specular="0.3103448502657381"/>
    <texture file="visuals/T_BC001.png" name="Drawer006_material" type="2d"/>
    <material name="Drawer006_material" rgba="1 1 1 1.0" texture="Drawer006_material" shininess="0.141421377658844" specular="0.3103448502657381"/>
  </asset>
  <default>
    <default class="visual">
      <geom conaffinity="0" contype="0" group="1" type="mesh"/>
    </default>
    <default class="collision">
      <geom group="0" rgba="0.5 0 0 0.5"/>
    </default>
    <default class="spawn">
      <geom group="0" rgba="1 1 1 0.5" contype="0" conaffinity="0"/>
      <site group="0" rgba="1 1 1 0.5"/>
    </default>
    <default class="region">
      <geom group="1" conaffinity="0" contype="0" rgba="0 1 0 0"/>
    </default>
  </default>
  <worldbody>
    <body>
      <body name="object">
        <geom mesh="Body001_vis" type="mesh" solimp="0.998 0.998 0.001" solref="0.001 1" density="100" friction="0.95 0.3 0.1" class="visual" material="Body001_material"/>
        <geom class="collision" type="box" pos="-0.016813 0.382124 0.049981" size="0.4438280463218689 0.034385766834020615 0.8702205419540405" quat="1.0 0.0 0.0 0.0"/>
        <geom class="collision" type="box" pos="0.424056 0.071677 -0.000300" size="0.03631758689880371 0.3448333144187927 0.9205009341239929" quat="1.0 0.0 0.0 0.0"/>
        <geom class="collision" type="box" pos="-0.423157 0.071677 -0.000300" size="0.03748410567641258 0.3448333144187927 0.9205009341239929" quat="1.0 0.0 0.0 0.0"/>
        <geom class="collision" type="box" pos="-0.016813 0.071677 -0.834020" size="0.4438280463218689 0.3448333144187927 0.03212868049740791" quat="1.0 0.0 0.0 0.0"/>
        <geom class="collision" type="box" pos="-0.001792 0.050878 -0.889424" size="0.45884913206100464 0.36563196778297424 0.03212868049740791" quat="1.0 0.0 0.0 0.0"/>
        <geom class="collision" type="box" pos="-0.016813 0.071677 0.888073" size="0.4438280463218689 0.3448333144187927 0.03212868049740791" quat="1.0 0.0 0.0 0.0"/>
        <geom class="collision" type="box" pos="0.012706 0.085278 0.598519" size="0.005047741811722517 0.27649617195129395 0.038640059530735016" quat="1.0 0.0 0.0 0.0"/>
        <geom class="collision" type="box" pos="0.404169 0.085278 0.598519" size="0.005047741811722517 0.27649617195129395 0.038640059530735016" quat="1.0 0.0 0.0 0.0"/>
        <geom class="collision" type="box" pos="-0.402846 0.085278 0.598519" size="0.005047741811722517 0.27649617195129395 0.038640059530735016" quat="1.0 0.0 0.0 0.0"/>
        <geom class="collision" type="box" pos="-0.402846 0.085278 0.266983" size="0.005047741811722517 0.27649617195129395 0.038640059530735016" quat="1.0 0.0 0.0 0.0"/>
        <geom class="collision" type="box" pos="0.404169 0.085278 0.266983" size="0.005047741811722517 0.27649617195129395 0.038640059530735016" quat="1.0 0.0 0.0 0.0"/>
        <geom class="collision" type="box" pos="0.012706 0.085278 0.266983" size="0.005047741811722517 0.27649617195129395 0.038640059530735016" quat="1.0 0.0 0.0 0.0"/>
        <geom class="collision" type="box" pos="0.000045 0.062923 -0.403471" size="0.019796887412667274 0.29134079813957214 0.40340542793273926" quat="1.0 0.0 0.0 0.0"/>
        <body name="Body001_Clear">
          <geom mesh="Body001_Clear_vis" type="mesh" solimp="0.998 0.998 0.001" solref="0.001 1" density="100" friction="0.95 0.3 0.1" class="visual" material="Body001_Clear_material"/>
          <geom class="collision" type="box" pos="0.000837 0.064792 0.640074" size="0.378988653421402 0.2545841336250305 0.005309588275849819" quat="1.0 0.0 0.0 0.0"/>
          <geom class="collision" type="box" pos="0.000837 0.064792 0.308163" size="0.378988653421402 0.2545841336250305 0.005309588275849819" quat="1.0 0.0 0.0 0.0"/>
        </body>
        <body name="Door001">
          <joint axis="0.0 -2.7425745221132825e-15 -1.0" pos="-0.423015 -0.317409 0.018729" limited="true" name="Door001_joint" range="0.0 1.5707963267948966" type="hinge" damping="1" frictionloss="1" armature=".01" stiffness="0.05"/>
          <geom mesh="Door001_vis" type="mesh" solimp="0.998 0.998 0.001" solref="0.001 1" density="100" friction="0.95 0.3 0.1" class="visual" material="Door001_material"/>
          <geom class="collision" type="box" pos="-0.105999 -0.375461 0.281121" size="0.00784711167216301 0.015974299982190132 0.009277479723095894" quat="1.0 0.0 0.0 0.0"/>
          <geom class="collision" type="box" pos="-0.105999 -0.375461 -0.076206" size="0.007847119122743607 0.01597430743277073 0.009277488104999065" quat="1.0 0.0 0.0 0.0"/>
          <geom class="collision" type="box" pos="-0.105578 -0.402137 0.236662" size="0.014525260776281357 0.0745832622051239 0.00947658997029066" quat="0.7363455891609192 0.6766056418418884 0.0 0.0"/>
          <geom class="collision" type="box" pos="-0.105578 -0.402599 -0.028677" size="0.014525260776281357 0.0745832622051239 0.00947658997029066" quat="5.559254034892547e-08 5.108230993755569e-08 0.7363455295562744 -0.6766057014465332"/>
          <geom class="collision" type="box" pos="-0.105578 -0.408102 0.101841" size="0.014525260776281357 0.0745718777179718 0.009477976709604263" quat="5.366500488435122e-08 5.310367257038706e-08 0.7108145952224731 -0.7033794522285461"/>
          <geom class="collision" type="box" pos="-0.251567 -0.330462 0.035591" size="0.2057373821735382 0.026373615488409996 0.885962724685669" quat="1.0 0.0 0.0 0.0"/>
          <body name="Door001_Clear">
            <geom mesh="Door001_Clear_vis" type="mesh" solimp="0.998 0.998 0.001" solref="0.001 1" density="100" friction="0.95 0.3 0.1" class="visual" material="Door001_Clear_material"/>
            <geom class="collision" type="box" pos="-0.093675 -0.204790 0.220483" size="0.003785009728744626 0.06231058016419411 0.03261616453528404" quat="1.0 0.0 0.0 0.0"/>
            <geom class="collision" type="box" pos="-0.353605 -0.204790 0.220483" size="0.003785009728744626 0.06231058016419411 0.03261616453528404" quat="1.0 0.0 0.0 0.0"/>
            <geom class="collision" type="box" pos="-0.223696 -0.146824 0.220483" size="0.1338062435388565 0.0022211794275790453 0.03261615335941315" quat="1.0 0.0 0.0 0.0"/>
            <geom class="collision" type="box" pos="-0.223696 -0.205872 0.190510" size="0.1338062435388565 0.05933448672294617 0.00264250161126256" quat="1.0 0.0 0.0 0.0"/>
            <geom class="collision" type="box" pos="-0.223696 -0.266145 0.220483" size="0.1338062435388565 0.0022211794275790453 0.03261615335941315" quat="1.0 0.0 0.0 0.0"/>
            <geom class="collision" type="box" pos="-0.093675 -0.204790 0.454175" size="0.003785009728744626 0.06231058016419411 0.03261616453528404" quat="1.0 0.0 0.0 0.0"/>
            <geom class="collision" type="box" pos="-0.353605 -0.204790 0.454175" size="0.003785009728744626 0.06231058016419411 0.03261616453528404" quat="1.0 0.0 0.0 0.0"/>
            <geom class="collision" type="box" pos="-0.223696 -0.146824 0.454175" size="0.1338062435388565 0.0022211794275790453 0.03261615335941315" quat="1.0 0.0 0.0 0.0"/>
            <geom class="collision" type="box" pos="-0.223696 -0.205872 0.424202" size="0.1338062435388565 0.05933448672294617 0.00264250161126256" quat="1.0 0.0 0.0 0.0"/>
            <geom class="collision" type="box" pos="-0.223696 -0.266145 0.454175" size="0.1338062435388565 0.0022211794275790453 0.03261615335941315" quat="1.0 0.0 0.0 0.0"/>
            <geom class="collision" type="box" pos="-0.093675 -0.204790 0.682652" size="0.003785009728744626 0.06231058016419411 0.03261616453528404" quat="1.0 0.0 0.0 0.0"/>
            <geom class="collision" type="box" pos="-0.353605 -0.204790 0.682652" size="0.003785009728744626 0.06231058016419411 0.03261616453528404" quat="1.0 0.0 0.0 0.0"/>
            <geom class="collision" type="box" pos="-0.223696 -0.146824 0.682652" size="0.1338062435388565 0.0022211794275790453 0.03261615335941315" quat="1.0 0.0 0.0 0.0"/>
            <geom class="collision" type="box" pos="-0.223696 -0.205872 0.652678" size="0.1338062435388565 0.05933448672294617 0.00264250161126256" quat="1.0 0.0 0.0 0.0"/>
            <geom class="collision" type="box" pos="-0.223696 -0.266145 0.682652" size="0.1338062435388565 0.0022211794275790453 0.03261615335941315" quat="1.0 0.0 0.0 0.0"/>
          </body>
        </body>
        <body name="Door002">
          <joint axis="0.0 2.7425745221132825e-15 1.0" pos="0.425569 -0.317409 0.018729" limited="true" name="Door002_joint" range="0.0 1.5707963267948966" type="hinge" damping="1" frictionloss="1" armature=".01" stiffness="0.05"/>
          <geom mesh="Door002_vis" type="mesh" solimp="0.998 0.998 0.001" solref="0.001 1" density="100" friction="0.95 0.3 0.1" class="visual" material="Door002_material"/>
          <geom class="collision" type="box" pos="0.018887 -0.408102 0.101841" size="0.014525260776281357 0.0745718777179718 0.009477976709604263" quat="5.366500488435122e-08 5.310367257038706e-08 0.7108145952224731 -0.7033794522285461"/>
          <geom class="collision" type="box" pos="0.018887 -0.402599 -0.028677" size="0.014525260776281357 0.0745832622051239 0.00947658997029066" quat="5.559254034892547e-08 5.108230993755569e-08 0.7363455295562744 -0.6766057014465332"/>
          <geom class="collision" type="box" pos="0.018887 -0.402137 0.236662" size="0.014525260776281357 0.0745832622051239 0.00947658997029066" quat="0.7363455891609192 0.6766056418418884 0.0 0.0"/>
          <geom class="collision" type="box" pos="0.018466 -0.375461 -0.076206" size="0.007847125642001629 0.015974316745996475 0.009277496486902237" quat="1.0 0.0 0.0 0.0"/>
          <geom class="collision" type="box" pos="0.018466 -0.375461 0.281121" size="0.007847133092582226 0.01597432605922222 0.009277504868805408" quat="1.0 0.0 0.0 0.0"/>
          <geom class="collision" type="box" pos="0.209902 -0.330462 0.035591" size="0.2497742921113968 0.026373615488409996 0.885962724685669" quat="1.0 0.0 0.0 0.0"/>
          <body name="Door002_Clear">
            <geom mesh="Door002_Clear_vis" type="mesh" solimp="0.998 0.998 0.001" solref="0.001 1" density="100" friction="0.95 0.3 0.1" class="visual" material="Door002_Clear_material"/>
            <geom class="collision" type="box" pos="0.354575 -0.204790 0.682652" size="0.003785009728744626 0.06231058016419411 0.03261616453528404" quat="1.0 0.0 0.0 0.0"/>
            <geom class="collision" type="box" pos="0.354575 -0.204790 0.454175" size="0.003785009728744626 0.06231058016419411 0.03261616453528404" quat="1.0 0.0 0.0 0.0"/>
            <geom class="collision" type="box" pos="0.354575 -0.204790 0.220483" size="0.003785009728744626 0.06231058016419411 0.03261616453528404" quat="1.0 0.0 0.0 0.0"/>
            <geom class="collision" type="box" pos="0.094645 -0.204790 0.682652" size="0.003785009728744626 0.06231058016419411 0.03261616453528404" quat="1.0 0.0 0.0 0.0"/>
            <geom class="collision" type="box" pos="0.094645 -0.204790 0.454175" size="0.003785009728744626 0.06231058016419411 0.03261616453528404" quat="1.0 0.0 0.0 0.0"/>
            <geom class="collision" type="box" pos="0.094645 -0.204790 0.220483" size="0.003785009728744626 0.06231058016419411 0.03261616453528404" quat="1.0 0.0 0.0 0.0"/>
            <geom class="collision" type="box" pos="0.224553 -0.146824 0.682652" size="0.1338062435388565 0.0022211794275790453 0.03261615335941315" quat="1.0 0.0 0.0 0.0"/>
            <geom class="collision" type="box" pos="0.224553 -0.146824 0.454175" size="0.1338062435388565 0.0022211794275790453 0.03261615335941315" quat="1.0 0.0 0.0 0.0"/>
            <geom class="collision" type="box" pos="0.224553 -0.146824 0.220483" size="0.1338062435388565 0.0022211794275790453 0.03261615335941315" quat="1.0 0.0 0.0 0.0"/>
            <geom class="collision" type="box" pos="0.224553 -0.205872 0.652678" size="0.1338062435388565 0.05933448672294617 0.00264250161126256" quat="1.0 0.0 0.0 0.0"/>
            <geom class="collision" type="box" pos="0.224553 -0.205872 0.424202" size="0.1338062435388565 0.05933448672294617 0.00264250161126256" quat="1.0 0.0 0.0 0.0"/>
            <geom class="collision" type="box" pos="0.224553 -0.205872 0.190510" size="0.1338062435388565 0.05933448672294617 0.00264250161126256" quat="1.0 0.0 0.0 0.0"/>
            <geom class="collision" type="box" pos="0.224553 -0.266145 0.682652" size="0.1338062435388565 0.0022211794275790453 0.03261615335941315" quat="1.0 0.0 0.0 0.0"/>
            <geom class="collision" type="box" pos="0.224553 -0.266145 0.454175" size="0.1338062435388565 0.0022211794275790453 0.03261615335941315" quat="1.0 0.0 0.0 0.0"/>
            <geom class="collision" type="box" pos="0.224553 -0.266145 0.220483" size="0.1338062435388565 0.0022211794275790453 0.03261615335941315" quat="1.0 0.0 0.0 0.0"/>
          </body>
        </body>
        <body name="Drawer001">
          <joint axis="0.0 -1.0 2.7425745221132825e-15" pos="-0.214018 0.094951 -0.135478" limited="true" name="Drawer001_joint" range="0.0 0.3" type="slide" damping="1" frictionloss="1" armature=".01" stiffness="0.05"/>
          <geom mesh="Drawer001_vis" type="mesh" solimp="0.998 0.998 0.001" solref="0.001 1" density="100" friction="0.95 0.3 0.1" class="visual" material="Drawer001_material"/>
          <geom class="collision" type="box" pos="-0.201345 -0.125979 -0.146088" size="0.17529575526714325 0.009535533376038074 0.10549142211675644" quat="1.0 0.0 0.0 0.0"/>
          <geom class="collision" type="box" pos="-0.034791 0.098914 -0.150835" size="0.0024029372725635767 0.22436416149139404 0.10074503719806671" quat="1.0 0.0 0.0 0.0"/>
          <geom class="collision" type="box" pos="-0.366343 0.098914 -0.150835" size="0.002402936341241002 0.22436416149139404 0.10074503719806671" quat="1.0 0.0 0.0 0.0"/>
          <geom class="collision" type="box" pos="-0.201400 0.101638 -0.247365" size="0.16821546852588654 0.21998432278633118 0.004214934539049864" quat="1.0 0.0 0.0 0.0"/>
          <geom class="collision" type="box" pos="-0.201144 0.322183 -0.150835" size="0.16897644102573395 0.002896403893828392 0.10074503719806671" quat="1.0 0.0 0.0 0.0"/>
        </body>
        <body name="Drawer002">
          <joint axis="0.0 -1.0 2.7425745221132825e-15" pos="-0.214018 0.094951 -0.400588" limited="true" name="Drawer002_joint" range="0.0 0.3" type="slide" damping="1" frictionloss="1" armature=".01" stiffness="0.05"/>
          <geom mesh="Drawer002_vis" type="mesh" solimp="0.998 0.998 0.001" solref="0.001 1" density="100" friction="0.95 0.3 0.1" class="visual" material="Drawer002_material"/>
          <geom class="collision" type="box" pos="-0.201144 0.322183 -0.415665" size="0.16897644102573395 0.002896403893828392 0.10074503719806671" quat="1.0 0.0 0.0 0.0"/>
          <geom class="collision" type="box" pos="-0.201400 0.101638 -0.512195" size="0.16821546852588654 0.21998432278633118 0.004214934539049864" quat="1.0 0.0 0.0 0.0"/>
          <geom class="collision" type="box" pos="-0.366343 0.098914 -0.415665" size="0.002402936341241002 0.22436416149139404 0.10074503719806671" quat="1.0 0.0 0.0 0.0"/>
          <geom class="collision" type="box" pos="-0.034791 0.098914 -0.415665" size="0.0024029372725635767 0.22436416149139404 0.10074503719806671" quat="1.0 0.0 0.0 0.0"/>
          <geom class="collision" type="box" pos="-0.201345 -0.125979 -0.410918" size="0.17529575526714325 0.009535533376038074 0.10549142211675644" quat="1.0 0.0 0.0 0.0"/>
        </body>
        <body name="Drawer003">
          <joint axis="0.0 -1.0 2.7425745221132825e-15" pos="-0.214018 0.094951 -0.663753" limited="true" name="Drawer003_joint" range="0.0 0.3" type="slide" damping="1" frictionloss="1" armature=".01" stiffness="0.05"/>
          <geom mesh="Drawer003_vis" type="mesh" solimp="0.998 0.998 0.001" solref="0.001 1" density="100" friction="0.95 0.3 0.1" class="visual" material="Drawer003_material"/>
          <geom class="collision" type="box" pos="-0.201345 -0.125979 -0.673272" size="0.17529575526714325 0.009535533376038074 0.10549142211675644" quat="1.0 0.0 0.0 0.0"/>
          <geom class="collision" type="box" pos="-0.034791 0.098914 -0.678018" size="0.0024029372725635767 0.22436416149139404 0.10074503719806671" quat="1.0 0.0 0.0 0.0"/>
          <geom class="collision" type="box" pos="-0.366343 0.098914 -0.678018" size="0.002402936341241002 0.22436416149139404 0.10074503719806671" quat="1.0 0.0 0.0 0.0"/>
          <geom class="collision" type="box" pos="-0.201400 0.101638 -0.774548" size="0.16821546852588654 0.21998432278633118 0.004214934539049864" quat="1.0 0.0 0.0 0.0"/>
          <geom class="collision" type="box" pos="-0.201144 0.322183 -0.678018" size="0.16897644102573395 0.002896403893828392 0.10074503719806671" quat="1.0 0.0 0.0 0.0"/>
        </body>
        <body name="Drawer004">
          <joint axis="0.0 -1.0 2.7425745221132825e-15" pos="0.215015 0.094951 -0.135478" limited="true" name="Drawer004_joint" range="0.0 0.3" type="slide" damping="1" frictionloss="1" armature=".01" stiffness="0.05"/>
          <geom mesh="Drawer004_vis" type="mesh" solimp="0.998 0.998 0.001" solref="0.001 1" density="100" friction="0.95 0.3 0.1" class="visual" material="Drawer004_material"/>
          <geom class="collision" type="box" pos="0.202936 -0.125979 -0.146088" size="0.1761501580476761 0.009535533376038074 0.10549142211675644" quat="1.0 0.0 0.0 0.0"/>
          <geom class="collision" type="box" pos="0.203137 0.322183 -0.150835" size="0.1698308289051056 0.002896403893828392 0.10074503719806671" quat="1.0 0.0 0.0 0.0"/>
          <geom class="collision" type="box" pos="0.202882 0.101638 -0.247365" size="0.16906984150409698 0.21998432278633118 0.004214934539049864" quat="1.0 0.0 0.0 0.0"/>
          <geom class="collision" type="box" pos="0.037084 0.098914 -0.150835" size="0.0024029372725635767 0.22436416149139404 0.10074503719806671" quat="1.0 0.0 0.0 0.0"/>
          <geom class="collision" type="box" pos="0.370345 0.098914 -0.150835" size="0.002402937039732933 0.22436416149139404 0.10074503719806671" quat="1.0 0.0 0.0 0.0"/>
        </body>
        <body name="Drawer005">
          <joint axis="0.0 -1.0 2.7425745221132825e-15" pos="0.215015 0.094951 -0.400588" limited="true" name="Drawer005_joint" range="0.0 0.3" type="slide" damping="1" frictionloss="1" armature=".01" stiffness="0.05"/>
          <geom mesh="Drawer005_vis" type="mesh" solimp="0.998 0.998 0.001" solref="0.001 1" density="100" friction="0.95 0.3 0.1" class="visual" material="Drawer005_material"/>
          <geom class="collision" type="box" pos="0.202936 -0.125979 -0.410918" size="0.1761501580476761 0.009535533376038074 0.10549142211675644" quat="1.0 0.0 0.0 0.0"/>
          <geom class="collision" type="box" pos="0.370345 0.098914 -0.415665" size="0.002402937039732933 0.22436416149139404 0.10074503719806671" quat="1.0 0.0 0.0 0.0"/>
          <geom class="collision" type="box" pos="0.037084 0.098914 -0.415665" size="0.0024029372725635767 0.22436416149139404 0.10074503719806671" quat="1.0 0.0 0.0 0.0"/>
          <geom class="collision" type="box" pos="0.202882 0.101638 -0.512195" size="0.16906984150409698 0.21998432278633118 0.004214934539049864" quat="1.0 0.0 0.0 0.0"/>
          <geom class="collision" type="box" pos="0.203137 0.322183 -0.415665" size="0.1698308289051056 0.002896403893828392 0.10074503719806671" quat="1.0 0.0 0.0 0.0"/>
        </body>
        <body name="Drawer006">
          <joint axis="0.0 -1.0 2.7425745221132825e-15" pos="0.215015 0.094951 -0.663753" limited="true" name="Drawer006_joint" range="0.0 0.3" type="slide" damping="1" frictionloss="1" armature=".01" stiffness="0.05"/>
          <geom mesh="Drawer006_vis" type="mesh" solimp="0.998 0.998 0.001" solref="0.001 1" density="100" friction="0.95 0.3 0.1" class="visual" material="Drawer006_material"/>
          <geom class="collision" type="box" pos="0.203137 0.322183 -0.678018" size="0.1698308289051056 0.002896403893828392 0.10074503719806671" quat="1.0 0.0 0.0 0.0"/>
          <geom class="collision" type="box" pos="0.202882 0.101638 -0.774548" size="0.16906984150409698 0.21998432278633118 0.004214934539049864" quat="1.0 0.0 0.0 0.0"/>
          <geom class="collision" type="box" pos="0.037084 0.098914 -0.678018" size="0.0024029372725635767 0.22436416149139404 0.10074503719806671" quat="1.0 0.0 0.0 0.0"/>
          <geom class="collision" type="box" pos="0.370345 0.098914 -0.678018" size="0.002402937039732933 0.22436416149139404 0.10074503719806671" quat="1.0 0.0 0.0 0.0"/>
          <geom class="collision" type="box" pos="0.202936 -0.125979 -0.673272" size="0.1761501580476761 0.009535533376038074 0.10549142211675644" quat="1.0 0.0 0.0 0.0"/>
        </body>
        <geom class="region" name="reg_main" type="box" pos="0.00030249999999998334 0.026568499999999995 0.0018785000000000052" size="0.4603375 0.3894275 0.9194985"/>
      </body>
    </body>
  </worldbody>
  <actuator>
    <motor name="Door001_joint_actuator" joint="Door001_joint" gear="50"/>
    <motor name="Door002_joint_actuator" joint="Door002_joint" gear="50"/>
    <motor name="Drawer001_joint_actuator" joint="Drawer001_joint" gear="50"/>
    <motor name="Drawer002_joint_actuator" joint="Drawer002_joint" gear="50"/>
    <motor name="Drawer003_joint_actuator" joint="Drawer003_joint" gear="50"/>
    <motor name="Drawer004_joint_actuator" joint="Drawer004_joint" gear="50"/>
    <motor name="Drawer005_joint_actuator" joint="Drawer005_joint" gear="50"/>
    <motor name="Drawer006_joint_actuator" joint="Drawer006_joint" gear="50"/>
  </actuator>
</mujoco>
