<mujoco model="model">
  <compiler angle="radian"/>
  <asset>
    <mesh file="visuals/Body001.obj" name="Body001_vis"/>
    <mesh file="visuals/Button001.obj" name="Button001_vis"/>
    <mesh file="visuals/Button002.obj" name="Button002_vis"/>
    <mesh file="visuals/Container001_Clear.obj" name="Container001_Clear_vis"/>
    <mesh file="visuals/Lid001.obj" name="Lid001_vis"/>
    <mesh file="visuals/Lid002.obj" name="Lid002_vis"/>
    <mesh file="visuals/Lid003.obj" name="Lid003_vis"/>
    <texture file="visuals/T_BC001.png" name="Body001_material" type="2d"/>
    <material name="Body001_material" rgba="1 1 1 1.0" texture="Body001_material" shininess="0.4472135901451111" specular="1"/>
    <texture file="visuals/T_BC001.png" name="Button001_material" type="2d"/>
    <material name="Button001_material" rgba="1 1 1 1.0" texture="Button001_material" shininess="0.4472135901451111" specular="1"/>
    <texture file="visuals/T_BC001.png" name="Button002_material" type="2d"/>
    <material name="Button002_material" rgba="1 1 1 1.0" texture="Button002_material" shininess="0.4472135901451111" specular="1"/>
    <texture file="visuals/T_BC001.png" name="Container001_Clear_material" type="2d"/>
    <material name="Container001_Clear_material" rgba="1 1 1 0.15636134147644043" texture="Container001_Clear_material" shininess="0.4472135901451111" specular="0.3103448502657381"/>
    <texture file="visuals/T_BC001.png" name="Lid003_material" type="2d"/>
    <material name="Lid003_material" rgba="1 1 1 1.0" texture="Lid003_material" shininess="0.4472135901451111" specular="1"/>
    <texture file="visuals/T_BC001.png" name="Lid001_material" type="2d"/>
    <material name="Lid001_material" rgba="1 1 1 1.0" texture="Lid001_material" shininess="0.4472135901451111" specular="1"/>
    <texture file="visuals/T_BC001.png" name="Lid002_material" type="2d"/>
    <material name="Lid002_material" rgba="1 1 1 1.0" texture="Lid002_material" shininess="0.4472135901451111" specular="1"/>
  </asset>
  <default>
    <default class="visual">
      <geom conaffinity="0" contype="0" group="1" type="mesh"/>
    </default>
    <default class="collision">
      <geom group="0" rgba="0.5 0 0 0.5"/>
    </default>
    <default class="spawn">
      <geom group="0" rgba="1 1 1 0.5" contype="0" conaffinity="0"/>
      <site group="0" rgba="1 1 1 0.5"/>
    </default>
    <default class="region">
      <geom group="1" conaffinity="0" contype="0" rgba="0 1 0 0"/>
    </default>
  </default>
  <worldbody>
    <body>
      <body name="object">
        <geom class="collision" type="box" pos="-0.018050096929073334 -0.20923642814159393 0.019880376756191254" size="0.007607913576066494 0.000513038074132055 0.007609408348798752" quat="1.0 0.0 0.0 0.0" name="start_button_1" rgba="0.0 0.5 0 0.5"/>
        <geom class="collision" type="box" pos="0.019412139430642128 -0.20923642814159393 0.019880376756191254" size="0.007607912644743919 0.000513038074132055 0.007609408348798752" quat="1.0 0.0 0.0 0.0" name="start_button_2" rgba="0.0 0.5 0 0.5"/>
        <site type="cylinder" rgba="0.8 0.5 0.25 1" size="0.0027536980342119932 0.06338528543710709" pos="-0.015527896583080292 -0.17875368893146515 -0.11882961541414261" name="coffee_liquid_left"/>
        <site rgba="0 0 0 0" size="0.009999999776482582 0.009999999776482582" pos="-0.01603623479604721 -0.17851491272449493 -0.1711750328540802" name="receptacle_place_site001"/>
        <site rgba="0 0 0 0" size="0.009999999776482582 0.009999999776482582" pos="0.015832852572202682 -0.17851491272449493 -0.1711750328540802" name="receptacle_place_site002"/>
        <site type="cylinder" rgba="0.8 0.5 0.25 1" size="0.0027536980342119932 0.06338528543710709" pos="0.0163411907851696 -0.17875368893146515 -0.11882961541414261" name="coffee_liquid_right"/>
        <geom mesh="Body001_vis" type="mesh" solimp="0.998 0.998 0.001" solref="0.001 1" density="100" friction="0.95 0.3 0.1" class="visual" material="Body001_material"/>
        <geom class="collision" type="box" pos="-0.0018081322778016329 -0.008352495729923248 -0.11013568192720413" size="0.16140811145305634 0.11595714092254639 0.1767483353614807" quat="1.0 0.0 0.0 0.0"/>
        <geom class="collision" type="box" pos="-0.0018081322778016329 -0.05096442997455597 0.14814423024654388" size="0.16140766441822052 0.15856853127479553 0.0741918683052063" quat="1.0 0.0 0.0 0.0"/>
        <geom class="collision" type="box" pos="-0.0018081322778016329 -0.2232503592967987 0.16413545608520508" size="0.16140811145305634 0.014656653627753258 0.0975407287478447" quat="0.9989863634109497 -0.045013654977083206 0.0 0.0"/>
        <geom class="collision" type="box" pos="2.3095635697245598e-05 -0.1769639402627945 0.04561735689640045" size="0.040392324328422546 0.027623746544122696 0.06020960584282875" quat="1.0 0.0 0.0 0.0"/>
        <geom class="collision" type="box" pos="2.3095635697245598e-05 -0.17800618708133698 -0.029646430164575577" size="0.05014890059828758 0.04398461803793907 0.01660066843032837" quat="1.0 0.0 0.0 0.0"/>
        <geom class="collision" type="box" pos="2.3095635697245598e-05 -0.18215309083461761 -0.22792154550552368" size="0.16366252303123474 0.07314565032720566 0.04473858326673508" quat="1.0 0.0 0.0 0.0"/>
        <geom class="collision" type="cylinder" pos="-0.01523048710078001 -0.17851823568344116 -0.055432677268981934" size="0.007415913511067629 0.005615164991468191" quat="1.0 0.0 0.0 0.0"/>
        <geom class="collision" type="cylinder" pos="0.015889642760157585 -0.17851823568344116 -0.055432677268981934" size="0.007415913511067629 0.005615164991468191" quat="1.0 0.0 0.0 0.0"/>
        <geom class="collision" type="box" pos="0.002026383299380541 -0.0810312032699585 0.2487303614616394" size="0.08055607974529266 0.009867528453469276 0.028551267459988594" quat="1.0 0.0 0.0 0.0"/>
        <geom class="collision" type="box" pos="0.12464404106140137 0.1814788430929184 -0.03227414935827255" size="0.03495582193136215 0.0738741084933281 0.25461024045944214" quat="1.0 0.0 0.0 0.0"/>
        <geom class="collision" type="box" pos="-0.12579992413520813 0.1814788430929184 -0.03227414935827255" size="0.03495582938194275 0.07387413084506989 0.25461024045944214" quat="1.0 0.0 0.0 0.0"/>
        <geom class="collision" type="box" pos="-0.0005779396742582321 0.1814788430929184 -0.18736642599105835" size="0.09026603400707245 0.07387415319681168 0.09951797872781754" quat="1.0 0.0 0.0 0.0"/>
        <geom class="collision" type="box" pos="0.002026383299380541 0.06972206383943558 0.2487303614616394" size="0.08055607974529266 0.01049297396093607 0.028551267459988594" quat="1.0 0.0 0.0 0.0"/>
        <geom class="collision" type="box" pos="0.07269097119569778 -0.0028506682720035315 0.2487303614616394" size="0.08055607974529266 0.011447040364146233 0.028551271185278893" quat="0.70710688829422 0.0 0.0 -0.7071066498756409"/>
        <geom class="collision" type="box" pos="-0.06724951416254044 -0.002850667806342244 0.2487303614616394" size="0.08055607974529266 0.010927602648735046 0.028551271185278893" quat="0.70710688829422 0.0 0.0 -0.7071066498756409"/>
        <body name="Button001">
          <joint axis="0.0 1.0 0.0" pos="-0.01812969706952572 -0.2061816304922104 0.01988898403942585" limited="true" name="Button001_joint" range="0.0 0.003" type="slide" damping="1" frictionloss="1" armature=".01" stiffness="0.05"/>
          <geom mesh="Button001_vis" type="mesh" solimp="0.998 0.998 0.001" solref="0.001 1" density="100" friction="0.95 0.3 0.1" class="visual" material="Button001_material"/>
          <geom class="collision" type="box" pos="-0.018050096929073334 -0.20743173360824585 0.019874684512615204" size="0.007607913576066494 0.0008148298365995288 0.007610357366502285" quat="1.0 0.0 0.0 0.0"/>
        </body>
        <body name="Button002">
          <joint axis="0.0 1.0 0.0" pos="0.01919984258711338 -0.2061815857887268 0.01988895982503891" limited="true" name="Button002_joint" range="0.0 0.003" type="slide" damping="1" frictionloss="1" armature=".01" stiffness="0.05"/>
          <geom mesh="Button002_vis" type="mesh" solimp="0.998 0.998 0.001" solref="0.001 1" density="100" friction="0.95 0.3 0.1" class="visual" material="Button002_material"/>
          <geom class="collision" type="box" pos="0.019412139430642128 -0.20743173360824585 0.019874684512615204" size="0.007607912644743919 0.0008148298365995288 0.007610357366502285" quat="1.0 0.0 0.0 0.0"/>
        </body>
        <body name="Container001_Clear">
          <joint axis="0.0 0.0 1.0" pos="-0.0005515962839126587 0.18424837291240692 0.07957255840301514" limited="true" name="Container001_Clear_joint" range="0.0 0.1" type="slide" damping="1" frictionloss="1" armature=".01" stiffness="0.05"/>
          <geom mesh="Container001_Clear_vis" type="mesh" solimp="0.998 0.998 0.001" solref="0.001 1" density="100" friction="0.95 0.3 0.1" class="visual" material="Container001_Clear_material"/>
          <geom class="collision" type="box" pos="-0.0005779396742582321 0.25053077936172485 0.08116258680820465" size="0.08521081507205963 0.004822235554456711 0.1619313508272171" quat="1.0 0.0 0.0 0.0"/>
          <geom class="collision" type="box" pos="-0.08414202183485031 0.18418189883232117 0.08116258680820465" size="0.004039258696138859 0.0706646591424942 0.1619313508272171" quat="1.0 0.0 0.0 0.0"/>
          <geom class="collision" type="box" pos="-0.0005779396742582321 0.11855147778987885 0.08116258680820465" size="0.08521081507205963 0.004822235554456711 0.1619313508272171" quat="1.0 0.0 0.0 0.0"/>
          <geom class="collision" type="box" pos="0.08096463233232498 0.18418189883232117 0.08116258680820465" size="0.004039258696138859 0.0706646591424942 0.1619313508272171" quat="1.0 0.0 0.0 0.0"/>
          <geom class="collision" type="box" pos="-0.0005779396742582321 0.18492837250232697 -0.07753968238830566" size="0.08521081507205963 0.062457527965307236 0.005437565501779318" quat="1.0 0.0 0.0 0.0"/>
          <body name="Lid003">
            <joint axis="0.0 0.0 1.0" pos="-0.0005515962839126587 0.18157488107681274 0.24958136677742004" limited="true" name="Lid003_joint" range="0.0 0.1" type="slide" damping="1" frictionloss="1" armature=".01" stiffness="0.05"/>
            <geom mesh="Lid003_vis" type="mesh" solimp="0.998 0.998 0.001" solref="0.001 1" density="100" friction="0.95 0.3 0.1" class="visual" material="Lid003_material"/>
            <geom class="collision" type="box" pos="-0.0005515934899449348 0.18174636363983154 0.2560531497001648" size="0.09321165084838867 0.07360666245222092 0.011472675018012524" quat="1.0 0.0 0.0 0.0"/>
          </body>
        </body>
        <body name="Lid001">
          <joint axis="0.0 0.0 1.0" pos="0.003058146685361862 -0.009461015462875366 0.28329718112945557" limited="true" name="Lid001_joint" range="0.0 0.1" type="slide" damping="1" frictionloss="1" armature=".01" stiffness="0.05"/>
          <geom mesh="Lid001_vis" type="mesh" solimp="0.998 0.998 0.001" solref="0.001 1" density="100" friction="0.95 0.3 0.1" class="visual" material="Lid001_material"/>
          <geom class="collision" type="box" pos="0.0042525408789515495 -0.004495017230510712 0.28284165263175964" size="0.07832992821931839 0.08269385248422623 0.003769206115975976" quat="1.0 0.0 0.0 0.0"/>
          <geom class="collision" type="box" pos="0.0042525408789515495 -0.09441821277141571 0.28284165263175964" size="0.04286365583539009 0.00635392963886261 0.0020625826437026262" quat="1.0 0.0 0.0 0.0"/>
        </body>
        <body name="Lid002">
          <joint axis="0.0 0.0 1.0" pos="0.0008950179908424616 -0.18545866012573242 -0.18292519450187683" limited="true" name="Lid002_joint" range="0.0 0.06" type="slide" damping="1" frictionloss="1" armature=".01" stiffness="0.05"/>
          <geom mesh="Lid002_vis" type="mesh" solimp="0.998 0.998 0.001" solref="0.001 1" density="100" friction="0.95 0.3 0.1" class="visual" material="Lid002_material"/>
          <geom class="collision" type="box" pos="0.0008485887665301561 -0.18492485582828522 -0.18040791153907776" size="0.15218988060951233 0.05581967905163765 0.001768449554219842" quat="1.0 0.0 0.0 0.0"/>
        </body>
        <geom class="region" name="reg_main" type="box" pos="3.725290298461914e-09 0.0 0.0" size="0.16923843324184418 0.25535309314727783 0.2874471843242645"/>
      </body>
    </body>
  </worldbody>
  <actuator>
    <motor name="Button001_joint_actuator" joint="Button001_joint" gear="0.5"/>
    <motor name="Button002_joint_actuator" joint="Button002_joint" gear="0.5"/>
    <motor name="Container001_Clear_joint_actuator" joint="Container001_Clear_joint" gear="100"/>
    <motor name="Lid001_joint_actuator" joint="Lid001_joint" gear="10"/>
    <motor name="Lid002_joint_actuator" joint="Lid002_joint" gear="10"/>
    <motor name="Lid003_joint_actuator" joint="Lid003_joint" gear="50"/>
  </actuator>
</mujoco>
