<mujoco model="model">
  <compiler angle="radian"/>
  <asset>
    <mesh file="visuals/Body001.obj" name="Body001_vis"/>
    <mesh file="visuals/Button001.obj" name="Button001_vis"/>
    <mesh file="visuals/Door001.obj" name="Door001_vis"/>
    <mesh file="visuals/Door001_Clear.obj" name="Door001_Clear_vis"/>
    <mesh file="visuals/Handle001.obj" name="Handle001_vis"/>
    <mesh file="visuals/Knob001.obj" name="Knob001_vis"/>
    <mesh file="visuals/Knob002.obj" name="Knob002_vis"/>
    <mesh file="visuals/Shelf001.obj" name="Shelf001_vis"/>
    <texture file="visuals/T_BC001.png" name="Body001_material" type="2d"/>
    <material name="Body001_material" rgba="1 1 1 1.0" texture="Body001_material" shininess="2" specular="2"/>
    <texture file="visuals/T_BC001.png" name="Button001_material" type="2d"/>
    <material name="Button001_material" rgba="1 1 1 1.0" texture="Button001_material" shininess="0.141421377658844" specular="0.3103448502657381"/>
    <texture file="visuals/T_BC001.png" name="Door001_material" type="2d"/>
    <material name="Door001_material" rgba="1 1 1 1.0" texture="Door001_material" shininess="1" specular="1"/>
    <material name="Door001_Clear_material" rgba="0.01328548975288868 0.01328548975288868 0.01328548975288868 0.80275958776474" shininess="0.141421377658844" specular="0.3103448502657381"/>
    <texture file="visuals/T_BC001.png" name="Handle001_material" type="2d"/>
    <material name="Handle001_material" rgba="1 1 1 1.0" texture="Handle001_material" shininess="0.141421377658844" specular="0.3103448502657381"/>
    <texture file="visuals/T_BC001.png" name="Knob001_material" type="2d"/>
    <material name="Knob001_material" rgba="1 1 1 1.0" texture="Knob001_material" shininess="0.141421377658844" specular="0.3103448502657381"/>
    <texture file="visuals/T_BC001.png" name="Knob002_material" type="2d"/>
    <material name="Knob002_material" rgba="1 1 1 1.0" texture="Knob002_material" shininess="0.141421377658844" specular="0.3103448502657381"/>
    <texture file="visuals/T_BC001.png" name="Shelf001_material" type="2d"/>
    <material name="Shelf001_material" rgba="1 1 1 1.0" texture="Shelf001_material" shininess="3" specular="3"/>
  </asset>
  <default>
    <default class="visual">
      <geom conaffinity="0" contype="0" group="1" type="mesh"/>
    </default>
    <default class="collision">
      <geom group="0" rgba="0.5 0 0 0.5"/>
    </default>
    <default class="spawn">
      <geom group="0" rgba="1 1 1 0.5" contype="0" conaffinity="0"/>
      <site group="0" rgba="1 1 1 0.5"/>
    </default>
    <default class="region">
      <geom group="1" conaffinity="0" contype="0" rgba="0 1 0 0"/>
    </default>
  </default>
  <worldbody>
    <body>
      <body name="object">
        <geom mesh="Body001_vis" type="mesh" solimp="0.998 0.998 0.001" solref="0.001 1" density="100" friction="0.95 0.3 0.1" class="visual" material="Body001_material"/>
        <geom class="collision" type="box" pos="-0.19938713312149048 0.02369273640215397 0.030586978420615196" size="0.011045469902455807 0.13945896923542023 0.09352082759141922" quat="1.0 0.0 0.0 0.0"/>
        <geom class="collision" type="box" pos="6.728991866111755e-05 0.02369273640215397 -0.08999532461166382" size="0.23448415100574493 0.13945895433425903 0.034242551773786545" quat="1.0 0.0 0.0 0.0"/>
        <geom class="collision" type="box" pos="-0.0327727273106575 0.16241779923439026 0.03255204111337662" size="0.17766007781028748 0.002849905053153634 0.09155573695898056" quat="1.0 0.0 0.0 0.0"/>
        <geom class="collision" type="box" pos="0.14060518145561218 0.02369273640215397 0.030586978420615196" size="0.011045466177165508 0.13945890963077545 0.09352079778909683" quat="1.0 0.0 0.0 0.0"/>
        <geom class="collision" type="box" pos="-0.0327727273106575 0.02369273640215397 0.11286628991365433" size="0.1776600331068039 0.13945889472961426 0.011241402477025986" quat="1.0 0.0 0.0 0.0"/>
        <geom class="collision" type="box" pos="-0.029766708612442017 0.17539861798286438 0.01943136751651764" size="0.11408711969852448 0.010328519158065319 0.060446981340646744" quat="1.0 0.0 0.0 0.0"/>
        <geom class="collision" type="box" pos="0.17819008231163025 0.019317056983709335 -3.230944275856018e-05" size="0.032723404467105865 0.14383453130722046 0.12414012849330902" quat="1.0 0.0 0.0 0.0"/>
        <geom class="collision" type="box" pos="-0.0327727273106575 -0.12230610847473145 -0.08770491182804108" size="0.17765997350215912 0.00883223582059145 0.014290397986769676" quat="1.0 0.0 0.0 0.0"/>
        <geom class="collision" type="cylinder" pos="-0.029392004013061523 -0.06635764241218567 -0.03115256316959858" size="0.004076976794749498 0.14250428974628448" quat="0.7071068286895752 -0.0 0.7071067690849304 0.0"/>
        <geom class="collision" type="cylinder" pos="-0.18013900518417358 -0.06635764241218567 -0.03115258179605007" size="0.00822426751255989 0.009378585033118725" quat="0.7071068286895752 -0.0 0.7071067690849304 0.0"/>
        <geom class="collision" type="cylinder" pos="0.12085077166557312 -0.06635764241218567 -0.03115258179605007" size="0.00822426751255989 0.009378585033118725" quat="0.7071068286895752 -0.0 0.7071067690849304 0.0"/>
        <geom class="collision" type="cylinder" pos="-0.029392004013061523 0.11517299711704254 -0.03115256316959858" size="0.004076976794749498 0.14250428974628448" quat="0.7071068286895752 -0.0 0.7071067690849304 0.0"/>
        <geom class="collision" type="cylinder" pos="0.12085077166557312 0.11517299711704254 -0.03115258179605007" size="0.00822426751255989 0.009378585033118725" quat="0.7071068286895752 -0.0 0.7071067690849304 0.0"/>
        <geom class="collision" type="cylinder" pos="-0.18013900518417358 0.11517299711704254 -0.03115258179605007" size="0.00822426751255989 0.009378585033118725" quat="0.7071068286895752 -0.0 0.7071067690849304 0.0"/>
        <body name="Button001">
          <joint axis="0.0 1.0 0.0" pos="0.17770147323608398 -0.12866096198558807 0.07837564498186111" limited="true" name="Button001_joint" range="0.0 0.002" type="slide" damping="1" frictionloss="1" armature=".01" stiffness="0.05"/>
          <geom mesh="Button001_vis" type="mesh" solimp="0.998 0.998 0.001" solref="0.001 1" density="100" friction="0.95 0.3 0.1" class="visual" material="Button001_material"/>
          <geom class="collision" type="box" pos="0.17767612636089325 -0.12866094708442688 0.07818392664194107" size="0.0169745534658432 0.0015185559168457985 0.00391674879938364" quat="1.0 0.0 0.0 0.0"/>
        </body>
        <body name="Door001">
          <joint axis="1.0 0.0 0.0" pos="-0.03425564616918564 -0.1284104436635971 -0.06965545564889908" limited="true" name="Door001_joint" range="0.0 1.5707963267948966" type="hinge" damping="1" frictionloss="1" armature=".01" stiffness="0.05"/>
          <geom mesh="Door001_vis" type="mesh" solimp="0.998 0.998 0.001" solref="0.001 1" density="100" friction="0.95 0.3 0.1" class="visual" material="Door001_material"/>
          <geom class="collision" type="box" pos="-0.03403389826416969 -0.12261100858449936 0.02702808752655983" size="0.17340099811553955 0.0063090454787015915 0.09479888528585434" quat="1.0 0.0 0.0 0.0"/>
          <body name="Door001_Clear">
            <geom mesh="Door001_Clear_vis" type="mesh" solimp="0.998 0.998 0.001" solref="0.001 1" density="100" friction="0.95 0.3 0.1" class="visual" material="Door001_Clear_material"/>
            <geom class="collision" type="box" pos="-0.034382034093141556 -0.12344960868358612 0.027474859729409218" size="0.15032900869846344 0.0017526516458019614 0.07011965662240982" quat="1.0 0.0 0.0 0.0"/>
          </body>
          <body name="Handle001">
            <geom mesh="Handle001_vis" type="mesh" solimp="0.998 0.998 0.001" solref="0.001 1" density="100" friction="0.95 0.3 0.1" class="visual" material="Handle001_material"/>
            <geom class="collision" type="box" pos="-0.16138596832752228 -0.15656164288520813 0.10979864746332169" size="0.010255392640829086 0.028609011322259903 0.012028306722640991" quat="1.0 0.0 0.0 0.0"/>
            <geom class="collision" type="box" pos="0.09250868856906891 -0.15656164288520813 0.10979864746332169" size="0.010255392640829086 0.028609009459614754 0.012028305791318417" quat="1.0 0.0 0.0 0.0"/>
            <geom class="collision" type="cylinder" pos="-0.03351541608572006 -0.17494116723537445 0.11027831584215164" size="0.008183791302144527 0.11854784935712814" quat="0.7071068286895752 0.0 -0.7071067690849304 0.0"/>
          </body>
        </body>
        <body name="Knob001">
          <joint axis="0.0 1.0 0.0" pos="0.1777443289756775 -0.13426315784454346 0.03638564050197601" limited="true" name="Knob001_joint" range="0.0 5.235987755982989" type="hinge" damping="1" frictionloss="1" armature=".01" stiffness="0.05"/>
          <geom mesh="Knob001_vis" type="mesh" solimp="0.998 0.998 0.001" solref="0.001 1" density="100" friction="0.95 0.3 0.1" class="visual" material="Knob001_material"/>
          <geom class="collision" type="cylinder" pos="0.1777443289756775 -0.13475176692008972 0.03704773634672165" size="0.016061143949627876 0.005259526893496513" quat="0.7071068286895752 0.7071067690849304 0.0 0.0"/>
        </body>
        <body name="Knob002">
          <joint axis="0.0 1.0 0.0" pos="0.1777443289756775 -0.13428866863250732 -0.01666785590350628" limited="true" name="Knob002_joint" range="0.0 4.66002910282486" type="hinge" damping="1" frictionloss="1" armature=".01" stiffness="0.05"/>
          <geom mesh="Knob002_vis" type="mesh" solimp="0.998 0.998 0.001" solref="0.001 1" density="100" friction="0.95 0.3 0.1" class="visual" material="Knob002_material"/>
          <geom class="collision" type="cylinder" pos="0.1777443289756775 -0.13475176692008972 -0.01644095964729786" size="0.016061143949627876 0.005259526893496513" quat="0.7071068286895752 0.7071067690849304 0.0 0.0"/>
        </body>
        <body name="Shelf001">
          <joint axis="0.0 -1.0 0.0" pos="-0.02956014685332775 0.027116652578115463 0.011530434712767601" limited="true" name="Shelf001_joint" range="0.0 0.15" type="slide" damping="1" frictionloss="1" armature=".01" stiffness="0.05"/>
          <geom mesh="Shelf001_vis" type="mesh" solimp="0.998 0.998 0.001" solref="0.001 1" density="100" friction="0.95 0.3 0.1" class="visual" material="Shelf001_material"/>
          <geom class="collision" type="box" pos="-0.030479762703180313 0.027071617543697357 0.004106040112674236" size="0.13582004606723785 0.1287454217672348 0.003292788052931428" quat="1.0 0.0 0.0 0.0"/>
          <geom class="collision" type="box" pos="0.12056825309991837 0.027066828683018684 0.020100772380828857" size="0.007618641015142202 0.12887655198574066 0.002635304583236575" quat="1.0 0.0 0.0 0.0"/>
          <geom class="collision" type="box" pos="0.11070646345615387 0.027066828683018684 0.011470561847090721" size="0.01061615813523531 0.12887655198574066 0.0026352968998253345" quat="0.8631649017333984 -7.03137033042367e-08 -0.504922091960907 -4.1131080763534555e-08"/>
          <geom class="collision" type="box" pos="-0.16972272098064423 0.027066826820373535 0.011470560915768147" size="0.01061615813523531 0.12887655198574066 0.0026352968998253345" quat="2.709616353513411e-07 0.8631649017333984 1.5850328338729014e-07 -0.504922091960907"/>
          <geom class="collision" type="box" pos="-0.17958450317382812 0.027066826820373535 0.020100772380828857" size="0.007618641015142202 0.12887655198574066 0.002635364653542638" quat="1.0 0.0 0.0 0.0"/>
        </body>
        <geom class="region" name="reg_main_body" type="box" pos="-3.725290298461914e-09 0.02744142711162567 7.450580596923828e-09" size="0.23408736288547516 0.1575000137090683 0.12405222654342651"/>
        <geom class="region" name="reg_int" type="box" pos="-0.029320351779460907 0.022937458008527756 0.022960403934121132" size="0.15423067659139633 0.13214289024472237 0.07424370758235455"/>
      </body>
    </body>
  </worldbody>
  <actuator>
    <motor name="Button001_joint_actuator" joint="Button001_joint" gear="0.3"/>
    <motor name="Door001_joint_actuator" joint="Door001_joint" gear="10"/>
    <motor name="Knob001_joint_actuator" joint="Knob001_joint" gear="10"/>
    <motor name="Knob002_joint_actuator" joint="Knob002_joint" gear="10"/>
    <motor name="Shelf001_joint_actuator" joint="Shelf001_joint" gear="10"/>
  </actuator>
</mujoco>
