<?xml version='1.0' encoding='UTF-8'?>
<mujoco model="model">
  <option timestep="0.002" gravity="0.0 0.0 -9.81"/>
  <compiler angle="radian"/>
  <asset>
    <mesh file="visuals/Body001.obj" name="Body001_vis"/>
    <mesh file="visuals/Door001.obj" name="Door001_vis"/>
    <mesh file="visuals/Door001_Clear.obj" name="Door001_Clear_vis"/>
    <mesh file="visuals/Handle001.obj" name="Handle001_vis"/>
    <mesh file="visuals/Knob001.obj" name="Knob001_vis"/>
    <mesh file="visuals/Knob002.obj" name="Knob002_vis"/>
    <mesh file="visuals/Shelf001.obj" name="Shelf001_vis"/>
    <texture file="visuals/T_BC001.png" name="Body001_material" type="2d"/>
    <material name="Body001_material" rgba="1 1 1 1.0" texture="Body001_material" shininess="1" specular="1"/>
    <texture file="visuals/T_BC001.png" name="Door001_material" type="2d"/>
    <material name="Door001_material" rgba="1 1 1 1.0" texture="Door001_material" shininess="0.141421377658844" specular="0.3103448502657381"/>
    <material name="Door001_Clear_material" rgba="0.032748669385910034 0.032748669385910034 0.032748669385910034 0.75" shininess="0.141421377658844" specular="0.3103448502657381"/>
    <texture file="visuals/T_BC001.png" name="Handle001_material" type="2d"/>
    <material name="Handle001_material" rgba="1 1 1 1.0" texture="Handle001_material" shininess="0.141421377658844" specular="0.3103448502657381"/>
    <texture file="visuals/T_BC001.png" name="Knob001_material" type="2d"/>
    <material name="Knob001_material" rgba="1 1 1 1.0" texture="Knob001_material" shininess="1" specular="1"/>
    <texture file="visuals/T_BC001.png" name="Knob002_material" type="2d"/>
    <material name="Knob002_material" rgba="1 1 1 1.0" texture="Knob002_material" shininess="1" specular="1"/>
    <texture file="visuals/T_BC001.png" name="Shelf001_material" type="2d"/>
    <material name="Shelf001_material" rgba="1 1 1 1.0" texture="Shelf001_material" shininess="10" specular="10"/>
  </asset>
  <default>
    <default class="visual">
      <geom conaffinity="0" contype="0" group="1" type="mesh"/>
    </default>
    <default class="collision">
      <geom group="0" rgba="0.5 0 0 0.5"/>
    </default>
    <default class="spawn">
      <geom group="0" rgba="1 1 1 0.5" contype="0" conaffinity="0"/>
      <site group="0" rgba="1 1 1 0.5"/>
    </default>
    <default class="region">
      <geom group="1" conaffinity="0" contype="0" rgba="0 1 0 0"/>
    </default>
  </default>
  <worldbody>
    <body>
      <body name="object">
        <geom mesh="Body001_vis" type="mesh" solimp="0.998 0.998 0.001" solref="0.001 1" friction="0.95 0.3 0.1" class="visual" material="Body001_material"/>
        <geom class="collision" type="box" pos="-0.19915375113487244 0.023692751303315163 0.019506996497511864" size="0.011346306651830673 0.13945896923542023 0.0934930220246315" quat="1.0 0.0 0.0 0.0" density="1000.0"/>
        <geom class="collision" type="box" pos="-0.023264974355697632 0.023692751303315163 -0.07780774682760239" size="0.16671471297740936 0.13945895433425903 0.011364622972905636" quat="1.0 0.0 0.0 0.0" density="1000.0"/>
        <geom class="collision" type="box" pos="-0.03292854130268097 0.16241781413555145 0.021472088992595673" size="0.17757153511047363 0.002849905053153634 0.09152796864509583" quat="1.0 0.0 0.0 0.0" density="1000.0"/>
        <geom class="collision" type="box" pos="0.1396062970161438 0.023692751303315163 0.019507044926285744" size="0.011799996718764305 0.13945890963077545 0.09349304437637329" quat="1.0 0.0 0.0 0.0" density="1000.0"/>
        <geom class="collision" type="box" pos="-0.03292854130268097 0.023692751303315163 0.10178637504577637" size="0.17757150530815125 0.13945889472961426 0.011213671416044235" quat="1.0 0.0 0.0 0.0" density="1000.0"/>
        <geom class="collision" type="box" pos="-0.030011050403118134 0.17500576376914978 0.008379187434911728" size="0.11408711969852448 0.009935657493770123 0.060446981340646744" quat="1.0 0.0 0.0 0.0" density="1000.0"/>
        <geom class="collision" type="box" pos="0.17786118388175964 0.01931707188487053 3.119930624961853e-08" size="0.032638855278491974 0.14383453130722046 0.11300002783536911" quat="1.0 0.0 0.0 0.0" density="1000.0"/>
        <geom class="collision" type="box" pos="-0.032928597182035446 -0.12176620215177536 -0.09873336553573608" size="0.17757150530815125 0.008292344398796558 0.014266670681536198" quat="1.0 0.0 0.0 0.0" density="1000.0"/>
        <geom class="collision" type="box" pos="-0.1976035237312317 0.025271344929933548 -0.09316490590572357" size="0.138315811753273 0.012896534986793995 0.019835161045193672" quat="0.7071068286895752 0.0 0.0 0.7071067094802856" density="1000.0"/>
        <geom class="collision" type="box" pos="0.1369469165802002 0.025271344929933548 -0.09357748925685883" size="0.138315811753273 0.009070738218724728 0.01942254789173603" quat="0.7071068286895752 0.0 0.0 0.7071067094802856" density="1000.0"/>
        <geom class="collision" type="box" pos="-0.186309814453125 0.023692749440670013 0.02976948767900467" size="0.004095414653420448 0.11066911369562149 0.013503814116120338" quat="1.0 0.0 0.0 0.0" density="1000.0"/>
        <geom class="collision" type="box" pos="-0.186309814453125 0.023692749440670013 -0.010365255177021027" size="0.004095414653420448 0.11066911369562149 0.013503814116120338" quat="1.0 0.0 0.0 0.0" density="1000.0"/>
        <geom class="collision" type="box" pos="0.12682807445526123 0.023692749440670013 0.02976948767900467" size="0.004095414653420448 0.11066911369562149 0.013503814116120338" quat="1.0 0.0 0.0 0.0" density="1000.0"/>
        <geom class="collision" type="box" pos="0.12682807445526123 0.023692749440670013 -0.010365255177021027" size="0.004095414653420448 0.11066911369562149 0.013503814116120338" quat="1.0 0.0 0.0 0.0" density="1000.0"/>
        <body name="Door001">
          <joint axis="1.0 0.0 0.0" pos="-0.034499987959861755 -0.1284104287624359 -0.08070763945579529" limited="true" name="Door001_joint" range="0.0 1.5707963267948966" type="hinge" damping="1" frictionloss="1" armature=".01" stiffness="0.05"/>
          <geom mesh="Door001_vis" type="mesh" solimp="0.998 0.998 0.001" solref="0.001 1" friction="0.95 0.3 0.1" class="visual" material="Door001_material"/>
          <geom class="collision" type="box" pos="-0.03427824005484581 -0.12261099368333817 0.01597590744495392" size="0.17340099811553955 0.0063090454787015915 0.09479888528585434" quat="1.0 0.0 0.0 0.0" density="1000.0"/>
          <body name="Door001_Clear">
            <geom mesh="Door001_Clear_vis" type="mesh" solimp="0.998 0.998 0.001" solref="0.001 1" friction="0.95 0.3 0.1" class="visual" material="Door001_Clear_material"/>
            <geom class="collision" type="box" pos="-0.03462637588381767 -0.12344959378242493 0.016422679647803307" size="0.15032900869846344 0.0017526516458019614 0.07011965662240982" quat="1.0 0.0 0.0 0.0" density="1000.0"/>
          </body>
          <body name="Handle001">
            <geom mesh="Handle001_vis" type="mesh" solimp="0.998 0.998 0.001" solref="0.001 1" friction="0.95 0.3 0.1" class="visual" material="Handle001_material"/>
            <geom class="collision" type="box" pos="-0.1616303026676178 -0.15656162798404694 0.09874646365642548" size="0.010255392640829086 0.028609011322259903 0.012028306722640991" quat="1.0 0.0 0.0 0.0" density="1000.0"/>
            <geom class="collision" type="box" pos="0.09226434677839279 -0.15656162798404694 0.09874646365642548" size="0.010255392640829086 0.028609009459614754 0.012028305791318417" quat="1.0 0.0 0.0 0.0" density="1000.0"/>
            <geom class="collision" type="cylinder" pos="-0.03375975787639618 -0.17494115233421326 0.09922613203525543" size="0.008183791302144527 0.11854784935712814" quat="0.7071068286895752 0.0 -0.7071067690849304 0.0" density="1000.0"/>
          </body>
        </body>
        <body name="Knob001">
          <joint axis="0.0 1.0 0.0" pos="0.17749997973442078 -0.13410982489585876 0.04776974022388458" limited="true" name="Knob001_joint" range="0.0 5.323254218582705" type="hinge" damping="0.05" armature="0.001"/>
          <geom mesh="Knob001_vis" type="mesh" solimp="0.998 0.998 0.001" solref="0.001 1" friction="0.95 0.3 0.1" class="visual" material="Knob001_material"/>
          <geom class="collision" type="cylinder" pos="0.17749997973442078 -0.13022786378860474 0.04776974022388458" size="0.014455029740929604 0.003352796658873558" quat="0.7071068286895752 0.7071067690849304 0.0 0.0" density="1000.0"/>
          <geom class="collision" type="box" pos="0.17749997973442078 -0.1376115083694458 0.04776974022388458" size="0.010511142201721668 0.004862803965806961 0.002875745762139559" quat="1.0 0.0 0.0 0.0" density="1000.0"/>
        </body>
        <body name="Knob002">
          <joint axis="0.0 1.0 0.0" pos="0.17749997973442078 -0.13413533568382263 -0.03509907424449921" limited="true" name="Knob002_joint" range="0.0 4.537856055185257" type="hinge" damping="0.05" armature="0.001"/>
          <geom mesh="Knob002_vis" type="mesh" solimp="0.998 0.998 0.001" solref="0.001 1" friction="0.95 0.3 0.1" class="visual" material="Knob002_material"/>
          <geom class="collision" type="cylinder" pos="0.17749997973442078 -0.13024592399597168 -0.03509907424449921" size="0.014455029740929604 0.003352796658873558" quat="0.7071068286895752 0.7071067690849304 0.0 0.0" density="1000.0"/>
          <geom class="collision" type="box" pos="0.17749997973442078 -0.13762956857681274 -0.03509907424449921" size="0.010511142201721668 0.004862803965806961 0.002875745762139559" quat="0.7071068286895752 -4.750302551315144e-08 0.7071067094802856 4.7503014855010406e-08" density="1000.0"/>
        </body>
        <body name="Shelf001">
          <joint axis="0.0 -1.0 0.0" pos="-0.029804488644003868 0.027116667479276657 0.00047825463116168976" limited="true" name="Shelf001_joint" range="0.0 0.2" type="slide" damping="1" frictionloss="1" armature=".01" stiffness="0.05"/>
          <geom mesh="Shelf001_vis" type="mesh" solimp="0.998 0.998 0.001" solref="0.001 1" friction="0.95 0.3 0.1" class="visual" material="Shelf001_material"/>
          <geom class="collision" type="box" pos="-0.03072410449385643 0.02707163244485855 -0.006946139968931675" size="0.13582004606723785 0.1287454217672348 0.003292788052931428" quat="1.0 0.0 0.0 0.0" density="1000.0"/>
          <geom class="collision" type="box" pos="0.11883842945098877 0.027066843584179878 0.009048592299222946" size="0.007618641015142202 0.12887655198574066 0.002635304583236575" quat="1.0 0.0 0.0 0.0" density="1000.0"/>
          <geom class="collision" type="box" pos="0.11046212166547775 0.027066843584179878 0.0004183817654848099" size="0.01061615813523531 0.12887655198574066 0.0026352968998253345" quat="0.8631649017333984 -7.031371040966405e-08 -0.5049221515655518 -4.113108786896191e-08" density="1000.0"/>
          <geom class="collision" type="box" pos="-0.16996705532073975 0.02706684172153473 0.00041838083416223526" size="0.01061615813523531 0.12887655198574066 0.0026352968998253345" quat="2.709616353513411e-07 0.8631649017333984 1.5850329759814485e-07 -0.5049221515655518" density="1000.0"/>
          <geom class="collision" type="box" pos="-0.17815768718719482 0.02706684172153473 0.009048592299222946" size="0.007618641015142202 0.12887655198574066 0.002635364653542638" quat="1.0 0.0 0.0 0.0" density="1000.0"/>
        </body>
        <geom class="region" name="reg_int" type="box" pos="-0.030440330505371094 0.02490226924419403 0.01190822571516037" size="0.1577332615852356 0.1350083351135254 0.07862193137407303"/>
        <geom class="region" name="reg_main" type="box" pos="0.0 0.02744145691394806 0.0" size="0.2105000615119934 0.1574999988079071 0.1130000501871109"/>
      </body>
    </body>
  </worldbody>
  <actuator>
    <motor name="Door001_joint_actuator" joint="Door001_joint" gear="30"/>
    <motor name="Knob001_joint_actuator" joint="Knob001_joint" gear="10"/>
    <motor name="Knob002_joint_actuator" joint="Knob002_joint" gear="10"/>
    <motor name="Shelf001_joint_actuator" joint="Shelf001_joint" gear="10"/>
  </actuator>
</mujoco>
