<?xml version='1.0' encoding='UTF-8'?>
<mujoco model="model">
  <compiler angle="radian"/>
  <asset>
    <mesh file="visuals/Body001.obj" name="Body001_vis"/>
    <mesh file="visuals/Body002.obj" name="Body002_vis"/>
    <mesh file="visuals/Button001.obj" name="Button001_vis"/>
    <mesh file="visuals/Knob001.obj" name="Knob001_vis"/>
    <mesh file="visuals/Lever001.obj" name="Lever001_vis"/>
    <texture file="visuals/T_BC001.png" name="Body001_material" type="2d"/>
    <material name="Body001_material" rgba="1 1 1 1.0" texture="Body001_material" shininess="0.4472135901451111" specular="0.3103448502657381"/>
    <texture file="visuals/T_BC001.png" name="Body002_material" type="2d"/>
    <material name="Body002_material" rgba="1 1 1 1.0" texture="Body002_material" shininess="0.4472135901451111" specular="2"/>
    <texture file="visuals/T_BC001.png" name="Button001_material" type="2d"/>
    <material name="Button001_material" rgba="1 1 1 1.0" texture="Button001_material" shininess="0.4472135901451111" specular="0.3103448502657381"/>
    <texture file="visuals/T_BC001.png" name="Knob001_material" type="2d"/>
    <material name="Knob001_material" rgba="1 1 1 1.0" texture="Knob001_material" shininess="0.4472135901451111" specular="0.3103448502657381"/>
    <texture file="visuals/T_BC001.png" name="Lever001_material" type="2d"/>
    <material name="Lever001_material" rgba="1 1 1 1.0" texture="Lever001_material" shininess="0.4472135901451111" specular="0.3103448502657381"/>
  </asset>
  <default>
    <default class="visual">
      <geom conaffinity="0" contype="0" group="1" type="mesh"/>
    </default>
    <default class="collision">
      <geom group="0" rgba="0.5 0 0 0.5"/>
    </default>
    <default class="spawn">
      <geom group="0" rgba="1 1 1 0.5" contype="0" conaffinity="0"/>
      <site group="0" rgba="1 1 1 0.5"/>
    </default>
    <default class="region">
      <geom group="1" conaffinity="0" contype="0" rgba="0 1 0 0"/>
    </default>
  </default>
  <worldbody>
    <body>
      <body name="object">
        <geom mesh="Body001_vis" type="mesh" solimp="0.998 0.998 0.001" solref="0.001 1" density="100" friction="0.95 0.3 0.1" class="visual" material="Body001_material"/>
        <geom class="collision" type="box" pos="-0.101480 0.021550 -0.001574" size="0.03418779745697975 0.13385793566703796 0.13836859166622162" quat="1.0 0.0 0.0 0.0"/>
        <geom class="collision" type="box" pos="0.101748 0.021550 -0.002332" size="0.03435457870364189 0.13385801017284393 0.13761071860790253" quat="1.0 0.0 0.0 0.0"/>
        <geom class="collision" type="box" pos="0.001698 0.149989 -0.002090" size="0.12160955369472504 0.03326985612511635 0.13785582780838013" quat="1.0 0.0 0.0 0.0"/>
        <geom class="collision" type="box" pos="0.001698 -0.076439 -0.005231" size="0.12160954624414444 0.037079066038131714 0.1347140371799469" quat="1.0 0.0 0.0 0.0"/>
        <geom class="collision" type="box" pos="0.000530 0.021550 0.049543" size="0.039765287190675735 0.13385890424251556 0.08181670308113098" quat="1.0 0.0 0.0 0.0"/>
        <geom class="collision" type="box" pos="-0.000389 0.021550 -0.087799" size="0.07910510897636414 0.1401977688074112 0.05210856720805168" quat="1.0 0.0 0.0 0.0"/>
        <geom class="collision" type="box" pos="-0.082185 -0.133412 -0.015819" size="0.05375341325998306 0.024923771619796753 0.12403124570846558" quat="1.0 0.0 0.0 0.0"/>
        <geom class="collision" type="box" pos="0.001698 -0.164325 -0.094838" size="0.1378471851348877 0.019114144146442413 0.04403212293982506" quat="1.0 0.0 0.0 0.0"/>
        <geom class="collision" type="box" pos="0.081494 -0.133412 -0.015819" size="0.053583789616823196 0.024923808872699738 0.1240314468741417" quat="1.0 0.0 0.0 0.0"/>
        <body name="Body002">
          <geom mesh="Body002_vis" type="mesh" solimp="0.998 0.998 0.001" solref="0.001 1" density="100" friction="0.95 0.3 0.1" class="visual" material="Body002_material"/>
        </body>
        <body name="Button001">
          <joint axis="0.09770318120718002 0.986335277557373 -0.13265320658683777" pos="-0.046442 -0.119553 -0.000037" limited="true" name="Button001_joint" range="0.0 0.001" type="slide" damping="1" frictionloss="1" armature=".01" stiffness="0.2" springref="-0.1"/>
          <geom mesh="Button001_vis" type="mesh" solimp="0.998 0.998 0.001" solref="0.001 1" density="100" friction="0.95 0.3 0.1" class="visual" material="Button001_material"/>
          <geom class="collision" type="box" pos="-0.066238 -0.171683 -0.000055" size="0.011931066401302814 0.002311410615220666 0.0043693301267921925" quat="0.9978824853897095 -0.0529823899269104 -0.0020003479439765215 -0.03767504170536995"/>
        </body>
        <body name="Knob001">
          <joint axis="0.0 0.9935271143913269 -0.11359558254480362" pos="0.065887 -0.178635 -0.006563" limited="true" name="Knob001_joint" range="0.0 5.235987755982989" type="hinge" damping="0.05" armature="0.001"/>
          <geom mesh="Knob001_vis" type="mesh" solimp="0.998 0.998 0.001" solref="0.001 1" density="100" friction="0.95 0.3 0.1" class="visual" material="Knob001_material"/>
          <geom class="collision" type="cylinder" pos="0.065479 -0.175957 -0.006841" size="0.01848733052611351 0.002492166357114911" quat="0.745511531829834 0.666492760181427 0.0 0.0"/>
          <geom class="collision" type="box" pos="0.065249 -0.183388 -0.005304" size="0.005110322032123804 0.006326127797365189 0.016014806926250458" quat="0.997992992401123 -0.06332430243492126 -0.0 0.0"/>
        </body>
        <body name="Lever001">
          <joint axis="0.0 0.0 -1.0" pos="0.000000 -0.142114 0.096123" limited="true" name="Lever001_joint" range="0.0 0.091" type="slide" damping="1" frictionloss="1" armature=".01" stiffness="1" springref="-0.6"/>
          <geom mesh="Lever001_vis" type="mesh" solimp="0.998 0.998 0.001" solref="0.001 1" density="100" friction="0.95 0.3 0.1" class="visual" material="Lever001_material"/>
          <geom class="collision" type="box" pos="0.000000 -0.146778 0.092597" size="0.016314776614308357 0.012130996212363243 0.003923389595001936" quat="1.0 0.0 0.0 0.0" name="lever_knob"/>
          <geom class="collision" type="box" pos="0.000000 -0.137767 0.099513" size="0.016314787790179253 0.003120197681710124 0.003923393785953522" quat="1.0 0.0 0.0 0.0"/>
          <geom class="collision" type="box" pos="0.053820 0.038277 0.125320" size="0.012550000101327896 0.07443460077047348 0.001251728623174131" quat="1.0 0.0 0.0 0.0" name="slotR_floor"/>
          <geom class="collision" type="box" pos="-0.053239 0.038277 0.125320" size="0.012550000101327896 0.07443460077047348 0.001251729903742671" quat="1.0 0.0 0.0 0.0" name="slotL_floor"/>
        </body>
        <geom class="region" name="reg_main" type="box" pos="0.0 0.0013854999999999978 0.0" size="0.13534 0.18987949999999998 0.138792"/>
      </body>
    </body>
  </worldbody>
  <actuator>
    <motor name="Button001_joint_actuator" joint="Button001_joint" gear="0.5"/>
    <motor name="Knob001_joint_actuator" joint="Knob001_joint" gear="10"/>
    <motor name="Lever001_joint_actuator" joint="Lever001_joint" gear="5"/>
  </actuator>
</mujoco>
