<?xml version='1.0' encoding='UTF-8'?>
<mujoco model="model">
  <compiler angle="radian"/>
  <asset>
    <mesh file="visuals/knob_front_left.obj" name="knob_front_left_vis"/>
    <mesh file="visuals/knob_front_right.obj" name="knob_front_right_vis"/>
    <mesh file="visuals/knob_rear_left.obj" name="knob_rear_left_vis"/>
    <mesh file="visuals/knob_rear_right.obj" name="knob_rear_right_vis"/>
    <mesh file="visuals/Body001.obj" name="Body001_vis"/>
    <mesh file="visuals/Door001.obj" name="Door001_vis"/>
    <mesh file="visuals/Door001_Clear.obj" name="Door001_Clear_vis"/>
    <mesh file="visuals/Knob001.obj" name="Knob001_vis"/>
    <mesh file="visuals/Knob002.obj" name="Knob002_vis"/>
    <mesh file="visuals/Shelf001.obj" name="Shelf001_vis"/>
    <texture file="visuals/T_BC001.png" name="Body001_material" type="2d"/>
    <material name="Body001_material" rgba="1 1 1 1.0" texture="Body001_material" shininess="0.44721364974975586" specular="0.7"/>
    <texture file="visuals/T_BC001.png" name="knob_front_left_material" type="2d"/>
    <material name="knob_front_left_material" rgba="1 1 1 1.0" texture="knob_front_left_material" shininess="0.44721364974975586" specular="0.3103448502657381"/>
    <texture file="visuals/T_BC001.png" name="knob_front_right_material" type="2d"/>
    <material name="knob_front_right_material" rgba="1 1 1 1.0" texture="knob_front_right_material" shininess="0.44721364974975586" specular="0.3103448502657381"/>
    <texture file="visuals/T_BC001.png" name="knob_rear_left_material" type="2d"/>
    <material name="knob_rear_left_material" rgba="1 1 1 1.0" texture="knob_rear_left_material" shininess="0.44721364974975586" specular="0.3103448502657381"/>
    <texture file="visuals/T_BC001.png" name="knob_rear_right_material" type="2d"/>
    <material name="knob_rear_right_material" rgba="1 1 1 1.0" texture="knob_rear_right_material" shininess="0.44721364974975586" specular="0.3103448502657381"/>
    <texture file="visuals/T_BC001.png" name="Door001_material" type="2d"/>
    <material name="Door001_material" rgba="1 1 1 1.0" texture="Door001_material" shininess="0.44721364974975586" specular="0.3103448502657381"/>
    <material name="Door001_Clear_material" rgba="0.06827369332313538 0.06827369332313538 0.06827369332313538 0.699999988079071" shininess="0.44721364974975586" specular="0.3103448502657381"/>
    <texture file="visuals/T_BC001.png" name="Knob001_material" type="2d"/>
    <material name="Knob001_material" rgba="1 1 1 1.0" texture="Knob001_material" shininess="0.44721364974975586" specular="0.3103448502657381"/>
    <texture file="visuals/T_BC001.png" name="Knob002_material" type="2d"/>
    <material name="Knob002_material" rgba="1 1 1 1.0" texture="Knob002_material" shininess="0.44721364974975586" specular="0.3103448502657381"/>
    <texture file="visuals/T_BC001.png" name="Shelf001_material" type="2d"/>
    <material name="Shelf001_material" rgba="1 1 1 1.0" texture="Shelf001_material" shininess="0.44721364974975586" specular="0.3103448502657381"/>
  </asset>
  <default>
    <default class="visual">
      <geom conaffinity="0" contype="0" group="1" type="mesh"/>
    </default>
    <default class="collision">
      <geom group="0" rgba="0.5 0 0 0.5"/>
    </default>
    <default class="spawn">
      <geom group="0" rgba="1 1 1 0.5" contype="0" conaffinity="0"/>
      <site group="0" rgba="1 1 1 0.5"/>
    </default>
    <default class="region">
      <geom group="1" conaffinity="0" contype="0" rgba="0 1 0 0"/>
    </default>
  </default>
  <worldbody>
    <body>
      <body name="object">
        <site type="cylinder" rgba="0.5 0 0 0.5" size="0.11301018297672272 0.0001" pos="-0.163959 0.158725 0.500847" name="burner_on_rear_left"/>
        <site type="cylinder" rgba="0.5 0 0 0.5" size="0.11806419491767883 0.0001" pos="0.166136 -0.101286 0.498320" name="burner_on_front_right"/>
        <site type="cylinder" rgba="0.5 0 0 0.5" size="0.08921706676483154 0.0001" pos="0.179507 0.173874 0.499532" name="burner_on_rear_right"/>
        <site type="cylinder" rgba="0.5 0 0 0.5" size="0.08654578775167465 0.0001" pos="-0.178005 -0.102378 0.499407" name="burner_on_front_left"/>
        <geom mesh="Body001_vis" type="mesh" solimp="0.998 0.998 0.001" solref="0.001 1" density="100" friction="0.95 0.3 0.1" class="visual" material="Body001_material"/>
        <geom class="collision" type="box" pos="0.000212 0.011594 0.384819" size="0.3899860382080078 0.3450489640235901 0.0726412832736969" quat="1.0 0.0 0.0 0.0"/>
        <geom class="collision" type="box" pos="-0.000304 0.024289 0.480035" size="0.39050203561782837 0.35778361558914185 0.021875659003853798" quat="1.0 0.0 0.0 0.0"/>
        <geom class="collision" type="box" pos="0.000148 0.319748 -0.094428" size="0.39005038142204285 0.03689435496926308 0.4065956175327301" quat="1.0 0.0 0.0 0.0"/>
        <geom class="collision" type="box" pos="-0.363437 0.014530 -0.094428" size="0.02749677188694477 0.26943087577819824 0.4065956175327301" quat="1.0 0.0 0.0 0.0"/>
        <geom class="collision" type="box" pos="0.361682 0.014530 -0.094428" size="0.027995208278298378 0.26943087577819824 0.4065956175327301" quat="1.0 0.0 0.0 0.0"/>
        <geom class="collision" type="box" pos="-0.002094 0.010582 -0.361508" size="0.3304120600223541 0.2728126645088196 0.1128060519695282" quat="1.0 0.0 0.0 0.0"/>
        <geom class="collision" type="box" pos="-0.000039 -0.299405 -0.386560" size="0.3912808299064636 0.03293570131063461 0.11657709628343582" quat="1.0 0.0 0.0 0.0"/>
        <geom class="collision" type="box" pos="0.321052 0.015630 -0.009627" size="0.013427120633423328 0.2681756615638733 0.004859191831201315" quat="1.0 0.0 0.0 0.0"/>
        <geom class="collision" type="box" pos="-0.326650 0.015630 -0.009627" size="0.01115818228572607 0.2681756615638733 0.004859191831201315" quat="1.0 0.0 0.0 0.0"/>
        <body name="knob_front_left">
          <joint axis="0.0 -1.0 0.0" pos="-0.283540 -0.352213 0.377974" limited="true" name="knob_front_left_joint" range="0.0 3.141592653589793" type="hinge" damping="0.05" armature="0.001"/>
          <geom mesh="knob_front_left_vis" type="mesh" solimp="0.998 0.998 0.001" solref="0.001 1" density="100" friction="0.95 0.3 0.1" class="visual" material="knob_front_left_material"/>
          <geom class="collision" type="cylinder" pos="-0.283085 -0.345812 0.377885" size="0.028806501999497414 0.00980240385979414" quat="0.7071067094802856 0.7071068286895752 0.0 0.0"/>
          <geom class="collision" type="box" pos="-0.283133 -0.363041 0.377709" size="0.008616055361926556 0.007660010829567909 0.023619145154953003" quat="1.0 0.0 0.0 0.0" name="knob_front_left_main"/>
        </body>
        <body name="knob_front_right">
          <joint axis="0.0 -1.0 0.0" pos="0.048532 -0.352213 0.377975" limited="true" name="knob_front_right_joint" range="0.0 3.141592653589793" type="hinge" damping="0.05" armature="0.001"/>
          <geom mesh="knob_front_right_vis" type="mesh" solimp="0.998 0.998 0.001" solref="0.001 1" density="100" friction="0.95 0.3 0.1" class="visual" material="knob_front_right_material"/>
          <geom class="collision" type="box" pos="0.048464 -0.363041 0.377709" size="0.00861604418605566 0.007660005707293749 0.023619122803211212" quat="1.0 0.0 0.0 0.0" name="knob_front_right_main"/>
          <geom class="collision" type="cylinder" pos="0.048511 -0.345812 0.377885" size="0.028806501999497414 0.00980240385979414" quat="0.7071067094802856 0.7071068286895752 0.0 0.0"/>
        </body>
        <body name="knob_rear_left">
          <joint axis="0.0 -1.0 0.0" pos="-0.173767 -0.352213 0.377974" limited="true" name="knob_rear_left_joint" range="0.0 3.141592653589793" type="hinge" damping="0.05" armature="0.001"/>
          <geom mesh="knob_rear_left_vis" type="mesh" solimp="0.998 0.998 0.001" solref="0.001 1" density="100" friction="0.95 0.3 0.1" class="visual" material="knob_rear_left_material"/>
          <geom class="collision" type="box" pos="-0.173871 -0.363041 0.377709" size="0.008616049773991108 0.007660008501261473 0.023619133979082108" quat="1.0 0.0 0.0 0.0" name="knob_rear_left_main"/>
          <geom class="collision" type="cylinder" pos="-0.173823 -0.345812 0.377885" size="0.028806501999497414 0.00980240385979414" quat="0.7071067094802856 0.7071068286895752 0.0 0.0"/>
        </body>
        <body name="knob_rear_right">
          <joint axis="0.0 -1.0 0.0" pos="-0.062610 -0.352213 0.377975" limited="true" name="knob_rear_right_joint" range="0.0 3.141592653589793" type="hinge" damping="0.05" armature="0.001"/>
          <geom mesh="knob_rear_right_vis" type="mesh" solimp="0.998 0.998 0.001" solref="0.001 1" density="100" friction="0.95 0.3 0.1" class="visual" material="knob_rear_right_material"/>
          <geom class="collision" type="box" pos="-0.062893 -0.363041 0.377709" size="0.008616039529442787 0.007660002913326025 0.023619113489985466" quat="1.0 0.0 0.0 0.0" name="knob_rear_right_main"/>
          <geom class="collision" type="cylinder" pos="-0.062845 -0.345812 0.377885" size="0.028806501999497414 0.00980240385979414" quat="0.7071067094802856 0.7071068286895752 0.0 0.0"/>
        </body>
        <body name="Door001">
          <joint axis="1.0 0.0 0.0" pos="-0.000007 -0.332501 -0.256010" limited="true" name="Door001_joint" range="0.0 1.5707963267948966" type="hinge" damping="1" frictionloss="1" armature=".01" stiffness="0.05"/>
          <geom mesh="Door001_vis" type="mesh" solimp="0.998 0.998 0.001" solref="0.001 1" density="100" friction="0.95 0.3 0.1" class="visual" material="Door001_material"/>
          <geom class="collision" type="box" pos="0.000231 -0.299651 0.022286" size="0.39120522141456604 0.034707047045230865 0.279128760099411" quat="1.0 0.0 0.0 0.0"/>
          <geom class="collision" type="box" pos="0.000618 -0.372540 0.280519" size="0.2601470649242401 0.010277687571942806 0.0203574039041996" quat="1.0 0.0 0.0 0.0"/>
          <geom class="collision" type="box" pos="-0.300473 -0.359329 0.280519" size="0.042267441749572754 0.014645480550825596 0.020357487723231316" quat="0.9714630246162415 0.0 -0.0 -0.23719099164009094"/>
          <geom class="collision" type="box" pos="0.303663 -0.359329 0.280519" size="0.042267441749572754 0.014645480550825596 0.020357487723231316" quat="0.9714630246162415 0.0 0.0 0.23719105124473572"/>
          <body name="Door001_Clear">
            <geom mesh="Door001_Clear_vis" type="mesh" solimp="0.998 0.998 0.001" solref="0.001 1" density="100" friction="0.95 0.3 0.1" class="visual" material="Door001_Clear_material"/>
            <geom class="collision" type="box" pos="-0.000138 -0.304011 0.054946" size="0.25481799244880676 0.004614125471562147 0.1529656946659088" quat="1.0 0.0 0.0 0.0"/>
          </body>
        </body>
        <body name="Knob001">
          <joint axis="0.0 0.9999999403953552 0.0" pos="0.173007 -0.352213 0.377737" limited="true" name="Knob001_joint" range="0.0 5.288347633542818" type="hinge" damping="0.05" armature="0.001"/>
          <geom mesh="Knob001_vis" type="mesh" solimp="0.998 0.998 0.001" solref="0.001 1" density="100" friction="0.95 0.3 0.1" class="visual" material="Knob001_material"/>
          <geom class="collision" type="box" pos="0.172739 -0.363041 0.378235" size="0.02361910231411457 0.0076600005850195885 0.008616035804152489" quat="1.0 0.0 0.0 0.0"/>
          <geom class="collision" type="cylinder" pos="0.172915 -0.345812 0.378187" size="0.028806501999497414 0.00980240385979414" quat="0.5 0.5 0.4999999701976776 -0.5"/>
        </body>
        <body name="Knob002">
          <joint axis="0.0 1.0 0.0" pos="0.283604 -0.352213 0.377973" limited="true" name="Knob002_joint" range="0.0 5.602506898901798" type="hinge" damping="0.05" armature="0.001"/>
          <geom mesh="Knob002_vis" type="mesh" solimp="0.998 0.998 0.001" solref="0.001 1" density="100" friction="0.95 0.3 0.1" class="visual" material="Knob002_material"/>
          <geom class="collision" type="box" pos="0.283398 -0.363041 0.377709" size="0.008616028353571892 0.007659997791051865 0.023619091138243675" quat="1.0 0.0 0.0 0.0"/>
          <geom class="collision" type="cylinder" pos="0.283446 -0.345812 0.377885" size="0.028806501999497414 0.00980240385979414" quat="0.7071067094802856 0.7071068286895752 0.0 0.0"/>
        </body>
        <body name="Shelf001">
          <joint axis="0.0 -1.0 0.0" pos="-0.003067 0.027412 0.001080" limited="true" name="Shelf001_joint" range="0.0 0.5" type="slide" damping="1" frictionloss="1" armature=".01" stiffness="0.05"/>
          <geom mesh="Shelf001_vis" type="mesh" solimp="0.998 0.998 0.001" solref="0.001 1" density="100" friction="0.95 0.3 0.1" class="visual" material="Shelf001_material"/>
          <geom class="collision" type="box" pos="-0.002433 0.027924 0.001763" size="0.3329881727695465 0.22152017056941986 0.004735182039439678" quat="1.0 0.0 0.0 0.0"/>
        </body>
        <site name="burner_rear_left_place_site" type="cylinder" rgba="0.5 0 0 0" size="0.11301018297672272 4.999999509891495e-05" pos="-0.163959 0.158725 0.500847"/>
        <site name="burner_front_right_place_site" type="cylinder" rgba="0.5 0 0 0" size="0.11806419491767883 4.999999873689376e-05" pos="0.166136 -0.101286 0.498320"/>
        <site name="burner_rear_right_place_site" type="cylinder" rgba="0.5 0 0 0" size="0.08921706676483154 4.999999873689376e-05" pos="0.179507 0.173874 0.499532"/>
        <site name="burner_front_left_place_site" type="cylinder" rgba="0.5 0 0 0" size="0.08654578775167465 4.999999509891495e-05" pos="-0.178005 -0.102378 0.499407"/>
        <geom class="region" name="reg_main" type="box" pos="0.0 0.0240485 0.0009359999999999924" size="0.391619 0.35876850000000005 0.5022009999999999"/>
        <geom class="region" name="reg_int" type="box" pos="-0.0007909999999999862 0.01757900000000001 0.050092" size="0.335909 0.273003 0.302802"/>
      </body>
    </body>
  </worldbody>
  <actuator>
    <motor name="knob_front_left_joint_actuator" joint="knob_front_left_joint" gear="10"/>
    <motor name="knob_front_right_joint_actuator" joint="knob_front_right_joint" gear="10"/>
    <motor name="knob_rear_left_joint_actuator" joint="knob_rear_left_joint" gear="10"/>
    <motor name="knob_rear_right_joint_actuator" joint="knob_rear_right_joint" gear="10"/>
    <motor name="Door001_joint_actuator" joint="Door001_joint" gear="50"/>
    <motor name="Knob001_joint_actuator" joint="Knob001_joint" gear="50"/>
    <motor name="Knob002_joint_actuator" joint="Knob002_joint" gear="50"/>
    <motor name="Shelf001_joint_actuator" joint="Shelf001_joint" gear="50"/>
  </actuator>
</mujoco>
