<?xml version='1.0' encoding='UTF-8'?>
<mujoco model="model">
  <compiler angle="radian"/>
  <asset>
    <mesh file="visuals/knob_front_center.obj" name="knob_front_center_vis"/>
    <mesh file="visuals/knob_front_left.obj" name="knob_front_left_vis"/>
    <mesh file="visuals/knob_front_right.obj" name="knob_front_right_vis"/>
    <mesh file="visuals/knob_rear_center.obj" name="knob_rear_center_vis"/>
    <mesh file="visuals/knob_rear_left.obj" name="knob_rear_left_vis"/>
    <mesh file="visuals/knob_rear_right.obj" name="knob_rear_right_vis"/>
    <mesh file="visuals/Body001.obj" name="Body001_vis"/>
    <mesh file="visuals/Door001.obj" name="Door001_vis"/>
    <mesh file="visuals/Door001_Clear.obj" name="Door001_Clear_vis"/>
    <mesh file="visuals/Knob001.obj" name="Knob001_vis"/>
    <mesh file="visuals/Knob002.obj" name="Knob002_vis"/>
    <mesh file="visuals/Shelf001.obj" name="Shelf001_vis"/>
    <texture file="visuals/T_BC001.png" name="Body001_material" type="2d"/>
    <material name="Body001_material" rgba="1 1 1 1.0" texture="Body001_material" shininess="0.5" specular="1.5"/>
    <texture file="visuals/T_BC001.png" name="knob_front_center_material" type="2d"/>
    <material name="knob_front_center_material" rgba="1 1 1 1.0" texture="knob_front_center_material" shininess="0.5" specular="2"/>
    <texture file="visuals/T_BC001.png" name="knob_front_left_material" type="2d"/>
    <material name="knob_front_left_material" rgba="1 1 1 1.0" texture="knob_front_left_material" shininess="0.5" specular="2"/>
    <texture file="visuals/T_BC001.png" name="knob_front_right_material" type="2d"/>
    <material name="knob_front_right_material" rgba="1 1 1 1.0" texture="knob_front_right_material" shininess="0.5" specular="2"/>
    <texture file="visuals/T_BC001.png" name="knob_rear_center_material" type="2d"/>
    <material name="knob_rear_center_material" rgba="1 1 1 1.0" texture="knob_rear_center_material" shininess="0.5" specular="2"/>
    <texture file="visuals/T_BC001.png" name="knob_rear_left_material" type="2d"/>
    <material name="knob_rear_left_material" rgba="1 1 1 1.0" texture="knob_rear_left_material" shininess="0.5" specular="2"/>
    <texture file="visuals/T_BC001.png" name="knob_rear_right_material" type="2d"/>
    <material name="knob_rear_right_material" rgba="1 1 1 1.0" texture="knob_rear_right_material" shininess="0.5" specular="2"/>
    <texture file="visuals/T_BC001.png" name="Door001_material" type="2d"/>
    <material name="Door001_material" rgba="1 1 1 1.0" texture="Door001_material" shininess="0.5" specular="1"/>
    <material name="Door001_Clear_material" rgba="0.3485074043273926 0.3485074043273926 0.3485074043273926 0.5" shininess="0.5" specular="0.3103448502657381"/>
    <texture file="visuals/T_BC001.png" name="Knob001_material" type="2d"/>
    <material name="Knob001_material" rgba="1 1 1 1.0" texture="Knob001_material" shininess="0.5" specular="2"/>
    <texture file="visuals/T_BC001.png" name="Knob002_material" type="2d"/>
    <material name="Knob002_material" rgba="1 1 1 1.0" texture="Knob002_material" shininess="0.5" specular="2"/>
    <texture file="visuals/T_BC001.png" name="Shelf001_material" type="2d"/>
    <material name="Shelf001_material" rgba="1 1 1 1.0" texture="Shelf001_material" shininess="0.5" specular="2"/>
  </asset>
  <default>
    <default class="visual">
      <geom conaffinity="0" contype="0" group="1" type="mesh"/>
    </default>
    <default class="collision">
      <geom group="0" rgba="0.5 0 0 0.5"/>
    </default>
    <default class="spawn">
      <geom group="0" rgba="1 1 1 0.5" contype="0" conaffinity="0"/>
      <site group="0" rgba="1 1 1 0.5"/>
    </default>
    <default class="region">
      <geom group="1" conaffinity="0" contype="0" rgba="0 1 0 0"/>
    </default>
  </default>
  <worldbody>
    <body>
      <body name="object">
        <site type="cylinder" rgba="0.3 0.4 1 0.5" size="0.045871008187532425 0.013815520331263542" pos="-0.286249 0.146158 0.397564" name="burner_on_rear_left"/>
        <site type="cylinder" rgba="0.3 0.4 1 0.5" size="0.06383007019758224 0.013815520331263542" pos="-0.286719 -0.110187 0.396464" name="burner_on_front_left"/>
        <site type="cylinder" rgba="0.3 0.4 1 0.5" size="0.035795263946056366 0.010543806478381157" pos="0.283868 -0.110335 0.389359" name="burner_on_front_right"/>
        <site type="cylinder" rgba="0.3 0.4 1 0.5" size="0.052925318479537964 0.018182458356022835" pos="0.284603 0.146193 0.396892" name="burner_on_rear_right"/>
        <site type="cylinder" rgba="0.3 0.4 1 0.5" size="0.07991979271173477 0.010543806478381157" pos="-0.000364 -0.110209 0.389359" name="burner_on_front_center"/>
        <site type="cylinder" rgba="0.3 0.4 1 0.5" size="0.0651245266199112 0.010543806478381157" pos="-0.000229 0.146359 0.389359" name="burner_on_rear_center"/>
        <geom mesh="Body001_vis" type="mesh" solimp="0.998 0.998 0.001" solref="0.001 1" density="100" friction="0.95 0.3 0.1" class="visual" material="Body001_material"/>
        <geom class="collision" type="box" pos="-0.465576 0.030373 -0.007222" size="0.02281191758811474 0.32583460211753845 0.40695932507514954" quat="1.0 0.0 0.0 0.0"/>
        <geom class="collision" type="box" pos="0.462853 0.030375 -0.007222" size="0.027301255613565445 0.32582736015319824 0.40693792700767517" quat="1.0 0.0 0.0 0.0"/>
        <geom class="collision" type="box" pos="-0.007828 0.030289 -0.343044" size="0.4429432153701782 0.32591354846954346 0.07090509682893753" quat="1.0 0.0 0.0 0.0"/>
        <geom class="collision" type="box" pos="0.000883 0.341562 0.095813" size="0.4892715811729431 0.014645854011178017 0.3746751844882965" quat="1.0 0.0 0.0 0.0"/>
        <geom class="collision" type="box" pos="-0.007828 0.030938 0.301078" size="0.44297242164611816 0.30182188749313354 0.061493270099163055" quat="1.0 0.0 0.0 0.0"/>
        <geom class="collision" type="box" pos="-0.007828 -0.261878 0.371255" size="0.44295358657836914 0.034286003559827805 0.02430732175707817" quat="1.0 0.0 0.0 0.0"/>
        <geom class="collision" type="box" pos="-0.007828 -0.261688 0.231488" size="0.4429881274700165 0.03409847617149353 0.010478483512997627" quat="1.0 0.0 0.0 0.0"/>
        <geom class="collision" type="box" pos="-0.007828 0.300878 0.371255" size="0.442954421043396 0.035997215658426285 0.02430732175707817" quat="1.0 0.0 0.0 0.0"/>
        <geom class="collision" type="box" pos="-0.435284 0.017543 0.371255" size="0.026038331910967827 0.2506503462791443 0.024305829778313637" quat="1.0 0.0 0.0 0.0"/>
        <geom class="collision" type="box" pos="0.421416 0.017543 0.371255" size="0.026038331910967827 0.250650554895401 0.024305863305926323" quat="1.0 0.0 0.0 0.0"/>
        <geom class="collision" type="box" pos="0.145393 0.017543 0.371255" size="0.012343472801148891 0.25066816806793213 0.0243085790425539" quat="1.0 0.0 0.0 0.0"/>
        <geom class="collision" type="box" pos="-0.139185 0.017543 0.371255" size="0.012343459762632847 0.2506679594516754 0.024308545514941216" quat="1.0 0.0 0.0 0.0"/>
        <geom class="collision" type="box" pos="0.003188 0.021158 0.398953" size="0.4297998249530792 0.00840801652520895 0.007894785143435001" quat="1.0 0.0 0.0 0.0"/>
        <geom class="collision" type="box" pos="0.146227 -0.110828 0.398953" size="0.0883287712931633 0.011926512233912945 0.00789455883204937" quat="1.0 0.0 0.0 0.0"/>
        <geom class="collision" type="box" pos="-0.379343 -0.109645 0.398953" size="0.04288601502776146 0.008407792076468468 0.007894523441791534" quat="1.0 0.0 0.0 0.0"/>
        <geom class="collision" type="box" pos="-0.139757 -0.109645 0.398953" size="0.0883287712931633 0.00840780045837164 0.007894600741565228" quat="1.0 0.0 0.0 0.0"/>
        <geom class="collision" type="box" pos="0.383107 -0.109645 0.398953" size="0.04288609325885773 0.008407801389694214 0.007894554175436497" quat="1.0 0.0 0.0 0.0"/>
        <geom class="collision" type="box" pos="0.146227 0.155053 0.398953" size="0.0883287712931633 0.010853624902665615 0.007894582115113735" quat="1.0 0.0 0.0 0.0"/>
        <geom class="collision" type="box" pos="-0.379343 0.155437 0.398953" size="0.042886167764663696 0.00840781070291996 0.007894554175436497" quat="1.0 0.0 0.0 0.0"/>
        <geom class="collision" type="box" pos="-0.139757 0.154772 0.398953" size="0.0883287712931633 0.011325187049806118 0.007894624955952168" quat="1.0 0.0 0.0 0.0"/>
        <geom class="collision" type="box" pos="0.383107 0.155437 0.398953" size="0.042886242270469666 0.008407819084823132 0.00789456907659769" quat="1.0 0.0 0.0 0.0"/>
        <geom class="collision" type="box" pos="-0.282329 0.248352 0.398953" size="0.008407678455114365 0.04288633167743683 0.00789457093924284" quat="1.0 0.0 0.0 0.0"/>
        <geom class="collision" type="box" pos="-0.282329 0.027268 0.398953" size="0.00840795412659645 0.08832675963640213 0.007894625887274742" quat="1.0 0.0 0.0 0.0"/>
        <geom class="collision" type="box" pos="-0.282329 -0.202560 0.398953" size="0.008407698012888432 0.0428864061832428 0.007894585840404034" quat="1.0 0.0 0.0 0.0"/>
        <geom class="collision" type="box" pos="0.003795 0.248352 0.398953" size="0.008407707326114178 0.042886439710855484 0.007894594222307205" quat="1.0 0.0 0.0 0.0"/>
        <geom class="collision" type="box" pos="0.003795 0.027268 0.398953" size="0.00840795412659645 0.08832697570323944 0.007894644513726234" quat="1.0 0.0 0.0 0.0"/>
        <geom class="collision" type="box" pos="0.003795 -0.202560 0.398953" size="0.00840772595256567 0.04288651421666145 0.007894609123468399" quat="1.0 0.0 0.0 0.0"/>
        <geom class="collision" type="box" pos="0.286639 0.248352 0.398953" size="0.008407735265791416 0.04288654774427414 0.007894616574048996" quat="1.0 0.0 0.0 0.0"/>
        <geom class="collision" type="box" pos="0.287244 0.027268 0.398953" size="0.012256301939487457 0.08832719177007675 0.00789463147521019" quat="1.0 0.0 0.0 0.0"/>
        <geom class="collision" type="box" pos="0.286639 -0.202560 0.398953" size="0.008407754823565483 0.04288662225008011 0.00789461750537157" quat="1.0 0.0 0.0 0.0"/>
        <geom class="collision" type="box" pos="-0.398863 0.267355 0.398953" size="0.007894790731370449 0.008407950401306152 0.02992229163646698" quat="0.270597904920578 -0.653281569480896 0.2705978751182556 0.6532815098762512"/>
        <geom class="collision" type="box" pos="-0.113969 0.267355 0.398953" size="0.007894790731370449 0.008407950401306152 0.02992229163646698" quat="0.270597904920578 -0.653281569480896 0.2705978751182556 0.6532815098762512"/>
        <geom class="collision" type="box" pos="0.172291 0.267355 0.398953" size="0.007894746027886868 0.008407950401306152 0.02992229163646698" quat="0.270597904920578 -0.653281569480896 0.2705978751182556 0.6532815098762512"/>
        <geom class="collision" type="box" pos="0.405945 0.267355 0.398953" size="0.007894731126725674 0.008407950401306152 0.02992229163646698" quat="0.27059808373451233 -0.653281569480896 -0.27059799432754517 -0.6532813906669617"/>
        <geom class="collision" type="box" pos="0.121051 0.267355 0.398953" size="0.007894746027886868 0.008407950401306152 0.02992229163646698" quat="0.27059808373451233 -0.653281569480896 -0.27059799432754517 -0.6532813906669617"/>
        <geom class="collision" type="box" pos="-0.165209 0.267355 0.398953" size="0.007894790731370449 0.008407950401306152 0.02992229163646698" quat="0.27059808373451233 -0.653281569480896 -0.27059799432754517 -0.6532813906669617"/>
        <geom class="collision" type="box" pos="-0.398863 0.001727 0.398953" size="0.007894790731370449 0.008407950401306152 0.02992229163646698" quat="0.270597904920578 -0.653281569480896 0.2705978751182556 0.6532815098762512"/>
        <geom class="collision" type="box" pos="-0.113969 0.001727 0.398953" size="0.007894790731370449 0.008407950401306152 0.02992229163646698" quat="0.270597904920578 -0.653281569480896 0.2705978751182556 0.6532815098762512"/>
        <geom class="collision" type="box" pos="0.172291 0.001727 0.398953" size="0.007894746027886868 0.008407950401306152 0.02992229163646698" quat="0.270597904920578 -0.653281569480896 0.2705978751182556 0.6532815098762512"/>
        <geom class="collision" type="box" pos="0.405945 0.001727 0.398953" size="0.007894731126725674 0.008407950401306152 0.02992229163646698" quat="0.27059808373451233 -0.653281569480896 -0.27059799432754517 -0.6532813906669617"/>
        <geom class="collision" type="box" pos="0.121051 0.001727 0.398953" size="0.007894746027886868 0.008407950401306152 0.02992229163646698" quat="0.27059808373451233 -0.653281569480896 -0.27059799432754517 -0.6532813906669617"/>
        <geom class="collision" type="box" pos="-0.165209 0.001727 0.398953" size="0.007894790731370449 0.008407950401306152 0.02992229163646698" quat="0.27059808373451233 -0.653281569480896 -0.27059799432754517 -0.6532813906669617"/>
        <geom class="collision" type="box" pos="0.405945 -0.222089 0.398953" size="0.007894731126725674 0.008407950401306152 0.02992229163646698" quat="0.653281569480896 0.2705981135368347 0.6532813906669617 -0.27059802412986755"/>
        <geom class="collision" type="box" pos="0.121051 -0.222089 0.398953" size="0.007894760929048061 0.008407950401306152 0.02992229163646698" quat="0.653281569480896 0.2705981135368347 0.6532813906669617 -0.27059802412986755"/>
        <geom class="collision" type="box" pos="-0.165209 -0.222089 0.398953" size="0.007894790731370449 0.008407950401306152 0.02992229163646698" quat="0.653281569480896 0.2705981135368347 0.6532813906669617 -0.27059802412986755"/>
        <geom class="collision" type="box" pos="-0.398863 -0.222089 0.398953" size="0.007894790731370449 0.008407950401306152 0.02992229163646698" quat="0.6532815098762512 0.27059823274612427 -0.6532813310623169 0.2705981433391571"/>
        <geom class="collision" type="box" pos="-0.113969 -0.222089 0.398953" size="0.007894790731370449 0.008407950401306152 0.02992229163646698" quat="0.6532815098762512 0.27059823274612427 -0.6532813310623169 0.2705981433391571"/>
        <geom class="collision" type="box" pos="0.172291 -0.222089 0.398953" size="0.007894760929048061 0.008407950401306152 0.02992229163646698" quat="0.6532815098762512 0.27059823274612427 -0.6532813310623169 0.2705981433391571"/>
        <geom class="collision" type="box" pos="0.405945 0.047091 0.398953" size="0.007894746027886868 0.008407950401306152 0.02992229163646698" quat="0.653281569480896 0.2705981135368347 0.6532813906669617 -0.27059802412986755"/>
        <geom class="collision" type="box" pos="0.121051 0.047091 0.398953" size="0.007894731126725674 0.008407950401306152 0.02992229163646698" quat="0.653281569480896 0.2705981135368347 0.6532813906669617 -0.27059802412986755"/>
        <geom class="collision" type="box" pos="-0.165209 0.047091 0.398953" size="0.007894790731370449 0.008407950401306152 0.02992229163646698" quat="0.653281569480896 0.2705981135368347 0.6532813906669617 -0.27059802412986755"/>
        <geom class="collision" type="box" pos="-0.398863 0.047091 0.398953" size="0.007894790731370449 0.008407950401306152 0.02992229163646698" quat="0.6532815098762512 0.27059823274612427 -0.6532813310623169 0.2705981433391571"/>
        <geom class="collision" type="box" pos="-0.113969 0.047091 0.398953" size="0.007894790731370449 0.008407950401306152 0.02992229163646698" quat="0.6532815098762512 0.27059823274612427 -0.6532813310623169 0.2705981433391571"/>
        <geom class="collision" type="box" pos="0.172291 0.047091 0.398953" size="0.007894760929048061 0.008407950401306152 0.02992229163646698" quat="0.6532815098762512 0.27059823274612427 -0.6532813310623169 0.2705981433391571"/>
        <geom class="collision" type="box" pos="-0.007828 0.024111 0.215394" size="0.4429723918437958 0.28328001499176025 0.010477830655872822" quat="1.0 0.0 0.0 0.0"/>
        <geom class="collision" type="box" pos="-0.007828 0.024111 -0.258969" size="0.4429723918437958 0.28328001499176025 0.010477830655872822" quat="1.0 0.0 0.0 0.0"/>
        <geom class="collision" type="box" pos="-0.424349 0.024111 -0.022338" size="0.010477871634066105 0.28328001499176025 0.23162606358528137" quat="1.0 0.0 0.0 0.0"/>
        <geom class="collision" type="box" pos="0.423539 0.024111 -0.022338" size="0.011447538621723652 0.28328001499176025 0.23162606358528137" quat="1.0 0.0 0.0 0.0"/>
        <geom class="collision" type="box" pos="-0.002769 0.299407 -0.024966" size="0.4178180396556854 0.010477843694388866 0.2359468936920166" quat="1.0 0.0 0.0 0.0"/>
        <geom class="collision" type="cylinder" pos="-0.285052 0.146454 0.370380" size="0.07551901042461395 0.008533874526619911" quat="1.0 0.0 0.0 0.0"/>
        <geom class="collision" type="cylinder" pos="-0.002809 0.146454 0.362575" size="0.07551901042461395 0.008533874526619911" quat="1.0 0.0 0.0 0.0"/>
        <geom class="collision" type="cylinder" pos="0.286568 0.146454 0.372822" size="0.06650479882955551 0.007515241391956806" quat="1.0 0.0 0.0 0.0"/>
        <geom class="collision" type="cylinder" pos="-0.285052 -0.110117 0.370380" size="0.08158350735902786 0.009219180792570114" quat="1.0 0.0 0.0 0.0"/>
        <geom class="collision" type="cylinder" pos="-0.000669 -0.108769 0.361717" size="0.0886225476861 0.010014613159000874" quat="1.0 0.0 0.0 0.0"/>
        <geom class="collision" type="cylinder" pos="0.283628 -0.110477 0.369704" size="0.05324289947748184 0.008796552196145058" quat="1.0 0.0 0.0 0.0"/>
        <geom class="collision" type="cylinder" pos="-0.285052 -0.110117 0.391344" size="0.060808539390563965 0.011219466105103493" quat="1.0 0.0 0.0 0.0"/>
        <geom class="collision" type="cylinder" pos="-0.285052 0.146454 0.392436" size="0.042530860751867294 0.011385127902030945" quat="1.0 0.0 0.0 0.0"/>
        <geom class="collision" type="cylinder" pos="-0.002809 0.146454 0.381206" size="0.06009776145219803 0.007740130182355642" quat="1.0 0.0 0.0 0.0"/>
        <geom class="collision" type="cylinder" pos="-0.000669 -0.108769 0.379076" size="0.07909324765205383 0.00893777422606945" quat="1.0 0.0 0.0 0.0"/>
        <geom class="collision" type="cylinder" pos="0.283628 -0.110477 0.390530" size="0.028883107006549835 0.012157234363257885" quat="1.0 0.0 0.0 0.0"/>
        <geom class="collision" type="cylinder" pos="0.286568 0.146454 0.389888" size="0.0419054739177227 0.013532611541450024" quat="1.0 0.0 0.0 0.0"/>
        <geom class="collision" type="box" pos="-0.408472 0.003875 -0.001103" size="0.01244853064417839 0.20002445578575134 0.004354590084403753" quat="1.0 0.0 0.0 0.0"/>
        <geom class="collision" type="box" pos="0.408847 0.003875 -0.001103" size="0.01244853064417839 0.20002445578575134 0.004354590084403753" quat="1.0 0.0 0.0 0.0"/>
        <geom class="collision" type="cylinder" pos="-0.403637 -0.241929 -0.438970" size="0.02651587501168251 0.02479064092040062" quat="1.0 0.0 0.0 0.0"/>
        <geom class="collision" type="cylinder" pos="0.408654 -0.243430 -0.438970" size="0.02651587501168251 0.02479064092040062" quat="1.0 0.0 0.0 0.0"/>
        <geom class="collision" type="cylinder" pos="0.408654 0.301583 -0.438970" size="0.02651587501168251 0.02479064092040062" quat="1.0 0.0 0.0 0.0"/>
        <geom class="collision" type="cylinder" pos="-0.403637 0.303083 -0.438970" size="0.02651587501168251 0.02479064092040062" quat="1.0 0.0 0.0 0.0"/>
        <body name="knob_front_center">
          <joint axis="0.0 -1.0 0.0" pos="0.078752 -0.290999 0.284789" limited="true" name="knob_front_center_joint" range="0.0 3.141592653589793" type="hinge" damping="0.05" armature="0.001"/>
          <geom mesh="knob_front_center_vis" type="mesh" solimp="0.998 0.998 0.001" solref="0.001 1" density="100" friction="0.95 0.3 0.1" class="visual" material="knob_front_center_material"/>
          <geom class="collision" type="cylinder" pos="0.079250 -0.288180 0.284789" size="0.02351096272468567 0.006129719782620668" quat="0.7071068286895752 0.7071067690849304 -1.5700924318127872e-16 -5.9269340452702814e-24"/>
          <geom class="collision" type="box" pos="0.079250 -0.301823 0.284789" size="0.005404462572187185 0.009122075513005257 0.01902027055621147" quat="1.0 0.0 0.0 0.0" name="knob_front_center_main"/>
        </body>
        <body name="knob_front_left">
          <joint axis="0.0 -1.0 0.0" pos="-0.377609 -0.290999 0.284789" limited="true" name="knob_front_left_joint" range="0.0 3.141592653589793" type="hinge" damping="0.05" armature="0.001"/>
          <geom mesh="knob_front_left_vis" type="mesh" solimp="0.998 0.998 0.001" solref="0.001 1" density="100" friction="0.95 0.3 0.1" class="visual" material="knob_front_left_material"/>
          <geom class="collision" type="cylinder" pos="-0.377609 -0.288180 0.284789" size="0.02351096272468567 0.006129719782620668" quat="0.7071068286895752 0.7071067690849304 -1.5700924318127872e-16 -5.9269340452702814e-24"/>
          <geom class="collision" type="box" pos="-0.377609 -0.301823 0.284789" size="0.005404462572187185 0.009122075513005257 0.019020281732082367" quat="1.0 0.0 0.0 0.0" name="knob_front_left_main"/>
        </body>
        <body name="knob_front_right">
          <joint axis="0.0 -1.0 0.0" pos="0.397645 -0.290999 0.284789" limited="true" name="knob_front_right_joint" range="0.0 3.141592653589793" type="hinge" damping="0.05" armature="0.001"/>
          <geom mesh="knob_front_right_vis" type="mesh" solimp="0.998 0.998 0.001" solref="0.001 1" density="100" friction="0.95 0.3 0.1" class="visual" material="knob_front_right_material"/>
          <geom class="collision" type="cylinder" pos="0.397909 -0.288180 0.284789" size="0.02351096272468567 0.006129719782620668" quat="0.7071068286895752 0.7071067690849304 -1.5700924318127872e-16 -5.9269340452702814e-24"/>
          <geom class="collision" type="box" pos="0.397909 -0.301823 0.284789" size="0.005404462572187185 0.009122075513005257 0.019020291045308113" quat="1.0 0.0 0.0 0.0" name="knob_front_right_main"/>
        </body>
        <body name="knob_rear_center">
          <joint axis="0.0 -1.0 0.0" pos="0.185085 -0.290999 0.284789" limited="true" name="knob_rear_center_joint" range="0.0 3.141592653589793" type="hinge" damping="0.05" armature="0.001"/>
          <geom mesh="knob_rear_center_vis" type="mesh" solimp="0.998 0.998 0.001" solref="0.001 1" density="100" friction="0.95 0.3 0.1" class="visual" material="knob_rear_center_material"/>
          <geom class="collision" type="cylinder" pos="0.184773 -0.288180 0.284789" size="0.02351096272468567 0.006129719782620668" quat="0.7071068286895752 0.7071067690849304 -1.5700924318127872e-16 -5.9269340452702814e-24"/>
          <geom class="collision" type="box" pos="0.184773 -0.301823 0.284789" size="0.005404462572187185 0.009122075513005257 0.01902030222117901" quat="1.0 0.0 0.0 0.0" name="knob_rear_center_main"/>
        </body>
        <body name="knob_rear_left">
          <joint axis="0.0 -1.0 0.0" pos="-0.271090 -0.290999 0.284789" limited="true" name="knob_rear_left_joint" range="0.0 3.141592653589793" type="hinge" damping="0.05" armature="0.001"/>
          <geom mesh="knob_rear_left_vis" type="mesh" solimp="0.998 0.998 0.001" solref="0.001 1" density="100" friction="0.95 0.3 0.1" class="visual" material="knob_rear_left_material"/>
          <geom class="collision" type="cylinder" pos="-0.270988 -0.288180 0.284789" size="0.02351096272468567 0.006129719782620668" quat="0.7071068286895752 0.7071067690849304 -1.5700924318127872e-16 -5.9269340452702814e-24"/>
          <geom class="collision" type="box" pos="-0.270988 -0.301823 0.284789" size="0.005404462572187185 0.009122075513005257 0.019020311534404755" quat="1.0 0.0 0.0 0.0" name="knob_rear_left_main"/>
        </body>
        <body name="knob_rear_right">
          <joint axis="0.0 -1.0 0.0" pos="0.291343 -0.290999 0.284789" limited="true" name="knob_rear_right_joint" range="0.0 3.141592653589793" type="hinge" damping="0.05" armature="0.001"/>
          <geom mesh="knob_rear_right_vis" type="mesh" solimp="0.998 0.998 0.001" solref="0.001 1" density="100" friction="0.95 0.3 0.1" class="visual" material="knob_rear_right_material"/>
          <geom class="collision" type="cylinder" pos="0.291496 -0.288180 0.284789" size="0.02351096272468567 0.006129719782620668" quat="0.7071068286895752 0.7071067690849304 -1.5700924318127872e-16 -5.9269340452702814e-24"/>
          <geom class="collision" type="box" pos="0.291496 -0.301823 0.284789" size="0.005404462572187185 0.009122075513005257 0.01902032271027565" quat="1.0 0.0 0.0 0.0" name="knob_rear_right_main"/>
        </body>
        <body name="Door001">
          <joint axis="1.0 0.0 0.0" pos="-0.000528 -0.296384 -0.270393" limited="true" name="Door001_joint" range="0.0 1.5707963267948966" type="hinge" damping="1" frictionloss="1" armature=".01" stiffness="0.05"/>
          <geom mesh="Door001_vis" type="mesh" solimp="0.998 0.998 0.001" solref="0.001 1" density="100" friction="0.95 0.3 0.1" class="visual" material="Door001_material"/>
          <geom class="collision" type="box" pos="0.000000 -0.281511 -0.022519" size="0.4303256869316101 0.01450288761407137 0.22068700194358826" quat="1.0 0.0 0.0 0.0"/>
          <geom class="collision" type="box" pos="-0.313469 -0.319299 0.179285" size="0.03494257107377052 0.024839654564857483 0.011061478406190872" quat="1.0 0.0 0.0 0.0"/>
          <geom class="collision" type="box" pos="0.306819 -0.319299 0.179285" size="0.034942589700222015 0.024839669466018677 0.01106148399412632" quat="1.0 0.0 0.0 0.0"/>
          <geom class="collision" type="cylinder" pos="-0.000000 -0.350748 0.179930" size="0.011870450340211391 0.3469732999801636" quat="0.7071068286895752 -4.7503018407724085e-08 -0.7071067094802856 -4.750301130229673e-08"/>
          <body name="Door001_Clear">
            <geom mesh="Door001_Clear_vis" type="mesh" solimp="0.998 0.998 0.001" solref="0.001 1" density="100" friction="0.95 0.3 0.1" class="visual" material="Door001_Clear_material"/>
            <geom class="collision" type="box" pos="0.000000 -0.279657 -0.011890" size="0.35245248675346375 0.011737396009266376 0.18250848352909088" quat="1.0 0.0 0.0 0.0"/>
          </body>
        </body>
        <body name="Knob001">
          <joint axis="0.0 1.0 0.0" pos="-0.141599 -0.290999 0.284789" limited="true" name="Knob001_joint" range="0.0 5.235987755982989" type="hinge" damping="0.05" armature="0.001"/>
          <geom mesh="Knob001_vis" type="mesh" solimp="0.998 0.998 0.001" solref="0.001 1" density="100" friction="0.95 0.3 0.1" class="visual" material="Knob001_material"/>
          <geom class="collision" type="cylinder" pos="-0.141136 -0.288180 0.284789" size="0.02351096272468567 0.006129719782620668" quat="0.7071068286895752 0.7071067690849304 -1.5700924318127872e-16 -5.9269340452702814e-24"/>
          <geom class="collision" type="box" pos="-0.141136 -0.301823 0.284789" size="0.019020427018404007 0.00912207830697298 0.005404421128332615" quat="1.0 0.0 0.0 0.0"/>
        </body>
        <body name="Knob002">
          <joint axis="0.0 1.0 0.0" pos="-0.036059 -0.290999 0.284789" limited="true" name="Knob002_joint" range="0.0 5.585053606381854" type="hinge" damping="0.05" armature="0.001"/>
          <geom mesh="Knob002_vis" type="mesh" solimp="0.998 0.998 0.001" solref="0.001 1" density="100" friction="0.95 0.3 0.1" class="visual" material="Knob002_material"/>
          <geom class="collision" type="cylinder" pos="-0.035950 -0.288180 0.284789" size="0.02351096272468567 0.006129719782620668" quat="0.7071068286895752 0.7071067690849304 -1.5700924318127872e-16 -5.9269340452702814e-24"/>
          <geom class="collision" type="box" pos="-0.035950 -0.301823 0.284789" size="0.005404462572187185 0.009122075513005257 0.01902034319937229" quat="1.0 0.0 0.0 0.0"/>
        </body>
        <body name="Shelf001">
          <joint axis="0.0 -1.0 0.0" pos="0.001380 0.005550 0.015202" limited="true" name="Shelf001_joint" range="0.0 0.37" type="slide" damping="1" frictionloss="1" armature=".01" stiffness="0.05"/>
          <geom mesh="Shelf001_vis" type="mesh" solimp="0.998 0.998 0.001" solref="0.001 1" density="100" friction="0.95 0.3 0.1" class="visual" material="Shelf001_material"/>
          <geom class="collision" type="box" pos="0.000398 0.003875 0.014034" size="0.4045194685459137 0.2453322559595108 0.005284389015287161" quat="1.0 0.0 0.0 0.0"/>
        </body>
        <site name="burner_rear_left_place_site" type="cylinder" rgba="0.3 0.4 1 0" size="0.045871008187532425 0.013815520331263542" pos="-0.286249 0.146158 0.397564"/>
        <site name="burner_front_left_place_site" type="cylinder" rgba="0.3 0.4 1 0" size="0.06383007019758224 0.013815520331263542" pos="-0.286719 -0.110187 0.396464"/>
        <site name="burner_front_right_place_site" type="cylinder" rgba="0.3 0.4 1 0" size="0.035795263946056366 0.010543806478381157" pos="0.283868 -0.110335 0.389359"/>
        <site name="burner_rear_right_place_site" type="cylinder" rgba="0.3 0.4 1 0" size="0.052925318479537964 0.018182458356022835" pos="0.284603 0.146193 0.396892"/>
        <site name="burner_front_center_place_site" type="cylinder" rgba="0.3 0.4 1 0" size="0.07991979271173477 0.010543806478381157" pos="-0.000364 -0.110209 0.389359"/>
        <site name="burner_rear_center_place_site" type="cylinder" rgba="0.3 0.4 1 0" size="0.0651245266199112 0.010543806478381157" pos="-0.000229 0.146359 0.389359"/>
        <geom class="region" name="reg_main" type="box" pos="0.0 0.03235199999999999 -0.030309500000000017" size="0.492836 0.33 0.4371575"/>
        <geom class="region" name="reg_int" type="box" pos="0.0023304999999999854 0.01881949999999999 -0.026097499999999996" size="0.41618849999999996 0.2764875 0.2303905"/>
      </body>
    </body>
  </worldbody>
  <actuator>
    <motor name="knob_front_center_joint_actuator" joint="knob_front_center_joint" gear="10"/>
    <motor name="knob_front_left_joint_actuator" joint="knob_front_left_joint" gear="10"/>
    <motor name="knob_front_right_joint_actuator" joint="knob_front_right_joint" gear="10"/>
    <motor name="knob_rear_center_joint_actuator" joint="knob_rear_center_joint" gear="10"/>
    <motor name="knob_rear_left_joint_actuator" joint="knob_rear_left_joint" gear="10"/>
    <motor name="knob_rear_right_joint_actuator" joint="knob_rear_right_joint" gear="10"/>
    <motor name="Door001_joint_actuator" joint="Door001_joint" gear="50"/>
    <motor name="Knob001_joint_actuator" joint="Knob001_joint" gear="50"/>
    <motor name="Knob002_joint_actuator" joint="Knob002_joint" gear="50"/>
    <motor name="Shelf001_joint_actuator" joint="Shelf001_joint" gear="50"/>
  </actuator>
</mujoco>
