<mujoco model="model">
  <compiler angle="radian"/>
  <asset>
    <material name="metal_Mat" specular="0.5" shininess="0.36" rgba="0.800000 0.800000 0.800000 1.000000"/>
    <material name="sink_Mat" specular="0.5" shininess="0.36" rgba="0.800000 0.800000 0.800000 1.000000"/>
    <material name="tap_Mat" specular="0.5" shininess="0.36" rgba="0.800000 0.800000 0.800000 1.000000"/>
    <mesh file="visuals/model_0.obj" name="model_0_vis" scale="1 1 1"/>
    <mesh file="visuals/model_1.obj" name="model_1_vis" scale="1 1 1"/>
    <mesh file="visuals/model_2.obj" name="model_2_vis" scale="1 1 1"/>
    <mesh file="visuals/spout_0.obj" name="spout_0_vis" scale="1 1 1"/>
    <mesh file="visuals/handle_0.obj" name="handle_0_vis" scale="1 1 1"/>
  </asset>
  <default>
    <default class="visual">
      <geom conaffinity="0" contype="0" group="1" type="mesh"/>
    </default>
    <default class="collision">
      <!-- <geom group="0" rgba="0.5 0 0 0.5"/> -->
      <geom group="0" rgba="0.5 0 0 0.5" solimp="0.998 0.998 0.001" solref="0.001 2"/>
    </default>
    <default class="region">
      <geom group="1" conaffinity="0" contype="0" rgba="0 1 0 0"/>
    </default>
  </default>
  <worldbody>
    <body>
      <!-- exterior bounding box points -->
      <!-- interior bounding box points (LEFT) -->
      <!-- interior bounding box points (RIGHT) -->
      <body name="object">
        <geom solimp="0.998 0.998 0.001" solref="0.001 1" density="100" friction="0.95 0.3 0.1" type="mesh" mesh="model_0_vis" material="sink_Mat" class="visual"/>
        <geom solimp="0.998 0.998 0.001" solref="0.001 1" density="100" friction="0.95 0.3 0.1" type="mesh" mesh="model_1_vis" material="tap_Mat" class="visual"/>
        <geom solimp="0.998 0.998 0.001" solref="0.001 1" density="100" friction="0.95 0.3 0.1" type="mesh" mesh="model_2_vis" material="metal_Mat" class="visual"/>
        <!-- Bottom -->
        <geom class="collision" type="box" pos="0 0 -0.255" size="0.42 0.24 0.005"/>
        <geom class="collision" type="box" pos="0.215 0 -0.25" size="0.20 0.23 0.01" name="bottom"/>
        <geom class="collision" type="box" pos="-0.215 0 -0.25" size="0.20 0.23 0.01" name="bottom_left"/>
        <!-- Center Wall -->
        <geom class="collision" type="box" pos="0 0 -0.14" size="0.021 0.24 0.105"/>
        <!-- Back Wall -->
        <geom class="collision" type="box" pos="0 0.24 -0.14" size="0.42 0.01 0.105"/>
        <!-- Front Wall -->
        <geom class="collision" type="box" pos="0 -0.24 -0.14" size="0.42 0.01 0.105"/>
        <!-- Right Wall -->
        <geom class="collision" type="box" pos="0.42 0 -0.14" size="0.01 0.24 0.105"/>
        <!-- Left Wall -->
        <geom class="collision" type="box" pos="-0.42 0 -0.14" size="0.01 0.24 0.105"/>
        <!-- Back Ledge -->
        <geom class="collision" type="box" pos="0 0.271 -0.03" size="0.5 0.021 0.007"/>
        <!-- Front Ledge -->
        <geom class="collision" type="box" pos="0 -0.271 -0.03" size="0.5 0.021 0.007"/>
        <!-- Right Ledge -->
        <geom class="collision" type="box" pos="0.465 0 -0.03" size="0.037 0.27 0.007"/>
        <!-- Left Ledge -->
        <geom class="collision" type="box" pos="-0.465 0 -0.03" size="0.037 0.27 0.007"/>
        <!-- Faucet Base -->
        <geom class="collision" type="cylinder" pos="0.001 0.2245 0.035" size="0.022 0.071 0"/>
        <!-- Handle Attach Point-->
        <!-- <geom class="collision" type="cylinder" pos="0.0295 0.2245 0.047" size="0.02 0.019 0" axisangle="0 1 0 1.57"/> -->
        <body name="spout">
          <joint axis="0 0 1" limited="true" name="spout_joint" range="-2.36 0.79" pos="0.001 0.2245 0" armature="2" damping="10"/>
          <geom solimp="0.998 0.998 0.001" solref="0.001 1" density="100" friction="0.95 0.3 0.1" type="mesh" mesh="spout_0_vis" material="tap_Mat" class="visual"/>
          <geom class="collision" type="cylinder" pos="0.001 0.2245 0.15" size="0.022 0.044 0"/>
          <geom class="collision" type="box" pos="0.02 0.205 0.245" size="0.015 0.06 0.015" quat="0.854 -0.354 -0.146 0.354"/>
          <geom class="collision" type="box" pos="0.123 0.102 0.285" size="0.015 0.098 0.015" quat="0.923 -0.0322 -0.0134 0.382" name="spout_top"/>
          <site type="cylinder" rgba="0.5 0.75 1 1" pos="0.18 0.045 0.025" size="0.01 0.275" name="water"/>
        </body>
        <body name="handle">
          <joint axis="1 0 0" limited="true" name="handle_temp_joint" range="-0.79 0.79" pos="0.0485 0.2245 0.047" armature="2" damping="50"/>
          <joint axis="0 1 0" type="hinge" limited="true" name="handle_joint" range="0 0.52" pos="0.0485 0.2245 0.045" damping="10"/>
          <geom solimp="0.998 0.998 0.001" solref="0.001 1" density="100" friction="0.95 0.3 0.1" type="mesh" mesh="handle_0_vis" material="tap_Mat" class="visual"/>
          <geom class="collision" type="cylinder" pos="0.0625 0.2245 0.047" size="0.02 0.014 0" axisangle="0 1 0 1.57"/>
          <geom class="collision" type="box" pos="0.07 0.2243 0.10" size="0.005 0.0024 0.034" name="handle_main"/>
        </body>
        <geom class="region" name="reg_main_body" type="box" pos="0.0 0.0 -0.14" size="0.5 0.292 0.12000000000000001"/>
        <geom class="region" name="reg_left_int" type="box" pos="-0.2155 0.0 -0.135" size="0.19449999999999998 0.23 0.105"/>
        <geom class="region" name="reg_int" type="box" pos="0.2155 0.0 -0.135" size="0.19449999999999998 0.23 0.105"/>
      </body>
    </body>
  </worldbody>
</mujoco>
