<mujoco model="model">
  <compiler angle="radian"/>
  <asset>
    <mesh file="visuals/Body001.obj" name="Body001_vis"/>
    <mesh file="visuals/Button001.obj" name="Button001_vis"/>
    <mesh file="visuals/Door001_Clear.obj" name="Door001_Clear_vis"/>
    <mesh file="visuals/Handle001.obj" name="Handle001_vis"/>
    <mesh file="visuals/Knob001.obj" name="Knob001_vis"/>
    <mesh file="visuals/Knob002.obj" name="Knob002_vis"/>
    <mesh file="visuals/Knob003.obj" name="Knob003_vis"/>
    <mesh file="visuals/Shelf001.obj" name="Shelf001_vis"/>
    <texture file="visuals/T_BC001.png" name="Body001_material" type="2d"/>
    <material name="Body001_material" rgba="1 1 1 1.0" texture="Body001_material" shininess="0.4472135901451111" specular="0.3103448502657381"/>
    <texture file="visuals/T_BC001.png" name="Button001_material" type="2d"/>
    <material name="Button001_material" rgba="1 1 1 1.0" texture="Button001_material" shininess="0.4472135901451111" specular="0.3103448502657381"/>
    <texture file="visuals/T_BC001.png" name="Door001_Clear_material" type="2d"/>
    <material name="Door001_Clear_material" rgba="1 1 1 0.75" texture="Door001_Clear_material" shininess="0.4472135901451111" specular="0.3103448502657381"/>
    <texture file="visuals/T_BC001.png" name="Handle001_material" type="2d"/>
    <material name="Handle001_material" rgba="1 1 1 1.0" texture="Handle001_material" shininess="0.4472135901451111" specular="0.3103448502657381"/>
    <texture file="visuals/T_BC001.png" name="Knob001_material" type="2d"/>
    <material name="Knob001_material" rgba="1 1 1 1.0" texture="Knob001_material" shininess="0.4472135901451111" specular="0.3103448502657381"/>
    <texture file="visuals/T_BC001.png" name="Knob002_material" type="2d"/>
    <material name="Knob002_material" rgba="1 1 1 1.0" texture="Knob002_material" shininess="0.4472135901451111" specular="0.3103448502657381"/>
    <texture file="visuals/T_BC001.png" name="Knob003_material" type="2d"/>
    <material name="Knob003_material" rgba="1 1 1 1.0" texture="Knob003_material" shininess="0.4472135901451111" specular="0.3103448502657381"/>
    <texture file="visuals/T_BC001.png" name="Shelf001_material" type="2d"/>
    <material name="Shelf001_material" rgba="1 1 1 1.0" texture="Shelf001_material" shininess="0.4472135901451111" specular="0.3103448502657381"/>
  </asset>
  <default>
    <default class="visual">
      <geom conaffinity="0" contype="0" group="1" type="mesh"/>
    </default>
    <default class="collision">
      <geom group="0" rgba="0.5 0 0 0.5"/>
    </default>
    <default class="spawn">
      <geom group="0" rgba="1 1 1 0.5" contype="0" conaffinity="0"/>
      <site group="0" rgba="1 1 1 0.5"/>
    </default>
    <default class="region">
      <geom group="1" conaffinity="0" contype="0" rgba="0 1 0 0"/>
    </default>
  </default>
  <worldbody>
    <body>
      <body name="object">
        <geom mesh="Body001_vis" type="mesh" solimp="0.998 0.998 0.001" solref="0.001 1" density="100" friction="0.95 0.3 0.1" class="visual" material="Body001_material"/>
        <geom class="collision" type="box" pos="0.001202 0.109214 0.030551" size="0.23925261199474335 0.030078081414103508 0.09976297616958618" quat="1.0 0.0 0.0 0.0"/>
        <geom class="collision" type="box" pos="0.000033 0.005152 -0.081754" size="0.2404221147298813 0.12423568964004517 0.01791861094534397" quat="1.0 0.0 0.0 0.0"/>
        <geom class="collision" type="box" pos="-0.219004 -0.008027 0.022592" size="0.021385671570897102 0.10776318609714508 0.11764828860759735" quat="1.0 0.0 0.0 0.0"/>
        <geom class="collision" type="box" pos="0.000033 0.014681 -0.083406" size="0.2404221147298813 0.12461169064044952 0.013379821553826332" quat="1.0 0.0 0.0 0.0"/>
        <geom class="collision" type="box" pos="-0.220103 0.044475 0.016071" size="0.020286601036787033 0.09481760859489441 0.11285706609487534" quat="1.0 0.0 0.0 0.0"/>
        <geom class="collision" type="box" pos="0.192266 0.011676 0.016071" size="0.047987766563892365 0.10498538613319397 0.11285706609487534" quat="1.0 0.0 0.0 0.0"/>
        <geom class="collision" type="box" pos="0.001202 0.023934 0.117250" size="0.23925261199474335 0.11535798013210297 0.01306379958987236" quat="1.0 0.0 0.0 0.0"/>
        <geom class="collision" type="box" pos="0.213299 0.095819 -0.114809" size="0.011492754332721233 0.023974789306521416 0.015316318720579147" quat="1.0 0.0 0.0 0.0"/>
        <geom class="collision" type="box" pos="-0.213164 0.095819 -0.114809" size="0.011492754332721233 0.023974789306521416 0.015316318720579147" quat="1.0 0.0 0.0 0.0"/>
        <geom class="collision" type="box" pos="-0.213164 -0.065545 -0.114809" size="0.011492754332721233 0.023974789306521416 0.015316318720579147" quat="1.0 0.0 0.0 0.0"/>
        <geom class="collision" type="box" pos="0.213299 -0.065545 -0.114809" size="0.011492754332721233 0.023974789306521416 0.015316318720579147" quat="1.0 0.0 0.0 0.0"/>
        <geom class="collision" type="box" pos="-0.191249 -0.011698 0.012850" size="0.0061254040338099 0.08170703798532486 0.005685448180884123" quat="1.0 0.0 0.0 0.0"/>
        <geom class="collision" type="box" pos="0.137866 -0.012928 -0.009118" size="0.006125274114310741 0.08311451971530914 0.005685448180884123" quat="1.0 0.0 0.0 0.0"/>
        <geom class="collision" type="box" pos="-0.191249 -0.012928 -0.009820" size="0.006125305313616991 0.08311488479375839 0.005685448180884123" quat="1.0 0.0 0.0 0.0"/>
        <geom class="collision" type="box" pos="0.137866 -0.011698 0.014526" size="0.0061254040338099 0.08170703798532486 0.005685448180884123" quat="1.0 0.0 0.0 0.0"/>
        <geom class="collision" type="box" pos="0.224282 -0.091230 0.015080" size="0.013469301164150238 0.01662404090166092 0.11281628906726837" quat="0.9977014064788818 -0.06640700250864029 0.006385390181094408 -0.011886697262525558"/>
        <geom class="collision" type="box" pos="0.155817 -0.092350 0.016177" size="0.010035064071416855 0.01662258617579937 0.11281241476535797" quat="0.9977014064788818 -0.06640700250864029 0.006385390181094408 -0.011886697262525558"/>
        <geom class="collision" type="box" pos="0.185608 -0.103750 -0.077853" size="0.01716957613825798 0.01662403717637062 0.018499847501516342" quat="0.9977014064788818 -0.06640700250864029 0.006385390181094408 -0.011886697262525558"/>
        <body name="Button001">
          <joint axis="0.0 1.0 0.0" pos="0.186019 -0.116662 -0.050943" limited="true" name="Button001_joint" range="0.0 0.002" type="slide" damping="1" frictionloss="1" armature=".01" stiffness="0.05"/>
          <geom mesh="Button001_vis" type="mesh" solimp="0.998 0.998 0.001" solref="0.001 1" density="100" friction="0.95 0.3 0.1" class="visual" material="Button001_material"/>
          <geom class="collision" type="box" pos="0.186001 -0.117074 -0.050914" size="0.015358434058725834 0.0020628010388463736 0.005804631859064102" quat="0.99686199426651 -0.07915915548801422 -1.7576863406535242e-17 -1.5752137258014866e-24"/>
        </body>
        <body name="Door001_Clear">
          <joint axis="1.0 0.0 0.0" pos="-0.026818 -0.108145 -0.063759" limited="true" name="Door001_Clear_joint" range="0.0 1.5707963267948966" type="hinge" damping="1" frictionloss="1" armature=".01" stiffness="0.05"/>
          <geom mesh="Door001_Clear_vis" type="mesh" solimp="0.998 0.998 0.001" solref="0.001 1" density="100" friction="0.95 0.3 0.1" class="visual" material="Door001_Clear_material"/>
          <geom class="collision" type="box" pos="-0.026549 -0.098230 0.020423" size="0.1632433533668518 0.0019640049431473017 0.08078492432832718" quat="0.9979764223098755 -0.06358522176742554 -1.4118755446418504e-17 -1.202521814548543e-24"/>
          <body name="Handle001">
            <geom mesh="Handle001_vis" type="mesh" solimp="0.998 0.998 0.001" solref="0.001 1" density="100" friction="0.95 0.3 0.1" class="visual" material="Handle001_material"/>
            <geom class="collision" type="box" pos="0.121343 -0.114045 0.094563" size="0.021890953183174133 0.025094499811530113 0.011600500904023647" quat="0.9967019557952881 -0.08114931732416153 -1.8018744944122294e-17 -4.9555610977259785e-24"/>
            <geom class="collision" type="box" pos="-0.027549 -0.127582 0.096782" size="0.13131047785282135 0.011377752758562565 0.013575291261076927" quat="0.9967019557952881 -0.08114931732416153 -1.8018744944122294e-17 -4.9555610977259785e-24"/>
            <geom class="collision" type="box" pos="-0.174868 -0.114045 0.094563" size="0.02161538600921631 0.025094501674175262 0.011225162073969841" quat="0.9965037703514099 -0.0835433155298233 -0.0006798804388381541 0.0005293409340083599"/>
            <geom class="collision" type="box" pos="-0.023265 -0.094079 0.089710" size="0.13216720521450043 0.0046061924658715725 0.013575291261076927" quat="0.9967019557952881 -0.08114931732416153 -1.8018744944122294e-17 -4.9555610977259785e-24"/>
          </body>
        </body>
        <body name="Knob001">
          <joint axis="0.0 0.9903785586357117 -0.1383843868970871" pos="0.187598 -0.100167 0.083003" limited="true" name="Knob001_joint" range="0.0 4.1887902047863905" type="hinge" damping="0.05" armature="0.001"/>
          <geom mesh="Knob001_vis" type="mesh" solimp="0.998 0.998 0.001" solref="0.001 1" density="100" friction="0.95 0.3 0.1" class="visual" material="Knob001_material"/>
          <geom class="collision" type="cylinder" pos="0.187114 -0.101106 0.083056" size="0.01513941865414381 0.004578040447086096" quat="0.7660444378852844 0.6427876353263855 0.0 0.0"/>
        </body>
        <body name="Knob002">
          <joint axis="0.0 0.9849876165390015 -0.17262469232082367" pos="0.185821 -0.108023 0.032782" limited="true" name="Knob002_joint" range="0.0 5.235987755982989" type="hinge" damping="0.05" armature="0.001"/>
          <geom mesh="Knob002_vis" type="mesh" solimp="0.998 0.998 0.001" solref="0.001 1" density="100" friction="0.95 0.3 0.1" class="visual" material="Knob002_material"/>
          <geom class="collision" type="cylinder" pos="0.186401 -0.109541 0.032692" size="0.015245648100972176 0.004331246949732304" quat="0.7660444378852844 0.6427876353263855 0.0 0.0"/>
        </body>
        <body name="Knob003">
          <joint axis="0.0 1.0 0.0" pos="0.186864 -0.112894 -0.018078" limited="true" name="Knob003_joint" range="0.0 5.759586531581287" type="hinge" damping="0.05" armature="0.001"/>
          <geom mesh="Knob003_vis" type="mesh" solimp="0.998 0.998 0.001" solref="0.001 1" density="100" friction="0.95 0.3 0.1" class="visual" material="Knob003_material"/>
          <geom class="collision" type="cylinder" pos="0.187070 -0.115289 -0.018285" size="0.015245648100972176 0.004331246949732304" quat="0.7660444378852844 0.6427876353263855 0.0 0.0"/>
        </body>
        <body name="Shelf001">
          <joint axis="0.0 -1.0 0.0" pos="-0.027334 -0.010218 0.002174" limited="true" name="Shelf001_joint" range="0.0 0.12" type="slide" damping="1" frictionloss="1" armature=".01" stiffness="0.05"/>
          <geom mesh="Shelf001_vis" type="mesh" solimp="0.998 0.998 0.001" solref="0.001 1" density="100" friction="0.95 0.3 0.1" class="visual" material="Shelf001_material"/>
          <geom class="collision" type="box" pos="-0.026799 -0.010615 0.002457" size="0.16731858253479004 0.08346723020076752 0.00440177833661437" quat="1.0 0.0 0.0 0.0"/>
        </body>
        <geom class="region" name="reg_main" type="box" pos="0.0 0.0096165 0.0" size="0.240111 0.1290725 0.130151"/>
        <geom class="region" name="reg_int" type="box" pos="-0.026895500000000003 -0.003342500000000005 0.023198499999999997" size="0.16791050000000002 0.07847950000000001 0.0778335"/>
      </body>
    </body>
  </worldbody>
  <actuator>
    <motor name="Button001_joint_actuator" joint="Button001_joint" gear="0.5"/>
    <motor name="Door001_Clear_joint_actuator" joint="Door001_Clear_joint" gear="50"/>
    <motor name="Knob001_joint_actuator" joint="Knob001_joint" gear="50"/>
    <motor name="Knob002_joint_actuator" joint="Knob002_joint" gear="50"/>
    <motor name="Knob003_joint_actuator" joint="Knob003_joint" gear="50"/>
    <motor name="Shelf001_joint_actuator" joint="Shelf001_joint" gear="50"/>
  </actuator>
</mujoco>
