<mujoco model="model">
  <compiler angle="radian"/>
  <asset>
    <mesh file="visuals/Body001.obj" name="Body001_vis"/>
    <mesh file="visuals/Body001_Clear.obj" name="Body001_Clear_vis"/>
    <mesh file="visuals/Door001.obj" name="Door001_vis"/>
    <mesh file="visuals/Door001_Clear.obj" name="Door001_Clear_vis"/>
    <mesh file="visuals/Drawer001.obj" name="Drawer001_vis"/>
    <mesh file="visuals/Drawer002.obj" name="Drawer002_vis"/>
    <mesh file="visuals/Drawer003.obj" name="Drawer003_vis"/>
    <texture file="visuals/T_BC001.png" name="Body001_material" type="2d"/>
    <material name="Body001_material" rgba="1 1 1 1.0" texture="Body001_material" shininess="0.4472135901451111" specular="1"/>
    <texture file="visuals/T_BC001.png" name="Body001_Clear_material" type="2d"/>
    <material name="Body001_Clear_material" rgba="1 1 1 0.4411303400993347" texture="Body001_Clear_material" shininess="0.5" specular="0.3103448502657381"/>
    <texture file="visuals/T_BC001.png" name="Door001_material" type="2d"/>
    <material name="Door001_material" rgba="1 1 1 1.0" texture="Door001_material" shininess="0.4472135901451111" specular="1"/>
    <texture file="visuals/T_BC001.png" name="Door001_Clear_material" type="2d"/>
    <material name="Door001_Clear_material" rgba="1 1 1 0.4411303400993347" texture="Door001_Clear_material" shininess="0.5" specular="0.3103448502657381"/>
    <texture file="visuals/T_BC001.png" name="Drawer001_material" type="2d"/>
    <material name="Drawer001_material" rgba="1 1 1 1.0" texture="Drawer001_material" shininess="0.4472135901451111" specular="0.3103448502657381"/>
    <texture file="visuals/T_BC001.png" name="Drawer002_material" type="2d"/>
    <material name="Drawer002_material" rgba="1 1 1 1.0" texture="Drawer002_material" shininess="0.4472135901451111" specular="0.3103448502657381"/>
    <texture file="visuals/T_BC001.png" name="Drawer003_material" type="2d"/>
    <material name="Drawer003_material" rgba="1 1 1 1.0" texture="Drawer003_material" shininess="0.4472135901451111" specular="1"/>
  </asset>
  <default>
    <default class="visual">
      <geom conaffinity="0" contype="0" group="1" type="mesh"/>
    </default>
    <default class="collision">
      <geom group="0" rgba="0.5 0 0 0.5"/>
    </default>
    <default class="spawn">
      <geom group="0" rgba="1 1 1 0.5" contype="0" conaffinity="0"/>
      <site group="0" rgba="1 1 1 0.5"/>
    </default>
    <default class="region">
      <geom group="1" conaffinity="0" contype="0" rgba="0 1 0 0"/>
    </default>
  </default>
  <worldbody>
    <body>
      <body name="object">
        <geom mesh="Body001_vis" type="mesh" solimp="0.998 0.998 0.001" solref="0.001 1" density="100" friction="0.95 0.3 0.1" class="visual" material="Body001_material"/>
        <geom class="collision" type="box" pos="-0.00028220959939062595 0.046065088361501694 -0.8849540948867798" size="0.4174952507019043 0.40577802062034607 0.048721931874752045" quat="1.0 0.0 0.0 0.0"/>
        <geom class="collision" type="box" pos="-0.3892420828342438 0.0463176891207695 0.0472198948264122" size="0.0285353846848011 0.4055253565311432 0.8854473829269409" quat="1.0 0.0 0.0 0.0"/>
        <geom class="collision" type="box" pos="-0.014195600524544716 0.04606311395764351 0.8895912766456604" size="0.34721803665161133 0.40577998757362366 0.043075814843177795" quat="1.0 0.0 0.0 0.0"/>
        <geom class="collision" type="box" pos="0.3752589225769043 0.04562413692474365 0.04722072184085846" size="0.04195408895611763 0.40621891617774963 0.8854464292526245" quat="1.0 0.0 0.0 0.0"/>
        <geom class="collision" type="box" pos="-0.014991133473813534 0.32848867774009705 0.006801291834563017" size="0.3463194668292999 0.12335442006587982 0.8450056314468384" quat="1.0 0.0 0.0 0.0"/>
        <geom class="collision" type="box" pos="-0.014195600524544716 -0.02551545947790146 -0.22356769442558289" size="0.34721803665161133 0.32394760847091675 0.030765503644943237" quat="1.0 0.0 0.0 0.0"/>
        <body name="Body001_Clear">
          <geom mesh="Body001_Clear_vis" type="mesh" solimp="0.998 0.998 0.001" solref="0.001 1" density="100" friction="0.95 0.3 0.1" class="visual" material="Body001_Clear_material"/>
          <geom class="collision" type="box" pos="-0.009869547560811043 -0.040154919028282166 0.5256437063217163" size="0.34337595105171204 0.2510439455509186 0.0007182847475633025" quat="1.0 0.0 0.0 0.0"/>
          <geom class="collision" type="box" pos="-0.009583763778209686 -0.05967281386256218 0.21403063833713531" size="0.34366172552108765 0.26773449778556824 0.0007899237680248916" quat="1.0 0.0 0.0 0.0"/>
        </body>
        <body name="Door001">
          <joint axis="0.0 0.0 1.0" pos="0.398270845413208 -0.39148035645484924 0.357952356338501" limited="true" name="Door001_joint" range="0.0 1.5707963267948966" type="hinge" damping="1" frictionloss="1" armature=".01" stiffness="0.05"/>
          <geom mesh="Door001_vis" type="mesh" solimp="0.998 0.998 0.001" solref="0.001 1" density="100" friction="0.95 0.3 0.1" class="visual" material="Door001_material"/>
          <geom class="collision" type="box" pos="0.0006382146384567022 -0.3950631320476532 0.3596794009208679" size="0.4184156656265259 0.01681710220873356 0.5777788162231445" quat="1.0 0.0 0.0 0.0"/>
          <geom class="collision" type="box" pos="-0.3326978087425232 -0.4237545430660248 0.7210708856582642" size="0.017770806327462196 0.01319112442433834 0.02116990089416504" quat="1.0 0.0 0.0 0.0"/>
          <geom class="collision" type="box" pos="-0.3332245945930481 -0.44065728783607483 0.2762830853462219" size="0.021486591547727585 0.01143124233931303 0.4793464243412018" quat="1.0 0.0 0.0 0.0"/>
          <geom class="collision" type="box" pos="-0.3326978087425232 -0.4237545430660248 -0.1627090871334076" size="0.017770806327462196 0.01319084595888853 0.02116990089416504" quat="1.0 0.0 0.0 0.0"/>
          <geom class="collision" type="box" pos="-0.01318422518670559 -0.35715028643608093 0.840620756149292" size="0.34219425916671753 0.023262569680809975 0.004276500083506107" quat="1.0 0.0 0.0 0.0"/>
          <geom class="collision" type="box" pos="0.3195115029811859 -0.35715028643608093 0.4454904794692993" size="0.009498503990471363 0.023262569680809975 0.39117616415023804" quat="1.0 0.0 0.0 0.0"/>
          <geom class="collision" type="box" pos="-0.3373781442642212 -0.35715028643608093 0.4454904794692993" size="0.016009612008929253 0.023262571543455124 0.39117616415023804" quat="1.0 0.0 0.0 0.0"/>
          <body name="Door001_Clear">
            <geom mesh="Door001_Clear_vis" type="mesh" solimp="0.998 0.998 0.001" solref="0.001 1" density="100" friction="0.95 0.3 0.1" class="visual" material="Door001_Clear_material"/>
            <geom class="collision" type="box" pos="-0.3035118579864502 -0.3609536588191986 0.1288968026638031" size="0.003228553105145693 0.011789285577833652 0.059241604059934616" quat="1.0 0.0 0.0 0.0"/>
            <geom class="collision" type="box" pos="-0.0008189299842342734 -0.3415113389492035 0.13031218945980072" size="0.301035076379776 0.0039555649273097515 0.06320180743932724" quat="1.0 0.0 0.0 0.0"/>
            <geom class="collision" type="box" pos="0.30434656143188477 -0.35811498761177063 0.12843604385852814" size="0.0020166372414678335 0.020167620852589607 0.058914560824632645" quat="1.0 0.0 0.0 0.0"/>
            <geom class="collision" type="box" pos="-0.0010958004277199507 -0.3632794916629791 0.0617678165435791" size="0.301297664642334 0.014990507625043392 0.004100287798792124" quat="1.0 0.0 0.0 0.0"/>
            <geom class="collision" type="box" pos="0.0006768889725208282 -0.3464416563510895 0.3771534860134125" size="0.2995249629020691 0.014958427287638187 0.0021699205972254276" quat="1.0 0.0 0.0 0.0"/>
            <geom class="collision" type="box" pos="0.3041929602622986 -0.3431452214717865 0.41270139813423157" size="0.002170219086110592 0.012792040593922138 0.029203588142991066" quat="1.0 0.0 0.0 0.0"/>
            <geom class="collision" type="box" pos="0.00023628940107300878 -0.3249150812625885 0.4143744111061096" size="0.2999781370162964 0.0050478107295930386 0.027853142470121384" quat="1.0 0.0 0.0 0.0"/>
            <geom class="collision" type="box" pos="-0.3053753972053528 -0.3468959629535675 0.41161346435546875" size="0.0013649907195940614 0.01509031094610691 0.028536992147564888" quat="1.0 0.0 0.0 0.0"/>
            <geom class="collision" type="box" pos="-0.3035118579864502 -0.34567341208457947 0.5358172655105591" size="0.0032285209745168686 0.014797506853938103 0.029959529638290405" quat="1.0 0.0 0.0 0.0"/>
            <geom class="collision" type="box" pos="0.0007004301296547055 -0.3274819552898407 0.5373093485832214" size="0.29951298236846924 0.0037087812088429928 0.029826143756508827" quat="1.0 0.0 0.0 0.0"/>
            <geom class="collision" type="box" pos="0.30440574884414673 -0.3509902060031891 0.5287048816680908" size="0.0019574060570448637 0.011457794345915318 0.03615258261561394" quat="1.0 0.0 0.0 0.0"/>
            <geom class="collision" type="box" pos="0.0013456159504130483 -0.35078075528144836 0.5021404027938843" size="0.2988562285900116 0.014763807877898216 0.0041002850048244" quat="1.0 0.0 0.0 0.0"/>
            <geom class="collision" type="box" pos="-0.00013862716150470078 -0.33811357617378235 0.6366299390792847" size="0.300340473651886 0.022642824798822403 0.0015565496869385242" quat="1.0 0.0 0.0 0.0"/>
            <geom class="collision" type="box" pos="0.3044595718383789 -0.34080877900123596 0.6812611222267151" size="0.0019036070443689823 0.019667141139507294 0.041286613792181015" quat="1.0 0.0 0.0 0.0"/>
            <geom class="collision" type="box" pos="-0.0001229922636412084 -0.31280675530433655 0.6845166683197021" size="0.3003346920013428 0.004460365977138281 0.03835388273000717" quat="1.0 0.0 0.0 0.0"/>
            <geom class="collision" type="box" pos="-0.3035118579864502 -0.3385394513607025 0.6774614453315735" size="0.003228538203984499 0.017397744581103325 0.04565775394439697" quat="1.0 0.0 0.0 0.0"/>
          </body>
        </body>
        <body name="Drawer001">
          <joint axis="0.0 -1.0 0.0" pos="-0.01722750999033451 -0.06104498356580734 0.10283555090427399" limited="true" name="Drawer001_joint" range="0.0 0.4" type="slide" damping="1" frictionloss="1" armature=".01" stiffness="0.05"/>
          <geom mesh="Drawer001_vis" type="mesh" solimp="0.998 0.998 0.001" solref="0.001 1" density="100" friction="0.95 0.3 0.1" class="visual" material="Drawer001_material"/>
          <geom class="collision" type="box" pos="-0.3300918936729431 -0.03274644911289215 0.10766411572694778" size="0.012271959334611893 0.21677258610725403 0.08815472573041916" quat="1.0 0.0 0.0 0.0"/>
          <geom class="collision" type="box" pos="0.2944066524505615 -0.03485676646232605 0.10750240832567215" size="0.012768152169883251 0.2197364717721939 0.08799302577972412" quat="1.0 0.0 0.0 0.0"/>
          <geom class="collision" type="box" pos="-0.016805533319711685 0.19075459241867065 0.10831139236688614" size="0.31907016038894653 0.0028994481544941664 0.08880159258842468" quat="1.0 0.0 0.0 0.0"/>
          <geom class="collision" type="box" pos="-0.019166722893714905 -0.2574569284915924 0.10762117058038712" size="0.3196590542793274 0.0070279669016599655 0.0881117731332779" quat="1.0 0.0 0.0 0.0"/>
          <geom class="collision" type="box" pos="-0.020612698048353195 -0.033869437873363495 0.010581914335489273" size="0.29958799481391907 0.22204646468162537 0.0024576352443546057" quat="1.0 0.0 0.0 0.0"/>
          <geom class="collision" type="box" pos="0.1829824298620224 -0.27968233823776245 0.18143442273139954" size="0.11831755191087723 0.008652029559016228 0.014979681000113487" quat="0.9945970773696899 0.0 0.0 0.10381060838699341"/>
          <geom class="collision" type="box" pos="-0.22086118161678314 -0.2785322666168213 0.18143442273139954" size="0.11387142539024353 0.008652029559016228 0.014979681000113487" quat="0.99354088306427 0.0 -0.0 -0.11347470432519913"/>
          <geom class="collision" type="box" pos="-0.02271162159740925 -0.3040718138217926 0.18143442273139954" size="0.09203242510557175 0.008652029559016228 0.014979681000113487" quat="1.0 0.0 0.0 0.0"/>
        </body>
        <body name="Drawer002">
          <joint axis="0.0 -1.0 0.0" pos="-0.01722750999033451 -0.06281699240207672 -0.09212801605463028" limited="true" name="Drawer002_joint" range="0.0 0.4" type="slide" damping="1" frictionloss="1" armature=".01" stiffness="0.05"/>
          <geom mesh="Drawer002_vis" type="mesh" solimp="0.998 0.998 0.001" solref="0.001 1" density="100" friction="0.95 0.3 0.1" class="visual" material="Drawer002_material"/>
          <geom class="collision" type="box" pos="-0.3300918936729431 -0.03469010442495346 -0.08874400705099106" size="0.01227185782045126 0.2160429060459137 0.08815417438745499" quat="1.0 0.0 0.0 0.0"/>
          <geom class="collision" type="box" pos="0.2944066524505615 -0.03688087314367294 -0.0889057144522667" size="0.012768056243658066 0.21911968290805817 0.08799250423908234" quat="1.0 0.0 0.0 0.0"/>
          <geom class="collision" type="box" pos="-0.016805533319711685 0.18833434581756592 -0.0880967304110527" size="0.3190721869468689 0.0030099789146333933 0.08880262821912766" quat="1.0 0.0 0.0 0.0"/>
          <geom class="collision" type="box" pos="-0.019166722893714905 -0.25897011160850525 -0.08878696709871292" size="0.31965428590774536 0.007295942399650812 0.0881110280752182" quat="1.0 0.0 0.0 0.0"/>
          <geom class="collision" type="box" pos="-0.020612698048353195 -0.035855911672115326 -0.18582621216773987" size="0.2995855212211609 0.22151002287864685 0.0024576119612902403" quat="1.0 0.0 0.0 0.0"/>
          <geom class="collision" type="box" pos="-0.021015210077166557 -0.30426040291786194 -0.012694921344518661" size="0.09203242510557175 0.008652027696371078 0.014979681000113487" quat="1.0 0.0 0.0 0.0"/>
          <geom class="collision" type="box" pos="-0.21916477382183075 -0.27872082591056824 -0.012694921344518661" size="0.11387142539024353 0.008652029559016228 0.014979681000113487" quat="0.99354088306427 0.0 -0.0 -0.11347470432519913"/>
          <geom class="collision" type="box" pos="0.1846788376569748 -0.2798709273338318 -0.012694921344518661" size="0.11831755191087723 0.008652027696371078 0.014979681000113487" quat="0.9945970773696899 0.0 0.0 0.10381060838699341"/>
        </body>
        <body name="Drawer003">
          <joint axis="0.0 -1.0 0.0" pos="8.940696716308594e-08 -0.1895536482334137 -0.5760611891746521" limited="true" name="Drawer003_joint" range="0.0 0.4" type="slide" damping="1" frictionloss="1" armature=".01" stiffness="0.05"/>
          <geom mesh="Drawer003_vis" type="mesh" solimp="0.998 0.998 0.001" solref="0.001 1" density="100" friction="0.95 0.3 0.1" class="visual" material="Drawer003_material"/>
          <geom class="collision" type="box" pos="0.0003351327031850815 -0.3912123739719391 -0.5759356617927551" size="0.4179703891277313 0.019580064341425896 0.34442299604415894" quat="1.0 0.0 0.0 0.0"/>
          <geom class="collision" type="box" pos="-0.3456881642341614 -0.423907071352005 -0.2831193506717682" size="0.02116990275681019 0.013190827332437038 0.017770808190107346" quat="1.0 0.0 0.0 0.0"/>
          <geom class="collision" type="box" pos="0.00203077495098114 -0.44080981612205505 -0.2825925648212433" size="0.39828863739967346 0.01143124233931303 0.02148660458624363" quat="1.0 0.0 0.0 0.0"/>
          <geom class="collision" type="box" pos="0.3575775623321533 -0.423907071352005 -0.2831193506717682" size="0.02116990275681019 0.013190790079534054 0.017770808190107346" quat="1.0 0.0 0.0 0.0"/>
          <geom class="collision" type="box" pos="0.3081456422805786 -0.08935493230819702 -0.6066580414772034" size="0.012117437086999416 0.26494473218917847 0.22165796160697937" quat="1.0 0.0 0.0 0.0"/>
          <geom class="collision" type="box" pos="-0.32881656289100647 -0.08935493230819702 -0.6066580414772034" size="0.012117435224354267 0.26494473218917847 0.22165796160697937" quat="1.0 0.0 0.0 0.0"/>
          <geom class="collision" type="box" pos="-0.009681074880063534 0.16568218171596527 -0.6066580414772034" size="0.306090384721756 0.009798376820981503 0.22165796160697937" quat="1.0 0.0 0.0 0.0"/>
          <geom class="collision" type="box" pos="-0.009681080467998981 -0.09938091784715652 -0.8112134337425232" size="0.306090384721756 0.2548059821128845 0.017102576792240143" quat="1.0 0.0 0.0 0.0"/>
          <geom class="collision" type="box" pos="-0.013841669075191021 -0.3630203902721405 -0.5440488457679749" size="0.34341034293174744 0.010004036128520966 0.28850358724594116" quat="1.0 0.0 0.0 0.0"/>
        </body>
        <geom class="region" name="reg_main" type="box" pos="1.4901161193847656e-08 0.02136211469769478 -5.960464477539063e-08" size="0.4184049665927887 0.4304814040660858 0.9336766600608826"/>
      </body>
    </body>
  </worldbody>
  <actuator>
    <motor name="Door001_joint_actuator" joint="Door001_joint" gear="50"/>
    <motor name="Drawer001_joint_actuator" joint="Drawer001_joint" gear="50"/>
    <motor name="Drawer002_joint_actuator" joint="Drawer002_joint" gear="50"/>
    <motor name="Drawer003_joint_actuator" joint="Drawer003_joint" gear="50"/>
  </actuator>
</mujoco>
