<?xml version='1.0' encoding='UTF-8'?>
<mujoco model="model">
  <compiler angle="radian"/>
  <asset>
    <mesh file="visuals/knob_center.obj" name="knob_center_vis"/>
    <mesh file="visuals/knob_front_left.obj" name="knob_front_left_vis"/>
    <mesh file="visuals/knob_front_right.obj" name="knob_front_right_vis"/>
    <mesh file="visuals/knob_rear_left.obj" name="knob_rear_left_vis"/>
    <mesh file="visuals/knob_rear_right.obj" name="knob_rear_right_vis"/>
    <mesh file="visuals/Body001.obj" name="Body001_vis"/>
    <mesh file="visuals/Body002.obj" name="Body002_vis"/>
    <texture file="visuals/T_BC001.png" name="Body001_material" type="2d"/>
    <material name="Body001_material" rgba="1 1 1 1.0" texture="Body001_material" shininess="0.4472135901451111" specular="3"/>
    <texture file="visuals/T_BC001.png" name="knob_center_material" type="2d"/>
    <material name="knob_center_material" rgba="1 1 1 1.0" texture="knob_center_material" shininess="0.4472135901451111" specular="1"/>
    <texture file="visuals/T_BC001.png" name="knob_front_left_material" type="2d"/>
    <material name="knob_front_left_material" rgba="1 1 1 1.0" texture="knob_front_left_material" shininess="0.4472135901451111" specular="1"/>
    <texture file="visuals/T_BC001.png" name="knob_front_right_material" type="2d"/>
    <material name="knob_front_right_material" rgba="1 1 1 1.0" texture="knob_front_right_material" shininess="0.4472135901451111" specular="1"/>
    <texture file="visuals/T_BC001.png" name="knob_rear_left_material" type="2d"/>
    <material name="knob_rear_left_material" rgba="1 1 1 1.0" texture="knob_rear_left_material" shininess="0.4472135901451111" specular="1"/>
    <texture file="visuals/T_BC001.png" name="knob_rear_right_material" type="2d"/>
    <material name="knob_rear_right_material" rgba="1 1 1 1.0" texture="knob_rear_right_material" shininess="0.4472135901451111" specular="1"/>
    <texture file="visuals/T_BC001.png" name="Body002_material" type="2d"/>
    <material name="Body002_material" rgba="1 1 1 1.0" texture="Body002_material" shininess="0.4472135901451111" specular="5"/>
  </asset>
  <default>
    <default class="visual">
      <geom conaffinity="0" contype="0" group="1" type="mesh"/>
    </default>
    <default class="collision">
      <geom group="0" rgba="0.5 0 0 0.5"/>
    </default>
    <default class="spawn">
      <geom group="0" rgba="1 1 1 0.5" contype="0" conaffinity="0"/>
      <site group="0" rgba="1 1 1 0.5"/>
    </default>
    <default class="region">
      <geom group="1" conaffinity="0" contype="0" rgba="0 1 0 0"/>
    </default>
  </default>
  <worldbody>
    <body>
      <body name="object">
        <site type="cylinder" rgba="0.3 0.4 1 0.5" size="0.03971847891807556 0.0026724718045443296" pos="0.000282 0.050622 0.004721" name="burner_on_center"/>
        <site type="cylinder" rgba="0.3 0.4 1 0.5" size="0.02907802164554596 0.0028289109468460083" pos="-0.229425 -0.066910 -0.002340" name="burner_on_front_left"/>
        <site type="cylinder" rgba="0.3 0.4 1 0.5" size="0.02907802164554596 0.0022845834027975798" pos="-0.229425 0.089983 -0.002580" name="burner_on_rear_left"/>
        <site type="cylinder" rgba="0.3 0.4 1 0.5" size="0.022008158266544342 0.0015378475654870272" pos="0.228963 0.089780 -0.006863" name="burner_on_rear_right"/>
        <site type="cylinder" rgba="0.3 0.4 1 0.5" size="0.03311452642083168 0.0023280151654034853" pos="0.229166 -0.066910 -0.001730" name="burner_on_front_right"/>
        <geom mesh="Body001_vis" type="mesh" solimp="0.998 0.998 0.001" solref="0.001 1" density="100" friction="0.95 0.3 0.1" class="visual" material="Body001_material"/>
        <geom class="collision" type="box" pos="-0.288136 -0.166382 0.005370" size="0.0751245766878128 0.04443773999810219 0.0019045202061533928" quat="1.0 0.0 0.0 0.0"/>
        <geom class="collision" type="box" pos="0.289992 -0.167471 0.005331" size="0.07326879352331161 0.04469894990324974 0.0019430917454883456" quat="1.0 0.0 0.0 0.0"/>
        <geom class="collision" type="box" pos="0.001065 -0.004342 -0.011048" size="0.3523796498775482 0.20782798528671265 0.017709948122501373" quat="1.0 0.0 0.0 0.0"/>
        <geom class="collision" type="box" pos="0.146121 -0.187612 0.005668" size="0.024549225345253944 0.024557819589972496 0.001606714678928256" quat="1.0 0.0 0.0 0.0"/>
        <geom class="collision" type="box" pos="0.052259 -0.187612 0.005668" size="0.024549225345253944 0.024557825177907944 0.0016066848766058683" quat="1.0 0.0 0.0 0.0"/>
        <geom class="collision" type="box" pos="-0.042845 -0.187612 0.005668" size="0.025561736896634102 0.02455783076584339 0.0016066852258518338" quat="1.0 0.0 0.0 0.0"/>
        <geom class="collision" type="box" pos="-0.140434 -0.187612 0.005668" size="0.027516139671206474 0.02455807849764824 0.001606715377420187" quat="1.0 0.0 0.0 0.0"/>
        <geom class="collision" type="box" pos="-0.000542 -0.143056 0.006360" size="0.21817293763160706 0.021450063213706017 0.0009147481177933514" quat="1.0 0.0 0.0 0.0"/>
        <body name="knob_center">
          <joint axis="0.0 0.0 1.0" pos="0.004111 -0.187591 0.014754" limited="true" name="knob_center_joint" range="0.0 3.490658503988659" type="hinge" damping="0.05" armature="0.001"/>
          <geom mesh="knob_center_vis" type="mesh" solimp="0.998 0.998 0.001" solref="0.001 1" density="100" friction="0.95 0.3 0.1" class="visual" material="knob_center_material"/>
          <geom class="collision" type="cylinder" pos="0.004803 -0.187583 0.010908" size="0.019496535882353783 0.002368065295740962" quat="1.0 0.0 0.0 0.0"/>
          <geom class="collision" type="box" pos="0.004798 -0.187072 0.020896" size="0.0055315857753157616 0.018967404961586 0.007450352888554335" quat="1.0 0.0 0.0 0.0"/>
        </body>
        <body name="knob_front_left">
          <joint axis="0.0 0.0 1.0" pos="-0.189641 -0.187624 0.014760" limited="true" name="knob_front_left_joint" range="0.0 3.490658503988659" type="hinge" damping="0.05" armature="0.001"/>
          <geom mesh="knob_front_left_vis" type="mesh" solimp="0.998 0.998 0.001" solref="0.001 1" density="100" friction="0.95 0.3 0.1" class="visual" material="knob_front_left_material"/>
          <geom class="collision" type="cylinder" pos="-0.190240 -0.187735 0.010743" size="0.020140523090958595 0.002446284517645836" quat="1.0 0.0 0.0 0.0"/>
          <geom class="collision" type="box" pos="-0.190196 -0.187508 0.021061" size="0.005714252591133118 0.019593756645917892 0.007696310058236122" quat="1.0 0.0 0.0 0.0"/>
        </body>
        <body name="knob_front_right">
          <joint axis="0.0 0.0 1.0" pos="0.192704 -0.187533 0.014751" limited="true" name="knob_front_right_joint" range="0.0 3.490658503988659" type="hinge" damping="0.05" armature="0.001"/>
          <geom mesh="knob_front_right_vis" type="mesh" solimp="0.998 0.998 0.001" solref="0.001 1" density="100" friction="0.95 0.3 0.1" class="visual" material="knob_front_right_material"/>
          <geom class="collision" type="cylinder" pos="0.192672 -0.187421 0.010902" size="0.019521916285157204 0.0023711479734629393" quat="1.0 0.0 0.0 0.0"/>
          <geom class="collision" type="box" pos="0.193185 -0.187498 0.020903" size="0.0055387429893016815 0.018991945311427116 0.007459922228008509" quat="1.0 0.0 0.0 0.0"/>
        </body>
        <body name="knob_rear_left">
          <joint axis="0.0 0.0 1.0" pos="-0.089955 -0.187549 0.014752" limited="true" name="knob_rear_left_joint" range="0.0 3.490658503988659" type="hinge" damping="0.05" armature="0.001"/>
          <geom mesh="knob_rear_left_vis" type="mesh" solimp="0.998 0.998 0.001" solref="0.001 1" density="100" friction="0.95 0.3 0.1" class="visual" material="knob_rear_left_material"/>
          <geom class="collision" type="cylinder" pos="-0.089811 -0.187208 0.010834" size="0.019788820296525955 0.0024035663809627295" quat="1.0 0.0 0.0 0.0"/>
          <geom class="collision" type="box" pos="-0.089852 -0.187194 0.020971" size="0.005614469293504953 0.019251607358455658 0.0075619155541062355" quat="1.0 0.0 0.0 0.0"/>
        </body>
        <body name="knob_rear_right">
          <joint axis="0.0 0.0 1.0" pos="0.098888 -0.187509 0.014753" limited="true" name="knob_rear_right_joint" range="0.0 3.490658503988659" type="hinge" damping="0.05" armature="0.001"/>
          <geom mesh="knob_rear_right_vis" type="mesh" solimp="0.998 0.998 0.001" solref="0.001 1" density="100" friction="0.95 0.3 0.1" class="visual" material="knob_rear_right_material"/>
          <geom class="collision" type="cylinder" pos="0.099014 -0.187288 0.010915" size="0.019472436979413033 0.0023651381488889456" quat="1.0 0.0 0.0 0.0"/>
          <geom class="collision" type="box" pos="0.099159 -0.187447 0.020890" size="0.005524749401956797 0.01894395798444748 0.007441017311066389" quat="1.0 0.0 0.0 0.0"/>
        </body>
        <body name="Body002">
          <geom mesh="Body002_vis" type="mesh" solimp="0.998 0.998 0.001" solref="0.001 1" density="100" friction="0.95 0.3 0.1" class="visual" material="Body002_material"/>
        </body>
        <geom class="region" name="reg_main" type="box" pos="0.0 5.000000000005e-07 -0.0107415" size="0.36326 0.21217049999999998 0.018016499999999998"/>
      </body>
    </body>
  </worldbody>
  <actuator>
    <motor name="knob_center_joint_actuator" joint="knob_center_joint" gear="10"/>
    <motor name="knob_front_left_joint_actuator" joint="knob_front_left_joint" gear="10"/>
    <motor name="knob_front_right_joint_actuator" joint="knob_front_right_joint" gear="10"/>
    <motor name="knob_rear_left_joint_actuator" joint="knob_rear_left_joint" gear="10"/>
    <motor name="knob_rear_right_joint_actuator" joint="knob_rear_right_joint" gear="10"/>
  </actuator>
</mujoco>
