<mujoco model="model">
  <compiler angle="radian"/>
  <asset>
    <mesh file="visuals/handle.obj" name="handle_vis"/>
    <mesh file="visuals/Body001.obj" name="Body001_vis"/>
    <mesh file="visuals/Funnel001.obj" name="Funnel001_vis"/>
    <mesh file="visuals/Funnel002.obj" name="Funnel002_vis"/>
    <mesh file="visuals/spout.obj" name="spout_vis"/>
    <texture file="visuals/T_BC001.png" name="Body001_material" type="2d"/>
    <material name="Body001_material" rgba="1 1 1 1.0" texture="Body001_material" shininess="0.4472135901451111" specular="0.7"/>
    <texture file="visuals/T_BC001.png" name="handle_material" type="2d"/>
    <material name="handle_material" rgba="1 1 1 1.0" texture="handle_material" shininess="0.4472135901451111" specular="0.7"/>
    <texture file="visuals/T_BC001.png" name="Funnel001_material" type="2d"/>
    <material name="Funnel001_material" rgba="1 1 1 1.0" texture="Funnel001_material" shininess="0.4472135901451111" specular="0.7"/>
    <texture file="visuals/T_BC001.png" name="Funnel002_material" type="2d"/>
    <material name="Funnel002_material" rgba="1 1 1 1.0" texture="Funnel002_material" shininess="0.4472135901451111" specular="0.7"/>
    <texture file="visuals/T_BC001.png" name="spout_material" type="2d"/>
    <material name="spout_material" rgba="1 1 1 1.0" texture="spout_material" shininess="0.4472135901451111" specular="0.7"/>
  </asset>
  <default>
    <default class="visual">
      <geom conaffinity="0" contype="0" group="1" type="mesh"/>
    </default>
    <default class="collision">
      <geom group="0" rgba="0.5 0 0 0.5"/>
    </default>
    <default class="spawn">
      <geom group="0" rgba="1 1 1 0.5" contype="0" conaffinity="0"/>
      <site group="0" rgba="1 1 1 0.5"/>
    </default>
    <default class="region">
      <geom group="1" conaffinity="0" contype="0" rgba="0 1 0 0"/>
    </default>
  </default>
  <worldbody>
    <body>
      <body name="object">
        <geom mesh="Body001_vis" type="mesh" solimp="0.998 0.998 0.001" solref="0.001 1" density="100" friction="0.95 0.3 0.1" class="visual" material="Body001_material"/>
        <geom class="collision" type="box" pos="0.0 0.0 -0.19952483475208282" size="0.3863246440887451 0.2115684300661087 0.005586881656199694" quat="1.0 0.0 0.0 0.0"/>
        <geom class="collision" type="box" pos="0.373686283826828 0.0 -0.1109139695763588" size="0.013876662589609623 0.2115684300661087 0.09326047450304031" quat="1.0 0.0 0.0 0.0"/>
        <geom class="collision" type="box" pos="-0.37364235520362854 0.0 -0.1109139695763588" size="0.013876662589609623 0.2115684300661087 0.09326047450304031" quat="1.0 0.0 0.0 0.0"/>
        <geom class="collision" type="box" pos="0.0012131482362747192 0.20416085422039032 -0.11035669595003128" size="0.007811950985342264 0.3632982075214386 0.09326047450304031" quat="0.7071067094802856 0.0 0.0 0.7071068286895752"/>
        <geom class="collision" type="box" pos="0.0012131482362747192 -0.20442795753479004 -0.11035669595003128" size="0.007811950985342264 0.3632982075214386 0.09326047450304031" quat="0.7071067094802856 0.0 0.0 0.7071068286895752"/>
        <geom class="collision" type="box" pos="0.0012131482362747192 0.18821613490581512 -0.11736245453357697" size="0.009673441760241985 0.3632982075214386 0.08898404985666275" quat="0.7071067094802856 0.0 0.0 0.7071068286895752"/>
        <geom class="collision" type="box" pos="0.0012131482362747192 -0.19174771010875702 -0.11736245453357697" size="0.009673441760241985 0.3632982075214386 0.08898404985666275" quat="0.7071067094802856 0.0 0.0 0.7071068286895752"/>
        <geom class="collision" type="box" pos="0.35152482986450195 0.0 -0.11683103442192078" size="0.010122813284397125 0.2115684300661087 0.08823632448911667" quat="1.0 0.0 0.0 0.0"/>
        <geom class="collision" type="box" pos="-0.3506115674972534 0.0 -0.11683103442192078" size="0.010122813284397125 0.2115684300661087 0.08823632448911667" quat="1.0 0.0 0.0 0.0"/>
        <geom class="collision" type="box" pos="-0.049932487308979034 0.0 -0.11683103442192078" size="0.020335232838988304 0.2115684300661087 0.08823632448911667" quat="1.0 0.0 0.0 0.0"/>
        <geom class="collision" type="box" pos="0.04770541191101074 0.0 -0.18960413336753845" size="0.08750303089618683 0.18343639373779297 0.01580731011927128" quat="1.0 0.0 0.0 0.0"/>
        <geom class="collision" type="box" pos="0.2829618752002716 0.0 -0.1891126036643982" size="0.061674099415540695 0.18343639373779297 0.01580731011927128" quat="1.0 0.0 0.0 0.0"/>
        <geom class="collision" type="box" pos="0.1785999834537506 0.10524630546569824 -0.18960413336753845" size="0.044393956661224365 0.0735950842499733 0.01580731011927128" quat="1.0 0.0 0.0 0.0"/>
        <geom class="collision" type="box" pos="0.1785999834537506 -0.12359806895256042 -0.18960413336753845" size="0.044393956661224365 0.0735950842499733 0.01580731011927128" quat="1.0 0.0 0.0 0.0"/>
        <geom class="collision" type="box" pos="-0.20686092972755432 0.10524630546569824 -0.18960413336753845" size="0.044393956661224365 0.0735950842499733 0.01580731011927128" quat="1.0 0.0 0.0 0.0"/>
        <geom class="collision" type="box" pos="-0.20686092972755432 -0.12359806895256042 -0.18960413336753845" size="0.044393956661224365 0.0735950842499733 0.01580731011927128" quat="1.0 0.0 0.0 0.0"/>
        <geom class="collision" type="box" pos="-0.2951148450374603 0.0 -0.18918123841285706" size="0.04538893699645996 0.18343639373779297 0.01580731011927128" quat="1.0 0.0 0.0 0.0"/>
        <geom class="collision" type="box" pos="-0.11546649038791656 0.0 -0.18918123841285706" size="0.04660268872976303 0.18343639373779297 0.01580731011927128" quat="1.0 0.0 0.0 0.0"/>
        <geom class="collision" type="box" pos="-0.33367568254470825 0.17161761224269867 -0.11683103442192078" size="0.019925637170672417 0.007462342269718647 0.08823632448911667" quat="0.940239667892456 0.0 0.0 0.3405134379863739"/>
        <geom class="collision" type="box" pos="-0.02384537272155285 0.17186811566352844 -0.11683103442192078" size="0.019925637170672417 0.007462342269718647 0.08823632448911667" quat="0.940239667892456 0.0 0.0 0.3405134379863739"/>
        <geom class="collision" type="box" pos="0.33523038029670715 -0.17924779653549194 -0.11683103442192078" size="0.019925637170672417 0.007462342269718647 0.08823632448911667" quat="0.9531394243240356 0.0 0.0 0.302531361579895"/>
        <geom class="collision" type="box" pos="-0.07779514789581299 -0.1783633679151535 -0.11683103442192078" size="0.019925637170672417 0.007462342735379934 0.08823632448911667" quat="0.9558876156806946 0.0 0.0 0.29373273253440857"/>
        <geom class="collision" type="box" pos="-0.3338356018066406 -0.1801322102546692 -0.11683103442192078" size="0.019925637170672417 0.007462342269718647 0.08823632448911667" quat="0.9399371147155762 0.0 -0.0 -0.34134769439697266"/>
        <geom class="collision" type="box" pos="-0.07469967007637024 0.1771746724843979 -0.11683103442192078" size="0.019925637170672417 0.007462342269718647 0.08823632448911667" quat="0.9495238065719604 0.0 -0.0 -0.3136950433254242"/>
        <geom class="collision" type="box" pos="-0.023403137922286987 -0.180574432015419 -0.11683103442192078" size="0.019925637170672417 0.007462342735379934 0.08823632448911667" quat="0.9591093063354492 0.0 -0.0 -0.28303593397140503"/>
        <geom class="collision" type="box" pos="0.3356725871562958 0.17629022896289825 -0.11683103442192078" size="0.019925637170672417 0.007462342735379934 0.08823632448911667" quat="0.9488807916641235 0.0 -0.0 -0.3156346082687378"/>
        <geom class="collision" type="cylinder" pos="-0.049444589763879776 0.17700879275798798 -0.02717815339565277" size="0.020696282386779785 0.0019337263656780124" quat="1.0 0.0 0.0 0.0"/>
        <geom class="collision" type="cylinder" pos="-0.049444589763879776 0.17726176977157593 0.022596560418605804" size="0.01705211028456688 0.04953644052147865" quat="1.0 0.0 0.0 0.0"/>
        <geom class="collision" type="cylinder" pos="-0.02029481530189514 0.17738276720046997 0.018992409110069275" size="0.012767321430146694 0.017574816942214966" quat="0.7071068286895752 -0.0 0.7071067690849304 0.0"/>
        <body name="handle">
          <joint axis="1.0 0.0 0.0" pos="0.008804760873317719 0.17751868069171906 0.019089844077825546" limited="true" name="handle_joint_hinge_0" type="hinge" range="-0.7853981633974483 0.7853981633974483" damping="1" frictionloss="1" armature=".01" stiffness="0.05"/>
          <joint axis="0.0 1.0 0.0" pos="0.008804760873317719 0.17751868069171906 0.019089844077825546" limited="true" name="handle_joint_hinge_1" type="hinge" range="0.0 0.17453292519943295" damping="1" frictionloss="1" armature=".01" stiffness="0.05"/>
          <geom mesh="handle_vis" type="mesh" solimp="0.998 0.998 0.001" solref="0.001 1" density="100" friction="0.95 0.3 0.1" class="visual" material="handle_material"/>
          <geom class="collision" type="cylinder" pos="0.010035322979092598 0.17738276720046997 0.018992410972714424" size="0.012767321430146694 0.007471789140254259" quat="0.7071068286895752 -0.0 0.7071067690849304 0.0"/>
          <geom class="collision" type="cylinder" pos="0.009375208988785744 0.17726176977157593 0.053251489996910095" size="0.0028966048266738653 0.02498188614845276" quat="1.0 0.0 0.0 0.0"/>
        </body>
        <body name="Funnel001">
          <joint axis="0.0 0.0 1.0" pos="-0.20534762740135193 -0.010111430659890175 -0.1846631020307541" limited="true" name="Funnel001_joint" range="0.0 0.15" type="slide" damping="1" frictionloss="1" armature=".01" stiffness="0.05"/>
          <geom mesh="Funnel001_vis" type="mesh" solimp="0.998 0.998 0.001" solref="0.001 1" density="100" friction="0.95 0.3 0.1" class="visual" material="Funnel001_material"/>
          <geom class="collision" type="cylinder" pos="-0.20553743839263916 -0.010092412121593952 -0.19298234581947327" size="0.039555322378873825 0.0018517236458137631" quat="1.0 0.0 0.0 0.0"/>
          <geom class="collision" type="cylinder" pos="-0.20553743839263916 -0.010092412121593952 -0.18880541622638702" size="0.0043230620212852955 0.004567450378090143" quat="1.0 0.0 0.0 0.0"/>
        </body>
        <body name="Funnel002">
          <joint axis="0.0 0.0 1.0" pos="0.17784348130226135 -0.010111430659890175 -0.1846631020307541" limited="true" name="Funnel002_joint" range="0.0 0.15" type="slide" damping="1" frictionloss="1" armature=".01" stiffness="0.05"/>
          <geom mesh="Funnel002_vis" type="mesh" solimp="0.998 0.998 0.001" solref="0.001 1" density="100" friction="0.95 0.3 0.1" class="visual" material="Funnel002_material"/>
          <geom class="collision" type="cylinder" pos="0.17750334739685059 -0.010092412121593952 -0.1925785094499588" size="0.039555322378873825 0.0018517236458137631" quat="1.0 0.0 0.0 0.0"/>
          <geom class="collision" type="cylinder" pos="0.17750334739685059 -0.010092412121593952 -0.18840157985687256" size="0.0043230620212852955 0.004567450378090143" quat="1.0 0.0 0.0 0.0"/>
        </body>
        <body name="spout">
          <joint axis="0.0 0.0 1.0" pos="-0.04904136061668396 0.17851115763187408 0.13632214069366455" limited="true" name="spout_joint" range="-0.7853981633974483 0.7853981633974483" type="hinge" damping="1" frictionloss="1" armature=".01" stiffness="0.05"/>
          <site type="cylinder" rgba="0.5 0.75 1 1" size="0.004692251328378916 0.18583299219608307" pos="-0.11325418204069138 0.03193925321102142 -0.0023765861988067627" name="water"/>
          <geom mesh="spout_vis" type="mesh" solimp="0.998 0.998 0.001" solref="0.001 1" density="100" friction="0.95 0.3 0.1" class="visual" material="spout_material"/>
          <geom class="collision" type="cylinder" pos="-0.049444589763879776 0.17850525677204132 0.11271379888057709" size="0.009567921981215477 0.0430426299571991" quat="1.0 0.0 0.0 0.0"/>
          <geom class="collision" type="cylinder" pos="-0.052810266613960266 0.1702764630317688 0.16827000677585602" size="0.009567921981215477 0.020221775397658348" quat="0.9513658285140991 0.2607976198196411 -0.1363416612148285 0.09109681844711304"/>
          <geom class="collision" type="cylinder" pos="-0.062100600451231 0.1497892439365387 0.18924789130687714" size="0.009567921049892902 0.015004752203822136" quat="0.8503028154373169 0.4190908372402191 -0.2927687466144562 0.12503796815872192"/>
          <geom class="collision" type="cylinder" pos="-0.07453925162553787 0.12178981304168701 0.19504337012767792" size="0.009567921981215477 0.020221775397658348" quat="0.7059001326560974 0.5602014064788818 -0.4060839116573334 0.15157592296600342"/>
          <geom class="collision" type="cylinder" pos="-0.09944776445627213 0.06365624070167542 0.19526846706867218" size="0.009567921981215477 0.04792982339859009" quat="0.6845719814300537 0.5685099959373474 -0.42573148012161255 0.16404356062412262"/>
          <geom class="collision" type="cylinder" pos="-0.11299525946378708 0.031744394451379776 0.1826270967721939" size="0.007299602031707764 0.0068480451591312885" quat="1.0 0.0 0.0 0.0"/>
        </body>
        <geom class="region" name="reg_main" type="box" pos="-7.450580596923828e-09 5.960464477539063e-08 -0.1111467182636261" size="0.38748350739479065 0.2119612693786621 0.09310051798820496"/>
        <geom class="region" name="reg_basin_left" type="box" pos="-0.20425155386328697 -0.003130972385406494 -0.10773851722478867" size="0.12396830692887306 0.16950438916683197 0.07297144085168839"/>
        <geom class="region" name="reg_basin_right" type="box" pos="0.15521953999996185 -0.0007356703281402588 -0.10773851722478867" size="0.17630673944950104 0.17110125720500946 0.07297144085168839"/>
      </body>
    </body>
  </worldbody>
  <actuator>
    <motor name="handle_joint_hinge_0_actuator" joint="handle_joint_hinge_0" gear="10"/>
    <motor name="handle_joint_hinge_1_actuator" joint="handle_joint_hinge_1" gear="10"/>
    <motor name="Funnel001_joint_actuator" joint="Funnel001_joint" gear="10"/>
    <motor name="Funnel002_joint_actuator" joint="Funnel002_joint" gear="10"/>
    <motor name="spout_joint_actuator" joint="spout_joint" gear="10"/>
  </actuator>
</mujoco>
