<?xml version='1.0' encoding='UTF-8'?>
<mujoco model="model">
  <option timestep="0.002" gravity="0.0 0.0 -9.81"/>
  <compiler angle="radian"/>
  <asset>
    <mesh file="visuals/Body001.obj" name="Body001_vis"/>
    <mesh file="visuals/Container001.obj" name="Container001_vis"/>
    <mesh file="visuals/Door001.obj" name="Door001_vis"/>
    <mesh file="visuals/Door001_Clear.obj" name="Door001_Clear_vis"/>
    <mesh file="visuals/Knob001.obj" name="Knob001_vis"/>
    <mesh file="visuals/Knob002.obj" name="Knob002_vis"/>
    <mesh file="visuals/Knob003.obj" name="Knob003_vis"/>
    <texture file="visuals/T_BC001.png" name="Body001_material" type="2d"/>
    <material name="Body001_material" rgba="1 1 1 1.0" texture="Body001_material" shininess="0.4472135901451111" specular="2"/>
    <texture file="visuals/T_BC001.png" name="Container001_material" type="2d"/>
    <material name="Container001_material" rgba="1 1 1 1.0" texture="Container001_material" shininess="0.4472135901451111" specular="2"/>
    <texture file="visuals/T_BC001.png" name="Door001_material" type="2d"/>
    <material name="Door001_material" rgba="1 1 1 1.0" texture="Door001_material" shininess="0.4472135901451111" specular="1"/>
    <texture file="visuals/T_BC001.png" name="Door001_Clear_material" type="2d"/>
    <material name="Door001_Clear_material" rgba="1 1 1 0.7874016165733337" texture="Door001_Clear_material" shininess="0.4472135901451111" specular="0.3103448502657381"/>
    <texture file="visuals/T_BC001.png" name="Knob001_material" type="2d"/>
    <material name="Knob001_material" rgba="1 1 1 1.0" texture="Knob001_material" shininess="0.4472135901451111" specular="0.3103448502657381"/>
    <texture file="visuals/T_BC001.png" name="Knob002_material" type="2d"/>
    <material name="Knob002_material" rgba="1 1 1 1.0" texture="Knob002_material" shininess="0.4472135901451111" specular="0.3103448502657381"/>
    <texture file="visuals/T_BC001.png" name="Knob003_material" type="2d"/>
    <material name="Knob003_material" rgba="1 1 1 1.0" texture="Knob003_material" shininess="0.4472135901451111" specular="0.3103448502657381"/>
  </asset>
  <default>
    <default class="visual">
      <geom conaffinity="0" contype="0" group="1" type="mesh"/>
    </default>
    <default class="collision">
      <geom group="0" rgba="0.5 0 0 0.5"/>
    </default>
    <default class="spawn">
      <geom group="0" rgba="1 1 1 0.5" contype="0" conaffinity="0"/>
      <site group="0" rgba="1 1 1 0.5"/>
    </default>
    <default class="region">
      <geom group="1" conaffinity="0" contype="0" rgba="0 1 0 0"/>
    </default>
  </default>
  <worldbody>
    <body>
      <body name="object">
        <geom mesh="Body001_vis" type="mesh" solimp="0.998 0.998 0.001" solref="0.001 1" friction="0.95 0.3 0.1" class="visual" material="Body001_material"/>
        <geom class="collision" type="box" pos="-0.15014806389808655 0.03225326165556908 0.007988776080310345" size="0.01095607504248619 0.12452957034111023 0.15582062304019928" quat="1.0 0.0 0.0 0.0" density="1000.0"/>
        <geom class="collision" type="box" pos="0.15029776096343994 0.03225326165556908 0.007988776080310345" size="0.011105741374194622 0.12452957034111023 0.15582062304019928" quat="1.0 0.0 0.0 0.0" density="1000.0"/>
        <geom class="collision" type="box" pos="0.00037354338564909995 0.03225326165556908 -0.14459064602851868" size="0.029636366292834282 0.12452957034111023 0.15582062304019928" quat="0.7071068286895752 -0.0 0.7071067690849304 0.0" density="1000.0"/>
        <geom class="collision" type="box" pos="0.0003735424834303558 0.02025252766907215 0.11629744619131088" size="0.050077278167009354 0.1365303099155426 0.15582062304019928" quat="0.7071068286895752 -0.0 0.7071067690849304 0.0" density="1000.0"/>
        <geom class="collision" type="box" pos="-0.003032587468624115 0.1421884149312973 0.007988776080310345" size="0.01459441240876913 0.1524145007133484 0.15582062304019928" quat="0.7071067094802856 0.0 0.0 0.7071068286895752" density="1000.0"/>
        <geom class="collision" type="cylinder" pos="-0.1104695200920105 -0.04687829315662384 0.16864657402038574" size="0.015137218870222569 0.005071556195616722" quat="1.0 0.0 0.0 0.0" density="1000.0"/>
        <geom class="collision" type="box" pos="0.00037354344385676086 0.03225326165556908 0.08603633940219879" size="0.029581598937511444 0.12452957034111023 0.15582062304019928" quat="0.7071068286895752 -0.0 0.7071067690849304 0.0" density="1000.0"/>
        <geom class="collision" type="box" pos="0.13413213193416595 0.030581790953874588 -0.034753818064928055" size="0.0023184120655059814 0.08300451189279556 0.012300278060138226" quat="0.7071068286895752 -0.0 0.7071067690849304 0.0" density="1000.0"/>
        <geom class="collision" type="box" pos="-0.1335434913635254 0.030581790953874588 -0.034753818064928055" size="0.0023184120655059814 0.08300451189279556 0.012300278060138226" quat="0.7071068286895752 -0.0 0.7071067690849304 0.0" density="1000.0"/>
        <body name="Container001">
          <joint axis="0.0 -1.0 0.0" pos="0.007002250291407108 0.019703805446624756 -0.036553241312503815" limited="true" name="Container001_joint" range="0.0 0.13" type="slide" damping="1" frictionloss="1" armature=".01" stiffness="0.05"/>
          <geom mesh="Container001_vis" type="mesh" solimp="0.998 0.998 0.001" solref="0.001 1" friction="0.95 0.3 0.1" class="visual" material="Container001_material"/>
          <geom class="collision" type="box" pos="0.00039822518010623753 0.019827313721179962 -0.03828849270939827" size="0.10529593378305435 0.09532225131988525 0.002356566721573472" quat="1.0 0.0 0.0 0.0" density="1000.0"/>
          <geom class="collision" type="box" pos="-0.11944076418876648 0.019765039905905724 -0.030751248821616173" size="0.006655312608927488 0.09543942660093307 0.0012939152074977756" quat="1.0 0.0 0.0 0.0" density="1000.0"/>
          <geom class="collision" type="box" pos="-0.10865580290555954 0.01975994184613228 -0.03446810320019722" size="0.00665531400591135 0.09544443339109421 0.0012939026346430182" quat="0.9440328478813171 -2.0632491271044273e-08 0.3298514783382416 7.209132402152818e-09" density="1000.0"/>
          <geom class="collision" type="box" pos="0.10940202325582504 0.01975994184613228 -0.03446810692548752" size="0.00665531400591135 0.09544443339109421 0.0012939036823809147" quat="7.127249546101666e-08 -0.9440328478813171 -2.4903092921135794e-08 -0.3298514783382416" density="1000.0"/>
          <geom class="collision" type="box" pos="0.11957360059022903 0.019765039905905724 -0.030751248821616173" size="0.006655312608927488 0.09543942660093307 0.001293914276175201" quat="1.0 0.0 0.0 0.0" density="1000.0"/>
          <geom class="collision" type="box" pos="-0.10581588745117188 0.02135636657476425 -0.03038015402853489" size="0.00806617084890604 0.07869242876768112 0.001056751236319542" quat="0.834775984287262 4.428877176110291e-08 0.5505897402763367 -1.4125792757724298e-09" density="1000.0"/>
          <geom class="collision" type="box" pos="-0.00176620960701257 -0.06675811856985092 -0.03000950999557972" size="0.008066176436841488 0.09491541981697083 0.0010567521676421165" quat="0.560018002986908 -0.43171724677085876 0.43171700835227966 0.5600183010101318" density="1000.0"/>
          <geom class="collision" type="box" pos="0.1065501943230629 0.02135636657476425 -0.03038015402853489" size="0.00806617084890604 0.07869242876768112 0.0010567507706582546" quat="3.057072461842836e-08 0.834775984287262 7.635378551640315e-09 0.5505897402763367" density="1000.0"/>
          <geom class="collision" type="box" pos="-0.00176620960701257 0.1104477047920227 -0.03000950999557972" size="0.008066178299486637 0.09491542726755142 0.0010567522840574384" quat="0.4317190647125244 -0.5600156188011169 -0.5600206851959229 -0.431715190410614" density="1000.0"/>
          <geom class="collision" type="box" pos="-0.10295441746711731 -0.058874256908893585 -0.03038015402853489" size="0.008066173642873764 0.005420687608420849 0.001056752516888082" quat="0.8021135926246643 -0.15250761806964874 0.529046893119812 0.23122413456439972" density="1000.0"/>
          <geom class="collision" type="box" pos="-0.09684649854898453 -0.06447828561067581 -0.0303801279515028" size="0.008066168054938316 0.0054206750355660915 0.0010567408753558993" quat="0.7184903621673584 -0.28031352162361145 0.4738919734954834 0.42499685287475586" density="1000.0"/>
          <geom class="collision" type="box" pos="-0.11111374199390411 0.021576568484306335 -0.024164412170648575" size="0.003295277012512088 0.08215053379535675 0.0008282599737867713" quat="1.0 0.0 0.0 0.0" density="1000.0"/>
          <geom class="collision" type="box" pos="0.00018828315660357475 -0.06956321001052856 -0.024164412170648575" size="0.10313545167446136 0.0020921058021485806 0.0008282687049359083" quat="1.0 0.0 0.0 0.0" density="1000.0"/>
          <geom class="collision" type="box" pos="-0.10904745012521744 -0.061951227486133575 -0.024164412170648575" size="0.003295270958915353 0.003842470468953252 0.000828248739708215" quat="0.9630976915359497 -7.4883722334107e-08 -9.148812374348836e-09 0.26915204524993896" density="1000.0"/>
          <geom class="collision" type="box" pos="-0.10437021404504776 -0.06636030972003937 -0.024164412170648575" size="0.003295283066108823 0.004517356399446726 0.000828248739708215" quat="0.8660538196563721 -1.892820655768901e-08 -1.0926771487618225e-08 0.4999507665634155" density="1000.0"/>
          <geom class="collision" type="box" pos="-0.10437019914388657 0.10918091982603073 -0.024164412170648575" size="0.003295283764600754 0.004517356865108013 0.000828248739708215" quat="4.651262841548487e-08 -0.4999507665634155 -0.8660538196563721 -7.043785643645606e-08" density="1000.0"/>
          <geom class="collision" type="box" pos="-0.10904745012521744 0.10477190464735031 -0.024164412170648575" size="0.003295272123068571 0.0038424718659371138 0.000828248739708215" quat="8.102094284367922e-08 0.26915183663368225 0.9630977511405945 9.411745161003182e-09" density="1000.0"/>
          <geom class="collision" type="box" pos="-0.09684651345014572 0.10729900747537613 -0.030380140990018845" size="0.008066168986260891 0.005420675966888666 0.001056741108186543" quat="0.4738919138908386 -0.42499667406082153 -0.7184905409812927 -0.2803134322166443" density="1000.0"/>
          <geom class="collision" type="box" pos="-0.10295438766479492 0.1016950011253357 -0.03038014844059944" size="0.008066173642873764 0.0054206643253564835 0.0010567526333034039" quat="0.5290468335151672 -0.23122407495975494 -0.8021136522293091 -0.15250758826732635" density="1000.0"/>
          <geom class="collision" type="box" pos="0.0001882869837572798 0.11308570951223373 -0.024164412170648575" size="0.10313545167446136 0.0020921058021485806 0.0008282687049359083" quat="1.0 0.0 0.0 0.0" density="1000.0"/>
          <geom class="collision" type="box" pos="0.10341976583003998 0.1016949787735939 -0.030380140990018845" size="0.008066173642873764 0.0054206643253564835 0.001056752516888082" quat="0.23122406005859375 0.5290468335151672 0.15250755846500397 -0.8021136522293091" density="1000.0"/>
          <geom class="collision" type="box" pos="0.09724130481481552 0.10729903727769852 -0.03038015402853489" size="0.008066167123615742 0.005420675966888666 0.0010567406425252557" quat="0.4249967634677887 0.47389188408851624 0.2803134620189667 -0.718490481376648" density="1000.0"/>
          <geom class="collision" type="box" pos="0.10944225639104843 0.1047719344496727 -0.024164412170648575" size="0.0032952839974313974 0.0038424718659371138 0.000828248739708215" quat="0.2691517472267151 6.893837500854261e-09 1.7478617664323792e-08 -0.9630978107452393" density="1000.0"/>
          <geom class="collision" type="box" pos="0.10476507246494293 0.10918091982603073 -0.024164412170648575" size="0.0032952839974313974 0.0045173573307693005 0.000828248739708215" quat="0.49995073676109314 1.88726119176863e-08 -3.26926254956561e-08 -0.8660538196563721" density="1000.0"/>
          <geom class="collision" type="box" pos="0.10507585853338242 -0.06636028736829758 -0.024164412170648575" size="0.003295283066108823 0.004517356399446726 0.000828248739708215" quat="6.538524388588485e-08 -0.8660538196563721 0.4999507665634155 -3.7745234493513635e-08" density="1000.0"/>
          <geom class="collision" type="box" pos="0.1097530946135521 -0.061951227486133575 -0.024164412170648575" size="0.0032952839974313974 0.0038424718659371138 0.000828248739708215" quat="7.576508664897119e-08 -0.9630977511405945 0.26915186643600464 -9.395116684629556e-09" density="1000.0"/>
          <geom class="collision" type="box" pos="0.0972413495182991 -0.0644783303141594 -0.030380165204405785" size="0.008066167123615742 0.0054206750355660915 0.0010567406425252557" quat="0.28031325340270996 0.7184906601905823 -0.4249964952468872 0.4738919734954834" density="1000.0"/>
          <geom class="collision" type="box" pos="0.1033492237329483 -0.058874234557151794 -0.030380140990018845" size="0.008066173642873764 0.005420664791017771 0.0010567522840574384" quat="0.15250751376152039 0.8021135926246643 -0.23122410476207733 0.5290469527244568" density="1000.0"/>
          <geom class="collision" type="box" pos="0.11166868358850479 0.021576568484306335 -0.024164412170648575" size="0.003295275615528226 0.08215053379535675 0.0008282599737867713" quat="1.0 0.0 0.0 0.0" density="1000.0"/>
        </body>
        <body name="Door001">
          <joint axis="1.0 0.0 0.0" pos="-0.0002447452279739082 -0.09181776642799377 -0.14766952395439148" limited="true" name="Door001_joint" range="0.0 1.5707963267948966" type="hinge" damping="1" frictionloss="1" armature=".01" stiffness="0.2" springref="-3"/>
          <geom mesh="Door001_vis" type="mesh" solimp="0.998 0.998 0.001" solref="0.001 1" friction="0.95 0.3 0.1" class="visual" material="Door001_material"/>
          <geom class="collision" type="box" pos="-0.14410129189491272 -0.10681606829166412 -0.04308674484491348" size="0.015532135032117367 0.007766919210553169 0.09968185424804688" quat="1.0 0.0 0.0 0.0" density="1000.0"/>
          <geom class="collision" type="box" pos="0.14359517395496368 -0.10681606829166412 -0.04308674484491348" size="0.015532135032117367 0.007766919210553169 0.09968185424804688" quat="1.0 0.0 0.0 0.0" density="1000.0"/>
          <geom class="collision" type="box" pos="0.012223323807120323 -0.10681606829166412 0.04404744505882263" size="0.14690399169921875 0.007766919210553169 0.012547672726213932" quat="1.0 0.0 0.0 0.0" density="1000.0"/>
          <geom class="collision" type="box" pos="0.012223323807120323 -0.10681606829166412 -0.12251543253660202" size="0.14690399169921875 0.007766919210553169 0.019562775269150734" quat="1.0 0.0 0.0 0.0" density="1000.0"/>
          <geom class="collision" type="box" pos="-0.002028370974585414 -0.15088653564453125 0.0458734966814518" size="0.12011595070362091 0.005527830217033625 0.005527830217033625" quat="1.0 0.0 0.0 0.0" density="1000.0"/>
          <geom class="collision" type="box" pos="0.12467844784259796 -0.1289527416229248 0.0458734966814518" size="0.018671143800020218 0.005527838133275509 0.005527830217033625" quat="0.7071068286895752 0.0 0.0 0.7071067690849304" density="1000.0"/>
          <geom class="collision" type="box" pos="-0.12602689862251282 -0.1289527416229248 0.0458734966814518" size="0.018671143800020218 0.005527838133275509 0.005527830217033625" quat="0.7071068286895752 0.0 0.0 0.7071067690849304" density="1000.0"/>
          <body name="Door001_Clear">
            <geom mesh="Door001_Clear_vis" type="mesh" solimp="0.998 0.998 0.001" solref="0.001 1" friction="0.95 0.3 0.1" class="visual" material="Door001_Clear_material"/>
            <geom class="collision" type="box" pos="-6.950646638870239e-05 -0.10270194709300995 -0.03836246207356453" size="0.12502355873584747 0.0007287650369107723 0.06635313481092453" quat="1.0 0.0 0.0 0.0" density="1000.0"/>
          </body>
        </body>
        <body name="Knob001">
          <joint axis="0.0 1.0 0.0" pos="-0.09195391088724136 -0.12413480877876282 0.11093045771121979" limited="true" name="Knob001_joint" range="0.0 4.014257279586958" type="hinge" damping="0.05" armature="0.001"/>
          <geom mesh="Knob001_vis" type="mesh" solimp="0.998 0.998 0.001" solref="0.001 1" friction="0.95 0.3 0.1" class="visual" material="Knob001_material"/>
          <geom class="collision" type="cylinder" pos="-0.09187865257263184 -0.1199907511472702 0.11097143590450287" size="0.01761051081120968 0.0027485794853419065" quat="0.7071067094802856 0.7071068286895752 0.0 0.0" density="1000.0"/>
          <geom class="collision" type="box" pos="-0.09196415543556213 -0.12741884589195251 0.1105961799621582" size="0.0030167505610734224 0.005303218029439449 0.00994835700839758" quat="1.0 0.0 0.0 0.0" density="1000.0"/>
        </body>
        <body name="Knob002">
          <joint axis="0.0 1.0 0.0" pos="-0.0007955431356094778 -0.12392156571149826 0.11093005537986755" limited="true" name="Knob002_joint" range="0.0 3.2288591161895095" type="hinge" damping="0.05" armature="0.001"/>
          <geom mesh="Knob002_vis" type="mesh" solimp="0.998 0.998 0.001" solref="0.001 1" friction="0.95 0.3 0.1" class="visual" material="Knob002_material"/>
          <geom class="collision" type="cylinder" pos="-0.0009866959881037474 -0.1199907511472702 0.11097143590450287" size="0.01761051081120968 0.0027485794853419065" quat="0.7071067094802856 0.7071068286895752 0.0 0.0" density="1000.0"/>
          <geom class="collision" type="box" pos="-0.000777900218963623 -0.12741884589195251 0.11086548119783401" size="0.0030167505610734224 0.005303218029439449 0.00994835700839758" quat="0.7071068286895752 -0.0 0.7071067690849304 0.0" density="1000.0"/>
        </body>
        <body name="Knob003">
          <joint axis="0.0 1.0 0.0" pos="0.09242948144674301 -0.12413480877876282 0.11093045771121979" limited="true" name="Knob003_joint" range="0.0 3.141592653589793" type="hinge" damping="0.05" armature="0.001"/>
          <geom mesh="Knob003_vis" type="mesh" solimp="0.998 0.998 0.001" solref="0.001 1" friction="0.95 0.3 0.1" class="visual" material="Knob003_material"/>
          <geom class="collision" type="cylinder" pos="0.09248964488506317 -0.1199907511472702 0.11097143590450287" size="0.01761051081120968 0.0027485794853419065" quat="0.7071067094802856 0.7071068286895752 0.0 0.0" density="1000.0"/>
          <geom class="collision" type="box" pos="0.0924294963479042 -0.12741884589195251 0.11086548119783401" size="0.0030167505610734224 0.005303218029439449 0.00994835700839758" quat="0.6227676868438721 0.0 0.7824068069458008 0.0" density="1000.0"/>
        </body>
        <geom class="region" name="reg_int" type="box" pos="-0.0001509934663772583 0.021129027009010315 -0.029451973736286163" size="0.139651358127594 0.1126990020275116 0.08607987314462662"/>
        <geom class="region" name="reg_main" type="box" pos="0.0 0.020252518355846405 -1.862645149230957e-08" size="0.16110414266586304 0.1365303248167038 0.1742270141839981"/>
      </body>
    </body>
  </worldbody>
  <actuator>
    <motor name="Container001_joint_actuator" joint="Container001_joint" gear="10"/>
    <motor name="Door001_joint_actuator" joint="Door001_joint" gear="50"/>
    <motor name="Knob001_joint_actuator" joint="Knob001_joint" gear="50"/>
    <motor name="Knob002_joint_actuator" joint="Knob002_joint" gear="50"/>
    <motor name="Knob003_joint_actuator" joint="Knob003_joint" gear="50"/>
  </actuator>
</mujoco>
