<mujoco model="model">
  <compiler angle="radian"/>
  <asset>
    <mesh file="visuals/door.obj" name="door_vis"/>
    <mesh file="visuals/door_Clear.obj" name="door_Clear_vis"/>
    <mesh file="visuals/Body001.obj" name="Body001_vis"/>
    <mesh file="visuals/Disc001.obj" name="Disc001_vis"/>
    <texture file="visuals/T_BC001.png" name="Body001_material" type="2d"/>
    <material name="Body001_material" rgba="1 1 1 1.0" texture="Body001_material" shininess="0.4472135901451111" specular="1"/>
    <texture file="visuals/T_BC001.png" name="door_material" type="2d"/>
    <material name="door_material" rgba="1 1 1 1.0" texture="door_material" shininess="0.4472135901451111" specular="1"/>
    <texture file="visuals/T_BC001.png" name="door_Clear_material" type="2d"/>
    <material name="door_Clear_material" rgba="1 1 1 0.8999999761581421" texture="door_Clear_material" shininess="0.4472135901451111" specular="1"/>
    <texture file="visuals/T_BC001.png" name="Disc001_material" type="2d"/>
    <material name="Disc001_material" rgba="1 1 1 1.0" texture="Disc001_material" shininess="0.4472135901451111" specular="1"/>
  </asset>
  <default>
    <default class="visual">
      <geom conaffinity="0" contype="0" group="1" type="mesh"/>
    </default>
    <default class="collision">
      <geom group="0" rgba="0.5 0 0 0.5"/>
    </default>
    <default class="spawn">
      <geom group="0" rgba="1 1 1 0.5" contype="0" conaffinity="0"/>
      <site group="0" rgba="1 1 1 0.5"/>
    </default>
    <default class="region">
      <geom group="1" conaffinity="0" contype="0" rgba="0 1 0 0"/>
    </default>
  </default>
  <worldbody>
    <body>
      <body name="object">
        <geom class="collision" type="box" pos="-0.03636551275849342 0.009838864207267761 -0.0665702372789383" size="0.11146734654903412 0.11318691074848175 0.0010362376924604177" quat="1.0 0.0 0.0 0.0" name="tray" rgba="0 1 0 0.5"/>
        <geom class="collision" type="box" pos="0.16379722952842712 -0.14703530073165894 -0.08088003844022751" size="0.007899247109889984 0.0003051722887903452 0.00369465840049088" quat="1.0 0.0 0.0 0.0" name="stop_button" rgba="0.0 0.5 0 0.5"/>
        <geom class="collision" type="box" pos="0.1869337260723114 -0.14703530073165894 -0.08088003844022751" size="0.007899250835180283 0.000305172405205667 0.0036946600303053856" quat="1.0 0.0 0.0 0.0" name="start_button" rgba="0.0 0.5 0 0.5"/>
        <geom mesh="Body001_vis" type="mesh" solimp="0.998 0.998 0.001" solref="0.001 1" density="100" friction="0.95 0.3 0.1" class="visual" material="Body001_material"/>
        <geom class="collision" type="box" pos="0.018791131675243378 0.03180336579680443 -0.09959933161735535" size="0.19373486936092377 0.14701543748378754 0.027904359623789787" quat="1.0 0.0 0.0 0.0"/>
        <geom class="collision" type="box" pos="0.018791131675243378 0.03180336579680443 0.10421013832092285" size="0.19373486936092377 0.14701543748378754 0.02343263104557991" quat="1.0 0.0 0.0 0.0"/>
        <geom class="collision" type="box" pos="-0.19416449964046478 0.03501163423061371 6.953533738851547e-05" size="0.01836172118782997 0.14380718767642975 0.12757323682308197" quat="1.0 0.0 0.0 0.0"/>
        <geom class="collision" type="box" pos="0.15654659271240234 0.03180336579680443 0.004541270434856415" size="0.0559794120490551 0.14701543748378754 0.07623624056577682" quat="1.0 0.0 0.0 0.0"/>
        <geom class="collision" type="box" pos="-0.037617795169353485 0.15067614614963531 0.004541270434856415" size="0.13818496465682983 0.0281426589936018 0.07623624056577682" quat="1.0 0.0 0.0 0.0"/>
        <geom class="collision" type="box" pos="0.17571911215782166 -0.13088573515415192 0.0038172851782292128" size="0.03680688887834549 0.015673667192459106 0.12382548302412033" quat="1.0 0.0 0.0 0.0"/>
        <geom class="collision" type="cylinder" pos="-0.1736367642879486 0.0008884384296834469 0.00873629655689001" size="0.049335919320583344 0.0018317922949790955" quat="0.7071068286895752 -0.0 0.7071067690849304 0.0"/>
        <body name="door">
          <joint axis="0.0 0.0 1.0" pos="-0.19490347802639008 -0.13214513659477234 0.003795334603637457" limited="true" name="microjoint" range="-1.5707963267948966 0.0" type="hinge" damping="1" frictionloss="1" armature=".01" stiffness="0.05"/>
          <geom mesh="door_vis" type="mesh" solimp="0.998 0.998 0.001" solref="0.001 1" density="100" friction="0.95 0.3 0.1" class="visual" material="door_material"/>
          <geom class="collision" type="box" pos="-0.03461475670337677 -0.13503505289554596 0.003286900231614709" size="0.17200621962547302 0.011605629697442055 0.1233435869216919" quat="1.0 0.0 0.0 0.0"/>
          <geom class="collision" type="box" pos="0.12603279948234558 -0.17740680277347565 0.01427589450031519" size="0.005254993215203285 0.0014122388092800975 0.062476806342601776" quat="1.0 0.0 0.0 0.0" name="door_handle"/>
          <geom class="collision" type="box" pos="0.12603279948234558 -0.14955738186836243 0.0978788435459137" size="0.0052550071850419044 0.002864970825612545 0.001412239857017994" quat="1.0 0.0 0.0 0.0"/>
          <geom class="collision" type="box" pos="0.12603279948234558 -0.1557542085647583 0.09720427542924881" size="0.0052550071850419044 0.0035753746051341295 0.001412239740602672" quat="0.9961947202682495 0.08715573698282242 0.0 0.0"/>
          <geom class="collision" type="box" pos="0.12603279948234558 -0.16232790052890778 0.09527873247861862" size="0.0052550071850419044 0.0035753746051341295 0.001412239857017994" quat="0.9762960076332092 0.2164396047592163 0.0 0.0"/>
          <geom class="collision" type="box" pos="0.12603279948234558 -0.16795040667057037 0.09179335087537766" size="0.0052550071850419044 0.0035753746051341295 0.001412239857017994" quat="0.9396926164627075 0.3420201539993286 0.0 0.0"/>
          <geom class="collision" type="box" pos="0.12603279948234558 -0.17258590459823608 0.08685877174139023" size="0.0052550071850419044 0.003575374837964773 0.001412239857017994" quat="0.8870107531547546 0.46174874901771545 0.0 0.0"/>
          <geom class="collision" type="box" pos="0.12603279948234558 -0.17569993436336517 0.08061955124139786" size="0.0052550071850419044 0.0035753746051341295 0.001412239857017994" quat="0.8191520571708679 0.5735764503479004 0.0 0.0"/>
          <geom class="collision" type="box" pos="0.12603279948234558 -0.17569993436336517 -0.05230771377682686" size="0.0052550071850419044 0.0035753746051341295 0.001412239857017994" quat="0.8191520571708679 -0.5735764503479004 -0.0 0.0"/>
          <geom class="collision" type="box" pos="0.12603279948234558 -0.17258590459823608 -0.05854693427681923" size="0.0052550071850419044 0.003575374837964773 0.001412239857017994" quat="0.8870107531547546 -0.46174874901771545 -0.0 0.0"/>
          <geom class="collision" type="box" pos="0.12603279948234558 -0.16795040667057037 -0.06348151713609695" size="0.0052550071850419044 0.0035753746051341295 0.001412239857017994" quat="0.9396926164627075 -0.3420201539993286 -0.0 0.0"/>
          <geom class="collision" type="box" pos="0.12603279948234558 -0.1557542085647583 -0.06889244168996811" size="0.0052550071850419044 0.0035753746051341295 0.001412239740602672" quat="0.9961947202682495 -0.08715573698282242 -0.0 0.0"/>
          <geom class="collision" type="box" pos="0.12603279948234558 -0.16232790052890778 -0.06696689873933792" size="0.0052550071850419044 0.0035753746051341295 0.001412239857017994" quat="0.9762960076332092 -0.2164396047592163 -0.0 0.0"/>
          <geom class="collision" type="box" pos="0.12603279948234558 -0.14955738186836243 -0.0695670023560524" size="0.0052550071850419044 0.002864970825612545 0.001412239857017994" quat="1.0 0.0 0.0 0.0"/>
          <body name="door_Clear">
            <geom mesh="door_Clear_vis" type="mesh" solimp="0.998 0.998 0.001" solref="0.001 1" density="100" friction="0.95 0.3 0.1" class="visual" material="door_Clear_material"/>
            <geom class="collision" type="box" pos="-0.03762907534837723 -0.1422935575246811 0.003795329947024584" size="0.13983526825904846 0.0009526921785436571 0.07724489271640778" quat="1.0 0.0 0.0 0.0"/>
          </body>
        </body>
        <body name="Disc001">
          <joint axis="0.0 0.0 -1.0" pos="-0.036365509033203125 0.009838864207267761 -0.07034800201654434" limited="false" name="Disc001_joint" range="0 360" type="hinge" damping="1" frictionloss="1" armature=".01" stiffness="0.05"/>
          <geom mesh="Disc001_vis" type="mesh" solimp="0.998 0.998 0.001" solref="0.001 1" density="100" friction="0.95 0.3 0.1" class="visual" material="Disc001_material"/>
          <geom class="collision" type="cylinder" pos="-0.03636551275849342 0.009838864207267761 -0.06935924291610718" size="0.11146734654903412 0.001351660117506981" quat="1.0 0.0 0.0 0.0"/>
        </body>
        <geom class="region" name="reg_main" type="box" pos="0.0 0.016092151403427124 0.0" size="0.21252620220184326 0.16272689402103424 0.12764734029769897"/>
        <geom class="region" name="reg_int" type="box" pos="-0.03802519664168358 0.004330195486545563 0.0035058483481407166" size="0.13771483674645424 0.1168738454580307 0.07589094340801239"/>
      </body>
    </body>
  </worldbody>
  <actuator>
    <motor name="microjoint_actuator" joint="microjoint" gear="10"/>
    <motor name="Disc001_joint_actuator" joint="Disc001_joint" gear="10"/>
  </actuator>
</mujoco>
