<mujoco model="model">
  <compiler angle="radian"/>
  <asset>
    <mesh file="visuals/Blade001.obj" name="Blade001_vis"/>
    <mesh file="visuals/Body001.obj" name="Body001_vis"/>
    <mesh file="visuals/Button001.obj" name="Button001_vis"/>
    <mesh file="visuals/Jug001.obj" name="Jug001_vis"/>
    <mesh file="visuals/Jug001_Clear.obj" name="Jug001_Clear_vis"/>
    <mesh file="visuals/Knob001.obj" name="Knob001_vis"/>
    <mesh file="visuals/Lid001.obj" name="Lid001_vis"/>
    <texture file="visuals/T_BC001.png" name="Body001_material" type="2d"/>
    <material name="Body001_material" rgba="1 1 1 1.0" texture="Body001_material" shininess="-1.0" specular="0.3103448502657381"/>
    <texture file="visuals/T_BC001.png" name="Button001_material" type="2d"/>
    <material name="Button001_material" rgba="1 1 1 1.0" texture="Button001_material" shininess="-1.0" specular="0.3103448502657381"/>
    <texture file="visuals/T_BC001.png" name="Jug001_Clear_material" type="2d"/>
    <material name="Jug001_Clear_material" rgba="1 1 1 0.10000000149011612" texture="Jug001_Clear_material" shininess="-1.0" specular="0.3103448502657381"/>
    <texture file="visuals/T_BC001.png" name="Blade001_material" type="2d"/>
    <material name="Blade001_material" rgba="1 1 1 1.0" texture="Blade001_material" shininess="-1.0" specular="20"/>
    <texture file="visuals/T_BC001.png" name="Jug001_material" type="2d"/>
    <material name="Jug001_material" rgba="1 1 1 1.0" texture="Jug001_material" shininess="-1.0" specular="0.3103448502657381"/>
    <texture file="visuals/T_BC001.png" name="Lid001_material" type="2d"/>
    <material name="Lid001_material" rgba="1 1 1 1.0" texture="Lid001_material" shininess="-1.0" specular="0.3103448502657381"/>
    <texture file="visuals/T_BC001.png" name="Knob001_material" type="2d"/>
    <material name="Knob001_material" rgba="1 1 1 1.0" texture="Knob001_material" shininess="-1.0" specular="0.3103448502657381"/>
  </asset>
  <default>
    <default class="visual">
      <geom conaffinity="0" contype="0" group="1" type="mesh"/>
    </default>
    <default class="collision">
      <geom group="0" rgba="0.5 0 0 0.5"/>
    </default>
    <default class="spawn">
      <geom group="0" rgba="1 1 1 0.5" contype="0" conaffinity="0"/>
      <site group="0" rgba="1 1 1 0.5"/>
    </default>
    <default class="region">
      <geom group="1" conaffinity="0" contype="0" rgba="0 1 0 0"/>
    </default>
  </default>
  <worldbody>
    <body>
      <body name="object">
        <geom mesh="Body001_vis" type="mesh" solimp="0.998 0.998 0.001" solref="0.001 1" density="100" friction="0.95 0.3 0.1" class="visual" material="Body001_material"/>
        <geom class="collision" type="cylinder" pos="-0.017104 0.010298 -0.243621" size="0.11577003449201584 0.0249093659222126" quat="1.0 0.0 0.0 0.0"/>
        <geom class="collision" type="cylinder" pos="-0.017104 0.010298 -0.150437" size="0.0996200293302536 0.0757393166422844" quat="1.0 0.0 0.0 0.0"/>
        <geom class="collision" type="cylinder" pos="-0.017104 0.010298 -0.053235" size="0.08248960971832275 0.023709116503596306" quat="1.0 0.0 0.0 0.0"/>
        <body name="Button001">
          <joint axis="0.0 1.0 0.0" pos="-0.072136 -0.083158 -0.167684" limited="true" name="Button001_joint" range="0.0 0.001" type="slide" damping="1" frictionloss="1" armature=".01" stiffness="0.05"/>
          <geom mesh="Button001_vis" type="mesh" solimp="0.998 0.998 0.001" solref="0.001 1" density="100" friction="0.95 0.3 0.1" class="visual" material="Button001_material"/>
        </body>
        <body name="Jug001_Clear">
          <joint axis="0.0 0.0 1.0" pos="0.004362 0.009059 0.108097" limited="true" name="Jug001_Clear_joint" range="0.0 0.1" type="slide" damping="1" frictionloss="1" armature=".01" stiffness="0.05"/>
          <geom mesh="Jug001_Clear_vis" type="mesh" solimp="0.998 0.998 0.001" solref="0.001 1" density="100" friction="0.95 0.3 0.1" class="visual" material="Jug001_Clear_material"/>
          <geom class="collision" type="box" pos="0.108075 0.009078 0.205149" size="0.010490579530596733 0.01306664478033781 0.012952008284628391" quat="0.8922321200370789 0.0 -0.4515770375728607 0.0"/>
          <geom class="collision" type="box" pos="0.089010 0.009078 0.209398" size="0.010490579530596733 0.01306664478033781 0.014333631843328476" quat="0.7071068286895752 0.0 -0.7071067690849304 0.0"/>
          <geom class="collision" type="box" pos="0.119538 0.009078 0.185501" size="0.010490579530596733 0.01306664478033781 0.017087645828723907" quat="0.9909359216690063 0.0 -0.13433536887168884 0.0"/>
          <geom class="collision" type="box" pos="0.116732 0.009078 0.107882" size="0.010490579530596733 0.01306664478033781 0.025639450177550316" quat="0.9911426305770874 0.0 0.13280166685581207 0.0"/>
          <geom class="collision" type="box" pos="0.123259 0.009078 0.150514" size="0.010490579530596733 0.01306664478033781 0.023151246830821037" quat="0.9999921321868896 0.0 -0.003964924719184637 0.0"/>
          <geom class="collision" type="box" pos="0.096966 0.009078 0.067914" size="0.010490579530596733 0.01306664478033781 0.025639450177550316" quat="0.9335750341415405 0.0 0.35838204622268677 0.0"/>
          <geom class="collision" type="box" pos="0.072245 0.009078 0.049294" size="0.010490579530596733 0.01306664478033781 0.015172729268670082" quat="0.7355284094810486 0.0 0.6774938702583313 0.0"/>
          <geom class="collision" type="box" pos="-0.007907 -0.065869 0.119786" size="0.030166035518050194 0.009558545425534248 0.12247002869844437" quat="0.996038019657135 0.0562993586063385 0.003884746227413416 0.0687282532453537"/>
          <geom class="collision" type="box" pos="-0.060139 -0.053848 0.119786" size="0.030166039243340492 0.009558546356856823 0.12247002124786377" quat="0.9557594060897827 0.05402259901165962 -0.016317427158355713 -0.2886854112148285"/>
          <geom class="collision" type="box" pos="-0.091081 -0.010997 0.119786" size="0.030166039243340492 0.009558545425534248 0.12247002124786377" quat="0.7946256399154663 0.04491480067372322 -0.03416666015982628 -0.6044712066650391"/>
          <geom class="collision" type="box" pos="-0.085831 0.042826 0.119786" size="0.030166035518050194 0.009558546356856823 0.12247002869844437" quat="0.5259811878204346 0.02973017282783985 -0.04796688258647919 -0.8486219048500061"/>
          <geom class="collision" type="box" pos="-0.048580 0.078299 0.119786" size="0.030166039243340492 0.009558545425534248 0.12247002124786377" quat="0.2060254067182541 0.011645224876701832 -0.055218569934368134 -0.9769180417060852"/>
          <geom class="collision" type="box" pos="0.002517 0.081803 0.119786" size="0.030166039243340492 0.009558545425534248 0.12247002869844437" quat="0.13694703578948975 0.007740695495158434 0.05589979141950607 0.9889695644378662"/>
          <geom class="collision" type="box" pos="0.042871 0.053717 0.119786" size="0.030166039243340492 0.009558545425534248 0.12247002869844437" quat="0.45098650455474854 0.02549123205244541 0.050347812473773956 0.8907449245452881"/>
          <geom class="collision" type="box" pos="0.057375 0.005387 0.119786" size="0.030166039243340492 0.009558545425534248 0.12247002869844437" quat="0.7223079204559326 0.0408271960914135 0.03895952180027962 0.689265251159668"/>
          <geom class="collision" type="box" pos="0.039275 -0.040138 0.119786" size="0.030166035518050194 0.009558546356856823 0.12247002869844437" quat="0.9066253304481506 0.05124542862176895 0.023634959012269974 0.41814568638801575"/>
          <body name="Blade001">
            <joint axis="0.0 0.0 1.0" pos="-0.015873 0.009358 0.000648" limited="false" name="Blade001_joint" range="0 360" type="hinge" damping="1" frictionloss="1" armature=".01" stiffness="0.05"/>
            <geom mesh="Blade001_vis" type="mesh" solimp="0.998 0.998 0.001" solref="0.001 1" density="100" friction="0.95 0.3 0.1" class="visual" material="Blade001_material"/>
            <geom class="collision" type="box" pos="-0.044031 -0.001564 -0.011177" size="0.007543550338596106 0.0059546735137701035 0.000863152788951993" quat="0.9321237802505493 -0.06661441922187805 -0.2755560278892517 0.2253367006778717"/>
            <geom class="collision" type="box" pos="-0.019941 0.026339 0.006357" size="0.008318131789565086 0.01207124162465334 0.0010331370867788792" quat="0.9443404674530029 0.2828863859176636 -0.048185814172029495 0.16085538268089294"/>
            <geom class="collision" type="box" pos="-0.032033 0.005936 -0.003404" size="0.01066170446574688 0.008802132681012154 0.0008631527307443321" quat="0.9462018013000488 -0.04611463472247124 -0.2797178030014038 0.1559920310974121"/>
            <geom class="collision" type="box" pos="-0.002232 0.011535 -0.000441" size="0.007543550338596106 0.00848355796188116 0.000863152788951993" quat="0.9773774147033691 0.02403903566300869 0.151308074593544 0.14581291377544403"/>
            <geom class="collision" type="box" pos="0.011731 0.020469 -0.004836" size="0.011898030526936054 0.006339432671666145 0.0008631530799902976" quat="0.949954628944397 0.04359858110547066 0.1468711495399475 0.27223920822143555"/>
            <geom class="collision" type="box" pos="-0.016541 0.009649 -0.003776" size="0.010661705397069454 0.010661705397069454 0.006958658341318369" quat="1.0 0.0 0.0 0.0"/>
            <geom class="collision" type="box" pos="-0.027135 0.037302 0.013572" size="0.005351291038095951 0.01207124162465334 0.0010331370867788792" quat="0.9085248112678528 0.2721574008464813 -0.09097743034362793 0.3037039339542389"/>
            <geom class="collision" type="box" pos="-0.004975 -0.019220 0.007755" size="0.005351291038095951 0.011837908066809177 0.0010331370867788792" quat="0.4182606339454651 -0.07813757658004761 -0.13567319512367249 -0.8947319984436035"/>
            <geom class="collision" type="box" pos="-0.013556 -0.007303 0.003857" size="0.008318132720887661 0.012071240693330765 0.0010331370867788792" quat="0.2761724889278412 -0.056418295949697495 -0.14604680240154266 -0.9482700228691101"/>
          </body>
          <body name="Jug001">
            <geom mesh="Jug001_vis" type="mesh" solimp="0.998 0.998 0.001" solref="0.001 1" density="100" friction="0.95 0.3 0.1" class="visual" material="Jug001_material"/>
            <geom class="collision" type="cylinder" pos="-0.017104 0.010298 -0.021924" size="0.05342128127813339 0.003904070006683469" quat="1.0 0.0 0.0 0.0"/>
          </body>
          <body name="Lid001">
            <joint axis="0.0 0.0 1.0" pos="-0.025278 0.010196 0.244185" limited="true" name="Lid001_joint" range="0.0 0.06" type="slide" damping="1" frictionloss="1" armature=".01" stiffness="0.05"/>
            <geom mesh="Lid001_vis" type="mesh" solimp="0.998 0.998 0.001" solref="0.001 1" density="100" friction="0.95 0.3 0.1" class="visual" material="Lid001_material"/>
            <geom class="collision" type="cylinder" pos="-0.017104 0.010298 0.261739" size="0.029718130826950073 0.006639882456511259" quat="1.0 0.0 0.0 0.0"/>
            <geom class="collision" type="cylinder" pos="-0.017104 0.010298 0.250097" size="0.09667138755321503 0.006559877656400204" quat="1.0 0.0 0.0 0.0"/>
          </body>
        </body>
        <body name="Knob001">
          <joint axis="0.0 1.0 0.0" pos="-0.017503 -0.108299 -0.168722" limited="true" name="Knob001_joint" range="0.0 4.81710873550435" type="hinge" damping="1" frictionloss="1" armature=".01" stiffness="0.05"/>
          <geom mesh="Knob001_vis" type="mesh" solimp="0.998 0.998 0.001" solref="0.001 1" density="100" friction="0.95 0.3 0.1" class="visual" material="Knob001_material"/>
          <geom class="collision" type="cylinder" pos="-0.017495 -0.107929 -0.168310" size="0.03693224489688873 0.01709366776049137" quat="0.7071068286895752 0.7071067690849304 0.0 0.0"/>
        </body>
        <geom class="region" name="reg_main" type="box" pos="0.0 -5.000000000005e-07 -0.00021699999999999497" size="0.132501 0.12504949999999998 0.268332"/>
      </body>
    </body>
  </worldbody>
  <actuator>
    <motor name="Button001_joint_actuator" joint="Button001_joint" gear="0.5"/>
    <motor name="Jug001_Clear_joint_actuator" joint="Jug001_Clear_joint" gear="50"/>
    <motor name="Knob001_joint_actuator" joint="Knob001_joint" gear="50"/>
    <motor name="Blade001_joint_actuator" joint="Blade001_joint" gear="50"/>
    <motor name="Lid001_joint_actuator" joint="Lid001_joint" gear="50"/>
  </actuator>
</mujoco>
