<mujoco model="model">
  <compiler angle="radian"/>
  <asset>
    <mesh file="visuals/Body001.obj" name="Body001_vis"/>
    <mesh file="visuals/Button001.obj" name="Button001_vis"/>
    <mesh file="visuals/Container001.obj" name="Container001_vis"/>
    <mesh file="visuals/Door001.001.obj" name="Door001.001_vis"/>
    <mesh file="visuals/Door001.obj" name="Door001_vis"/>
    <mesh file="visuals/Door001_Clear.obj" name="Door001_Clear_vis"/>
    <mesh file="visuals/Knob001.obj" name="Knob001_vis"/>
    <mesh file="visuals/Knob002.obj" name="Knob002_vis"/>
    <mesh file="visuals/Knob003.obj" name="Knob003_vis"/>
    <mesh file="visuals/Knob004.obj" name="Knob004_vis"/>
    <mesh file="visuals/Shelf001.obj" name="Shelf001_vis"/>
    <texture file="visuals/T_BC001.png" name="Body001_material" type="2d"/>
    <material name="Body001_material" rgba="1 1 1 1.0" texture="Body001_material" shininess="0.2512328028678894" specular="0.3103448502657381"/>
    <texture file="visuals/T_BC001.png" name="Button001_material" type="2d"/>
    <material name="Button001_material" rgba="1 1 1 1.0" texture="Button001_material" shininess="0.2512328028678894" specular="0.3103448502657381"/>
    <texture file="visuals/T_BC001.png" name="Container001_material" type="2d"/>
    <material name="Container001_material" rgba="1 1 1 1.0" texture="Container001_material" shininess="0.2512328028678894" specular="0.3103448502657381"/>
    <texture file="visuals/T_BC001.png" name="Door001_material" type="2d"/>
    <material name="Door001_material" rgba="1 1 1 1.0" texture="Door001_material" shininess="0.2512328028678894" specular="0.3103448502657381"/>
    <texture file="visuals/T_BC001.png" name="Door001_Clear_material" type="2d"/>
    <material name="Door001_Clear_material" rgba="1 1 1 0.586021900177002" texture="Door001_Clear_material" shininess="0.2512328028678894" specular="0.3103448502657381"/>
    <texture file="visuals/T_BC001.png" name="Knob001_material" type="2d"/>
    <material name="Knob001_material" rgba="1 1 1 1.0" texture="Knob001_material" shininess="0.2512328028678894" specular="0.3103448502657381"/>
    <texture file="visuals/T_BC001.png" name="Knob002_material" type="2d"/>
    <material name="Knob002_material" rgba="1 1 1 1.0" texture="Knob002_material" shininess="0.2512328028678894" specular="0.3103448502657381"/>
    <texture file="visuals/T_BC001.png" name="Knob003_material" type="2d"/>
    <material name="Knob003_material" rgba="1 1 1 1.0" texture="Knob003_material" shininess="0.2512328028678894" specular="0.3103448502657381"/>
    <texture file="visuals/T_BC001.png" name="Knob004_material" type="2d"/>
    <material name="Knob004_material" rgba="1 1 1 1.0" texture="Knob004_material" shininess="0.2512328028678894" specular="0.3103448502657381"/>
    <texture file="visuals/T_BC001.png" name="Shelf001_material" type="2d"/>
    <material name="Shelf001_material" rgba="1 1 1 1.0" texture="Shelf001_material" shininess="0.2512328028678894" specular="0.3103448502657381"/>
  </asset>
  <default>
    <default class="visual">
      <geom conaffinity="0" contype="0" group="1" type="mesh"/>
    </default>
    <default class="collision">
      <geom group="0" rgba="0.5 0 0 0.5"/>
    </default>
    <default class="spawn">
      <geom group="0" rgba="1 1 1 0.5" contype="0" conaffinity="0"/>
      <site group="0" rgba="1 1 1 0.5"/>
    </default>
    <default class="region">
      <geom group="1" conaffinity="0" contype="0" rgba="0 1 0 0"/>
    </default>
  </default>
  <worldbody>
    <body>
      <body name="object">
        <geom mesh="Body001_vis" type="mesh" solimp="0.998 0.998 0.001" solref="0.001 1" density="100" friction="0.95 0.3 0.1" class="visual" material="Body001_material"/>
        <geom class="collision" type="box" pos="-0.3550794720649719 0.05530204623937607 0.01423376053571701" size="0.05505045875906944 0.27127689123153687 0.3279729187488556" quat="1.0 0.0 0.0 0.0"/>
        <geom class="collision" type="box" pos="0.01330062560737133 0.05530204623937607 -0.2817709147930145" size="0.30019262433052063 0.2712770998477936 0.03331492841243744" quat="1.0 0.0 0.0 0.0"/>
        <geom class="collision" type="box" pos="0.35432878136634827 0.05544929578900337 0.015737120062112808" size="0.05505051091313362 0.2712773084640503 0.327973335981369" quat="1.0 0.0 0.0 0.0"/>
        <geom class="collision" type="box" pos="-0.0003753461642190814 0.05537567660212517 0.2035246044397354" size="0.40974971652030945 0.27135106921195984 0.15088705718517303" quat="1.0 0.0 0.0 0.0"/>
        <geom class="collision" type="box" pos="-0.00037534430157393217 -0.23091892898082733 0.2280452400445938" size="0.3754713237285614 0.013311764225363731 0.09936340898275375" quat="1.0 0.0 0.0 0.0"/>
        <geom class="collision" type="cylinder" pos="0.31834080815315247 -0.14341618120670319 -0.3347505033016205" size="0.024599812924861908 0.019663896411657333" quat="7.549790126404332e-08 -1.0 -0.0 0.0"/>
        <geom class="collision" type="cylinder" pos="-0.32112810015678406 -0.14341618120670319 -0.3347505033016205" size="0.024599812924861908 0.019663896411657333" quat="7.549790126404332e-08 -1.0 -0.0 0.0"/>
        <geom class="collision" type="cylinder" pos="0.31834080815315247 0.24488861858844757 -0.3347505033016205" size="0.024599812924861908 0.019663896411657333" quat="7.549790126404332e-08 -1.0 -0.0 0.0"/>
        <geom class="collision" type="cylinder" pos="-0.32112810015678406 0.24488861858844757 -0.3347505033016205" size="0.024599812924861908 0.019663896411657333" quat="7.549790126404332e-08 -1.0 -0.0 0.0"/>
        <geom class="collision" type="box" pos="0.013300621882081032 0.21676991879940033 -0.09791024029254913" size="0.3001976013183594 0.10981497913599014 0.15054459869861603" quat="1.0 0.0 0.0 0.0"/>
        <body name="Button001">
          <joint axis="0.0 1.0 0.0" pos="0.3146982491016388 -0.25854599475860596 0.23059013485908508" limited="true" name="Button001_joint" range="0.0 0.002" type="slide" damping="1" frictionloss="1" armature=".01" stiffness="0.05"/>
          <geom mesh="Button001_vis" type="mesh" solimp="0.998 0.998 0.001" solref="0.001 1" density="100" friction="0.95 0.3 0.1" class="visual" material="Button001_material"/>
          <geom class="collision" type="box" pos="0.31405720114707947 -0.2576240599155426 0.23078547418117523" size="0.009057222865521908 0.002362209837883711 0.012157456949353218" quat="1.0 0.0 0.0 0.0"/>
          <geom class="collision" type="box" pos="0.3264957070350647 -0.2576240599155426 0.23078548908233643" size="0.003381385002285242 0.002362208440899849 0.0087867621332407" quat="1.0 0.0 0.0 0.0"/>
          <geom class="collision" type="box" pos="0.30226147174835205 -0.2576240599155426 0.23078548908233643" size="0.002800926100462675 0.0023622065782546997 0.008786754682660103" quat="1.0 0.0 0.0 0.0"/>
        </body>
        <body name="Container001">
          <joint axis="0.0 -1.0 0.0" pos="-0.002430705586448312 -0.06614194065332413 -0.09172055870294571" limited="true" name="Container001_joint" range="0.0 0.15" type="slide" damping="1" frictionloss="1" armature=".01" stiffness="0.05"/>
          <geom mesh="Container001_vis" type="mesh" solimp="0.998 0.998 0.001" solref="0.001 1" density="100" friction="0.95 0.3 0.1" class="visual" material="Container001_material"/>
          <geom class="collision" type="box" pos="-0.001733607379719615 -0.06703557819128036 -0.09780487418174744" size="0.28812915086746216 0.09547343850135803 0.02181098610162735" quat="1.0 0.0 0.0 0.0"/>
        </body>
        <body name="Door001">
          <joint axis="1.0 0.0 0.0" pos="5.662441253662109e-07 -0.2309364378452301 -0.2542535960674286" limited="true" name="Door001_joint" range="0.0 1.5707963267948966" type="hinge" damping="1" frictionloss="1" armature=".01" stiffness="0.8" springref="-1"/>
          <geom mesh="Door001_vis" type="mesh" solimp="0.998 0.998 0.001" solref="0.001 1" density="100" friction="0.95 0.3 0.1" class="visual" material="Door001_material"/>
          <geom class="collision" type="box" pos="-0.0039738137274980545 -0.23091892898082733 0.09128674864768982" size="0.3886701166629791 0.0133118387311697 0.025664666667580605" quat="1.0 0.0 0.0 0.0"/>
          <geom class="collision" type="box" pos="-0.35790637135505676 -0.23091892898082733 -0.08848544210195541" size="0.03474030643701553 0.013311848044395447 0.15886850655078888" quat="1.0 0.0 0.0 0.0"/>
          <geom class="collision" type="box" pos="0.34896087646484375 -0.23091892898082733 -0.08848544210195541" size="0.03474033623933792 0.013311854563653469 0.15886861085891724" quat="1.0 0.0 0.0 0.0"/>
          <geom class="collision" type="box" pos="0.35255375504493713 -0.257743775844574 0.09920641779899597" size="0.023440957069396973 0.013744233176112175 0.021145589649677277" quat="1.0 0.0 0.0 0.0"/>
          <geom class="collision" type="box" pos="-0.3525537848472595 -0.257743775844574 0.09920641779899597" size="0.023441074416041374 0.013744239695370197 0.021145600825548172" quat="1.0 0.0 0.0 0.0"/>
          <geom class="collision" type="box" pos="0.19445963203907013 -0.2951712906360626 0.09920641779899597" size="0.021145718172192574 0.013744303025305271 0.1329551339149475" quat="0.7042938470840454 0.06300976872444153 -0.7042937874794006 0.06300976127386093"/>
          <geom class="collision" type="box" pos="-0.19672182202339172 -0.2951712906360626 0.09920641779899597" size="0.021145718172192574 0.013744303956627846 0.1329551339149475" quat="0.7042938470840454 -0.06300957500934601 -0.7042937874794006 -0.06300956755876541"/>
          <geom class="collision" type="box" pos="-0.005806652829051018 -0.3062925636768341 0.09920641779899597" size="0.07425907254219055 0.019304824993014336 0.021145615726709366" quat="1.0 0.0 0.0 0.0"/>
          <body name="Door001_Clear">
            <geom mesh="Door001_Clear_vis" type="mesh" solimp="0.998 0.998 0.001" solref="0.001 1" density="100" friction="0.95 0.3 0.1" class="visual" material="Door001_Clear_material"/>
            <geom class="collision" type="box" pos="-0.0003499195445328951 -0.2235126495361328 -0.08473260700702667" size="0.3064973056316376 0.003752752672880888 0.13884639739990234" quat="1.0 0.0 0.0 0.0"/>
          </body>
        </body>
        <body name="Knob001">
          <joint axis="0.0 1.0 0.0" pos="-0.22405008971691132 -0.2695924639701843 0.22957409918308258" limited="true" name="Knob001_joint" range="0.0 4.71238898038469" type="hinge" damping="1" frictionloss="1" armature=".01" stiffness="0.05"/>
          <geom mesh="Knob001_vis" type="mesh" solimp="0.998 0.998 0.001" solref="0.001 1" density="100" friction="0.95 0.3 0.1" class="visual" material="Knob001_material"/>
          <geom class="collision" type="cylinder" pos="-0.22411006689071655 -0.2619580924510956 0.22902646660804749" size="0.03739810362458229 0.004008350428193808" quat="0.7071067094802856 0.7071068286895752 0.0 0.0"/>
          <geom class="collision" type="box" pos="-0.22427600622177124 -0.27465754747390747 0.2275896668434143" size="0.01063434686511755 0.008691221475601196 0.03324195370078087" quat="1.0 0.0 0.0 0.0"/>
        </body>
        <body name="Knob002">
          <joint axis="0.0 1.0 0.0" pos="-0.07669051736593246 -0.2695924639701843 0.22957409918308258" limited="true" name="Knob002_joint" range="0.0 3.141592653589793" type="hinge" damping="1" frictionloss="1" armature=".01" stiffness="0.05"/>
          <geom mesh="Knob002_vis" type="mesh" solimp="0.998 0.998 0.001" solref="0.001 1" density="100" friction="0.95 0.3 0.1" class="visual" material="Knob002_material"/>
          <geom class="collision" type="cylinder" pos="-0.07658664137125015 -0.2619580924510956 0.22902646660804749" size="0.03739810362458229 0.004008350428193808" quat="0.7071067094802856 0.7071068286895752 0.0 0.0"/>
          <geom class="collision" type="box" pos="-0.07224148511886597 -0.27465754747390747 0.22926822304725647" size="0.033241983503103256 0.008691229857504368 0.01063435710966587" quat="1.0 0.0 0.0 0.0"/>
        </body>
        <body name="Knob003">
          <joint axis="0.0 1.0 0.0" pos="0.070595383644104 -0.2695924639701843 0.22957409918308258" limited="true" name="Knob003_joint" range="0.0 3.141592653589793" type="hinge" damping="1" frictionloss="1" armature=".01" stiffness="0.05"/>
          <geom mesh="Knob003_vis" type="mesh" solimp="0.998 0.998 0.001" solref="0.001 1" density="100" friction="0.95 0.3 0.1" class="visual" material="Knob003_material"/>
          <geom class="collision" type="cylinder" pos="0.07020571827888489 -0.2619580924510956 0.22948023676872253" size="0.03739810362458229 0.004008350428193808" quat="0.7071067094802856 0.7071068286895752 0.0 0.0"/>
          <geom class="collision" type="box" pos="0.0756293460726738 -0.27465754747390747 0.22955413162708282" size="0.033242009580135345 0.00869123637676239 0.010634364560246468" quat="1.0 0.0 0.0 0.0"/>
        </body>
        <body name="Knob004">
          <joint axis="0.0 1.0 0.0" pos="0.21739795804023743 -0.2695924639701843 0.22957409918308258" limited="true" name="Knob004_joint" range="0.0 4.1887902047863905" type="hinge" damping="1" frictionloss="1" armature=".01" stiffness="0.05"/>
          <geom mesh="Knob004_vis" type="mesh" solimp="0.998 0.998 0.001" solref="0.001 1" density="100" friction="0.95 0.3 0.1" class="visual" material="Knob004_material"/>
          <geom class="collision" type="cylinder" pos="0.21738289296627045 -0.2619580924510956 0.22948023676872253" size="0.03739810362458229 0.004008350428193808" quat="0.7071067094802856 0.7071068286895752 0.0 0.0"/>
          <geom class="collision" type="box" pos="0.21721693873405457 -0.27465754747390747 0.22804343700408936" size="0.010634368285536766 0.008691242896020412 0.033242035657167435" quat="1.0 0.0 0.0 0.0"/>
        </body>
        <body name="Shelf001">
          <joint axis="0.0 -1.0 0.0" pos="0.0016162358224391937 -0.06778070330619812 -0.1922188699245453" limited="true" name="Shelf001_joint" range="0.0 0.15" type="slide" damping="1" frictionloss="1" armature=".01" stiffness="0.05"/>
          <geom mesh="Shelf001_vis" type="mesh" solimp="0.998 0.998 0.001" solref="0.001 1" density="100" friction="0.95 0.3 0.1" class="visual" material="Shelf001_material"/>
          <geom class="collision" type="box" pos="0.0011112364009022713 -0.06730316579341888 -0.2058584988117218" size="0.27866747975349426 0.10852125287055969 0.004268546123057604" quat="1.0 0.0 0.0 0.0"/>
          <geom class="collision" type="box" pos="-0.27432969212532043 -0.06730315089225769 -0.1828484684228897" size="0.004268570803105831 0.10852129012346268 0.019186941906809807" quat="1.0 0.0 0.0 0.0"/>
          <geom class="collision" type="box" pos="0.2761322855949402 -0.06730315089225769 -0.1828484684228897" size="0.004268576391041279 0.10852137953042984 0.019186964258551598" quat="1.0 0.0 0.0 0.0"/>
        </body>
        <geom class="region" name="reg_main_body" type="box" pos="-7.450580596923828e-09 0.035183221101760864 0.0" size="0.4201844036579132 0.2914019525051117 0.3544144332408905"/>
        <geom class="region" name="reg_int" type="box" pos="-0.00013051927089691162 -0.052296265959739685 -0.0989045724272728" size="0.2986011356115341 0.15628202259540558 0.16598422080278397"/>
      </body>
    </body>
  </worldbody>
  <actuator>
    <motor name="Button001_joint_actuator" joint="Button001_joint" gear="0.5"/>
    <motor name="Container001_joint_actuator" joint="Container001_joint" gear="10"/>
    <motor name="Door001_joint_actuator" joint="Door001_joint" gear="50"/>
    <motor name="Knob001_joint_actuator" joint="Knob001_joint" gear="50"/>
    <motor name="Knob002_joint_actuator" joint="Knob002_joint" gear="50"/>
    <motor name="Knob003_joint_actuator" joint="Knob003_joint" gear="50"/>
    <motor name="Knob004_joint_actuator" joint="Knob004_joint" gear="50"/>
    <motor name="Shelf001_joint_actuator" joint="Shelf001_joint" gear="50"/>
  </actuator>
</mujoco>
