<?xml version='1.0' encoding='utf-8'?>
<mujoco model="model">
    <compiler angle="radian" />
    <asset>
        <mesh file="visuals/CoffeeMachine086_Body001.obj" name="CoffeeMachine086_Body001_vis" />
        <mesh file="visuals/CoffeeMachine086_Button001.obj" name="CoffeeMachine086_Button001_vis" />
        <mesh file="visuals/CoffeeMachine086_Button002.obj" name="CoffeeMachine086_Button002_vis" />
        <mesh file="visuals/CoffeeMachine086_Button003.obj" name="CoffeeMachine086_Button003_vis" />
        <mesh file="visuals/CoffeeMachine086_Button004.obj" name="CoffeeMachine086_Button004_vis" />
        <mesh file="visuals/CoffeeMachine086_Container001_Clear.obj" name="CoffeeMachine086_Container001_Clear_vis" />
        <mesh file="visuals/CoffeeMachine086_Lever001.obj" name="CoffeeMachine086_Lever001_vis" />
        <mesh file="visuals/CoffeeMachine086_Lever002.obj" name="CoffeeMachine086_Lever002_vis" />
        <mesh file="visuals/CoffeeMachine086_Lid001.obj" name="CoffeeMachine086_Lid001_vis" />
        <mesh file="visuals/CoffeeMachine086_Lid002_Clear.obj" name="CoffeeMachine086_Lid002_Clear_vis" />
        <mesh file="visuals/CoffeeMachine086_Lid003.obj" name="CoffeeMachine086_Lid003_vis" />
        <texture file="visuals/T_CoffeeMachine086_BC001.png" name="CoffeeMachine086_Body001_material" type="2d" />
        <material name="CoffeeMachine086_Body001_material" rgba="1 1 1 1.0" texture="CoffeeMachine086_Body001_material" shininess="0.4472135901451111" specular="0.3103448502657381" />
        <texture file="visuals/T_CoffeeMachine086_BC001.png" name="CoffeeMachine086_Button001_material" type="2d" />
        <material name="CoffeeMachine086_Button001_material" rgba="1 1 1 1.0" texture="CoffeeMachine086_Button001_material" shininess="0.4472135901451111" specular="0.3103448502657381" />
        <texture file="visuals/T_CoffeeMachine086_BC001.png" name="CoffeeMachine086_Button002_material" type="2d" />
        <material name="CoffeeMachine086_Button002_material" rgba="1 1 1 1.0" texture="CoffeeMachine086_Button002_material" shininess="0.4472135901451111" specular="0.3103448502657381" />
        <texture file="visuals/T_CoffeeMachine086_BC001.png" name="CoffeeMachine086_Button003_material" type="2d" />
        <material name="CoffeeMachine086_Button003_material" rgba="1 1 1 1.0" texture="CoffeeMachine086_Button003_material" shininess="0.4472135901451111" specular="0.3103448502657381" />
        <texture file="visuals/T_CoffeeMachine086_BC001.png" name="CoffeeMachine086_Button004_material" type="2d" />
        <material name="CoffeeMachine086_Button004_material" rgba="1 1 1 1.0" texture="CoffeeMachine086_Button004_material" shininess="0.4472135901451111" specular="0.3103448502657381" />
        <texture file="visuals/T_CoffeeMachine086_BC001.png" name="CoffeeMachine086_Container001_Clear_material" type="2d" />
        <material name="CoffeeMachine086_Container001_Clear_material" rgba="1 1 1 0.24187728762626648" texture="CoffeeMachine086_Container001_Clear_material" shininess="0.4472135901451111" specular="0.3103448502657381" />
        <texture file="visuals/T_CoffeeMachine086_BC001.png" name="CoffeeMachine086_Lid002_Clear_material" type="2d" />
        <material name="CoffeeMachine086_Lid002_Clear_material" rgba="1 1 1 0.24187728762626648" texture="CoffeeMachine086_Lid002_Clear_material" shininess="0.4472135901451111" specular="0.3103448502657381" />
        <texture file="visuals/T_CoffeeMachine086_BC001.png" name="CoffeeMachine086_Lever001_material" type="2d" />
        <material name="CoffeeMachine086_Lever001_material" rgba="1 1 1 1.0" texture="CoffeeMachine086_Lever001_material" shininess="0.4472135901451111" specular="0.3103448502657381" />
        <texture file="visuals/T_CoffeeMachine086_BC001.png" name="CoffeeMachine086_Lever002_material" type="2d" />
        <material name="CoffeeMachine086_Lever002_material" rgba="1 1 1 1.0" texture="CoffeeMachine086_Lever002_material" shininess="0.4472135901451111" specular="0.3103448502657381" />
        <texture file="visuals/T_CoffeeMachine086_BC001.png" name="CoffeeMachine086_Lid001_material" type="2d" />
        <material name="CoffeeMachine086_Lid001_material" rgba="1 1 1 1.0" texture="CoffeeMachine086_Lid001_material" shininess="0.4472135901451111" specular="0.3103448502657381" />
        <texture file="visuals/T_CoffeeMachine086_BC001.png" name="CoffeeMachine086_Lid003_material" type="2d" />
        <material name="CoffeeMachine086_Lid003_material" rgba="1 1 1 1.0" texture="CoffeeMachine086_Lid003_material" shininess="0.4472135901451111" specular="0.3103448502657381" />
    </asset>
    <default>
        <default class="visual">
            <geom conaffinity="0" contype="0" group="1" type="mesh" />
        </default>
        <default class="collision">
            <geom group="0" rgba="0.5 0 0 0.5" />
    </default>
        <default class="spawn">
            <geom group="0" rgba="1 1 1 0.5" contype="0" conaffinity="0" />
            <site group="0" rgba="1 1 1 0.5" />
        </default>
    </default>
    <worldbody>
        <body>
            <site rgba="0 0 0 0.5" size="0.01" pos="-0.174636 -0.338145 -0.245112" name="ext_p0" />
            <site rgba="1 0 0 0.5" size="0.01" pos="0.175189 -0.338145 -0.245112" name="ext_px" />
            <site rgba="0 1 0 0.5" size="0.01" pos="-0.174636 0.326345 -0.245112" name="ext_py" />
            <site rgba="0 0 1 0.5" size="0.01" pos="-0.174636 -0.338145 0.244687" name="ext_pz" />
            <geom class="collision" type="box" pos="-0.109587 -0.173058 0.148473" size="0.018481513485312462 0.0012715308694168925 0.01872592233121395" quat="1.0 0.0 0.0 0.0" name="stop_button_1" rgba="0.0 0.5 0 0.5" />
            <geom class="collision" type="box" pos="-0.109587 -0.176358 0.148473" size="0.018481513485312462 0.0012715308694168925 0.01872592233121395" quat="1.0 0.0 0.0 0.0" name="start_button_1" rgba="0.0 0.5 0 0.5" />
            <geom class="collision" type="box" pos="-0.035011 -0.176358 0.148473" size="0.018481513485312462 0.0012715308694168925 0.01872592233121395" quat="1.0 0.0 0.0 0.0" name="start_button_2" rgba="0.0 0.5 0 0.5" />
            <geom class="collision" type="box" pos="-0.035011 -0.173058 0.148473" size="0.018481513485312462 0.0012715308694168925 0.01872592233121395" quat="1.0 0.0 0.0 0.0" name="stop_button_2" rgba="0.0 0.5 0 0.5" />
            <body name="object">
                <site type="cylinder" rgba="0.8 0.5 0.25 1" size="0.005838461220264435 0.07244577258825302" pos="-0.065841 -0.085230 -0.105613" name="coffee_liquid" />
                <site rgba="1 1 1 0.5" size="0.009999999776482582 0.009999999776482582" pos="-0.066560 -0.085727 -0.167931" name="receptable_place_site" />
                <geom mesh="CoffeeMachine086_Body001_vis" type="mesh" solimp="0.998 0.998 0.001" solref="0.001 1" density="100" friction="0.95 0.3 0.1" class="visual" material="CoffeeMachine086_Body001_material" />
                <geom class="collision" type="box" pos="-0.001163 -0.005091 -0.218430" size="0.17642024159431458 0.20682454109191895 0.026909422129392624" quat="1.0 0.0 0.0 0.0" />
                <geom class="collision" type="box" pos="0.168601 0.093015 0.025034" size="0.008983146399259567 0.10871749371290207 0.2143014520406723" quat="1.0 0.0 0.0 0.0" />
                <geom class="collision" type="box" pos="0.143811 -0.086514 0.140308" size="0.03258775547146797 0.07066439092159271 0.09978016465902328" quat="1.0 0.0 0.0 0.0" />
                <geom class="collision" type="box" pos="-0.157631 -0.086514 0.140308" size="0.01785922795534134 0.07066436856985092 0.0997801348567009" quat="1.0 0.0 0.0 0.0" />
                <geom class="collision" type="box" pos="0.035507 -0.148879 0.101701" size="0.12784676253795624 0.01095810066908598 0.05440106615424156" quat="1.0 0.0 0.0 0.0" />
                <geom class="collision" type="box" pos="-0.005876 0.192489 0.025034" size="0.16611431539058685 0.008983141742646694 0.2143014818429947" quat="1.0 0.0 0.0 0.0" />
                <geom class="collision" type="box" pos="-0.167841 0.093015 0.025034" size="0.008983146399259567 0.10871749371290207 0.2143014520406723" quat="1.0 0.0 0.0 0.0" />
                <geom class="collision" type="box" pos="0.000276 -0.071436 0.230841" size="0.17203819751739502 0.0848815068602562 0.011769748292863369" quat="1.0 0.0 0.0 0.0" />
                <geom class="collision" type="box" pos="-0.061179 -0.073225 0.134588" size="0.08678238838911057 0.0866703912615776 0.08549359440803528" quat="1.0 0.0 0.0 0.0" />
                <geom class="collision" type="box" pos="0.091048 -0.073225 0.187602" size="0.06870485097169876 0.0866703912615776 0.032479435205459595" quat="1.0 0.0 0.0 0.0" />
                <geom class="collision" type="box" pos="-0.003379 -0.009421 -0.071419" size="0.1721239686012268 0.00898314081132412 0.11784803122282028" quat="1.0 0.0 0.0 0.0" />
                <geom class="collision" type="box" pos="-0.003379 -0.083678 0.048325" size="0.1721239686012268 0.07390400767326355 0.008983148261904716" quat="1.0 0.0 0.0 0.0" />
                <geom class="collision" type="box" pos="-0.066423 -0.031697 0.021478" size="0.07347027212381363 0.07633064687252045 0.024022288620471954" quat="1.0 0.0 0.0 0.0" />
                <geom class="collision" type="cylinder" pos="-0.066725 -0.078281 0.021835" size="0.07261468470096588 0.02395540289580822" quat="1.0 0.0 0.0 0.0" />
                <body name="CoffeeMachine086_Button001">
                    <joint axis="0.0 1.0 0.0" pos="-0.069033 -0.171607 0.148803" limited="true" name="CoffeeMachine086_Button001_joint" range="0.0 0.003" type="slide" damping="1" frictionloss="1" armature=".01" stiffness="0.05" />
                    <geom mesh="CoffeeMachine086_Button001_vis" type="mesh" solimp="0.998 0.998 0.001" solref="0.001 1" density="100" friction="0.95 0.3 0.1" class="visual" material="CoffeeMachine086_Button001_material" />
                    <geom class="collision" type="box" pos="-0.109587 -0.168882 0.148473" size="0.018481513485312462 0.0023912638425827026 0.01872592233121395" quat="1.0 0.0 0.0 0.0" />
                </body>
                <body name="CoffeeMachine086_Button002">
                    <joint axis="0.0 1.0 0.0" pos="-0.022823 -0.171607 0.148803" limited="true" name="CoffeeMachine086_Button002_joint" range="0.0 0.003" type="slide" damping="1" frictionloss="1" armature=".01" stiffness="0.05" />
                    <geom mesh="CoffeeMachine086_Button002_vis" type="mesh" solimp="0.998 0.998 0.001" solref="0.001 1" density="100" friction="0.95 0.3 0.1" class="visual" material="CoffeeMachine086_Button002_material" />
                    <geom class="collision" type="box" pos="-0.034154 -0.169063 0.148473" size="0.018481513485312462 0.0022063704673200846 0.01872592233121395" quat="1.0 0.0 0.0 0.0" />
                </body>
                <body name="CoffeeMachine086_Button003">
                    <joint axis="0.0 1.0 0.0" pos="0.023386 -0.171607 0.148803" limited="true" name="CoffeeMachine086_Button003_joint" range="0.0 0.003" type="slide" damping="1" frictionloss="1" armature=".01" stiffness="0.05" />
                    <geom mesh="CoffeeMachine086_Button003_vis" type="mesh" solimp="0.998 0.998 0.001" solref="0.001 1" density="100" friction="0.95 0.3 0.1" class="visual" material="CoffeeMachine086_Button003_material" />
                    <geom class="collision" type="box" pos="0.036785 -0.171865 0.148473" size="0.018481513485312462 0.005007907748222351 0.01872592233121395" quat="1.0 0.0 0.0 0.0" />
                </body>
                <body name="CoffeeMachine086_Button004">
                    <joint axis="0.0 1.0 0.0" pos="0.069595 -0.171607 0.148803" limited="true" name="CoffeeMachine086_Button004_joint" range="0.0 0.003" type="slide" damping="1" frictionloss="1" armature=".01" stiffness="0.05" />
                    <geom mesh="CoffeeMachine086_Button004_vis" type="mesh" solimp="0.998 0.998 0.001" solref="0.001 1" density="100" friction="0.95 0.3 0.1" class="visual" material="CoffeeMachine086_Button004_material" />
                    <geom class="collision" type="box" pos="0.108232 -0.171865 0.148473" size="0.018481513485312462 0.005007907748222351 0.01872592233121395" quat="1.0 0.0 0.0 0.0" />
                </body>
                <body name="CoffeeMachine086_Container001_Clear">
                    <joint axis="0.0 0.0 1.0" pos="0.000275 0.264757 -0.001161" limited="true" name="CoffeeMachine086_Container001_Clear_joint" range="0.0 0.05" type="slide" damping="1" frictionloss="1" armature=".01" stiffness="0.05" />
                    <geom mesh="CoffeeMachine086_Container001_Clear_vis" type="mesh" solimp="0.998 0.998 0.001" solref="0.001 1" density="100" friction="0.95 0.3 0.1" class="visual" material="CoffeeMachine086_Container001_Clear_material" />
                    <geom class="collision" type="box" pos="0.000130 0.265436 -0.019006" size="0.16842325031757355 0.06035245582461357 0.22750474512577057" quat="1.0 0.0 0.0 0.0" />
                    <body name="CoffeeMachine086_Lid002_Clear">
                        <joint axis="0.0 0.0 1.0" pos="0.000279 0.264757 0.225531" limited="true" name="CoffeeMachine086_Lid002_Clear_joint" range="0.0 0.05" type="slide" damping="1" frictionloss="1" armature=".01" stiffness="0.05" />
                        <geom mesh="CoffeeMachine086_Lid002_Clear_vis" type="mesh" solimp="0.998 0.998 0.001" solref="0.001 1" density="100" friction="0.95 0.3 0.1" class="visual" material="CoffeeMachine086_Lid002_Clear_material" />
                        <geom class="collision" type="box" pos="0.000130 0.265436 0.227256" size="0.16842325031757355 0.06035245582461357 0.017398059368133545" quat="1.0 0.0 0.0 0.0" />
                    </body>
                </body>
                <body name="CoffeeMachine086_Lever001">
                    <joint axis="0.0 0.0 -1.0" pos="-0.065973 -0.085026 -0.012329" limited="true" name="CoffeeMachine086_Lever001_joint" range="0.0 1.5707963267948966" type="hinge" damping="1" frictionloss="1" armature=".01" stiffness="0.05" />
                    <geom mesh="CoffeeMachine086_Lever001_vis" type="mesh" solimp="0.998 0.998 0.001" solref="0.001 1" density="100" friction="0.95 0.3 0.1" class="visual" material="CoffeeMachine086_Lever001_material" />
                    <geom class="collision" type="box" pos="-0.067524 -0.191102 -0.019651" size="0.03757234662771225 0.029788699001073837 0.01395616214722395" quat="0.7071059942245483 0.001071624574251473 -0.0010715760290622711 0.7071059346199036" />
                    <geom class="collision" type="box" pos="-0.067524 -0.250360 -0.023904" size="0.02233966812491417 0.029788704589009285 0.017276881262660027" quat="0.7063846588134766 0.03194882348179817 -0.0319487638771534 0.7063846588134766" />
                    <geom class="collision" type="box" pos="-0.067524 -0.292403 -0.033124" size="0.028250370174646378 0.029788699001073837 0.017276886850595474" quat="0.696171224117279 0.12387723475694656 -0.12387711554765701 0.6961713433265686" />
                    <geom class="collision" type="cylinder" pos="-0.065187 -0.086352 -0.020572" size="0.050704918801784515 0.01385729480534792" quat="1.0 0.0 0.0 0.0" />
                    <geom class="collision" type="cylinder" pos="-0.066035 -0.084957 -0.040101" size="0.013463281095027924 0.005200744140893221" quat="1.0 0.0 0.0 0.0" />
                    <geom class="collision" type="box" pos="-0.066504 -0.144325 -0.014903" size="0.009434502571821213 0.009214445017278194 0.0019158277427777648" quat="0.7070986032485962 0.0034117817413061857 -0.003411733079701662 0.7070985436439514" />
                </body>
                <body name="CoffeeMachine086_Lever002">
                    <joint axis="0.0 0.0 1.0" pos="0.113698 -0.104152 0.044545" limited="true" name="CoffeeMachine086_Lever002_joint" range="0.0 1.0471975511965976" type="hinge" damping="1" frictionloss="1" armature=".01" stiffness="0.05" />
                    <geom mesh="CoffeeMachine086_Lever002_vis" type="mesh" solimp="0.998 0.998 0.001" solref="0.001 1" density="100" friction="0.95 0.3 0.1" class="visual" material="CoffeeMachine086_Lever002_material" />
                    <geom class="collision" type="cylinder" pos="0.098792 -0.133791 -0.027538" size="0.0062906574457883835 0.01386959757655859" quat="0.7152868509292603 -0.6563178896903992 0.16059985756874084 -0.1783793866634369" />
                    <geom class="collision" type="cylinder" pos="0.114505 -0.104597 0.010139" size="0.0062906574457883835 0.013869596645236015" quat="0.9707667231559753 -0.0006475318223237991 -0.0021047110203653574 -0.24001479148864746" />
                    <geom class="collision" type="cylinder" pos="0.110984 -0.111519 -0.014815" size="0.0062906574457883835 0.013869598507881165" quat="0.8966236114501953 -0.3720947504043579 0.08990528434515 -0.22255031764507294" />
                    <geom class="collision" type="cylinder" pos="0.076442 -0.176847 -0.106027" size="0.006472952663898468 0.05017020180821419" quat="1.0 0.0 0.0 0.0" />
                    <geom class="collision" type="cylinder" pos="0.079951 -0.168559 -0.043047" size="0.008795724250376225 0.019172366708517075" quat="0.7761518955230713 -0.26191267371177673 0.3789600431919098 0.43055692315101624" />
                    <geom class="collision" type="cylinder" pos="0.084311 -0.159505 -0.034620" size="0.008795724250376225 0.019172366708517075" quat="0.7029361724853516 -0.32940199971199036 0.5018993616104126 0.38140803575515747" />
                </body>
                <body name="CoffeeMachine086_Lid001">
                    <joint axis="0.0 0.0 1.0" pos="0.000960 0.109360 0.238305" limited="true" name="CoffeeMachine086_Lid001_joint" range="0.0 0.05" type="slide" damping="1" frictionloss="1" armature=".01" stiffness="0.05" />
                    <geom mesh="CoffeeMachine086_Lid001_vis" type="mesh" solimp="0.998 0.998 0.001" solref="0.001 1" density="100" friction="0.95 0.3 0.1" class="visual" material="CoffeeMachine086_Lid001_material" />
                    <geom class="collision" type="box" pos="0.000875 0.107732 0.243877" size="0.15957199037075043 0.08544464409351349 0.002633030992001295" quat="1.0 0.0 0.0 0.0" />
                </body>
                <body name="CoffeeMachine086_Lid003">
                    <joint axis="0.0 0.0 1.0" pos="0.000563 -0.112357 -0.183590" limited="true" name="CoffeeMachine086_Lid003_joint" range="0.0 0.02" type="slide" damping="1" frictionloss="1" armature=".01" stiffness="0.05" />
                    <geom mesh="CoffeeMachine086_Lid003_vis" type="mesh" solimp="0.998 0.998 0.001" solref="0.001 1" density="100" friction="0.95 0.3 0.1" class="visual" material="CoffeeMachine086_Lid003_material" />
                    <geom class="collision" type="box" pos="0.000829 -0.112310 -0.183445" size="0.1606253981590271 0.08553853631019592 0.0019397219875827432" quat="1.0 0.0 0.0 0.0" />
                </body>
            </body>
        </body>
    </worldbody>
    <actuator>
        <motor name="CoffeeMachine086_Button001_joint_actuator" joint="CoffeeMachine086_Button001_joint" gear="0.5" />
        <motor name="CoffeeMachine086_Button002_joint_actuator" joint="CoffeeMachine086_Button002_joint" gear="0.5" />
        <motor name="CoffeeMachine086_Button003_joint_actuator" joint="CoffeeMachine086_Button003_joint" gear="0.5" />
        <motor name="CoffeeMachine086_Button004_joint_actuator" joint="CoffeeMachine086_Button004_joint" gear="0.5" />
        <motor name="CoffeeMachine086_Container001_Clear_joint_actuator" joint="CoffeeMachine086_Container001_Clear_joint" gear="250" />
        <motor name="CoffeeMachine086_Lever001_joint_actuator" joint="CoffeeMachine086_Lever001_joint" gear="10" />
        <motor name="CoffeeMachine086_Lever002_joint_actuator" joint="CoffeeMachine086_Lever002_joint" gear="10" />
        <motor name="CoffeeMachine086_Lid001_joint_actuator" joint="CoffeeMachine086_Lid001_joint" gear="5" />
        <motor name="CoffeeMachine086_Lid003_joint_actuator" joint="CoffeeMachine086_Lid003_joint" gear="5" />
        <motor name="CoffeeMachine086_Lid002_Clear_joint_actuator" joint="CoffeeMachine086_Lid002_Clear_joint" gear="20" />
    </actuator>
</mujoco>