<?xml version='1.0' encoding='UTF-8'?>
<mujoco model="model">
  <compiler angle="radian"/>
  <asset>
    <mesh file="visuals/Body001.obj" name="Body001_vis"/>
    <mesh file="visuals/Door001.obj" name="Door001_vis"/>
    <mesh file="visuals/Door001_Clear.obj" name="Door001_Clear_vis"/>
    <mesh file="visuals/Knob001.obj" name="Knob001_vis"/>
    <mesh file="visuals/Knob002.obj" name="Knob002_vis"/>
    <mesh file="visuals/Knob003.obj" name="Knob003_vis"/>
    <mesh file="visuals/Shelf001.obj" name="Shelf001_vis"/>
    <mesh file="visuals/Shelf002.obj" name="Shelf002_vis"/>
    <texture file="visuals/T_BC001.png" name="Body001_material" type="2d"/>
    <material name="Body001_material" rgba="1 1 1 1.0" texture="Body001_material" shininess="0.40476077795028687" specular="1.5"/>
    <texture file="visuals/T_BC001.png" name="Door001_material" type="2d"/>
    <material name="Door001_material" rgba="1 1 1 1.0" texture="Door001_material" shininess="0.40476077795028687" specular="0.5"/>
    <texture file="visuals/T_BC001.png" name="Door001_Clear_material" type="2d"/>
    <material name="Door001_Clear_material" rgba="1 1 1 0.800000011920929" texture="Door001_Clear_material" shininess="0.5" specular="0.3103448502657381"/>
    <texture file="visuals/T_BC001.png" name="Knob001_material" type="2d"/>
    <material name="Knob001_material" rgba="1 1 1 1.0" texture="Knob001_material" shininess="0.40476077795028687" specular="0.3103448502657381"/>
    <texture file="visuals/T_BC001.png" name="Knob002_material" type="2d"/>
    <material name="Knob002_material" rgba="1 1 1 1.0" texture="Knob002_material" shininess="0.40476077795028687" specular="0.3103448502657381"/>
    <texture file="visuals/T_BC001.png" name="Knob003_material" type="2d"/>
    <material name="Knob003_material" rgba="1 1 1 1.0" texture="Knob003_material" shininess="0.40476077795028687" specular="0.3103448502657381"/>
    <texture file="visuals/T_BC001.png" name="Shelf001_material" type="2d"/>
    <material name="Shelf001_material" rgba="1 1 1 1.0" texture="Shelf001_material" shininess="0.40476077795028687" specular="2"/>
    <texture file="visuals/T_BC001.png" name="Shelf002_material" type="2d"/>
    <material name="Shelf002_material" rgba="1 1 1 1.0" texture="Shelf002_material" shininess="0.40476077795028687" specular="2"/>
  </asset>
  <default>
    <default class="visual">
      <geom conaffinity="0" contype="0" group="1" type="mesh"/>
    </default>
    <default class="collision">
      <geom group="0" rgba="0.5 0 0 0.5"/>
    </default>
    <default class="spawn">
      <geom group="0" rgba="1 1 1 0.5" contype="0" conaffinity="0"/>
      <site group="0" rgba="1 1 1 0.5"/>
    </default>
    <default class="region">
      <geom group="1" conaffinity="0" contype="0" rgba="0 1 0 0"/>
    </default>
  </default>
  <worldbody>
    <body>
      <body name="object">
        <geom mesh="Body001_vis" type="mesh" solimp="0.998 0.998 0.001" solref="0.001 1" density="100" friction="0.95 0.3 0.1" class="visual" material="Body001_material"/>
        <geom class="collision" type="box" pos="0.000129 0.014205 0.115347" size="0.16799390316009521 0.15449689328670502 0.046898286789655685" quat="1.0 0.0 0.0 0.0"/>
        <geom class="collision" type="box" pos="0.000129 0.027268 -0.146551" size="0.16799390316009521 0.14143456518650055 0.004279122222214937" quat="1.0 0.0 0.0 0.0"/>
        <geom class="collision" type="box" pos="0.164412 0.024972 -0.036548" size="0.003169992472976446 0.14373032748699188 0.10511252284049988" quat="1.0 0.0 0.0 0.0"/>
        <geom class="collision" type="box" pos="-0.163892 0.024972 -0.036548" size="0.0020520328544080257 0.14373034238815308 0.10511252284049988" quat="1.0 0.0 0.0 0.0"/>
        <geom class="collision" type="box" pos="-0.000447 0.155160 -0.037226" size="0.1614246666431427 0.013542283326387405 0.10444756597280502" quat="1.0 0.0 0.0 0.0"/>
        <geom class="collision" type="box" pos="0.154903 0.019328 -0.086268" size="0.00484692445024848 0.12642931938171387 0.0063050612807273865" quat="1.0 0.0 0.0 0.0"/>
        <geom class="collision" type="box" pos="0.154903 0.019328 -0.024174" size="0.00484692445024848 0.12642931938171387 0.0063050612807273865" quat="1.0 0.0 0.0 0.0"/>
        <geom class="collision" type="box" pos="-0.155905 0.019328 -0.024174" size="0.00484692445024848 0.12642931938171387 0.0063050612807273865" quat="1.0 0.0 0.0 0.0"/>
        <geom class="collision" type="box" pos="-0.155905 0.019328 -0.086268" size="0.00484692445024848 0.12642931938171387 0.0063050612807273865" quat="1.0 0.0 0.0 0.0"/>
        <geom class="collision" type="box" pos="-0.142190 -0.098611 -0.156741" size="0.007177562452852726 0.009858162142336369 0.0062631466425955296" quat="1.0 0.0 0.0 0.0"/>
        <geom class="collision" type="box" pos="0.141914 -0.098611 -0.156741" size="0.007177562452852726 0.009858162142336369 0.0062631466425955296" quat="1.0 0.0 0.0 0.0"/>
        <geom class="collision" type="box" pos="0.141914 0.146397 -0.156741" size="0.007177562452852726 0.009858162142336369 0.0062631466425955296" quat="1.0 0.0 0.0 0.0"/>
        <geom class="collision" type="box" pos="-0.142190 0.146397 -0.156741" size="0.007177562452852726 0.009858162142336369 0.0062631466425955296" quat="1.0 0.0 0.0 0.0"/>
        <body name="Door001">
          <joint axis="1.0 0.0 0.0" pos="0.000000 -0.130478 -0.138188" limited="true" name="Door001_joint" range="0.0 1.5707963267948966" type="hinge" damping="1" frictionloss="1" armature=".01" stiffness="0.4" springref="-2"/>
          <geom mesh="Door001_vis" type="mesh" solimp="0.998 0.998 0.001" solref="0.001 1" density="100" friction="0.95 0.3 0.1" class="visual" material="Door001_material"/>
          <geom class="collision" type="box" pos="-0.139651 -0.129979 -0.042741" size="0.028908470645546913 0.009729273617267609 0.09801409393548965" quat="1.0 0.0 0.0 0.0"/>
          <geom class="collision" type="box" pos="0.137514 -0.129979 -0.042741" size="0.02929525636136532 0.009729273617267609 0.09801409393548965" quat="1.0 0.0 0.0 0.0"/>
          <geom class="collision" type="box" pos="-0.001434 -0.129979 -0.122029" size="0.10868487507104874 0.009729273617267609 0.018725590780377388" quat="1.0 0.0 0.0 0.0"/>
          <geom class="collision" type="box" pos="-0.001434 -0.129979 0.033646" size="0.10868487507104874 0.009729273617267609 0.021839696913957596" quat="1.0 0.0 0.0 0.0"/>
          <geom class="collision" type="box" pos="0.000353 -0.165753 0.039765" size="0.10052364319562912 0.004941307939589024 0.009371878579258919" quat="1.0 0.0 0.0 0.0"/>
          <geom class="collision" type="box" pos="0.000353 -0.141903 0.039826" size="0.10052364319562912 0.003314411034807563 0.010362689383327961" quat="1.0 0.0 0.0 0.0"/>
          <geom class="collision" type="box" pos="0.119537 -0.154512 0.039826" size="0.0181875079870224 0.015924016013741493 0.010362689383327961" quat="1.0 0.0 0.0 0.0"/>
          <geom class="collision" type="box" pos="-0.118908 -0.154512 0.039826" size="0.0181875079870224 0.015924016013741493 0.010362689383327961" quat="1.0 0.0 0.0 0.0"/>
          <body name="Door001_Clear">
            <geom mesh="Door001_Clear_vis" type="mesh" solimp="0.998 0.998 0.001" solref="0.001 1" density="100" friction="0.95 0.3 0.1" class="visual" material="Door001_Clear_material"/>
            <geom class="collision" type="box" pos="-0.001277 -0.133813 -0.045837" size="0.10990311950445175 0.004647101275622845 0.05809466168284416" quat="1.0 0.0 0.0 0.0"/>
          </body>
        </body>
        <body name="Knob001">
          <joint axis="0.0 1.0 0.0" pos="-0.083965 -0.149826 0.108350" limited="true" name="Knob001_joint" range="0.0 3.9269908169872414" type="hinge" damping="0.05" armature="0.001"/>
          <geom mesh="Knob001_vis" type="mesh" solimp="0.998 0.998 0.001" solref="0.001 1" density="100" friction="0.95 0.3 0.1" class="visual" material="Knob001_material"/>
          <geom class="collision" type="cylinder" pos="-0.084027 -0.146483 0.108434" size="0.015089793130755424 0.004180982243269682" quat="0.29001113772392273 0.29001107811927795 -0.6448981761932373 0.6448980569839478"/>
          <geom class="collision" type="box" pos="-0.083621 -0.156136 0.107884" size="0.003915501292794943 0.006732615176588297 0.012667737901210785" quat="0.0012701309751719236 0.0 0.9999991655349731 0.0"/>
        </body>
        <body name="Knob002">
          <joint axis="0.0 1.0 0.0" pos="-0.000245 -0.149826 0.108350" limited="true" name="Knob002_joint" range="0.0 3.3161255787892263" type="hinge" damping="0.05" armature="0.001"/>
          <geom mesh="Knob002_vis" type="mesh" solimp="0.998 0.998 0.001" solref="0.001 1" density="100" friction="0.95 0.3 0.1" class="visual" material="Knob002_material"/>
          <geom class="collision" type="cylinder" pos="-0.000365 -0.146483 0.108434" size="0.015089793130755424 0.004180982243269682" quat="0.29001113772392273 0.29001107811927795 -0.6448981761932373 0.6448980569839478"/>
          <geom class="collision" type="box" pos="0.000041 -0.156136 0.108668" size="0.003915501292794943 0.006732615176588297 0.012667737901210785" quat="0.7162219882011414 0.0 0.697872519493103 0.0"/>
        </body>
        <body name="Knob003">
          <joint axis="0.0 1.0 0.0" pos="0.083031 -0.149826 0.108350" limited="true" name="Knob003_joint" range="0.0 3.3161255787892263" type="hinge" damping="0.05" armature="0.001"/>
          <geom mesh="Knob003_vis" type="mesh" solimp="0.998 0.998 0.001" solref="0.001 1" density="100" friction="0.95 0.3 0.1" class="visual" material="Knob003_material"/>
          <geom class="collision" type="cylinder" pos="0.083059 -0.146483 0.108434" size="0.015089793130755424 0.004180982243269682" quat="0.29001113772392273 0.29001107811927795 -0.6448981761932373 0.6448980569839478"/>
          <geom class="collision" type="box" pos="0.083465 -0.156136 0.108541" size="0.003915501292794943 0.006732615176588297 0.012667737901210785" quat="0.6758393049240112 0.0 0.7370489835739136 0.0"/>
        </body>
        <body name="Shelf001">
          <joint axis="0.0 -1.0 0.0" pos="-0.000317 0.009504 -0.016043" limited="true" name="Shelf001_joint" range="0.0 0.2" type="slide" damping="1" frictionloss="1" armature=".01" stiffness="0.05"/>
          <geom mesh="Shelf001_vis" type="mesh" solimp="0.998 0.998 0.001" solref="0.001 1" density="100" friction="0.95 0.3 0.1" class="visual" material="Shelf001_material"/>
          <geom class="collision" type="box" pos="-0.000372 0.009310 -0.016045" size="0.15958759188652039 0.11407769471406937 0.0017067822627723217" quat="1.0 0.0 0.0 0.0"/>
        </body>
        <body name="Shelf002">
          <joint axis="0.0 -1.0 0.0" pos="-0.000317 0.009537 -0.078211" limited="true" name="Shelf002_joint" range="0.0 0.2" type="slide" damping="1" frictionloss="1" armature=".01" stiffness="0.05"/>
          <geom mesh="Shelf002_vis" type="mesh" solimp="0.998 0.998 0.001" solref="0.001 1" density="100" friction="0.95 0.3 0.1" class="visual" material="Shelf002_material"/>
          <geom class="collision" type="box" pos="-0.000372 0.009310 -0.077946" size="0.15958759188652039 0.11407769471406937 0.0017067822627723217" quat="1.0 0.0 0.0 0.0"/>
        </body>
        <geom class="region" name="reg_main" type="box" pos="0.0 0.01440699999999999 0.0" size="0.170107 0.156067 0.164996"/>
        <geom class="region" name="reg_int" type="box" pos="3.199999999999037e-05 0.012664999999999996 -0.039658000000000006" size="0.16300399999999998 0.13164599999999999 0.10436000000000001"/>
      </body>
    </body>
  </worldbody>
  <actuator>
    <motor name="Door001_joint_actuator" joint="Door001_joint" gear="50"/>
    <motor name="Knob001_joint_actuator" joint="Knob001_joint" gear="50"/>
    <motor name="Knob002_joint_actuator" joint="Knob002_joint" gear="50"/>
    <motor name="Knob003_joint_actuator" joint="Knob003_joint" gear="50"/>
    <motor name="Shelf001_joint_actuator" joint="Shelf001_joint" gear="50"/>
    <motor name="Shelf002_joint_actuator" joint="Shelf002_joint" gear="50"/>
  </actuator>
</mujoco>
