<?xml version='1.0' encoding='utf-8'?>
<mujoco model="model">
    <compiler angle="radian" />
    <asset>
        <mesh file="visuals/ToasterOven031_Body001.obj" name="ToasterOven031_Body001_vis" />
        <mesh file="visuals/ToasterOven031_Button001.obj" name="ToasterOven031_Button001_vis" />
        <mesh file="visuals/ToasterOven031_Door001.obj" name="ToasterOven031_Door001_vis" />
        <mesh file="visuals/ToasterOven031_Door001_Clear.obj" name="ToasterOven031_Door001_Clear_vis" />
        <mesh file="visuals/ToasterOven031_Knob001.obj" name="ToasterOven031_Knob001_vis" />
        <mesh file="visuals/ToasterOven031_Knob002.obj" name="ToasterOven031_Knob002_vis" />
        <mesh file="visuals/ToasterOven031_Knob003.obj" name="ToasterOven031_Knob003_vis" />
        <mesh file="visuals/ToasterOven031_Shelf001.obj" name="ToasterOven031_Shelf001_vis" />
        <mesh file="visuals/ToasterOven031_Shelf002.obj" name="ToasterOven031_Shelf002_vis" />
        <texture file="visuals/T_ToasterOven031_BC001.png" name="ToasterOven031_Body001_material" type="2d" />
        <material name="ToasterOven031_Body001_material" rgba="1 1 1 1.0" texture="ToasterOven031_Body001_material" shininess="0.40476077795028687" specular="0.3103448502657381" />
        <texture file="visuals/T_ToasterOven031_BC001.png" name="ToasterOven031_Button001_material" type="2d" />
        <material name="ToasterOven031_Button001_material" rgba="1 1 1 1.0" texture="ToasterOven031_Button001_material" shininess="0.40476077795028687" specular="0.3103448502657381" />
        <texture file="visuals/T_ToasterOven031_BC001.png" name="ToasterOven031_Door001_material" type="2d" />
        <material name="ToasterOven031_Door001_material" rgba="1 1 1 1.0" texture="ToasterOven031_Door001_material" shininess="0.40476077795028687" specular="0.3103448502657381" />
        <texture file="visuals/T_ToasterOven031_BC001.png" name="ToasterOven031_Door001_Clear_material" type="2d" />
        <material name="ToasterOven031_Door001_Clear_material" rgba="1 1 1 0.37735849618911743" texture="ToasterOven031_Door001_Clear_material" shininess="0.37645912170410156" specular="0.3103448502657381" />
        <texture file="visuals/T_ToasterOven031_BC001.png" name="ToasterOven031_Knob001_material" type="2d" />
        <material name="ToasterOven031_Knob001_material" rgba="1 1 1 1.0" texture="ToasterOven031_Knob001_material" shininess="0.40476077795028687" specular="0.3103448502657381" />
        <texture file="visuals/T_ToasterOven031_BC001.png" name="ToasterOven031_Knob002_material" type="2d" />
        <material name="ToasterOven031_Knob002_material" rgba="1 1 1 1.0" texture="ToasterOven031_Knob002_material" shininess="0.40476077795028687" specular="0.3103448502657381" />
        <texture file="visuals/T_ToasterOven031_BC001.png" name="ToasterOven031_Knob003_material" type="2d" />
        <material name="ToasterOven031_Knob003_material" rgba="1 1 1 1.0" texture="ToasterOven031_Knob003_material" shininess="0.40476077795028687" specular="0.3103448502657381" />
        <texture file="visuals/T_ToasterOven031_BC001.png" name="ToasterOven031_Shelf001_material" type="2d" />
        <material name="ToasterOven031_Shelf001_material" rgba="1 1 1 1.0" texture="ToasterOven031_Shelf001_material" shininess="0.40476077795028687" specular="0.3103448502657381" />
        <texture file="visuals/T_ToasterOven031_BC001.png" name="ToasterOven031_Shelf002_material" type="2d" />
        <material name="ToasterOven031_Shelf002_material" rgba="1 1 1 1.0" texture="ToasterOven031_Shelf002_material" shininess="0.40476077795028687" specular="0.3103448502657381" />
    </asset>
    <default>
        <default class="visual">
            <geom conaffinity="0" contype="0" group="1" type="mesh" />
        </default>
        <default class="collision">
            <geom group="0" rgba="0.5 0 0 0.5" />
    </default>
        <default class="spawn">
            <geom group="0" rgba="1 1 1 0.5" contype="0" conaffinity="0" />
            <site group="0" rgba="1 1 1 0.5" />
        </default>
    </default>
    <worldbody>
        <body>
            <site rgba="0 0 0 0.5" size="0.01" pos="-0.17010746523737907 -0.14138975739479065 -0.1649962216615677" name="ext_p0" />
            <site rgba="1 0 0 0.5" size="0.01" pos="0.17010747268795967 -0.14138975739479065 -0.1649962216615677" name="ext_px" />
            <site rgba="0 1 0 0.5" size="0.01" pos="-0.17010746523737907 0.17103427648544312 -0.1649962216615677" name="ext_py" />
            <site rgba="0 0 1 0.5" size="0.01" pos="-0.17010746523737907 -0.14138975739479065 0.1649962216615677" name="ext_pz" />
            <site rgba="0 1 1 0.5" size="0.004999999888241291" pos="-0.1556340754032135 0.13546234369277954 -0.13521234691143036" name="int_py" />
            <site rgba="1 1 0 0.5" size="0.004999999888241291" pos="0.15441572666168213 -0.1096525639295578 -0.13521233201026917" name="int_px" />
            <site rgba="1 0.75 0.8 0.5" size="0.004999999888241291" pos="-0.15563437342643738 -0.1096525639295578 0.05751647800207138" name="int_pz" />
            <site rgba="0.5 0.5 0.5 0.5" size="0.004999999888241291" pos="-0.1556340754032135 -0.1096525639295578 -0.13521219789981842" name="int_p0" />
            <body name="object">
                <geom mesh="ToasterOven031_Body001_vis" type="mesh" solimp="0.998 0.998 0.001" solref="0.001 1" density="100" friction="0.95 0.3 0.1" class="visual" material="ToasterOven031_Body001_material" />
                <geom class="collision" type="box" pos="-0.0009891408262774348 0.015436498448252678 0.11730329692363739" size="0.1724657416343689 0.15615400671958923 0.04885471239686012" quat="1.0 0.0 0.0 0.0" />
                <geom class="collision" type="box" pos="-0.0009891408262774348 0.029037978500127792 -0.1465512216091156" size="0.1724657416343689 0.14255252480506897 0.004279122222214937" quat="1.0 0.0 0.0 0.0" />
                <geom class="collision" type="box" pos="0.16608868539333344 0.02674221061170101 -0.03654816001653671" size="0.00484692445024848 0.1448482871055603 0.10511252284049988" quat="1.0 0.0 0.0 0.0" />
                <geom class="collision" type="box" pos="-0.1666867434978485 0.02674221061170101 -0.03654816001653671" size="0.00484692445024848 0.1448483020067215 0.10511252284049988" quat="1.0 0.0 0.0 0.0" />
                <geom class="collision" type="box" pos="-0.0004474023880902678 0.15693026781082153 -0.03722626715898514" size="0.1614246666431427 0.014660242944955826 0.10444756597280502" quat="1.0 0.0 0.0 0.0" />
                <geom class="collision" type="box" pos="0.15490256249904633 0.019980380311608315 -0.08626840263605118" size="0.00484692445024848 0.12642931938171387 0.0063050612807273865" quat="1.0 0.0 0.0 0.0" />
                <geom class="collision" type="box" pos="0.15490256249904633 0.019980380311608315 -0.024174436926841736" size="0.00484692445024848 0.12642931938171387 0.0063050612807273865" quat="1.0 0.0 0.0 0.0" />
                <geom class="collision" type="box" pos="-0.15590518712997437 0.019980380311608315 -0.024174436926841736" size="0.00484692445024848 0.12642931938171387 0.0063050612807273865" quat="1.0 0.0 0.0 0.0" />
                <geom class="collision" type="box" pos="-0.15590518712997437 0.019980380311608315 -0.08626840263605118" size="0.00484692445024848 0.12642931938171387 0.0063050612807273865" quat="1.0 0.0 0.0 0.0" />
                <geom class="collision" type="box" pos="-0.14218968152999878 -0.09795837849378586 -0.15841788053512573" size="0.007177562452852726 0.009858162142336369 0.007940078154206276" quat="1.0 0.0 0.0 0.0" />
                <geom class="collision" type="box" pos="0.1419139802455902 -0.09795837849378586 -0.15841788053512573" size="0.007177562452852726 0.009858162142336369 0.007940078154206276" quat="1.0 0.0 0.0 0.0" />
                <geom class="collision" type="box" pos="0.1419139802455902 0.14704978466033936 -0.15841788053512573" size="0.007177562452852726 0.009858162142336369 0.007940078154206276" quat="1.0 0.0 0.0 0.0" />
                <geom class="collision" type="box" pos="-0.14218968152999878 0.14704978466033936 -0.15841788053512573" size="0.007177562452852726 0.009858162142336369 0.007940078154206276" quat="1.0 0.0 0.0 0.0" />
                <body name="ToasterOven031_Button001">
                    <joint axis="0.0 1.0 0.0" pos="0.12799300253391266 -0.14291922748088837 0.11102001368999481" limited="true" name="ToasterOven031_Button001_joint" range="0.0 0.002" type="slide" damping="1" frictionloss="1" armature=".01" stiffness="0.05" />
                    <geom mesh="ToasterOven031_Button001_vis" type="mesh" solimp="0.998 0.998 0.001" solref="0.001 1" density="100" friction="0.95 0.3 0.1" class="visual" material="ToasterOven031_Button001_material" />
                    <geom class="collision" type="cylinder" pos="0.12800398468971252 -0.14348427951335907 0.11098511517047882" size="0.007347939535975456 0.0015010382048785686" quat="0.7071067094802856 0.7071068286895752 0.0 0.0" />
                </body>
                <body name="ToasterOven031_Door001">
                    <joint axis="1.0 0.0 0.0" pos="0.0 -0.11853693425655365 -0.14956465363502502" limited="true" name="ToasterOven031_Door001_joint" range="0.0 1.5707963267948966" type="hinge" damping="1" frictionloss="1" armature=".01" stiffness="0.4" springref="-2" />
                    <geom mesh="ToasterOven031_Door001_vis" type="mesh" solimp="0.998 0.998 0.001" solref="0.001 1" density="100" friction="0.95 0.3 0.1" class="visual" material="ToasterOven031_Door001_material" />
                    <geom class="collision" type="box" pos="-0.14062108099460602 -0.12986579537391663 -0.04204209893941879" size="0.02987891621887684 0.01026841253042221 0.10849493741989136" quat="1.0 0.0 0.0 0.0" />
                    <geom class="collision" type="box" pos="0.1391908973455429 -0.12986579537391663 -0.04204209893941879" size="0.030972188338637352 0.01026841253042221 0.10849493741989136" quat="1.0 0.0 0.0 0.0" />
                    <geom class="collision" type="box" pos="-0.0014342479407787323 -0.12986579537391663 -0.1269204020500183" size="0.10868487507104874 0.01026841253042221 0.023616651073098183" quat="1.0 0.0 0.0 0.0" />
                    <geom class="collision" type="box" pos="-0.0014342479407787323 -0.12986579537391663 0.03923570364713669" size="0.10868487507104874 0.01026841253042221 0.027429481968283653" quat="1.0 0.0 0.0 0.0" />
                    <geom class="collision" type="box" pos="0.0003533660201355815 -0.16510069370269775 0.03976462408900261" size="0.10052364319562912 0.004941307939589024 0.009371878579258919" quat="1.0 0.0 0.0 0.0" />
                    <geom class="collision" type="box" pos="0.0003533660201355815 -0.141789510846138 0.039826299995183945" size="0.10052364319562912 0.0027752721216529608 0.010362689383327961" quat="1.0 0.0 0.0 0.0" />
                    <geom class="collision" type="box" pos="0.11953706294298172 -0.154399111866951 0.039826299995183945" size="0.0181875079870224 0.015384877100586891 0.010362689383327961" quat="1.0 0.0 0.0 0.0" />
                    <geom class="collision" type="box" pos="-0.11890767514705658 -0.154399111866951 0.039826299995183945" size="0.0181875079870224 0.015384877100586891 0.010362689383327961" quat="1.0 0.0 0.0 0.0" />
                    <body name="ToasterOven031_Door001_Clear">
                        <geom mesh="ToasterOven031_Door001_Clear_vis" type="mesh" solimp="0.998 0.998 0.001" solref="0.001 1" density="100" friction="0.95 0.3 0.1" class="visual" material="ToasterOven031_Door001_Clear_material" />
                        <geom class="collision" type="box" pos="-0.001277260947972536 -0.1336991935968399 -0.04583720117807388" size="0.10990311950445175 0.005186240188777447 0.05809466168284416" quat="1.0 0.0 0.0 0.0" />
                    </body>
                </body>
                <body name="ToasterOven031_Knob001">
                    <joint axis="0.0 1.0 0.0" pos="-0.07688681781291962 -0.14679017663002014 0.10730992257595062" limited="true" name="ToasterOven031_Knob001_joint" range="-1.9198621771937625 3.141592653589793" type="hinge" damping="1" frictionloss="1" armature=".01" stiffness="0.05" />
                    <geom mesh="ToasterOven031_Knob001_vis" type="mesh" solimp="0.998 0.998 0.001" solref="0.001 1" density="100" friction="0.95 0.3 0.1" class="visual" material="ToasterOven031_Knob001_material" />
                    <geom class="collision" type="cylinder" pos="-0.07688664644956589 -0.14752952754497528 0.10726528614759445" size="0.019297314807772636 0.006470163818448782" quat="0.7071067094802856 0.7071068286895752 0.0 0.0" />
                </body>
                <body name="ToasterOven031_Knob002">
                    <joint axis="0.0 1.0 0.0" pos="-1.1047348380088806e-05 -0.14679017663002014 0.10840262472629547" limited="true" name="ToasterOven031_Knob002_joint" range="0.0 4.886921905584122" type="hinge" damping="1" frictionloss="1" armature=".01" stiffness="0.05" />
                    <geom mesh="ToasterOven031_Knob002_vis" type="mesh" solimp="0.998 0.998 0.001" solref="0.001 1" density="100" friction="0.95 0.3 0.1" class="visual" material="ToasterOven031_Knob002_material" />
                    <geom class="collision" type="cylinder" pos="-6.880669388920069e-05 -0.14747314155101776 0.10837401449680328" size="0.016757601872086525 0.006448411848396063" quat="0.7071067094802856 0.7071068286895752 0.0 0.0" />
                </body>
                <body name="ToasterOven031_Knob003">
                    <joint axis="0.0 -1.0 0.0" pos="0.0768294706940651 -0.14679017663002014 0.10730992257595062" limited="true" name="ToasterOven031_Knob003_joint" range="0.0 4.1887902047863905" type="hinge" damping="1" frictionloss="1" armature=".01" stiffness="0.05" />
                    <geom mesh="ToasterOven031_Knob003_vis" type="mesh" solimp="0.998 0.998 0.001" solref="0.001 1" density="100" friction="0.95 0.3 0.1" class="visual" material="ToasterOven031_Knob003_material" />
                    <geom class="collision" type="cylinder" pos="0.07677632570266724 -0.14752952754497528 0.10726528614759445" size="0.019297314807772636 0.006470163818448782" quat="0.7071067094802856 0.7071068286895752 0.0 0.0" />
                </body>
                <body name="ToasterOven031_Shelf001">
                    <joint axis="0.0 -1.0 0.0" pos="-0.0003170967102050781 0.01015649363398552 -0.016043085604906082" limited="true" name="ToasterOven031_Shelf001_joint" range="0.0 0.12" type="slide" damping="1" frictionloss="1" armature=".01" stiffness="0.05" />
                    <geom mesh="ToasterOven031_Shelf001_vis" type="mesh" solimp="0.998 0.998 0.001" solref="0.001 1" density="100" friction="0.95 0.3 0.1" class="visual" material="ToasterOven031_Shelf001_material" />
                    <geom class="collision" type="box" pos="-0.0003722023975569755 0.009962760843336582 -0.016044560819864273" size="0.15958759188652039 0.11407769471406937 0.0017067822627723217" quat="1.0 0.0 0.0 0.0" />
                </body>
                <body name="ToasterOven031_Shelf002">
                    <joint axis="0.0 -1.0 0.0" pos="-0.0003170967102050781 0.01015649363398552 -0.07821105420589447" limited="true" name="ToasterOven031_Shelf002_joint" range="0.0 0.12" type="slide" damping="1" frictionloss="1" armature=".01" stiffness="0.05" />
                    <geom mesh="ToasterOven031_Shelf002_vis" type="mesh" solimp="0.998 0.998 0.001" solref="0.001 1" density="100" friction="0.95 0.3 0.1" class="visual" material="ToasterOven031_Shelf002_material" />
                    <geom class="collision" type="box" pos="-0.0003722023975569755 0.009962760843336582 -0.07794599235057831" size="0.15958759188652039 0.11407769471406937 0.0017067822627723217" quat="1.0 0.0 0.0 0.0" />
                </body>
            </body>
        </body>
    </worldbody>
    <actuator>
        <motor name="ToasterOven031_Button001_joint_actuator" joint="ToasterOven031_Button001_joint" gear="0.5" />
        <motor name="ToasterOven031_Door001_joint_actuator" joint="ToasterOven031_Door001_joint" gear="10" />
        <motor name="ToasterOven031_Knob001_joint_actuator" joint="ToasterOven031_Knob001_joint" gear="10" />
        <motor name="ToasterOven031_Knob002_joint_actuator" joint="ToasterOven031_Knob002_joint" gear="10" />
        <motor name="ToasterOven031_Knob003_joint_actuator" joint="ToasterOven031_Knob003_joint" gear="10" />
        <motor name="ToasterOven031_Shelf001_joint_actuator" joint="ToasterOven031_Shelf001_joint" gear="10" />
        <motor name="ToasterOven031_Shelf002_joint_actuator" joint="ToasterOven031_Shelf002_joint" gear="10" />
    </actuator>
</mujoco>