<?xml version='1.0' encoding='UTF-8'?>
<mujoco model="model">
  <compiler angle="radian"/>
  <asset>
    <mesh file="visuals/Body001.obj" name="Body001_vis"/>
    <mesh file="visuals/Button001.obj" name="Button001_vis"/>
    <mesh file="visuals/Button002.obj" name="Button002_vis"/>
    <mesh file="visuals/Button003.obj" name="Button003_vis"/>
    <mesh file="visuals/Button004.obj" name="Button004_vis"/>
    <mesh file="visuals/Button005.obj" name="Button005_vis"/>
    <texture file="visuals/T_BC001.png" name="Body001_material" type="2d"/>
    <material name="Body001_material" rgba="1 1 1 1.0" texture="Body001_material" shininess="-1615.1451416015625" specular="0.7"/>
    <texture file="visuals/T_BC001.png" name="Button001_material" type="2d"/>
    <material name="Button001_material" rgba="1 1 1 1.0" texture="Button001_material" shininess="-1615.1451416015625" specular="0.3103448502657381"/>
    <texture file="visuals/T_BC001.png" name="Button002_material" type="2d"/>
    <material name="Button002_material" rgba="1 1 1 1.0" texture="Button002_material" shininess="-1615.1451416015625" specular="0.3103448502657381"/>
    <texture file="visuals/T_BC001.png" name="Button003_material" type="2d"/>
    <material name="Button003_material" rgba="1 1 1 1.0" texture="Button003_material" shininess="-1615.1451416015625" specular="0.3103448502657381"/>
    <texture file="visuals/T_BC001.png" name="Button004_material" type="2d"/>
    <material name="Button004_material" rgba="1 1 1 1.0" texture="Button004_material" shininess="-1615.1451416015625" specular="0.3103448502657381"/>
    <texture file="visuals/T_BC001.png" name="Button005_material" type="2d"/>
    <material name="Button005_material" rgba="1 1 1 1.0" texture="Button005_material" shininess="-1615.1451416015625" specular="0.3103448502657381"/>
  </asset>
  <default>
    <default class="visual">
      <geom conaffinity="0" contype="0" group="1" type="mesh"/>
    </default>
    <default class="collision">
      <geom group="0" rgba="0.5 0 0 0.5"/>
    </default>
    <default class="spawn">
      <geom group="0" rgba="1 1 1 0.5" contype="0" conaffinity="0"/>
      <site group="0" rgba="1 1 1 0.5"/>
    </default>
    <default class="region">
      <geom group="1" conaffinity="0" contype="0" rgba="0 1 0 0"/>
    </default>
  </default>
  <worldbody>
    <body>
      <body name="object">
        <geom mesh="Body001_vis" type="mesh" solimp="0.998 0.998 0.001" solref="0.001 1" density="100" friction="0.95 0.3 0.1" class="visual" material="Body001_material"/>
        <geom class="collision" type="box" pos="-0.000000 0.169169 0.052685" size="0.5031148195266724 0.14136171340942383 0.22405751049518585" quat="1.0 0.0 0.0 0.0"/>
        <geom class="collision" type="box" pos="-0.000000 -0.122727 0.054321" size="0.5031148195266724 0.018117135390639305 0.266616553068161" quat="0.9430525302886963 -0.3326438069343567 -7.400192679193351e-17 -4.955875248644164e-20"/>
        <geom class="collision" type="box" pos="-0.000000 -0.120024 -0.141008" size="0.5031148195266724 0.15663526952266693 0.030364563688635826" quat="1.0 0.0 0.0 0.0"/>
        <geom class="collision" type="box" pos="-0.000000 -0.077251 -0.081126" size="0.5031148195266724 0.15663526952266693 0.030364563688635826" quat="1.0 0.0 0.0 0.0"/>
        <geom class="collision" type="box" pos="-0.000000 -0.076622 -0.022873" size="0.5031148195266724 0.10973050445318222 0.030364563688635826" quat="1.0 0.0 0.0 0.0"/>
        <geom class="collision" type="box" pos="0.000000 -0.055490 0.033342" size="0.5031148195266724 0.08540207892656326 0.030364563688635826" quat="1.0 0.0 0.0 0.0"/>
        <geom class="collision" type="box" pos="0.000000 -0.030999 0.093468" size="0.5031148195266724 0.06149798259139061 0.030364563688635826" quat="1.0 0.0 0.0 0.0"/>
        <geom class="collision" type="box" pos="0.000000 -0.006979 0.153724" size="0.5031148195266724 0.03799305856227875 0.030364563688635826" quat="1.0 0.0 0.0 0.0"/>
        <geom class="collision" type="box" pos="0.000000 0.016753 0.211716" size="0.5031148195266724 0.016180111095309258 0.030364563688635826" quat="1.0 0.0 0.0 0.0"/>
        <geom class="collision" type="box" pos="-0.000000 0.275568 -0.222590" size="0.5031148195266724 0.034963008016347885 0.05370902642607689" quat="1.0 0.0 0.0 0.0"/>
        <geom class="collision" type="box" pos="-0.000000 -0.028239 -0.213599" size="0.059800684452056885 0.2723213732242584 0.040973205119371414" quat="1.0 0.0 0.0 0.0"/>
        <geom class="collision" type="box" pos="-0.491141 -0.028239 -0.224362" size="0.012497935444116592 0.2723214328289032 0.05173563212156296" quat="1.0 0.0 0.0 0.0"/>
        <geom class="collision" type="box" pos="0.492404 -0.028239 -0.225589" size="0.011018079705536366 0.2723214626312256 0.052963223308324814" quat="1.0 0.0 0.0 0.0"/>
        <geom class="collision" type="box" pos="-0.000000 -0.261698 -0.199101" size="0.5031148195266724 0.04257308691740036 0.05696665495634079" quat="1.0 0.0 0.0 0.0"/>
        <geom class="collision" type="box" pos="-0.000000 -0.297733 -0.265655" size="0.5031148195266724 0.006861616391688585 0.011589289642870426" quat="1.0 0.0 0.0 0.0"/>
        <geom class="collision" type="box" pos="-0.245198 0.009114 -0.177724" size="0.18749186396598816 0.22904665768146515 0.008937964215874672" quat="1.0 0.0 0.0 0.0"/>
        <geom class="collision" type="box" pos="0.248248 0.009114 -0.177724" size="0.18749186396598816 0.22904665768146515 0.008937967009842396" quat="1.0 0.0 0.0 0.0"/>
        <geom class="collision" type="cylinder" pos="-0.310267 -0.256152 -0.259484" size="0.0319037064909935 0.008677883073687553" quat="1.0 0.0 0.0 0.0"/>
        <geom class="collision" type="cylinder" pos="0.002586 -0.256152 -0.259484" size="0.0319037064909935 0.008677883073687553" quat="1.0 0.0 0.0 0.0"/>
        <geom class="collision" type="cylinder" pos="0.305254 -0.256152 -0.259484" size="0.0319037064909935 0.008677883073687553" quat="1.0 0.0 0.0 0.0"/>
        <geom class="collision" type="box" pos="0.456571 0.010770 -0.213599" size="0.02761506475508213 0.2309870421886444 0.04097319766879082" quat="1.0 0.0 0.0 0.0"/>
        <geom class="collision" type="box" pos="-0.453150 0.010770 -0.213599" size="0.02576306276023388 0.230987086892128 0.04097319766879082" quat="1.0 0.0 0.0 0.0"/>
        <body name="Button001">
          <joint axis="0.0 1.0 0.0" pos="-0.140570 -0.306417 -0.213872" limited="true" name="Button001_joint" range="0.0 0.004" type="slide" damping="1" frictionloss="1" armature=".01" stiffness="0.05"/>
          <geom mesh="Button001_vis" type="mesh" solimp="0.998 0.998 0.001" solref="0.001 1" density="100" friction="0.95 0.3 0.1" class="visual" material="Button001_material"/>
          <geom class="collision" type="cylinder" pos="-0.140560 -0.307832 -0.213944" size="0.01494545303285122 0.002617895370349288" quat="0.7071067094802856 0.7071068286895752 0.0 0.0"/>
        </body>
        <body name="Button002">
          <joint axis="0.0 1.0 0.0" pos="-0.060564 -0.306417 -0.213872" limited="true" name="Button002_joint" range="0.0 0.004" type="slide" damping="1" frictionloss="1" armature=".01" stiffness="0.05"/>
          <geom mesh="Button002_vis" type="mesh" solimp="0.998 0.998 0.001" solref="0.001 1" density="100" friction="0.95 0.3 0.1" class="visual" material="Button002_material"/>
          <geom class="collision" type="cylinder" pos="-0.060605 -0.307832 -0.213944" size="0.01494545303285122 0.002617895370349288" quat="0.7071067094802856 0.7071068286895752 0.0 0.0"/>
        </body>
        <body name="Button003">
          <joint axis="0.0 1.0 0.0" pos="0.014618 -0.306417 -0.213872" limited="true" name="Button003_joint" range="0.0 0.004" type="slide" damping="1" frictionloss="1" armature=".01" stiffness="0.05"/>
          <geom mesh="Button003_vis" type="mesh" solimp="0.998 0.998 0.001" solref="0.001 1" density="100" friction="0.95 0.3 0.1" class="visual" material="Button003_material"/>
          <geom class="collision" type="cylinder" pos="0.015029 -0.307832 -0.213944" size="0.01494545303285122 0.002617895370349288" quat="0.7071067094802856 0.7071068286895752 0.0 0.0"/>
        </body>
        <body name="Button004">
          <joint axis="0.0 1.0 0.0" pos="0.090061 -0.306417 -0.213872" limited="true" name="Button004_joint" range="0.0 0.004" type="slide" damping="1" frictionloss="1" armature=".01" stiffness="0.05"/>
          <geom mesh="Button004_vis" type="mesh" solimp="0.998 0.998 0.001" solref="0.001 1" density="100" friction="0.95 0.3 0.1" class="visual" material="Button004_material"/>
          <geom class="collision" type="cylinder" pos="0.090269 -0.307832 -0.213944" size="0.01494545303285122 0.002617895370349288" quat="0.7071067094802856 0.7071068286895752 0.0 0.0"/>
        </body>
        <body name="Button005">
          <joint axis="0.0 1.0 0.0" pos="0.163793 -0.306417 -0.213872" limited="true" name="Button005_joint" range="0.0 0.004" type="slide" damping="1" frictionloss="1" armature=".01" stiffness="0.05"/>
          <geom mesh="Button005_vis" type="mesh" solimp="0.998 0.998 0.001" solref="0.001 1" density="100" friction="0.95 0.3 0.1" class="visual" material="Button005_material"/>
          <geom class="collision" type="cylinder" pos="0.163938 -0.307832 -0.213944" size="0.01494545303285122 0.002617895370349288" quat="0.7071067094802856 0.7071068286895752 0.0 0.0"/>
        </body>
        <geom class="region" name="reg_main" type="box" pos="0.0 0.001988500000000004 0.0" size="0.499026 0.3078335 0.276029"/>
      </body>
    </body>
  </worldbody>
  <actuator>
    <motor name="Button001_joint_actuator" joint="Button001_joint" gear="2"/>
    <motor name="Button002_joint_actuator" joint="Button002_joint" gear="2"/>
    <motor name="Button003_joint_actuator" joint="Button003_joint" gear="2"/>
    <motor name="Button004_joint_actuator" joint="Button004_joint" gear="2"/>
    <motor name="Button005_joint_actuator" joint="Button005_joint" gear="2"/>
  </actuator>
</mujoco>
