<?xml version='1.0' encoding='utf-8'?>
<mujoco model="model">
    <compiler angle="radian" />
    <asset>
        <mesh file="visuals/RangeHood019_Body001.obj" name="RangeHood019_Body001_vis" />
        <mesh file="visuals/RangeHood019_Button001.obj" name="RangeHood019_Button001_vis" />
        <mesh file="visuals/RangeHood019_Button002.obj" name="RangeHood019_Button002_vis" />
        <mesh file="visuals/RangeHood019_Button003.obj" name="RangeHood019_Button003_vis" />
        <mesh file="visuals/RangeHood019_Button004.obj" name="RangeHood019_Button004_vis" />
        <mesh file="visuals/RangeHood019_Button005.obj" name="RangeHood019_Button005_vis" />
        <texture file="visuals/T_RangeHood019_BC001.png" name="RangeHood019_Body001_material" type="2d" />
        <material name="RangeHood019_Body001_material" rgba="1 1 1 1.0" texture="RangeHood019_Body001_material" shininess="0.141421377658844" specular="0.3103448502657381" />
        <texture file="visuals/T_RangeHood019_BC001.png" name="RangeHood019_Button001_material" type="2d" />
        <material name="RangeHood019_Button001_material" rgba="1 1 1 1.0" texture="RangeHood019_Button001_material" shininess="0.141421377658844" specular="0.3103448502657381" />
        <texture file="visuals/T_RangeHood019_BC001.png" name="RangeHood019_Button002_material" type="2d" />
        <material name="RangeHood019_Button002_material" rgba="1 1 1 1.0" texture="RangeHood019_Button002_material" shininess="0.141421377658844" specular="0.3103448502657381" />
        <texture file="visuals/T_RangeHood019_BC001.png" name="RangeHood019_Button003_material" type="2d" />
        <material name="RangeHood019_Button003_material" rgba="1 1 1 1.0" texture="RangeHood019_Button003_material" shininess="0.141421377658844" specular="0.3103448502657381" />
        <texture file="visuals/T_RangeHood019_BC001.png" name="RangeHood019_Button004_material" type="2d" />
        <material name="RangeHood019_Button004_material" rgba="1 1 1 1.0" texture="RangeHood019_Button004_material" shininess="0.141421377658844" specular="0.3103448502657381" />
        <texture file="visuals/T_RangeHood019_BC001.png" name="RangeHood019_Button005_material" type="2d" />
        <material name="RangeHood019_Button005_material" rgba="1 1 1 1.0" texture="RangeHood019_Button005_material" shininess="0.141421377658844" specular="0.3103448502657381" />
    </asset>
    <default>
        <default class="visual">
            <geom conaffinity="0" contype="0" group="1" type="mesh" />
        </default>
        <default class="collision">
            <geom group="0" rgba="0.5 0 0 0.5" />
    </default>
        <default class="spawn">
            <geom group="0" rgba="1 1 1 0.5" contype="0" conaffinity="0" />
            <site group="0" rgba="1 1 1 0.5" />
        </default>
    </default>
    <worldbody>
        <body>
            <site rgba="0 0 0 0.5" size="0.01" pos="-0.447165 -0.201431 -0.676163" name="ext_p0" />
            <site rgba="1 0 0 0.5" size="0.01" pos="0.447836 -0.201431 -0.676163" name="ext_px" />
            <site rgba="0 1 0 0.5" size="0.01" pos="-0.447165 0.199411 -0.676163" name="ext_py" />
            <site rgba="0 0 1 0.5" size="0.01" pos="-0.447165 -0.201431 0.676163" name="ext_pz" />
            <body name="object">
                <geom mesh="RangeHood019_Body001_vis" type="mesh" solimp="0.998 0.998 0.001" solref="0.001 1" density="100" friction="0.95 0.3 0.1" class="visual" material="RangeHood019_Body001_material" />
                <geom class="collision" type="box" pos="0.000669 0.033546 -0.405528" size="0.4479215443134308 0.24603599309921265 0.031694505363702774" quat="0.882147490978241 -0.47097328305244446 1.0403968710015132e-16 -2.8502211480588545e-19" />
                <geom class="collision" type="box" pos="0.000335 0.055192 0.241410" size="0.20281653106212616 0.14591030776500702 0.43344056606292725" quat="1.0 0.0 0.0 0.0" />
                <geom class="collision" type="box" pos="-0.000000 0.169420 -0.631414" size="0.4483370780944824 0.031127022579312325 0.04460078105330467" quat="1.0 0.0 0.0 0.0" />
                <geom class="collision" type="box" pos="-0.000000 -0.138144 -0.219603" size="0.4483370780944824 0.05307907611131668 0.03169449791312218" quat="1.0 0.0 0.0 0.0" />
                <geom class="collision" type="box" pos="-0.001785 0.077027 -0.335474" size="0.32393988966941833 0.06334581226110458 0.11842090636491776" quat="0.9568553566932678 0.29056471586227417 0.0 0.0" />
                <geom class="collision" type="box" pos="-0.000051 0.173229 -0.556374" size="0.30869561433792114 0.028240203857421875 0.03860531374812126" quat="1.0 0.0 0.0 0.0" />
                <geom class="collision" type="box" pos="-0.000051 0.153358 -0.484176" size="0.30869561433792114 0.04811130836606026 0.03860531374812126" quat="1.0 0.0 0.0 0.0" />
                <geom class="collision" type="box" pos="-0.000051 0.145741 -0.316596" size="0.30869561433792114 0.05572855472564697 0.12868766486644745" quat="1.0 0.0 0.0 0.0" />
                <geom class="collision" type="box" pos="0.001686 0.016751 -0.228170" size="0.3348701596260071 0.08984062075614929 0.04026122763752937" quat="1.0 0.0 0.0 0.0" />
                <body name="RangeHood019_Button001">
                    <joint axis="0.0 1.0 0.0" pos="-0.171879 -0.199553 -0.219038" limited="true" name="RangeHood019_Button001_joint" range="0.0 0.002" type="slide" damping="1" frictionloss="1" armature=".01" stiffness="0.05" />
                    <geom mesh="RangeHood019_Button001_vis" type="mesh" solimp="0.998 0.998 0.001" solref="0.001 1" density="100" friction="0.95 0.3 0.1" class="visual" material="RangeHood019_Button001_material" />
                    <geom class="collision" type="cylinder" pos="-0.171879 -0.199499 -0.219038" size="0.006602177862077951 0.0019707230385392904" quat="0.7071068286895752 0.7071067690849304 0.0 0.0" />
                </body>
                <body name="RangeHood019_Button002">
                    <joint axis="0.0 1.0 0.0" pos="-0.084945 -0.199553 -0.219038" limited="true" name="RangeHood019_Button002_joint" range="0.0 0.002" type="slide" damping="1" frictionloss="1" armature=".01" stiffness="0.05" />
                    <geom mesh="RangeHood019_Button002_vis" type="mesh" solimp="0.998 0.998 0.001" solref="0.001 1" density="100" friction="0.95 0.3 0.1" class="visual" material="RangeHood019_Button002_material" />
                    <geom class="collision" type="cylinder" pos="-0.085035 -0.199499 -0.219038" size="0.006602177862077951 0.0019707230385392904" quat="0.7071068286895752 0.7071067690849304 0.0 0.0" />
                </body>
                <body name="RangeHood019_Button003">
                    <joint axis="0.0 1.0 0.0" pos="0.001236 -0.199553 -0.219038" limited="true" name="RangeHood019_Button003_joint" range="0.0 0.002" type="slide" damping="1" frictionloss="1" armature=".01" stiffness="0.05" />
                    <geom mesh="RangeHood019_Button003_vis" type="mesh" solimp="0.998 0.998 0.001" solref="0.001 1" density="100" friction="0.95 0.3 0.1" class="visual" material="RangeHood019_Button003_material" />
                    <geom class="collision" type="cylinder" pos="0.001239 -0.199499 -0.219038" size="0.006602177862077951 0.0019707230385392904" quat="0.7071068286895752 0.7071067690849304 0.0 0.0" />
                </body>
                <body name="RangeHood019_Button004">
                    <joint axis="0.0 1.0 0.0" pos="0.085166 -0.199553 -0.219038" limited="true" name="RangeHood019_Button004_joint" range="0.0 0.002" type="slide" damping="1" frictionloss="1" armature=".01" stiffness="0.05" />
                    <geom mesh="RangeHood019_Button004_vis" type="mesh" solimp="0.998 0.998 0.001" solref="0.001 1" density="100" friction="0.95 0.3 0.1" class="visual" material="RangeHood019_Button004_material" />
                    <geom class="collision" type="cylinder" pos="0.085176 -0.199499 -0.219038" size="0.006602177862077951 0.0019707230385392904" quat="0.7071068286895752 0.7071067690849304 0.0 0.0" />
                </body>
                <body name="RangeHood019_Button005">
                    <joint axis="0.0 1.0 0.0" pos="0.168235 -0.199553 -0.219038" limited="true" name="RangeHood019_Button005_joint" range="0.0 0.002" type="slide" damping="1" frictionloss="1" armature=".01" stiffness="0.05" />
                    <geom mesh="RangeHood019_Button005_vis" type="mesh" solimp="0.998 0.998 0.001" solref="0.001 1" density="100" friction="0.95 0.3 0.1" class="visual" material="RangeHood019_Button005_material" />
                    <geom class="collision" type="cylinder" pos="0.168255 -0.199499 -0.219038" size="0.006602177862077951 0.0019707230385392904" quat="0.7071068286895752 0.7071067690849304 0.0 0.0" />
                </body>
            </body>
        </body>
    </worldbody>
    <actuator>
        <motor name="RangeHood019_Button001_joint_actuator" joint="RangeHood019_Button001_joint" gear="0.2" />
        <motor name="RangeHood019_Button002_joint_actuator" joint="RangeHood019_Button002_joint" gear="0.2" />
        <motor name="RangeHood019_Button003_joint_actuator" joint="RangeHood019_Button003_joint" gear="0.2" />
        <motor name="RangeHood019_Button004_joint_actuator" joint="RangeHood019_Button004_joint" gear="0.2" />
        <motor name="RangeHood019_Button005_joint_actuator" joint="RangeHood019_Button005_joint" gear="0.2" />
    </actuator>
</mujoco>