<mujoco model="model">
  <compiler angle="radian"/>
  <asset>
    <mesh file="visuals/Body001.obj" name="Body001_vis"/>
    <mesh file="visuals/Button001.obj" name="Button001_vis"/>
    <mesh file="visuals/Button002.obj" name="Button002_vis"/>
    <mesh file="visuals/Button003.obj" name="Button003_vis"/>
    <mesh file="visuals/Button004.obj" name="Button004_vis"/>
    <mesh file="visuals/Button005.obj" name="Button005_vis"/>
    <texture file="visuals/T_BC001.png" name="Body001_material" type="2d"/>
    <material name="Body001_material" rgba="1 1 1 1.0" texture="Body001_material" shininess="0.141421377658844" specular="0.3103448502657381"/>
    <texture file="visuals/T_BC001.png" name="Button001_material" type="2d"/>
    <material name="Button001_material" rgba="1 1 1 1.0" texture="Button001_material" shininess="0.141421377658844" specular="0.3103448502657381"/>
    <texture file="visuals/T_BC001.png" name="Button002_material" type="2d"/>
    <material name="Button002_material" rgba="1 1 1 1.0" texture="Button002_material" shininess="0.141421377658844" specular="0.3103448502657381"/>
    <texture file="visuals/T_BC001.png" name="Button003_material" type="2d"/>
    <material name="Button003_material" rgba="1 1 1 1.0" texture="Button003_material" shininess="0.141421377658844" specular="0.3103448502657381"/>
    <texture file="visuals/T_BC001.png" name="Button004_material" type="2d"/>
    <material name="Button004_material" rgba="1 1 1 1.0" texture="Button004_material" shininess="0.141421377658844" specular="0.3103448502657381"/>
    <texture file="visuals/T_BC001.png" name="Button005_material" type="2d"/>
    <material name="Button005_material" rgba="1 1 1 1.0" texture="Button005_material" shininess="0.141421377658844" specular="0.3103448502657381"/>
  </asset>
  <default>
    <default class="visual">
      <geom conaffinity="0" contype="0" group="1" type="mesh"/>
    </default>
    <default class="collision">
      <geom group="0" rgba="0.5 0 0 0.5"/>
    </default>
    <default class="spawn">
      <geom group="0" rgba="1 1 1 0.5" contype="0" conaffinity="0"/>
      <site group="0" rgba="1 1 1 0.5"/>
    </default>
    <default class="region">
      <geom group="1" conaffinity="0" contype="0" rgba="0 1 0 0"/>
    </default>
  </default>
  <worldbody>
    <body>
      <body name="object">
        <geom mesh="Body001_vis" type="mesh" solimp="0.998 0.998 0.001" solref="0.001 1" density="100" friction="0.95 0.3 0.1" class="visual" material="Body001_material"/>
        <geom class="collision" type="box" pos="0.000669 0.033546 -0.405528" size="0.4479215443134308 0.24603599309921265 0.031694505363702774" quat="0.882147490978241 -0.47097328305244446 1.0403968710015132e-16 -2.8502211480588545e-19"/>
        <geom class="collision" type="box" pos="0.000335 0.055192 0.241410" size="0.20281653106212616 0.14591030776500702 0.43344056606292725" quat="1.0 0.0 0.0 0.0"/>
        <geom class="collision" type="box" pos="-0.000000 0.169420 -0.631414" size="0.4483370780944824 0.031127022579312325 0.04460078105330467" quat="1.0 0.0 0.0 0.0"/>
        <geom class="collision" type="box" pos="-0.000000 -0.138144 -0.219603" size="0.4483370780944824 0.05307907611131668 0.03169449791312218" quat="1.0 0.0 0.0 0.0"/>
        <geom class="collision" type="box" pos="-0.001785 0.077027 -0.335474" size="0.32393988966941833 0.06334581226110458 0.11842090636491776" quat="0.9568553566932678 0.29056471586227417 0.0 0.0"/>
        <geom class="collision" type="box" pos="-0.000051 0.173229 -0.556374" size="0.30869561433792114 0.028240203857421875 0.03860531374812126" quat="1.0 0.0 0.0 0.0"/>
        <geom class="collision" type="box" pos="-0.000051 0.153358 -0.484176" size="0.30869561433792114 0.04811130836606026 0.03860531374812126" quat="1.0 0.0 0.0 0.0"/>
        <geom class="collision" type="box" pos="-0.000051 0.145741 -0.316596" size="0.30869561433792114 0.05572855472564697 0.12868766486644745" quat="1.0 0.0 0.0 0.0"/>
        <geom class="collision" type="box" pos="0.001686 0.016751 -0.228170" size="0.3348701596260071 0.08984062075614929 0.04026122763752937" quat="1.0 0.0 0.0 0.0"/>
        <body name="Button001">
          <joint axis="0.0 1.0 0.0" pos="-0.171879 -0.199553 -0.219038" limited="true" name="Button001_joint" range="0.0 0.002" type="slide" damping="1" frictionloss="1" armature=".01" stiffness="0.05"/>
          <geom mesh="Button001_vis" type="mesh" solimp="0.998 0.998 0.001" solref="0.001 1" density="100" friction="0.95 0.3 0.1" class="visual" material="Button001_material"/>
          <geom class="collision" type="cylinder" pos="-0.171879 -0.199499 -0.219038" size="0.006602177862077951 0.0019707230385392904" quat="0.7071068286895752 0.7071067690849304 0.0 0.0"/>
        </body>
        <body name="Button002">
          <joint axis="0.0 1.0 0.0" pos="-0.084945 -0.199553 -0.219038" limited="true" name="Button002_joint" range="0.0 0.002" type="slide" damping="1" frictionloss="1" armature=".01" stiffness="0.05"/>
          <geom mesh="Button002_vis" type="mesh" solimp="0.998 0.998 0.001" solref="0.001 1" density="100" friction="0.95 0.3 0.1" class="visual" material="Button002_material"/>
          <geom class="collision" type="cylinder" pos="-0.085035 -0.199499 -0.219038" size="0.006602177862077951 0.0019707230385392904" quat="0.7071068286895752 0.7071067690849304 0.0 0.0"/>
        </body>
        <body name="Button003">
          <joint axis="0.0 1.0 0.0" pos="0.001236 -0.199553 -0.219038" limited="true" name="Button003_joint" range="0.0 0.002" type="slide" damping="1" frictionloss="1" armature=".01" stiffness="0.05"/>
          <geom mesh="Button003_vis" type="mesh" solimp="0.998 0.998 0.001" solref="0.001 1" density="100" friction="0.95 0.3 0.1" class="visual" material="Button003_material"/>
          <geom class="collision" type="cylinder" pos="0.001239 -0.199499 -0.219038" size="0.006602177862077951 0.0019707230385392904" quat="0.7071068286895752 0.7071067690849304 0.0 0.0"/>
        </body>
        <body name="Button004">
          <joint axis="0.0 1.0 0.0" pos="0.085166 -0.199553 -0.219038" limited="true" name="Button004_joint" range="0.0 0.002" type="slide" damping="1" frictionloss="1" armature=".01" stiffness="0.05"/>
          <geom mesh="Button004_vis" type="mesh" solimp="0.998 0.998 0.001" solref="0.001 1" density="100" friction="0.95 0.3 0.1" class="visual" material="Button004_material"/>
          <geom class="collision" type="cylinder" pos="0.085176 -0.199499 -0.219038" size="0.006602177862077951 0.0019707230385392904" quat="0.7071068286895752 0.7071067690849304 0.0 0.0"/>
        </body>
        <body name="Button005">
          <joint axis="0.0 1.0 0.0" pos="0.168235 -0.199553 -0.219038" limited="true" name="Button005_joint" range="0.0 0.002" type="slide" damping="1" frictionloss="1" armature=".01" stiffness="0.05"/>
          <geom mesh="Button005_vis" type="mesh" solimp="0.998 0.998 0.001" solref="0.001 1" density="100" friction="0.95 0.3 0.1" class="visual" material="Button005_material"/>
          <geom class="collision" type="cylinder" pos="0.168255 -0.199499 -0.219038" size="0.006602177862077951 0.0019707230385392904" quat="0.7071068286895752 0.7071067690849304 0.0 0.0"/>
        </body>
        <geom class="region" name="reg_main" type="box" pos="0.00033550000000001634 -0.001009999999999997 0.0" size="0.44750049999999997 0.20042100000000002 0.676163"/>
      </body>
    </body>
  </worldbody>
  <actuator>
    <motor name="Button001_joint_actuator" joint="Button001_joint" gear="0.2"/>
    <motor name="Button002_joint_actuator" joint="Button002_joint" gear="0.2"/>
    <motor name="Button003_joint_actuator" joint="Button003_joint" gear="0.2"/>
    <motor name="Button004_joint_actuator" joint="Button004_joint" gear="0.2"/>
    <motor name="Button005_joint_actuator" joint="Button005_joint" gear="0.2"/>
  </actuator>
</mujoco>
