<mujoco model="model">
  <compiler angle="radian"/>
  <asset>
    <mesh file="visuals/Dishwasher032_Door001.obj" name="Dishwasher032_Door_vis"/>
    <mesh file="visuals/Dishwasher032_Shelf002.obj" name="Dishwasher032_Shelf2_vis"/>
    <mesh file="visuals/Dishwasher032_Button002.obj" name="Dishwasher032_Button2_vis"/>
    <mesh file="visuals/Dishwasher032_Shelf001.obj" name="Dishwasher032_Shelf1_vis"/>
    <mesh file="visuals/Dishwasher032_Button001.obj" name="Dishwasher032_Button1_vis"/>
    <mesh file="visuals/Dishwasher032_Body001.obj" name="Dishwasher032_Body_vis"/>
    <texture file="visuals/T_Dishwasher32_BC001.png" name="T_Dishwasher32_BaseColor" type="2d"/>
    <material name="material" rgba="1 1 1 1" texture="T_Dishwasher32_BaseColor"/>
  </asset>
  <default>
    <default class="visual">
      <geom conaffinity="0" contype="0" group="1" type="mesh"/>
    </default>
    <default class="collision">
      <geom group="0" rgba="0.5 0 0 0.5"/>
    </default>
  </default>
  <worldbody>
    <body>
      <geom name="reg_ext" conaffinity="0" contype="0" group="1" type="box" size="0.28506916761398315 0.22750000655651093 0.3126577287912369" pos="-0.0017305612564086914 0.0019617166835814714 0.3126577287912369" rgba="0 0 1 0"/>
      <geom name="reg_int" conaffinity="0" contype="0" group="1" type="box" size="0.21625076979398727 0.17631269991397858 0.2052006982266903" pos="0.0027486905455589294 0.01602134108543396 0.26530495658516884" rgba="0 0 1 0"/>
      <body name="object">
        <geom mesh="Dishwasher032_Body_vis" type="mesh" solimp="0.998 0.998 0.001" solref="0.001 1" density="100" friction="0.95 0.3 0.1" class="visual" material="material"/>
        <geom class="collision" type="box" pos="-0.0018957694992423058 0.01668199896812439 0.5393564105033875" size="0.21029743552207947 0.26956525444984436 0.06475762277841568" quat="0.7071067690849304 0.0 0.0 -0.7071067690849304"/>
        <geom class="collision" type="box" pos="-0.0018957694992423058 0.01668199896812439 0.024256287142634392" size="0.21029743552207947 0.26956525444984436 0.023800313472747803" quat="0.7071067690849304 0.0 0.0 -0.7071067690849304"/>
        <geom class="collision" type="box" pos="0.2454683482646942 0.016681984066963196 0.26908645033836365" size="0.21029740571975708 0.26956525444984436 0.023800328373908997" quat="0.5000000596046448 -0.5 0.4999999701976776 -0.5"/>
        <geom class="collision" type="box" pos="-0.24863016605377197 0.01668199896812439 0.26908639073371887" size="0.21029740571975708 0.269565224647522 0.023800332099199295" quat="0.5000000596046448 -0.5 0.4999999701976776 -0.5"/>
        <geom class="collision" type="box" pos="-0.0020945370197296143 -0.19469085335731506 0.5814701914787292" size="0.0006708857254125178 0.28551146388053894 0.04393337666988373" quat="0.7071067690849304 0.0 0.0 -0.7071067690849304"/>
        <geom class="collision" type="box" pos="-0.0018957555294036865 0.2211882323026657 0.30254751443862915" size="0.0067467098124325275 0.26956525444984436 0.301566481590271" quat="0.7071067690849304 0.0 0.0 -0.7071067690849304"/>
        <body name="Dishwasher032_Button1">
          <joint axis="0 1 0" pos="-0.15934637188911438 -0.20224100351333618 0.5780166387557983" limited="true" name="Dishwasher032_Button1_joint" range="0.0 0.003" type="slide" damping="2" frictionloss="2" armature=".01"/>
          <geom mesh="Dishwasher032_Button1_vis" type="mesh" solimp="0.998 0.998 0.001" solref="0.001 1" density="100" friction="0.95 0.3 0.1" class="visual" material="material"/>
          <geom class="collision" type="cylinder" pos="-0.15934635698795319 -0.2014778107404709 0.5780166387557983" size="0.01903359219431877 0.002112695947289467" quat="0.5000000596046448 0.5000000596046448 0.4999999403953552 -0.4999999701976776"/>
        </body>
        <body name="Dishwasher032_Button2">
          <joint axis="0 1 0" pos="0.15588542819023132 -0.2022409737110138 0.5780166387557983" limited="true" name="Dishwasher032_Button2_joint" range="0.0 0.003" type="slide" damping="2" frictionloss="2" armature=".01"/>
          <geom mesh="Dishwasher032_Button2_vis" type="mesh" solimp="0.998 0.998 0.001" solref="0.001 1" density="100" friction="0.95 0.3 0.1" class="visual" material="material"/>
          <geom class="collision" type="cylinder" pos="0.15578481554985046 -0.2014778107404709 0.5780166387557983" size="0.01903359219431877 0.002112695947289467" quat="0.5000000596046448 0.5000000596046448 0.4999999403953552 -0.4999999701976776"/>
        </body>
        <body name="Dishwasher032_Door">
          <joint axis="1 0 0" pos="-0.0020254109986126423 -0.1931646466255188 -0.00036662659840658307" limited="true" name="Dishwasher032_Door_joint" range="0.0 0.79" type="hinge" damping="2" frictionloss="20" armature=".01"/>
          <geom mesh="Dishwasher032_Door_vis" type="mesh" solimp="0.998 0.998 0.001" solref="0.001 1" density="100" friction="0.95 0.3 0.1" class="visual" material="material"/>
          <geom class="collision" type="cylinder" pos="-1.0150045437785034e-16 -0.2666173279285431 0.47182366251945496" size="0.01004740595817566 0.06065373867750168" quat="0.7071068286895752 1.2101618374060763e-08 0.7071067690849304 -1.2101617485882343e-08"/>
          <geom class="collision" type="cylinder" pos="-0.12063857167959213 -0.2582337260246277 0.47182366251945496" size="0.010047406889498234 0.06065373867750168" quat="0.7052760124206543 0.05085095390677452 0.7052759528160095 -0.05085095018148422"/>
          <geom class="collision" type="cylinder" pos="0.11992809921503067 -0.25766533613204956 0.47182366251945496" size="0.01004740595817566 0.06065373867750168" quat="0.705083429813385 -0.053454648703336716 0.7050833702087402 0.05345464497804642"/>
          <geom class="collision" type="cylinder" pos="0.20940566062927246 -0.24207565188407898 0.47182366251945496" size="0.010047406889498234 0.033481400460004807" quat="0.7034791111946106 -0.07153436541557312 0.7034790515899658 0.07153435796499252"/>
          <geom class="collision" type="cylinder" pos="-0.21443267166614532 -0.24204936623573303 0.47182366251945496" size="0.01004740595817566 0.03348139673471451" quat="0.7033578753471375 0.07271656394004822 0.7033578753471375 -0.07271655648946762"/>
        </body>
        <body name="Dishwasher032_Shelf1">
          <joint axis="0 -1 0" pos="-0.006404141429811716 0.0029320232570171356 0.3411805331707001" limited="true" name="Dishwasher032_Shelf1_joint" range="0.0 0.25" type="slide" damping="2" frictionloss="2" armature=".01"/>
          <geom mesh="Dishwasher032_Shelf1_vis" type="mesh" solimp="0.998 0.998 0.001" solref="0.001 1" density="100" friction="0.95 0.3 0.1" class="visual" material="material"/>
          <geom class="collision" type="box" pos="-0.0057608638890087605 0.15042434632778168 0.33242934942245483" size="0.1883002668619156 0.0029522564727813005 0.04325665533542633" quat="1.0 0.0 0.0 0.0"/>
          <geom class="collision" type="box" pos="0.17856302857398987 0.01908557116985321 0.33242934942245483" size="0.1331595480442047 0.002952256938442588 0.04325665533542633" quat="0.7071067690849304 0.0 -0.0 -0.7071067690849304"/>
          <geom class="collision" type="box" pos="0.17856302857398987 0.01908557116985321 0.33242934942245483" size="0.1331595480442047 0.002952256938442588 0.04325665533542633" quat="0.7071067690849304 0.0 -0.0 -0.7071067690849304"/>
          <geom class="collision" type="box" pos="-0.1932958960533142 0.01908557116985321 0.33242934942245483" size="0.1331595480442047 0.002952256938442588 0.04325665533542633" quat="0.7071067690849304 0.0 -0.0 -0.7071067690849304"/>
          <geom class="collision" type="box" pos="-0.0057608638890087605 -0.11161099374294281 0.33242934942245483" size="0.1883002668619156 0.0029522564727813005 0.04325665533542633" quat="1.0 0.0 0.0 0.0"/>
          <geom class="collision" type="box" pos="-0.0057608638890087605 0.01908554881811142 0.28907790780067444" size="0.1883002668619156 0.002952256938442588 0.13367383182048798" quat="0.7071067690849304 0.7071067690849304 -1.5700926965105832e-16 3.431546515433212e-24"/>
          <geom class="collision" type="box" pos="-0.15607543289661407 0.019085552543401718 0.3833683729171753" size="0.049168653786182404 0.0029522560071200132 0.13367381691932678" quat="0.6528859734535217 0.6528859734535217 -0.2715509235858917 0.2715509533882141"/>
          <geom class="collision" type="box" pos="0.14477597177028656 0.019085552543401718 0.38433367013931274" size="0.0491686686873436 0.002952256705611944 0.13367383182048798" quat="0.2624167799949646 0.262416809797287 -0.6566104888916016 0.6566106081008911"/>
          <geom class="collision" type="box" pos="0.020082632079720497 0.01908555068075657 0.33798515796661377" size="0.026120148599147797 0.0029522560071200132 0.13367381691932678" quat="0.5006696581840515 0.5006696581840515 -0.49932944774627686 0.49932947754859924"/>
          <geom class="collision" type="box" pos="-0.02933082915842533 0.01908554695546627 0.3381175994873047" size="0.026120148599147797 0.0029522560071200132 0.13367381691932678" quat="0.5006696581840515 0.5006696581840515 -0.49932944774627686 0.49932947754859924"/>
          <geom class="collision" type="box" pos="-0.09876056760549545 0.01908554509282112 0.3080485761165619" size="0.031425610184669495 0.0029522564727813005 0.13367381691932678" quat="0.5006696581840515 0.5006696581840515 -0.49932944774627686 0.49932947754859924"/>
          <geom class="collision" type="box" pos="0.0904393345117569 0.019085556268692017 0.3075414299964905" size="0.031425610184669495 0.0029522564727813005 0.13367381691932678" quat="0.5006696581840515 0.5006696581840515 -0.49932944774627686 0.49932947754859924"/>
        </body>
        <body name="Dishwasher032_Shelf2">
          <joint axis="0 -1 0" pos="0.0001301566808251664 0.01636328548192978 0.16738994419574738" limited="true" name="Dishwasher032_Shelf2_joint" range="0.0 0.25" type="slide" damping="2" frictionloss="2" armature=".01"/>
          <geom mesh="Dishwasher032_Shelf2_vis" type="mesh" solimp="0.998 0.998 0.001" solref="0.001 1" density="100" friction="0.95 0.3 0.1" class="visual" material="material"/>
          <geom class="collision" type="box" pos="-0.18803180754184723 0.024459408596158028 0.1597479283809662" size="0.0036186655052006245 0.10586300492286682 0.05741702765226364" quat="1.0 0.0 0.0 0.0"/>
          <geom class="collision" type="box" pos="0.19161631166934967 0.024459408596158028 0.1597479283809662" size="0.0036186655052006245 0.10586300492286682 0.05741702765226364" quat="1.0 0.0 0.0 0.0"/>
          <geom class="collision" type="box" pos="0.0041309441439807415 0.15191827714443207 0.1597479283809662" size="0.0036186659708619118 0.15860338509082794 0.05741702765226364" quat="0.7071067690849304 0.0 -0.0 -0.7071067690849304"/>
          <geom class="collision" type="box" pos="0.1782337874174118 0.13957515358924866 0.1597479283809662" size="0.003618665272369981 0.020787067711353302 0.05741702765226364" quat="0.4040769040584564 0.0 -0.0 -0.9147250056266785"/>
          <geom class="collision" type="box" pos="-0.17073184251785278 0.14056028425693512 0.1597479283809662" size="0.0036186655052006245 0.02078706957399845 0.05741702765226364" quat="0.8900058269500732 0.0 -0.0 -0.45594921708106995"/>
          <geom class="collision" type="box" pos="0.1619928479194641 -0.09208556264638901 0.1597479283809662" size="0.0036186655052006245 0.03688569366931915 0.05741702765226364" quat="0.876239538192749 0.0 -0.0 -0.48187580704689026"/>
          <geom class="collision" type="box" pos="-0.1600625216960907 -0.09321083128452301 0.1597479283809662" size="0.003618665272369981 0.031552840024232864 0.05741702765226364" quat="0.46219104528427124 0.0 -0.0 -0.8867803812026978"/>
          <geom class="collision" type="box" pos="-4.491070285439491e-06 -0.11192173510789871 0.1597479283809662" size="0.0036186659708619118 0.13690444827079773 0.05741702765226364" quat="0.7071067690849304 0.0 -0.0 -0.7071067690849304"/>
          <geom class="collision" type="box" pos="0.0014314198633655906 -0.1052643284201622 0.22658303380012512" size="0.003618665272369981 0.04680907726287842 0.014446288347244263" quat="0.6951007843017578 -0.1297493577003479 -0.1297493577003479 -0.6951007843017578"/>
          <geom class="collision" type="box" pos="0.0014314198633655906 -0.09925960749387741 0.2512545883655548" size="0.003618665272369981 0.04680907726287842 0.014446288347244263" quat="0.7070992588996887 -0.003261008532717824 -0.0032610094640403986 -0.7070992588996887"/>
          <geom class="collision" type="box" pos="-0.013206142000854015 -0.04663316160440445 0.13741004467010498" size="0.0036186659708619118 0.1266833245754242 0.03506574407219887" quat="0.7071067690849304 0.0 -0.0 -0.7071067690849304"/>
          <geom class="collision" type="box" pos="-0.013206139206886292 0.012032147496938705 0.13741004467010498" size="0.0036186659708619118 0.1266833245754242 0.03506574407219887" quat="0.7071067690849304 0.0 -0.0 -0.7071067690849304"/>
          <geom class="collision" type="box" pos="0.0025285487063229084 0.018802568316459656 0.10939037054777145" size="0.0036186655052006245 0.12554281949996948 0.19252623617649078" quat="0.7071068286895752 1.2101617485882343e-08 -0.7071067690849304 1.2101616597703924e-08"/>
        </body>
      </body>
    </body>
  </worldbody>
</mujoco>
