<mujoco model="model">
  <compiler angle="radian"/>
  <asset>
    <texture type="2d" name="image0" file="visuals/image0.png"/>
    <material name="kitchen_sink" texture="image0" specular="0.5" shininess="0.25"/>
    <mesh file="visuals/model_0.obj" name="model_0_vis" scale="1 1 1"/>
    <mesh file="visuals/model_1.obj" name="model_1_vis" scale="1 1 1"/>
    <mesh file="visuals/spout_0.obj" name="spout_0_vis" scale="1 1 1"/>
    <mesh file="visuals/handle_0.obj" name="handle_0_vis" scale="1 1 1"/>
  </asset>
  <default>
    <default class="visual">
      <geom conaffinity="0" contype="0" group="1" type="mesh"/>
    </default>
    <default class="collision">
      <!-- <geom group="0" rgba="0.5 0 0 0.5"/> -->
      <geom group="0" rgba="0.5 0 0 0.5" solimp="0.998 0.998 0.001" solref="0.001 2"/>
    </default>
  </default>
  <worldbody>
    <body>
      <body name="object">
        <!-- <geom solimp="0.998 0.998 0.001" solref="0.001 1" density="100" friction="0.95 0.3 0.1" type="mesh" mesh="model_0_vis" material="geometry_1" class="visual"/> -->
        <geom solimp="0.998 0.998 0.001" solref="0.001 1" density="100" friction="0.95 0.3 0.1" type="mesh" mesh="model_1_vis" material="kitchen_sink" class="visual"/>
        <!--Add Collision Geom(s) for model here - i.e. <geom class="collision" type="" pos="" size=""/>-->
        <!-- Bottom -->
        <geom class="collision" type="box" pos="0 -0.08 -0.4825" size="0.485 0.35 0.0125" name="bottom"/>
        <!-- Left -->
        <geom class="collision" type="box" pos="-0.455 0 -0.31" size="0.04 0.43 0.18"/>
        <!-- Right -->
        <geom class="collision" type="box" pos="0.455 0 -0.31" size="0.04 0.43 0.18"/>
        <!-- Back -->
        <geom class="collision" type="box" pos="0 0.335 -0.31" size="0.485 0.115 0.18"/>
        <!-- Front -->
        <geom class="collision" type="box" pos="0 -0.41 -0.31" size="0.485 0.038 0.18"/>
        <!-- Base -->
        <geom class="collision" type="cylinder" pos="0 0.323 -0.026" size="0.05 0.105 0"/>
        <!-- Knob Connection -->
        <!-- <geom class="collision" type="cylinder" quat="0 1 0 1" pos="0.05 0.325 -0.01" size="0.039 0.029 0"/> -->
        <body name="spout">
          <joint axis="0 0 1" limited="true" name="spout_joint" damping="10" range="-1.57 1.57" pos="0 0.325 0.25"/>
          <geom solimp="0.998 0.998 0.001" solref="0.001 1" density="100" friction="0.95 0.3 0.1" type="mesh" mesh="spout_0_vis" material="kitchen_sink" class="visual"/>
          <!-- Faucet Main -->
          <geom class="collision" type="cylinder" pos="0 0.325 0.25" size="0.022 0.18 0"/>
          <geom class="collision" type="cylinder" axisangle="1 0 0 0.785" pos="0 0.28 0.45" size="0.025 0.05 0"/>
          <!-- Faucet Top -->
          <geom class="collision" type="cylinder" axisangle="1 0 0 1.5708" pos="0 0.15 0.47" size="0.025 0.13 0" name="spout_top"/>
          <!-- Faucet Front -->
          <geom class="collision" type="cylinder" axisangle="1 0 0 2.79" pos="0 -0.02 0.385" size="0.03 0.1 0"/>
          <site type="cylinder" rgba="0.5 0.75 1 1" pos="0.0 -0.05 -0.10" size="0.01 0.40" name="water"/>
        </body>
        <body name="handle">
          <joint axis="1 0 0" limited="true" name="handle_temp_joint" range="-0.785 0.785" damping="50" pos="0.079 0.325 -0.01" armature="2"/>
          <joint axis="0 1 0" limited="true" name="handle_joint" range="0 0.52" damping="10" pos="0.079 0.325 0.01" armature="2"/>
          <geom solimp="0.998 0.998 0.001" solref="0.001 1" density="100" friction="0.95 0.3 0.1" type="mesh" mesh="handle_0_vis" material="kitchen_sink" class="visual"/>
          <!-- Knob Main -->
          <geom class="collision" type="cylinder" pos="0.108 0.325 -0.01" size="0.039 0.029 0" quat="0 1 0 1"/>
          <!-- Knob Handle -->
          <geom class="collision" type="cylinder" pos="0.118 0.325 0.091" size="0.009 0.07 0" name="handle_main"/>
        </body>
        <!-- exterior bounding box points -->
        <geom name="reg_ext" conaffinity="0" contype="0" group="1" type="box" size="0.485 0.45 0.1785" pos="0.0 0.0 -0.3135" rgba="0 0 1 0"/>
        <!-- interior bounding box points -->
        <geom name="reg_int" conaffinity="0" contype="0" group="1" type="box" size="0.415 0.295 0.16749999999999998" pos="0.0 -0.075 -0.3025" rgba="0 0 1 0"/>
      </body>
    </body>
  </worldbody>
</mujoco>
