<mujoco model="model">
  <asset>
    <material name="metal_Mat" specular="0.5" shininess="0.36" rgba="0.800000 0.800000 0.800000 1.000000"/>
    <material name="sink_Mat" specular="0.5" shininess="0.36" rgba="0.800000 0.800000 0.800000 1.000000"/>
    <material name="tap_Mat" specular="0.5" shininess="0.36" rgba="0.800000 0.800000 0.800000 1.000000"/>
    <mesh file="visuals/model_0.obj" name="model_0_vis" scale="1 1 1"/>
    <mesh file="visuals/model_1.obj" name="model_1_vis" scale="1 1 1"/>
    <mesh file="visuals/model_2.obj" name="model_2_vis" scale="1 1 1"/>
    <mesh file="visuals/spout_0.obj" name="spout_0_vis" scale="1 1 1"/>
    <mesh file="visuals/handle_0.obj" name="handle_0_vis" scale="1 1 1"/>
  </asset>
  <default>
    <default class="visual">
      <geom conaffinity="0" contype="0" group="1" type="mesh"/>
    </default>
    <default class="collision">
      <!-- <geom group="0" rgba="0.5 0 0 0.5"/> -->
      <geom group="0" rgba="0.5 0 0 0.5" solimp="0.998 0.998 0.001" solref="0.001 2"/>
    </default>
    <default class="region">
      <geom group="1" conaffinity="0" contype="0" rgba="0 1 0 0"/>
    </default>
  </default>
  <worldbody>
    <body>
      <!-- exterior bounding box points -->
      <!-- interior bounding box points (LEFT) -->
      <!-- interior bounding box points (RIGHT) -->
      <body name="object">
        <geom solimp="0.998 0.998 0.001" solref="0.001 1" density="100" friction="0.95 0.3 0.1" type="mesh" mesh="model_0_vis" material="sink_Mat" class="visual"/>
        <geom solimp="0.998 0.998 0.001" solref="0.001 1" density="100" friction="0.95 0.3 0.1" type="mesh" mesh="model_1_vis" material="tap_Mat" class="visual"/>
        <geom solimp="0.998 0.998 0.001" solref="0.001 1" density="100" friction="0.95 0.3 0.1" type="mesh" mesh="model_2_vis" material="metal_Mat" class="visual"/>
        <!-- Bottom -->
        <geom class="collision" type="box" pos="0.27 0 -0.25" size="0.145 0.19 0.01"/>
        <!-- Left Wall -->
        <geom class="collision" type="box" pos="0.11 0 -0.14" size="0.01 0.21 0.11" axisangle="0 1 0 -3"/>
        <!-- Right Wall -->
        <geom class="collision" type="box" pos="0.44 0 -0.14" size="0.01 0.21 0.11" axisangle="0 1 0 10"/>
        <!-- Back Wall -->
        <geom class="collision" type="box" pos="0.27 0.205 -0.14" size="0.17 0.01 0.11" axisangle="1 0 0 -10"/>
        <!-- Front Wall -->
        <geom class="collision" type="box" pos="0.27 -0.2 -0.14" size="0.17 0.01 0.11" axisangle="1 0 0 12"/>
        <!-- Bottom 2 -->
        <geom class="collision" type="box" pos="-0.01 0 -0.16" size="0.07 0.15 0.01"/>
        <!-- Left Wall 2 -->
        <geom class="collision" type="box" pos="-0.09 0 -0.1" size="0.01 0.17 0.065" axisangle="0 1 0 -8"/>
        <!-- Right Wall 2 -->
        <geom class="collision" type="box" pos="0.075 0 -0.1" size="0.01 0.17 0.065" axisangle="0 1 0 7"/>
        <!-- Back Wall 2 -->
        <geom class="collision" type="box" pos="-0.01 0.16 -0.1" size="0.07 0.01 0.065" axisangle="1 0 0 -10"/>
        <!-- Front Wall 2 -->
        <geom class="collision" type="box" pos="-0.01 -0.16 -0.1" size="0.07 0.01 0.065" axisangle="1 0 0 10"/>
        <!-- Storage -->
        <geom class="collision" type="box" pos="-0.297 0 -0.034" size="0.203 0.26 0.01"/>
        <!-- Back Ledge -->
        <geom class="collision" type="box" pos="0.2 0.245 -0.034" size="0.3 0.014 0.01"/>
        <!-- Front Ledge -->
        <geom class="collision" type="box" pos="0.2 -0.245 -0.034" size="0.3 0.014 0.01"/>
        <!-- Right Ledge -->
        <geom class="collision" type="box" pos="0.48 0 -0.034" size="0.02 0.25 0.01"/>
        <!-- Divider Ledge -->
        <geom class="collision" type="box" pos="0.092 0 -0.04" size="0.014 0.2 0.01"/>
        <!-- Extended Back Ledge -->
        <geom class="collision" type="box" pos="-0.01 0.198 -0.04" size="0.09 0.033 0.01"/>
        <!-- Extended Front Ledge -->
        <geom class="collision" type="box" pos="-0.01 -0.198 -0.04" size="0.09 0.033 0.01"/>
        <!-- Faucet Base -->
        <geom class="collision" type="cylinder" pos="0.0915 0.2205 0.03" size="0.019 0.06 0"/>
        <!-- Handle Attach Point-->
        <geom class="collision" type="cylinder" pos="0.11 0.2205 0.0385" size="0.018 0.023 0" axisangle="0 1 0 90"/>
        <body name="spout">
          <joint axis="0 0 1" limited="true" name="faucet_joint" range="-135 45" pos="0.0915 0.2205 0.09" armature="2"/>
          <geom solimp="0.998 0.998 0.001" solref="0.001 1" density="100" friction="0.95 0.3 0.1" type="mesh" mesh="spout_0_vis" material="tap_Mat" class="visual"/>
          <geom class="collision" type="cylinder" pos="0.0915 0.2205 0.134" size="0.019 0.044 0"/>
          <geom class="collision" type="box" pos="0.107 0.205 0.222" size="0.013 0.05 0.015" quat="0.854 -0.354 -0.146 0.354"/>
          <geom class="collision" type="box" pos="0.192 0.12 0.248" size="0.013 0.0985 0.013" quat="0.923 -0.0322 -0.0134 0.382"/>
        </body>
        <body name="handle">
          <joint axis="1 0 0" limited="true" name="knob_joint" range="-90 90" pos="0.1332 0.2205 0.0385" armature="2"/>
          <joint axis="0 1 0" type="hinge" limited="true" name="knob_hinge_joint" range="0 10" pos="0.1332 0.2205 0.037" armature="2"/>
          <geom solimp="0.998 0.998 0.001" solref="0.001 1" density="100" friction="0.95 0.3 0.1" type="mesh" mesh="handle_0_vis" material="tap_Mat" class="visual"/>
          <geom class="collision" type="cylinder" pos="0.145 0.2205 0.0385" size="0.018 0.0118 0" axisangle="0 1 0 90"/>
          <geom class="collision" type="box" pos="0.1525 0.22 0.08353" size="0.0043 0.0021 0.032"/>
        </body>
        <geom class="region" name="reg_main_body" type="box" pos="0.0 0.0 -0.14200000000000002" size="0.5 0.259 0.11800000000000001"/>
        <geom class="region" name="reg_left_basin" type="box" pos="-0.010000000000000002 0.0 -0.095" size="0.07 0.16 0.05499999999999999"/>
        <geom class="region" name="reg_right_basin" type="box" pos="0.275 0.0024999999999999883 -0.135" size="0.165 0.2025 0.105"/>
      </body>
    </body>
  </worldbody>
</mujoco>
