<?xml version='1.0' encoding='UTF-8'?>
<mujoco model="model">
  <option timestep="0.002" gravity="0.0 0.0 -9.81"/>
  <compiler angle="radian"/>
  <asset>
    <mesh file="visuals/Blender001.obj" name="Blender001_vis"/>
    <mesh file="visuals/Body001.obj" name="Body001_vis"/>
    <mesh file="visuals/Button001.obj" name="Button001_vis"/>
    <mesh file="visuals/Container001.obj" name="Container001_vis"/>
    <mesh file="visuals/Lever001.obj" name="Lever001_vis"/>
    <mesh file="visuals/Lid001.obj" name="Lid001_vis"/>
    <texture file="visuals/T_BC001.png" name="Body001_material" type="2d"/>
    <material name="Body001_material" rgba="1 1 1 1.0" texture="Body001_material" shininess="0.141421377658844" specular="0.5"/>
    <texture file="visuals/T_BC001.png" name="Button001_material" type="2d"/>
    <material name="Button001_material" rgba="1 1 1 1.0" texture="Button001_material" shininess="0.141421377658844" specular="0.3103448502657381"/>
    <texture file="visuals/T_BC001.png" name="Container001_material" type="2d"/>
    <material name="Container001_material" rgba="1 1 1 1.0" texture="Container001_material" shininess="0.141421377658844" specular="1"/>
    <texture file="visuals/T_BC001.png" name="Lid001_material" type="2d"/>
    <material name="Lid001_material" rgba="1 1 1 1.0" texture="Lid001_material" shininess="0.141421377658844" specular="0.5"/>
    <texture file="visuals/T_BC001.png" name="Blender001_material" type="2d"/>
    <material name="Blender001_material" rgba="1 1 1 1.0" texture="Blender001_material" shininess="0.141421377658844" specular="1"/>
    <texture file="visuals/T_BC001.png" name="Lever001_material" type="2d"/>
    <material name="Lever001_material" rgba="1 1 1 1.0" texture="Lever001_material" shininess="0.141421377658844" specular="0.3103448502657381"/>
  </asset>
  <default>
    <default class="visual">
      <geom conaffinity="0" contype="0" group="1" type="mesh"/>
    </default>
    <default class="collision">
      <geom group="0" rgba="0.5 0 0 0.5"/>
    </default>
    <default class="spawn">
      <geom group="0" rgba="1 1 1 0.5" contype="0" conaffinity="0"/>
      <site group="0" rgba="1 1 1 0.5"/>
    </default>
    <default class="region">
      <geom group="1" conaffinity="0" contype="0" rgba="0 1 0 0"/>
    </default>
  </default>
  <worldbody>
    <body>
      <body name="object">
        <geom mesh="Body001_vis" type="mesh" solimp="0.998 0.998 0.001" solref="0.001 1" friction="0.95 0.3 0.1" class="visual" material="Body001_material"/>
        <geom class="collision" type="box" pos="-0.000388 0.014858 -0.236480" size="0.1470741182565689 0.24640962481498718 0.018197868019342422" quat="1.0 0.0 0.0 0.0" density="1000.0"/>
        <geom class="collision" type="box" pos="0.002929 0.190886 -0.139831" size="0.06197034567594528 0.020992998033761978 0.10480103641748428" quat="3.186945605193614e-07 4.054764024541413e-10 -0.17126384377479553 0.9852252006530762" density="1000.0"/>
        <geom class="collision" type="box" pos="-0.097369 0.128064 -0.192540" size="0.02340238355100155 0.051185041666030884 0.037328436970710754" quat="4.0934835965344973e-07 0.18937274813652039 6.279142206189192e-10 0.9819052815437317" density="1000.0"/>
        <geom class="collision" type="box" pos="0.062334 0.126368 -0.152365" size="0.0234023816883564 0.052881255745887756 0.09892302751541138" quat="4.989324224879965e-07 -0.1999048888683319 -9.668909228821576e-08 0.9798153042793274" density="1000.0"/>
        <geom class="collision" type="box" pos="0.002929 0.126368 -0.082664" size="0.061970364302396774 0.05288127809762955 0.13840024173259735" quat="1.0 0.0 0.0 0.0" density="1000.0"/>
        <geom class="collision" type="box" pos="0.079927 0.122957 -0.171644" size="0.0234023816883564 0.05629220977425575 0.0786064937710762" quat="4.989324224879965e-07 -0.1999048888683319 -9.668909228821576e-08 0.9798153042793274" density="1000.0"/>
        <geom class="collision" type="box" pos="0.032969 0.126368 -0.061355" size="0.0234023816883564 0.052881255745887756 0.05018816143274307" quat="4.989324224879965e-07 -0.1999048888683319 -9.668909228821576e-08 0.9798153042793274" density="1000.0"/>
        <geom class="collision" type="box" pos="-0.001893 0.068770 -0.135004" size="0.06679213792085648 0.025309335440397263 0.08402279764413834" quat="0.9671083092689514 -0.2543649673461914 -5.648036206370866e-17 4.208608428094833e-25" density="1000.0"/>
        <geom class="collision" type="box" pos="0.000269 0.111018 -0.225568" size="0.1389281153678894 0.12880635261535645 0.018197905272245407" quat="1.0 0.0 0.0 0.0" density="1000.0"/>
        <geom class="collision" type="box" pos="0.000269 0.079318 -0.229734" size="0.1389281153678894 0.12880635261535645 0.018197912722826004" quat="1.0 0.0 0.0 0.0" density="1000.0"/>
        <geom class="collision" type="box" pos="0.000269 0.009611 -0.232980" size="0.1389281153678894 0.12880635261535645 0.0181979201734066" quat="1.0 0.0 0.0 0.0" density="1000.0"/>
        <geom class="collision" type="box" pos="-0.072196 0.190806 -0.164141" size="0.021484268829226494 0.024510791525244713 0.06869032979011536" quat="0.35829052329063416 0.17631539702415466 -0.06910073757171631 0.9142023324966431" density="1000.0"/>
        <geom class="collision" type="box" pos="0.075516 0.179870 -0.163242" size="0.01742730475962162 0.029545051977038383 0.07128416001796722" quat="0.9555922150611877 0.0435466431081295 -0.18429800868034363 0.2257906198501587" density="1000.0"/>
        <geom class="collision" type="box" pos="-0.084653 0.060327 -0.162775" size="0.021484268829226494 0.024510791525244713 0.06869032979011536" quat="0.32037287950515747 -0.2896636128425598 -0.10357760637998581 -0.8959508538246155" density="1000.0"/>
        <geom class="collision" type="box" pos="0.072380 0.057587 -0.156329" size="0.021484268829226494 0.024510791525244713 0.06869032979011536" quat="0.7780860066413879 -0.17706523835659027 -0.2515576481819153 -0.5476758480072021" density="1000.0"/>
        <geom class="collision" type="box" pos="-0.047645 0.128064 -0.068424" size="0.02340238355100155 0.051185041666030884 0.037328436970710754" quat="4.0934835965344973e-07 0.18937274813652039 6.279142206189192e-10 0.9819052815437317" density="1000.0"/>
        <body name="Button001">
          <joint axis="0.9512019157409668 0.0 -0.30856916308403015" pos="-0.085569 0.118268 -0.123152" limited="true" name="Button001_joint" range="0.0 0.008" type="slide" damping="1" frictionloss="1" armature=".01" stiffness="0.5" springref="-0.5"/>
          <geom mesh="Button001_vis" type="mesh" solimp="0.998 0.998 0.001" solref="0.001 1" friction="0.95 0.3 0.1" class="visual" material="Button001_material"/>
          <geom class="collision" type="cylinder" pos="-0.089643 0.118370 -0.121302" size="0.022103259339928627 0.005479670129716396" quat="0.8143262267112732 0.0 -0.580407440662384 0.0" density="1000.0"/>
        </body>
        <body name="Container001">
          <joint axis="0.0 0.0 1.0" pos="0.000162 -0.096114 -0.078570" limited="true" name="Container001_joint" range="0.0 0.05" type="slide" damping="1" frictionloss="1" armature=".01" stiffness="0.05"/>
          <geom mesh="Container001_vis" type="mesh" solimp="0.998 0.998 0.001" solref="0.001 1" friction="0.95 0.3 0.1" class="visual" material="Container001_material"/>
          <geom class="collision" type="box" pos="-0.148255 -0.090790 -0.022015" size="0.01607884094119072 0.044406406581401825 0.06841403245925903" quat="1.0 0.0 0.0 0.0" density="1000.0"/>
          <geom class="collision" type="box" pos="-0.017746 0.046576 -0.020338" size="0.00875962246209383 0.044406406581401825 0.0681932121515274" quat="0.7471170425415039 -0.021018153056502342 -0.023651298135519028 -0.6639389991760254" density="1000.0"/>
          <geom class="collision" type="box" pos="0.085154 0.025298 -0.021433" size="0.010286817327141762 0.044406406581401825 0.0681932121515274" quat="0.447671115398407 -0.028289711102843285 -0.014171858318150043 -0.8936383128166199" density="1000.0"/>
          <geom class="collision" type="box" pos="0.140927 -0.053782 -0.020999" size="0.009610497392714024 0.044406406581401825 0.0681932121515274" quat="0.12310067564249039 -0.03139999881386757 -0.0038969668094068766 -0.9918896555900574" density="1000.0"/>
          <geom class="collision" type="box" pos="0.123162 -0.169396 -0.019739" size="0.009641319513320923 0.044406406581401825 0.0681932121515274" quat="0.2708934545516968 0.03045661188662052 -0.00857560709118843 0.9620891809463501" density="1000.0"/>
          <geom class="collision" type="box" pos="0.043434 -0.233884 -0.020275" size="0.00974887516349554 0.044406406581401825 0.0681932121515274" quat="0.5933062434196472 0.025463253259658813 -0.018782146275043488 0.804354727268219" density="1000.0"/>
          <geom class="collision" type="box" pos="-0.062789 -0.227658 -0.020301" size="0.009340297430753708 0.044406406581401825 0.0681932121515274" quat="0.8428366184234619 0.01700722984969616 -0.02668146975338459 0.537238597869873" density="1000.0"/>
          <geom class="collision" type="box" pos="-0.122634 -0.176011 -0.021285" size="0.008992565795779228 0.044406406581401825 0.0681932121515274" quat="0.954062819480896 0.009431536309421062 -0.03020252287387848 0.2979312539100647" density="1000.0"/>
          <geom class="collision" type="box" pos="-0.004514 -0.202288 -0.146500" size="0.009864562191069126 0.044406432658433914 0.0681932121515274" quat="0.6845924258232117 0.19955039024353027 -0.19691559672355652 0.672857403755188" density="1000.0"/>
          <geom class="collision" type="box" pos="-0.089603 -0.148948 -0.146752" size="0.009229958988726139 0.044406428933143616 0.0681932121515274" quat="0.925520658493042 0.0784800723195076 -0.2691411077976227 0.2545888125896454" density="1000.0"/>
          <geom class="collision" type="box" pos="-0.091742 -0.045617 -0.146906" size="0.010463465936481953 0.044406432658433914 0.06695568561553955" quat="0.9261558651924133 -0.06953360885381699 -0.27159008383750916 -0.2522681653499603" density="1000.0"/>
          <geom class="collision" type="box" pos="-0.001994 0.008544 -0.145692" size="0.011980590410530567 0.044406428933143616 0.06371644139289856" quat="0.6856235861778259 -0.19312475621700287 -0.2032213658094406 -0.6718066930770874" density="1000.0"/>
          <geom class="collision" type="box" pos="0.079890 -0.163643 -0.145549" size="0.010591658763587475 0.044406428933143616 0.0681932121515274" quat="0.30785584449768066 0.26688408851623535 -0.0858425498008728 0.9091912508010864" density="1000.0"/>
          <geom class="collision" type="box" pos="-0.111377 -0.002750 -0.020063" size="0.008105087094008923 0.044406406581401825 0.0681932121515274" quat="0.9396122694015503 -0.010787836275994778 -0.029745087027549744 -0.34077510237693787" density="1000.0"/>
          <geom class="collision" type="box" pos="0.090874 -0.054072 -0.148766" size="0.012311420403420925 0.044406428933143616 0.0655110701918602" quat="0.17554129660129547 -0.28112170100212097 -0.040944475680589676 -0.9425918459892273" density="1000.0"/>
          <geom class="collision" type="box" pos="-0.136059 -0.152041 -0.022015" size="0.016078781336545944 0.044406406581401825 0.06841429322957993" quat="0.9760299324989319 0.0 0.0 0.21763628721237183" density="1000.0"/>
          <geom class="collision" type="box" pos="-0.140077 -0.056674 -0.020063" size="0.008105087094008923 0.044406406581401825 0.0681932121515274" quat="0.9912547469139099 -0.0040556457825005054 -0.03137991949915886 -0.12811297178268433" density="1000.0"/>
          <geom class="collision" type="box" pos="-0.076272 0.027758 -0.020338" size="0.00875962246209383 0.044406406581401825 0.0681932121515274" quat="0.8737058043479919 -0.015366965904831886 -0.02765868976712227 -0.48542454838752747" density="1000.0"/>
          <geom class="collision" type="box" pos="0.026238 0.052157 -0.021433" size="0.010286817327141762 0.044406406581401825 0.0681932121515274" quat="0.6580836772918701 -0.023814741522073746 -0.020832838490605354 -0.7522796988487244" density="1000.0"/>
          <geom class="collision" type="box" pos="0.110006 0.004317 -0.020999" size="0.009610498324036598 0.044406406581401825 0.0681932121515274" quat="0.3360210359096527 -0.02979923225939274 -0.010637335479259491 -0.9413228631019592" density="1000.0"/>
          <geom class="collision" type="box" pos="0.143042 -0.107892 -0.019739" size="0.009641320444643497 0.044406406581401825 0.0681932121515274" quat="0.055014610290527344 0.03159289062023163 -0.0017415831098333001 0.9979841113090515" density="1000.0"/>
          <geom class="collision" type="box" pos="0.098263 -0.200143 -0.020275" size="0.00974887516349554 0.044406406581401825 0.0681932121515274" quat="0.40402790904045105 0.02894057333469391 -0.012790211476385593 0.9141992926597595" density="1000.0"/>
          <geom class="collision" type="box" pos="-0.000542 -0.239634 -0.020301" size="0.009340297430753708 0.044406402856111526 0.0681932121515274" quat="0.7057111263275146 0.02240642160177231 -0.022340519353747368 0.7077928185462952" density="1000.0"/>
          <geom class="collision" type="box" pos="-0.076660 -0.218304 -0.021285" size="0.008992565795779228 0.044406406581401825 0.0681932121515274" quat="0.8663532137870789 0.01577862910926342 -0.027425924316048622 0.49842849373817444" density="1000.0"/>
          <geom class="collision" type="box" pos="0.041434 -0.191910 -0.146500" size="0.009864562191069126 0.044406428933143616 0.0681932121515274" quat="0.5217445492744446 0.23762311041355133 -0.14876608550548553 0.8057211637496948" density="1000.0"/>
          <geom class="collision" type="box" pos="-0.058255 -0.179772 -0.146752" size="0.009229958988726139 0.044406428933143616 0.0681932121515274" quat="0.8479281067848206 0.1351737529039383 -0.24560968577861786 0.4499131143093109" density="1000.0"/>
          <geom class="collision" type="box" pos="-0.103426 -0.087190 -0.147949" size="0.010463465936481953 0.044406428933143616 0.0681932121515274" quat="0.9588585495948792 -0.008759032003581524 -0.2802131474018097 -0.044656168669462204" density="1000.0"/>
          <geom class="collision" type="box" pos="-0.045686 -0.000307 -0.146269" size="0.011980590410530567 0.044406428933143616 0.06440060585737228" quat="0.815398633480072 -0.1442672163248062 -0.24038104712963104 -0.5064868927001953" density="1000.0"/>
          <geom class="collision" type="box" pos="0.101425 -0.121068 -0.145549" size="0.01059165969491005 0.044406428933143616 0.0681932121515274" quat="0.10260351747274399 0.2791692018508911 -0.025701219215989113 0.954398512840271" density="1000.0"/>
          <geom class="collision" type="box" pos="0.065596 -0.016459 -0.147101" size="0.012311420403420925 0.044406428933143616 0.06352639943361282" quat="0.3764757812023163 -0.2654721736907959 -0.10114531964063644 -0.8817936778068542" density="1000.0"/>
          <geom class="collision" type="cylinder" pos="-0.000513 -0.097655 -0.202249" size="0.06730954349040985 0.010610586032271385" quat="1.0 0.0 0.0 0.0" density="1000.0"/>
        </body>
        <body name="Lid001">
          <joint axis="-1.0 0.0 0.0" pos="0.000000 0.171565 -0.011696" limited="true" name="Lid001_joint" range="0.0 1.5707963267948966" type="hinge" damping="1" frictionloss="1" armature=".01" stiffness="0.05"/>
          <geom mesh="Lid001_vis" type="mesh" solimp="0.998 0.998 0.001" solref="0.001 1" friction="0.95 0.3 0.1" class="visual" material="Lid001_material"/>
          <geom class="collision" type="cylinder" pos="0.000578 -0.195159 0.187492" size="0.030359400436282158 0.030359400436282158" quat="0.7071067094802856 0.7071068286895752 0.0 0.0" density="1000.0"/>
          <geom class="collision" type="box" pos="0.002929 0.045644 0.174672" size="0.07102589309215546 0.215374156832695 0.07949654757976532" quat="1.0 0.0 0.0 0.0" density="1000.0"/>
          <body name="Blender001">
            <joint axis="0.0 0.0 1.0" pos="-0.012228 -0.106075 -0.064676" limited="false" name="Blender001_joint" range="0 360" type="hinge" damping="1" frictionloss="1" armature=".01" stiffness="0.05"/>
            <geom mesh="Blender001_vis" type="mesh" solimp="0.998 0.998 0.001" solref="0.001 1" friction="0.95 0.3 0.1" class="visual" material="Blender001_material"/>
            <geom class="collision" type="cylinder" pos="-0.011704 -0.106994 0.013438" size="0.03237089887261391 0.01715884543955326" quat="0.7855479121208191 0.0 0.0 0.6188008785247803" density="1000.0"/>
            <geom class="collision" type="box" pos="-0.010055 -0.106648 -0.029984" size="0.008867871947586536 0.07720372825860977 0.009225652553141117" quat="0.7855479121208191 0.0 0.0 0.6188008785247803" density="1000.0"/>
            <geom class="collision" type="box" pos="0.025883 -0.116140 -0.132653" size="0.008867871947586536 0.05385828763246536 0.013741519302129745" quat="0.72093266248703 -0.2991736829280853 -0.2465105652809143 0.5744421482086182" density="1000.0"/>
            <geom class="collision" type="box" pos="-0.052884 -0.095430 -0.136504" size="0.008867872878909111 0.04532240703701973 0.013741519302129745" quat="0.2993749976158142 -0.7114409804344177 -0.5862623453140259 0.2460137903690338" density="1000.0"/>
            <geom class="collision" type="box" pos="-0.012712 -0.105408 -0.007613" size="0.017273016273975372 0.033695898950099945 0.020048784092068672" quat="0.7855479121208191 0.0 0.0 0.6188008785247803" density="1000.0"/>
            <geom class="collision" type="box" pos="-0.087266 -0.086898 -0.067785" size="0.008867871947586536 0.04532240703701973 0.013741519302129745" quat="0.46521297097206116 -0.5983477830886841 -0.5078616738319397 0.40943053364753723" density="1000.0"/>
            <geom class="collision" type="box" pos="0.062364 -0.123251 -0.069558" size="0.008867871947586536 0.04216091334819794 0.013741519302129745" quat="0.609071671962738 -0.476049542427063 -0.38677018880844116 0.502809464931488" density="1000.0"/>
            <geom class="collision" type="cylinder" pos="-0.011559 -0.106392 0.036884" size="0.01104024238884449 0.007753560785204172" quat="0.7855479121208191 0.0 0.0 0.6188008785247803" density="1000.0"/>
          </body>
          <body name="Lever001">
            <joint axis="0.0 -1.0 0.0" pos="-0.072482 0.086954 0.118166" limited="true" name="Lever001_joint" range="0.0 0.09" type="slide" damping="1" frictionloss="1" armature=".01" stiffness="-0.05" springref="0.05"/>
            <geom mesh="Lever001_vis" type="mesh" solimp="0.998 0.998 0.001" solref="0.001 1" friction="0.95 0.3 0.1" class="visual" material="Lever001_material"/>
            <geom class="collision" type="cylinder" pos="-0.130385 0.088643 0.120134" size="0.013762379996478558 0.013762379996478558" quat="0.622999906539917 0.33447137475013733 0.6215016841888428 0.33724719285964966" density="1000.0"/>
            <geom class="collision" type="box" pos="-0.097136 0.087262 0.118014" size="0.01756945066154003 0.004704898688942194 0.002714346395805478" quat="1.0 0.0 0.0 0.0" density="1000.0"/>
          </body>
        </body>
        <geom class="region" name="reg_main" type="box" pos="-2.4000000000010124e-05 0.011418499999999984 2.4999999999886224e-06" size="0.1496 0.24568849999999998 0.25275349999999996"/>
      </body>
    </body>
  </worldbody>
  <actuator>
    <motor name="Button001_joint_actuator" joint="Button001_joint" gear="0.5"/>
    <motor name="Container001_joint_actuator" joint="Container001_joint" gear="10"/>
    <motor name="Lid001_joint_actuator" joint="Lid001_joint" gear="10"/>
    <motor name="Blender001_joint_actuator" joint="Blender001_joint" gear="10"/>
    <motor name="Lever001_joint_actuator" joint="Lever001_joint" gear="10"/>
  </actuator>
</mujoco>
