<mujoco model="model">
  <compiler angle="radian"/>
  <asset>
    <mesh file="visuals/door.obj" name="door_vis"/>
    <mesh file="visuals/door_Clear.obj" name="door_Clear_vis"/>
    <mesh file="visuals/Body001.obj" name="Body001_vis"/>
    <mesh file="visuals/Button001.obj" name="Button001_vis"/>
    <mesh file="visuals/Button002.obj" name="Button002_vis"/>
    <mesh file="visuals/Disc001.obj" name="Disc001_vis"/>
    <mesh file="visuals/Knob001.obj" name="Knob001_vis"/>
    <texture file="visuals/T_BC001.png" name="Body001_material" type="2d"/>
    <material name="Body001_material" rgba="1 1 1 1.0" texture="Body001_material" shininess="2" specular="2"/>
    <texture file="visuals/T_BC001.png" name="door_material" type="2d"/>
    <material name="door_material" rgba="1 1 1 1.0" texture="door_material" shininess="2" specular="2"/>
    <texture file="visuals/T_BC001.png" name="door_Clear_material" type="2d"/>
    <material name="door_Clear_material" rgba="1 1 1 0.8557591438293457" texture="door_Clear_material" shininess="1" specular="1"/>
    <texture file="visuals/T_BC001.png" name="Button001_material" type="2d"/>
    <material name="Button001_material" rgba="1 1 1 1.0" texture="Button001_material" shininess="0.4472135901451111" specular="0.3103448502657381"/>
    <texture file="visuals/T_BC001.png" name="Button002_material" type="2d"/>
    <material name="Button002_material" rgba="1 1 1 1.0" texture="Button002_material" shininess="0.4472135901451111" specular="0.3103448502657381"/>
    <texture file="visuals/T_BC001.png" name="Disc001_material" type="2d"/>
    <material name="Disc001_material" rgba="1 1 1 1.0" texture="Disc001_material" shininess="1" specular="1"/>
    <texture file="visuals/T_BC001.png" name="Knob001_material" type="2d"/>
    <material name="Knob001_material" rgba="1 1 1 1.0" texture="Knob001_material" shininess="0.4472135901451111" specular="0.3103448502657381"/>
  </asset>
  <default>
    <default class="visual">
      <geom conaffinity="0" contype="0" group="1" type="mesh"/>
    </default>
    <default class="collision">
      <geom group="0" rgba="0.5 0 0 0.5"/>
    </default>
    <default class="spawn">
      <geom group="0" rgba="1 1 1 0.5" contype="0" conaffinity="0"/>
      <site group="0" rgba="1 1 1 0.5"/>
    </default>
    <default class="region">
      <geom group="1" conaffinity="0" contype="0" rgba="0 1 0 0"/>
    </default>
  </default>
  <worldbody>
    <body>
      <body name="object">
        <geom class="collision" type="box" pos="-0.05938774719834328 0.016429780051112175 -0.09502654522657394" size="0.10291451960802078 0.10291451960802078 0.0022197843063622713" quat="1.0 0.0 0.0 0.0" name="tray" rgba="0 1 0 0.5"/>
        <geom class="collision" type="box" pos="0.24567539989948273 -0.18528784811496735 -0.07138217985630035" size="0.010529562830924988 0.0007581612444482744 0.006517639849334955" quat="1.0 0.0 0.0 0.0" name="stop_button" rgba="0.0 0.5 0 0.5"/>
        <geom class="collision" type="box" pos="0.2090815156698227 -0.18528784811496735 -0.07138217985630035" size="0.010529578663408756 0.0007581632817164063 0.006517652887851" quat="1.0 0.0 0.0 0.0" name="start_button" rgba="0.0 0.5 0 0.5"/>
        <geom mesh="Body001_vis" type="mesh" solimp="0.998 0.998 0.001" solref="0.001 1" density="100" friction="0.95 0.3 0.1" class="visual" material="Body001_material"/>
        <geom class="collision" type="box" pos="-2.3052096366882324e-05 0.039480894804000854 -0.1284608095884323" size="0.28024062514305115 0.17873340845108032 0.014597782865166664" quat="1.0 0.0 0.0 0.0"/>
        <geom class="collision" type="box" pos="-0.008200384676456451 0.029451943933963776 -0.1503056138753891" size="0.207381010055542 0.13438034057617188 0.010015944018959999" quat="1.0 0.0 0.0 0.0"/>
        <geom class="collision" type="box" pos="0.2115650475025177 0.03948093205690384 0.010735150426626205" size="0.06865295767784119 0.1787334382534027 0.13717962801456451" quat="1.0 0.0 0.0 0.0"/>
        <geom class="collision" type="box" pos="-2.3052096366882324e-05 0.03948093205690384 0.1412004828453064" size="0.28024062514305115 0.1787334382534027 0.019719595089554787" quat="1.0 0.0 0.0 0.0"/>
        <geom class="collision" type="box" pos="-0.2640726864337921 0.03948093205690384 0.010735150426626205" size="0.016190968453884125 0.1787334382534027 0.13717962801456451" quat="1.0 0.0 0.0 0.0"/>
        <geom class="collision" type="box" pos="-0.0001710653305053711 0.20273303985595703 0.010341539978981018" size="0.2641007900238037 0.015481341630220413 0.13668522238731384" quat="1.0 0.0 0.0 0.0"/>
        <geom class="collision" type="box" pos="0.2299848347902298 -0.1528521031141281 0.011875919066369534" size="0.050232741981744766 0.015066191554069519 0.149148091673851" quat="1.0 0.0 0.0 0.0"/>
        <geom class="collision" type="box" pos="0.2299848347902298 -0.17526082694530487 0.09021499007940292" size="0.050232745707035065 0.008356140926480293 0.0708090215921402" quat="1.0 0.0 0.0 0.0"/>
        <geom class="collision" type="box" pos="0.2299848347902298 -0.17526082694530487 -0.11876236647367477" size="0.050232741981744766 0.008356140926480293 0.02330286055803299" quat="1.0 0.0 0.0 0.0"/>
        <geom class="collision" type="box" pos="0.2735767960548401 -0.17526082694530487 -0.037645623087882996" size="0.00664076441898942 0.008356140926480293 0.05796971544623375" quat="1.0 0.0 0.0 0.0"/>
        <geom class="collision" type="box" pos="0.18247374892234802 -0.17526082694530487 -0.0376456193625927" size="0.004678760655224323 0.008356140926480293 0.05796970799565315" quat="1.0 0.0 0.0 0.0"/>
        <geom class="collision" type="box" pos="0.2277427464723587 -0.17526082694530487 -0.049250662326812744" size="0.040190719068050385 0.008356140926480293 0.011540122330188751" quat="1.0 0.0 0.0 0.0"/>
        <body name="door">
          <joint axis="0.0 0.0 1.0" pos="-0.26329922676086426 -0.16534414887428284 0.010757192969322205" limited="true" name="microjoint" range="-1.5707963267948966 0.0" type="hinge" damping="1" frictionloss="1" armature=".01" stiffness="0.05"/>
          <geom mesh="door_vis" type="mesh" solimp="0.998 0.998 0.001" solref="0.001 1" density="100" friction="0.95 0.3 0.1" class="visual" material="door_material"/>
          <geom class="collision" type="box" pos="-0.06862357258796692 -0.1657126396894455 0.13580423593521118" size="0.20452848076820374 0.0165959931910038 0.022893140092492104" quat="1.0 0.0 0.0 0.0"/>
          <geom class="collision" type="box" pos="-0.07248614728450775 -0.1657126247882843 -0.11270149052143097" size="0.2006658911705017 0.016595976427197456 0.024815762415528297" quat="1.0 0.0 0.0 0.0"/>
          <geom class="collision" type="box" pos="-0.24498218297958374 -0.1657126247882843 0.012848451733589172" size="0.02813088521361351 0.016595976427197456 0.10035819560289383" quat="1.0 0.0 0.0 0.0"/>
          <geom class="collision" type="box" pos="0.14541085064411163 -0.1657126098871231 0.012848451733589172" size="0.028212498873472214 0.016595961526036263 0.10035819560289383" quat="1.0 0.0 0.0 0.0"/>
          <geom class="collision" type="box" pos="0.1517094522714615 -0.16740120947360992 -0.1251775026321411" size="0.023682627826929092 0.01828456111252308 0.013537155464291573" quat="1.0 0.0 0.0 0.0"/>
          <geom class="collision" type="box" pos="0.15553125739097595 -0.1657126098871231 0.14593495428562164" size="0.019860822707414627 0.016595961526036263 0.012627840973436832" quat="1.0 0.0 0.0 0.0"/>
          <geom class="collision" type="box" pos="0.15099483728408813 -0.2019350528717041 0.1266351342201233" size="0.014203044585883617 0.01893213577568531 0.004992937669157982" quat="1.0 0.0 0.0 0.0"/>
          <geom class="collision" type="box" pos="0.15099483728408813 -0.2019350528717041 -0.10199031233787537" size="0.014203044585883617 0.01893213577568531 0.004992937669157982" quat="1.0 0.0 0.0 0.0"/>
          <geom class="collision" type="box" pos="0.15099483728408813 -0.2161160260438919 0.012491273693740368" size="0.014203045517206192 0.004992939531803131 0.10917972773313522" quat="1.0 0.0 0.0 0.0" name="door_handle"/>
          <body name="door_Clear">
            <geom mesh="door_Clear_vis" type="mesh" solimp="0.998 0.998 0.001" solref="0.001 1" density="100" friction="0.95 0.3 0.1" class="visual" material="door_Clear_material"/>
            <geom class="collision" type="box" pos="-0.04953077435493469 -0.1657126247882843 0.012109030969440937" size="0.16435062885284424 0.016595978289842606 0.0968436598777771" quat="1.0 0.0 0.0 0.0"/>
          </body>
        </body>
        <body name="Button001">
          <joint axis="0.0 1.0 0.0" pos="0.2091110348701477 -0.18389424681663513 -0.07123757153749466" limited="true" name="Button001_joint" range="0.0 0.0025" type="slide" damping="1" frictionloss="1" armature=".01" stiffness="0.05"/>
          <geom mesh="Button001_vis" type="mesh" solimp="0.998 0.998 0.001" solref="0.001 1" density="100" friction="0.95 0.3 0.1" class="visual" material="Button001_material"/>
          <geom class="collision" type="box" pos="0.2090815156698227 -0.18352563679218292 -0.07138217985630035" size="0.010529573075473309 0.0007581625832244754 0.006517648696899414" quat="1.0 0.0 0.0 0.0"/>
        </body>
        <body name="Button002">
          <joint axis="0.0 1.0 0.0" pos="0.24564091861248016 -0.18389424681663513 -0.07123757898807526" limited="true" name="Button002_joint" range="0.0 0.0025" type="slide" damping="1" frictionloss="1" armature=".01" stiffness="0.05"/>
          <geom mesh="Button002_vis" type="mesh" solimp="0.998 0.998 0.001" solref="0.001 1" density="100" friction="0.95 0.3 0.1" class="visual" material="Button002_material"/>
          <geom class="collision" type="box" pos="0.24567539989948273 -0.18352563679218292 -0.07138217985630035" size="0.010529567487537861 0.0007581619429402053 0.006517644505947828" quat="1.0 0.0 0.0 0.0"/>
        </body>
        <body name="Disc001">
          <joint axis="0.0 0.0 1.0" pos="-0.05964674800634384 0.016020210459828377 -0.10005097091197968" limited="false" name="Disc001_joint" range="0 360" type="hinge" damping="1" frictionloss="1" armature=".01" stiffness="0.05"/>
          <geom mesh="Disc001_vis" type="mesh" solimp="0.998 0.998 0.001" solref="0.001 1" density="100" friction="0.95 0.3 0.1" class="visual" material="Disc001_material"/>
          <geom class="collision" type="cylinder" pos="-0.05938774719834328 0.016429780051112175 -0.10699434578418732" size="0.10291451960802078 0.0022197843063622713" quat="1.0 0.0 0.0 0.0"/>
        </body>
        <body name="Knob001">
          <joint axis="0.0 1.0 0.0" pos="0.22610574960708618 -0.18846583366394043 -0.010493787005543709" limited="true" name="Knob001_joint" range="0.0 5.235987755982989" type="hinge" damping="0.05" armature="0.001"/>
          <geom mesh="Knob001_vis" type="mesh" solimp="0.998 0.998 0.001" solref="0.001 1" density="100" friction="0.95 0.3 0.1" class="visual" material="Knob001_material"/>
          <geom class="collision" type="cylinder" pos="0.2261015623807907 -0.1877712458372116 -0.010438723489642143" size="0.01641750894486904 0.005470505449920893" quat="0.7071068286895752 0.7071067690849304 0.0 0.0"/>
        </body>
        <geom class="region" name="reg_main" type="box" pos="-2.3029744625091553e-05 0.01770583540201187 1.564621925354004e-07" size="0.28024062514305115 0.2005084753036499 0.16102385520935059"/>
        <geom class="region" name="reg_int" type="box" pos="-0.05287456512451172 0.02081458270549774 0.010233838111162186" size="0.1911577731370926 0.1580009013414383 0.11673283204436302"/>
      </body>
    </body>
  </worldbody>
  <actuator>
    <motor name="microjoint_actuator" joint="microjoint" gear="10"/>
    <motor name="Button001_joint_actuator" joint="Button001_joint" gear="0.4"/>
    <motor name="Button002_joint_actuator" joint="Button002_joint" gear="0.4"/>
    <motor name="Disc001_joint_actuator" joint="Disc001_joint" gear="20"/>
    <motor name="Knob001_joint_actuator" joint="Knob001_joint" gear="10"/>
  </actuator>
</mujoco>
