<mujoco model="model">
  <compiler angle="radian"/>
  <asset>
    <mesh file="visuals/door.obj" name="door_vis"/>
    <mesh file="visuals/door_Clear.obj" name="door_Clear_vis"/>
    <mesh file="visuals/Body001.obj" name="Body001_vis"/>
    <mesh file="visuals/Button001.obj" name="Button001_vis"/>
    <mesh file="visuals/Button002.obj" name="Button002_vis"/>
    <mesh file="visuals/Disc001.obj" name="Disc001_vis"/>
    <texture file="visuals/T_BC001.png" name="Body001_material" type="2d"/>
    <material name="Body001_material" rgba="1 1 1 1.0" texture="Body001_material" shininess="0.4472135901451111" specular="0.3103448502657381"/>
    <texture file="visuals/T_BC001.png" name="door_material" type="2d"/>
    <material name="door_material" rgba="1 1 1 1.0" texture="door_material" shininess="0.4472135901451111" specular="0.3103448502657381"/>
    <texture file="visuals/T_BC001.png" name="door_Clear_material" type="2d"/>
    <material name="door_Clear_material" rgba="1 1 1 0.7461665868759155" texture="door_Clear_material" shininess="0.5" specular="0.3103448502657381"/>
    <texture file="visuals/T_BC001.png" name="Button001_material" type="2d"/>
    <material name="Button001_material" rgba="1 1 1 1.0" texture="Button001_material" shininess="0.4472135901451111" specular="0.3103448502657381"/>
    <texture file="visuals/T_BC001.png" name="Button002_material" type="2d"/>
    <material name="Button002_material" rgba="1 1 1 1.0" texture="Button002_material" shininess="0.4472135901451111" specular="0.3103448502657381"/>
    <texture file="visuals/T_BC001.png" name="Disc001_material" type="2d"/>
    <material name="Disc001_material" rgba="1 1 1 1.0" texture="Disc001_material" shininess="0.4472135901451111" specular="0.3103448502657381"/>
  </asset>
  <default>
    <default class="visual">
      <geom conaffinity="0" contype="0" group="1" type="mesh"/>
    </default>
    <default class="collision">
      <geom group="0" rgba="0.5 0 0 0.5"/>
    </default>
    <default class="spawn">
      <geom group="0" rgba="1 1 1 0.5" contype="0" conaffinity="0"/>
      <site group="0" rgba="1 1 1 0.5"/>
    </default>
  </default>
  <worldbody>
    <body>
      <site rgba="0 0 0 0.5" size="0.01" pos="-0.196495 -0.129731 -0.114324" name="ext_p0"/>
      <site rgba="1 0 0 0.5" size="0.01" pos="0.197065 -0.129731 -0.114324" name="ext_px"/>
      <site rgba="0 1 0 0.5" size="0.01" pos="-0.196495 0.152725 -0.114324" name="ext_py"/>
      <site rgba="0 0 1 0.5" size="0.01" pos="-0.196495 -0.129731 0.114214" name="ext_pz"/>
      <site rgba="0 1 1 0.5" size="0.004999999888241291" pos="-0.171567 0.127996 -0.072180" name="int_py"/>
      <site rgba="1 1 0 0.5" size="0.004999999888241291" pos="0.098796 -0.097089 -0.072180" name="int_px"/>
      <site rgba="1 0.75 0.8 0.5" size="0.004999999888241291" pos="-0.171567 -0.097089 0.087826" name="int_pz"/>
      <site rgba="0.5 0.5 0.5 0.5" size="0.004999999888241291" pos="-0.171567 -0.097089 -0.072180" name="int_p0"/>
      <geom class="collision" type="box" pos="-0.041640 0.012094 -0.067527" size="0.10619761049747467 0.10619761049747467 0.0014588331105187535" quat="1.0 0.0 0.0 0.0" name="tray" rgba="0 1 0 0.5"/>
      <geom class="collision" type="box" pos="0.181054 -0.129420 -0.077208" size="0.01183738186955452 0.0009990474209189415 0.010231570340692997" quat="1.0 0.0 0.0 0.0" name="stop_button" rgba="0.0 0.5 0 0.5"/>
      <geom class="collision" type="box" pos="0.138036 -0.129244 -0.077143" size="0.011760499328374863 0.0010291410144418478 0.010124889202415943" quat="1.0 0.0 0.0 0.0" name="start_button" rgba="0.0 0.5 0 0.5"/>
      <body name="object">
        <geom mesh="Body001_vis" type="mesh" solimp="0.998 0.998 0.001" solref="0.001 1" density="100" friction="0.95 0.3 0.1" class="visual" material="Body001_material"/>
        <geom class="collision" type="box" pos="-0.000324 0.026338 -0.088463" size="0.1977785974740982 0.12830674648284912 0.011053582653403282" quat="1.0 0.0 0.0 0.0"/>
        <geom class="collision" type="box" pos="-0.004116 0.011087 -0.103419" size="0.14896182715892792 0.09288105368614197 0.011053582653403282" quat="1.0 0.0 0.0 0.0"/>
        <geom class="collision" type="box" pos="-0.185675 0.026338 0.008116" size="0.011053552851080894 0.12830685079097748 0.1060165986418724" quat="1.0 0.0 0.0 0.0"/>
        <geom class="collision" type="box" pos="0.149123 0.026338 0.008116" size="0.04898044094443321 0.12830689549446106 0.1060165986418724" quat="1.0 0.0 0.0 0.0"/>
        <geom class="collision" type="box" pos="-0.000324 0.026338 0.103419" size="0.19777880609035492 0.12830695509910583 0.011053582653403282" quat="1.0 0.0 0.0 0.0"/>
        <geom class="collision" type="box" pos="0.160605 -0.117626 0.008328" size="0.037204641848802567 0.012688353657722473 0.10598212480545044" quat="1.0 0.0 0.0 0.0"/>
        <geom class="collision" type="box" pos="0.000629 0.143701 0.006918" size="0.17504045367240906 0.011053584516048431 0.08441870659589767" quat="1.0 0.0 0.0 0.0"/>
        <body name="door">
          <joint axis="0.0 0.0 1.0" pos="-0.184475 -0.117981 0.010266" limited="true" name="microjoint" range="-1.5707963267948966 0.0" type="hinge" damping="1" frictionloss="1" armature=".01" stiffness="0.05"/>
          <geom mesh="door_vis" type="mesh" solimp="0.998 0.998 0.001" solref="0.001 1" density="100" friction="0.95 0.3 0.1" class="visual" material="door_material"/>
          <geom class="collision" type="box" pos="-0.047336 -0.120250 0.103419" size="0.14162985980510712 0.010064341127872467 0.011053582653403282" quat="1.0 0.0 0.0 0.0"/>
          <geom class="collision" type="box" pos="-0.047336 -0.120250 -0.086420" size="0.1416299045085907 0.010064343921840191 0.011053582653403282" quat="1.0 0.0 0.0 0.0"/>
          <geom class="collision" type="box" pos="-0.181651 -0.120250 0.008019" size="0.00648471200838685 0.01006434764713049 0.08364085108041763" quat="1.0 0.0 0.0 0.0"/>
          <geom class="collision" type="box" pos="0.108715 -0.119685 0.008328" size="0.01252767350524664 0.010628785006701946 0.10598211735486984" quat="1.0 0.0 0.0 0.0"/>
          <geom class="collision" type="box" pos="0.109215 -0.150731 0.008514" size="0.0070229885168373585 0.004023266956210136 0.06596163660287857" quat="1.0 0.0 0.0 0.0" name="door_handle"/>
          <geom class="collision" type="box" pos="0.109215 -0.142241 0.089875" size="0.007022990845143795 0.012130236253142357 0.0040232837200164795" quat="1.0 0.0 0.0 0.0"/>
          <geom class="collision" type="box" pos="0.109215 -0.142281 -0.069990" size="0.007022994104772806 0.012170159257948399 0.0040232837200164795" quat="1.0 0.0 0.0 0.0"/>
          <geom class="collision" type="box" pos="0.109215 -0.150436 0.081764" size="0.007022990845143795 0.003936103545129299 0.0040232837200164795" quat="1.0 0.0 0.0 0.0"/>
          <geom class="collision" type="box" pos="0.109215 -0.150436 -0.064808" size="0.007022990845143795 0.003936103545129299 0.0040232837200164795" quat="1.0 0.0 0.0 0.0"/>
          <body name="door_Clear">
            <geom mesh="door_Clear_vis" type="mesh" solimp="0.998 0.998 0.001" solref="0.001 1" density="100" friction="0.95 0.3 0.1" class="visual" material="door_Clear_material"/>
            <geom class="collision" type="box" pos="-0.039603 -0.118190 0.008174" size="0.13389736413955688 0.012123913504183292 0.0808444619178772" quat="1.0 0.0 0.0 0.0"/>
          </body>
        </body>
        <body name="Button001">
          <joint axis="0.0 1.0 0.0" pos="0.136998 -0.129615 -0.079146" limited="true" name="Button001_joint" range="0.0 0.001" type="slide" damping="1" frictionloss="1" armature=".01" stiffness="0.05"/>
          <geom mesh="Button001_vis" type="mesh" solimp="0.998 0.998 0.001" solref="0.001 1" density="100" friction="0.95 0.3 0.1" class="visual" material="Button001_material"/>
        </body>
        <body name="Button002">
          <joint axis="0.0 1.0 0.0" pos="0.183386 -0.129615 -0.079171" limited="true" name="Button002_joint" range="0.0 0.001" type="slide" damping="1" frictionloss="1" armature=".01" stiffness="0.05"/>
          <geom mesh="Button002_vis" type="mesh" solimp="0.998 0.998 0.001" solref="0.001 1" density="100" friction="0.95 0.3 0.1" class="visual" material="Button002_material"/>
        </body>
        <body name="Disc001">
          <joint axis="0.0 0.0 1.0" pos="-0.041892 0.010701 -0.069644" limited="false" name="Disc001_joint" range="0 360" type="hinge" damping="1" frictionloss="1" armature=".01" stiffness="0.05"/>
          <geom mesh="Disc001_vis" type="mesh" solimp="0.998 0.998 0.001" solref="0.001 1" density="100" friction="0.95 0.3 0.1" class="visual" material="Disc001_material"/>
          <geom class="collision" type="cylinder" pos="-0.041640 0.012094 -0.070773" size="0.10619761049747467 0.0014588331105187535" quat="1.0 0.0 0.0 0.0"/>
        </body>
      </body>
    </body>
  </worldbody>
  <actuator>
    <motor name="microjoint_actuator" joint="microjoint" gear="5"/>
    <motor name="Button001_joint_actuator" joint="Button001_joint" gear="0.1"/>
    <motor name="Button002_joint_actuator" joint="Button002_joint" gear="0.1"/>
    <motor name="Disc001_joint_actuator" joint="Disc001_joint" gear="10"/>
  </actuator>
</mujoco>