<mujoco model="model">
  <compiler angle="radian"/>
  <asset>
    <mesh file="visuals/Body001.obj" name="Body001_vis"/>
    <mesh file="visuals/Button001.obj" name="Button001_vis"/>
    <mesh file="visuals/Container001.obj" name="Container001_vis"/>
    <mesh file="visuals/Container002.obj" name="Container002_vis"/>
    <mesh file="visuals/Door001.obj" name="Door001_vis"/>
    <mesh file="visuals/Handle001.obj" name="Handle001_vis"/>
    <texture file="visuals/T_BC001.png" name="Body001_material" type="2d"/>
    <material name="Body001_material" rgba="1 1 1 1.0" texture="Body001_material" shininess="1" specular="1"/>
    <texture file="visuals/T_BC001.png" name="Button001_material" type="2d"/>
    <material name="Button001_material" rgba="1 1 1 1.0" texture="Button001_material" shininess="1" specular="1"/>
    <texture file="visuals/T_BC001.png" name="Container001_material" type="2d"/>
    <material name="Container001_material" rgba="1 1 1 1.0" texture="Container001_material" shininess="1" specular="1"/>
    <texture file="visuals/T_BC001.png" name="Container002_material" type="2d"/>
    <material name="Container002_material" rgba="1 1 1 1.0" texture="Container002_material" shininess="1" specular="1"/>
    <texture file="visuals/T_BC001.png" name="Door001_material" type="2d"/>
    <material name="Door001_material" rgba="1 1 1 1.0" texture="Door001_material" shininess="1" specular="1"/>
    <texture file="visuals/T_BC001.png" name="Handle001_material" type="2d"/>
    <material name="Handle001_material" rgba="1 1 1 1.0" texture="Handle001_material" shininess="1" specular="1"/>
  </asset>
  <default>
    <default class="visual">
      <geom conaffinity="0" contype="0" group="1" type="mesh"/>
    </default>
    <default class="collision">
      <geom group="0" rgba="0.5 0 0 0.5"/>
    </default>
    <default class="spawn">
      <geom group="0" rgba="1 1 1 0.5" contype="0" conaffinity="0"/>
      <site group="0" rgba="1 1 1 0.5"/>
    </default>
    <default class="region">
      <geom group="1" conaffinity="0" contype="0" rgba="0 1 0 0"/>
    </default>
  </default>
  <worldbody>
    <body>
      <body name="object">
        <geom mesh="Body001_vis" type="mesh" solimp="0.998 0.998 0.001" solref="0.001 1" density="100" friction="0.95 0.3 0.1" class="visual" material="Body001_material"/>
        <geom class="collision" type="box" pos="-0.320134 0.036232 0.010804" size="0.012114939279854298 0.29174354672431946 0.29274818301200867" quat="1.0 0.0 0.0 0.0"/>
        <geom class="collision" type="box" pos="0.320281 -0.006769 0.008377" size="0.011156880296766758 0.25465190410614014 0.2944124937057495" quat="1.0 0.0 0.0 0.0"/>
        <geom class="collision" type="box" pos="0.000110 0.038823 0.394401" size="0.3323088586330414 0.32938113808631897 0.09508378803730011" quat="1.0 0.0 0.0 0.0"/>
        <geom class="collision" type="box" pos="0.000039 0.037621 -0.389276" size="0.33354267477989197 0.33075353503227234 0.1033061221241951" quat="1.0 0.0 0.0 0.0"/>
        <geom class="collision" type="box" pos="0.000285 0.310262 0.008342" size="0.33119404315948486 0.058056801557540894 0.2918362021446228" quat="1.0 0.0 0.0 0.0"/>
        <body name="Button001">
          <joint axis="0.0 1.0 0.0" pos="-0.252831 -0.293053 0.376465" limited="true" name="Button001_joint" range="0.0 0.004" type="slide" damping="1" frictionloss="1" armature=".01" stiffness="0.05"/>
          <geom mesh="Button001_vis" type="mesh" solimp="0.998 0.998 0.001" solref="0.001 1" density="100" friction="0.95 0.3 0.1" class="visual" material="Button001_material"/>
          <geom class="collision" type="box" pos="-0.252866 -0.293988 0.376553" size="0.01696334406733513 0.0026795221492648125 0.01153666153550148" quat="1.0 0.0 0.0 0.0"/>
        </body>
        <body name="Container001">
          <joint axis="0.0 -1.0 0.0" pos="0.000136 -0.000163 0.127939" limited="true" name="Container001_joint" range="0.0 0.13" type="slide" damping="1" frictionloss="1" armature=".01" stiffness="0.05"/>
          <geom mesh="Container001_vis" type="mesh" solimp="0.998 0.998 0.001" solref="0.001 1" density="100" friction="0.95 0.3 0.1" class="visual" material="Container001_material"/>
          <geom class="collision" type="box" pos="0.007631 0.242523 0.133468" size="0.29884931445121765 0.009070084430277348 0.05426874756813049" quat="1.0 0.0 0.0 0.0"/>
          <geom class="collision" type="box" pos="0.001528 -0.010683 0.073694" size="0.2927471995353699 0.24595850706100464 0.009566865861415863" quat="1.0 0.0 0.0 0.0"/>
          <geom class="collision" type="box" pos="-0.298976 0.000269 0.128841" size="0.24705632030963898 0.007493689656257629 0.050720565021038055" quat="0.7071067094802856 0.0 0.0 0.7071068286895752"/>
          <geom class="collision" type="box" pos="-0.001258 -0.242011 0.139326" size="0.29377201199531555 0.010061964392662048 0.04841029644012451" quat="1.0 0.0 0.0 0.0"/>
          <geom class="collision" type="box" pos="0.298903 -0.008724 0.130903" size="0.24254518747329712 0.007755940314382315 0.04865901172161102" quat="0.7071067094802856 0.0 0.0 0.7071068286895752"/>
        </body>
        <body name="Container002">
          <joint axis="0.0 -1.0 0.0" pos="0.000136 -0.000163 -0.137966" limited="true" name="Container002_joint" range="0.0 0.1" type="slide" damping="1" frictionloss="1" armature=".01" stiffness="0.05"/>
          <geom mesh="Container002_vis" type="mesh" solimp="0.998 0.998 0.001" solref="0.001 1" density="100" friction="0.95 0.3 0.1" class="visual" material="Container002_material"/>
          <geom class="collision" type="box" pos="0.298903 -0.008724 -0.138312" size="0.24254518747329712 0.007755940314382315 0.04865901172161102" quat="0.7071067094802856 0.0 0.0 0.7071068286895752"/>
          <geom class="collision" type="box" pos="-0.298976 0.000269 -0.135143" size="0.24705632030963898 0.007493689656257629 0.050720565021038055" quat="0.7071067094802856 0.0 0.0 0.7071068286895752"/>
          <geom class="collision" type="box" pos="0.007631 0.242523 -0.132359" size="0.29884931445121765 0.009070084430277348 0.05426874756813049" quat="1.0 0.0 0.0 0.0"/>
          <geom class="collision" type="box" pos="-0.001258 -0.242011 -0.136436" size="0.29377201199531555 0.010061964392662048 0.04841029644012451" quat="1.0 0.0 0.0 0.0"/>
          <geom class="collision" type="box" pos="0.001528 -0.010683 -0.192379" size="0.2927471995353699 0.24595850706100464 0.009566865861415863" quat="1.0 0.0 0.0 0.0"/>
        </body>
        <body name="Door001">
          <joint axis="1.0 0.0 0.0" pos="-0.000274 -0.289268 -0.287976" limited="true" name="Door001_joint" range="0.0 0.5235987755982988" type="hinge" damping="1" frictionloss="1" armature=".01" stiffness="0.05"/>
          <geom mesh="Door001_vis" type="mesh" solimp="0.998 0.998 0.001" solref="0.001 1" density="100" friction="0.95 0.3 0.1" class="visual" material="Door001_material"/>
          <geom class="collision" type="box" pos="0.000046 -0.278061 0.006081" size="0.32965609431266785 0.014063283801078796 0.2890564799308777" quat="1.0 0.0 0.0 0.0"/>
          <body name="Handle001">
            <geom mesh="Handle001_vis" type="mesh" solimp="0.998 0.998 0.001" solref="0.001 1" density="100" friction="0.95 0.3 0.1" class="visual" material="Handle001_material"/>
            <geom class="collision" type="box" pos="-0.001291 -0.353571 0.271422" size="0.28864988684654236 0.014407921582460403 0.020323341712355614" quat="1.0 0.0 0.0 0.0"/>
            <geom class="collision" type="box" pos="0.272246 -0.321798 0.270539" size="0.03452816605567932 0.013897823169827461 0.018780503422021866" quat="0.7071067094802856 0.0 0.0 0.7071068286895752"/>
            <geom class="collision" type="box" pos="-0.273957 -0.321798 0.270539" size="0.03452816605567932 0.015166739001870155 0.018780503422021866" quat="0.7071067094802856 0.0 0.0 0.7071068286895752"/>
          </body>
        </body>
        <geom class="region" name="reg_main" type="box" pos="0.0 0.03751550000000001 0.0" size="0.329388 0.32953350000000003 0.488954"/>
        <geom class="region" name="reg_int" type="box" pos="-0.00022199999999999998 -0.004154500000000005 0.008095500000000005" size="0.304197 0.2557495 0.28969449999999997"/>
      </body>
    </body>
  </worldbody>
  <actuator>
    <motor name="Button001_joint_actuator" joint="Button001_joint" gear="0.5"/>
    <motor name="Container001_joint_actuator" joint="Container001_joint" gear="10"/>
    <motor name="Container002_joint_actuator" joint="Container002_joint" gear="10"/>
    <motor name="Door001_joint_actuator" joint="Door001_joint" gear="50"/>
  </actuator>
</mujoco>
