<mujoco model="model">
  <compiler angle="radian"/>
  <asset>
    <mesh file="visuals/door.obj" name="door_vis"/>
    <mesh file="visuals/door_Clear.obj" name="door_Clear_vis"/>
    <mesh file="visuals/Body001.obj" name="Body001_vis"/>
    <mesh file="visuals/Disc001.obj" name="Disc001_vis"/>
    <texture file="visuals/T_BC001.png" name="Body001_material" type="2d"/>
    <material name="Body001_material" rgba="1 1 1 1.0" texture="Body001_material" shininess="0.2512328028678894" specular="0.3103448502657381"/>
    <texture file="visuals/T_BC001.png" name="door_material" type="2d"/>
    <material name="door_material" rgba="1 1 1 1.0" texture="door_material" shininess="0.2512328028678894" specular="0.3103448502657381"/>
    <material name="door_Clear_material" rgba="0.04224412515759468 0.04224412515759468 0.04224412515759468 0.800000011920929" shininess="0.2512328028678894" specular="0.3103448502657381"/>
    <texture file="visuals/T_BC001.png" name="Disc001_material" type="2d"/>
    <material name="Disc001_material" rgba="1 1 1 1.0" texture="Disc001_material" shininess="0.2512328028678894" specular="0.3103448502657381"/>
  </asset>
  <default>
    <default class="visual">
      <geom conaffinity="0" contype="0" group="1" type="mesh"/>
    </default>
    <default class="collision">
      <geom group="0" rgba="0.5 0 0 0.5"/>
    </default>
    <default class="spawn">
      <geom group="0" rgba="1 1 1 0.5" contype="0" conaffinity="0"/>
      <site group="0" rgba="1 1 1 0.5"/>
    </default>
    <default class="region">
      <geom group="1" conaffinity="0" contype="0" rgba="0 1 0 0"/>
    </default>
  </default>
  <worldbody>
    <body>
      <body name="object">
        <geom class="collision" type="box" pos="0.28804028034210205 -0.22508026659488678 -0.08048746734857559" size="0.010044815950095654 0.00039716094033792615 0.006886591203510761" quat="1.0 0.0 0.0 0.0" name="start_button" rgba="0.0 0.5 0 0.5"/>
        <geom class="collision" type="box" pos="0.23524892330169678 -0.22508026659488678 -0.08021195232868195" size="0.010021554306149483 0.0003947782388422638 0.006872855126857758" quat="1.0 0.0 0.0 0.0" name="stop_button" rgba="0.0 0.5 0 0.5"/>
        <geom class="collision" type="box" pos="-0.05606522411108017 -0.006216840352863073 -0.07694835215806961" size="0.16716837882995605 0.16716837882995605 0.0010897878091782331" quat="1.0 0.0 0.0 0.0" name="tray" rgba="0 1 0 0.5"/>
        <geom mesh="Body001_vis" type="mesh" solimp="0.998 0.998 0.001" solref="0.001 1" density="100" friction="0.95 0.3 0.1" class="visual" material="Body001_material"/>
        <geom class="collision" type="box" pos="-0.2888477146625519 0.039665114134550095 -0.0012215570313856006" size="0.027851169928908348 0.21701890230178833 0.1852727234363556" quat="1.0 0.0 0.0 0.0"/>
        <geom class="collision" type="box" pos="0.23082037270069122 0.03936713933944702 -0.0007989425212144852" size="0.08150354772806168 0.21672089397907257 0.1883750557899475" quat="1.0 0.0 0.0 0.0"/>
        <geom class="collision" type="box" pos="-2.34867911785841e-08 0.03936713561415672 0.15464387834072113" size="0.3166988492012024 0.21672092378139496 0.03453011065721512" quat="1.0 0.0 0.0 0.0"/>
        <geom class="collision" type="box" pos="-2.34867911785841e-08 0.03936713561415672 -0.14804884791374207" size="0.3166988492012024 0.21672092378139496 0.04112515226006508" quat="1.0 0.0 0.0 0.0"/>
        <geom class="collision" type="box" pos="-0.07183446735143661 0.21443091332912445 -0.004791893996298313" size="0.24538031220436096 0.041657134890556335 0.1843820959329605" quat="1.0 0.0 0.0 0.0"/>
        <geom class="collision" type="box" pos="0.261223703622818 -0.006090258713811636 -4.0745362639427185e-09" size="0.0554751381278038 0.21786582469940186 0.18917399644851685" quat="1.0 0.0 0.0 0.0"/>
        <geom class="collision" type="box" pos="-0.27998873591423035 -0.005724452435970306 0.012928989715874195" size="0.026524532586336136 0.12103907763957977 0.08569302409887314" quat="1.0 0.0 0.0 0.0"/>
        <body name="door">
          <joint axis="0.0 0.0 1.0" pos="-0.2902221977710724 -0.2019326090812683 0.0076302215456962585" limited="true" name="microjoint" range="-1.5707963267948966 0.0" type="hinge" damping="1" frictionloss="1" armature=".01" stiffness="0.05"/>
          <geom mesh="door_vis" type="mesh" solimp="0.998 0.998 0.001" solref="0.001 1" density="100" friction="0.95 0.3 0.1" class="visual" material="door_material"/>
          <geom class="collision" type="box" pos="-0.055106304585933685 -0.20777581632137299 0.1539645791053772" size="0.2370222806930542 0.015952063724398613 0.03360941261053085" quat="1.0 0.0 0.0 0.0"/>
          <geom class="collision" type="box" pos="-0.055106304585933685 -0.20777581632137299 -0.14089101552963257" size="0.2370222806930542 0.015952063724398613 0.033911868929862976" quat="1.0 0.0 0.0 0.0"/>
          <geom class="collision" type="box" pos="0.16612358391284943 -0.20777581632137299 0.003234627190977335" size="0.01586299203336239 0.015952063724398613 0.12191569805145264" quat="1.0 0.0 0.0 0.0"/>
          <geom class="collision" type="box" pos="-0.27732789516448975 -0.20777581632137299 0.005661776289343834" size="0.014800661243498325 0.015952063724398613 0.12143727391958237" quat="1.0 0.0 0.0 0.0"/>
          <geom class="collision" type="box" pos="0.1452796310186386 -0.2523866593837738 -0.12741456925868988" size="0.01679394580423832 0.00402682414278388 0.017611566931009293" quat="1.0 0.0 0.0 0.0"/>
          <geom class="collision" type="box" pos="0.14527960121631622 -0.2523885667324066 0.13459058105945587" size="0.01679394766688347 0.004026825539767742 0.01692659966647625" quat="1.0 0.0 0.0 0.0"/>
          <geom class="collision" type="box" pos="0.14527955651283264 -0.23616871237754822 0.15471932291984558" size="0.01679397001862526 0.016284829005599022 0.0041481382213532925" quat="1.0 0.0 0.0 0.0"/>
          <geom class="collision" type="box" pos="0.1455850899219513 -0.2345203310251236 -0.14039626717567444" size="0.016553714871406555 0.014636514708399773 0.004379956983029842" quat="1.0 0.0 0.0 0.0"/>
          <geom class="collision" type="box" pos="0.14527961611747742 -0.2523866593837738 0.0036662218626588583" size="0.016794003546237946 0.004026795271784067 0.11099153757095337" quat="1.0 0.0 0.0 0.0" name="door_handle"/>
          <body name="door_Clear">
            <geom mesh="door_Clear_vis" type="mesh" solimp="0.998 0.998 0.001" solref="0.001 1" density="100" friction="0.95 0.3 0.1" class="visual" material="door_Clear_material"/>
            <geom class="collision" type="box" pos="-0.05552075803279877 -0.22018659114837646 0.007482514716684818" size="0.20229002833366394 0.0018031829968094826 0.10940734297037125" quat="1.0 0.0 0.0 0.0"/>
          </body>
        </body>
        <body name="Disc001">
          <joint axis="0.0 0.0 -1.0" pos="-0.05599730834364891 -0.0066619813442230225 -0.08074215054512024" limited="false" name="Disc001_joint" range="0 360" type="hinge" damping="1" frictionloss="1" armature=".01" stiffness="0.05"/>
          <geom mesh="Disc001_vis" type="mesh" solimp="0.998 0.998 0.001" solref="0.001 1" density="100" friction="0.95 0.3 0.1" class="visual" material="Disc001_material"/>
          <geom class="collision" type="cylinder" pos="-0.05556977167725563 -0.0066036563366651535 -0.0855187177658081" size="0.16685064136981964 0.006239700131118298" quat="1.0 0.0 0.0 0.0"/>
        </body>
        <geom class="region" name="reg_main" type="box" pos="0.0 0.01607944816350937 0.0" size="0.3166988492012024 0.24000859260559082 0.18917399644851685"/>
        <geom class="region" name="reg_int" type="box" pos="-0.05486471951007843 -0.001358814537525177 0.009017027914524078" size="0.20403523743152618 0.17526546865701675 0.11028897762298584"/>
      </body>
    </body>
  </worldbody>
  <actuator>
    <motor name="microjoint_actuator" joint="microjoint" gear="10"/>
    <motor name="Disc001_joint_actuator" joint="Disc001_joint" gear="10"/>
  </actuator>
</mujoco>
