<?xml version='1.0' encoding='UTF-8'?>
<mujoco model="model">
  <option timestep="0.002" gravity="0.0 0.0 -9.81"/>
  <compiler angle="radian"/>
  <asset>
    <mesh file="visuals/Blade001.obj" name="Blade001_vis"/>
    <mesh file="visuals/Body001.obj" name="Body001_vis"/>
    <mesh file="visuals/Button001.obj" name="Button001_vis"/>
    <mesh file="visuals/Button002.obj" name="Button002_vis"/>
    <mesh file="visuals/Jug001.obj" name="Jug001_vis"/>
    <mesh file="visuals/Jug001_Clear.obj" name="Jug001_Clear_vis"/>
    <mesh file="visuals/Knob001.obj" name="Knob001_vis"/>
    <mesh file="visuals/Lid001.obj" name="Lid001_vis"/>
    <texture file="visuals/T_BC001.png" name="Body001_material" type="2d"/>
    <material name="Body001_material" rgba="1 1 1 1.0" texture="Body001_material" shininess="0.5" specular="0.3103448502657381"/>
    <texture file="visuals/T_BC001.png" name="Button001_material" type="2d"/>
    <material name="Button001_material" rgba="1 1 1 1.0" texture="Button001_material" shininess="0.5" specular="0.3103448502657381"/>
    <texture file="visuals/T_BC001.png" name="Button002_material" type="2d"/>
    <material name="Button002_material" rgba="1 1 1 1.0" texture="Button002_material" shininess="0.5" specular="0.3103448502657381"/>
    <texture file="visuals/T_BC001.png" name="Jug001_material" type="2d"/>
    <material name="Jug001_material" rgba="1 1 1 1.0" texture="Jug001_material" shininess="0.5" specular="0.3103448502657381"/>
    <texture file="visuals/T_BC001.png" name="Blade001_material" type="2d"/>
    <material name="Blade001_material" rgba="1 1 1 1.0" texture="Blade001_material" shininess="0.5" specular="0.3103448502657381"/>
    <texture file="visuals/T_BC001.png" name="Jug001_Clear_material" type="2d"/>
    <material name="Jug001_Clear_material" rgba="1 1 1 0.699999988079071" texture="Jug001_Clear_material" shininess="0.5" specular="0.3103448502657381"/>
    <texture file="visuals/T_BC001.png" name="Lid001_material" type="2d"/>
    <material name="Lid001_material" rgba="1 1 1 1.0" texture="Lid001_material" shininess="0.5" specular="0.3103448502657381"/>
    <texture file="visuals/T_BC001.png" name="Knob001_material" type="2d"/>
    <material name="Knob001_material" rgba="1 1 1 1.0" texture="Knob001_material" shininess="0.5" specular="0.3103448502657381"/>
  </asset>
  <default>
    <default class="visual">
      <geom conaffinity="0" contype="0" group="1" type="mesh"/>
    </default>
    <default class="collision">
      <geom group="0" rgba="0.5 0 0 0.5"/>
    </default>
    <default class="spawn">
      <geom group="0" rgba="1 1 1 0.5" contype="0" conaffinity="0"/>
      <site group="0" rgba="1 1 1 0.5"/>
    </default>
    <default class="region">
      <geom group="1" conaffinity="0" contype="0" rgba="0 1 0 0"/>
    </default>
  </default>
  <worldbody>
    <body>
      <body name="object">
        <geom mesh="Body001_vis" type="mesh" solimp="0.998 0.998 0.001" solref="0.001 1" friction="0.95 0.3 0.1" class="visual" material="Body001_material"/>
        <geom class="collision" type="box" pos="-0.015612 -0.049564 -0.168835" size="0.09955644607543945 0.044624779373407364 0.032997120171785355" quat="0.8877590894699097 0.46030834317207336 0.0 0.0" density="1000.0"/>
        <geom class="collision" type="box" pos="-0.015612 0.004733 -0.213757" size="0.09955644607543945 0.10717274248600006 0.03572746366262436" quat="1.0 0.0 0.0 0.0" density="1000.0"/>
        <geom class="collision" type="box" pos="-0.015612 0.030626 -0.147045" size="0.09955644607543945 0.08168954402208328 0.032997116446495056" quat="1.0 0.0 0.0 0.0" density="1000.0"/>
        <geom class="collision" type="cylinder" pos="-0.016043 0.026247 -0.103772" size="0.07834652066230774 0.01722797192633152" quat="1.0 0.0 0.0 0.0" density="1000.0"/>
        <body name="Button001">
          <joint axis="0.10692079365253448 0.8121441602706909 -0.5735763907432556" pos="-0.061698 -0.090387 -0.155615" limited="true" name="Button001_joint" range="0.0 0.0015" type="slide" damping="1" frictionloss="1" armature=".01" stiffness="0.05" springref="-0.4"/>
          <geom mesh="Button001_vis" type="mesh" solimp="0.998 0.998 0.001" solref="0.001 1" friction="0.95 0.3 0.1" class="visual" material="Button001_material"/>
          <geom class="collision" type="box" pos="-0.061698 -0.090387 -0.155615" size="0.010050386190414429 0.0029207041952759027 0.00618571974337101" quat="0.95280921459198 -0.3004196286201477 0.013116603717207909 -0.0416005440056324" density="1000.0"/>
        </body>
        <body name="Button002">
          <joint axis="-0.10692079365253448 0.8121441602706909 -0.5735763907432556" pos="0.031339 -0.090387 -0.155615" limited="true" name="Button002_joint" range="0.0 0.0015" type="slide" damping="1" frictionloss="1" armature=".01" stiffness="0.05" springref="-0.4"/>
          <geom mesh="Button002_vis" type="mesh" solimp="0.998 0.998 0.001" solref="0.001 1" friction="0.95 0.3 0.1" class="visual" material="Button002_material"/>
          <geom class="collision" type="box" pos="0.031339 -0.090387 -0.155615" size="0.010050386190414429 0.0029207041952759027 0.00618571974337101" quat="0.95280921459198 -0.3004196286201477 -0.013116603717207909 0.0416005440056324" density="1000.0"/>
        </body>
        <body name="Jug001">
          <joint axis="0.0 0.0 1.0" pos="-0.016322 0.015513 0.049152" limited="true" name="Jug001_joint" range="0.0 0.05" type="slide" damping="1" frictionloss="1" armature=".01" stiffness="0.05"/>
          <geom mesh="Jug001_vis" type="mesh" solimp="0.998 0.998 0.001" solref="0.001 1" friction="0.95 0.3 0.1" class="visual" material="Jug001_material"/>
          <geom class="collision" type="cylinder" pos="-0.016043 0.026247 -0.061340" size="0.07198860496282578 0.023390205577015877" quat="1.0 0.0 0.0 0.0" density="1000.0"/>
          <body name="Blade001">
            <joint axis="0.0 0.0 1.0" pos="-0.016335 0.024566 -0.019085" limited="false" name="Blade001_joint" range="0 360" type="hinge" damping="1" frictionloss="1" armature=".01" stiffness="0.05"/>
            <geom mesh="Blade001_vis" type="mesh" solimp="0.998 0.998 0.001" solref="0.001 1" friction="0.95 0.3 0.1" class="visual" material="Blade001_material"/>
            <geom class="collision" type="cylinder" pos="-0.016339 0.024586 -0.024406" size="0.007670124527066946 0.010787472128868103" quat="1.0 0.0 0.0 0.0" density="1000.0"/>
            <geom class="collision" type="box" pos="-0.029776 0.024758 -0.016572" size="0.008050991222262383 0.005571782123297453 0.000517530832439661" quat="0.979388952255249 0.0 -0.20198345184326172 0.0" density="1000.0"/>
            <geom class="collision" type="box" pos="-0.045692 0.024721 -0.023506" size="0.009483198635280132 0.003432794939726591 0.0005175308906473219" quat="0.9779711961746216 0.0 -0.20873989164829254 0.0" density="1000.0"/>
            <geom class="collision" type="box" pos="0.012136 0.024721 -0.023481" size="0.009483198635280132 0.003432794939726591 0.0005175308906473219" quat="7.383476940958644e-08 0.9779711961746216 1.5759423988015442e-08 -0.20873990654945374" density="1000.0"/>
            <geom class="collision" type="box" pos="-0.003744 0.024758 -0.016420" size="0.008050992153584957 0.005571782123297453 0.0005175308906473219" quat="7.394180556730134e-08 0.979388952255249 1.5249323581656427e-08 -0.20198343694210052" density="1000.0"/>
            <geom class="collision" type="box" pos="-0.016064 0.054418 -0.002179" size="0.009483198635280132 0.003432794939726591 0.0005175308906473219" quat="0.6829333901405334 0.18330861628055573 -0.18330861628055573 0.6829333305358887" density="1000.0"/>
            <geom class="collision" type="box" pos="-0.016027 0.039307 -0.010726" size="0.008050991222262383 0.005571782123297453 0.000517530832439661" quat="0.6841824650764465 0.17858955264091492 -0.17858952283859253 0.6841826438903809" density="1000.0"/>
            <geom class="collision" type="box" pos="-0.016027 0.010910 -0.010726" size="0.008050991222262383 0.005571782123297453 0.000517530832439661" quat="0.17858953773975372 0.6841825842857361 0.6841825246810913 -0.17858950793743134" density="1000.0"/>
            <geom class="collision" type="box" pos="-0.016064 -0.004201 -0.002179" size="0.009483198635280132 0.003432794939726591 0.0005175308906473219" quat="0.18330861628055573 0.6829333305358887 0.6829333305358887 -0.18330855667591095" density="1000.0"/>
          </body>
          <body name="Jug001_Clear">
            <geom class="region" name="reg_int" type="box" pos="-0.0166235 0.024068999999999997 0.064287" size="0.0592115 0.059614 0.15187099999999998"/>
            <geom mesh="Jug001_Clear_vis" type="mesh" solimp="0.998 0.998 0.001" solref="0.001 1" friction="0.95 0.3 0.1" class="visual" material="Jug001_Clear_material"/>
            <geom class="collision" type="box" pos="-0.064544 -0.020689 0.083932" size="0.045629244297742844 0.008825822733342648 0.12603016197681427" quat="0.9212555885314941 0.06958147138357162 -0.028821583837270737 -0.38159650564193726" density="1000.0"/>
            <geom class="collision" type="box" pos="-0.015087 -0.046024 -0.062070" size="0.025154929608106613 0.0036438615061342716 0.023110834881663322" quat="1.0 0.0 0.0 0.0" density="1000.0"/>
            <geom class="collision" type="box" pos="-0.061070 0.073343 0.083954" size="0.045629244297742844 0.008825824595987797 0.12605208158493042" quat="0.3815966546535492 0.02882160060107708 -0.06958146393299103 -0.9212555289268494" density="1000.0"/>
            <geom class="collision" type="box" pos="0.032908 0.069811 0.083428" size="0.045629240572452545 0.008825824595987797 0.12551972270011902" quat="0.38159632682800293 0.02882157452404499 0.06958147138357162 0.9212556481361389" density="1000.0"/>
            <geom class="collision" type="box" pos="0.029398 -0.024077 0.083110" size="0.045629244297742844 0.008825824595987797 0.1251983642578125" quat="0.9212555289268494 0.06958146393299103 0.02882159873843193 0.3815966546535492" density="1000.0"/>
            <geom class="collision" type="box" pos="-0.060620 -0.029974 -0.062070" size="0.025154929608106613 0.0036438615061342716 0.023110834881663322" quat="0.9397565126419067 0.0 0.0 -0.3418445587158203" density="1000.0"/>
            <geom class="collision" type="box" pos="-0.085131 0.011228 -0.062070" size="0.025154927745461464 0.0036438617389649153 0.023110834881663322" quat="0.7679169178009033 0.0 0.0 -0.6405494213104248" density="1000.0"/>
            <geom class="collision" type="box" pos="-0.077417 0.059066 -0.062070" size="0.025154927745461464 0.0036438615061342716 0.023110834881663322" quat="0.501535177230835 0.0 0.0 -0.8651372790336609" density="1000.0"/>
            <geom class="collision" type="box" pos="-0.041758 0.090256 -0.062070" size="0.025154929608106613 0.0036438617389649153 0.023110834881663322" quat="0.1822759509086609 0.0 0.0 -0.9832473993301392" density="1000.0"/>
            <geom class="collision" type="box" pos="0.007493 0.091255 -0.062070" size="0.025154929608106613 0.0036438615061342716 0.023110834881663322" quat="0.1721271127462387 0.0 0.0 0.9850747585296631" density="1000.0"/>
            <geom class="collision" type="box" pos="0.044959 0.060590 -0.062070" size="0.025154929608106613 0.0036438617389649153 0.023110834881663322" quat="0.4993874430656433 0.0 0.0 0.8663787841796875" density="1000.0"/>
            <geom class="collision" type="box" pos="0.053844 0.012854 -0.062070" size="0.02515493333339691 0.003643861971795559 0.023110834881663322" quat="0.7668055891990662 0.0 0.0 0.6418794393539429" density="1000.0"/>
            <geom class="collision" type="box" pos="0.029800 -0.029339 -0.062070" size="0.025154931470751762 0.0036438617389649153 0.023110834881663322" quat="0.9407618045806885 0.0 0.0 0.33906814455986023" density="1000.0"/>
            <geom class="collision" type="box" pos="-0.090205 0.025339 0.083261" size="0.02850382588803768 0.008825824595987797 0.1265544295310974" quat="0.709650456905365 0.05359915643930435 -0.05290931463241577 -0.700516939163208" density="1000.0"/>
            <geom class="collision" type="box" pos="-0.016654 0.094261 0.082986" size="0.02850382775068283 0.008825822733342648 0.12627652287483215" quat="0.03943026438355446 0.00297812232747674 0.07525552809238434 0.9963799715042114" density="1000.0"/>
            <geom class="collision" type="box" pos="0.051368 0.023786 0.082214" size="0.02850382775068283 0.008825823664665222 0.12549585103988647" quat="0.6996919512748718 0.0528470017015934 0.05366060510277748 0.7104638814926147" density="1000.0"/>
            <geom class="collision" type="box" pos="-0.019557 -0.045821 0.083302" size="0.02850382775068283 0.008825824595987797 0.12659597396850586" quat="0.9962204694747925 0.07524346560239792 0.003268356202170253 0.04327284172177315" density="1000.0"/>
            <geom class="collision" type="box" pos="0.111584 0.025927 0.073795" size="0.023755626752972603 0.010479923337697983 0.011317872442305088" quat="0.6425239443778992 0.0 0.7662656307220459 0.0" density="1000.0"/>
            <geom class="collision" type="box" pos="0.096511 0.025927 0.170497" size="0.023755624890327454 0.010479923337697983 0.00687967985868454" quat="1.0 0.0 0.0 0.0" density="1000.0"/>
            <geom class="collision" type="box" pos="0.111100 0.025927 0.130129" size="0.038404859602451324 0.010479923337697983 0.011317871510982513" quat="0.7342893481254578 0.0 0.6788366436958313 0.0" density="1000.0"/>
            <geom class="collision" type="box" pos="0.101759 0.025960 0.047254" size="0.016342977061867714 0.010479924269020557 0.011317871510982513" quat="0.1951066106557846 -1.9346716726431623e-05 0.9807310700416565 -0.00999981164932251" density="1000.0"/>
            <geom class="collision" type="box" pos="0.072527 0.025928 0.039834" size="0.023755624890327454 0.010479924269020557 0.011317872442305088" quat="0.0005009422893635929 0.0019272376084700227 0.9999498724937439 -0.00981235783547163" density="1000.0"/>
          </body>
          <body name="Lid001">
            <joint axis="0.0 0.0 1.0" pos="-0.004041 0.023773 0.214101" limited="true" name="Lid001_joint" range="0.0 0.05" type="slide" damping="1" frictionloss="1" armature=".01" stiffness="0.05"/>
            <geom mesh="Lid001_vis" type="mesh" solimp="0.998 0.998 0.001" solref="0.001 1" friction="0.95 0.3 0.1" class="visual" material="Lid001_material"/>
            <geom class="collision" type="cylinder" pos="-0.016205 0.023159 0.224910" size="0.09406635165214539 0.01148100383579731" quat="1.0 0.0 0.0 0.0" density="1000.0"/>
            <geom class="collision" type="cylinder" pos="-0.012212 0.023159 0.241958" size="0.03719872981309891 0.007537921890616417" quat="1.0 0.0 0.0 0.0" density="1000.0"/>
          </body>
        </body>
        <body name="Knob001">
          <joint axis="1.9229623871719884e-16 0.8660253882408142 -0.5" pos="-0.016404 -0.101570 -0.148913" limited="true" name="Knob001_joint" range="0.0 4.974188368183839" type="hinge" damping="0.05" armature="0.001"/>
          <geom mesh="Knob001_vis" type="mesh" solimp="0.998 0.998 0.001" solref="0.001 1" friction="0.95 0.3 0.1" class="visual" material="Knob001_material"/>
          <geom class="collision" type="cylinder" pos="-0.016382 -0.099427 -0.150115" size="0.018016861751675606 0.005274674389511347" quat="0.874619722366333 0.48480960726737976 -1.509269775197314e-16 -4.327761319274158e-17" density="1000.0"/>
        </body>
        <geom class="region" name="reg_main" type="box" pos="-0.004040500000000002 0.0023805000000000007 0.0" size="0.1207415 0.11312249999999999 0.249503"/>
      </body>
    </body>
  </worldbody>
  <actuator>
    <motor name="Button001_joint_actuator" joint="Button001_joint" gear="0.1"/>
    <motor name="Button002_joint_actuator" joint="Button002_joint" gear="0.1"/>
    <motor name="Jug001_joint_actuator" joint="Jug001_joint" gear="20"/>
    <motor name="Knob001_joint_actuator" joint="Knob001_joint" gear="10"/>
    <motor name="Blade001_joint_actuator" joint="Blade001_joint" gear="10"/>
    <motor name="Lid001_joint_actuator" joint="Lid001_joint" gear="10"/>
  </actuator>
</mujoco>
