<mujoco model="model">
  <compiler angle="radian"/>
  <asset>
    <mesh file="visuals/handle.obj" name="handle_vis"/>
    <mesh file="visuals/Body001.obj" name="Body001_vis"/>
    <mesh file="visuals/Body002.obj" name="Body002_vis"/>
    <mesh file="visuals/Funnel001.obj" name="Funnel001_vis"/>
    <mesh file="visuals/spout.obj" name="spout_vis"/>
    <texture file="visuals/T_BC001.png" name="Body001_material" type="2d"/>
    <material name="Body001_material" rgba="1 1 1 1.0" texture="Body001_material" shininess="0.4472135901451111" specular="0.3103448502657381"/>
    <texture file="visuals/T_BC001.png" name="Body002_material" type="2d"/>
    <material name="Body002_material" rgba="1 1 1 1.0" texture="Body002_material" shininess="8" specular="8"/>
    <texture file="visuals/T_BC001.png" name="handle_material" type="2d"/>
    <material name="handle_material" rgba="1 1 1 1.0" texture="handle_material" shininess="8" specular="8"/>
    <texture file="visuals/T_BC001.png" name="spout_material" type="2d"/>
    <material name="spout_material" rgba="1 1 1 1.0" texture="spout_material" shininess="8" specular="8"/>
    <texture file="visuals/T_BC001.png" name="Funnel001_material" type="2d"/>
    <material name="Funnel001_material" rgba="1 1 1 1.0" texture="Funnel001_material" shininess="8" specular="8"/>
  </asset>
  <default>
    <default class="visual">
      <geom conaffinity="0" contype="0" group="1" type="mesh"/>
    </default>
    <default class="collision">
      <geom group="0" rgba="0.5 0 0 0.5"/>
    </default>
    <default class="spawn">
      <geom group="0" rgba="1 1 1 0.5" contype="0" conaffinity="0"/>
      <site group="0" rgba="1 1 1 0.5"/>
    </default>
    <default class="region">
      <geom group="1" conaffinity="0" contype="0" rgba="0 1 0 0"/>
    </default>
  </default>
  <worldbody>
    <body>
      <body name="object">
        <geom mesh="Body001_vis" type="mesh" solimp="0.998 0.998 0.001" solref="0.001 1" density="100" friction="0.95 0.3 0.1" class="visual" material="Body001_material"/>
        <geom class="collision" type="cylinder" pos="0.000133 0.225779 -0.005818" size="0.016698651015758514 0.0544344037771225" quat="0.7071067094802856 0.0 0.0 -0.7071068286895752"/>
        <geom class="collision" type="cylinder" pos="0.000229 0.225779 -0.062937" size="0.025238705798983574 0.002348281443119049" quat="0.7071067094802856 0.0 0.0 -0.7071068286895752"/>
        <geom class="collision" type="cylinder" pos="0.021589 0.225779 -0.006023" size="0.015174861997365952 0.020444747060537338" quat="0.7071068286895752 1.2101623703131281e-08 0.7071067690849304 -1.2101622814952862e-08"/>
        <geom class="collision" type="box" pos="-0.224507 0.001841 -0.129897" size="0.012504592537879944 0.25616538524627686 0.06801488250494003" quat="1.0 0.0 0.0 0.0"/>
        <geom class="collision" type="box" pos="0.224422 0.001841 -0.129897" size="0.012258598580956459 0.2561629116535187 0.06801455467939377" quat="1.0 0.0 0.0 0.0"/>
        <geom class="collision" type="box" pos="-0.008722 -0.240480 -0.129897" size="0.2252257615327835 0.013843913562595844 0.06801486760377884" quat="1.0 0.0 0.0 0.0"/>
        <geom class="collision" type="box" pos="-0.136932 0.001218 -0.189083" size="0.0868404284119606 0.23745973408222198 0.008854970335960388" quat="1.0 0.0 0.0 0.0"/>
        <geom class="collision" type="box" pos="0.142064 0.001219 -0.189793" size="0.0939398854970932 0.2374599128961563 0.008144158869981766" quat="1.0 0.0 0.0 0.0"/>
        <geom class="collision" type="box" pos="-0.000952 0.150956 -0.189793" size="0.04979882016777992 0.08736347407102585 0.008144168183207512" quat="1.0 0.0 0.0 0.0"/>
        <geom class="collision" type="box" pos="-0.000952 -0.134312 -0.189793" size="0.04979899898171425 0.10186735540628433 0.008144198916852474" quat="1.0 0.0 0.0 0.0"/>
        <geom class="collision" type="box" pos="-0.008721 0.226664 -0.128275" size="0.22522734105587006 0.031342193484306335 0.06806662678718567" quat="1.0 0.0 0.0 0.0"/>
        <geom class="collision" type="box" pos="0.214557 -0.222782 -0.129897" size="0.011599640361964703 0.009580041281878948 0.06801487505435944" quat="0.43918120861053467 -3.5775858719944154e-08 7.318384831478397e-08 -0.8983985185623169"/>
        <geom class="collision" type="box" pos="-0.210495 -0.228230 -0.129897" size="0.011599640361964703 0.009580040350556374 0.06801487505435944" quat="0.338575154542923 -2.7580441042118764e-08 -7.664925050221427e-08 0.9409393668174744"/>
        <geom class="collision" type="box" pos="-0.213312 0.194750 -0.129897" size="0.011599640361964703 0.009580041281878948 0.06801487505435944" quat="0.9065268039703369 -7.38459888793841e-08 -3.4388353498115976e-08 0.422148197889328"/>
        <geom class="collision" type="box" pos="0.213941 0.197509 -0.129897" size="0.011599640361964703 0.009580041281878948 0.06801487505435944" quat="0.9206199645996094 -7.49940269884064e-08 3.180697660809528e-08 -0.3904598355293274"/>
        <body name="Body002">
          <geom mesh="Body002_vis" type="mesh" solimp="0.998 0.998 0.001" solref="0.001 1" density="100" friction="0.95 0.3 0.1" class="visual" material="Body002_material"/>
          <body name="handle">
            <joint axis="1.0 0.0 0.0" pos="0.059168 0.225788 -0.005479" limited="true" name="handle_joint_hinge_0" type="hinge" range="-0.7853981633974483 0.7853981633974483" damping="1" frictionloss="1" armature=".01" stiffness="0.05"/>
            <joint axis="0.0 1.0 0.0" pos="0.059168 0.225788 -0.005479" limited="true" name="handle_joint_hinge_1" type="hinge" range="0.0 0.17453292519943295" damping="1" frictionloss="1" armature=".01" stiffness="0.05"/>
            <geom mesh="handle_vis" type="mesh" solimp="0.998 0.998 0.001" solref="0.001 1" density="100" friction="0.95 0.3 0.1" class="visual" material="handle_material"/>
            <geom class="collision" type="box" pos="0.061306 0.225779 -0.005056" size="0.009259761311113834 0.014272594824433327 0.014272598549723625" quat="1.0 0.0 0.0 0.0"/>
            <geom class="collision" type="box" pos="0.059139 0.225779 0.035546" size="0.01202891394495964 0.002811787184327841 0.02961360663175583" quat="1.0 0.0 0.0 0.0"/>
          </body>
          <body name="spout">
            <joint axis="0.0 0.0 1.0" pos="0.000208 0.225931 0.119217" limited="true" name="spout_joint" range="-0.7853981633974483 0.7853981633974483" type="hinge" damping="1" frictionloss="1" armature=".01" stiffness="0.05"/>
            <site type="cylinder" rgba="0.5 0.75 1 1" size="0.007300759665668011 0.18885229527950287" pos="-0.000175 0.014026 0.001543" name="water"/>
            <geom mesh="spout_vis" type="mesh" solimp="0.998 0.998 0.001" solref="0.001 1" density="100" friction="0.95 0.3 0.1" class="visual" material="spout_material"/>
            <geom class="collision" type="box" pos="0.000145 0.225852 0.100582" size="0.014651758596301079 0.004856440704315901 0.052547164261341095" quat="1.0 0.0 0.0 0.0"/>
            <geom class="collision" type="box" pos="0.000145 0.091570 0.187218" size="0.004856437910348177 0.014651536010205746 0.09460997581481934" quat="0.49069109559059143 -0.5091387033462524 -0.5091405510902405 -0.4906892776489258"/>
            <geom class="collision" type="box" pos="0.000145 0.224860 0.159451" size="0.004856437910348177 0.014651536010205746 0.008405144326388836" quat="0.7054564952850342 0.04828108102083206 0.04828107729554176 -0.7054566144943237"/>
            <geom class="collision" type="box" pos="0.000145 0.221095 0.169524" size="0.00485643744468689 0.014651536010205746 0.008405144326388836" quat="0.6765242218971252 0.20570605993270874 0.20570604503154755 -0.6765242218971252"/>
            <geom class="collision" type="box" pos="0.000145 0.211379 0.178985" size="0.00485643744468689 0.014651536010205746 0.008405151776969433" quat="0.6162595748901367 0.3467335104942322 0.3467335104942322 -0.6162595748901367"/>
            <geom class="collision" type="box" pos="0.000145 0.198653 0.183187" size="0.004856438841670752 0.014651536010205746 0.008405154570937157" quat="0.5158554911613464 0.4836246371269226 0.4836215078830719 -0.5158590078353882"/>
            <geom class="collision" type="box" pos="0.000145 0.187786 0.183808" size="0.004856437910348177 0.014651536010205746 0.008405153639614582" quat="0.5070902109146118 0.49280792474746704 0.49281108379364014 -0.5070868730545044"/>
            <geom class="collision" type="cylinder" pos="0.000008 0.013670 0.181484" size="0.012532871216535568 0.004810836631804705" quat="0.7071067094802856 0.0 0.0 -0.7071068286895752"/>
          </body>
        </body>
        <body name="Funnel001">
          <joint axis="0.0 0.0 1.0" pos="-0.000756 0.015653 -0.189659" limited="true" name="Funnel001_joint" range="0.0 0.05" type="slide" damping="1" frictionloss="1" armature=".01" stiffness="0.05"/>
          <geom mesh="Funnel001_vis" type="mesh" solimp="0.998 0.998 0.001" solref="0.001 1" density="100" friction="0.95 0.3 0.1" class="visual" material="Funnel001_material"/>
          <geom class="collision" type="cylinder" pos="-0.000887 0.015076 -0.194613" size="0.031385838985443115 0.000918934412766248" quat="0.7071067094802856 0.0 0.0 -0.7071068286895752"/>
          <geom class="collision" type="cylinder" pos="-0.000798 0.015689 -0.190361" size="0.008735990151762962 0.003130966564640403" quat="0.7071067094802856 0.0 0.0 -0.7071068286895752"/>
          <geom class="collision" type="box" pos="0.031589 0.015689 -0.189946" size="0.0024221877101808786 0.0074821338057518005 0.00569393765181303" quat="1.0 0.0 0.0 0.0"/>
          <geom class="collision" type="box" pos="0.036884 0.015689 -0.185203" size="0.0056939381174743176 0.0074821338057518005 0.0009679003269411623" quat="1.0 0.0 0.0 0.0"/>
          <geom class="collision" type="box" pos="0.029844 0.005199 -0.189946" size="0.0024221877101808786 0.007482134271413088 0.00569393765181303" quat="0.9864323139190674 0.0 -0.0 -0.1641685664653778"/>
          <geom class="collision" type="box" pos="0.034853 0.003484 -0.185203" size="0.000967899919487536 0.007482134271413088 0.00569393765181303" quat="0.6975129842758179 0.11608472466468811 0.6975129246711731 -0.11608471721410751"/>
          <geom class="collision" type="box" pos="0.025056 -0.003818 -0.189946" size="0.0024221877101808786 0.0074821338057518005 0.00569393765181303" quat="0.9482275247573853 0.0 -0.0 -0.3175918757915497"/>
          <geom class="collision" type="box" pos="0.029282 -0.007007 -0.185203" size="0.000967899919487536 0.007482134271413088 0.00569393765181303" quat="0.6704981327056885 0.22457140684127808 0.6704980731010437 -0.22457139194011688"/>
          <geom class="collision" type="box" pos="0.017345 -0.011140 -0.189946" size="0.0024221877101808786 0.0074821338057518005 0.00569393765181303" quat="0.8832235336303711 0.0 -0.0 -0.4689521789550781"/>
          <geom class="collision" type="box" pos="0.020310 -0.015526 -0.185203" size="0.000967899919487536 0.0074821338057518005 0.00569393765181303" quat="0.6245334148406982 0.33159923553466797 0.6245333552360535 -0.3315992057323456"/>
          <geom class="collision" type="box" pos="0.008515 -0.015330 -0.189946" size="0.0024221877101808786 0.0074821338057518005 0.00569393765181303" quat="0.8023572564125061 0.0 -0.0 -0.5968440771102905"/>
          <geom class="collision" type="box" pos="0.010038 -0.020401 -0.185203" size="0.000967899919487536 0.0074821338057518005 0.005693937186151743" quat="0.567352294921875 0.42203250527381897 0.5673522353172302 -0.4220324754714966"/>
          <geom class="collision" type="box" pos="-0.002033 -0.016675 -0.189946" size="0.0024221877101808786 0.007482133340090513 0.00569393765181303" quat="0.6934880018234253 0.0 -0.0 -0.7204681634902954"/>
          <geom class="collision" type="box" pos="-0.002235 -0.021965 -0.185203" size="0.007693903055042028 0.005975225940346718 0.0009679005015641451" quat="1.0 0.0 0.0 0.0"/>
          <geom class="collision" type="box" pos="-0.012046 -0.014682 -0.189946" size="0.0024221877101808786 0.007482133340090513 0.00569393765181303" quat="0.5712643265724182 0.0 -0.0 -0.8207661509513855"/>
          <geom class="collision" type="box" pos="-0.013885 -0.019647 -0.185203" size="0.000967899919487536 0.007482133340090513 0.00569393765181303" quat="0.4039449095726013 0.5803692936897278 0.40394487977027893 -0.5803692936897278"/>
          <geom class="collision" type="box" pos="-0.021277 -0.009402 -0.189946" size="0.0024221877101808786 0.0074821338057518005 0.00569393765181303" quat="0.42876964807510376 0.0 -0.0 -0.9034138321876526"/>
          <geom class="collision" type="box" pos="-0.024624 -0.013504 -0.185203" size="0.000967899919487536 0.0074821338057518005 0.00569393765181303" quat="0.30318593978881836 0.6388100981712341 0.30318590998649597 -0.6388100385665894"/>
          <geom class="collision" type="box" pos="-0.028182 -0.001604 -0.189946" size="0.0024221877101808786 0.0074821338057518005 0.00569393765181303" quat="0.2779256999492645 0.0 -0.0 -0.9606025815010071"/>
          <geom class="collision" type="box" pos="-0.032658 -0.004431 -0.185203" size="0.000967899919487536 0.0074821338057518005 0.00569393765181303" quat="0.19652314484119415 0.6792486310005188 0.19652312994003296 -0.679248571395874"/>
          <geom class="collision" type="box" pos="-0.032307 0.008197 -0.189946" size="0.0024221877101808786 0.0074821338057518005 0.00569393765181303" quat="0.1164541244506836 0.0 -0.0 -0.9931960701942444"/>
          <geom class="collision" type="box" pos="-0.037457 0.006972 -0.185203" size="0.000967899919487536 0.0074821338057518005 0.005693937186151743" quat="0.08234550803899765 0.70229572057724 0.08234550058841705 -0.7022956609725952"/>
          <geom class="collision" type="box" pos="-0.033073 0.018377 -0.189946" size="0.0024221877101808786 0.0074821338057518005 0.00569393765181303" quat="0.04154292494058609 0.0 0.0 0.999136745929718"/>
          <geom class="collision" type="box" pos="-0.038349 0.018817 -0.185203" size="0.000967899919487536 0.0074821338057518005 0.00569393765181303" quat="0.029375284910202026 -0.7064963579177856 0.029375283047556877 0.7064962983131409"/>
          <geom class="collision" type="box" pos="-0.030463 0.028686 -0.189946" size="0.0024221877101808786 0.0074821338057518005 0.00569393765181303" quat="0.20500601828098297 0.0 0.0 0.9787607192993164"/>
          <geom class="collision" type="box" pos="-0.035312 0.030811 -0.185203" size="0.000967899919487536 0.0074821338057518005 0.00569393765181303" quat="0.1449611485004425 -0.6920883655548096 0.1449611335992813 0.6920883059501648"/>
          <geom class="collision" type="box" pos="-0.024806 0.037427 -0.189946" size="0.0024221879430115223 0.0074821338057518005 0.00569393765181303" quat="0.35966718196868896 0.0 0.0 0.9330806732177734"/>
          <geom class="collision" type="box" pos="-0.028730 0.040981 -0.185203" size="0.000967899919487536 0.0074821338057518005 0.00569393765181303" quat="0.2543230354785919 -0.6597877144813538 0.25432300567626953 0.659787654876709"/>
          <geom class="collision" type="box" pos="-0.016471 0.044031 -0.189946" size="0.0024221877101808786 0.007482134271413088 0.00569393765181303" quat="0.5079696178436279 0.0 0.0 0.8613749742507935"/>
          <geom class="collision" type="box" pos="-0.019033 0.048664 -0.185203" size="0.000967899919487536 0.0074821338057518005 0.00569393765181303" quat="0.35918885469436646 -0.6090840697288513 0.35918882489204407 0.6090840101242065"/>
          <geom class="collision" type="box" pos="-0.006870 0.047502 -0.189946" size="0.0024221877101808786 0.007482134271413088 0.00569393765181303" quat="0.6373849511146545 0.0 0.0 0.7705455422401428"/>
          <geom class="collision" type="box" pos="-0.007862 0.052702 -0.185203" size="0.000967899919487536 0.0074821338057518005 0.00569393765181303" quat="0.4506993591785431 -0.5448578596115112 0.4506993293762207 0.5448578596115112"/>
          <geom class="collision" type="box" pos="0.003761 0.047754 -0.189946" size="0.002422187477350235 0.0074821338057518005 0.00569393765181303" quat="0.7552365064620972 0.0 0.0 0.6554523706436157"/>
          <geom class="collision" type="box" pos="0.004506 0.052995 -0.185203" size="0.000967899919487536 0.0074821338057518005 0.00569393765181303" quat="0.534032940864563 -0.463474839925766 0.5340328216552734 0.46347475051879883"/>
          <geom class="collision" type="box" pos="0.011550 0.045630 -0.189946" size="0.0024221877101808786 0.0074821338057518005 0.00569393765181303" quat="0.8310381174087524 0.0 0.0 0.5562154650688171"/>
          <geom class="collision" type="box" pos="0.013568 0.050525 -0.185203" size="0.000967899919487536 0.007482133340090513 0.00569393765181303" quat="0.5876326560974121 -0.39330387115478516 0.5876325368881226 0.3933038115501404"/>
          <geom class="collision" type="box" pos="0.020582 0.040017 -0.189946" size="0.0024221879430115223 0.0074821338057518005 0.00569393765181303" quat="0.9110758304595947 0.0 0.0 0.4122387766838074"/>
          <geom class="collision" type="box" pos="0.024077 0.043994 -0.185203" size="0.000967899919487536 0.007482134271413088 0.00569393765181303" quat="0.644227921962738 -0.2914968729019165 0.6442278623580933 0.2914968430995941"/>
          <geom class="collision" type="box" pos="0.027092 0.032153 -0.189946" size="0.0024221877101808786 0.0074821338057518005 0.00569393765181303" quat="0.9646627306938171 0.0 0.0 0.263487845659256"/>
          <geom class="collision" type="box" pos="0.031652 0.034845 -0.185203" size="0.000967899919487536 0.007482134271413088 0.00569393765181303" quat="0.682119607925415 -0.18631403148174286 0.6821195483207703 0.18631401658058167"/>
          <geom class="collision" type="box" pos="0.030922 0.022232 -0.189946" size="0.0024221877101808786 0.0074821338057518005 0.00569393765181303" quat="0.994830846786499 0.0 0.0 0.10154592245817184"/>
          <geom class="collision" type="box" pos="0.036107 0.023302 -0.185203" size="0.000967899919487536 0.0074821338057518005 0.00569393765181303" quat="0.7034516930580139 -0.07180377840995789 0.7034516334533691 0.07180377095937729"/>
        </body>
        <geom class="region" name="reg_main" type="box" pos="-5.000000000005e-07 0.0 -0.1287165" size="0.23617149999999998 0.253878 0.0666875"/>
        <geom class="region" name="reg_basin" type="box" pos="-0.0006909999999999972 -0.01614800000000001 -0.12351999999999999" size="0.204169 0.208994 0.05908499999999999"/>
      </body>
    </body>
  </worldbody>
  <actuator>
    <motor name="Funnel001_joint_actuator" joint="Funnel001_joint" gear="10"/>
    <motor name="handle_joint_hinge_0_actuator" joint="handle_joint_hinge_0" gear="10"/>
    <motor name="handle_joint_hinge_1_actuator" joint="handle_joint_hinge_1" gear="10"/>
    <motor name="spout_joint_actuator" joint="spout_joint" gear="10"/>
  </actuator>
</mujoco>
