<mujoco model="model">
  <compiler angle="radian"/>
  <asset>
    <mesh file="visuals/handle.obj" name="handle_vis"/>
    <mesh file="visuals/Body002.obj" name="Body002_vis"/>
    <mesh file="visuals/Body001.obj" name="Body001_vis"/>
    <mesh file="visuals/Funnel001.obj" name="Funnel_vis"/>
    <mesh file="visuals/spout.obj" name="spout_vis"/>
    <texture file="visuals/T_BC001.png" name="T_BC001" type="2d"/>
    <material name="material" rgba="1 1 1 1" texture="T_BC001"/>
  </asset>
  <default>
    <default class="visual">
      <geom conaffinity="0" contype="0" group="1" type="mesh"/>
    </default>
    <default class="collision">
      <geom group="0" rgba="0.5 0 0 0.5"/>
    </default>
    <default class="region">
      <geom group="1" conaffinity="0" contype="0" rgba="0 1 0 0"/>
    </default>
  </default>
  <worldbody>
    <body>
      <body name="object">
        <geom mesh="Body001_vis" type="mesh" solimp="0.998 0.998 0.001" solref="0.001 1" density="100" friction="0.95 0.3 0.1" class="visual" material="material"/>
        <geom class="collision" type="cylinder" pos="-0.006958474405109882 0.0 0.16443879902362823" size="0.014489528723061085 0.047233082354068756" quat="0.7071067690849304 0.0 -0.0 -0.7071067690849304"/>
        <geom class="collision" type="cylinder" pos="-0.006875015329569578 0.0 0.11487629264593124" size="0.021899787709116936 0.002037618774920702" quat="0.7071067690849304 0.0 -0.0 -0.7071067690849304"/>
        <geom class="collision" type="cylinder" pos="0.011659065261483192 -9.313225746154785e-10 0.16426052153110504" size="0.013167324475944042 0.0177400391548872" quat="0.7071068286895752 1.2101618374060763e-08 0.7071067690849304 -1.2101617485882343e-08"/>
        <geom class="collision" type="box" pos="-0.20084623992443085 -0.19516971707344055 0.03190179541707039" size="0.2231341153383255 0.013241598382592201 0.08141572028398514" quat="0.7071067690849304 -5.76011558450773e-08 5.76011558450773e-08 -0.7071067690849304"/>
        <geom class="collision" type="box" pos="0.19723926484584808 -0.19516974687576294 0.03279146924614906" size="0.2231341153383255 0.019062750041484833 0.08230539411306381" quat="0.7071067690849304 -5.76011558450773e-08 5.76011558450773e-08 -0.7071067690849304"/>
        <geom class="collision" type="box" pos="-0.014641322195529938 0.00956006906926632 0.03364773467183113" size="0.19543136656284332 0.019062746316194534 0.08316165953874588" quat="7.549790126404332e-08 -7.289104440509847e-16 2.1855694143368964e-08 -1.0"/>
        <geom class="collision" type="box" pos="-0.014641344547271729 -0.39752548933029175 0.03364773094654083" size="0.19543136656284332 0.019062746316194534 0.08316165953874588" quat="7.549790126404332e-08 -7.289104440509847e-16 2.1855694143368964e-08 -1.0"/>
        <geom class="collision" type="box" pos="-0.1197042465209961 -0.18166831135749817 -0.009911640547215939" size="0.07203380018472672 0.019062746316194534 0.17875871062278748" quat="9.553192370503893e-08 1.1238227237697629e-08 -0.7071067690849304 -0.7071068286895752"/>
        <geom class="collision" type="box" pos="0.10671751201152802 -0.18166828155517578 -0.00991163868457079" size="0.07203380018472672 0.019062746316194534 0.17875871062278748" quat="9.553192370503893e-08 1.1238227237697629e-08 -0.7071067690849304 -0.7071068286895752"/>
        <geom class="collision" type="box" pos="-0.00789988785982132 -0.07819554209709167 -0.00991163868457079" size="0.06395793706178665 0.019062750041484833 0.043210890144109726" quat="-0.5 -0.4999999701976776 -0.4999999701976776 -0.5"/>
        <geom class="collision" type="box" pos="-0.00789991021156311 -0.2906027138233185 -0.00991163868457079" size="0.06395793706178665 0.019062750041484833 0.043210890144109726" quat="-0.5 -0.4999999701976776 -0.4999999701976776 -0.5"/>
        <body name="Funnel">
          <joint axis="0 0 1" pos="-0.007595268078148365 -0.18232913315296173 0.002935395110398531" limited="true" name="Funnel_joint" range="0.0 0.02" type="slide" damping="2" frictionloss="2" armature=".01"/>
          <geom mesh="Funnel_vis" type="mesh" solimp="0.998 0.998 0.001" solref="0.001 1" density="100" friction="0.95 0.3 0.1" class="visual" material="material"/>
          <geom class="collision" type="box" pos="-0.00736081600189209 -0.1828279346227646 -0.003717811545357108" size="0.03082732856273651 0.03082732856273651 0.0059769731014966965" quat="0.7071067690849304 0.0 -0.0 -0.7071067690849304"/>
          <geom class="collision" type="box" pos="-0.007535099983215332 -0.18280398845672607 0.0038125196006149054" size="0.007117520552128553 0.007117520086467266 0.002466885605826974" quat="0.7071067690849304 0.0 -0.0 -0.7071067690849304"/>
        </body>
        <body name="Body002">
          <geom mesh="Body002_vis" type="mesh" solimp="0.998 0.998 0.001" solref="0.001 1" density="100" friction="0.95 0.3 0.1" class="visual" material="material"/>
        </body>
        <body name="spout">
          <site type="cylinder" rgba="0.5 0.75 1 1" pos="-0.0076065040193498135 -0.18391381204128265 0.1626429408788681" size="0.01 0.16" name="water"/>
          <joint axis="0 0 1" pos="-0.00689280591905117 1.402873067490873e-06 0.20682460069656372" limited="true" name="spout_joint" range="-1.5707963267948966 1.5707963267948966" type="hinge" damping="2" frictionloss="2" armature=".01"/>
          <geom mesh="spout_vis" type="mesh" solimp="0.998 0.998 0.001" solref="0.001 1" density="100" friction="0.95 0.3 0.1" class="visual" material="material"/>
          <geom class="collision" type="box" pos="-0.0069480412639677525 6.35925680398941e-05 0.25676262378692627" size="0.0042139627039432526 0.012713233008980751 0.04559551179409027" quat="0.7071067690849304 0.0 -0.0 -0.7071067690849304"/>
          <geom class="collision" type="box" pos="-0.00694805383682251 -0.11645355820655823 0.331937313079834" size="0.0042139627039432526 0.012713231146335602 0.08209367841482162" quat="0.4906902015209198 -0.5091395974159241 -0.5091395974159241 -0.4906902015209198"/>
          <geom class="collision" type="box" pos="-0.006948043592274189 -0.0007971804589033127 0.3078439235687256" size="0.004213962238281965 0.012713231146335602 0.007293197326362133" quat="0.705456554889679 0.04828108102083206 0.04828108102083206 -0.705456554889679"/>
          <geom class="collision" type="box" pos="-0.006948044523596764 -0.004064199980348349 0.3165840804576874" size="0.004213962238281965 0.012713231146335602 0.007293197326362133" quat="0.6765242218971252 0.20570605993270874 0.20570604503154755 -0.6765242218971252"/>
          <geom class="collision" type="box" pos="-0.006948044523596764 -0.012494385242462158 0.32479310035705566" size="0.004213961772620678 0.012713231146335602 0.007293203845620155" quat="0.6162595748901367 0.3467335104942322 0.3467335104942322 -0.6162595748901367"/>
          <geom class="collision" type="box" pos="-0.006948046386241913 -0.02353726699948311 0.3284395635128021" size="0.0042139627039432526 0.012713231146335602 0.007293206173926592" quat="0.5158572793006897 0.48362308740615845 0.48362308740615845 -0.5158572793006897"/>
          <geom class="collision" type="box" pos="-0.006948046386241913 -0.0329667404294014 0.32897815108299255" size="0.004213962238281965 0.012713231146335602 0.0072932057082653046" quat="0.5070885419845581 0.4928094744682312 0.4928094744682312 -0.5070886015892029"/>
        </body>
        <body name="handle">
          <joint axis="1 0 0" pos="0.03567527234554291 6.9684588197560515e-06 0.16606798768043518" limited="true" name="handle_joint" range="0.0 1.5707963267948966" type="hinge" damping="2" frictionloss="2" armature=".01"/>
          <joint axis="0 1 0" pos="0.03567527234554291 6.9684588197560515e-06 0.16606798768043518" limited="true" name="handle_joint2" range="0.0 1.04719755" type="hinge" damping="2" frictionloss="2" armature=".01"/>
          <geom mesh="handle_vis" type="mesh" solimp="0.998 0.998 0.001" solref="0.001 1" density="100" friction="0.95 0.3 0.1" class="visual" material="material"/>
          <geom class="collision" type="cylinder" pos="0.04761418700218201 -3.335179243890707e-09 0.16509996354579926" size="0.012384424917399883 0.00699999975040555" quat="0.7071068286895752 1.2101618374060763e-08 0.7071067690849304 -1.2101617485882343e-08"/>
          <geom class="collision" type="box" pos="0.04424170032143593 -3.725290298461914e-09 0.2003302127122879" size="0.0024397713132202625 0.010437444783747196 0.025695916265249252" quat="0.7071067690849304 0.0 -0.0 -0.7071067690849304"/>
        </body>
        <geom class="region" name="reg_main" type="box" pos="-0.007073655724525452 -0.1959095597267151 0.05783206224441528" size="0.20492751896381378 0.22029149532318115 0.05783206224441528"/>
        <geom class="region" name="reg_basin" type="box" pos="-0.004061050713062286 -0.2104230783879757 0.0632351003587246" size="0.17677969485521317 0.17827752605080605 0.04825190082192421"/>
      </body>
    </body>
  </worldbody>
  <actuator>
    <motor name="Funnel_joint_actuator" joint="Funnel_joint" gear="10"/>
    <motor name="spout_joint_actuator" joint="spout_joint" gear="10"/>
    <motor name="handle_joint_actuator" joint="handle_joint" gear="10"/>
    <motor name="handle_joint2_actuator" joint="handle_joint2" gear="10"/>
  </actuator>
</mujoco>
