<mujoco model="model">
  <compiler angle="radian"/>
  <asset>
    <mesh file="visuals/door.obj" name="door_vis"/>
    <mesh file="visuals/door_Clear.obj" name="door_Clear_vis"/>
    <mesh file="visuals/Body001.obj" name="Body001_vis"/>
    <mesh file="visuals/Button001.obj" name="Button001_vis"/>
    <mesh file="visuals/Button002.obj" name="Button002_vis"/>
    <mesh file="visuals/Disc001.obj" name="Disc001_vis"/>
    <texture file="visuals/T_BC001.png" name="Body001_material" type="2d"/>
    <material name="Body001_material" rgba="1 1 1 1.0" texture="Body001_material" shininess="2" specular="2"/>
    <texture file="visuals/T_BC001.png" name="door_material" type="2d"/>
    <material name="door_material" rgba="1 1 1 1.0" texture="door_material" shininess="2" specular="2"/>
    <material name="door_Clear_material" rgba="0.012270155362784863 0.012270155362784863 0.012270155362784863 0.8397825360298157" shininess="1" specular="1"/>
    <texture file="visuals/T_BC001.png" name="Button001_material" type="2d"/>
    <material name="Button001_material" rgba="1 1 1 1.0" texture="Button001_material" shininess="0.141421377658844" specular="0.3103448502657381"/>
    <texture file="visuals/T_BC001.png" name="Button002_material" type="2d"/>
    <material name="Button002_material" rgba="1 1 1 1.0" texture="Button002_material" shininess="0.141421377658844" specular="0.3103448502657381"/>
    <texture file="visuals/T_BC001.png" name="Disc001_material" type="2d"/>
    <material name="Disc001_material" rgba="1 1 1 1.0" texture="Disc001_material" shininess="1" specular="1"/>
  </asset>
  <default>
    <default class="visual">
      <geom conaffinity="0" contype="0" group="1" type="mesh"/>
    </default>
    <default class="collision">
      <geom group="0" rgba="0.5 0 0 0.5"/>
    </default>
    <default class="spawn">
      <geom group="0" rgba="1 1 1 0.5" contype="0" conaffinity="0"/>
      <site group="0" rgba="1 1 1 0.5"/>
    </default>
    <default class="region">
      <geom group="1" conaffinity="0" contype="0" rgba="0 1 0 0"/>
    </default>
  </default>
  <worldbody>
    <body>
      <body name="object">
        <geom class="collision" type="box" pos="-0.053948815912008286 0.00721850385889411 -0.09509222954511642" size="0.13166764378547668 0.13166764378547668 0.0021522443275898695" quat="1.0 0.0 0.0 0.0" name="tray" rgba="0 1 0 0.5"/>
        <geom class="collision" type="box" pos="0.23246632516384125 -0.19946980476379395 -0.05689051374793053" size="0.010617456398904324 0.00027986132772639394 0.007955159060657024" quat="1.0 0.0 0.0 0.0" name="start_button" rgba="0.0 0.5 0 0.5"/>
        <geom class="collision" type="box" pos="0.1815623790025711 -0.19946980476379395 -0.05655767768621445" size="0.01157171931117773 0.0002798614150378853 0.007955159060657024" quat="1.0 0.0 0.0 0.0" name="stop_button" rgba="0.0 0.5 0 0.5"/>
        <geom mesh="Body001_vis" type="mesh" solimp="0.998 0.998 0.001" solref="0.001 1" density="100" friction="0.95 0.3 0.1" class="visual" material="Body001_material"/>
        <geom class="collision" type="box" pos="3.026798367500305e-09 0.028110068291425705 0.1366085708141327" size="0.2709481418132782 0.19487737119197845 0.02329542674124241" quat="1.0 0.0 0.0 0.0"/>
        <geom class="collision" type="box" pos="-0.24649880826473236 0.028110038489103317 -0.021508557721972466" size="0.024449609220027924 0.19487740099430084 0.13776856660842896" quat="1.0 0.0 0.0 0.0"/>
        <geom class="collision" type="box" pos="0.19384488463401794 0.028110068291425705 -0.021508557721972466" size="0.07710346579551697 0.194877490401268 0.13776859641075134" quat="1.0 0.0 0.0 0.0"/>
        <geom class="collision" type="box" pos="-6.868503987789154e-09 0.028110068291425705 -0.13163922727108002" size="0.2709481418132782 0.19487756490707397 0.027739325538277626" quat="1.0 0.0 0.0 0.0"/>
        <geom class="collision" type="box" pos="-6.868503987789154e-09 0.19042719900608063 0.0032751087564975023" size="0.2709481418132782 0.0325612835586071 0.11367622017860413" quat="1.0 0.0 0.0 0.0"/>
        <geom class="collision" type="box" pos="0.21813222765922546 -0.17393672466278076 0.0036033657379448414" size="0.05281614139676094 0.018024178221821785 0.15630051493644714" quat="1.0 0.0 0.0 0.0"/>
        <body name="door">
          <joint axis="0.0 0.0 1.0" pos="-0.2574526071548462 -0.1819857656955719 0.004441767930984497" limited="true" name="microjoint" range="-1.5707963267948966 0.0" type="hinge" damping="1" frictionloss="1" armature=".01" stiffness="0.05"/>
          <geom mesh="door_vis" type="mesh" solimp="0.998 0.998 0.001" solref="0.001 1" density="100" friction="0.95 0.3 0.1" class="visual" material="door_material"/>
          <geom class="collision" type="box" pos="-0.045881107449531555 -0.1879672259092331 0.004935173317790031" size="0.20303361117839813 0.006920710206031799 0.15533727407455444" quat="1.0 0.0 0.0 0.0"/>
          <geom class="collision" type="box" pos="0.14146743714809418 -0.20280475914478302 0.1052076667547226" size="0.014644913375377655 0.0205366313457489 0.02123347856104374" quat="1.0 0.0 0.0 0.0"/>
          <geom class="collision" type="box" pos="0.14146743714809418 -0.20361050963401794 -0.07204311341047287" size="0.014644913375377655 0.020746484398841858 0.02141886204481125" quat="1.0 0.0 0.0 0.0"/>
          <geom class="collision" type="box" pos="0.14146743714809418 -0.21701546013355255 0.016374727711081505" size="0.014644913375377655 0.0065969196148216724 0.06424761563539505" quat="1.0 0.0 0.0 0.0" name="door_handle"/>
          <body name="door_Clear">
            <geom mesh="door_Clear_vis" type="mesh" solimp="0.998 0.998 0.001" solref="0.001 1" density="100" friction="0.95 0.3 0.1" class="visual" material="door_Clear_material"/>
            <geom class="collision" type="box" pos="-0.05269811302423477 -0.18954874575138092 0.020522303879261017" size="0.16385461390018463 0.0018168184906244278 0.08685800433158875" quat="1.0 0.0 0.0 0.0"/>
          </body>
        </body>
        <body name="Button001">
          <joint axis="0.0 1.0 0.0" pos="0.18114350736141205 -0.1946958601474762 -0.05697348341345787" limited="true" name="Button001_joint" range="0.0 0.003" type="slide" damping="1" frictionloss="1" armature=".01" stiffness="0.05"/>
          <geom mesh="Button001_vis" type="mesh" solimp="0.998 0.998 0.001" solref="0.001 1" density="100" friction="0.95 0.3 0.1" class="visual" material="Button001_material"/>
          <geom class="collision" type="box" pos="0.1815623790025711 -0.19658896327018738 -0.05655767768621445" size="0.01157171931117773 0.001951877260580659 0.007955159060657024" quat="1.0 0.0 0.0 0.0"/>
        </body>
        <body name="Button002">
          <joint axis="0.0 1.0 0.0" pos="0.23229819536209106 -0.19503822922706604 -0.05696532875299454" limited="true" name="Button002_joint" range="0.0 0.003" type="slide" damping="1" frictionloss="1" armature=".01" stiffness="0.05"/>
          <geom mesh="Button002_vis" type="mesh" solimp="0.998 0.998 0.001" solref="0.001 1" density="100" friction="0.95 0.3 0.1" class="visual" material="Button002_material"/>
          <geom class="collision" type="box" pos="0.23246632516384125 -0.19658896327018738 -0.05689051374793053" size="0.010617456398904324 0.001951877260580659 0.007955159060657024" quat="1.0 0.0 0.0 0.0"/>
        </body>
        <body name="Disc001">
          <joint axis="0.0 0.0 -1.0" pos="-0.05321287363767624 0.00750887393951416 -0.09866394102573395" limited="false" name="Disc001_joint" range="0 360" type="hinge" damping="1" frictionloss="1" armature=".01" stiffness="0.05"/>
          <geom mesh="Disc001_vis" type="mesh" solimp="0.998 0.998 0.001" solref="0.001 1" density="100" friction="0.95 0.3 0.1" class="visual" material="Disc001_material"/>
          <geom class="collision" type="cylinder" pos="-0.053948815912008286 0.00721850385889411 -0.10085192322731018" size="0.1316681206226349 0.001950909267179668" quat="1.0 0.0 0.0 0.0"/>
        </body>
        <geom class="region" name="reg_main" type="box" pos="-7.450580596923828e-09 0.01356690376996994 0.0" size="0.2709484398365021 0.20942085981369019 0.15990403294563293"/>
        <geom class="region" name="reg_int" type="box" pos="-0.05183784291148186 -0.0012772679328918457 0.004606325179338455" size="0.16899896040558815 0.16266408562660217 0.10769542679190636"/>
      </body>
    </body>
  </worldbody>
  <actuator>
    <motor name="microjoint_actuator" joint="microjoint" gear="10"/>
    <motor name="Button001_joint_actuator" joint="Button001_joint" gear="0.5"/>
    <motor name="Button002_joint_actuator" joint="Button002_joint" gear="0.5"/>
    <motor name="Disc001_joint_actuator" joint="Disc001_joint" gear="10"/>
  </actuator>
</mujoco>
