<?xml version='1.0' encoding='UTF-8'?>
<mujoco model="model">
  <option timestep="0.002" gravity="0.0 0.0 -9.81"/>
  <compiler angle="radian"/>
  <asset>
    <mesh file="visuals/button_lock.obj" name="button_lock_vis"/>
    <mesh file="visuals/button_power.obj" name="button_power_vis"/>
    <mesh file="visuals/Body001.obj" name="Body001_vis"/>
    <mesh file="visuals/door.obj" name="door_vis"/>
    <mesh file="visuals/rack0.obj" name="rack0_vis"/>
    <mesh file="visuals/rack1.obj" name="rack1_vis"/>
    <texture file="visuals/T_BC001.png" name="Body001_material" type="2d"/>
    <material name="Body001_material" rgba="1 1 1 1.0" texture="Body001_material" shininess="0.2512328028678894" specular="1"/>
    <texture file="visuals/T_BC001.png" name="button_lock_material" type="2d"/>
    <material name="button_lock_material" rgba="1 1 1 1.0" texture="button_lock_material" shininess="0.2512328028678894" specular="0.3103448502657381"/>
    <texture file="visuals/T_BC001.png" name="button_power_material" type="2d"/>
    <material name="button_power_material" rgba="1 1 1 1.0" texture="button_power_material" shininess="0.2512328028678894" specular="0.3103448502657381"/>
    <texture file="visuals/T_BC001.png" name="door_material" type="2d"/>
    <material name="door_material" rgba="1 1 1 1.0" texture="door_material" shininess="0.2512328028678894" specular="1"/>
    <texture file="visuals/T_BC001.png" name="rack0_material" type="2d"/>
    <material name="rack0_material" rgba="1 1 1 1.0" texture="rack0_material" shininess="0.2512328028678894" specular="7"/>
    <texture file="visuals/T_BC001.png" name="rack1_material" type="2d"/>
    <material name="rack1_material" rgba="1 1 1 1.0" texture="rack1_material" shininess="0.2512328028678894" specular="7"/>
  </asset>
  <default>
    <default class="visual">
      <geom conaffinity="0" contype="0" group="1" type="mesh"/>
    </default>
    <default class="collision">
      <geom group="0" rgba="0.5 0 0 0.5"/>
    </default>
    <default class="spawn">
      <geom group="0" rgba="1 1 1 0.5" contype="0" conaffinity="0"/>
      <site group="0" rgba="1 1 1 0.5"/>
    </default>
    <default class="region">
      <geom group="1" conaffinity="0" contype="0" rgba="0 1 0 0"/>
    </default>
  </default>
  <worldbody>
    <body>
      <body name="object">
        <geom mesh="Body001_vis" type="mesh" solimp="0.998 0.998 0.001" solref="0.001 1" friction="0.95 0.3 0.1" class="visual" material="Body001_material"/>
        <geom class="collision" type="box" pos="0.002270948840305209 0.30219388008117676 -0.004621784668415785" size="0.2934557795524597 0.031141722574830055 0.3999965190887451" quat="1.0 0.0 0.0 0.0"/>
        <geom class="collision" type="box" pos="0.002270943485200405 0.04500756412744522 0.28445860743522644" size="0.2934557795524597 0.2883281409740448 0.11296357214450836" quat="1.0 0.0 0.0 0.0"/>
        <geom class="collision" type="box" pos="0.283699095249176 0.04893629252910614 -0.004621789325028658" size="0.013583042658865452 0.28229135274887085 0.3999965488910675" quat="1.0 0.0 0.0 0.0"/>
        <geom class="collision" type="box" pos="-0.2821372151374817 0.04735734313726425 -0.0036820757668465376" size="0.013743063434958458 0.2838580310344696 0.40093621611595154" quat="1.0 0.0 0.0 0.0"/>
        <geom class="collision" type="box" pos="0.002834443934261799 0.04775632172822952 -0.35406163334846497" size="0.29289230704307556 0.28347134590148926 0.05055676028132439" quat="1.0 0.0 0.0 0.0"/>
        <geom class="collision" type="box" pos="0.001645534299314022 -0.2566308081150055 0.38181814551353455" size="0.23946069180965424 0.014339210465550423 0.022003211081027985" quat="1.0 0.0 0.0 0.0"/>
        <geom class="collision" type="box" pos="0.001645534299314022 -0.2566308081150055 0.33316099643707275" size="0.18578501045703888 0.014339076355099678 0.02632884308695793" quat="1.0 0.0 0.0 0.0"/>
        <geom class="collision" type="box" pos="0.001645534299314022 -0.24943575263023376 0.33316099643707275" size="0.24276535212993622 0.007144160568714142 0.0263291634619236" quat="1.0 0.0 0.0 0.0"/>
        <geom class="collision" type="box" pos="0.30705559253692627 -0.257473349571228 -0.06499844789505005" size="0.011688482016324997 0.013232498429715633 0.3362135589122772" quat="1.0 0.0 0.0 0.0"/>
        <geom class="collision" type="box" pos="-0.2991386353969574 -0.25582897663116455 -0.06303557008504868" size="0.01549624465405941 0.014965040609240532 0.3371136486530304" quat="1.0 0.0 0.0 0.0"/>
        <geom class="collision" type="box" pos="0.0013974723406136036 -0.25582897663116455 -0.3842719495296478" size="0.31603240966796875 0.014965040609240532 0.020346524193882942" quat="1.0 0.0 0.0 0.0"/>
        <geom class="collision" type="box" pos="0.27595484256744385 -0.2566308379173279 0.33751824498176575" size="0.04174598306417465 0.014339236542582512 0.06630311161279678" quat="1.0 0.0 0.0 0.0"/>
        <geom class="collision" type="box" pos="-0.27554571628570557 -0.2566308379173279 0.33751824498176575" size="0.03830210119485855 0.014339236542582512 0.06630311161279678" quat="1.0 0.0 0.0 0.0"/>
        <geom class="collision" type="box" pos="0.002166450023651123 -0.2566308081150055 0.288998544216156" size="0.23795722424983978 0.014339210465550423 0.01768752932548523" quat="1.0 0.0 0.0 0.0"/>
        <geom class="collision" type="box" pos="0.002166450023651123 -0.25403892993927 0.24915501475334167" size="0.28395089507102966 0.011747335083782673 0.03424625098705292" quat="1.0 0.0 0.0 0.0"/>
        <geom class="collision" type="box" pos="-0.26278406381607056 0.0033570234663784504 -0.12307623773813248" size="0.005532166454941034 0.21645444631576538 0.0021562271285802126" quat="1.0 0.0 0.0 0.0"/>
        <geom class="collision" type="box" pos="-0.26278406381607056 0.0033570234663784504 -0.17768573760986328" size="0.005532166454941034 0.21645456552505493 0.0021562278270721436" quat="1.0 0.0 0.0 0.0"/>
        <geom class="collision" type="box" pos="-0.26278406381607056 0.0033570234663784504 -0.2356557995080948" size="0.005532166454941034 0.21645468473434448 0.002156228758394718" quat="1.0 0.0 0.0 0.0"/>
        <geom class="collision" type="box" pos="-0.26278406381607056 0.0033570234663784504 -0.06762661039829254" size="0.005532166454941034 0.21645481884479523 0.002156229689717293" quat="1.0 0.0 0.0 0.0"/>
        <geom class="collision" type="box" pos="-0.26278406381607056 0.0033570234663784504 0.03683154284954071" size="0.005532166454941034 0.21645493805408478 0.0021562303882092237" quat="1.0 0.0 0.0 0.0"/>
        <geom class="collision" type="box" pos="-0.26278406381607056 0.0033570234663784504 0.04747339338064194" size="0.005532166454941034 0.21645505726337433 0.0021562313195317984" quat="1.0 0.0 0.0 0.0"/>
        <geom class="collision" type="box" pos="-0.26278406381607056 0.0033570234663784504 0.10068264603614807" size="0.005532166454941034 0.21645517647266388 0.002156232250854373" quat="1.0 0.0 0.0 0.0"/>
        <geom class="collision" type="box" pos="-0.27026477456092834 -0.20971053838729858 -0.0668596625328064" size="0.005532166454941034 0.0021562387701123953 0.16745783388614655" quat="1.0 0.0 0.0 0.0"/>
        <geom class="collision" type="box" pos="-0.27026477456092834 0.2217143476009369 -0.0668596625328064" size="0.005532166454941034 0.002156240167096257 0.16745789349079132" quat="1.0 0.0 0.0 0.0"/>
        <geom class="collision" type="box" pos="0.26350605487823486 0.008646785281598568 -0.12307623773813248" size="0.005532199516892433 0.21645554900169373 0.002156234811991453" quat="1.0 0.0 0.0 0.0"/>
        <geom class="collision" type="box" pos="0.26350605487823486 0.008646785281598568 -0.17768573760986328" size="0.005532199516892433 0.21645566821098328 0.002156235510483384" quat="1.0 0.0 0.0 0.0"/>
        <geom class="collision" type="box" pos="0.26350605487823486 0.008646785281598568 -0.23565581440925598" size="0.005532199516892433 0.21645578742027283 0.0021562364418059587" quat="1.0 0.0 0.0 0.0"/>
        <geom class="collision" type="box" pos="0.26350605487823486 0.008646785281598568 -0.06762661039829254" size="0.005532199516892433 0.21645590662956238 0.0021562373731285334" quat="1.0 0.0 0.0 0.0"/>
        <geom class="collision" type="box" pos="0.26350605487823486 0.008646785281598568 0.03683154284954071" size="0.005532199516892433 0.21645602583885193 0.0021562380716204643" quat="1.0 0.0 0.0 0.0"/>
        <geom class="collision" type="box" pos="0.26350605487823486 0.008646785281598568 0.04747339338064194" size="0.005532199516892433 0.21645614504814148 0.002156239002943039" quat="1.0 0.0 0.0 0.0"/>
        <geom class="collision" type="box" pos="0.26350605487823486 0.008646785281598568 0.10068265348672867" size="0.005532199516892433 0.21645627915859222 0.0021562399342656136" quat="1.0 0.0 0.0 0.0"/>
        <geom class="collision" type="box" pos="0.27098673582077026 0.2217143476009369 -0.0668596625328064" size="0.005532166920602322 0.002156252972781658 0.16745832562446594" quat="1.0 0.0 0.0 0.0"/>
        <geom class="collision" type="box" pos="0.27098679542541504 -0.20971053838729858 -0.0668596625328064" size="0.005532166920602322 0.00215625436976552 0.16745838522911072" quat="1.0 0.0 0.0 0.0"/>
        <body name="button_lock">
          <joint axis="0.0 1.0 0.0" pos="-0.21002115309238434 -0.2743443250656128 0.3323754668235779" limited="true" name="button_lock_joint" range="0.0 0.004" type="slide" damping="1" frictionloss="1" armature=".01" stiffness="0.05"/>
          <geom mesh="button_lock_vis" type="mesh" solimp="0.998 0.998 0.001" solref="0.001 1" friction="0.95 0.3 0.1" class="visual" material="button_lock_material"/>
          <geom class="collision" type="box" pos="-0.21002115309238434 -0.27553072571754456 0.3323754668235779" size="0.016192251816391945 0.0023901311215013266 0.02115476503968239" quat="1.0 0.0 0.0 0.0"/>
        </body>
        <body name="button_power">
          <joint axis="0.0 1.0 0.0" pos="0.2092234045267105 -0.2743443250656128 0.3323754668235779" limited="true" name="button_power_joint" range="0.0 0.004" type="slide" damping="1" frictionloss="1" armature=".01" stiffness="0.05"/>
          <geom mesh="button_power_vis" type="mesh" solimp="0.998 0.998 0.001" solref="0.001 1" friction="0.95 0.3 0.1" class="visual" material="button_power_material"/>
          <geom class="collision" type="box" pos="0.2092234045267105 -0.27553072571754456 0.3323754668235779" size="0.016192251816391945 0.0023901311215013266 0.021154770627617836" quat="1.0 0.0 0.0 0.0"/>
        </body>
        <body name="door">
          <joint axis="1.0 0.0 0.0" pos="0.00013502946239896119 -0.26235145330429077 -0.36066174507141113" limited="true" name="door_joint" range="0.0 0.5235987755982988" type="hinge" damping="1" frictionloss="1" armature=".01" stiffness="2" springref="-2"/>
          <geom mesh="door_vis" type="mesh" solimp="0.998 0.998 0.001" solref="0.001 1" friction="0.95 0.3 0.1" class="visual" material="door_material"/>
          <geom class="collision" type="box" pos="-0.12108007073402405 -0.2888696491718292 0.23808304965496063" size="0.010053523816168308 0.01570415496826172 0.01735311932861805" quat="1.0 0.0 0.0 0.0"/>
          <geom class="collision" type="box" pos="-0.11625811457633972 -0.3146785795688629 0.23808304965496063" size="0.01003683265298605 0.015267157927155495 0.01735311932861805" quat="0.9445226192474365 0.0 0.0 0.3284463584423065"/>
          <geom class="collision" type="box" pos="0.1170012503862381 -0.28709566593170166 0.23808304965496063" size="0.010053527541458607 0.015349476598203182 0.01735311932861805" quat="1.0 0.0 0.0 0.0"/>
          <geom class="collision" type="box" pos="0.11414425075054169 -0.3152996897697449 0.23808304965496063" size="0.00786184798926115 0.015053094364702702 0.01735311932861805" quat="0.9742051362991333 0.0 0.0 -0.2256641983985901"/>
          <geom class="collision" type="box" pos="0.0012862393632531166 -0.3255290985107422 0.23808304965496063" size="0.11001329869031906 0.00799134187400341 0.01735311932861805" quat="1.0 0.0 0.0 0.0" name="door_handle_main"/>
          <geom class="collision" type="box" pos="0.006062620785087347 -0.26658323407173157 -0.041804518550634384" size="0.2794951796531677 0.00455561513081193 0.2976440489292145" quat="1.0 0.0 0.0 0.0" name="door_main"/>
        </body>
        <body name="rack0">
          <geom class="region" name="reg_rack0" type="box" pos="0.000350266695022583 0.009881153702735901 -0.17115172743797302" size="0.22662316262722015 0.18598924577236176 0.06369508802890778"/>
          <joint axis="0.0 -1.0 0.0" pos="0.0014886088902130723 0.00591316819190979 -0.1771361082792282" limited="true" name="rack0_joint" range="0.0 0.14400000000000002" type="slide" damping="1" frictionloss="1" armature=".01" stiffness="0.05"/>
          <geom mesh="rack0_vis" type="mesh" solimp="0.998 0.998 0.001" solref="0.001 1" friction="0.95 0.3 0.1" class="visual" material="rack0_material"/>
          <geom class="collision" type="box" pos="-0.0963621512055397 0.005913173779845238 -0.23199830949306488" size="0.0024885283783078194 0.19438549876213074 0.014615296386182308" quat="0.15898919105529785 -1.2307309314266179e-15 0.9872803092002869 1.3264960330161557e-07"/>
          <geom class="collision" type="box" pos="0.013931304216384888 0.005913173779845238 -0.23316852748394012" size="0.0024885283783078194 0.19438549876213074 0.014615296386182308" quat="0.24899983406066895 -2.6311786781210277e-15 0.9685035347938538 1.301269634268465e-07"/>
          <geom class="collision" type="box" pos="0.14883191883563995 0.005913173779845238 -0.23479384183883667" size="0.0024885283783078194 0.19438549876213074 0.014615295454859734" quat="0.2927439510822296 -1.3194538845307142e-14 0.9561908841133118 1.2847267782944982e-07"/>
          <geom class="collision" type="box" pos="0.19459091126918793 0.005913173779845238 -0.23428140580654144" size="0.0024885283783078194 0.19438549876213074 0.04257377237081528" quat="0.7895917296409607 -1.2440509268628417e-14 0.6136325597763062 8.244701632520446e-08"/>
          <geom class="collision" type="box" pos="0.0831272304058075 0.005913173779845238 -0.23486652970314026" size="0.0024885288439691067 0.19438549876213074 0.0634777694940567" quat="0.7705856561660767 3.3243539350339205e-14 0.6373364329338074 8.563171860487273e-08"/>
          <geom class="collision" type="box" pos="-0.041501447558403015 0.005913173779845238 -0.23223352432250977" size="0.0024885288439691067 0.19438549876213074 0.05279025435447693" quat="0.7867818474769592 5.065194344142619e-14 0.6172311902046204 8.293049802432506e-08"/>
          <geom class="collision" type="box" pos="-0.1626194566488266 0.005913173779845238 -0.22843030095100403" size="0.0024885288439691067 0.19438549876213074 0.06428566575050354" quat="0.7540631294250488 2.1524044008171435e-14 0.6568019390106201 8.824712693922265e-08"/>
          <geom class="collision" type="box" pos="0.23054438829421997 0.00591316819190979 -0.17874950170516968" size="0.002488528611138463 0.19438549876213074 0.04923447594046593" quat="1.0 0.0 0.0 0.0"/>
          <geom class="collision" type="box" pos="0.0016956562176346779 -0.1869753748178482 -0.17325755953788757" size="0.2274533212184906 0.0024885728489607573 0.06267448514699936" quat="1.0 0.0 0.0 0.0"/>
          <geom class="collision" type="box" pos="0.0016956562176346779 0.19985394179821014 -0.17325755953788757" size="0.2274533212184906 0.0024885728489607573 0.06267448514699936" quat="1.0 0.0 0.0 0.0"/>
          <geom class="collision" type="box" pos="-0.23920971155166626 0.005913160741329193 -0.12186144292354584" size="0.0024885283783078194 0.19438549876213074 0.01963345892727375" quat="1.6715887340978952e-07 0.426746666431427 6.416874498427205e-08 -0.9043712019920349"/>
          <geom class="collision" type="box" pos="0.24237048625946045 0.005913160741329193 -0.12186144292354584" size="0.0024885283783078194 0.19438549876213074 0.01963345892727375" quat="0.8787773847579956 2.109912484798363e-15 0.4772319495677948 6.412033570768472e-08"/>
          <geom class="collision" type="box" pos="0.15735438466072083 0.0059131719172000885 -0.20215296745300293" size="0.002488528611138463 0.19438549876213074 0.040634509176015854" quat="1.0 0.0 0.0 0.0"/>
          <geom class="collision" type="box" pos="0.0320236012339592 0.0059131719172000885 -0.20215296745300293" size="0.002488528611138463 0.19438549876213074 0.040634509176015854" quat="1.0 0.0 0.0 0.0"/>
          <geom class="collision" type="box" pos="-0.07470064610242844 0.0059131719172000885 -0.20109976828098297" size="0.002488528611138463 0.19438549876213074 0.040634509176015854" quat="1.0 0.0 0.0 0.0"/>
          <geom class="collision" type="box" pos="-0.1803717017173767 0.0059131719172000885 -0.200046569108963" size="0.002488528611138463 0.19438549876213074 0.040634509176015854" quat="1.0 0.0 0.0 0.0"/>
          <geom class="collision" type="box" pos="-0.22895154356956482 0.00591316819190979 -0.18423491716384888" size="0.002488528611138463 0.1943827122449875 0.055606160312891006" quat="1.0 0.0 0.0 0.0"/>
        </body>
        <body name="rack1">
          <geom class="region" name="reg_rack1" type="box" pos="0.000350266695022583 0.009881153702735901 0.05519571527838707" size="0.22662316262722015 0.18598924577236176 0.06369509175419807"/>
          <joint axis="0.0 -1.0 0.0" pos="0.0014886088902130723 0.00591316819190979 0.04921133443713188" limited="true" name="rack1_joint" range="0.0 0.27399999999999997" type="slide" damping="1" frictionloss="1" armature=".01" stiffness="0.05"/>
          <geom mesh="rack1_vis" type="mesh" solimp="0.998 0.998 0.001" solref="0.001 1" friction="0.95 0.3 0.1" class="visual" material="rack1_material"/>
          <geom class="collision" type="box" pos="-0.22895154356956482 0.00591316819190979 0.040915489196777344" size="0.002488528611138463 0.19438277184963226 0.05560619384050369" quat="1.0 0.0 0.0 0.0"/>
          <geom class="collision" type="box" pos="0.23054438829421997 0.00591316819190979 0.04640090465545654" size="0.002488528611138463 0.19438549876213074 0.04923447594046593" quat="1.0 0.0 0.0 0.0"/>
          <geom class="collision" type="box" pos="-0.1626194566488266 0.005913173779845238 -0.003279894357547164" size="0.0024885288439691067 0.19438549876213074 0.06428566575050354" quat="0.7540631294250488 2.1524044008171435e-14 0.6568019390106201 8.824712693922265e-08"/>
          <geom class="collision" type="box" pos="-0.041501447558403015 0.005913173779845238 -0.007083116099238396" size="0.0024885288439691067 0.19438549876213074 0.05279025435447693" quat="0.7867818474769592 5.065194344142619e-14 0.6172311902046204 8.293049802432506e-08"/>
          <geom class="collision" type="box" pos="0.0831272304058075 0.005913173779845238 -0.009716115891933441" size="0.0024885288439691067 0.19438549876213074 0.0634777694940567" quat="0.7705856561660767 3.3243539350339205e-14 0.6373364329338074 8.563171860487273e-08"/>
          <geom class="collision" type="box" pos="0.19459091126918793 0.005913173779845238 -0.00913100503385067" size="0.0024885283783078194 0.19438549876213074 0.04257377237081528" quat="0.7895917296409607 -1.2440509268628417e-14 0.6136325597763062 8.244701632520446e-08"/>
          <geom class="collision" type="box" pos="0.14883191883563995 0.005913173779845238 -0.009643428027629852" size="0.0024885283783078194 0.19438549876213074 0.014615295454859734" quat="0.2927439510822296 -1.3194538845307142e-14 0.9561908841133118 1.2847267782944982e-07"/>
          <geom class="collision" type="box" pos="0.013931304216384888 0.005913173779845238 -0.008018119260668755" size="0.0024885283783078194 0.19438549876213074 0.014615296386182308" quat="0.24899983406066895 -2.6311786781210277e-15 0.9685035347938538 1.301269634268465e-07"/>
          <geom class="collision" type="box" pos="-0.0963621512055397 0.005913173779845238 -0.006847897078841925" size="0.0024885283783078194 0.19438549876213074 0.014615296386182308" quat="0.15898919105529785 -1.2307309314266179e-15 0.9872803092002869 1.3264960330161557e-07"/>
          <geom class="collision" type="box" pos="-0.1803717017173767 0.0059131719172000885 0.025103837251663208" size="0.002488528611138463 0.19438549876213074 0.040634509176015854" quat="1.0 0.0 0.0 0.0"/>
          <geom class="collision" type="box" pos="-0.07470064610242844 0.0059131719172000885 0.02405063807964325" size="0.002488528611138463 0.19438549876213074 0.040634509176015854" quat="1.0 0.0 0.0 0.0"/>
          <geom class="collision" type="box" pos="0.0320236012339592 0.0059131719172000885 0.02299743890762329" size="0.002488528611138463 0.19438549876213074 0.040634509176015854" quat="1.0 0.0 0.0 0.0"/>
          <geom class="collision" type="box" pos="0.15735438466072083 0.0059131719172000885 0.02299743890762329" size="0.002488528611138463 0.19438549876213074 0.040634509176015854" quat="1.0 0.0 0.0 0.0"/>
          <geom class="collision" type="box" pos="0.24237048625946045 0.005913160741329193 0.10328896343708038" size="0.0024885283783078194 0.19438549876213074 0.01963345892727375" quat="0.8787773847579956 2.109912484798363e-15 0.4772319495677948 6.412033570768472e-08"/>
          <geom class="collision" type="box" pos="-0.23920971155166626 0.005913160741329193 0.10328896343708038" size="0.0024885283783078194 0.19438549876213074 0.01963345892727375" quat="1.6715887340978952e-07 0.426746666431427 6.416874498427205e-08 -0.9043712019920349"/>
          <geom class="collision" type="box" pos="0.0016956562176346779 0.19985394179821014 0.05189284682273865" size="0.2274533212184906 0.0024885728489607573 0.06267448514699936" quat="1.0 0.0 0.0 0.0"/>
          <geom class="collision" type="box" pos="0.0016956562176346779 -0.1869753748178482 0.05189284682273865" size="0.2274533212184906 0.0024885728489607573 0.06267448514699936" quat="1.0 0.0 0.0 0.0"/>
        </body>
        <geom class="region" name="reg_int" type="box" pos="0.0007773041725158691 0.014173552393913269 -0.06600489467382431" size="0.26933857798576355 0.25687839090824127 0.23663697391748428"/>
        <geom class="region" name="reg_main" type="box" pos="0.0 0.03109842538833618 0.0" size="0.31874412298202515 0.3022373914718628 0.404618501663208"/>
      </body>
    </body>
  </worldbody>
  <actuator>
    <motor name="button_lock_joint_actuator" joint="button_lock_joint" gear="0.5"/>
    <motor name="button_power_joint_actuator" joint="button_power_joint" gear="0.5"/>
    <motor name="door_joint_actuator" joint="door_joint" gear="0.5"/>
    <motor name="rack0_joint_actuator" joint="rack0_joint" gear="0.5"/>
    <motor name="rack1_joint_actuator" joint="rack1_joint" gear="0.5"/>
  </actuator>
</mujoco>
