<mujoco model="model">
  <compiler angle="radian"/>
  <asset>
    <mesh file="visuals/Body001.obj" name="Body001_vis"/>
    <mesh file="visuals/Button001.obj" name="Button001_vis"/>
    <mesh file="visuals/Button002.obj" name="Button002_vis"/>
    <mesh file="visuals/Button003.obj" name="Button003_vis"/>
    <mesh file="visuals/Container001_Clear.obj" name="Container001_Clear_vis"/>
    <mesh file="visuals/Lid001.obj" name="Lid001_vis"/>
    <mesh file="visuals/Lid002.obj" name="Lid002_vis"/>
    <mesh file="visuals/Lid003.obj" name="Lid003_vis"/>
    <texture file="visuals/T_BC001.png" name="Body001_material" type="2d"/>
    <material name="Body001_material" rgba="1 1 1 1.0" texture="Body001_material" shininess="0.4472135901451111" specular="0.3103448502657381"/>
    <texture file="visuals/T_BC001.png" name="Button001_material" type="2d"/>
    <material name="Button001_material" rgba="1 1 1 1.0" texture="Button001_material" shininess="0.4472135901451111" specular="0.3103448502657381"/>
    <texture file="visuals/T_BC001.png" name="Button002_material" type="2d"/>
    <material name="Button002_material" rgba="1 1 1 1.0" texture="Button002_material" shininess="0.4472135901451111" specular="0.3103448502657381"/>
    <texture file="visuals/T_BC001.png" name="Button003_material" type="2d"/>
    <material name="Button003_material" rgba="1 1 1 1.0" texture="Button003_material" shininess="0.4472135901451111" specular="0.3103448502657381"/>
    <texture file="visuals/T_BC001.png" name="Container001_Clear_material" type="2d"/>
    <material name="Container001_Clear_material" rgba="1 1 1 0.15000000596046448" texture="Container001_Clear_material" shininess="0.5" specular="0.3103448502657381"/>
    <texture file="visuals/T_BC001.png" name="Lid003_material" type="2d"/>
    <material name="Lid003_material" rgba="1 1 1 1.0" texture="Lid003_material" shininess="0.4472135901451111" specular="0.3103448502657381"/>
    <texture file="visuals/T_BC001.png" name="Lid001_material" type="2d"/>
    <material name="Lid001_material" rgba="1 1 1 1.0" texture="Lid001_material" shininess="0.4472135901451111" specular="0.3103448502657381"/>
    <texture file="visuals/T_BC001.png" name="Lid002_material" type="2d"/>
    <material name="Lid002_material" rgba="1 1 1 1.0" texture="Lid002_material" shininess="0.4472135901451111" specular="0.3103448502657381"/>
  </asset>
  <default>
    <default class="visual">
      <geom conaffinity="0" contype="0" group="1" type="mesh"/>
    </default>
    <default class="collision">
      <geom group="0" rgba="0.5 0 0 0.5"/>
    </default>
    <default class="spawn">
      <geom group="0" rgba="1 1 1 0.5" contype="0" conaffinity="0"/>
      <site group="0" rgba="1 1 1 0.5"/>
    </default>
    <default class="region">
      <geom group="1" conaffinity="0" contype="0" rgba="0 1 0 0"/>
    </default>
  </default>
  <worldbody>
    <body>
      <body name="object">
        <geom class="collision" type="box" pos="-0.002345 -0.180171 0.143757" size="0.006886770483106375 0.006886770483106375 0.0004488315898925066" quat="0.8026814460754395 0.5964080095291138 -1.3242920731979598e-16 1.205506075352994e-23" name="start_button_2" rgba="0.0 0.5 0 0.5"/>
        <geom class="collision" type="box" pos="0.014958 -0.180171 0.143757" size="0.006886770483106375 0.006886770483106375 0.0004488315898925066" quat="0.8026814460754395 0.5964080095291138 -1.3242920731979598e-16 1.205506075352994e-23" name="start_button_1" rgba="0.0 0.5 0 0.5"/>
        <site type="cylinder" rgba="0.8 0.5 0.25 1" size="0.002954429015517235 0.08485784381628036" pos="0.000287 -0.174561 -0.030164" name="coffee_liquid"/>
        <site rgba="0 0 0 0" size="0.011842739768326283 0.006940845865756273" pos="0.000326 -0.177109 -0.106821" name="receptacle_place_site"/>
        <geom mesh="Body001_vis" type="mesh" solimp="0.998 0.998 0.001" solref="0.001 1" density="100" friction="0.95 0.3 0.1" class="visual" material="Body001_material"/>
        <geom class="collision" type="box" pos="-0.000987 -0.060439 -0.144547" size="0.07204368710517883 0.22021633386611938 0.02972189337015152" quat="1.0 0.0 0.0 0.0"/>
        <geom class="collision" type="box" pos="-0.000987 0.220421 -0.159049" size="0.07204368710517883 0.060235217213630676 0.015220314264297485" quat="1.0 0.0 0.0 0.0"/>
        <geom class="collision" type="box" pos="-0.000987 0.007769 0.006619" size="0.07204368710517883 0.15399298071861267 0.12361911684274673" quat="1.0 0.0 0.0 0.0"/>
        <geom class="collision" type="box" pos="-0.068700 -0.161358 0.023754" size="0.005422599148005247 0.011838828213512897 0.14075365662574768" quat="1.0 0.0 0.0 0.0"/>
        <geom class="collision" type="box" pos="0.068772 -0.161358 0.023754" size="0.005422599148005247 0.011838828213512897 0.14075365662574768" quat="1.0 0.0 0.0 0.0"/>
        <geom class="collision" type="box" pos="-0.000987 -0.177655 0.100585" size="0.04579400271177292 0.004848794545978308 0.05061911791563034" quat="0.9943464398384094 -0.1061844751238823 2.357771629783386e-17 4.667787006084069e-24"/>
        <geom class="collision" type="box" pos="0.055757 -0.004822 0.168472" size="0.015515233390033245 0.16779345273971558 0.005796937737613916" quat="1.0 0.0 0.0 0.0"/>
        <geom class="collision" type="box" pos="-0.057604 -0.004822 0.168472" size="0.015655258670449257 0.16779345273971558 0.005796937737613916" quat="1.0 0.0 0.0 0.0"/>
        <geom class="collision" type="box" pos="-0.000621 0.037624 0.168472" size="0.041449788957834244 0.03292513266205788 0.005796937737613916" quat="1.0 0.0 0.0 0.0"/>
        <geom class="collision" type="box" pos="-0.000621 0.112773 0.168472" size="0.041449788957834244 0.04893093183636665 0.005796937737613916" quat="1.0 0.0 0.0 0.0"/>
        <geom class="collision" type="box" pos="0.000287 -0.175069 0.046558" size="0.010950170457363129 0.010950170457363129 0.004562229849398136" quat="1.0 0.0 0.0 0.0"/>
        <geom class="collision" type="box" pos="0.000287 -0.175069 0.040764" size="0.004728950560092926 0.004728950560092926 0.0029425860848277807" quat="1.0 0.0 0.0 0.0"/>
        <geom class="collision" type="box" pos="-0.046233 -0.003979 0.094371" size="0.02678225189447403 0.16590256989002228 0.06799963861703873" quat="1.0 0.0 0.0 0.0"/>
        <geom class="collision" type="box" pos="0.046681 -0.003979 0.094371" size="0.026612915098667145 0.16590256989002228 0.06799963861703873" quat="1.0 0.0 0.0 0.0"/>
        <geom class="collision" type="box" pos="-0.000935 0.040558 0.094371" size="0.026612915098667145 0.1207849532365799 0.06799963861703873" quat="1.0 0.0 0.0 0.0"/>
        <geom class="collision" type="box" pos="-0.000935 -0.145791 0.094371" size="0.026612915098667145 0.024870222434401512 0.06799963861703873" quat="1.0 0.0 0.0 0.0"/>
        <body name="Button001">
          <joint axis="-7.115342281912752e-18 0.9679552912712097 -0.25112250447273254" pos="0.014938 -0.178943 0.143396" limited="true" name="Button001_joint" range="0.0 0.0015" type="slide" damping="1" frictionloss="1" armature=".01" stiffness="0.2" springref="-0.1"/>
          <geom mesh="Button001_vis" type="mesh" solimp="0.998 0.998 0.001" solref="0.001 1" density="100" friction="0.95 0.3 0.1" class="visual" material="Button001_material"/>
          <geom class="collision" type="cylinder" pos="0.014952 -0.178709 0.143249" size="0.006886770483106375 0.0004474426677916199" quat="0.8026814460754395 0.5964080095291138 -1.3242920731979598e-16 1.205506075352994e-23"/>
        </body>
        <body name="Button002">
          <joint axis="-7.115342281912752e-18 0.9679552912712097 -0.25112250447273254" pos="-0.002403 -0.178943 0.143396" limited="true" name="Button002_joint" range="0.0 0.0015" type="slide" damping="1" frictionloss="1" armature=".01" stiffness="0.2" springref="-0.1"/>
          <geom mesh="Button002_vis" type="mesh" solimp="0.998 0.998 0.001" solref="0.001 1" density="100" friction="0.95 0.3 0.1" class="visual" material="Button002_material"/>
          <geom class="collision" type="cylinder" pos="-0.002322 -0.178709 0.143249" size="0.006886770483106375 0.0004474426677916199" quat="0.8026814460754395 0.5964080095291138 -1.3242920731979598e-16 1.205506075352994e-23"/>
        </body>
        <body name="Button003">
          <joint axis="-7.115342281912752e-18 0.9679552912712097 -0.25112250447273254" pos="-0.019281 -0.178958 0.143441" limited="true" name="Button003_joint" range="0.0 0.0015" type="slide" damping="1" frictionloss="1" armature=".01" stiffness="0.2" springref="-0.1"/>
          <geom mesh="Button003_vis" type="mesh" solimp="0.998 0.998 0.001" solref="0.001 1" density="100" friction="0.95 0.3 0.1" class="visual" material="Button003_material"/>
          <geom class="collision" type="cylinder" pos="-0.019272 -0.178657 0.143377" size="0.006886770483106375 0.0003383855218999088" quat="0.8026814460754395 0.5964080095291138 -1.3242920731979598e-16 1.205506075352994e-23"/>
        </body>
        <body name="Container001_Clear">
          <joint axis="0.0 0.0 1.0" pos="0.000447 0.226249 -0.025718" limited="true" name="Container001_Clear_joint" range="0.0 0.1" type="slide" damping="1" frictionloss="1" armature=".01" stiffness="0.05"/>
          <geom mesh="Container001_Clear_vis" type="mesh" solimp="0.998 0.998 0.001" solref="0.001 1" density="100" friction="0.95 0.3 0.1" class="visual" material="Container001_Clear_material"/>
          <geom class="collision" type="box" pos="-0.000987 0.166352 -0.015475" size="0.053464215248823166 0.00262853573076427 0.12245668470859528" quat="1.0 0.0 0.0 0.0"/>
          <geom class="collision" type="box" pos="-0.058148 0.170025 -0.015475" size="0.0067219240590929985 0.0022378561552613974 0.12245668470859528" quat="0.9318532943725586 0.0 -0.0 -0.36283522844314575"/>
          <geom class="collision" type="box" pos="-0.064977 0.182156 -0.015475" size="0.008961043320596218 0.0022378559224307537 0.12245668470859528" quat="0.7958449721336365 0.0 -0.0 -0.6055004596710205"/>
          <geom class="collision" type="box" pos="-0.067658 0.198329 -0.015475" size="0.0025004015769809484 0.009022975340485573 0.12245668470859528" quat="1.0 0.0 0.0 0.0"/>
          <geom class="collision" type="box" pos="-0.066108 0.219773 -0.015475" size="0.01506042294204235 0.0022378559224307537 0.12245668470859528" quat="0.6587887406349182 0.0 -0.0 -0.7523279786109924"/>
          <geom class="collision" type="box" pos="-0.057065 0.246178 -0.015475" size="0.0150604248046875 0.0022378559224307537 0.12245668470859528" quat="0.49419552087783813 0.0 -0.0 -0.869350790977478"/>
          <geom class="collision" type="box" pos="-0.038980 0.264729 -0.015475" size="0.0150604248046875 0.0022378561552613974 0.12245668470859528" quat="0.28371185064315796 0.0 -0.0 -0.9589095711708069"/>
          <geom class="collision" type="box" pos="-0.014125 0.274340 -0.015475" size="0.01506042294204235 0.0022378561552613974 0.12245668470859528" quat="0.06460487097501755 0.0 -0.0 -0.9979109168052673"/>
          <geom class="collision" type="box" pos="0.014243 0.274443 -0.015475" size="0.0150604248046875 0.0022378559224307537 0.12245668470859528" quat="0.07452089339494705 0.0 0.0 0.997219443321228"/>
          <geom class="collision" type="box" pos="0.040441 0.264470 -0.015475" size="0.01506042294204235 0.0022378559224307537 0.12245668470859528" quat="0.28778699040412903 0.0 0.0 0.9576944708824158"/>
          <geom class="collision" type="box" pos="0.058969 0.243636 -0.015475" size="0.01506042294204235 0.0022378559224307537 0.12245668470859528" quat="0.5296655297279358 0.0 0.0 0.848206639289856"/>
          <geom class="collision" type="box" pos="0.067676 0.215879 -0.015475" size="0.0150604248046875 0.0022378559224307537 0.12245668470859528" quat="0.6550995111465454 0.0 0.0 0.7555425763130188"/>
          <geom class="collision" type="box" pos="0.067315 0.188826 -0.015475" size="0.013179861009120941 0.0022378559224307537 0.12245668470859528" quat="0.7724838852882385 0.0 0.0 0.6350343823432922"/>
          <geom class="collision" type="box" pos="0.058315 0.171128 -0.015475" size="0.009633473120629787 0.00223785568960011 0.12245668470859528" quat="0.9465205669403076 0.0 0.0 0.3226434290409088"/>
          <geom class="collision" type="box" pos="-0.000987 0.207652 -0.136652" size="0.05588669702410698 0.04090724140405655 0.0026285392232239246" quat="1.0 0.0 0.0 0.0"/>
          <geom class="collision" type="box" pos="-0.000987 0.260146 -0.136652" size="0.028341200202703476 0.014146403409540653 0.0026285378262400627" quat="1.0 0.0 0.0 0.0"/>
          <geom class="collision" type="box" pos="0.034015 0.250859 -0.136652" size="0.019269196316599846 0.002628537593409419 0.014146402478218079" quat="0.6696438789367676 -0.6696439385414124 0.2271057814359665 -0.2271057665348053"/>
          <geom class="collision" type="box" pos="-0.035045 0.249391 -0.136652" size="0.019269196316599846 0.002628537593409419 0.014146402478218079" quat="0.26227328181266785 -0.26227331161499023 0.6566678881645203 -0.6566678881645203"/>
          <geom class="collision" type="box" pos="-0.058404 0.223354 -0.136652" size="0.019269192591309547 0.002628537593409419 0.005380535498261452" quat="0.4561922252178192 -0.4561922252178192 0.5402672290802002 -0.5402671694755554"/>
          <geom class="collision" type="box" pos="-0.059176 0.189690 -0.136652" size="0.019269192591309547 0.002628537593409419 0.005918747745454311" quat="0.538727343082428 -0.5387275218963623 0.45800960063934326 -0.4580094814300537"/>
          <geom class="collision" type="box" pos="0.060357 0.197745 -0.136652" size="0.022040346637368202 0.002628537593409419 0.007578243967145681" quat="0.5118736028671265 -0.5118741393089294 -0.4878375232219696 0.48783692717552185"/>
          <geom class="collision" type="box" pos="0.057925 0.228050 -0.136652" size="0.019269192591309547 0.002628537593409419 0.005918747745454311" quat="0.43583834171295166 -0.43583834171295166 -0.556816816329956 0.5568167567253113"/>
          <geom class="collision" type="box" pos="0.055913 0.175525 -0.136652" size="0.005416189786046743 0.002628537593409419 0.007578244898468256" quat="0.3460458517074585 -0.3460458815097809 -0.6166459918022156 0.6166459321975708"/>
          <body name="Lid003">
            <joint axis="1.0 0.0 0.0" pos="0.000449 0.170078 0.126625" limited="true" name="Lid003_joint" range="0.0 1.5707963267948966" type="hinge" damping="1" frictionloss="1" armature=".01" stiffness="0.05"/>
            <geom mesh="Lid003_vis" type="mesh" solimp="0.998 0.998 0.001" solref="0.001 1" density="100" friction="0.95 0.3 0.1" class="visual" material="Lid003_material"/>
            <geom class="collision" type="box" pos="-0.003020 0.236377 0.126740" size="0.07117515802383423 0.04168156906962395 0.003936311695724726" quat="1.0 0.0 0.0 0.0"/>
          </body>
        </body>
        <body name="Lid001">
          <joint axis="-1.0 0.0 0.0" pos="0.000165 -0.003247 0.167148" limited="true" name="Lid001_joint" range="0.0 1.5707963267948966" type="hinge" damping="1" frictionloss="1" armature=".01" stiffness="0.05"/>
          <geom mesh="Lid001_vis" type="mesh" solimp="0.998 0.998 0.001" solref="0.001 1" density="100" friction="0.95 0.3 0.1" class="visual" material="Lid001_material"/>
          <geom class="collision" type="box" pos="0.001021 -0.085551 0.167662" size="0.03528226166963577 0.08336244523525238 0.00374074699357152" quat="1.0 0.0 0.0 0.0"/>
          <geom class="collision" type="cylinder" pos="0.000288 -0.169137 0.167690" size="0.03453980013728142 0.003827712731435895" quat="1.0 0.0 0.0 0.0"/>
        </body>
        <body name="Lid002">
          <joint axis="0.0 0.0 1.0" pos="0.000265 -0.204308 -0.104962" limited="true" name="Lid002_joint" range="0.0 0.1" type="slide" damping="1" frictionloss="1" armature=".01" stiffness="0.05"/>
          <geom mesh="Lid002_vis" type="mesh" solimp="0.998 0.998 0.001" solref="0.001 1" density="100" friction="0.95 0.3 0.1" class="visual" material="Lid002_material"/>
          <geom class="collision" type="box" pos="0.000117 -0.209182 -0.108620" size="0.05922035500407219 0.06147303804755211 0.004763836041092873" quat="1.0 0.0 0.0 0.0"/>
        </body>
        <geom class="region" name="reg_main" type="box" pos="0.0003114999999999993 0.0009170000000000011 -0.0008800000000000058" size="0.07072049999999999 0.276999 0.17208400000000001"/>
      </body>
    </body>
  </worldbody>
  <actuator>
    <motor name="Button001_joint_actuator" joint="Button001_joint" gear="0.5"/>
    <motor name="Button002_joint_actuator" joint="Button002_joint" gear="0.5"/>
    <motor name="Button003_joint_actuator" joint="Button003_joint" gear="0.5"/>
    <motor name="Container001_Clear_joint_actuator" joint="Container001_Clear_joint" gear="10"/>
    <motor name="Lid001_joint_actuator" joint="Lid001_joint" gear="10"/>
    <motor name="Lid002_joint_actuator" joint="Lid002_joint" gear="10"/>
    <motor name="Lid003_joint_actuator" joint="Lid003_joint" gear="10"/>
  </actuator>
</mujoco>
