<mujoco model="model">
  <compiler angle="radian"/>
  <asset>
    <mesh file="visuals/Body001.obj" name="Body001_vis"/>
    <mesh file="visuals/Body001_Clear.obj" name="Body001_Clear_vis"/>
    <mesh file="visuals/Door001.obj" name="Door001_vis"/>
    <mesh file="visuals/Door001_Clear.obj" name="Door001_Clear_vis"/>
    <mesh file="visuals/Door002.obj" name="Door002_vis"/>
    <mesh file="visuals/Door002_Clear.obj" name="Door002_Clear_vis"/>
    <mesh file="visuals/Drawer001.obj" name="Drawer001_vis"/>
    <mesh file="visuals/Drawer002.obj" name="Drawer002_vis"/>
    <mesh file="visuals/Drawer003.obj" name="Drawer003_vis"/>
    <mesh file="visuals/Drawer004.obj" name="Drawer004_vis"/>
    <mesh file="visuals/Drawer005.obj" name="Drawer005_vis"/>
    <mesh file="visuals/Drawer006.obj" name="Drawer006_vis"/>
    <mesh file="visuals/Drawer007.obj" name="Drawer007_vis"/>
    <mesh file="visuals/Drawer008.obj" name="Drawer008_vis"/>
    <mesh file="visuals/Drawer009.obj" name="Drawer009_vis"/>
    <mesh file="visuals/Drawer010.obj" name="Drawer010_vis"/>
    <texture file="visuals/T_BC001.png" name="Body001_material" type="2d"/>
    <material name="Body001_material" rgba="1 1 1 1.0" texture="Body001_material" shininess="0.2512328028678894" specular="1"/>
    <texture file="visuals/T_BC001.png" name="Body001_Clear_material" type="2d"/>
    <material name="Body001_Clear_material" rgba="1 1 1 0.307692289352417" texture="Body001_Clear_material" shininess="0.2512328028678894" specular="1"/>
    <texture file="visuals/T_BC001.png" name="Door001_material" type="2d"/>
    <material name="Door001_material" rgba="1 1 1 1.0" texture="Door001_material" shininess="0.2512328028678894" specular="1"/>
    <texture file="visuals/T_BC001.png" name="Door001_Clear_material" type="2d"/>
    <material name="Door001_Clear_material" rgba="1 1 1 0.307692289352417" texture="Door001_Clear_material" shininess="0.2512328028678894" specular="1"/>
    <texture file="visuals/T_BC001.png" name="Door002_material" type="2d"/>
    <material name="Door002_material" rgba="1 1 1 1.0" texture="Door002_material" shininess="0.2512328028678894" specular="1"/>
    <texture file="visuals/T_BC001.png" name="Drawer001_material" type="2d"/>
    <material name="Drawer001_material" rgba="1 1 1 0.307692289352417" texture="Drawer001_material" shininess="0.2512328028678894" specular="1"/>
    <texture file="visuals/T_BC001.png" name="Drawer002_material" type="2d"/>
    <material name="Drawer002_material" rgba="1 1 1 0.307692289352417" texture="Drawer002_material" shininess="0.2512328028678894" specular="1"/>
    <texture file="visuals/T_BC001.png" name="Drawer003_material" type="2d"/>
    <material name="Drawer003_material" rgba="1 1 1 1.0" texture="Drawer003_material" shininess="0.2512328028678894" specular="1"/>
    <texture file="visuals/T_BC001.png" name="Drawer004_material" type="2d"/>
    <material name="Drawer004_material" rgba="1 1 1 1.0" texture="Drawer004_material" shininess="0.2512328028678894" specular="1"/>
    <texture file="visuals/T_BC001.png" name="Drawer005_material" type="2d"/>
    <material name="Drawer005_material" rgba="1 1 1 1.0" texture="Drawer005_material" shininess="0.2512328028678894" specular="1"/>
    <texture file="visuals/T_BC001.png" name="Drawer006_material" type="2d"/>
    <material name="Drawer006_material" rgba="1 1 1 1.0" texture="Drawer006_material" shininess="0.2512328028678894" specular="1"/>
    <texture file="visuals/T_BC001.png" name="Drawer007_material" type="2d"/>
    <material name="Drawer007_material" rgba="1 1 1 1.0" texture="Drawer007_material" shininess="0.2512328028678894" specular="1"/>
    <texture file="visuals/T_BC001.png" name="Drawer008_material" type="2d"/>
    <material name="Drawer008_material" rgba="1 1 1 1.0" texture="Drawer008_material" shininess="0.2512328028678894" specular="1"/>
    <texture file="visuals/T_BC001.png" name="Drawer009_material" type="2d"/>
    <material name="Drawer009_material" rgba="1 1 1 1.0" texture="Drawer009_material" shininess="0.2512328028678894" specular="1"/>
    <texture file="visuals/T_BC001.png" name="Drawer010_material" type="2d"/>
    <material name="Drawer010_material" rgba="1 1 1 1.0" texture="Drawer010_material" shininess="0.2512328028678894" specular="1"/>
  </asset>
  <default>
    <default class="visual">
      <geom conaffinity="0" contype="0" group="1" type="mesh"/>
    </default>
    <default class="collision">
      <geom group="0" rgba="0.5 0 0 0.5"/>
    </default>
    <default class="spawn">
      <geom group="0" rgba="1 1 1 0.5" contype="0" conaffinity="0"/>
      <site group="0" rgba="1 1 1 0.5"/>
    </default>
    <default class="region">
      <geom group="1" conaffinity="0" contype="0" rgba="0 1 0 0"/>
    </default>
  </default>
  <worldbody>
    <body>
      <body name="object">
        <geom mesh="Body001_vis" type="mesh" solimp="0.998 0.998 0.001" solref="0.001 1" density="100" friction="0.95 0.3 0.1" class="visual" material="Body001_material"/>
        <geom class="collision" type="box" pos="-0.4314097464084625 0.06337001919746399 -0.00506026204675436" size="0.01807491108775139 0.3385934829711914 0.9483897686004639" quat="1.0 0.0 0.0 0.0"/>
        <geom class="collision" type="box" pos="0.43142756819725037 0.06337001919746399 -0.00506026204675436" size="0.018074944615364075 0.3385940492153168 0.9483909010887146" quat="1.0 0.0 0.0 0.0"/>
        <geom class="collision" type="box" pos="-0.03617599606513977 0.06932438910007477 -0.00506026204675436" size="0.02239586040377617 0.33264604210853577 0.9484035968780518" quat="1.0 0.0 0.0 0.0"/>
        <geom class="collision" type="box" pos="-6.0811638832092285e-05 0.06932438910007477 -0.1588442325592041" size="0.4097903072834015 0.33264076709747314 0.02770553156733513" quat="1.0 0.0 0.0 0.0"/>
        <geom class="collision" type="box" pos="-6.081196988816373e-05 0.06932438910007477 0.9237262010574341" size="0.40979087352752686 0.3326413035392761 0.020109102129936218" quat="1.0 0.0 0.0 0.0"/>
        <geom class="collision" type="box" pos="-6.081513129174709e-05 0.31269246339797974 -0.005961598362773657" size="0.409791499376297 0.08925499022006989 0.9489522576332092" quat="1.0 0.0 0.0 0.0"/>
        <geom class="collision" type="box" pos="-6.081224637455307e-05 0.06932438910007477 -0.9327043294906616" size="0.4097919762134552 0.33264240622520447 0.022771652787923813" quat="1.0 0.0 0.0 0.0"/>
        <geom class="collision" type="box" pos="-0.3987797796726227 -0.2059071958065033 0.9563660621643066" size="0.03880257532000542 0.057414062321186066 0.013140099123120308" quat="1.0 0.0 0.0 0.0"/>
        <geom class="collision" type="box" pos="0.39935022592544556 -0.2059071958065033 0.9563660621643066" size="0.03880264237523079 0.05741412937641144 0.013140116818249226" quat="1.0 0.0 0.0 0.0"/>
        <body name="Body001_Clear">
          <geom mesh="Body001_Clear_vis" type="mesh" solimp="0.998 0.998 0.001" solref="0.001 1" density="100" friction="0.95 0.3 0.1" class="visual" material="Body001_Clear_material"/>
          <geom class="collision" type="box" pos="-0.23665212094783783 0.010217373259365559 0.5880203247070312" size="0.17314791679382324 0.20181740820407867 0.003748399903997779" quat="1.0 0.0 0.0 0.0"/>
          <geom class="collision" type="box" pos="0.19985148310661316 0.010217373259365559 0.5887021422386169" size="0.2091819941997528 0.2018178105354309 0.0037484061904251575" quat="1.0 0.0 0.0 0.0"/>
          <geom class="collision" type="box" pos="-0.23665212094783783 0.010217373259365559 0.27085381746292114" size="0.173148512840271 0.20181860029697418 0.003748418530449271" quat="1.0 0.0 0.0 0.0"/>
          <geom class="collision" type="box" pos="0.19985148310661316 0.010217373259365559 0.27153563499450684" size="0.20918317139148712 0.20181900262832642 0.00374842481687665" quat="1.0 0.0 0.0 0.0"/>
          <geom class="collision" type="box" pos="-0.23665212094783783 0.010217373259365559 0.09032253175973892" size="0.17314891517162323 0.20181940495967865 0.0037484311033040285" quat="1.0 0.0 0.0 0.0"/>
          <geom class="collision" type="box" pos="0.19985148310661316 0.010217373259365559 0.09100434929132462" size="0.2091839760541916 0.20181980729103088 0.003748437389731407" quat="1.0 0.0 0.0 0.0"/>
        </body>
        <body name="Door001">
          <joint axis="0.0 0.0 -1.0" pos="-0.41990166902542114 -0.3070699870586395 -0.1195378378033638" limited="true" name="Door001_joint" range="0.0 1.5707963267948966" type="hinge" damping="1" frictionloss="1" armature=".01" stiffness="0.05"/>
          <geom mesh="Door001_vis" type="mesh" solimp="0.998 0.998 0.001" solref="0.001 1" density="100" friction="0.95 0.3 0.1" class="visual" material="Door001_material"/>
          <geom class="collision" type="box" pos="-0.23585756123065948 -0.30889829993247986 -0.004155337810516357" size="0.17306047677993774 0.02668202668428421 0.9516863822937012" quat="1.0 0.0 0.0 0.0"/>
          <geom class="collision" type="box" pos="-0.06611627340316772 -0.3872798681259155 0.015286712907254696" size="0.012665143236517906 0.012665143236517906 0.1547602117061615" quat="1.0 0.0 0.0 0.0"/>
          <geom class="collision" type="box" pos="-0.047427210956811905 -0.3475547432899475 0.1526123583316803" size="0.004406571388244629 0.027533311396837234 0.014519368298351765" quat="1.0 0.0 0.0 0.0"/>
          <geom class="collision" type="box" pos="-0.047427210956811905 -0.3475547432899475 -0.12197266519069672" size="0.004406571388244629 0.027533311396837234 0.014519368298351765" quat="1.0 0.0 0.0 0.0"/>
          <body name="Door001_Clear">
            <geom mesh="Door001_Clear_vis" type="mesh" solimp="0.998 0.998 0.001" solref="0.001 1" density="100" friction="0.95 0.3 0.1" class="visual" material="Door001_Clear_material"/>
            <geom class="collision" type="box" pos="-0.24373874068260193 -0.27963539958000183 0.7416618466377258" size="0.14503848552703857 0.0009392445208504796 0.049916304647922516" quat="1.0 0.0 0.0 0.0"/>
            <geom class="collision" type="box" pos="-0.3864028751850128 -0.2427847981452942 0.741767406463623" size="0.0009392529027536511 0.03547966107726097 0.04981076717376709" quat="1.0 0.0 0.0 0.0"/>
            <geom class="collision" type="box" pos="-0.24444666504859924 -0.2059074193239212 0.741767406463623" size="0.1408872902393341 0.0009392508072778583 0.04981076717376709" quat="1.0 0.0 0.0 0.0"/>
            <geom class="collision" type="box" pos="-0.10058680176734924 -0.2427847981452942 0.741767406463623" size="0.0009392523788847029 0.03547966107726097 0.04981076717376709" quat="1.0 0.0 0.0 0.0"/>
            <geom class="collision" type="box" pos="-0.24302120506763458 -0.2426450401544571 0.6924877762794495" size="0.14432090520858765 0.0376768633723259 0.0009392482461407781" quat="1.0 0.0 0.0 0.0"/>
            <geom class="collision" type="box" pos="-0.24373874068260193 -0.27963539958000183 0.5614317059516907" size="0.14503848552703857 0.0009392445208504796 0.049916304647922516" quat="1.0 0.0 0.0 0.0"/>
            <geom class="collision" type="box" pos="-0.3864028751850128 -0.2427847981452942 0.5615372657775879" size="0.0009392529027536511 0.03547966107726097 0.04981076717376709" quat="1.0 0.0 0.0 0.0"/>
            <geom class="collision" type="box" pos="-0.24444666504859924 -0.2059074193239212 0.5615372657775879" size="0.1408872902393341 0.0009392508072778583 0.04981076717376709" quat="1.0 0.0 0.0 0.0"/>
            <geom class="collision" type="box" pos="-0.10058680176734924 -0.2427847981452942 0.5615372657775879" size="0.0009392523788847029 0.03547966107726097 0.04981076717376709" quat="1.0 0.0 0.0 0.0"/>
            <geom class="collision" type="box" pos="-0.24302120506763458 -0.2426450401544571 0.5122576355934143" size="0.14432090520858765 0.0376768633723259 0.0009392482461407781" quat="1.0 0.0 0.0 0.0"/>
          </body>
        </body>
        <body name="Door002">
          <joint axis="0.0 0.0 1.0" pos="0.420387864112854 -0.3062276244163513 -0.09063228964805603" limited="true" name="Door002_joint" range="0.0 1.5707963267948966" type="hinge" damping="1" frictionloss="1" armature=".01" stiffness="0.05"/>
          <geom mesh="Door002_vis" type="mesh" solimp="0.998 0.998 0.001" solref="0.001 1" density="100" friction="0.95 0.3 0.1" class="visual" material="Door002_material"/>
          <geom class="collision" type="box" pos="0.2084599882364273 -0.27963539958000183 0.7416618466377258" size="0.17995940148830414 0.0009392445208504796 0.049916304647922516" quat="1.0 0.0 0.0 0.0"/>
          <geom class="collision" type="box" pos="0.030874965712428093 -0.2427847981452942 0.741767406463623" size="0.0009392523788847029 0.03547966107726097 0.04981076717376709" quat="1.0 0.0 0.0 0.0"/>
          <geom class="collision" type="box" pos="0.2077520787715912 -0.2059074193239212 0.741767406463623" size="0.17580822110176086 0.0009392508072778583 0.04981076717376709" quat="1.0 0.0 0.0 0.0"/>
          <geom class="collision" type="box" pos="0.38653287291526794 -0.2427847981452942 0.741767406463623" size="0.0009392523788847029 0.03547966107726097 0.04981076717376709" quat="1.0 0.0 0.0 0.0"/>
          <geom class="collision" type="box" pos="0.20917755365371704 -0.2426450401544571 0.6924877762794495" size="0.1792418360710144 0.0376768633723259 0.0009392482461407781" quat="1.0 0.0 0.0 0.0"/>
          <geom class="collision" type="box" pos="0.2084599882364273 -0.27963539958000183 0.5617579817771912" size="0.17995940148830414 0.0009392445208504796 0.049916304647922516" quat="1.0 0.0 0.0 0.0"/>
          <geom class="collision" type="box" pos="0.030874965712428093 -0.2427847981452942 0.5618635416030884" size="0.0009392523788847029 0.03547966107726097 0.04981076717376709" quat="1.0 0.0 0.0 0.0"/>
          <geom class="collision" type="box" pos="0.2077520787715912 -0.2059074193239212 0.5618635416030884" size="0.17580822110176086 0.0009392508072778583 0.04981076717376709" quat="1.0 0.0 0.0 0.0"/>
          <geom class="collision" type="box" pos="0.38653287291526794 -0.2427847981452942 0.5618635416030884" size="0.0009392523788847029 0.03547966107726097 0.04981076717376709" quat="1.0 0.0 0.0 0.0"/>
          <geom class="collision" type="box" pos="0.20917755365371704 -0.2426450401544571 0.5125839114189148" size="0.1792418360710144 0.0376768633723259 0.0009392482461407781" quat="1.0 0.0 0.0 0.0"/>
          <geom class="collision" type="box" pos="0.20360955595970154 -0.30889829993247986 -0.004155337810516357" size="0.21106405556201935 0.02668202668428421 0.9516863822937012" quat="1.0 0.0 0.0 0.0"/>
          <geom class="collision" type="box" pos="-0.003860831493511796 -0.3872798681259155 0.32808175683021545" size="0.012665143236517906 0.012665143236517906 0.1547602117061615" quat="1.0 0.0 0.0 0.0"/>
          <geom class="collision" type="box" pos="-0.02287726104259491 -0.3475547432899475 0.4654074013233185" size="0.004406571388244629 0.027533311396837234 0.014519368298351765" quat="1.0 0.0 0.0 0.0"/>
          <geom class="collision" type="box" pos="-0.02287726104259491 -0.3475547432899475 0.19082237780094147" size="0.004406571388244629 0.027533311396837234 0.014519368298351765" quat="1.0 0.0 0.0 0.0"/>
        </body>
        <body name="Drawer001">
          <joint axis="0.0 -1.0 0.0" pos="-0.2171107530593872 0.003605358302593231 0.17583005130290985" limited="true" name="Drawer001_joint" range="0.0 0.3" type="slide" damping="1" frictionloss="1" armature=".01" stiffness="0.05"/>
          <geom mesh="Drawer001_vis" type="mesh" solimp="0.998 0.998 0.001" solref="0.001 1" density="100" friction="0.95 0.3 0.1" class="visual" material="Drawer001_material"/>
          <geom class="collision" type="box" pos="-0.21498090028762817 -0.18433767557144165 0.1492915153503418" size="0.045026764273643494 0.00229278695769608 0.023585114628076553" quat="0.9961947202682495 -0.08715573698282242 -0.0 0.0"/>
          <geom class="collision" type="box" pos="-0.21498090028762817 -0.18433767557144165 0.11113771051168442" size="0.04502692073583603 0.006329035852104425 0.014568768441677094" quat="1.0 0.0 0.0 0.0"/>
          <geom class="collision" type="box" pos="-0.21498090028762817 -0.18433767557144165 0.2143215537071228" size="0.04502691701054573 0.006329035386443138 0.04171183705329895" quat="1.0 0.0 0.0 0.0"/>
          <geom class="collision" type="box" pos="-0.11758849024772644 -0.18433767557144165 0.1761946976184845" size="0.052365921437740326 0.006329034920781851 0.0798388421535492" quat="1.0 0.0 0.0 0.0"/>
          <geom class="collision" type="box" pos="-0.21848009526729584 0.005912944674491882 0.10902069509029388" size="0.1405802071094513 0.18467341363430023 0.0032004129607230425" quat="1.0 0.0 0.0 0.0"/>
          <geom class="collision" type="box" pos="-0.08011176437139511 0.0059129465371370316 0.17514479160308838" size="0.0032007861882448196 0.18467363715171814 0.06957511603832245" quat="1.0 0.0 0.0 0.0"/>
          <geom class="collision" type="box" pos="-0.35516542196273804 0.0059129465371370316 0.17514479160308838" size="0.0032007957343012094 0.18467389047145844 0.0695752203464508" quat="1.0 0.0 0.0 0.0"/>
          <geom class="collision" type="box" pos="-0.21848006546497345 0.19479244947433472 0.17514479160308838" size="0.1405809372663498 0.0029303827323019505 0.06957533210515976" quat="1.0 0.0 0.0 0.0"/>
          <geom class="collision" type="box" pos="-0.21498090028762817 -0.17966006696224213 0.1492915153503418" size="0.045026764273643494 0.0017136718379333615 0.024223076179623604" quat="1.0 0.0 0.0 0.0"/>
          <geom class="collision" type="box" pos="-0.3146893382072449 -0.18433767557144165 0.1761946976184845" size="0.054681938141584396 0.00632903166115284 0.07983879745006561" quat="1.0 0.0 0.0 0.0"/>
        </body>
        <body name="Drawer002">
          <joint axis="0.0 -1.0 0.0" pos="-0.21935637295246124 0.0045370422303676605 -0.02909039705991745" limited="true" name="Drawer002_joint" range="0.0 0.3" type="slide" damping="1" frictionloss="1" armature=".01" stiffness="0.05"/>
          <geom mesh="Drawer002_vis" type="mesh" solimp="0.998 0.998 0.001" solref="0.001 1" density="100" friction="0.95 0.3 0.1" class="visual" material="Drawer002_material"/>
          <geom class="collision" type="box" pos="-0.2035452425479889 -0.18433767557144165 -0.04448869824409485" size="0.045026764273643494 0.00229278695769608 0.023585114628076553" quat="0.9961947202682495 -0.08715573698282242 -0.0 0.0"/>
          <geom class="collision" type="box" pos="-0.2035452425479889 -0.18433767557144165 -0.09826967120170593" size="0.045026995241642 0.006329045165330172 0.030196093022823334" quat="1.0 0.0 0.0 0.0"/>
          <geom class="collision" type="box" pos="-0.2035452425479889 -0.18433767557144165 0.024742193520069122" size="0.0450269915163517 0.006329044699668884 0.045912764966487885" quat="1.0 0.0 0.0 0.0"/>
          <geom class="collision" type="box" pos="-0.11397108435630798 -0.18433767557144165 -0.029011834412813187" size="0.04454759135842323 0.006329044234007597 0.0996670126914978" quat="1.0 0.0 0.0 0.0"/>
          <geom class="collision" type="box" pos="-0.22091658413410187 0.005912944674491882 -0.11601385474205017" size="0.13881613314151764 0.1846737116575241 0.003200417384505272" quat="1.0 0.0 0.0 0.0"/>
          <geom class="collision" type="box" pos="-0.08431261777877808 0.0059129465371370316 -0.02670106291770935" size="0.003200795268639922 0.18467393517494202 0.09276396036148071" quat="1.0 0.0 0.0 0.0"/>
          <geom class="collision" type="box" pos="-0.35583755373954773 0.0059129465371370316 -0.02670106291770935" size="0.0032008050475269556 0.1846741884946823 0.09276406466960907" quat="1.0 0.0 0.0 0.0"/>
          <geom class="collision" type="box" pos="-0.22091655433177948 0.19479244947433472 -0.02670106291770935" size="0.13881686329841614 0.0029303873889148235 0.09276417642831802" quat="1.0 0.0 0.0 0.0"/>
          <geom class="collision" type="box" pos="-0.2035452425479889 -0.17966006696224213 -0.04448869824409485" size="0.045026764273643494 0.0017136718379333615 0.02422311343252659" quat="1.0 0.0 0.0 0.0"/>
          <geom class="collision" type="box" pos="-0.3093075752258301 -0.18433767557144165 -0.029011834412813187" size="0.06073598191142082 0.006329040974378586 0.09966696798801422" quat="1.0 0.0 0.0 0.0"/>
        </body>
        <body name="Drawer003">
          <joint axis="0.0 -1.0 0.0" pos="-0.22957569360733032 -0.09317242354154587 -0.29646196961402893" limited="true" name="Drawer003_joint" range="0.0 0.3" type="slide" damping="1" frictionloss="1" armature=".01" stiffness="0.05"/>
          <geom mesh="Drawer003_vis" type="mesh" solimp="0.998 0.998 0.001" solref="0.001 1" density="100" friction="0.95 0.3 0.1" class="visual" material="Drawer003_material"/>
          <geom class="collision" type="box" pos="-0.23052501678466797 0.09210389107465744 -0.3017696738243103" size="0.1441011279821396 0.003485064022243023 0.08683301508426666" quat="1.0 0.0 0.0 0.0"/>
          <geom class="collision" type="box" pos="-0.37413159012794495 -0.09073059260845184 -0.3017696738243103" size="0.0032007170375436544 0.17880745232105255 0.08683387190103531" quat="1.0 0.0 0.0 0.0"/>
          <geom class="collision" type="box" pos="-0.08575929701328278 -0.09073059260845184 -0.3017696738243103" size="0.003200708655640483 0.17880716919898987 0.08683373034000397" quat="1.0 0.0 0.0 0.0"/>
          <geom class="collision" type="box" pos="-0.2287599891424179 -0.09018582105636597 -0.38537874817848206" size="0.14410027861595154 0.17935170233249664 0.0032003724481910467" quat="1.0 0.0 0.0 0.0"/>
          <geom class="collision" type="box" pos="-0.13881486654281616 -0.2758253812789917 -0.2961459159851074" size="0.0568477064371109 0.006329031195491552 0.10329634696245193" quat="1.0 0.0 0.0 0.0"/>
          <geom class="collision" type="box" pos="-0.247208833694458 -0.2758253812789917 -0.23707079887390137" size="0.05154670774936676 0.006329030729830265 0.04422110319137573" quat="1.0 0.0 0.0 0.0"/>
          <geom class="collision" type="box" pos="-0.247208833694458 -0.2758253812789917 -0.3646923899650574" size="0.05154670029878616 0.006329030264168978 0.03453686088323593" quat="1.0 0.0 0.0 0.0"/>
          <geom class="collision" type="box" pos="-0.3406710624694824 -0.2758253812789917 -0.2961459159851074" size="0.0419158861041069 0.00632902979850769 0.10329632461071014" quat="1.0 0.0 0.0 0.0"/>
          <geom class="collision" type="box" pos="-0.24720881879329681 -0.27526262402534485 -0.3047477602958679" size="0.05154647305607796 0.00229278695769608 0.023585114628076553" quat="0.9961947202682495 -0.08715573698282242 -0.0 0.0"/>
          <geom class="collision" type="box" pos="-0.24720881879329681 -0.2714467942714691 -0.3047477602958679" size="0.05154647305607796 0.00229278695769608 0.023585114628076553" quat="1.0 0.0 0.0 0.0"/>
        </body>
        <body name="Drawer004">
          <joint axis="0.0 -1.0 0.0" pos="-0.22957569360733032 -0.09317241609096527 -0.5194770693778992" limited="true" name="Drawer004_joint" range="0.0 0.3" type="slide" damping="1" frictionloss="1" armature=".01" stiffness="0.05"/>
          <geom mesh="Drawer004_vis" type="mesh" solimp="0.998 0.998 0.001" solref="0.001 1" density="100" friction="0.95 0.3 0.1" class="visual" material="Drawer004_material"/>
          <geom class="collision" type="box" pos="-0.23052500188350677 0.09207402169704437 -0.5247526168823242" size="0.14409838616847992 0.0029303007759153843 0.08683264255523682" quat="1.0 0.0 0.0 0.0"/>
          <geom class="collision" type="box" pos="-0.37413159012794495 -0.09073059260845184 -0.5247526168823242" size="0.0032006315886974335 0.1788046807050705 0.08683249354362488" quat="1.0 0.0 0.0 0.0"/>
          <geom class="collision" type="box" pos="-0.08575929701328278 -0.09073059260845184 -0.5247526168823242" size="0.003200623206794262 0.1788043975830078 0.08683235198259354" quat="1.0 0.0 0.0 0.0"/>
          <geom class="collision" type="box" pos="-0.2287599891424179 -0.09018582105636597 -0.6083617210388184" size="0.14409753680229187 0.1793489307165146 0.0032003293745219707" quat="1.0 0.0 0.0 0.0"/>
          <geom class="collision" type="box" pos="-0.24720881879329681 -0.27526262402534485 -0.5284433364868164" size="0.05154647305607796 0.00229278695769608 0.023585114628076553" quat="0.9961947202682495 -0.08715573698282242 -0.0 0.0"/>
          <geom class="collision" type="box" pos="-0.3406710624694824 -0.2758253812789917 -0.5198414325714111" size="0.041915882378816605 0.006329028867185116 0.10329631716012955" quat="1.0 0.0 0.0 0.0"/>
          <geom class="collision" type="box" pos="-0.247208833694458 -0.2758253812789917 -0.5883879661560059" size="0.05154667794704437 0.0063290284015238285 0.034536849707365036" quat="1.0 0.0 0.0 0.0"/>
          <geom class="collision" type="box" pos="-0.247208833694458 -0.2758253812789917 -0.46076634526252747" size="0.05154666677117348 0.006329027935862541 0.04422108456492424" quat="1.0 0.0 0.0 0.0"/>
          <geom class="collision" type="box" pos="-0.13881486654281616 -0.2758253812789917 -0.5198414325714111" size="0.056847650557756424 0.006329027470201254 0.10329629480838776" quat="1.0 0.0 0.0 0.0"/>
          <geom class="collision" type="box" pos="-0.24720881879329681 -0.27072015404701233 -0.5284433364868164" size="0.05154647305607796 0.00229278695769608 0.023585114628076553" quat="1.0 0.0 0.0 0.0"/>
        </body>
        <body name="Drawer005">
          <joint axis="0.0 -1.0 0.0" pos="-0.22957569360733032 -0.09317249804735184 -0.7747529745101929" limited="true" name="Drawer005_joint" range="0.0 0.3" type="slide" damping="1" frictionloss="1" armature=".01" stiffness="0.05"/>
          <geom mesh="Drawer005_vis" type="mesh" solimp="0.998 0.998 0.001" solref="0.001 1" density="100" friction="0.95 0.3 0.1" class="visual" material="Drawer005_material"/>
          <geom class="collision" type="box" pos="-0.23052500188350677 0.09207402169704437 -0.7800319790840149" size="0.14409565925598145 0.0029302574694156647 0.12170929461717606" quat="1.0 0.0 0.0 0.0"/>
          <geom class="collision" type="box" pos="-0.37413159012794495 -0.09073059260845184 -0.7800319194793701" size="0.0032005461398512125 0.17880190908908844 0.12170900404453278" quat="1.0 0.0 0.0 0.0"/>
          <geom class="collision" type="box" pos="-0.08575929701328278 -0.09073059260845184 -0.7800319194793701" size="0.003200537757948041 0.17880164086818695 0.12170872837305069" quat="1.0 0.0 0.0 0.0"/>
          <geom class="collision" type="box" pos="-0.2287599891424179 -0.09018582850694656 -0.8985105156898499" size="0.1440948098897934 0.17934617400169373 0.0032002872321754694" quat="1.0 0.0 0.0 0.0"/>
          <geom class="collision" type="box" pos="-0.13881486654281616 -0.2758253812789917 -0.7745332717895508" size="0.05684764310717583 0.006329027004539967 0.13777707517147064" quat="1.0 0.0 0.0 0.0"/>
          <geom class="collision" type="box" pos="-0.247208833694458 -0.2758253812789917 -0.701343297958374" size="0.051546644419431686 0.006329026538878679 0.06458690017461777" quat="1.0 0.0 0.0 0.0"/>
          <geom class="collision" type="box" pos="-0.247208833694458 -0.2758253812789917 -0.863445520401001" size="0.05154663696885109 0.006329026073217392 0.04865168780088425" quat="1.0 0.0 0.0 0.0"/>
          <geom class="collision" type="box" pos="-0.3406710624694824 -0.2758253812789917 -0.7745332717895508" size="0.04191585257649422 0.006329025607556105 0.13777701556682587" quat="1.0 0.0 0.0 0.0"/>
          <geom class="collision" type="box" pos="-0.24720881879329681 -0.27526262402534485 -0.789509654045105" size="0.05154647305607796 0.00229278695769608 0.023585114628076553" quat="0.9961947202682495 -0.08715573698282242 -0.0 0.0"/>
          <geom class="collision" type="box" pos="-0.24720881879329681 -0.271382600069046 -0.789509654045105" size="0.05154647305607796 0.00229278695769608 0.023585114628076553" quat="1.0 0.0 0.0 0.0"/>
        </body>
        <body name="Drawer006">
          <joint axis="0.0 -1.0 0.0" pos="0.17629678547382355 0.003605358302593231 0.17583005130290985" limited="true" name="Drawer006_joint" range="0.0 0.3" type="slide" damping="1" frictionloss="1" armature=".01" stiffness="0.05"/>
          <geom mesh="Drawer006_vis" type="mesh" solimp="0.998 0.998 0.001" solref="0.001 1" density="100" friction="0.95 0.3 0.1" class="visual" material="Drawer006_material"/>
          <geom class="collision" type="box" pos="0.0616711750626564 -0.18433767557144165 0.1761946976184845" size="0.06867996603250504 0.006329081021249294 0.07983958721160889" quat="1.0 0.0 0.0 0.0"/>
          <geom class="collision" type="box" pos="0.17543846368789673 0.19479244947433472 0.17514479160308838" size="0.17213769257068634 0.002930406713858247 0.06957609951496124" quat="1.0 0.0 0.0 0.0"/>
          <geom class="collision" type="box" pos="0.007197858300060034 0.0059129465371370316 0.17514479160308838" size="0.003200841136276722 0.18467538058757782 0.0695759728550911" quat="1.0 0.0 0.0 0.0"/>
          <geom class="collision" type="box" pos="0.34536200761795044 0.0059129465371370316 0.17514479160308838" size="0.0032008313573896885 0.18467511236667633 0.06957584619522095" quat="1.0 0.0 0.0 0.0"/>
          <geom class="collision" type="box" pos="0.17543844878673553 0.005912944674491882 0.10902069509029388" size="0.17213687300682068 0.18467484414577484 0.0032004353124648333" quat="1.0 0.0 0.0 0.0"/>
          <geom class="collision" type="box" pos="0.2898605167865753 -0.18433767557144165 0.1761946976184845" size="0.06945736706256866 0.006329047027975321 0.07983904331922531" quat="1.0 0.0 0.0 0.0"/>
          <geom class="collision" type="box" pos="0.17537686228752136 -0.18433767557144165 0.2143215537071228" size="0.045027006417512894 0.0063290465623140335 0.04171192646026611" quat="1.0 0.0 0.0 0.0"/>
          <geom class="collision" type="box" pos="0.17537686228752136 -0.18433767557144165 0.11113771051168442" size="0.045027002692222595 0.006329046096652746 0.014568810351192951" quat="1.0 0.0 0.0 0.0"/>
          <geom class="collision" type="box" pos="0.17537686228752136 -0.18433767557144165 0.1492915153503418" size="0.045026764273643494 0.00229278695769608 0.023585114628076553" quat="0.9961947202682495 -0.08715573698282242 -0.0 0.0"/>
          <geom class="collision" type="box" pos="0.17537686228752136 -0.17966006696224213 0.1492915153503418" size="0.045026764273643494 0.0017136718379333615 0.02422313019633293" quat="1.0 0.0 0.0 0.0"/>
        </body>
        <body name="Drawer007">
          <joint axis="0.0 -1.0 0.0" pos="0.17870624363422394 0.0045370422303676605 -0.02909039705991745" limited="true" name="Drawer007_joint" range="0.0 0.3" type="slide" damping="1" frictionloss="1" armature=".01" stiffness="0.05"/>
          <geom mesh="Drawer007_vis" type="mesh" solimp="0.998 0.998 0.001" solref="0.001 1" density="100" friction="0.95 0.3 0.1" class="visual" material="Drawer007_material"/>
          <geom class="collision" type="box" pos="0.15827108919620514 -0.17966006696224213 -0.04448869824409485" size="0.045026764273643494 0.0017136718379333615 0.02422310970723629" quat="1.0 0.0 0.0 0.0"/>
          <geom class="collision" type="box" pos="0.1769038885831833 0.19479244947433472 -0.02670106291770935" size="0.16865964233875275 0.0029303862247616053 0.09276413917541504" quat="1.0 0.0 0.0 0.0"/>
          <geom class="collision" type="box" pos="0.012140035629272461 0.0059129465371370316 -0.02670106291770935" size="0.003200802020728588 0.18467408418655396 0.09276401996612549" quat="1.0 0.0 0.0 0.0"/>
          <geom class="collision" type="box" pos="0.34559696912765503 0.0059129465371370316 -0.02670106291770935" size="0.003200789215043187 0.18467380106449127 0.09276389330625534" quat="1.0 0.0 0.0 0.0"/>
          <geom class="collision" type="box" pos="0.1769038587808609 0.005912944674491882 -0.11601385474205017" size="0.1686588078737259 0.18467354774475098 0.0032004148233681917" quat="1.0 0.0 0.0 0.0"/>
          <geom class="collision" type="box" pos="0.2807687222957611 -0.18433767557144165 -0.029011834412813187" size="0.07747119665145874 0.006329037714749575 0.09966691583395004" quat="1.0 0.0 0.0 0.0"/>
          <geom class="collision" type="box" pos="0.15827108919620514 -0.18433767557144165 0.024742193520069122" size="0.04502693563699722 0.006329037249088287 0.04591270908713341" quat="1.0 0.0 0.0 0.0"/>
          <geom class="collision" type="box" pos="0.15827108919620514 -0.18433767557144165 -0.09826967120170593" size="0.045026931911706924 0.006329036783427 0.03019602783024311" quat="1.0 0.0 0.0 0.0"/>
          <geom class="collision" type="box" pos="0.05558938533067703 -0.18433767557144165 -0.029011834412813187" size="0.05765528231859207 0.006329036317765713 0.09966689348220825" quat="1.0 0.0 0.0 0.0"/>
          <geom class="collision" type="box" pos="0.15827108919620514 -0.18433767557144165 -0.04448869824409485" size="0.045026764273643494 0.00229278695769608 0.023585114628076553" quat="0.9961947202682495 -0.08715573698282242 -0.0 0.0"/>
        </body>
        <body name="Drawer008">
          <joint axis="0.0 -1.0 0.0" pos="0.19439907371997833 -0.09317242354154587 -0.29646196961402893" limited="true" name="Drawer008_joint" range="0.0 0.3" type="slide" damping="1" frictionloss="1" armature=".01" stiffness="0.05"/>
          <geom mesh="Drawer008_vis" type="mesh" solimp="0.998 0.998 0.001" solref="0.001 1" density="100" friction="0.95 0.3 0.1" class="visual" material="Drawer008_material"/>
          <geom class="collision" type="box" pos="0.19592899084091187 0.0917285680770874 -0.3012940585613251" size="0.17917253077030182 0.0034850407391786575 0.08665382862091064" quat="1.0 0.0 0.0 0.0"/>
          <geom class="collision" type="box" pos="0.01671856828033924 -0.09091895818710327 -0.3012940585613251" size="0.0032006746623665094 0.17846788465976715 0.0866546630859375" quat="1.0 0.0 0.0 0.0"/>
          <geom class="collision" type="box" pos="0.37204763293266296 -0.09091895818710327 -0.3012940585613251" size="0.0032006646506488323 0.17846760153770447 0.08665452152490616" quat="1.0 0.0 0.0 0.0"/>
          <geom class="collision" type="box" pos="0.19249273836612701 -0.09091896563768387 -0.38449805974960327" size="0.17917168140411377 0.17846734821796417 0.0032003503292798996" quat="1.0 0.0 0.0 0.0"/>
          <geom class="collision" type="box" pos="0.21431928873062134 -0.27526262402534485 -0.3047477602958679" size="0.05154647305607796 0.00229278695769608 0.023585114628076553" quat="0.9961947202682495 -0.08715573698282242 -0.0 0.0"/>
          <geom class="collision" type="box" pos="0.08758071064949036 -0.2758253812789917 -0.2961459159851074" size="0.07519227266311646 0.006329025141894817 0.10329625010490417" quat="1.0 0.0 0.0 0.0"/>
          <geom class="collision" type="box" pos="0.21431928873062134 -0.2758253812789917 -0.3646923899650574" size="0.051546610891819 0.00632902467623353 0.03453681617975235" quat="1.0 0.0 0.0 0.0"/>
          <geom class="collision" type="box" pos="0.21431928873062134 -0.2758253812789917 -0.23707079887390137" size="0.0515466034412384 0.006329023744910955 0.044221051037311554" quat="1.0 0.0 0.0 0.0"/>
          <geom class="collision" type="box" pos="0.32089290022850037 -0.2758253812789917 -0.2961459159851074" size="0.05502722039818764 0.006329023279249668 0.10329622775316238" quat="1.0 0.0 0.0 0.0"/>
          <geom class="collision" type="box" pos="0.21431928873062134 -0.2708386778831482 -0.3047477602958679" size="0.05154647305607796 0.00229278695769608 0.023585114628076553" quat="1.0 0.0 0.0 0.0"/>
        </body>
        <body name="Drawer009">
          <joint axis="0.0 -1.0 0.0" pos="0.19439907371997833 -0.09317241609096527 -0.5194770693778992" limited="true" name="Drawer009_joint" range="0.0 0.3" type="slide" damping="1" frictionloss="1" armature=".01" stiffness="0.05"/>
          <geom mesh="Drawer009_vis" type="mesh" solimp="0.998 0.998 0.001" solref="0.001 1" density="100" friction="0.95 0.3 0.1" class="visual" material="Drawer009_material"/>
          <geom class="collision" type="box" pos="0.19592899084091187 0.09175843745470047 -0.5242770314216614" size="0.17916978895664215 0.002930280053988099 0.08665341883897781" quat="1.0 0.0 0.0 0.0"/>
          <geom class="collision" type="box" pos="0.01671856828033924 -0.09091895818710327 -0.5242770314216614" size="0.0032005892135202885 0.1784651279449463 0.08665327727794647" quat="1.0 0.0 0.0 0.0"/>
          <geom class="collision" type="box" pos="0.37204763293266296 -0.09091895818710327 -0.5242770314216614" size="0.0032005792018026114 0.1784648448228836 0.08665313571691513" quat="1.0 0.0 0.0 0.0"/>
          <geom class="collision" type="box" pos="0.19249273836612701 -0.09091896563768387 -0.6074810028076172" size="0.1791689395904541 0.17846457660198212 0.00320030702278018" quat="1.0 0.0 0.0 0.0"/>
          <geom class="collision" type="box" pos="0.3210240602493286 -0.2758253812789917 -0.5198414325714111" size="0.0544670931994915 0.006329022813588381 0.10329622030258179" quat="1.0 0.0 0.0 0.0"/>
          <geom class="collision" type="box" pos="0.21501058340072632 -0.2758253812789917 -0.46076634526252747" size="0.051546577364206314 0.0063290223479270935 0.04422103613615036" quat="1.0 0.0 0.0 0.0"/>
          <geom class="collision" type="box" pos="0.21501058340072632 -0.2758253812789917 -0.5883879661560059" size="0.05154656991362572 0.006329021882265806 0.03453679382801056" quat="1.0 0.0 0.0 0.0"/>
          <geom class="collision" type="box" pos="0.08698596060276031 -0.2758253812789917 -0.5198414325714111" size="0.07647824287414551 0.006329021416604519 0.1032961905002594" quat="1.0 0.0 0.0 0.0"/>
          <geom class="collision" type="box" pos="0.21501058340072632 -0.27526262402534485 -0.5284433364868164" size="0.05154647305607796 0.00229278695769608 0.023585114628076553" quat="0.9961947202682495 -0.08715573698282242 -0.0 0.0"/>
          <geom class="collision" type="box" pos="0.21501058340072632 -0.2710040509700775 -0.5284433364868164" size="0.05154647305607796 0.00229278695769608 0.023585114628076553" quat="1.0 0.0 0.0 0.0"/>
        </body>
        <body name="Drawer010">
          <joint axis="0.0 -1.0 0.0" pos="0.19439907371997833 -0.09317249804735184 -0.7747529745101929" limited="true" name="Drawer010_joint" range="0.0 0.3" type="slide" damping="1" frictionloss="1" armature=".01" stiffness="0.05"/>
          <geom mesh="Drawer010_vis" type="mesh" solimp="0.998 0.998 0.001" solref="0.001 1" density="100" friction="0.95 0.3 0.1" class="visual" material="Drawer010_material"/>
          <geom class="collision" type="box" pos="0.19592899084091187 0.09175843745470047 -0.7795563340187073" size="0.17916706204414368 0.002930236980319023 0.12152937799692154" quat="1.0 0.0 0.0 0.0"/>
          <geom class="collision" type="box" pos="0.01671856828033924 -0.09091895818710327 -0.7795563340187073" size="0.0032005037646740675 0.17846235632896423 0.12152910232543945" quat="1.0 0.0 0.0 0.0"/>
          <geom class="collision" type="box" pos="0.37204763293266296 -0.09091895818710327 -0.7795563340187073" size="0.0032004937529563904 0.17846207320690155 0.12152881920337677" quat="1.0 0.0 0.0 0.0"/>
          <geom class="collision" type="box" pos="0.19249273836612701 -0.09091897308826447 -0.8976297974586487" size="0.17916621267795563 0.17846181988716125 0.003200266044586897" quat="1.0 0.0 0.0 0.0"/>
          <geom class="collision" type="box" pos="0.21438169479370117 -0.27526262402534485 -0.789509654045105" size="0.05154647305607796 0.00229278695769608 0.023585114628076553" quat="0.9961947202682495 -0.08715573698282242 -0.0 0.0"/>
          <geom class="collision" type="box" pos="0.08771310746669769 -0.2758253812789917 -0.7745332717895508" size="0.07512220740318298 0.006329020950943232 0.13777686655521393" quat="1.0 0.0 0.0 0.0"/>
          <geom class="collision" type="box" pos="0.21438169479370117 -0.2758253812789917 -0.863445520401001" size="0.051546547561883926 0.006329020485281944 0.048651643097400665" quat="1.0 0.0 0.0 0.0"/>
          <geom class="collision" type="box" pos="0.21438169479370117 -0.2758253812789917 -0.701343297958374" size="0.05154654011130333 0.006329020019620657 0.06458679586648941" quat="1.0 0.0 0.0 0.0"/>
          <geom class="collision" type="box" pos="0.3210253119468689 -0.2758253812789917 -0.7745332717895508" size="0.05509716272354126 0.006329019088298082 0.13777682185173035" quat="1.0 0.0 0.0 0.0"/>
          <geom class="collision" type="box" pos="0.21438169479370117 -0.270767480134964 -0.789509654045105" size="0.05154647305607796 0.00229278695769608 0.023585114628076553" quat="1.0 0.0 0.0 0.0"/>
        </body>
        <geom class="region" name="reg_main" type="box" pos="7.450580596923828e-09 0.033196091651916504 -7.450580596923828e-08" size="0.44999998807907104 0.3687743544578552 0.9698987603187561"/>
      </body>
    </body>
  </worldbody>
  <actuator>
    <motor name="Door001_joint_actuator" joint="Door001_joint" gear="50"/>
    <motor name="Door002_joint_actuator" joint="Door002_joint" gear="50"/>
    <motor name="Drawer001_joint_actuator" joint="Drawer001_joint" gear="50"/>
    <motor name="Drawer002_joint_actuator" joint="Drawer002_joint" gear="50"/>
    <motor name="Drawer003_joint_actuator" joint="Drawer003_joint" gear="50"/>
    <motor name="Drawer004_joint_actuator" joint="Drawer004_joint" gear="50"/>
    <motor name="Drawer005_joint_actuator" joint="Drawer005_joint" gear="50"/>
    <motor name="Drawer006_joint_actuator" joint="Drawer006_joint" gear="50"/>
    <motor name="Drawer007_joint_actuator" joint="Drawer007_joint" gear="50"/>
    <motor name="Drawer008_joint_actuator" joint="Drawer008_joint" gear="50"/>
    <motor name="Drawer009_joint_actuator" joint="Drawer009_joint" gear="50"/>
    <motor name="Drawer010_joint_actuator" joint="Drawer010_joint" gear="50"/>
  </actuator>
</mujoco>
