<?xml version="1.0" ?>
<mujoco model="model">
    <compiler angle="radian"/>
    <asset>
        <mesh file="visuals/CoffeeMachine037_Button6.obj" name="CoffeeMachine037_Button6_vis"/>
        <mesh file="visuals/CoffeeMachine037_Handle.obj" name="CoffeeMachine037_Handle_vis"/>
        <mesh file="visuals/CoffeeMachine037_Button4.obj" name="CoffeeMachine037_Button4_vis"/>
        <mesh file="visuals/CoffeeMachine037_Lid2.obj" name="CoffeeMachine037_Lid2_vis"/>
        <mesh file="visuals/CoffeeMachine037_Lid3.obj" name="CoffeeMachine037_Lid3_vis"/>
        <mesh file="visuals/CoffeeMachine037_Knob3.obj" name="CoffeeMachine037_Knob3_vis"/>
        <mesh file="visuals/CoffeeMachine037_Knob2.obj" name="CoffeeMachine037_Knob2_vis"/>
        <mesh file="visuals/CoffeeMachine037_Button3.obj" name="CoffeeMachine037_Button3_vis"/>
        <mesh file="visuals/CoffeeMachine037_Body.obj" name="CoffeeMachine037_Body_vis"/>
        <mesh file="visuals/CoffeeMachine037_Button5.obj" name="CoffeeMachine037_Button5_vis"/>
        <mesh file="visuals/CoffeeMachine037_Lid1.obj" name="CoffeeMachine037_Lid1_vis"/>
        <mesh file="visuals/CoffeeMachine037_Button1.obj" name="CoffeeMachine037_Button1_vis"/>
        <mesh file="visuals/CoffeeMachine037_Button2.obj" name="CoffeeMachine037_Button2_vis"/>
        <texture file="visuals/T_CoffeeMachine037_BaseColor.png" name="T_CoffeeMachine037_BaseColor" type="2d"/>
        <material name="material" rgba="1 1 1 1" texture="T_CoffeeMachine037_BaseColor"/>
    </asset>
    <default>
        <default class="visual">
            <geom conaffinity="0" contype="0" group="1" type="mesh"/>
        </default>
        <default class="collision">
            <geom group="0" rgba="0.5 0 0 0.5"/>
        </default>
    </default>
    <worldbody>
        <body>
            <site rgba="0 0 0 1" size="0.01" pos="-0.18890488520264626 -0.17804184928536415 0" name="ext_p0"/>
            <site rgba="1 0 0 1" size="0.01" pos="0.22668686136603355 -0.17804184928536415 0" name="ext_px"/>
            <site rgba="0 1 0 1" size="0.01" pos="-0.18890488520264626 0.20051636919379234 0" name="ext_py"/>
            <site rgba="0 0 1 1" size="0.01" pos="-0.18890488520264626 -0.17804184928536415 0.49858927726745605" name="ext_pz"/>
            <body name="object">
                <geom mesh="CoffeeMachine037_Body_vis" type="mesh" solimp="0.998 0.998 0.001" solref="0.001 1" density="100" friction="0.95 0.3 0.1" class="visual" material="material"/>
                <geom class="collision" type="box" pos="-7.450580596923828e-09 0.11712385714054108 0.21331138908863068" size="0.09200504422187805 0.17657111585140228 0.20646260678768158" quat="0.7071067094802856 -5.760115939779098e-08 5.7601170055932016e-08 -0.7071068286895752"/>
                <geom class="collision" type="cylinder" pos="-0.06915999948978424 -0.010071039199829102 0.43034154176712036" size="0.09377652406692505 0.03622247278690338" quat="0.7071067094802856 -5.760115939779098e-08 5.7601170055932016e-08 -0.7071068286895752"/>
                <geom class="collision" type="box" pos="0.031026393175125122 0.0001581236720085144 0.3535173833370209" size="0.06613679230213165 0.15795257687568665 0.14841333031654358" quat="0.5000000596046448 0.5 0.5 -0.4999999701976776"/>
                <geom class="collision" type="cylinder" pos="0.07184287160634995 -0.06307458132505417 0.24776992201805115" size="0.05423872172832489 0.017365753650665283" quat="0.7071067094802856 -5.760115939779098e-08 5.7601170055932016e-08 -0.7071068286895752"/>
                <geom class="collision" type="box" pos="0.012509552761912346 0.018315693363547325 0.03299838304519653" size="0.026515210047364235 0.18908068537712097 0.1965922713279724" quat="0.5000000596046448 0.5 0.5 -0.4999999701976776"/>
                <geom class="collision" type="cylinder" pos="0.14796237647533417 -0.09701526165008545 0.26734375953674316" size="0.007268548011779785 0.029782891273498535" quat="0.7071067094802856 -5.760115939779098e-08 5.7601170055932016e-08 -0.7071068286895752"/>
                <geom class="collision" type="cylinder" pos="-0.05092264711856842 -0.06307457387447357 0.250214546918869" size="0.04452543705701828 0.06124719977378845" quat="0.7071067094802856 -5.760115939779098e-08 5.7601170055932016e-08 -0.7071068286895752"/>
                <geom class="collision" type="cylinder" pos="-0.13530653715133667 -0.06307458877563477 0.27326783537864685" size="0.03567936271429062 0.03428999334573746" quat="0.7071067094802856 -5.760115939779098e-08 5.7601170055932016e-08 -0.7071068286895752"/>
                <geom class="collision" name="start_button" type="cylinder" pos="-0.12183962762355804 -0.1601928323507309 0.3548138737678528" size="0.011778442189097404 0.002037472790107131" quat="0.42773404717445374 -0.5630662441253662 -0.5630661249160767 -0.4277341365814209"/>
                <body name="CoffeeMachine037_Button1">
                    <joint axis="0 1 0" pos="-0.121754951775074 -0.1594868153333664 0.35501518845558167" limited="true" name="CoffeeMachine037_Button1_joint" range="0.0 0.003" type="slide" damping="2" frictionloss="2" armature=".01"/>
                    <geom mesh="CoffeeMachine037_Button1_vis" type="mesh" solimp="0.998 0.998 0.001" solref="0.001 1" density="100" friction="0.95 0.3 0.1" class="visual" material="material"/>
                    <geom class="collision" type="cylinder" pos="-0.12183962762355804 -0.1601928323507309 0.3548138737678528" size="0.011778442189097404 0.002037472790107131" quat="0.42773404717445374 -0.5630662441253662 -0.5630661249160767 -0.4277341365814209"/>
                </body>
                <body name="CoffeeMachine037_Button2">
                    <joint axis="0 1 0" pos="-0.045459531247615814 -0.159552663564682 0.3550325334072113" limited="true" name="CoffeeMachine037_Button2_joint" range="0.0 0.003" type="slide" damping="2" frictionloss="2" armature=".01"/>
                    <geom mesh="CoffeeMachine037_Button2_vis" type="mesh" solimp="0.998 0.998 0.001" solref="0.001 1" density="100" friction="0.95 0.3 0.1" class="visual" material="material"/>
                    <geom class="collision" type="cylinder" pos="-0.04571245610713959 -0.1601928323507309 0.3548138737678528" size="0.011778442189097404 0.002037472790107131" quat="0.42773404717445374 -0.5630662441253662 -0.5630661249160767 -0.4277341365814209"/>
                </body>
                <body name="CoffeeMachine037_Button3">
                    <joint axis="0 1 0" pos="0.06703980267047882 -0.15954218804836273 0.35501620173454285" limited="true" name="CoffeeMachine037_Button3_joint" range="0.0 0.003" type="slide" damping="2" frictionloss="2" armature=".01"/>
                    <geom mesh="CoffeeMachine037_Button3_vis" type="mesh" solimp="0.998 0.998 0.001" solref="0.001 1" density="100" friction="0.95 0.3 0.1" class="visual" material="material"/>
                    <geom class="collision" type="cylinder" pos="0.06705833226442337 -0.1601928323507309 0.3548138737678528" size="0.011778442189097404 0.002037472790107131" quat="0.42773404717445374 -0.5630662441253662 -0.5630661249160767 -0.4277341365814209"/>
                </body>
                <body name="CoffeeMachine037_Button4">
                    <joint axis="0 1 0" pos="0.10518711060285568 -0.1599181443452835 0.3551241159439087" limited="true" name="CoffeeMachine037_Button4_joint" range="0.0 0.003" type="slide" damping="2" frictionloss="2" armature=".01"/>
                    <geom mesh="CoffeeMachine037_Button4_vis" type="mesh" solimp="0.998 0.998 0.001" solref="0.001 1" density="100" friction="0.95 0.3 0.1" class="visual" material="material"/>
                    <geom class="collision" type="cylinder" pos="0.105195552110672 -0.1601928472518921 0.3548138737678528" size="0.011778442189097404 0.002037472790107131" quat="0.42773404717445374 -0.5630662441253662 -0.5630661249160767 -0.4277341365814209"/>
                </body>
                <body name="CoffeeMachine037_Button5">
                    <joint axis="0 1 0" pos="0.14333473145961761 -0.1594523936510086 0.3549923300743103" limited="true" name="CoffeeMachine037_Button5_joint" range="0.0 0.003" type="slide" damping="2" frictionloss="2" armature=".01"/>
                    <geom mesh="CoffeeMachine037_Button5_vis" type="mesh" solimp="0.998 0.998 0.001" solref="0.001 1" density="100" friction="0.95 0.3 0.1" class="visual" material="material"/>
                    <geom class="collision" type="cylinder" pos="0.14318105578422546 -0.1601928174495697 0.3548138737678528" size="0.011778442189097404 0.002037472790107131" quat="0.42773404717445374 -0.5630662441253662 -0.5630661249160767 -0.4277341365814209"/>
                </body>
                <body name="CoffeeMachine037_Button6">
                    <joint axis="0 1 0" pos="-0.08348812162876129 -0.159552663564682 0.3550325334072113" limited="true" name="CoffeeMachine037_Button6_joint" range="0.0 0.003" type="slide" damping="2" frictionloss="2" armature=".01"/>
                    <geom mesh="CoffeeMachine037_Button6_vis" type="mesh" solimp="0.998 0.998 0.001" solref="0.001 1" density="100" friction="0.95 0.3 0.1" class="visual" material="material"/>
                    <geom class="collision" type="cylinder" pos="-0.0835803747177124 -0.16129954159259796 0.3554060161113739" size="0.011169712990522385 0.0014693646226078272" quat="0.5557887554168701 0.43714845180511475 0.43714839220046997 -0.5557889342308044"/>
                </body>
                <body name="CoffeeMachine037_Handle">
                    <joint axis="0 0 1" pos="0.16479890048503876 -0.06342162191867828 0.27622392773628235" limited="true" name="CoffeeMachine037_Handle_joint" range="0.0 1.0471975511965976" type="hinge" damping="2" frictionloss="2" armature=".01"/>
                    <geom mesh="CoffeeMachine037_Handle_vis" type="mesh" solimp="0.998 0.998 0.001" solref="0.001 1" density="100" friction="0.95 0.3 0.1" class="visual" material="material"/>
                    <geom class="collision" type="cylinder" pos="0.1828216314315796 -0.1268005669116974 0.14805251359939575" size="0.006428241264075041 0.04978618770837784" quat="0.9825748205184937 -0.12227720767259598 -0.03747636452317238 -0.13487234711647034"/>
                    <geom class="collision" type="cylinder" pos="0.17789243161678314 -0.10504312813282013 0.20977893471717834" size="0.00897189974784851 0.02144424058496952" quat="0.9353113770484924 -0.28616076707839966 -0.12760470807552338 -0.1643826961517334"/>
                    <geom class="collision" type="cylinder" pos="0.1719030886888504 -0.08570639789104462 0.22503095865249634" size="0.00897189974784851 0.02144424244761467" quat="0.8464418649673462 -0.44503793120384216 -0.22242693603038788 -0.1897464543581009"/>
                    <geom class="collision" type="cylinder" pos="0.1659342497587204 -0.06512872129678726 0.2525010108947754" size="0.008971898816525936 0.02144423872232437" quat="0.9767652750015259 0.026906557381153107 -0.05555149167776108 -0.2052306979894638"/>
                </body>
                <body name="CoffeeMachine037_Knob2">
                    <joint axis="0 0 1" pos="-0.159284770488739 -0.041792869567871094 0.35908013582229614" limited="false" name="CoffeeMachine037_Knob2_joint" range="0 360" type="hinge" damping="2" frictionloss="2" armature=".01"/>
                    <geom mesh="CoffeeMachine037_Knob2_vis" type="mesh" solimp="0.998 0.998 0.001" solref="0.001 1" density="100" friction="0.95 0.3 0.1" class="visual" material="material"/>
                    <geom class="collision" type="cylinder" pos="-0.16127806901931763 -0.04199129343032837 0.3590303957462311" size="0.02945457212626934 0.006591290235519409" quat="0.7071067094802856 -5.760115939779098e-08 5.7601170055932016e-08 -0.7071068286895752"/>
                </body>
                <body name="CoffeeMachine037_Knob3">
                    <joint axis="-1 0 0" pos="0.19350193440914154 -0.0772206038236618 0.35277944803237915" limited="true" name="CoffeeMachine037_Knob3_joint" range="0.0 4.1887902047863905" type="hinge" damping="2" frictionloss="2" armature=".01"/>
                    <geom mesh="CoffeeMachine037_Knob3_vis" type="mesh" solimp="0.998 0.998 0.001" solref="0.001 1" density="100" friction="0.95 0.3 0.1" class="visual" material="material"/>
                    <geom class="collision" type="cylinder" pos="0.20478256046772003 -0.07647667825222015 0.35225680470466614" size="0.02072836644947529 0.004638552665710449" quat="0.49999943375587463 -0.5000000596046448 0.500000536441803 -0.4999999403953552"/>
                </body>
                <body name="CoffeeMachine037_Lid1">
                    <joint axis="0 0 1" pos="-0.06929945200681686 -0.009897475130856037 0.4772985577583313" limited="true" name="CoffeeMachine037_Lid1_joint" range="0.0 0.02" type="slide" damping="2" frictionloss="2" armature=".01"/>
                    <geom mesh="CoffeeMachine037_Lid1_vis" type="mesh" solimp="0.998 0.998 0.001" solref="0.001 1" density="100" friction="0.95 0.3 0.1" class="visual" material="material"/>
                    <geom class="collision" type="cylinder" pos="-0.06915998458862305 -0.010071039199829102 0.492418497800827" size="0.09377652406692505 0.005735293030738831" quat="0.7071067094802856 -5.760115939779098e-08 5.7601170055932016e-08 -0.7071068286895752"/>
                </body>
                <body name="CoffeeMachine037_Lid2">
                    <joint axis="0 0 1" pos="7.2254326966003646e-09 -0.0748363509774208 0.06472651660442352" limited="true" name="CoffeeMachine037_Lid2_joint" range="0.0 0.02" type="slide" damping="2" frictionloss="2" armature=".01"/>
                    <geom mesh="CoffeeMachine037_Lid2_vis" type="mesh" solimp="0.998 0.998 0.001" solref="0.001 1" density="100" friction="0.95 0.3 0.1" class="visual" material="material"/>
                    <geom class="collision" type="box" pos="0.0114322230219841 -0.07151975482702255 0.06525687873363495" size="0.003789817914366722 0.16714586317539215 0.0705186054110527" quat="0.5000000596046448 0.5 0.5 -0.4999999701976776"/>
                </body>
                <body name="CoffeeMachine037_Lid3">
                    <joint axis="1 0 0" pos="0.012021987698972225 0.09259312599897385 0.41278892755508423" limited="true" name="CoffeeMachine037_Lid3_joint" range="0.0 1.5707963267948966" type="hinge" damping="2" frictionloss="2" armature=".01"/>
                    <geom mesh="CoffeeMachine037_Lid3_vis" type="mesh" solimp="0.998 0.998 0.001" solref="0.001 1" density="100" friction="0.95 0.3 0.1" class="visual" material="material"/>
                    <geom class="collision" type="box" pos="0.015755614265799522 0.1347399801015854 0.4057602286338806" size="0.185106456 0.042519983 0.01225509" quat="1.0 0.0 0.0 0.0"/>
                </body>
                <site rgba="0 0 0 0" size="0.01" pos="-0.0497917 -0.0641573 0.070714" name="receptacle_place_site"/>                
                <site rgba="0.8 0.5 0.25 1" size="0.006 0.08" pos="-0.0497917 -0.0641573 0.150714" type="cylinder" name="coffee_liquid_left"/>
                <site rgba="0.8 0.5 0.25 1" size="0.006 0.08" pos="0.0719176 -0.0641573 0.150714" type="cylinder" name="coffee_liquid_right"/>

            </body>
        </body>
    </worldbody>
</mujoco>
