<mujoco model="model">
  <compiler angle="radian"/>
  <asset>
    <mesh file="visuals/Body001.obj" name="Body001_vis"/>
    <mesh file="visuals/Body002_Clear.obj" name="Body002_Clear_vis"/>
    <mesh file="visuals/Door001.obj" name="Door001_vis"/>
    <mesh file="visuals/Door001_Clear.obj" name="Door001_Clear_vis"/>
    <mesh file="visuals/Door002.obj" name="Door002_vis"/>
    <mesh file="visuals/Door002_Clear.obj" name="Door002_Clear_vis"/>
    <mesh file="visuals/Drawer001.obj" name="Drawer001_vis"/>
    <mesh file="visuals/Drawer002.obj" name="Drawer002_vis"/>
    <mesh file="visuals/Drawer003.obj" name="Drawer003_vis"/>
    <mesh file="visuals/Drawer004.obj" name="Drawer004_vis"/>
    <mesh file="visuals/Drawer005.obj" name="Drawer005_vis"/>
    <mesh file="visuals/Drawer006.obj" name="Drawer006_vis"/>
    <mesh file="visuals/Drawer007.obj" name="Drawer007_vis"/>
    <texture file="visuals/T_BC001.png" name="Body001_material" type="2d"/>
    <material name="Body001_material" rgba="1 1 1 1.0" texture="Body001_material" shininess="0.7228040099143982" specular="0.8"/>
    <texture file="visuals/T_BC001.png" name="Body002_Clear_material" type="2d"/>
    <material name="Body002_Clear_material" rgba="1 1 1 0.4251968264579773" texture="Body002_Clear_material" shininess="0.5" specular="0.8"/>
    <texture file="visuals/T_BC001.png" name="Door001_material" type="2d"/>
    <material name="Door001_material" rgba="1 1 1 1.0" texture="Door001_material" shininess="0.7228040099143982" specular="0.8"/>
    <texture file="visuals/T_BC001.png" name="Door001_Clear_material" type="2d"/>
    <material name="Door001_Clear_material" rgba="1 1 1 0.4251968264579773" texture="Door001_Clear_material" shininess="0.5" specular="0.8"/>
    <texture file="visuals/T_BC001.png" name="Door002_material" type="2d"/>
    <material name="Door002_material" rgba="1 1 1 1.0" texture="Door002_material" shininess="0.7228040099143982" specular="0.8"/>
    <texture file="visuals/T_BC001.png" name="Door002_Clear_material" type="2d"/>
    <material name="Door002_Clear_material" rgba="1 1 1 0.4251968264579773" texture="Door002_Clear_material" shininess="0.5" specular="0.8"/>
    <texture file="visuals/T_BC001.png" name="Drawer001_material" type="2d"/>
    <material name="Drawer001_material" rgba="1 1 1 1.0" texture="Drawer001_material" shininess="0.7228040099143982" specular="0.8"/>
    <texture file="visuals/T_BC001.png" name="Drawer002_material" type="2d"/>
    <material name="Drawer002_material" rgba="1 1 1 1.0" texture="Drawer002_material" shininess="0.7228040099143982" specular="0.8"/>
    <texture file="visuals/T_BC001.png" name="Drawer003_material" type="2d"/>
    <material name="Drawer003_material" rgba="1 1 1 1.0" texture="Drawer003_material" shininess="0.7228040099143982" specular="0.8"/>
    <texture file="visuals/T_BC001.png" name="Drawer004_material" type="2d"/>
    <material name="Drawer004_material" rgba="1 1 1 1.0" texture="Drawer004_material" shininess="0.7228040099143982" specular="0.8"/>
    <texture file="visuals/T_BC001.png" name="Drawer005_material" type="2d"/>
    <material name="Drawer005_material" rgba="1 1 1 1.0" texture="Drawer005_material" shininess="0.7228040099143982" specular="0.8"/>
    <texture file="visuals/T_BC001.png" name="Drawer006_material" type="2d"/>
    <material name="Drawer006_material" rgba="1 1 1 1.0" texture="Drawer006_material" shininess="0.7228040099143982" specular="0.8"/>
    <texture file="visuals/T_BC001.png" name="Drawer007_material" type="2d"/>
    <material name="Drawer007_material" rgba="1 1 1 1.0" texture="Drawer007_material" shininess="0.7228040099143982" specular="0.8"/>
  </asset>
  <default>
    <default class="visual">
      <geom conaffinity="0" contype="0" group="1" type="mesh"/>
    </default>
    <default class="collision">
      <geom group="0" rgba="0.5 0 0 0.5"/>
    </default>
    <default class="spawn">
      <geom group="0" rgba="1 1 1 0.5" contype="0" conaffinity="0"/>
      <site group="0" rgba="1 1 1 0.5"/>
    </default>
    <default class="region">
      <geom group="1" conaffinity="0" contype="0" rgba="0 1 0 0"/>
    </default>
  </default>
  <worldbody>
    <body>
      <body name="object">
        <geom mesh="Body001_vis" type="mesh" solimp="0.998 0.998 0.001" solref="0.001 1" density="100" friction="0.95 0.3 0.1" class="visual" material="Body001_material"/>
        <geom class="collision" type="box" pos="0.18959122896194458 0.05818253755569458 0.8799152970314026" size="0.25953567028045654 0.3990899324417114 0.05621796101331711" quat="1.0 0.0 0.0 0.0"/>
        <geom class="collision" type="box" pos="0.0009982611518353224 0.441756010055542 0.00017643740284256637" size="0.4481288194656372 0.017898576334118843 0.9475670456886292" quat="1.0 0.0 0.0 0.0"/>
        <geom class="collision" type="box" pos="0.43895646929740906 0.058436278253793716 0.00017643740284256637" size="0.016016868874430656 0.40141767263412476 0.9475670456886292" quat="1.0 0.0 0.0 0.0"/>
        <geom class="collision" type="box" pos="-0.43486931920051575 0.058436278253793716 0.00017643740284256637" size="0.019876092672348022 0.40132734179496765 0.9475670456886292" quat="1.0 0.0 0.0 0.0"/>
        <geom class="collision" type="box" pos="2.7887028409168124e-05 0.02747405506670475 0.9344571232795715" size="0.45497027039527893 0.42980894446372986 0.01511151809245348" quat="1.0 0.0 0.0 0.0"/>
        <geom class="collision" type="box" pos="-0.07548540085554123 0.051525041460990906 -0.006091429386287928" size="0.024132326245307922 0.39910051226615906 0.9200156331062317" quat="1.0 0.0 0.0 0.0"/>
        <geom class="collision" type="box" pos="-0.2629220485687256 0.09088116884231567 -0.6056009531021118" size="0.173197403550148 0.35974442958831787 0.007823126390576363" quat="1.0 0.0 0.0 0.0"/>
        <geom class="collision" type="box" pos="-0.2629220485687256 0.09088116884231567 -0.3593347370624542" size="0.173197403550148 0.35974442958831787 0.0078231580555439" quat="1.0 0.0 0.0 0.0"/>
        <geom class="collision" type="box" pos="0.18642672896385193 0.1124727874994278 -0.21790079772472382" size="0.24038416147232056 0.2969996929168701 0.007823126390576363" quat="1.0 0.0 0.0 0.0"/>
        <geom class="collision" type="box" pos="0.18693335354328156 0.07380534708499908 -0.4156833589076996" size="0.24089078605175018 0.3356671631336212 0.0078231580555439" quat="1.0 0.0 0.0 0.0"/>
        <geom class="collision" type="box" pos="0.18693335354328156 0.07380534708499908 -0.6221714615821838" size="0.24089078605175018 0.3356671631336212 0.0078230956569314" quat="1.0 0.0 0.0 0.0"/>
        <geom class="collision" type="box" pos="0.41454946994781494 0.07198478281497955 0.008693575859069824" size="0.009805545210838318 0.2760608196258545 0.005919968243688345" quat="1.0 0.0 0.0 0.0"/>
        <geom class="collision" type="box" pos="-0.04574844613671303 0.07198478281497955 0.008693575859069824" size="0.009805545210838318 0.2760608196258545 0.005919968243688345" quat="1.0 0.0 0.0 0.0"/>
        <geom class="collision" type="box" pos="0.41454946994781494 0.07198478281497955 0.49186912178993225" size="0.009805545210838318 0.2760608196258545 0.005919968243688345" quat="1.0 0.0 0.0 0.0"/>
        <geom class="collision" type="box" pos="-0.04574844613671303 0.07198478281497955 0.49186912178993225" size="0.009805545210838318 0.2760608196258545 0.005919968243688345" quat="1.0 0.0 0.0 0.0"/>
        <geom class="collision" type="box" pos="-0.41330641508102417 0.07198478281497955 0.49315911531448364" size="0.009805545210838318 0.2760608196258545 0.005919968243688345" quat="1.0 0.0 0.0 0.0"/>
        <geom class="collision" type="box" pos="-0.10852186381816864 0.07198478281497955 0.49315911531448364" size="0.009805545210838318 0.2760608196258545 0.005919968243688345" quat="1.0 0.0 0.0 0.0"/>
        <geom class="collision" type="box" pos="-0.41330641508102417 0.07198478281497955 0.1717570573091507" size="0.009805545210838318 0.2760608196258545 0.005919968243688345" quat="1.0 0.0 0.0 0.0"/>
        <geom class="collision" type="box" pos="-0.10852186381816864 0.07198478281497955 0.1717570573091507" size="0.009805545210838318 0.2760608196258545 0.005919968243688345" quat="1.0 0.0 0.0 0.0"/>
        <geom class="collision" type="box" pos="-0.2563979923725128 0.05500462278723717 0.894343912601471" size="0.19848524034023285 0.4022783935070038 0.023743778467178345" quat="1.0 0.0 0.0 0.0"/>
        <geom class="collision" type="box" pos="0.1960643231868744 0.055109333246946335 0.8699206709861755" size="0.25683850049972534 0.4021736681461334 0.04816699028015137" quat="1.0 0.0 0.0 0.0"/>
        <geom class="collision" type="box" pos="0.00016309466445818543 0.054992955178022385 -0.8944204449653625" size="0.4533558487892151 0.4022900462150574 0.05515366047620773" quat="1.0 0.0 0.0 0.0"/>
        <geom class="collision" type="box" pos="0.4252990186214447 -0.3605630397796631 -0.9116199612617493" size="0.029702335596084595 0.020007407292723656 0.03795410320162773" quat="1.0 0.0 0.0 0.0"/>
        <geom class="collision" type="box" pos="-0.4254184067249298 -0.36056995391845703 -0.9115289449691772" size="0.02944943681359291 0.020014313980937004 0.03804513439536095" quat="1.0 0.0 0.0 0.0"/>
        <body name="Body002_Clear">
          <geom mesh="Body002_Clear_vis" type="mesh" solimp="0.998 0.998 0.001" solref="0.001 1" density="100" friction="0.95 0.3 0.1" class="visual" material="Body002_Clear_material"/>
          <geom class="collision" type="box" pos="-0.2619285583496094 0.06612826883792877 0.5065506100654602" size="0.16020195186138153 0.333356648683548 0.005285886116325855" quat="1.0 0.0 0.0 0.0"/>
          <geom class="collision" type="box" pos="-0.2616431713104248 0.06542140245437622 0.18752165138721466" size="0.15750616788864136 0.3326497972011566 0.005285938736051321" quat="1.0 0.0 0.0 0.0"/>
          <geom class="collision" type="box" pos="-0.2616431713104248 0.06542140245437622 -0.13954026997089386" size="0.15750616788864136 0.3326497972011566 0.005285931285470724" quat="1.0 0.0 0.0 0.0"/>
          <geom class="collision" type="box" pos="0.18476395308971405 0.06817471981048584 0.507149875164032" size="0.23851679265499115 0.3253078758716583 0.005285946186631918" quat="1.0 0.0 0.0 0.0"/>
          <geom class="collision" type="box" pos="0.18921372294425964 0.06817471981048584 0.022501319646835327" size="0.23514129221439362 0.3253078758716583 0.005285938736051321" quat="1.0 0.0 0.0 0.0"/>
        </body>
        <body name="Door001">
          <joint axis="0.0 0.0 -1.0" pos="-0.42675527930259705 -0.37689897418022156 0.09781890362501144" limited="true" name="Door001_joint" range="0.0 1.5707963267948966" type="hinge" damping="1" frictionloss="1" armature=".01" stiffness="0.05"/>
          <geom mesh="Door001_vis" type="mesh" solimp="0.998 0.998 0.001" solref="0.001 1" density="100" friction="0.95 0.3 0.1" class="visual" material="Door001_material"/>
          <geom class="collision" type="box" pos="-0.2666842043399811 -0.3823644518852234 0.025255579501390457" size="0.18504276871681213 0.018424075096845627 0.8917039632797241" quat="1.0 0.0 0.0 0.0"/>
          <geom class="collision" type="cylinder" pos="-0.12591570615768433 -0.44454118609428406 0.1299496442079544" size="0.015802860260009766 0.43129029870033264" quat="1.0 0.0 0.0 0.0"/>
          <geom class="collision" type="cylinder" pos="-0.12559297680854797 -0.42110177874565125 0.45060014724731445" size="0.01046145148575306 0.020187530666589737" quat="0.7071068286895752 0.7071067690849304 0.0 0.0"/>
          <geom class="collision" type="cylinder" pos="-0.12559297680854797 -0.42110177874565125 -0.1980651170015335" size="0.01046145148575306 0.020187530666589737" quat="0.7071068286895752 0.7071067690849304 0.0 0.0"/>
          <geom class="collision" type="box" pos="-0.26776042580604553 -0.3837219476699829 0.11726395040750504" size="0.15611831843852997 0.018424078822135925 0.12318645417690277" quat="1.0 0.0 0.0 0.0"/>
          <body name="Door001_Clear">
            <geom mesh="Door001_Clear_vis" type="mesh" solimp="0.998 0.998 0.001" solref="0.001 1" density="100" friction="0.95 0.3 0.1" class="visual" material="Door001_Clear_material"/>
            <geom class="collision" type="box" pos="-0.2667202651500702 -0.31501370668411255 0.5385845899581909" size="0.14274582266807556 0.032504741102457047 0.0022371821105480194" quat="1.0 0.0 0.0 0.0"/>
            <geom class="collision" type="box" pos="-0.2667202651500702 -0.28473934531211853 0.5720432996749878" size="0.14274582266807556 0.002237152075394988 0.03250475972890854" quat="1.0 0.0 0.0 0.0"/>
            <geom class="collision" type="box" pos="-0.2667202651500702 -0.3451758623123169 0.5720432996749878" size="0.14274582266807556 0.0022371369414031506 0.03250475972890854" quat="1.0 0.0 0.0 0.0"/>
            <geom class="collision" type="box" pos="-0.4093172252178192 -0.31463563442230225 0.5720432996749878" size="0.002237200504168868 0.0322568453848362 0.03250475972890854" quat="1.0 0.0 0.0 0.0"/>
            <geom class="collision" type="box" pos="-0.12592120468616486 -0.31463563442230225 0.5720432996749878" size="0.0022371828090399504 0.0322568453848362 0.03250475972890854" quat="1.0 0.0 0.0 0.0"/>
            <geom class="collision" type="box" pos="-0.12592120468616486 -0.31463563442230225 0.35271555185317993" size="0.0022371828090399504 0.0322568453848362 0.03250477463006973" quat="1.0 0.0 0.0 0.0"/>
            <geom class="collision" type="box" pos="-0.4093172252178192 -0.31463563442230225 0.35271555185317993" size="0.002237200504168868 0.0322568453848362 0.03250477463006973" quat="1.0 0.0 0.0 0.0"/>
            <geom class="collision" type="box" pos="-0.2667202651500702 -0.3451758623123169 0.35271555185317993" size="0.14274582266807556 0.0022371369414031506 0.03250477463006973" quat="1.0 0.0 0.0 0.0"/>
            <geom class="collision" type="box" pos="-0.2667202651500702 -0.28473934531211853 0.35271555185317993" size="0.14274582266807556 0.002237152075394988 0.03250477463006973" quat="1.0 0.0 0.0 0.0"/>
            <geom class="collision" type="box" pos="-0.2667202651500702 -0.31501370668411255 0.31925681233406067" size="0.14274582266807556 0.032504741102457047 0.002237152075394988" quat="1.0 0.0 0.0 0.0"/>
            <geom class="collision" type="box" pos="-0.12592120468616486 -0.31463563442230225 0.10848008096218109" size="0.0022371828090399504 0.0322568453848362 0.03250475600361824" quat="1.0 0.0 0.0 0.0"/>
            <geom class="collision" type="box" pos="-0.4093172252178192 -0.31463563442230225 0.10848008096218109" size="0.002237200504168868 0.0322568453848362 0.03250475600361824" quat="1.0 0.0 0.0 0.0"/>
            <geom class="collision" type="box" pos="-0.2667202651500702 -0.3451758623123169 0.10848008096218109" size="0.14274582266807556 0.0022371369414031506 0.03250475600361824" quat="1.0 0.0 0.0 0.0"/>
            <geom class="collision" type="box" pos="-0.2667202651500702 -0.28473934531211853 0.10848008096218109" size="0.14274582266807556 0.002237152075394988 0.03250475600361824" quat="1.0 0.0 0.0 0.0"/>
            <geom class="collision" type="box" pos="-0.2667202651500702 -0.31501370668411255 0.07502136379480362" size="0.14274582266807556 0.032504741102457047 0.0022371294908225536" quat="1.0 0.0 0.0 0.0"/>
            <geom class="collision" type="box" pos="-0.2667202651500702 -0.28473934531211853 0.45979422330856323" size="0.14274582266807556 0.002237152075394988 0.019442621618509293" quat="1.0 0.0 0.0 0.0"/>
            <geom class="collision" type="box" pos="-0.2667202651500702 -0.3451758623123169 0.45979422330856323" size="0.14274582266807556 0.0022371369414031506 0.019442621618509293" quat="1.0 0.0 0.0 0.0"/>
            <geom class="collision" type="box" pos="-0.4093172252178192 -0.31463563442230225 0.45979422330856323" size="0.002237200504168868 0.0322568453848362 0.019442621618509293" quat="1.0 0.0 0.0 0.0"/>
            <geom class="collision" type="box" pos="-0.12592120468616486 -0.31463563442230225 0.45979422330856323" size="0.0022371828090399504 0.0322568453848362 0.019442621618509293" quat="1.0 0.0 0.0 0.0"/>
          </body>
        </body>
        <body name="Door002">
          <joint axis="0.0 0.0 1.0" pos="0.42672601342201233 -0.37495362758636475 0.0996796116232872" limited="true" name="Door002_joint" range="0.0 1.5707963267948966" type="hinge" damping="1" frictionloss="1" armature=".01" stiffness="0.05"/>
          <geom mesh="Door002_vis" type="mesh" solimp="0.998 0.998 0.001" solref="0.001 1" density="100" friction="0.95 0.3 0.1" class="visual" material="Door002_material"/>
          <geom class="collision" type="cylinder" pos="-0.03658199682831764 -0.42110177874565125 -0.1980651170015335" size="0.010461447760462761 0.020187530666589737" quat="0.7071068286895752 0.7071067690849304 0.0 0.0"/>
          <geom class="collision" type="cylinder" pos="-0.037368711084127426 -0.42110177874565125 0.45060014724731445" size="0.010461447760462761 0.020187530666589737" quat="0.7071068286895752 0.7071067690849304 0.0 0.0"/>
          <geom class="collision" type="cylinder" pos="-0.036718107759952545 -0.444355309009552 0.1299496442079544" size="0.015873899683356285 0.43129029870033264" quat="1.0 0.0 0.0 0.0"/>
          <geom class="collision" type="box" pos="0.18605169653892517 -0.3823644518852234 0.025255579501390457" size="0.2619800567626953 0.018424075096845627 0.8917039632797241" quat="1.0 0.0 0.0 0.0"/>
          <body name="Door002_Clear">
            <geom mesh="Door002_Clear_vis" type="mesh" solimp="0.998 0.998 0.001" solref="0.001 1" density="100" friction="0.95 0.3 0.1" class="visual" material="Door002_Clear_material"/>
            <geom class="collision" type="box" pos="0.19549089670181274 -0.31043457984924316 0.023607749491930008" size="0.16924677789211273 0.03708387166261673 0.0022371350787580013" quat="1.0 0.0 0.0 0.0"/>
            <geom class="collision" type="box" pos="0.19549089670181274 -0.27558109164237976 0.06264669448137283" size="0.16924677789211273 0.002237121807411313 0.0380849726498127" quat="1.0 0.0 0.0 0.0"/>
            <geom class="collision" type="box" pos="0.19549089670181274 -0.3451758623123169 0.06264668703079224" size="0.16924677789211273 0.0022371369414031506 0.0380849726498127" quat="1.0 0.0 0.0 0.0"/>
            <geom class="collision" type="box" pos="0.026393001899123192 -0.31005650758743286 0.06264669448137283" size="0.00223718723282218 0.03683596849441528 0.038084980100393295" quat="1.0 0.0 0.0 0.0"/>
            <geom class="collision" type="box" pos="0.3627909719944 -0.31005650758743286 0.06264669448137283" size="0.0022371828090399504 0.03683596849441528 0.038084980100393295" quat="1.0 0.0 0.0 0.0"/>
            <geom class="collision" type="box" pos="0.19549089670181274 -0.31043457984924316 0.31353986263275146" size="0.16924677789211273 0.03708387166261673 0.002237152075394988" quat="1.0 0.0 0.0 0.0"/>
            <geom class="collision" type="box" pos="0.19549089670181274 -0.27558109164237976 0.3525788187980652" size="0.16924677789211273 0.002237121807411313 0.0380849726498127" quat="1.0 0.0 0.0 0.0"/>
            <geom class="collision" type="box" pos="0.19549089670181274 -0.3451758623123169 0.3525788187980652" size="0.16924677789211273 0.0022371369414031506 0.0380849726498127" quat="1.0 0.0 0.0 0.0"/>
            <geom class="collision" type="box" pos="0.026393001899123192 -0.31005650758743286 0.3525788187980652" size="0.00223718723282218 0.03683596849441528 0.038085002452135086" quat="1.0 0.0 0.0 0.0"/>
            <geom class="collision" type="box" pos="0.3627909719944 -0.31005650758743286 0.3525788187980652" size="0.0022371828090399504 0.03683596849441528 0.038085002452135086" quat="1.0 0.0 0.0 0.0"/>
            <geom class="collision" type="box" pos="0.19549089670181274 -0.31043457984924316 0.6533429622650146" size="0.16924677789211273 0.03708387166261673 0.002237152075394988" quat="1.0 0.0 0.0 0.0"/>
            <geom class="collision" type="box" pos="0.19549089670181274 -0.27558109164237976 0.6923818588256836" size="0.16924677789211273 0.002237121807411313 0.03808498755097389" quat="1.0 0.0 0.0 0.0"/>
            <geom class="collision" type="box" pos="0.19549089670181274 -0.3451758623123169 0.6923818588256836" size="0.16924677789211273 0.0022371369414031506 0.03808498755097389" quat="1.0 0.0 0.0 0.0"/>
            <geom class="collision" type="box" pos="0.026393001899123192 -0.31005650758743286 0.6923818588256836" size="0.00223718723282218 0.03683596849441528 0.03808498755097389" quat="1.0 0.0 0.0 0.0"/>
            <geom class="collision" type="box" pos="0.3627909719944 -0.31005650758743286 0.6923818588256836" size="0.0022371828090399504 0.03683596849441528 0.03808498755097389" quat="1.0 0.0 0.0 0.0"/>
            <geom class="collision" type="box" pos="0.19549089670181274 -0.31043457984924316 0.4631336033344269" size="0.16924677789211273 0.03708387166261673 0.0022371369414031506" quat="1.0 0.0 0.0 0.0"/>
            <geom class="collision" type="box" pos="0.19549088180065155 -0.27558109164237976 0.4855217933654785" size="0.16924677789211273 0.002237121807411313 0.021434303373098373" quat="1.0 0.0 0.0 0.0"/>
            <geom class="collision" type="box" pos="0.19549089670181274 -0.3451758623123169 0.4855217933654785" size="0.16924677789211273 0.0022371369414031506 0.021434303373098373" quat="1.0 0.0 0.0 0.0"/>
            <geom class="collision" type="box" pos="0.026393000036478043 -0.31005650758743286 0.4855217933654785" size="0.00223718723282218 0.03683596849441528 0.021434303373098373" quat="1.0 0.0 0.0 0.0"/>
            <geom class="collision" type="box" pos="0.3627909719944 -0.31005650758743286 0.4855217933654785" size="0.0022371828090399504 0.03683596849441528 0.021434303373098373" quat="1.0 0.0 0.0 0.0"/>
          </body>
        </body>
        <body name="Drawer001">
          <joint axis="0.0 -1.0 0.0" pos="-0.24865461885929108 -0.017918430268764496 -0.2642907500267029" limited="true" name="Drawer001_joint" range="0.0 0.4" type="slide" damping="1" frictionloss="1" armature=".01" stiffness="0.05"/>
          <geom mesh="Drawer001_vis" type="mesh" solimp="0.998 0.998 0.001" solref="0.001 1" density="100" friction="0.95 0.3 0.1" class="visual" material="Drawer001_material"/>
          <geom class="collision" type="box" pos="-0.1124996766448021 -0.0050514377653598785 -0.2603358328342438" size="0.009566756896674633 0.2201303094625473 0.08353892713785172" quat="1.0 0.0 0.0 0.0"/>
          <geom class="collision" type="box" pos="-0.24864104390144348 0.2255794107913971 -0.25591346621513367" size="0.14362436532974243 0.011887507513165474 0.07921136915683746" quat="1.0 0.0 0.0 0.0"/>
          <geom class="collision" type="box" pos="-0.2486410290002823 -0.23344916105270386 -0.25946244597435" size="0.143624410033226 0.009566661901772022 0.08273790031671524" quat="1.0 0.0 0.0 0.0"/>
          <geom class="collision" type="box" pos="-0.38250625133514404 -0.0050514377653598785 -0.2603358328342438" size="0.009566735476255417 0.2201305627822876 0.08353901654481888" quat="1.0 0.0 0.0 0.0"/>
          <geom class="collision" type="box" pos="-0.24856066703796387 -0.002395123243331909 -0.32403725385665894" size="0.14448028802871704 0.23951439559459686 0.026976007968187332" quat="1.0 0.0 0.0 0.0"/>
          <geom class="collision" type="box" pos="-0.24868275225162506 -0.25565993785858154 -0.18421171605587006" size="0.14201804995536804 0.01721375808119774 0.005844409577548504" quat="1.0 0.0 0.0 0.0"/>
          <geom class="collision" type="box" pos="-0.24868275225162506 -0.26886311173439026 -0.20266824960708618" size="0.14201804995536804 0.004010598175227642 0.013608235865831375" quat="1.0 0.0 0.0 0.0"/>
        </body>
        <body name="Drawer002">
          <joint axis="0.0 -1.0 0.0" pos="-0.24865461885929108 -0.017918437719345093 -0.5060727596282959" limited="true" name="Drawer002_joint" range="0.0 0.4" type="slide" damping="1" frictionloss="1" armature=".01" stiffness="0.05"/>
          <geom mesh="Drawer002_vis" type="mesh" solimp="0.998 0.998 0.001" solref="0.001 1" density="100" friction="0.95 0.3 0.1" class="visual" material="Drawer002_material"/>
          <geom class="collision" type="box" pos="-0.24832412600517273 -0.002721790224313736 -0.5682692527770996" size="0.1439076066017151 0.23920853435993195 0.026084385812282562" quat="1.0 0.0 0.0 0.0"/>
          <geom class="collision" type="box" pos="-0.38250625133514404 -0.0050514377653598785 -0.5051441192626953" size="0.009566737338900566 0.2201307713985443 0.0865643173456192" quat="1.0 0.0 0.0 0.0"/>
          <geom class="collision" type="box" pos="-0.24864104390144348 -0.23344916105270386 -0.5051441192626953" size="0.14362475275993347 0.00956668145954609 0.0865643247961998" quat="1.0 0.0 0.0 0.0"/>
          <geom class="collision" type="box" pos="-0.24864104390144348 0.2255794107913971 -0.5051442384719849" size="0.14362481236457825 0.01188753917813301 0.08656439930200577" quat="1.0 0.0 0.0 0.0"/>
          <geom class="collision" type="box" pos="-0.1124996766448021 -0.005051407963037491 -0.5051442384719849" size="0.009566771797835827 0.22013099491596222 0.08656442165374756" quat="1.0 0.0 0.0 0.0"/>
          <geom class="collision" type="box" pos="-0.24868275225162506 -0.25565993785858154 -0.42607825994491577" size="0.14201804995536804 0.01721375808119774 0.005844409577548504" quat="1.0 0.0 0.0 0.0"/>
          <geom class="collision" type="box" pos="-0.24868275225162506 -0.26886311173439026 -0.4445347785949707" size="0.14201804995536804 0.004010598175227642 0.013608235865831375" quat="1.0 0.0 0.0 0.0"/>
        </body>
        <body name="Drawer003">
          <joint axis="0.0 -1.0 0.0" pos="-0.24865461885929108 -0.0179184190928936 -0.7452696561813354" limited="true" name="Drawer003_joint" range="0.0 0.4" type="slide" damping="1" frictionloss="1" armature=".01" stiffness="0.05"/>
          <geom mesh="Drawer003_vis" type="mesh" solimp="0.998 0.998 0.001" solref="0.001 1" density="100" friction="0.95 0.3 0.1" class="visual" material="Drawer003_material"/>
          <geom class="collision" type="box" pos="-0.1124996766448021 -0.0050514377653598785 -0.744270384311676" size="0.009566782042384148 0.22013108432292938 0.08656448870897293" quat="1.0 0.0 0.0 0.0"/>
          <geom class="collision" type="box" pos="-0.24864104390144348 0.22570262849330902 -0.744270384311676" size="0.14362499117851257 0.011764447204768658 0.08656449615955353" quat="1.0 0.0 0.0 0.0"/>
          <geom class="collision" type="box" pos="-0.2486410290002823 -0.23344916105270386 -0.744270384311676" size="0.14362505078315735 0.00956670194864273 0.0865645632147789" quat="1.0 0.0 0.0 0.0"/>
          <geom class="collision" type="box" pos="-0.38250625133514404 -0.005051407963037491 -0.744270384311676" size="0.009566779248416424 0.2201313078403473 0.0865645706653595" quat="1.0 0.0 0.0 0.0"/>
          <geom class="collision" type="box" pos="-0.24965235590934753 -0.0050514377653598785 -0.7993665933609009" size="0.12738767266273499 0.22013278305530548 0.01962008886039257" quat="1.0 0.0 0.0 0.0"/>
          <geom class="collision" type="box" pos="-0.24868275225162506 -0.25565993785858154 -0.664338231086731" size="0.14201804995536804 0.01721375808119774 0.005844409577548504" quat="1.0 0.0 0.0 0.0"/>
          <geom class="collision" type="box" pos="-0.24868275225162506 -0.26886311173439026 -0.6827948093414307" size="0.14201804995536804 0.004010598175227642 0.013608235865831375" quat="1.0 0.0 0.0 0.0"/>
        </body>
        <body name="Drawer004">
          <joint axis="0.0 -1.0 0.0" pos="0.17909014225006104 -0.01393619179725647 -0.12423187494277954" limited="true" name="Drawer004_joint" range="0.0 0.4" type="slide" damping="1" frictionloss="1" armature=".01" stiffness="0.05"/>
          <geom mesh="Drawer004_vis" type="mesh" solimp="0.998 0.998 0.001" solref="0.001 1" density="100" friction="0.95 0.3 0.1" class="visual" material="Drawer004_material"/>
          <geom class="collision" type="box" pos="0.1790924072265625 0.00021125003695487976 -0.18357038497924805" size="0.21245886385440826 0.23668673634529114 0.01802760548889637" quat="1.0 0.0 0.0 0.0"/>
          <geom class="collision" type="box" pos="-0.023219138383865356 -0.0018224194645881653 -0.11775030195713043" size="0.011832806281745434 0.2233605533838272 0.07197927683591843" quat="1.0 0.0 0.0 0.0"/>
          <geom class="collision" type="box" pos="0.1793118119239807 -0.22899943590164185 -0.11775030195713043" size="0.21309185028076172 0.0095667140558362 0.07197929918766022" quat="1.0 0.0 0.0 0.0"/>
          <geom class="collision" type="box" pos="0.1796068400144577 0.2255794107913971 -0.11775030940771103" size="0.21338695287704468 0.011887588538229465 0.0719793289899826" quat="1.0 0.0 0.0 0.0"/>
          <geom class="collision" type="box" pos="0.3811049163341522 -0.0018224343657493591 -0.11775030195713043" size="0.011164355091750622 0.22336076200008392 0.07197935879230499" quat="1.0 0.0 0.0 0.0"/>
          <geom class="collision" type="box" pos="0.17867150902748108 -0.24769547581672668 -0.05285760015249252" size="0.2098865509033203 0.01721375808119774 0.005844409577548504" quat="1.0 0.0 0.0 0.0"/>
          <geom class="collision" type="box" pos="0.17867150902748108 -0.2608986496925354 -0.07131413370370865" size="0.2098865509033203 0.004010598175227642 0.013608235865831375" quat="1.0 0.0 0.0 0.0"/>
        </body>
        <body name="Drawer005">
          <joint axis="0.0 -1.0 0.0" pos="0.17909014225006104 -0.01393619179725647 -0.3239293098449707" limited="true" name="Drawer005_joint" range="0.0 0.4" type="slide" damping="1" frictionloss="1" armature=".01" stiffness="0.05"/>
          <geom mesh="Drawer005_vis" type="mesh" solimp="0.998 0.998 0.001" solref="0.001 1" density="100" friction="0.95 0.3 0.1" class="visual" material="Drawer005_material"/>
          <geom class="collision" type="box" pos="0.38029900193214417 -0.0023914948105812073 -0.31967470049858093" size="0.011959402821958065 0.22279174625873566 0.07342226803302765" quat="1.0 0.0 0.0 0.0"/>
          <geom class="collision" type="box" pos="0.17923715710639954 0.22592203319072723 -0.31967470049858093" size="0.21301749348640442 0.011545054614543915 0.07342227548360825" quat="1.0 0.0 0.0 0.0"/>
          <geom class="collision" type="box" pos="0.17923714220523834 -0.22353315353393555 -0.31967470049858093" size="0.2130175083875656 0.00956672616302967 0.07342231273651123" quat="1.0 0.0 0.0 0.0"/>
          <geom class="collision" type="box" pos="-0.02303919568657875 -0.002993490546941757 -0.31967470049858093" size="0.011443853378295898 0.2221900224685669 0.07342233508825302" quat="1.0 0.0 0.0 0.0"/>
          <geom class="collision" type="box" pos="0.1792045384645462 0.0023509636521339417 -0.38352787494659424" size="0.2127467691898346 0.23426400125026703 0.01857742853462696" quat="1.0 0.0 0.0 0.0"/>
          <geom class="collision" type="box" pos="0.17867150902748108 -0.24769547581672668 -0.2522381544113159" size="0.2098865509033203 0.01721375808119774 0.005844409577548504" quat="1.0 0.0 0.0 0.0"/>
          <geom class="collision" type="box" pos="0.17867150902748108 -0.2608986496925354 -0.27069470286369324" size="0.2098865509033203 0.004010598175227642 0.013608235865831375" quat="1.0 0.0 0.0 0.0"/>
        </body>
        <body name="Drawer006">
          <joint axis="0.0 -1.0 0.0" pos="0.17909014225006104 -0.013936210423707962 -0.5233203172683716" limited="true" name="Drawer006_joint" range="0.0 0.4" type="slide" damping="1" frictionloss="1" armature=".01" stiffness="0.05"/>
          <geom mesh="Drawer006_vis" type="mesh" solimp="0.998 0.998 0.001" solref="0.001 1" density="100" friction="0.95 0.3 0.1" class="visual" material="Drawer006_material"/>
          <geom class="collision" type="box" pos="0.1782468557357788 -0.000668700784444809 -0.6006120443344116" size="0.21283270418643951 0.23672060668468475 0.011206978932023048" quat="1.0 0.0 0.0 0.0"/>
          <geom class="collision" type="box" pos="-0.023306122049689293 -0.0050514377653598785 -0.5222383737564087" size="0.011097323149442673 0.2201322317123413 0.08520643413066864" quat="1.0 0.0 0.0 0.0"/>
          <geom class="collision" type="box" pos="0.1771976798772812 -0.22899943590164185 -0.5222383737564087" size="0.2109784632921219 0.009566753171384335 0.08520645648241043" quat="1.0 0.0 0.0 0.0"/>
          <geom class="collision" type="box" pos="0.1771976798772812 0.22527353465557098 -0.5222383737564087" size="0.21097852289676666 0.012517837807536125 0.08520650863647461" quat="1.0 0.0 0.0 0.0"/>
          <geom class="collision" type="box" pos="0.3817988634109497 -0.0050514377653598785 -0.5222383737564087" size="0.011753080412745476 0.2201324999332428 0.0852065160870552" quat="1.0 0.0 0.0 0.0"/>
          <geom class="collision" type="box" pos="0.17867150902748108 -0.2608986496925354 -0.46080681681632996" size="0.2098865509033203 0.004010598175227642 0.013608235865831375" quat="1.0 0.0 0.0 0.0"/>
          <geom class="collision" type="box" pos="0.17867150902748108 -0.24769547581672668 -0.44235026836395264" size="0.2098865509033203 0.01721375808119774 0.005844409577548504" quat="1.0 0.0 0.0 0.0"/>
        </body>
        <body name="Drawer007">
          <joint axis="0.0 -1.0 0.0" pos="0.17909014225006104 -0.01393619179725647 -0.7452696561813354" limited="true" name="Drawer007_joint" range="0.0 0.4" type="slide" damping="1" frictionloss="1" armature=".01" stiffness="0.05"/>
          <geom mesh="Drawer007_vis" type="mesh" solimp="0.998 0.998 0.001" solref="0.001 1" density="100" friction="0.95 0.3 0.1" class="visual" material="Drawer007_material"/>
          <geom class="collision" type="box" pos="0.38074564933776855 -0.0050514377653598785 -0.7437748312950134" size="0.01034089270979166 0.22013254463672638 0.085206538438797" quat="1.0 0.0 0.0 0.0"/>
          <geom class="collision" type="box" pos="0.1771976798772812 0.22513778507709503 -0.7437748312950134" size="0.21097877621650696 0.012329285964369774 0.0852065458893776" quat="1.0 0.0 0.0 0.0"/>
          <geom class="collision" type="box" pos="0.17719770967960358 -0.22899943590164185 -0.7437748312950134" size="0.21097880601882935 0.009566773660480976 0.08520655333995819" quat="1.0 0.0 0.0 0.0"/>
          <geom class="collision" type="box" pos="-0.02313416078686714 -0.0050514377653598785 -0.7437748312950134" size="0.011200624518096447 0.22013279795646667 0.08520662039518356" quat="1.0 0.0 0.0 0.0"/>
          <geom class="collision" type="box" pos="0.17618638277053833 -0.005051452666521072 -0.8052987456321716" size="0.19473621249198914 0.22013284265995026 0.026729857549071312" quat="1.0 0.0 0.0 0.0"/>
          <geom class="collision" type="box" pos="0.17867150902748108 -0.24769547581672668 -0.6643404960632324" size="0.2098865509033203 0.01721375808119774 0.005844409577548504" quat="1.0 0.0 0.0 0.0"/>
          <geom class="collision" type="box" pos="0.17867150902748108 -0.2608986496925354 -0.6827970147132874" size="0.2098865509033203 0.004010598175227642 0.013608235865831375" quat="1.0 0.0 0.0 0.0"/>
        </body>
        <geom class="region" name="reg_main" type="box" pos="0.0 0.028806794434785843 0.0" size="0.4550013542175293 0.4311416745185852 0.9496856927871704"/>
      </body>
    </body>
  </worldbody>
  <actuator>
    <motor name="Door001_joint_actuator" joint="Door001_joint" gear="50"/>
    <motor name="Door002_joint_actuator" joint="Door002_joint" gear="50"/>
    <motor name="Drawer001_joint_actuator" joint="Drawer001_joint" gear="50"/>
    <motor name="Drawer002_joint_actuator" joint="Drawer002_joint" gear="50"/>
    <motor name="Drawer003_joint_actuator" joint="Drawer003_joint" gear="50"/>
    <motor name="Drawer004_joint_actuator" joint="Drawer004_joint" gear="50"/>
    <motor name="Drawer005_joint_actuator" joint="Drawer005_joint" gear="50"/>
    <motor name="Drawer006_joint_actuator" joint="Drawer006_joint" gear="50"/>
    <motor name="Drawer007_joint_actuator" joint="Drawer007_joint" gear="50"/>
  </actuator>
</mujoco>
