<mujoco model="model">
  <compiler angle="radian"/>
  <asset>
    <mesh file="visuals/Body001.obj" name="Body001_vis"/>
    <mesh file="visuals/Button001.obj" name="Button001_vis"/>
    <mesh file="visuals/Button002.obj" name="Button002_vis"/>
    <mesh file="visuals/Container001_Clear.obj" name="Container001_Clear_vis"/>
    <mesh file="visuals/Lid001.obj" name="Lid001_vis"/>
    <mesh file="visuals/Lid002.obj" name="Lid002_vis"/>
    <mesh file="visuals/Lid003.obj" name="Lid003_vis"/>
    <texture file="visuals/T_BC001.png" name="Body001_material" type="2d"/>
    <material name="Body001_material" rgba="1 1 1 1.0" texture="Body001_material" shininess="-0.9999998807907104" specular="0.3103448502657381"/>
    <texture file="visuals/T_BC001.png" name="Button001_material" type="2d"/>
    <material name="Button001_material" rgba="1 1 1 1.0" texture="Button001_material" shininess="-0.9999998807907104" specular="0.3103448502657381"/>
    <texture file="visuals/T_BC001.png" name="Button002_material" type="2d"/>
    <material name="Button002_material" rgba="1 1 1 1.0" texture="Button002_material" shininess="-0.9999998807907104" specular="0.3103448502657381"/>
    <material name="Container001_Clear_material" rgba="0.800000011920929 0.800000011920929 0.800000011920929 0.060773469507694244" shininess="0.5" specular="0.3103448502657381"/>
    <texture file="visuals/T_BC001.png" name="Lid002_material" type="2d"/>
    <material name="Lid002_material" rgba="1 1 1 1.0" texture="Lid002_material" shininess="-0.9999998807907104" specular="0.3103448502657381"/>
    <texture file="visuals/T_BC001.png" name="Lid001_material" type="2d"/>
    <material name="Lid001_material" rgba="1 1 1 1.0" texture="Lid001_material" shininess="-0.9999998807907104" specular="0.3103448502657381"/>
    <texture file="visuals/T_BC001.png" name="Lid003_material" type="2d"/>
    <material name="Lid003_material" rgba="1 1 1 1.0" texture="Lid003_material" shininess="-0.9999998807907104" specular="0.3103448502657381"/>
  </asset>
  <default>
    <default class="visual">
      <geom conaffinity="0" contype="0" group="1" type="mesh"/>
    </default>
    <default class="collision">
      <geom group="0" rgba="0.5 0 0 0.5"/>
    </default>
    <default class="spawn">
      <geom group="0" rgba="1 1 1 0.5" contype="0" conaffinity="0"/>
      <site group="0" rgba="1 1 1 0.5"/>
    </default>
    <default class="region">
      <geom group="1" conaffinity="0" contype="0" rgba="0 1 0 0"/>
    </default>
  </default>
  <worldbody>
    <body>
      <body name="object">
        <geom class="collision" type="box" pos="0.01941634900867939 -0.12817154824733734 0.12557287514209747" size="0.00528807332739234 0.005288074724376202 0.00032053657923825085" quat="0.7006325721740723 -0.7006320953369141 -0.09546900540590286 0.09546893835067749" name="start_button_2" rgba="0.0 0.5 0 0.5"/>
        <geom class="collision" type="box" pos="-0.018726849928498268 -0.12815983593463898 0.12559442222118378" size="0.005281296093016863 0.00528129655867815 0.00028487719828262925" quat="0.6939712762832642 -0.6939708590507507 0.1356619894504547 -0.13566188514232635" name="start_button_1" rgba="0.0 0.5 0 0.5"/>
        <site type="cylinder" rgba="0.8 0.5 0.25 1" size="0.0026102596893906593 0.06480149179697037" pos="-6.197147740749642e-05 -0.17132879793643951 -0.05961602181196213" name="coffee_liquid"/>
        <site rgba="0 0 0 0" size="0.009999999776482582 0.009999999776482582" pos="0.0 -0.17099815607070923 -0.11491063982248306" name="receptacle_place_site"/>
        <geom mesh="Body001_vis" type="mesh" solimp="0.998 0.998 0.001" solref="0.001 1" density="100" friction="0.95 0.3 0.1" class="visual" material="Body001_material"/>
        <geom class="collision" type="cylinder" pos="-8.454520138911903e-05 0.08543447405099869 -0.004094035364687443" size="0.05943594127893448 0.1380547285079956" quat="1.0 0.0 0.0 0.0"/>
        <geom class="collision" type="cylinder" pos="-7.092425948940217e-05 -0.06774568557739258 -0.02443147636950016" size="0.06067289412021637 0.12002754956483841" quat="1.0 0.0 0.0 0.0"/>
        <geom class="collision" type="box" pos="0.04128960520029068 0.017888452857732773 0.11496768891811371" size="0.019130084663629532 0.10068270564079285 0.01811387576162815" quat="1.0 0.0 0.0 0.0"/>
        <geom class="collision" type="box" pos="-0.00013091738219372928 0.026476863771677017 -0.021638162434101105" size="0.06055061146616936 0.0920943021774292 0.12082803249359131" quat="1.0 0.0 0.0 0.0"/>
        <geom class="collision" type="box" pos="-0.0433063879609108 -0.08254817128181458 0.11496768891811371" size="0.013925363309681416 0.02177164889872074 0.01811387576162815" quat="0.9832549095153809 0.0 0.0 0.18223552405834198"/>
        <geom class="collision" type="box" pos="0.01800953410565853 -0.12805090844631195 0.042651161551475525" size="0.00665710773319006 0.01646968349814415 0.008929953910410404" quat="1.0 0.0 0.0 0.0"/>
        <geom class="collision" type="box" pos="0.0030271776486188173 0.048953305929899216 0.11488841474056244" size="0.0400843545794487 0.03352620452642441 0.01803458295762539" quat="1.0 0.0 0.0 0.0"/>
        <geom class="collision" type="box" pos="0.0030271776486188173 -0.06283143162727356 0.11256686598062515" size="0.0400843545794487 0.039562687277793884 0.01571306213736534" quat="1.0 0.0 0.0 0.0"/>
        <geom class="collision" type="box" pos="-0.02219565212726593 -0.10621590167284012 0.11496768891811371" size="0.013004411943256855 0.02177165262401104 0.01811387576162815" quat="0.8338857889175415 0.0 0.0 0.5519370436668396"/>
        <geom class="collision" type="box" pos="0.011333885602653027 -0.11084999889135361 0.11496768891811371" size="0.01349582802504301 0.02177164889872074 0.01811387576162815" quat="0.6293203830718994 0.0 0.0 0.7771459817886353"/>
        <geom class="collision" type="box" pos="0.037600286304950714 -0.09386398643255234 0.11496768891811371" size="0.013586108572781086 0.02177164889872074 0.01811387576162815" quat="0.2923716604709625 0.0 0.0 0.9563047885894775"/>
        <geom class="collision" type="cylinder" pos="-0.0009556879522278905 0.16287311911582947 -0.10906794667243958" size="0.06066026911139488 0.03334907069802284" quat="1.0 0.0 0.0 0.0"/>
        <geom class="collision" type="cylinder" pos="-7.033193833194673e-05 -0.17143413424491882 0.009215228259563446" size="0.003892710665240884 0.006618843879550695" quat="1.0 0.0 0.0 0.0"/>
        <geom class="collision" type="box" pos="-0.017768489196896553 -0.12805090844631195 0.042651161551475525" size="0.00665710773319006 0.01646968349814415 0.008929953910410404" quat="1.0 0.0 0.0 0.0"/>
        <geom class="collision" type="cylinder" pos="5.911971675232053e-05 -0.1639307141304016 -0.13106895983219147" size="0.05953378975391388 0.009571795351803303" quat="1.0 0.0 0.0 0.0"/>
        <geom class="collision" type="box" pos="-0.0415966734290123 0.026476863771677017 0.11496768891811371" size="0.01939186081290245 0.0920943021774292 0.01811387576162815" quat="1.0 0.0 0.0 0.0"/>
        <geom class="collision" type="cylinder" pos="-7.092472515068948e-05 -0.1613990068435669 0.060232967138290405" size="0.038454651832580566 0.04464395344257355" quat="1.0 0.0 0.0 0.0"/>
        <body name="Button001">
          <joint axis="0.2867574989795685 0.9580031633377075 0.0" pos="-0.017033055424690247 -0.12400650978088379 0.12556500732898712" limited="true" name="Button001_joint" range="0.0 0.002" type="slide" damping="1" frictionloss="1" armature=".01" stiffness="0.05"/>
          <geom mesh="Button001_vis" type="mesh" solimp="0.998 0.998 0.001" solref="0.001 1" density="100" friction="0.95 0.3 0.1" class="visual" material="Button001_material"/>
          <geom class="collision" type="cylinder" pos="-0.017583444714546204 -0.12537233531475067 0.12559442222118378" size="0.005281296093016863 0.002424245700240135" quat="0.6939712762832642 -0.6939708590507507 0.1356619894504547 -0.13566188514232635"/>
        </body>
        <body name="Button002">
          <joint axis="-0.2863234281539917 0.9581329226493835 0.0" pos="0.0182966161519289 -0.12447497248649597 0.12556500732898712" limited="true" name="Button002_joint" range="0.0 0.002" type="slide" damping="1" frictionloss="1" armature=".01" stiffness="0.05"/>
          <geom mesh="Button002_vis" type="mesh" solimp="0.998 0.998 0.001" solref="0.001 1" density="100" friction="0.95 0.3 0.1" class="visual" material="Button002_material"/>
          <geom class="collision" type="cylinder" pos="0.018599068745970726 -0.12569580972194672 0.12557287514209747" size="0.00528807332739234 0.0020867104176431894" quat="0.7006325721740723 -0.7006320953369141 -0.09546900540590286 0.09546893835067749"/>
        </body>
        <body name="Container001_Clear">
          <joint axis="0.0 0.0 1.0" pos="2.8185255359858274e-05 0.17531275749206543 0.027137942612171173" limited="true" name="Container001_Clear_joint" range="0.0 0.05" type="slide" damping="1" frictionloss="1" armature=".01" stiffness="0.05"/>
          <geom mesh="Container001_Clear_vis" type="mesh" solimp="0.998 0.998 0.001" solref="0.001 1" density="100" friction="0.95 0.3 0.1" class="visual" material="Container001_Clear_material"/>
          <geom class="collision" type="box" pos="0.04845482110977173 0.13288919627666473 0.025641433894634247" size="0.0012182785430923104 0.005222825799137354 0.09964721649885178" quat="0.9588197469711304 0.0 0.0 -0.28401538729667664"/>
          <geom class="collision" type="box" pos="0.053063590079545975 0.14209267497062683 0.025837630033493042" size="0.0012182783102616668 0.005222824867814779 0.09945102035999298" quat="0.9816271662712097 0.0 0.0 -0.19080907106399536"/>
          <geom class="collision" type="box" pos="0.05592886358499527 0.15187202394008636 0.025837630033493042" size="0.0012182785430923104 0.005222825799137354 0.09945101290941238" quat="0.9945219159126282 0.0 0.0 -0.10452854633331299"/>
          <geom class="collision" type="box" pos="0.057236198335886 0.16188883781433105 0.025837630033493042" size="0.0012182785430923104 0.005222825799137354 0.09945101290941238" quat="0.9998477101325989 0.0 0.0 -0.017452441155910492"/>
          <geom class="collision" type="box" pos="0.041721198707818985 0.13322775065898895 0.025837630033493042" size="0.0012182785430923104 0.005222825799137354 0.09945102035999298" quat="0.9099612236022949 0.0 0.0 0.41469329595565796"/>
          <geom class="collision" type="box" pos="0.054255951195955276 0.18234187364578247 0.025837630033493042" size="0.0012182786595076323 0.0052228267304599285 0.09945101290941238" quat="0.9862855672836304 0.0 0.0 0.16504766047000885"/>
          <geom class="collision" type="box" pos="0.04998215287923813 0.1918780654668808 0.025837630033493042" size="0.0012182786595076323 0.005222826264798641 0.09945102035999298" quat="0.9681476354598999 0.0 0.0 0.2503799796104431"/>
          <geom class="collision" type="box" pos="0.04403533786535263 0.2005777508020401 0.025837630033493042" size="0.0012182785430923104 0.005222825799137354 0.09945102035999298" quat="0.9396926164627075 0.0 0.0 0.3420201539993286"/>
          <geom class="collision" type="box" pos="0.03658280894160271 0.20799985527992249 0.025837630033493042" size="0.0012182785430923104 0.005222825799137354 0.09945102035999298" quat="0.9063077569007874 0.0 0.0 0.4226183295249939"/>
          <geom class="collision" type="box" pos="0.02797437645494938 0.21390105783939362 0.025837630033493042" size="0.001218278775922954 0.005222827196121216 0.09945101290941238" quat="0.866025447845459 0.0 0.0 0.4999999701976776"/>
          <geom class="collision" type="box" pos="0.018472464755177498 0.21819700300693512 0.025837630033493042" size="0.0012182785430923104 0.005222825799137354 0.09945101290941238" quat="0.8191520571708679 0.0 0.0 0.5735764503479004"/>
          <geom class="collision" type="box" pos="0.008633062243461609 0.22059538960456848 0.025837630033493042" size="0.0012182786595076323 0.005222826264798641 0.09945102035999298" quat="0.7660444378852844 0.0 0.0 0.6427876353263855"/>
          <geom class="collision" type="box" pos="-0.001572340726852417 0.22126458585262299 0.025837630033493042" size="0.0012182785430923104 0.005222825799137354 0.09945101290941238" quat="0.70710688829422 0.0 0.0 0.7071066498756409"/>
          <geom class="collision" type="box" pos="-0.01104770042002201 0.2202303558588028 0.025837630033493042" size="0.0012182785430923104 0.005222825799137354 0.09945102035999298" quat="0.6427876353263855 0.0 0.0 0.7660444378852844"/>
          <geom class="collision" type="box" pos="-0.02034054882824421 0.21752311289310455 0.025837630033493042" size="0.0012182785430923104 0.005222825799137354 0.09945101290941238" quat="0.5735764503479004 0.0 0.0 0.8191520571708679"/>
          <geom class="collision" type="box" pos="-0.02918805368244648 0.21312649548053741 0.025837630033493042" size="0.0012182786595076323 0.0052228267304599285 0.09945101290941238" quat="0.4999999701976776 0.0 0.0 0.866025447845459"/>
          <geom class="collision" type="box" pos="-0.037066441029310226 0.2075294852256775 0.025837630033493042" size="0.0012182785430923104 0.005222825799137354 0.09945102035999298" quat="0.42261824011802673 0.0 0.0 0.9063078165054321"/>
          <geom class="collision" type="box" pos="-0.04387257620692253 0.20080699026584625 0.025837630033493042" size="0.0012182785430923104 0.005222825799137354 0.09945102035999298" quat="0.3420201539993286 0.0 0.0 0.9396926164627075"/>
          <geom class="collision" type="box" pos="-0.0495760440826416 0.19264468550682068 0.025837630033493042" size="0.0012182786595076323 0.0052228267304599285 0.09945101290941238" quat="0.2588190734386444 0.0 0.0 0.9659258127212524"/>
          <geom class="collision" type="box" pos="-0.05378393456339836 0.18358251452445984 0.025837630033493042" size="0.0012182786595076323 0.005222826264798641 0.09945101290941238" quat="0.17364822328090668 0.0 0.0 0.9848077297210693"/>
          <geom class="collision" type="box" pos="-0.05640752986073494 0.1735951155424118 0.025837630033493042" size="0.0012182785430923104 0.005222825799137354 0.09945101290941238" quat="0.08715580403804779 0.0 0.0 0.9961947202682495"/>
          <geom class="collision" type="box" pos="-0.057193342596292496 0.16354434192180634 0.025837630033493042" size="0.0012182785430923104 0.005222825799137354 0.09945101290941238" quat="5.52335052361741e-07 0.0 -0.0 -1.0"/>
          <geom class="collision" type="box" pos="-0.05628078803420067 0.15341751277446747 0.025837630033493042" size="0.0012182784266769886 0.005222825799137354 0.09945102035999298" quat="0.0871562734246254 0.0 -0.0 -0.9961946606636047"/>
          <geom class="collision" type="box" pos="-0.0535912849009037 0.14354215562343597 0.025837630033493042" size="0.0012182786595076323 0.005222826264798641 0.09945101290941238" quat="0.17364822328090668 0.0 -0.0 -0.9848077297210693"/>
          <geom class="collision" type="box" pos="-0.0492408312857151 0.1341325044631958 0.025837630033493042" size="0.0012182785430923104 0.005222825799137354 0.09945102035999298" quat="0.2588194012641907 0.0 -0.0 -0.9659257531166077"/>
          <geom class="collision" type="box" pos="-0.043312229216098785 0.13204097747802734 0.025641433894634247" size="0.0012182785430923104 0.005222825799137354 0.09964721649885178" quat="0.41469326615333557 0.0 0.0 0.9099612832069397"/>
          <geom class="collision" type="box" pos="-0.034916725009679794 0.13832241296768188 0.025837630033493042" size="0.0012182785430923104 0.005222825799137354 0.09945102035999298" quat="0.4848094582557678 0.0 0.0 0.8746197819709778"/>
          <geom class="collision" type="box" pos="-0.025812717154622078 0.14325642585754395 0.025837630033493042" size="0.0012182785430923104 0.005222825799137354 0.09945101290941238" quat="0.544638991355896 0.0 0.0 0.8386706113815308"/>
          <geom class="collision" type="box" pos="-0.01621614210307598 0.1467789113521576 0.025837630033493042" size="0.001218278193846345 0.005222824867814779 0.09945102035999298" quat="0.6018149852752686 0.0 0.0 0.7986355423927307"/>
          <geom class="collision" type="box" pos="-0.006208940874785185 0.14870724081993103 0.025837630033493042" size="0.0012182785430923104 0.005222825799137354 0.09945101290941238" quat="0.6691306233406067 0.0 0.0 0.7431448101997375"/>
          <geom class="collision" type="box" pos="0.004022476263344288 0.14889217913150787 0.025837630033493042" size="0.0012182786595076323 0.005222826264798641 0.09945101290941238" quat="0.7313539385795593 0.0 0.0 0.6819981336593628"/>
          <geom class="collision" type="box" pos="0.014365005306899548 0.14731089770793915 0.025837630033493042" size="0.0012182785430923104 0.005222825799137354 0.09945102035999298" quat="0.7880106568336487 0.0 0.0 0.61566162109375"/>
          <geom class="collision" type="box" pos="0.024212321266531944 0.14405064284801483 0.025837630033493042" size="0.0012182786595076323 0.0052228267304599285 0.09945101290941238" quat="0.8338857889175415 0.0 0.0 0.5519370436668396"/>
          <geom class="collision" type="box" pos="0.033489957451820374 0.13921409845352173 0.025837630033493042" size="0.0012182786595076323 0.005222826264798641 0.09945102035999298" quat="0.8746196627616882 0.0 0.0 0.4848097264766693"/>
          <geom class="collision" type="box" pos="0.05668517202138901 0.17218083143234253 0.025837630033493042" size="0.0012182785430923104 0.005222825799137354 0.09945101290941238" quat="0.9975640773773193 0.0 0.0 0.06975650042295456"/>
          <geom class="collision" type="box" pos="-0.041156649589538574 0.18673016130924225 -0.05640029162168503" size="0.017046144232153893 0.008846818469464779 0.0021462563890963793" quat="0.5224984884262085 0.0 0.0 -0.8526402115821838"/>
          <geom class="collision" type="box" pos="0.026489881798624992 0.20149382948875427 -0.05640029162168503" size="0.017046144232153893 0.008846817538142204 0.0021462563890963793" quat="0.9563047289848328 0.0 0.0 -0.29237180948257446"/>
          <geom class="collision" type="box" pos="0.03521128371357918 0.1484232246875763 -0.05640029162168503" size="0.017046144232153893 0.008846818469464779 0.0021462563890963793" quat="0.9681476354598999 0.0 0.0 -0.2503799796104431"/>
          <geom class="collision" type="box" pos="-0.036010198295116425 0.14788013696670532 -0.05640029162168503" size="0.017046144232153893 0.008846817538142204 0.0021462563890963793" quat="0.9659258127212524 0.0 0.0 0.2588191032409668"/>
          <geom class="collision" type="box" pos="-0.001204542350023985 0.21229293942451477 -0.05640029162168503" size="0.017046144232153893 0.008846817538142204 0.0021462563890963793" quat="1.0 0.0 0.0 0.0"/>
          <geom class="collision" type="box" pos="-0.0012586124939844012 0.20378080010414124 -0.05640029162168503" size="0.029769079759716988 0.008846817538142204 0.0021462563890963793" quat="1.0 0.0 0.0 0.0"/>
          <geom class="collision" type="box" pos="-0.0007609847234562039 0.1870831698179245 -0.05640029162168503" size="0.04784898832440376 0.01339284423738718 0.0021462563890963793" quat="1.0 0.0 0.0 0.0"/>
          <geom class="collision" type="box" pos="-0.0001929873542394489 0.16198520362377167 -0.05640029162168503" size="0.05572507157921791 0.0125335194170475 0.0021462563890963793" quat="1.0 0.0 0.0 0.0"/>
          <geom class="collision" type="box" pos="-0.024352215230464935 0.20482343435287476 -0.05640029162168503" size="0.017046144232153893 0.008846817538142204 0.0021462563890963793" quat="0.2840152382850647 0.0 0.0 -0.9588197469711304"/>
          <geom class="collision" type="box" pos="0.043324656784534454 0.18046602606773376 -0.05640029162168503" size="0.017046146094799042 0.008846819400787354 0.0021462563890963793" quat="0.824126124382019 0.0 0.0 -0.5664063692092896"/>
          <body name="Lid002">
            <joint axis="0.0 0.0 1.0" pos="5.50062395632267e-09 0.1753700077533722 0.12939290702342987" limited="true" name="Lid002_joint" range="0.0 0.05" type="slide" damping="1" frictionloss="1" armature=".01" stiffness="0.05" springref="-10"/>
            <geom mesh="Lid002_vis" type="mesh" solimp="0.998 0.998 0.001" solref="0.001 1" density="100" friction="0.95 0.3 0.1" class="visual" material="Lid002_material"/>
            <geom class="collision" type="box" pos="-0.024352215230464935 0.20587436854839325 0.129324808716774" size="0.017046144232153893 0.008846817538142204 0.0037567391991615295" quat="0.2840152382850647 0.0 0.0 -0.9588197469711304"/>
            <geom class="collision" type="box" pos="-0.0001929873542394489 0.16303613781929016 0.129324808716774" size="0.05572507157921791 0.0125335194170475 0.0037567391991615295" quat="1.0 0.0 0.0 0.0"/>
            <geom class="collision" type="box" pos="-0.0007609847234562039 0.188134104013443 0.129324808716774" size="0.04784898832440376 0.01339284423738718 0.0037567391991615295" quat="1.0 0.0 0.0 0.0"/>
            <geom class="collision" type="box" pos="-0.0012586124939844012 0.20483173429965973 0.129324808716774" size="0.029769079759716988 0.008846817538142204 0.0037567391991615295" quat="1.0 0.0 0.0 0.0"/>
            <geom class="collision" type="box" pos="-0.001204542350023985 0.21334387362003326 0.129324808716774" size="0.017046144232153893 0.008846817538142204 0.0037567391991615295" quat="1.0 0.0 0.0 0.0"/>
            <geom class="collision" type="box" pos="-0.036010198295116425 0.14893107116222382 0.129324808716774" size="0.017046144232153893 0.008846817538142204 0.003756739431992173" quat="0.9659258127212524 0.0 0.0 0.2588191032409668"/>
            <geom class="collision" type="box" pos="0.03521128371357918 0.1494741588830948 0.129324808716774" size="0.017046144232153893 0.008846818469464779 0.003756739431992173" quat="0.9681476354598999 0.0 0.0 -0.2503799796104431"/>
            <geom class="collision" type="box" pos="0.043324656784534454 0.18151696026325226 0.129324808716774" size="0.017046146094799042 0.008846819400787354 0.003756739431992173" quat="0.824126124382019 0.0 0.0 -0.5664063692092896"/>
            <geom class="collision" type="box" pos="0.026489881798624992 0.20254476368427277 0.129324808716774" size="0.017046144232153893 0.008846817538142204 0.003756739431992173" quat="0.9563047289848328 0.0 0.0 -0.29237180948257446"/>
            <geom class="collision" type="box" pos="-0.041156649589538574 0.18778109550476074 0.129324808716774" size="0.017046144232153893 0.008846818469464779 0.003756739431992173" quat="0.5224984884262085 0.0 0.0 -0.8526402115821838"/>
          </body>
        </body>
        <body name="Lid001">
          <joint axis="-1.0 0.0 0.0" pos="-5.820766091346741e-11 0.01223236694931984 0.13308216631412506" limited="true" name="Lid001_joint" range="0.0 1.5707963267948966" type="hinge" damping="1" frictionloss="1" armature=".01" stiffness="0.05"/>
          <geom mesh="Lid001_vis" type="mesh" solimp="0.998 0.998 0.001" solref="0.001 1" density="100" friction="0.95 0.3 0.1" class="visual" material="Lid001_material"/>
          <geom class="collision" type="box" pos="7.655298759345897e-06 -0.07590800523757935 0.13666628301143646" size="0.020570728927850723 0.011319028213620186 0.0018015123205259442" quat="0.9848077893257141 -0.17364810407161713 0.0 0.0"/>
          <geom class="collision" type="box" pos="7.65573167882394e-06 -0.026532288640737534 0.131780743598938" size="0.020570728927850723 0.03908515349030495 0.0023022110108286142" quat="1.0 0.0 0.0 0.0"/>
        </body>
        <body name="Lid003">
          <joint axis="0.0 0.0 1.0" pos="1.6589183360338211e-09 -0.17033782601356506 -0.11866727471351624" limited="true" name="Lid003_joint" range="0.0 0.05" type="slide" damping="1" frictionloss="1" armature=".01" stiffness="0.05" springref="-20"/>
          <geom mesh="Lid003_vis" type="mesh" solimp="0.998 0.998 0.001" solref="0.001 1" density="100" friction="0.95 0.3 0.1" class="visual" material="Lid003_material"/>
          <geom class="collision" type="box" pos="0.04048456996679306 -0.1851375252008438 -0.11829263716936111" size="0.017046144232153893 0.008846818469464779 0.0018110563978552818" quat="0.8526402115821838 0.0 0.0 0.5224984884262085"/>
          <geom class="collision" type="box" pos="-0.027161961421370506 -0.19990120828151703 -0.11829264461994171" size="0.017046144232153893 0.008846817538142204 0.0018110565142706037" quat="0.2923717796802521 0.0 0.0 0.9563047289848328"/>
          <geom class="collision" type="box" pos="-0.04399673640727997 -0.17887338995933533 -0.11829264461994171" size="0.01704614795744419 0.008846819400787354 0.0018110565142706037" quat="0.5664061307907104 0.0 0.0 0.8241262435913086"/>
          <geom class="collision" type="box" pos="-0.03233996406197548 -0.14043816924095154 -0.11829263716936111" size="0.017046144232153893 0.01615563966333866 0.0018110566306859255" quat="0.2503805458545685 0.0 0.0 0.9681475162506104"/>
          <geom class="collision" type="box" pos="0.031960923224687576 -0.1404380053281784 -0.11829264461994171" size="0.017046144232153893 0.01560122985392809 0.0018110563978552818" quat="0.25881895422935486 0.0 0.0 -0.9659258723258972"/>
          <geom class="collision" type="box" pos="0.00053246202878654 -0.21070031821727753 -0.11829264461994171" size="0.017046144232153893 0.008846817538142204 0.0018110565142706037" quat="6.715443419125222e-07 0.0 0.0 1.0"/>
          <geom class="collision" type="box" pos="0.000586533104069531 -0.202188178896904 -0.11829264461994171" size="0.029769079759716988 0.008846817538142204 0.0018110565142706037" quat="6.715443419125222e-07 0.0 0.0 1.0"/>
          <geom class="collision" type="box" pos="8.89058574102819e-05 -0.18549054861068726 -0.11829264461994171" size="0.04784898832440376 0.01339284423738718 0.0018110565142706037" quat="6.715443419125222e-07 0.0 0.0 1.0"/>
          <geom class="collision" type="box" pos="0.0009344645659439266 -0.14459390938282013 -0.11829264461994171" size="0.03661051392555237 0.013927038758993149 0.0018110565142706037" quat="6.715443419125222e-07 0.0 0.0 1.0"/>
          <geom class="collision" type="box" pos="-0.0004790901148226112 -0.16039258241653442 -0.11829264461994171" size="0.05572507157921791 0.0125335194170475 0.0018110565142706037" quat="6.715443419125222e-07 0.0 0.0 1.0"/>
        </body>
        <geom class="region" name="reg_main" type="box" pos="2.5902409106492996e-09 1.4901161193847656e-08 1.4901161193847656e-08" size="0.06019207462668419 0.22270256280899048 0.1419580727815628"/>
      </body>
    </body>
  </worldbody>
  <actuator>
    <motor name="Button001_joint_actuator" joint="Button001_joint" gear="0.5"/>
    <motor name="Button002_joint_actuator" joint="Button002_joint" gear="0.5"/>
    <motor name="Container001_Clear_joint_actuator" joint="Container001_Clear_joint" gear="10"/>
    <motor name="Lid001_joint_actuator" joint="Lid001_joint" gear="10"/>
    <motor name="Lid003_joint_actuator" joint="Lid003_joint" gear="10"/>
    <motor name="Lid002_joint_actuator" joint="Lid002_joint" gear="10"/>
  </actuator>
</mujoco>
