<mujoco model="model">
  <compiler angle="radian"/>
  <asset>
    <mesh file="visuals/Body001.obj" name="Body001_vis"/>
    <mesh file="visuals/Button001.obj" name="Button001_vis"/>
    <mesh file="visuals/Button002.obj" name="Button002_vis"/>
    <texture file="visuals/T_BC001.png" name="Body001_material" type="2d"/>
    <material name="Body001_material" rgba="1 1 1 1.0" texture="Body001_material" shininess="0.2512328028678894" specular="0.3103448502657381"/>
    <texture file="visuals/T_BC001.png" name="Button001_material" type="2d"/>
    <material name="Button001_material" rgba="1 1 1 1.0" texture="Button001_material" shininess="0.2512328028678894" specular="0.3103448502657381"/>
    <texture file="visuals/T_BC001.png" name="Button002_material" type="2d"/>
    <material name="Button002_material" rgba="1 1 1 1.0" texture="Button002_material" shininess="0.2512328028678894" specular="0.3103448502657381"/>
  </asset>
  <default>
    <default class="visual">
      <geom conaffinity="0" contype="0" group="1" type="mesh"/>
    </default>
    <default class="collision">
      <geom group="0" rgba="0.5 0 0 0.5"/>
    </default>
    <default class="spawn">
      <geom group="0" rgba="1 1 1 0.5" contype="0" conaffinity="0"/>
      <site group="0" rgba="1 1 1 0.5"/>
    </default>
    <default class="region">
      <geom group="1" conaffinity="0" contype="0" rgba="0 1 0 0"/>
    </default>
  </default>
  <worldbody>
    <body>
      <body name="object">
        <geom mesh="Body001_vis" type="mesh" solimp="0.998 0.998 0.001" solref="0.001 1" density="100" friction="0.95 0.3 0.1" class="visual" material="Body001_material"/>
        <geom class="collision" type="box" pos="0.0002160108124371618 0.0022952635772526264 -0.23996613919734955" size="0.31345343589782715 0.14747558534145355 0.027916155755519867" quat="1.0 0.0 0.0 0.0"/>
        <geom class="collision" type="box" pos="-5.739702757523446e-08 0.06708835810422897 -0.07963159680366516" size="0.11166291683912277 0.08480796962976456 0.13256454467773438" quat="1.0 0.0 0.0 0.0"/>
        <geom class="collision" type="box" pos="-5.969290839402674e-08 0.08957803249359131 0.1766984909772873" size="0.11166291683912277 0.06231829896569252 0.12274312227964401" quat="1.0 0.0 0.0 0.0"/>
        <geom class="collision" type="box" pos="-0.0001321064046351239 -0.010899695567786694 -0.28365418314933777" size="0.03226620331406593 0.02035621553659439 0.017088599503040314" quat="1.0 0.0 0.0 0.0"/>
        <body name="Button001">
          <joint axis="0.0 1.0 0.0" pos="-0.2815648317337036 -0.15141354501247406 -0.23486673831939697" limited="true" name="Button001_joint" range="0.0 0.001" type="slide" damping="1" frictionloss="1" armature=".01" stiffness="0.05"/>
          <geom mesh="Button001_vis" type="mesh" solimp="0.998 0.998 0.001" solref="0.001 1" density="100" friction="0.95 0.3 0.1" class="visual" material="Button001_material"/>
          <geom class="collision" type="cylinder" pos="-0.2815355658531189 -0.1517217755317688 -0.23484845459461212" size="0.0021880476269870996 0.0007075949688442051" quat="0.7071067094802856 0.7071068286895752 0.0 0.0"/>
        </body>
        <body name="Button002">
          <joint axis="0.0 1.0 0.0" pos="-0.2585376501083374 -0.15141354501247406 -0.23486661911010742" limited="true" name="Button002_joint" range="0.0 0.001" type="slide" damping="1" frictionloss="1" armature=".01" stiffness="0.05"/>
          <geom mesh="Button002_vis" type="mesh" solimp="0.998 0.998 0.001" solref="0.001 1" density="100" friction="0.95 0.3 0.1" class="visual" material="Button002_material"/>
          <geom class="collision" type="cylinder" pos="-0.2585379481315613 -0.1517217755317688 -0.23486724495887756" size="0.0021880476269870996 0.0007075949688442051" quat="0.7071067094802856 0.7071068286895752 0.0 0.0"/>
        </body>
        <geom class="region" name="reg_main_body" type="box" pos="-7.450580596923828e-09 0.0 0.0" size="0.31366947293281555 0.15242967009544373 0.3009205758571625"/>
      </body>
    </body>
  </worldbody>
  <actuator>
    <motor name="Button001_joint_actuator" joint="Button001_joint" gear="0.5"/>
    <motor name="Button002_joint_actuator" joint="Button002_joint" gear="0.5"/>
  </actuator>
</mujoco>
