<?xml version='1.0' encoding='UTF-8'?>
<mujoco model="model">
  <option timestep="0.002" gravity="0.0 0.0 -9.81"/>
  <compiler angle="radian"/>
  <asset>
    <mesh file="visuals/Blade001.obj" name="Blade001_vis"/>
    <mesh file="visuals/Body001.obj" name="Body001_vis"/>
    <mesh file="visuals/Button001.obj" name="Button001_vis"/>
    <mesh file="visuals/Jug001.obj" name="Jug001_vis"/>
    <mesh file="visuals/Jug001_Clear.obj" name="Jug001_Clear_vis"/>
    <mesh file="visuals/Knob001.obj" name="Knob001_vis"/>
    <mesh file="visuals/Lid001.obj" name="Lid001_vis"/>
    <texture file="visuals/T_BC001.png" name="Body001_material" type="2d"/>
    <material name="Body001_material" rgba="1 1 1 1.0" texture="Body001_material" shininess="0.15" specular="2"/>
    <texture file="visuals/T_BC001.png" name="Button001_material" type="2d"/>
    <material name="Button001_material" rgba="1 1 1 1.0" texture="Button001_material" shininess="0.1" specular="0.7"/>
    <texture file="visuals/T_BC001.png" name="Jug001_Clear_material" type="2d"/>
    <material name="Jug001_Clear_material" rgba="1 1 1 0.800000011920929" texture="Jug001_Clear_material" shininess="0.1" specular="0.7"/>
    <texture file="visuals/T_BC001.png" name="Blade001_material" type="2d"/>
    <material name="Blade001_material" rgba="1 1 1 1.0" texture="Blade001_material" shininess="0.1" specular="0.7"/>
    <texture file="visuals/T_BC001.png" name="Jug001_material" type="2d"/>
    <material name="Jug001_material" rgba="1 1 1 1.0" texture="Jug001_material" shininess="0.1" specular="0.7"/>
    <texture file="visuals/T_BC001.png" name="Lid001_material" type="2d"/>
    <material name="Lid001_material" rgba="1 1 1 1.0" texture="Lid001_material" shininess="0.15" specular="2"/>
    <texture file="visuals/T_BC001.png" name="Knob001_material" type="2d"/>
    <material name="Knob001_material" rgba="1 1 1 1.0" texture="Knob001_material" shininess="0.15" specular="1.5"/>
  </asset>
  <default>
    <default class="visual">
      <geom conaffinity="0" contype="0" group="1" type="mesh"/>
    </default>
    <default class="collision">
      <geom group="0" rgba="0.5 0 0 0.5"/>
    </default>
    <default class="spawn">
      <geom group="0" rgba="1 1 1 0.5" contype="0" conaffinity="0"/>
      <site group="0" rgba="1 1 1 0.5"/>
    </default>
    <default class="region">
      <geom group="1" conaffinity="0" contype="0" rgba="0 1 0 0"/>
    </default>
  </default>
  <worldbody>
    <body>
      <body name="object">
        <geom mesh="Body001_vis" type="mesh" solimp="0.998 0.998 0.001" solref="0.001 1" friction="0.95 0.3 0.1" class="visual" material="Body001_material"/>
        <geom class="collision" type="box" pos="-0.064143 0.002932 -0.081316" size="0.003986308351159096 0.015745818614959717 0.054941773414611816" quat="0.9969801902770996 0.002991716144606471 0.05849111080169678 0.05099374055862427" density="1000.0"/>
        <geom class="collision" type="box" pos="-0.058982 0.031024 -0.081216" size="0.003986308351159096 0.015745816752314568 0.054941773414611816" quat="0.9726268649101257 0.021922767162322998 0.05430987477302551 -0.22487075626850128" density="1000.0"/>
        <geom class="collision" type="box" pos="-0.038216 0.052163 -0.081302" size="0.003986308351159096 0.01574581488966942 0.054941773414611816" quat="0.886173665523529 0.020056521520018578 0.0385282076895237 -0.4613128900527954" density="1000.0"/>
        <geom class="collision" type="box" pos="-0.011009 0.061396 -0.081394" size="0.002653482835739851 0.015745816752314568 0.054941773414611816" quat="0.7362769842147827 0.0351811945438385 0.038393545895814896 -0.6746735572814941" density="1000.0"/>
        <geom class="collision" type="box" pos="0.016331 0.055136 -0.081163" size="0.0021790468599647284 0.01574581488966942 0.054941777139902115" quat="0.49935898184776306 0.04383734613656998 0.025309504941105843 -0.8649151921272278" density="1000.0"/>
        <geom class="collision" type="box" pos="0.035459 0.037120 -0.081344" size="0.0018078562570735812 0.01574581488966942 0.054941773414611816" quat="0.30036523938179016 0.045378535985946655 0.014307779259979725 -0.9526367783546448" density="1000.0"/>
        <geom class="collision" type="box" pos="0.043633 0.010034 -0.080861" size="0.0026048512663692236 0.015745816752314568 0.054941773414611816" quat="7.540232616065623e-08 0.05030030384659767 3.797567593721851e-09 -0.9987341165542603" density="1000.0"/>
        <geom class="collision" type="box" pos="0.034813 -0.019445 -0.080941" size="0.0027222405187785625 0.015745816752314568 0.054941777139902115" quat="0.30034273862838745 -0.04684454947710037 0.01477002538740635 0.9525658488273621" density="1000.0"/>
        <geom class="collision" type="box" pos="0.025874 -0.035717 -0.081308" size="0.0014966638991609216 0.008354835212230682 0.05494178086519241" quat="0.4205015301704407 -0.04792412742972374 0.03366672620177269 0.9053995013237" density="1000.0"/>
        <geom class="collision" type="box" pos="-0.054388 -0.024282 -0.082464" size="0.003986308351159096 0.01574581488966942 0.054941773414611816" quat="0.9343163371086121 0.02062777802348137 0.05481475219130516 0.35160043835639954" density="1000.0"/>
        <geom class="collision" type="box" pos="-0.035549 -0.039831 -0.070365" size="0.003986308351159096 0.012453826144337654 0.04198986291885376" quat="0.8163965344429016 -0.016887996345758438 0.04775163158774376 0.5752662420272827" density="1000.0"/>
        <geom class="collision" type="box" pos="0.008395 -0.042975 -0.083887" size="0.002096703043207526 0.012412848882377148 0.04728870466351509" quat="0.560683012008667 -0.040940262377262115 0.030546532943844795 0.8264535069465637" density="1000.0"/>
        <geom class="collision" type="box" pos="-0.041752 -0.044520 -0.121380" size="0.0035907153505831957 0.010427257977426052 0.014271192252635956" quat="0.8109872341156006 0.0060891201719641685 0.05432721972465515 0.5825042128562927" density="1000.0"/>
        <geom class="collision" type="box" pos="-0.022156 -0.051259 -0.124746" size="0.003590715117752552 0.010427256114780903 0.010370254516601562" quat="0.8053919076919556 -0.005206680856645107 0.04405323788523674 0.5910804271697998" density="1000.0"/>
        <geom class="collision" type="box" pos="-0.003409 -0.051031 -0.125984" size="0.003590715816244483 0.010427255183458328 0.008998429402709007" quat="0.6632282137870789 -0.057456206530332565 0.01936173252761364 0.7459572553634644" density="1000.0"/>
        <geom class="collision" type="box" pos="0.013155 -0.040638 -0.085960" size="0.003590715117752552 0.010427254252135754 0.05563155561685562" quat="0.5456677079200745 -0.05234862118959427 0.011771116405725479 0.8362821340560913" density="1000.0"/>
        <geom class="collision" type="cylinder" pos="-0.010798 0.008530 -0.139860" size="0.05258236825466156 0.004347818437963724" quat="1.0 0.0 0.0 0.0" density="1000.0"/>
        <geom class="collision" type="cylinder" pos="-0.010798 0.008530 -0.145797" size="0.06486986577510834 0.0016201762482523918" quat="1.0 0.0 0.0 0.0" density="1000.0"/>
        <geom class="collision" type="cylinder" pos="-0.011135 0.007027 -0.028176" size="0.049913439899683 0.01324945967644453" quat="1.0 0.0 0.0 0.0" density="1000.0"/>
        <geom class="collision" type="box" pos="-0.009099 -0.045180 -0.079874" size="0.003590715117752552 0.015328536741435528 0.04948468133807182" quat="0.70053631067276 -0.018481511622667313 0.03286641836166382 0.7126199007034302" density="1000.0"/>
        <body name="Button001">
          <joint axis="-0.07474696636199951 0.9928273558616638 -0.09331002831459045" pos="-0.010700 -0.048670 -0.056173" limited="true" name="Button001_joint" range="0.0 0.0006" type="slide" damping="1" frictionloss="1" armature=".01" stiffness="0.2" springref="-0.1"/>
          <geom mesh="Button001_vis" type="mesh" solimp="0.998 0.998 0.001" solref="0.001 1" friction="0.95 0.3 0.1" class="visual" material="Button001_material"/>
          <geom class="collision" type="cylinder" pos="-0.010736 -0.049424 -0.056002" size="0.0033137896098196507 0.0009123445488512516" quat="0.7030347585678101 0.6229007840156555 -0.2200489640235901 0.26327773928642273" density="1000.0"/>
        </body>
        <body name="Jug001_Clear">
          <geom class="region" name="reg_int" type="box" pos="-0.009241999999999998 0.006499999999999999 0.063958" size="0.034897 0.034282 0.049332"/>
          <joint axis="0.0 0.0 1.0" pos="0.006293 0.006808 0.063425" limited="true" name="Jug001_Clear_joint" range="0.0 0.05" type="slide" damping="1" frictionloss="1" armature=".01" stiffness="0.05"/>
          <geom mesh="Jug001_Clear_vis" type="mesh" solimp="0.998 0.998 0.001" solref="0.001 1" friction="0.95 0.3 0.1" class="visual" material="Jug001_Clear_material"/>
          <geom class="collision" type="box" pos="-0.052013 -0.005448 0.064014" size="0.0011411537416279316 0.008665076456964016 0.04689289629459381" quat="0.9886313080787659 -0.0007852297276258469 -0.022206872701644897 0.14870889484882355" density="1000.0"/>
          <geom class="collision" type="box" pos="-0.044626 -0.019573 0.063636" size="0.0013928755652159452 0.007175058592110872 0.047899119555950165" quat="0.9493206143379211 -0.010618006810545921 -0.024758541956543922 0.31315281987190247" density="1000.0"/>
          <geom class="collision" type="box" pos="-0.034911 -0.029057 0.063561" size="0.0009027808555401862 0.007999305613338947 0.046975307166576385" quat="0.8626777529716492 0.00400641979649663 -0.025761157274246216 0.5050815939903259" density="1000.0"/>
          <geom class="collision" type="box" pos="0.006410 -0.034133 0.067305" size="0.0010227970778942108 0.00639775674790144 0.04582451283931732" quat="0.49985271692276 0.00337212230078876 -0.0017554215155541897 0.8661020994186401" density="1000.0"/>
          <geom class="collision" type="box" pos="0.018456 -0.027423 0.067953" size="0.0007466371753253043 0.007702946662902832 0.04582451656460762" quat="0.4149072468280792 -0.003698088228702545 0.0005286823725327849 0.9098560214042664" density="1000.0"/>
          <geom class="collision" type="box" pos="0.035226 0.005741 0.067601" size="0.0034557972103357315 0.014141874387860298 0.04613758996129036" quat="1.0 0.0 0.0 0.0" density="1000.0"/>
          <geom class="collision" type="box" pos="0.016510 0.042003 0.066424" size="0.0007405881187878549 0.005810028873383999 0.04582451283931732" quat="0.4493381381034851 0.004741608630865812 -0.01437248196452856 -0.8932335376739502" density="1000.0"/>
          <geom class="collision" type="box" pos="0.004084 0.046786 0.066056" size="0.0008923254208639264 0.007550706155598164 0.04582451283931732" quat="0.6081756353378296 0.001975441351532936 -0.015004957094788551 -0.7936581969261169" density="1000.0"/>
          <geom class="collision" type="box" pos="-0.035993 0.042409 0.065292" size="0.0009781541302800179 0.006452578119933605 0.04582451283931732" quat="0.8918564915657043 -0.004716404248028994 -0.014380785636603832 -0.45206522941589355" density="1000.0"/>
          <geom class="collision" type="box" pos="-0.044699 0.032845 0.065311" size="0.0011494028149172664 0.007025028578937054 0.04582451656460762" quat="0.9534119963645935 -0.006988314911723137 -0.013424396514892578 -0.30129143595695496" density="1000.0"/>
          <geom class="collision" type="box" pos="0.063578 0.006206 0.076313" size="0.005088288802653551 0.009546133689582348 0.023384999483823776" quat="0.9961947202682495 0.0 -0.08715573698282242 0.0" density="1000.0"/>
          <geom class="collision" type="box" pos="0.052190 0.006167 0.104347" size="0.007519893813878298 0.008824963122606277 0.01210277620702982" quat="0.7518044114112854 -0.00046680914238095284 0.6593855023384094 0.0008093591895885766" density="1000.0"/>
          <geom class="collision" type="box" pos="0.051941 0.006574 0.032930" size="0.0033454347867518663 0.009491372853517532 0.016489258036017418" quat="0.843391478061676 0.0 0.5372995734214783 0.0" density="1000.0"/>
          <geom class="collision" type="cylinder" pos="-0.009949 0.007546 0.018520" size="0.04288448393344879 0.0013050753623247147" quat="1.0 0.0 0.0 0.0" density="1000.0"/>
          <geom class="collision" type="box" pos="0.067062 0.006688 0.047009" size="0.004980669356882572 0.009491369128227234 0.008270477876067162" quat="0.9994047284126282 0.007976317778229713 0.033564552664756775 -0.0002168510400224477" density="1000.0"/>
          <geom class="collision" type="box" pos="-0.004978 -0.035022 0.067346" size="0.001022796961478889 0.006397756282240152 0.04582451283931732" quat="0.6432011723518372 0.003626530757173896 -0.001140607870183885 0.7656878232955933" density="1000.0"/>
          <geom class="collision" type="box" pos="-0.018697 -0.034973 0.063611" size="0.0010227971943095326 0.008234738372266293 0.04582451283931732" quat="0.7698814272880554 0.0037721358239650726 -0.0004729771171696484 0.6381756067276001" density="1000.0"/>
          <geom class="collision" type="box" pos="-0.052423 0.021847 0.065381" size="0.0011494026985019445 0.007025028113275766 0.04582451656460762" quat="0.9765552878379822 -0.00816198717802763 -0.012744918465614319 -0.2147340178489685" density="1000.0"/>
          <geom class="collision" type="box" pos="-0.054221 0.009736 0.065602" size="0.0011494028149172664 0.007025029044598341 0.04582451656460762" quat="0.9976705312728882 -0.009973456151783466 -0.011383378878235817 -0.06651640683412552" density="1000.0"/>
          <geom class="collision" type="box" pos="-0.023395 0.047373 0.065455" size="0.0009781541302800179 0.006452578119933605 0.04582451283931732" quat="0.7688629031181335 -0.0013972119195386767 -0.015069808810949326 -0.6392345428466797" density="1000.0"/>
          <geom class="collision" type="box" pos="-0.010786 0.049717 0.065675" size="0.000978154013864696 0.006452578119933605 0.04582451283931732" quat="0.7119560837745667 -0.00011576183896977454 -0.015133999288082123 -0.702060878276825" density="1000.0"/>
          <geom class="collision" type="box" pos="0.022346 0.033132 0.065493" size="0.000740588060580194 0.005810028873383999 0.04582451283931732" quat="0.3184846043586731 0.006726743653416634 -0.01355736143887043 -0.9478071928024292" density="1000.0"/>
          <geom class="collision" type="box" pos="0.030102 0.022892 0.065878" size="0.0007405880023725331 0.005810028873383999 0.04582451283931732" quat="0.1984029859304428 0.008357168175280094 -0.012617817148566246 -0.9800036549568176" density="1000.0"/>
          <geom class="collision" type="box" pos="0.028244 -0.014893 0.067964" size="0.0007466371171176434 0.00865502841770649 0.04582451283931732" quat="0.23986472189426422 -0.0035369955003261566 0.0012020895956084132 0.9707991480827332" density="1000.0"/>
          <body name="Blade001">
            <joint axis="0.0 0.0 1.0" pos="-0.011345 0.006755 0.025325" limited="false" name="Blade001_joint" range="0 360" type="hinge" damping="1" frictionloss="1" armature=".01" stiffness="0.05"/>
            <geom mesh="Blade001_vis" type="mesh" solimp="0.998 0.998 0.001" solref="0.001 1" friction="0.95 0.3 0.1" class="visual" material="Blade001_material"/>
            <geom class="collision" type="box" pos="-0.011335 0.004478 0.023163" size="0.0030732648447155952 0.020795876160264015 0.0011587267508730292" quat="1.0 0.0 0.0 0.0" density="1000.0"/>
            <geom class="collision" type="box" pos="-0.027368 0.006611 0.025734" size="0.0030642191413789988 0.010015010833740234 0.0011587272165343165" quat="0.6698104739189148 -0.09623399376869202 0.08818221837282181 -0.7309697866439819" density="1000.0"/>
            <geom class="collision" type="box" pos="0.003654 0.006611 0.025642" size="0.0030642191413789988 0.010015010833740234 0.0011587273329496384" quat="0.6653264760971069 0.12802685797214508 -0.11731503903865814 -0.7260764241218567" density="1000.0"/>
          </body>
          <body name="Jug001">
            <geom mesh="Jug001_vis" type="mesh" solimp="0.998 0.998 0.001" solref="0.001 1" friction="0.95 0.3 0.1" class="visual" material="Jug001_material"/>
            <geom class="collision" type="cylinder" pos="-0.011161 0.005777 0.003098" size="0.00906098261475563 0.008652156218886375" quat="1.0 0.0 0.0 0.0" density="1000.0"/>
            <geom class="collision" type="cylinder" pos="-0.011135 0.007027 -0.001064" size="0.04508111625909805 0.01324945967644453" quat="1.0 0.0 0.0 0.0" density="1000.0"/>
          </body>
          <body name="Lid001">
            <joint axis="0.0 0.0 1.0" pos="0.000454 0.006541 0.127432" limited="true" name="Lid001_joint" range="0.0 0.05" type="slide" damping="1" frictionloss="1" armature=".01" stiffness="0.05"/>
            <geom mesh="Lid001_vis" type="mesh" solimp="0.998 0.998 0.001" solref="0.001 1" friction="0.95 0.3 0.1" class="visual" material="Lid001_material"/>
            <geom class="collision" type="cylinder" pos="-0.010798 0.006949 0.123598" size="0.03988746181130409 0.006859514396637678" quat="1.0 0.0 0.0 0.0" density="1000.0"/>
            <geom class="collision" type="cylinder" pos="-0.010798 0.006949 0.116120" size="0.045904722064733505 0.0007029778207652271" quat="1.0 0.0 0.0 0.0" density="1000.0"/>
            <geom class="collision" type="cylinder" pos="-0.011513 0.006412 0.141297" size="0.019289351999759674 0.004582580644637346" quat="1.0 0.0 0.0 0.0" density="1000.0"/>
            <geom class="collision" type="box" pos="0.045153 0.006207 0.122294" size="0.015266613103449345 0.008549760095775127 0.006911179516464472" quat="1.0 0.0 0.0 0.0" density="1000.0"/>
            <geom class="collision" type="box" pos="0.031508 0.006207 0.123832" size="0.006593892816454172 0.016444940119981766 0.0057326871901750565" quat="1.0 0.0 0.0 0.0" density="1000.0"/>
            <geom class="collision" type="cylinder" pos="-0.011513 0.006412 0.133892" size="0.028988415375351906 0.0018546077189967036" quat="1.0 0.0 0.0 0.0" density="1000.0"/>
            <geom class="collision" type="cylinder" pos="-0.011513 0.006412 0.130252" size="0.035023611038923264 0.002240724628791213" quat="1.0 0.0 0.0 0.0" density="1000.0"/>
          </body>
        </body>
        <body name="Knob001">
          <joint axis="0.0 1.0 0.0" pos="-0.010994 -0.056961 -0.097077" limited="true" name="Knob001_joint" range="0.0 4.886921905584122" type="hinge" damping="0.05" armature="0.001"/>
          <geom mesh="Knob001_vis" type="mesh" solimp="0.998 0.998 0.001" solref="0.001 1" friction="0.95 0.3 0.1" class="visual" material="Knob001_material"/>
          <geom class="collision" type="cylinder" pos="-0.011212 -0.054815 -0.097667" size="0.01372851338237524 0.0028194477781653404" quat="0.7071067094802856 0.7071068286895752 0.0 0.0" density="1000.0"/>
          <geom class="collision" type="box" pos="-0.010586 -0.063688 -0.096855" size="0.003505827160552144 0.00607439037412405 0.011031358502805233" quat="0.8721806406974792 0.0 -0.4891839027404785 0.0" density="1000.0"/>
        </body>
        <geom class="region" name="reg_main" type="box" pos="-0.010925499999999998 0.0068080000000000016 0.0" size="0.06328149999999999 0.063283 0.147364"/>
      </body>
    </body>
  </worldbody>
  <actuator>
    <motor name="Button001_joint_actuator" joint="Button001_joint" gear="0.1"/>
    <motor name="Jug001_Clear_joint_actuator" joint="Jug001_Clear_joint" gear="15"/>
    <motor name="Knob001_joint_actuator" joint="Knob001_joint" gear="15"/>
    <motor name="Blade001_joint_actuator" joint="Blade001_joint" gear="15"/>
    <motor name="Lid001_joint_actuator" joint="Lid001_joint" gear="15"/>
  </actuator>
</mujoco>
