<mujoco model="model">
  <compiler angle="radian"/>
  <asset>
    <mesh file="visuals/Body001.obj" name="Body001_vis"/>
    <mesh file="visuals/Button001.obj" name="Button001_vis"/>
    <mesh file="visuals/Button002.obj" name="Button002_vis"/>
    <mesh file="visuals/Button003.obj" name="Button003_vis"/>
    <mesh file="visuals/Button004.obj" name="Button004_vis"/>
    <mesh file="visuals/Button005.obj" name="Button005_vis"/>
    <texture file="visuals/T_BC001.png" name="Body001_material" type="2d"/>
    <material name="Body001_material" rgba="1 1 1 1.0" texture="Body001_material" shininess="0.6159252524375916" specular="0.3103448502657381"/>
    <texture file="visuals/T_BC001.png" name="Button001_material" type="2d"/>
    <material name="Button001_material" rgba="1 1 1 1.0" texture="Button001_material" shininess="0.6159252524375916" specular="0.3103448502657381"/>
    <texture file="visuals/T_BC001.png" name="Button002_material" type="2d"/>
    <material name="Button002_material" rgba="1 1 1 1.0" texture="Button002_material" shininess="0.6159252524375916" specular="0.3103448502657381"/>
    <texture file="visuals/T_BC001.png" name="Button003_material" type="2d"/>
    <material name="Button003_material" rgba="1 1 1 1.0" texture="Button003_material" shininess="0.6159252524375916" specular="0.3103448502657381"/>
    <texture file="visuals/T_BC001.png" name="Button004_material" type="2d"/>
    <material name="Button004_material" rgba="1 1 1 1.0" texture="Button004_material" shininess="0.6159252524375916" specular="0.3103448502657381"/>
    <texture file="visuals/T_BC001.png" name="Button005_material" type="2d"/>
    <material name="Button005_material" rgba="1 1 1 1.0" texture="Button005_material" shininess="0.6159252524375916" specular="0.3103448502657381"/>
  </asset>
  <default>
    <default class="visual">
      <geom conaffinity="0" contype="0" group="1" type="mesh"/>
    </default>
    <default class="collision">
      <geom group="0" rgba="0.5 0 0 0.5"/>
    </default>
    <default class="spawn">
      <geom group="0" rgba="1 1 1 0.5" contype="0" conaffinity="0"/>
      <site group="0" rgba="1 1 1 0.5"/>
    </default>
    <default class="region">
      <geom group="1" conaffinity="0" contype="0" rgba="0 1 0 0"/>
    </default>
  </default>
  <worldbody>
    <body>
      <body name="object">
        <geom mesh="Body001_vis" type="mesh" solimp="0.998 0.998 0.001" solref="0.001 1" density="100" friction="0.95 0.3 0.1" class="visual" material="Body001_material"/>
        <geom class="collision" type="box" pos="-0.00047654082300141454 0.036292847245931625 0.11806812882423401" size="0.1729690581560135 0.060028936713933945 0.29116693139076233" quat="1.0 0.0 0.0 0.0"/>
        <geom class="collision" type="box" pos="-0.00047654082300141454 0.036292847245931625 -0.20133203268051147" size="0.1729690581560135 0.060028936713933945 0.029010536149144173" quat="1.0 0.0 0.0 0.0"/>
        <geom class="collision" type="box" pos="-0.00047654082300141454 0.04793693497776985 -0.26139259338378906" size="0.1729690581560135 0.04838484898209572 0.03028729185461998" quat="1.0 0.0 0.0 0.0"/>
        <geom class="collision" type="box" pos="-0.00047654082300141454 0.06213424727320671 -0.3271380364894867" size="0.1729690581560135 0.03418753668665886 0.03501170128583908" quat="1.0 0.0 0.0 0.0"/>
        <geom class="collision" type="box" pos="0.0004976977943442762 0.06213424727320671 -0.3861043453216553" size="0.4025149643421173 0.03418753668665886 0.024611853063106537" quat="1.0 0.0 0.0 0.0"/>
        <geom class="collision" type="box" pos="-7.186256698332727e-05 -0.015719495713710785 -0.2219235599040985" size="0.4501383900642395 0.012642232701182365 0.20768512785434723" quat="0.983300507068634 0.1819894015789032 -4.216618354321328e-17 -3.3973894910353183e-19"/>
        <body name="Button001">
          <joint axis="-1.3681741039555714e-17 0.9383828639984131 0.34559735655784607" pos="-0.056917704641819 -0.0805220827460289 -0.09023746848106384" limited="true" name="Button001_joint" range="0.0 0.001" type="slide" damping="1" frictionloss="1" armature=".01" stiffness="0.05"/>
          <geom mesh="Button001_vis" type="mesh" solimp="0.998 0.998 0.001" solref="0.001 1" density="100" friction="0.95 0.3 0.1" class="visual" material="Button001_material"/>
          <geom class="collision" type="box" pos="-0.05717410519719124 -0.08086919784545898 -0.09063208103179932" size="0.007078930269926786 0.0010401803301647305 0.007181541062891483" quat="0.983300507068634 0.1819894015789032 -4.216618354321328e-17 -3.3973894910353183e-19"/>
        </body>
        <body name="Button002">
          <joint axis="-1.405067186456049e-17 0.9367213845252991 0.35007575154304504" pos="-0.029297474771738052 -0.0805220827460289 -0.09023746848106384" limited="true" name="Button002_joint" range="0.0 0.001" type="slide" damping="1" frictionloss="1" armature=".01" stiffness="0.05"/>
          <geom mesh="Button002_vis" type="mesh" solimp="0.998 0.998 0.001" solref="0.001 1" density="100" friction="0.95 0.3 0.1" class="visual" material="Button002_material"/>
          <geom class="collision" type="box" pos="-0.02937600389122963 -0.08086919784545898 -0.09063208103179932" size="0.007078930269926786 0.0010401803301647305 0.007181541062891483" quat="0.983300507068634 0.1819894015789032 -4.216618354321328e-17 -3.3973894910353183e-19"/>
        </body>
        <body name="Button003">
          <joint axis="-1.5303418704298574e-17 0.9310795664787292 0.36481624841690063" pos="-0.0002926040906459093 -0.0805220827460289 -0.09023746848106384" limited="true" name="Button003_joint" range="0.0 0.001" type="slide" damping="1" frictionloss="1" armature=".01" stiffness="0.05"/>
          <geom mesh="Button003_vis" type="mesh" solimp="0.998 0.998 0.001" solref="0.001 1" density="100" friction="0.95 0.3 0.1" class="visual" material="Button003_material"/>
          <geom class="collision" type="box" pos="-0.000313756987452507 -0.08086919784545898 -0.09063208103179932" size="0.007078930269926786 0.0010401803301647305 0.007181541062891483" quat="0.983300507068634 0.1819894015789032 -4.216618354321328e-17 -3.3973894910353183e-19"/>
        </body>
        <body name="Button004">
          <joint axis="-1.5060358298744767e-17 0.9321741461753845 0.36201003193855286" pos="0.027422912418842316 -0.0805220827460289 -0.09023746848106384" limited="true" name="Button004_joint" range="0.0 0.001" type="slide" damping="1" frictionloss="1" armature=".01" stiffness="0.05"/>
          <geom mesh="Button004_vis" type="mesh" solimp="0.998 0.998 0.001" solref="0.001 1" density="100" friction="0.95 0.3 0.1" class="visual" material="Button004_material"/>
          <geom class="collision" type="box" pos="0.027484344318509102 -0.08086919784545898 -0.09063208103179932" size="0.007078930269926786 0.0010401803301647305 0.007181541062891483" quat="0.983300507068634 0.1819894015789032 -4.216618354321328e-17 -3.3973894910353183e-19"/>
        </body>
        <body name="Button005">
          <joint axis="-1.5537806948310375e-17 0.9300239086151123 0.3674989640712738" pos="0.055811136960983276 -0.0805220827460289 -0.09023746848106384" limited="true" name="Button005_joint" range="0.0 0.001" type="slide" damping="1" frictionloss="1" armature=".01" stiffness="0.05"/>
          <geom mesh="Button005_vis" type="mesh" solimp="0.998 0.998 0.001" solref="0.001 1" density="100" friction="0.95 0.3 0.1" class="visual" material="Button005_material"/>
          <geom class="collision" type="box" pos="0.05557790398597717 -0.08086919784545898 -0.09063208103179932" size="0.007078930269926786 0.0010401803301647305 0.007181541062891483" quat="0.983300507068634 0.1819894015789032 -4.216618354321328e-17 -3.3973894910353183e-19"/>
        </body>
        <geom class="region" name="reg_main_body" type="box" pos="-7.450580596923828e-09 -1.1175870895385742e-08 0.0" size="0.4492674171924591 0.09528280794620514 0.40920141339302063"/>
      </body>
    </body>
  </worldbody>
  <actuator>
    <motor name="Button001_joint_actuator" joint="Button001_joint" gear="0.5"/>
    <motor name="Button002_joint_actuator" joint="Button002_joint" gear="0.5"/>
    <motor name="Button003_joint_actuator" joint="Button003_joint" gear="0.5"/>
    <motor name="Button004_joint_actuator" joint="Button004_joint" gear="0.5"/>
    <motor name="Button005_joint_actuator" joint="Button005_joint" gear="0.5"/>
  </actuator>
</mujoco>
