<?xml version='1.0' encoding='utf-8'?>
<mujoco model="model">
    <compiler angle="radian" />
    <asset>
        <mesh file="visuals/ToasterOven027_Body001.obj" name="ToasterOven027_Body001_vis" />
        <mesh file="visuals/ToasterOven027_Button001.obj" name="ToasterOven027_Button001_vis" />
        <mesh file="visuals/ToasterOven027_Door001.obj" name="ToasterOven027_Door001_vis" />
        <mesh file="visuals/ToasterOven027_Door001_Clear.obj" name="ToasterOven027_Door001_Clear_vis" />
        <mesh file="visuals/ToasterOven027_Konb001.obj" name="ToasterOven027_Konb001_vis" />
        <mesh file="visuals/ToasterOven027_Konb002.obj" name="ToasterOven027_Konb002_vis" />
        <mesh file="visuals/ToasterOven027_Shelf001.obj" name="ToasterOven027_Shelf001_vis" />
        <texture file="visuals/T_ToasterOven027_BC001.png" name="ToasterOven027_Body001_material" type="2d" />
        <material name="ToasterOven027_Body001_material" rgba="1 1 1 1.0" texture="ToasterOven027_Body001_material" shininess="2" specular="2" />
        <texture file="visuals/T_ToasterOven027_BC001.png" name="ToasterOven027_Button001_material" type="2d" />
        <material name="ToasterOven027_Button001_material" rgba="1 1 1 1.0" texture="ToasterOven027_Button001_material" shininess="0.5" specular="0.3103448502657381" />
        <texture file="visuals/T_ToasterOven027_BC001.png" name="ToasterOven027_Door001_material" type="2d" />
        <material name="ToasterOven027_Door001_material" rgba="1 1 1 1.0" texture="ToasterOven027_Door001_material" shininess="2" specular="2" />
        <material name="ToasterOven027_Door001_Clear_material" rgba="0.021761858835816383 0.021761858835816383 0.021761858835816383 0.6023738980293274" shininess="0.5" specular="0.3103448502657381" />
        <texture file="visuals/T_ToasterOven027_BC001.png" name="ToasterOven027_Konb001_material" type="2d" />
        <material name="ToasterOven027_Konb001_material" rgba="1 1 1 1.0" texture="ToasterOven027_Konb001_material" shininess="0.5" specular="0.3103448502657381" />
        <texture file="visuals/T_ToasterOven027_BC001.png" name="ToasterOven027_Konb002_material" type="2d" />
        <material name="ToasterOven027_Konb002_material" rgba="1 1 1 1.0" texture="ToasterOven027_Konb002_material" shininess="0.5" specular="0.3103448502657381" />
        <texture file="visuals/T_ToasterOven027_BC001.png" name="ToasterOven027_Shelf001_material" type="2d" />
        <material name="ToasterOven027_Shelf001_material" rgba="1 1 1 1.0" texture="ToasterOven027_Shelf001_material" shininess="1" specular="1" />
    </asset>
    <default>
        <default class="visual">
            <geom conaffinity="0" contype="0" group="1" type="mesh" />
        </default>
        <default class="collision">
            <geom group="0" rgba="0.5 0 0 0.5" />
    </default>
        <default class="spawn">
            <geom group="0" rgba="1 1 1 0.5" contype="0" conaffinity="0" />
            <site group="0" rgba="1 1 1 0.5" />
        </default>
    </default>
    <worldbody>
        <body>
            <site rgba="0 0 0 0.5" size="0.01" pos="-0.275070 -0.202010 -0.171120" name="ext_p0" />
            <site rgba="1 0 0 0.5" size="0.01" pos="0.277204 -0.202010 -0.171120" name="ext_px" />
            <site rgba="0 1 0 0.5" size="0.01" pos="-0.275070 0.236885 -0.171120" name="ext_py" />
            <site rgba="0 0 1 0.5" size="0.01" pos="-0.275070 -0.202010 0.171120" name="ext_pz" />
            <site rgba="0.5 0.5 0.5 0.5" size="0.004999999888241291" pos="-0.224035 -0.170058 -0.081963" name="int_p0" />
            <site rgba="1 1 0 0.5" size="0.004999999888241291" pos="0.149756 -0.170058 -0.082168" name="int_px" />
            <site rgba="0 1 1 0.5" size="0.004999999888241291" pos="-0.224035 0.176378 -0.081963" name="int_py" />
            <site rgba="1 0.75 0.8 0.5" size="0.004999999888241291" pos="-0.223892 -0.170058 0.109435" name="int_pz" />
            <body name="object">
                <geom mesh="ToasterOven027_Body001_vis" type="mesh" solimp="0.998 0.998 0.001" solref="0.001 1" density="100" friction="0.95 0.3 0.1" class="visual" material="ToasterOven027_Body001_material" />
                <geom class="collision" type="box" pos="0.000784 0.030499 0.142506" size="0.2788809537887573 0.20857973396778107 0.03142211586236954" quat="1.0 0.0 0.0 0.0" />
                <geom class="collision" type="box" pos="0.000784 0.030499 -0.130266" size="0.2788809537887573 0.20857973396778107 0.04373272880911827" quat="1.0 0.0 0.0 0.0" />
                <geom class="collision" type="box" pos="0.228929 0.018856 0.010961" size="0.05073639750480652 0.22022274136543274 0.1619531810283661" quat="1.0 0.0 0.0 0.0" />
                <geom class="collision" type="box" pos="-0.252767 0.030492 0.010961" size="0.02549375407397747 0.20858722925186157 0.1619531810283661" quat="1.0 0.0 0.0 0.0" />
                <geom class="collision" type="box" pos="-0.019350 0.207176 0.010961" size="0.21508970856666565 0.031902533024549484 0.1619531810283661" quat="1.0 0.0 0.0 0.0" />
                <geom class="collision" type="box" pos="-0.039668 -0.171029 -0.128357" size="0.2079881727695465 0.03190247341990471 0.014099174179136753" quat="1.0 0.0 0.0 0.0" />
                <body name="ToasterOven027_Button001">
                    <joint axis="0.0 1.0 0.0" pos="0.220424 -0.205993 0.105435" limited="true" name="ToasterOven027_Button001_joint" range="0.0 0.005" type="slide" damping="1" frictionloss="1" armature=".01" stiffness="0.05" />
                    <geom mesh="ToasterOven027_Button001_vis" type="mesh" solimp="0.998 0.998 0.001" solref="0.001 1" density="100" friction="0.95 0.3 0.1" class="visual" material="ToasterOven027_Button001_material" />
                    <geom class="collision" type="box" pos="0.220541 -0.208551 0.105370" size="0.018599731847643852 0.0024944934993982315 0.007346090395003557" quat="1.0 0.0 0.0 0.0" />
                </body>
                <body name="ToasterOven027_Door001">
                    <joint axis="1.0 0.0 0.0" pos="-0.050802 -0.201197 -0.106915" limited="true" name="ToasterOven027_Door001_joint" range="0.0 1.5707963267948966" type="hinge" damping="1" frictionloss="1" armature=".01" stiffness="0.05" />
                    <geom mesh="ToasterOven027_Door001_vis" type="mesh" solimp="0.998 0.998 0.001" solref="0.001 1" density="100" friction="0.95 0.3 0.1" class="visual" material="ToasterOven027_Door001_material" />
                    <geom class="collision" type="box" pos="-0.049492 -0.194869 0.035259" size="0.21992427110671997 0.0032664891332387924 0.1372329294681549" quat="1.0 0.0 0.0 0.0" />
                    <geom class="collision" type="box" pos="-0.049492 -0.225489 0.154528" size="0.2255878895521164 0.011734182946383953 0.012705291621387005" quat="0.9953007102012634 -0.09683211147785187 2.1501044628433757e-17 3.156422991697879e-24" />
                    <body name="ToasterOven027_Door001_Clear">
                        <geom mesh="ToasterOven027_Door001_Clear_vis" type="mesh" solimp="0.998 0.998 0.001" solref="0.001 1" density="100" friction="0.95 0.3 0.1" class="visual" material="ToasterOven027_Door001_Clear_material" />
                        <geom class="collision" type="box" pos="-0.037358 -0.197391 0.012630" size="0.19115224480628967 0.0027262065559625626 0.09558199346065521" quat="1.0 0.0 0.0 0.0" />
                    </body>
                </body>
                <body name="ToasterOven027_Konb001">
                    <joint axis="0.0 1.0 0.0" pos="0.217115 -0.207937 0.040436" limited="true" name="ToasterOven027_Konb001_joint" range="0.0 4.590215932745086" type="hinge" damping="1" frictionloss="1" armature=".01" stiffness="0.05" />
                    <geom mesh="ToasterOven027_Konb001_vis" type="mesh" solimp="0.998 0.998 0.001" solref="0.001 1" density="100" friction="0.95 0.3 0.1" class="visual" material="ToasterOven027_Konb001_material" />
                    <geom class="collision" type="cylinder" pos="0.216800 -0.208095 0.040778" size="0.02389642223715782 0.0049089291132986546" quat="0.7071067094802856 0.7071068286895752 0.0 0.0" />
                </body>
                <body name="ToasterOven027_Konb002">
                    <joint axis="0.0 1.0 0.0" pos="0.217115 -0.207364 -0.054692" limited="true" name="ToasterOven027_Konb002_joint" range="0.0 5.270894341022875" type="hinge" damping="1" frictionloss="1" armature=".01" stiffness="0.05" />
                    <geom mesh="ToasterOven027_Konb002_vis" type="mesh" solimp="0.998 0.998 0.001" solref="0.001 1" density="100" friction="0.95 0.3 0.1" class="visual" material="ToasterOven027_Konb002_material" />
                    <geom class="collision" type="cylinder" pos="0.217428 -0.209187 -0.054502" size="0.024551689624786377 0.0050435373559594154" quat="0.7071067094802856 0.7071068286895752 0.0 0.0" />
                </body>
                <body name="ToasterOven027_Shelf001">
                    <joint axis="0.0 -1.0 0.0" pos="-0.038804 -0.008793 0.018943" limited="true" name="ToasterOven027_Shelf001_joint" range="0.0 0.15" type="slide" damping="1" frictionloss="1" armature=".01" stiffness="0.05" />
                    <geom mesh="ToasterOven027_Shelf001_vis" type="mesh" solimp="0.998 0.998 0.001" solref="0.001 1" density="100" friction="0.95 0.3 0.1" class="visual" material="ToasterOven027_Shelf001_material" />
                    <geom class="collision" type="box" pos="-0.038626 -0.008766 0.018820" size="0.16946637630462646 0.13897095620632172 0.0049700550734996796" quat="1.0 0.0 0.0 0.0" />
                </body>
            </body>
        </body>
    </worldbody>
    <actuator>
        <motor name="ToasterOven027_Button001_joint_actuator" joint="ToasterOven027_Button001_joint" gear="1" />
        <motor name="ToasterOven027_Door001_joint_actuator" joint="ToasterOven027_Door001_joint" gear="20" />
        <motor name="ToasterOven027_Konb001_joint_actuator" joint="ToasterOven027_Konb001_joint" gear="10" />
        <motor name="ToasterOven027_Konb002_joint_actuator" joint="ToasterOven027_Konb002_joint" gear="10" />
        <motor name="ToasterOven027_Shelf001_joint_actuator" joint="ToasterOven027_Shelf001_joint" gear="10" />
    </actuator>
</mujoco>