<?xml version='1.0' encoding='UTF-8'?>
<mujoco model="model">
  <option timestep="0.002" gravity="0.0 0.0 -9.81"/>
  <compiler angle="radian"/>
  <asset>
    <mesh file="visuals/Body001.obj" name="Body001_vis"/>
    <mesh file="visuals/Door001.obj" name="Door001_vis"/>
    <mesh file="visuals/Door001_Clear.obj" name="Door001_Clear_vis"/>
    <mesh file="visuals/Knob001.obj" name="Knob001_vis"/>
    <mesh file="visuals/Knob002.obj" name="Knob002_vis"/>
    <mesh file="visuals/Shelf001.obj" name="Shelf001_vis"/>
    <texture file="visuals/T_BC001.png" name="Body001_material" type="2d"/>
    <material name="Body001_material" rgba="1 1 1 1.0" texture="Body001_material" shininess="0.1" specular="4"/>
    <texture file="visuals/T_BC001.png" name="Door001_material" type="2d"/>
    <material name="Door001_material" rgba="1 1 1 1.0" texture="Door001_material" shininess="0.1" specular="4"/>
    <texture file="visuals/T_BC001.png" name="Door001_Clear_material" type="2d"/>
    <material name="Door001_Clear_material" rgba="1 1 1 0.860534131526947" texture="Door001_Clear_material" shininess="0.5" specular="0.3103448502657381"/>
    <texture file="visuals/T_BC001.png" name="Knob001_material" type="2d"/>
    <material name="Knob001_material" rgba="1 1 1 1.0" texture="Knob001_material" shininess="0.5" specular="0.3103448502657381"/>
    <texture file="visuals/T_BC001.png" name="Shelf001_material" type="2d"/>
    <material name="Shelf001_material" rgba="1 1 1 1.0" texture="Shelf001_material" shininess="0.1" specular="4"/>
    <texture file="visuals/T_BC001.png" name="Knob002_material" type="2d"/>
    <material name="Knob002_material" rgba="1 1 1 1.0" texture="Knob002_material" shininess="0.5" specular="0.3103448502657381"/>
  </asset>
  <default>
    <default class="visual">
      <geom conaffinity="0" contype="0" group="1" type="mesh"/>
    </default>
    <default class="collision">
      <geom group="0" rgba="0.5 0 0 0.5"/>
    </default>
    <default class="spawn">
      <geom group="0" rgba="1 1 1 0.5" contype="0" conaffinity="0"/>
      <site group="0" rgba="1 1 1 0.5"/>
    </default>
    <default class="region">
      <geom group="1" conaffinity="0" contype="0" rgba="0 1 0 0"/>
    </default>
  </default>
  <worldbody>
    <body>
      <body name="object">
        <geom mesh="Body001_vis" type="mesh" solimp="0.998 0.998 0.001" solref="0.001 1" friction="0.95 0.3 0.1" class="visual" material="Body001_material"/>
        <geom class="collision" type="box" pos="0.000000 0.029402 0.141102" size="0.2772040069103241 0.2074829488992691 0.030018068850040436" quat="1.0 0.0 0.0 0.0" density="1000.0"/>
        <geom class="collision" type="box" pos="0.000000 0.029402 -0.128827" size="0.2772040069103241 0.20748287439346313 0.04229314252734184" quat="1.0 0.0 0.0 0.0" density="1000.0"/>
        <geom class="collision" type="box" pos="0.227698 0.017759 0.010064" size="0.049505919218063354 0.219125896692276 0.16105617582798004" quat="1.0 0.0 0.0 0.0" density="1000.0"/>
        <geom class="collision" type="box" pos="-0.252238 0.029395 0.010064" size="0.024965299293398857 0.20749036967754364 0.16105616092681885" quat="1.0 0.0 0.0 0.0" density="1000.0"/>
        <geom class="collision" type="box" pos="-0.019350 0.206079 0.010064" size="0.21508970856666565 0.030805738642811775 0.16105619072914124" quat="1.0 0.0 0.0 0.0" density="1000.0"/>
        <geom class="collision" type="box" pos="-0.039668 -0.170448 -0.128357" size="0.20798663794994354 0.03132147341966629 0.01409910712391138" quat="1.0 0.0 0.0 0.0" density="1000.0"/>
        <geom class="collision" type="box" pos="0.184721 0.004628 0.010064" size="0.031199544668197632 0.17710693180561066 0.16105616092681885" quat="1.0 0.0 0.0 0.0" density="1000.0"/>
        <body name="Door001">
          <joint axis="1.0 0.0 0.0" pos="-0.050802 -0.201197 -0.106915" limited="true" name="Door001_joint" range="0.0 1.5707963267948966" type="hinge" damping="1" frictionloss="1" armature=".01" stiffness="0.05"/>
          <geom mesh="Door001_vis" type="mesh" solimp="0.998 0.998 0.001" solref="0.001 1" friction="0.95 0.3 0.1" class="visual" material="Door001_material"/>
          <geom class="collision" type="box" pos="-0.049492 -0.194869 0.034573" size="0.21992427110671997 0.0032664891332387924 0.13654744625091553" quat="1.0 0.0 0.0 0.0" density="1000.0"/>
          <geom class="collision" type="box" pos="-0.049492 -0.225489 0.154528" size="0.2255878895521164 0.011734182946383953 0.012705291621387005" quat="0.9953007102012634 -0.09683232009410858 2.150109425927051e-17 8.2856648339132e-24" density="1000.0"/>
          <body name="Door001_Clear">
            <geom mesh="Door001_Clear_vis" type="mesh" solimp="0.998 0.998 0.001" solref="0.001 1" friction="0.95 0.3 0.1" class="visual" material="Door001_Clear_material"/>
            <geom class="collision" type="box" pos="-0.037358 -0.197391 0.012630" size="0.1911514401435852 0.0027261930517852306 0.09558159112930298" quat="1.0 0.0 0.0 0.0" density="1000.0"/>
          </body>
        </body>
        <body name="Knob001">
          <joint axis="0.0 1.0 0.0" pos="0.217115 -0.207937 0.040436" limited="true" name="Knob001_joint" range="0.0 4.625122517784973" type="hinge" damping="0.05" armature="0.001"/>
          <geom mesh="Knob001_vis" type="mesh" solimp="0.998 0.998 0.001" solref="0.001 1" friction="0.95 0.3 0.1" class="visual" material="Knob001_material"/>
          <geom class="collision" type="cylinder" pos="0.216800 -0.209298 0.040376" size="0.026287123560905457 0.005400040186941624" quat="0.7071067094802856 0.7071068286895752 0.0 0.0" density="1000.0"/>
          <geom class="collision" type="box" pos="0.217024 -0.223396 0.039989" size="0.00500000175088644 0.00982767716050148 0.020134959369897842" quat="1.0 0.0 0.0 0.0" density="1000.0"/>
        </body>
        <body name="Shelf001">
          <joint axis="0.0 -1.0 0.0" pos="-0.038804 -0.008793 0.018943" limited="true" name="Shelf001_joint" range="0.0 0.15" type="slide" damping="1" frictionloss="1" armature=".01" stiffness="0.05"/>
          <geom mesh="Shelf001_vis" type="mesh" solimp="0.998 0.998 0.001" solref="0.001 1" friction="0.95 0.3 0.1" class="visual" material="Shelf001_material"/>
          <geom class="collision" type="box" pos="-0.038626 -0.008766 0.018820" size="0.16946569085121155 0.13897036015987396 0.004970031790435314" quat="1.0 0.0 0.0 0.0" density="1000.0"/>
        </body>
        <body name="Knob002">
          <joint axis="0.0 1.0 0.0" pos="0.217115 -0.207364 -0.054692" limited="true" name="Knob002_joint" range="0.0 5.270894341022875" type="hinge" damping="0.05" armature="0.001" springref="-0.1"/>
          <geom mesh="Knob002_vis" type="mesh" solimp="0.998 0.998 0.001" solref="0.001 1" friction="0.95 0.3 0.1" class="visual" material="Knob002_material"/>
          <geom class="collision" type="cylinder" pos="0.217428 -0.208794 -0.054696" size="0.026215171441435814 0.005385259166359901" quat="0.7071067094802856 0.7071068286895752 0.0 0.0" density="1000.0"/>
          <geom class="collision" type="box" pos="0.217347 -0.223396 -0.054513" size="0.020134959369897842 0.00982767716050148 0.004999999888241291" quat="1.0 0.0 0.0 0.0" density="1000.0"/>
        </body>
        <geom class="region" name="reg_int" type="box" pos="-0.037285 -0.0006489999999999968 0.013745" size="0.191716 0.177027 0.10065099999999999"/>
        <geom class="region" name="reg_main" type="box" pos="0.0 0.017557500000000004 0.0" size="0.277204 0.2193275 0.17112"/>
      </body>
    </body>
  </worldbody>
  <actuator>
    <motor name="Door001_joint_actuator" joint="Door001_joint" gear="50"/>
    <motor name="Knob001_joint_actuator" joint="Knob001_joint" gear="50"/>
    <motor name="Shelf001_joint_actuator" joint="Shelf001_joint" gear="50"/>
    <motor name="Knob002_joint_actuator" joint="Knob002_joint" gear="50"/>
  </actuator>
</mujoco>
