<?xml version='1.0' encoding='UTF-8'?>
<mujoco model="model">
  <option timestep="0.002" gravity="0.0 0.0 -9.81"/>
  <compiler angle="radian"/>
  <asset>
    <mesh file="visuals/Blade001.obj" name="Blade001_vis"/>
    <mesh file="visuals/Body001.obj" name="Body001_vis"/>
    <mesh file="visuals/Button001.obj" name="Button001_vis"/>
    <mesh file="visuals/Jug001.obj" name="Jug001_vis"/>
    <mesh file="visuals/Jug001_Clear.obj" name="Jug001_Clear_vis"/>
    <mesh file="visuals/Knob001.obj" name="Knob001_vis"/>
    <mesh file="visuals/Lid001.obj" name="Lid001_vis"/>
    <texture file="visuals/T_BC001.png" name="Body001_material" type="2d"/>
    <material name="Body001_material" rgba="1 1 1 1.0" texture="Body001_material" shininess="0.1" specular="4"/>
    <texture file="visuals/T_BC001.png" name="Button001_material" type="2d"/>
    <material name="Button001_material" rgba="1 1 1 1.0" texture="Button001_material" shininess="0.1" specular="4"/>
    <texture file="visuals/T_BC001.png" name="Jug001_Clear_material" type="2d"/>
    <material name="Jug001_Clear_material" rgba="1 1 1 0.699999988079071" texture="Jug001_Clear_material" shininess="0.141421377658844" specular="0.3103448502657381"/>
    <texture file="visuals/T_BC001.png" name="Blade001_material" type="2d"/>
    <material name="Blade001_material" rgba="1 1 1 1.0" texture="Blade001_material" shininess="0.1" specular="4"/>
    <texture file="visuals/T_BC001.png" name="Jug001_material" type="2d"/>
    <material name="Jug001_material" rgba="1 1 1 1.0" texture="Jug001_material" shininess="0.1" specular="4"/>
    <texture file="visuals/T_BC001.png" name="Lid001_material" type="2d"/>
    <material name="Lid001_material" rgba="1 1 1 1.0" texture="Lid001_material" shininess="0.1" specular="4"/>
    <texture file="visuals/T_BC001.png" name="Knob001_material" type="2d"/>
    <material name="Knob001_material" rgba="1 1 1 1.0" texture="Knob001_material" shininess="0.1" specular="4"/>
  </asset>
  <default>
    <default class="visual">
      <geom conaffinity="0" contype="0" group="1" type="mesh"/>
    </default>
    <default class="collision">
      <geom group="0" rgba="0.5 0 0 0.5"/>
    </default>
    <default class="spawn">
      <geom group="0" rgba="1 1 1 0.5" contype="0" conaffinity="0"/>
      <site group="0" rgba="1 1 1 0.5"/>
    </default>
    <default class="region">
      <geom group="1" conaffinity="0" contype="0" rgba="0 1 0 0"/>
    </default>
  </default>
  <worldbody>
    <body>
      <body name="object">
        <geom mesh="Body001_vis" type="mesh" solimp="0.998 0.998 0.001" solref="0.001 1" friction="0.95 0.3 0.1" class="visual" material="Body001_material"/>
        <geom class="collision" type="box" pos="-0.020425 0.010578 -0.135682" size="0.07114976644515991 0.07396972179412842 0.08590729534626007" quat="1.0 0.0 0.0 0.0" density="1000.0"/>
        <geom class="collision" type="cylinder" pos="-0.079273 -0.054104 -0.227276" size="0.01308267842978239 0.00483639445155859" quat="1.0 0.0 0.0 0.0" density="1000.0"/>
        <geom class="collision" type="cylinder" pos="0.038333 -0.054104 -0.227276" size="0.01308267842978239 0.00483639445155859" quat="1.0 0.0 0.0 0.0" density="1000.0"/>
        <geom class="collision" type="cylinder" pos="-0.079273 0.075818 -0.227276" size="0.01308267842978239 0.00483639445155859" quat="1.0 0.0 0.0 0.0" density="1000.0"/>
        <geom class="collision" type="cylinder" pos="0.038333 0.075818 -0.227276" size="0.01308267842978239 0.00483639445155859" quat="1.0 0.0 0.0 0.0" density="1000.0"/>
        <geom class="collision" type="box" pos="-0.106769 0.009860 -0.129311" size="0.007698316592723131 0.02908378839492798 0.07778923213481903" quat="1.0 0.0 0.0 0.0" density="1000.0"/>
        <geom class="collision" type="box" pos="-0.093076 0.057243 -0.129311" size="0.0043806531466543674 0.029083790257573128 0.07767295092344284" quat="0.9581294655799866 0.006108235102146864 0.02049650065600872 -0.28553539514541626" density="1000.0"/>
        <geom class="collision" type="box" pos="-0.051305 0.091214 -0.129311" size="0.00438065268099308 0.029083792120218277 0.07767295092344284" quat="0.8213495016098022 0.012194070965051651 0.01757046952843666 -0.5700241923332214" density="1000.0"/>
        <geom class="collision" type="box" pos="0.002473 0.093833 -0.129311" size="0.0043806531466543674 0.02908378094434738 0.07767295092344284" quat="0.6026906967163086 0.017064303159713745 0.01289287582039833 -0.7976882457733154" density="1000.0"/>
        <geom class="collision" type="box" pos="0.047348 0.064081 -0.129311" size="0.004380653612315655 0.02908378839492798 0.07767295092344284" quat="0.3239506483078003 0.020233428105711937 0.006930013187229633 -0.9458321928977966" density="1000.0"/>
        <geom class="collision" type="box" pos="0.065871 0.013526 -0.129311" size="0.008447176776826382 0.02927297353744507 0.07778921723365784" quat="1.0 0.0 0.0 0.0" density="1000.0"/>
        <geom class="collision" type="box" pos="0.050841 -0.038176 -0.129311" size="0.0043806531466543674 0.029083792120218277 0.07767295092344284" quat="0.29940521717071533 -0.020405719056725502 0.0064049335196614265 0.9538863301277161" density="1000.0"/>
        <geom class="collision" type="box" pos="0.006934 -0.067495 -0.108718" size="0.0016447921516373754 0.02908378653228283 0.05694369226694107" quat="0.5818799734115601 -0.017391711473464966 0.012447686865925789 0.8129934072494507" density="1000.0"/>
        <geom class="collision" type="box" pos="-0.044628 -0.068487 -0.109307" size="0.0015786336734890938 0.029083790257573128 0.05753026157617569" quat="0.8063479661941528 -0.012643959373235703 0.01724955067038536 0.5910546183586121" density="1000.0"/>
        <geom class="collision" type="box" pos="-0.089722 -0.040937 -0.129311" size="0.004380652215331793 0.02908378653228283 0.07767295092344284" quat="0.9504324793815613 -0.006635751109570265 0.02033185213804245 0.31019455194473267" density="1000.0"/>
        <body name="Button001">
          <joint axis="0.0 1.0 0.0" pos="-0.045038 -0.085252 -0.155139" limited="true" name="Button001_joint" range="0.0 0.0005" type="slide" damping="1" frictionloss="1" armature=".01" stiffness="0.05"/>
          <geom mesh="Button001_vis" type="mesh" solimp="0.998 0.998 0.001" solref="0.001 1" friction="0.95 0.3 0.1" class="visual" material="Button001_material"/>
          <geom class="collision" type="cylinder" pos="-0.019819 -0.088158 -0.120115" size="0.007343614939600229 0.0016827437793835998" quat="0.7071067094802856 0.7071068286895752 0.0 0.0" density="1000.0"/>
        </body>
        <body name="Jug001_Clear">
          <geom class="region" name="reg_int" type="box" pos="-0.020664 0.009729500000000002 0.09984649999999999" size="0.063328 0.0627345 0.1166465"/>
          <joint axis="0.0 0.0 1.0" pos="0.000791 0.008689 0.084590" limited="true" name="Jug001_Clear_joint" range="0.0 0.1" type="slide" damping="1" frictionloss="1" armature=".01" stiffness="0.05"/>
          <geom mesh="Jug001_Clear_vis" type="mesh" solimp="0.998 0.998 0.001" solref="0.001 1" friction="0.95 0.3 0.1" class="visual" material="Jug001_Clear_material"/>
          <geom class="collision" type="box" pos="-0.059117 0.064398 0.081959" size="0.028023838996887207 0.0020834733732044697 0.13005328178405762" quat="0.9469504356384277 -0.02456554025411606 -0.008309957571327686 0.3203316628932953" density="1000.0"/>
          <geom class="collision" type="box" pos="0.002601 0.076044 0.081927" size="0.012392974458634853 0.0014961141860112548 0.12993013858795166" quat="0.9747089147567749 -0.025285642594099045 0.00575824873521924 -0.22196851670742035" density="1000.0"/>
          <geom class="collision" type="box" pos="-0.029463 0.081530 0.081655" size="0.009814273566007614 0.0016803478356450796 0.1300542801618576" quat="0.996727466583252 -0.025856811553239822 -0.0019861608743667603 0.07656250149011612" density="1000.0"/>
          <geom class="collision" type="box" pos="0.101808 -0.001526 0.121730" size="0.010741529986262321 0.01777033507823944 0.0739496573805809" quat="1.0 0.0 0.0 0.0" density="1000.0"/>
          <geom class="collision" type="box" pos="0.076898 -0.001526 0.043010" size="0.008844220079481602 0.01777033880352974 0.024057047441601753" quat="0.5734533071517944 -4.337584148605229e-15 -0.8192382454872131 -1.1007189471001766e-07" density="1000.0"/>
          <geom class="collision" type="box" pos="0.074342 -0.001526 0.197213" size="0.018335478380322456 0.017770294100046158 0.008909444324672222" quat="1.0 0.0 0.0 0.0" density="1000.0"/>
          <geom class="collision" type="box" pos="-0.013637 0.081463 0.081713" size="0.009814273566007614 0.0016803450416773558 0.1300542801618576" quat="0.9917929768562317 -0.025728829205036163 0.0032478119246661663 -0.1251964271068573" density="1000.0"/>
          <geom class="collision" type="box" pos="0.021820 0.063216 0.081892" size="0.013895096257328987 0.001496114069595933 0.13005328178405762" quat="0.9332175850868225 -0.02420927956700325 0.009296861477196217 -0.3583747446537018" density="1000.0"/>
          <geom class="collision" type="box" pos="0.038940 0.044985 0.081822" size="0.013895098119974136 0.0014961148845031857 0.1301158219575882" quat="0.8938452005386353 -0.023187892511487007 0.011612174101173878 -0.44762516021728516" density="1000.0"/>
          <geom class="collision" type="box" pos="0.049548 0.026145 0.081767" size="0.013895098119974136 0.001496114069595933 0.13005328178405762" quat="0.8285778164863586 -0.021494749933481216 0.01450851745903492 -0.5592730045318604" density="1000.0"/>
          <geom class="collision" type="box" pos="0.051627 0.002516 0.081692" size="0.013895095326006413 0.0014961144188418984 0.1301158219575882" quat="0.6938533186912537 -0.017999760806560516 0.018668951466679573 -0.7196492552757263" density="1000.0"/>
          <geom class="collision" type="box" pos="0.044334 -0.019255 0.081908" size="0.013895101845264435 0.0014961172128096223 0.13005328178405762" quat="0.4744383990764618 -0.012307754717767239 0.02282630279660225 -0.8799066543579102" density="1000.0"/>
          <geom class="collision" type="box" pos="0.027787 -0.039090 0.082002" size="0.013895097188651562 0.0014961173292249441 0.13005328178405762" quat="0.3675457537174225 -0.009534777142107487 0.024116583168506622 -0.9296438097953796" density="1000.0"/>
          <geom class="collision" type="box" pos="0.007308 -0.055324 0.082150" size="0.013895098119974136 0.0014961144188418984 0.12987081706523895" quat="0.27956363558769226 -0.007252366282045841 0.02489827573299408 -0.9597768783569336" density="1000.0"/>
          <geom class="collision" type="box" pos="-0.010352 -0.063875 0.081897" size="0.00841239932924509 0.001496114069595933 0.12990111112594604" quat="0.10235937684774399 -0.002655386459082365 0.02579679898917675 -0.9944093823432922" density="1000.0"/>
          <geom class="collision" type="box" pos="-0.025328 -0.065656 0.081740" size="0.00841239932924509 0.0014961144188418984 0.13000434637069702" quat="0.014749111607670784 -0.0003826175525318831 -0.025930186733603477 0.9995548725128174" density="1000.0"/>
          <geom class="collision" type="box" pos="-0.038845 -0.063171 0.081827" size="0.008412400260567665 0.0014961141860112548 0.12996487319469452" quat="0.18885262310504913 -0.004899164661765099 -0.025466036051511765 0.9816629886627197" density="1000.0"/>
          <geom class="collision" type="box" pos="-0.055416 -0.052828 0.081903" size="0.013023199513554573 0.0014961143024265766 0.13005898892879486" quat="0.3136133849620819 -0.008135673590004444 -0.024623794481158257 0.9491965770721436" density="1000.0"/>
          <geom class="collision" type="box" pos="-0.076211 -0.032602 0.082008" size="0.01790199801325798 0.0014961148845031857 0.13000606000423431" quat="0.4126756191253662 -0.010705524124205112 -0.023620188236236572 0.9105088114738464" density="1000.0"/>
          <geom class="collision" type="box" pos="-0.080403 0.046393 0.081970" size="0.009814275428652763 0.001680344925262034 0.1299208700656891" quat="0.8943629860877991 -0.02320133149623871 -0.011585312895476818 0.44658970832824707" density="1000.0"/>
          <geom class="collision" type="box" pos="-0.089073 0.030584 0.075382" size="0.009814274497330189 0.0016803450416773558 0.12314633280038834" quat="0.835515558719635 -0.02167471870779991 -0.014238237403333187 0.5488545298576355" density="1000.0"/>
          <geom class="collision" type="box" pos="-0.092614 0.015737 0.075188" size="0.009814275428652763 0.0016803451580926776 0.12331690639257431" quat="0.724690854549408 -0.018799737095832825 -0.017863113433122635 0.6885859966278076" density="1000.0"/>
          <geom class="collision" type="box" pos="-0.091700 -0.001619 0.075315" size="0.009814274497330189 0.0016803448088467121 0.1232306957244873" quat="0.6293444037437439 -0.016326285898685455 -0.020148780196905136 0.7766937017440796" density="1000.0"/>
          <geom class="collision" type="box" pos="-0.087247 -0.017950 0.081988" size="0.009814273566007614 0.0016803448088467121 0.12987521290779114" quat="0.5572676658630371 -0.014456488192081451 -0.02152976021170616 0.8299278616905212" density="1000.0"/>
          <geom class="collision" type="box" pos="-0.105044 0.011516 0.207989" size="0.0253608338534832 0.0016803448088467121 0.010355044156312943" quat="0.6644766330718994 -0.25481677055358887 -0.2662017047405243 0.6501352787017822" density="1000.0"/>
          <geom class="collision" type="box" pos="-0.100480 0.039515 0.214238" size="0.009460925124585629 0.0009152903221547604 0.0032383257057517767" quat="0.9881901741027832 0.0 0.0 0.15323251485824585" density="1000.0"/>
          <geom class="collision" type="box" pos="-0.097472 0.040198 0.207827" size="0.006173263303935528 0.0009152903221547604 0.0036670449189841747" quat="0.9871951937675476 0.0 0.0 0.15951703488826752" density="1000.0"/>
          <geom class="collision" type="box" pos="-0.101875 -0.017288 0.214238" size="0.009460925124585629 0.0009152903221547604 0.0032383257057517767" quat="0.9885324835777283 0.0 -0.0 -0.15100839734077454" density="1000.0"/>
          <geom class="collision" type="box" pos="-0.099019 -0.018453 0.207827" size="0.006173263303935528 0.0009152903221547604 0.0036670449189841747" quat="0.9894733428955078 0.0 -0.0 -0.14471545815467834" density="1000.0"/>
          <body name="Blade001">
            <joint axis="0.0 0.0 1.0" pos="-0.020521 0.008475 0.016824" limited="false" name="Blade001_joint" range="0 360" type="hinge" damping="1" frictionloss="1" armature=".01" stiffness="0.05"/>
            <geom mesh="Blade001_vis" type="mesh" solimp="0.998 0.998 0.001" solref="0.001 1" friction="0.95 0.3 0.1" class="visual" material="Blade001_material"/>
            <geom class="collision" type="cylinder" pos="-0.020762 0.008603 0.015648" size="0.005578401032835245 0.009748686105012894" quat="1.0 0.0 0.0 0.0" density="1000.0"/>
            <geom class="collision" type="box" pos="-0.042655 0.008259 0.017690" size="0.005888754967600107 0.005354186054319143 0.0005539986887015402" quat="0.9403565526008606 0.22859342396259308 0.2510433495044708 0.021257082000374794" density="1000.0"/>
            <geom class="collision" type="box" pos="-0.035212 0.009072 0.014279" size="0.002375200856477022 0.005354185588657856 0.0005539986887015402" quat="0.9515479207038879 0.15689902007579803 0.2630090117454529 0.02766765095293522" density="1000.0"/>
            <geom class="collision" type="box" pos="-0.030513 0.009405 0.012824" size="0.002375200856477022 0.005354185588657856 0.0005539986887015402" quat="0.9828904867172241 0.15931963920593262 0.09243089705705643 -0.00021640831255353987" density="1000.0"/>
            <geom class="collision" type="box" pos="-0.025778 0.009499 0.012182" size="0.002375200856477022 0.005354185588657856 0.0005539986887015402" quat="0.9911357164382935 0.09542809426784515 0.09225142747163773 0.005761029198765755" density="1000.0"/>
            <geom class="collision" type="box" pos="-0.013339 0.007884 0.012458" size="0.002375201089307666 0.005354185588657856 0.0005539986887015402" quat="0.9974440336227417 -0.06621213257312775 0.0006647424306720495 0.026849370449781418" density="1000.0"/>
            <geom class="collision" type="box" pos="-0.008574 0.008177 0.012820" size="0.0023752006236463785 0.005354185588657856 0.0005539987469092011" quat="0.9935071468353271 -0.08202355355024338 -0.07651028037071228 -0.019022971391677856" density="1000.0"/>
            <geom class="collision" type="box" pos="-0.004265 0.007704 0.013615" size="0.002375200856477022 0.005354186054319143 0.0005539986887015402" quat="0.985020101070404 -0.1533612459897995 -0.07494162023067474 -0.02448371797800064" density="1000.0"/>
            <geom class="collision" type="box" pos="0.000610 0.007834 0.015193" size="0.002375201089307666 0.005354186054319143 0.0005539986887015402" quat="0.957770824432373 -0.15528972446918488 -0.24198324978351593 0.0020541767589747906" density="1000.0"/>
            <geom class="collision" type="box" pos="0.004691 0.008164 0.017214" size="0.002375200856477022 0.005354185588657856 0.0005539986887015402" quat="0.9437424540519714 -0.2432917356491089 -0.21870483458042145 0.04824477806687355" density="1000.0"/>
            <geom class="collision" type="box" pos="0.007151 0.008693 0.018938" size="0.002375200856477022 0.005354185588657856 0.0005539986887015402" quat="0.8137325048446655 -0.31561368703842163 -0.3493519723415375 0.340852826833725" density="1000.0"/>
            <geom class="collision" type="box" pos="-0.022311 0.023493 0.020433" size="0.002061778213828802 0.005354185588657856 0.0005539987469092011" quat="0.7475223541259766 0.29476454854011536 0.07653047889471054 -0.5903111696243286" density="1000.0"/>
            <geom class="collision" type="box" pos="-0.021835 0.019641 0.019098" size="0.002375200856477022 0.005354185588657856 0.0005539986887015402" quat="0.7485984563827515 0.2202669084072113 0.013303541578352451 -0.6252246499061584" density="1000.0"/>
            <geom class="collision" type="box" pos="-0.021108 0.015899 0.018358" size="0.002375200856477022 0.005354185122996569 0.0005539986887015402" quat="0.7479897737503052 0.18121476471424103 -0.03297616168856621 -0.6376402378082275" density="1000.0"/>
            <geom class="collision" type="box" pos="-0.020840 0.006913 0.017694" size="0.002375200856477022 0.005354185588657856 0.0005539986887015402" quat="0.7766215205192566 -0.04996641352772713 0.0434492826461792 -0.6264778971672058" density="1000.0"/>
            <geom class="collision" type="box" pos="-0.019822 0.002221 0.017868" size="0.002375200856477022 0.005354185588657856 0.0005539986887015402" quat="0.7438734173774719 -0.11205488443374634 -0.0050377692095935345 -0.6588404178619385" density="1000.0"/>
            <geom class="collision" type="box" pos="-0.019578 -0.002074 0.018851" size="0.002375200856477022 0.005354185122996569 0.0005539986887015402" quat="0.7338717579841614 -0.16533643007278442 0.04242377728223801 -0.657492458820343" density="1000.0"/>
            <geom class="collision" type="box" pos="-0.018592 -0.006673 0.020749" size="0.002375200856477022 0.005354185588657856 0.0005539986887015402" quat="0.7303425669670105 -0.2751429080963135 -0.08346966654062271 -0.6196200251579285" density="1000.0"/>
            <geom class="collision" type="box" pos="-0.018192 -0.010862 0.022835" size="0.002375200856477022 0.005354185588657856 0.0005539986887015402" quat="0.7495883703231812 -0.3710985481739044 -0.09950321167707443 -0.538982629776001" density="1000.0"/>
            <geom class="collision" type="box" pos="-0.017144 -0.012421 0.024364" size="0.002375200856477022 0.005354185588657856 0.0005539986887015402" quat="0.8404426574707031 -0.4668102562427521 -0.06121203675866127 -0.26832324266433716" density="1000.0"/>
            <geom class="collision" type="box" pos="-0.022938 0.026926 0.022525" size="0.002061778213828802 0.005354185588657856 0.0005539987469092011" quat="0.740454375743866 0.31209465861320496 0.06276106834411621 -0.59193354845047" density="1000.0"/>
            <geom class="collision" type="box" pos="-0.024203 0.030077 0.024873" size="0.002061778213828802 0.005354185122996569 0.0005539987469092011" quat="0.7192190885543823 0.35832902789115906 0.025174571201205254 -0.5947188138961792" density="1000.0"/>
          </body>
          <body name="Jug001">
            <geom mesh="Jug001_vis" type="mesh" solimp="0.998 0.998 0.001" solref="0.001 1" friction="0.95 0.3 0.1" class="visual" material="Jug001_material"/>
            <geom class="collision" type="cylinder" pos="-0.020375 0.008347 -0.008680" size="0.017309583723545074 0.013339472934603691" quat="1.0 0.0 0.0 0.0" density="1000.0"/>
            <geom class="collision" type="cylinder" pos="-0.019216 0.008508 -0.043675" size="0.04706339165568352 0.003497780067846179" quat="1.0 0.0 0.0 0.0" density="1000.0"/>
            <geom class="collision" type="cylinder" pos="-0.019216 0.008508 -0.038410" size="0.03889162465929985 0.0028904490172863007" quat="1.0 0.0 0.0 0.0" density="1000.0"/>
            <geom class="collision" type="cylinder" pos="-0.019216 0.008508 -0.032873" size="0.03192101791501045 0.0023723894264549017" quat="1.0 0.0 0.0 0.0" density="1000.0"/>
            <geom class="collision" type="cylinder" pos="-0.019216 0.008508 -0.027956" size="0.026319386437535286 0.0019560728687793016" quat="1.0 0.0 0.0 0.0" density="1000.0"/>
          </body>
          <body name="Lid001">
            <joint axis="0.0 0.0 1.0" pos="0.002114 0.007527 0.211691" limited="true" name="Lid001_joint" range="0.0 0.1" type="slide" damping="1" frictionloss="1" armature=".01" stiffness="0.05"/>
            <geom mesh="Lid001_vis" type="mesh" solimp="0.998 0.998 0.001" solref="0.001 1" friction="0.95 0.3 0.1" class="visual" material="Lid001_material"/>
            <geom class="collision" type="box" pos="0.076378 0.005878 0.223889" size="0.030511468648910522 0.016071908175945282 0.005857323762029409" quat="1.0 0.0 0.0 0.0" density="1000.0"/>
            <geom class="collision" type="cylinder" pos="-0.023654 0.007627 0.224357" size="0.08035063743591309 0.006332592573016882" quat="1.0 0.0 0.0 0.0" density="1000.0"/>
          </body>
        </body>
        <body name="Knob001">
          <joint axis="-1.0883673370624386e-18 0.9950984716415405 0.09888920187950134" pos="-0.019276 -0.095814 -0.174621" limited="true" name="Knob001_joint" range="0.0 4.71238898038469" type="hinge" damping="0.05" armature="0.001" springref="-0.01"/>
          <geom mesh="Knob001_vis" type="mesh" solimp="0.998 0.998 0.001" solref="0.001 1" friction="0.95 0.3 0.1" class="visual" material="Knob001_material"/>
          <geom class="collision" type="cylinder" pos="-0.018720 -0.088521 -0.173764" size="0.023056725040078163 0.005283305421471596" quat="0.6761780381202698 0.7367382645606995 -6.723511375239752e-18 6.723515097552509e-18" density="1000.0"/>
          <geom class="collision" type="box" pos="-0.019484 -0.100198 -0.174144" size="0.00802884716540575 0.006722955498844385 0.021096782758831978" quat="0.9083757996559143 0.058258578181266785 0.41322752833366394 -0.026502244174480438" density="1000.0"/>
        </body>
        <geom class="region" name="reg_main" type="box" pos="-0.020540000000000003 0.0107205 0.0" size="0.095447 0.0980135 0.230815"/>
      </body>
    </body>
  </worldbody>
  <actuator>
    <motor name="Button001_joint_actuator" joint="Button001_joint" gear="0.5"/>
    <motor name="Jug001_Clear_joint_actuator" joint="Jug001_Clear_joint" gear="0.5"/>
    <motor name="Knob001_joint_actuator" joint="Knob001_joint" gear="0.5"/>
    <motor name="Blade001_joint_actuator" joint="Blade001_joint" gear="30"/>
    <motor name="Lid001_joint_actuator" joint="Lid001_joint" gear="0.5"/>
  </actuator>
</mujoco>
