<?xml version='1.0' encoding='UTF-8'?>
<mujoco model="model">
  <compiler angle="radian"/>
  <asset>
    <mesh file="visuals/Body001.obj" name="Body001_vis"/>
    <mesh file="visuals/Button001.obj" name="Button001_vis"/>
    <mesh file="visuals/Handle001.obj" name="Handle001_vis"/>
    <mesh file="visuals/Lever001.obj" name="Lever001_vis"/>
    <mesh file="visuals/Lid001.obj" name="Lid001_vis"/>
    <texture file="visuals/T_BC001.png" name="Body001_material" type="2d"/>
    <material name="Body001_material" rgba="1 1 1 1.0" texture="Body001_material" shininess="1" specular="1"/>
    <texture file="visuals/T_BC001.png" name="Handle001_material" type="2d"/>
    <material name="Handle001_material" rgba="1 1 1 1.0" texture="Handle001_material" shininess="1" specular="1"/>
    <texture file="visuals/T_BC001.png" name="Button001_material" type="2d"/>
    <material name="Button001_material" rgba="1 1 1 1.0" texture="Button001_material" shininess="0.2512328028678894" specular="0.3103448502657381"/>
    <texture file="visuals/T_BC001.png" name="Lever001_material" type="2d"/>
    <material name="Lever001_material" rgba="1 1 1 1.0" texture="Lever001_material" shininess="0.2512328028678894" specular="0.3103448502657381"/>
    <texture file="visuals/T_BC001.png" name="Lid001_material" type="2d"/>
    <material name="Lid001_material" rgba="1 1 1 1.0" texture="Lid001_material" shininess="0.2512328028678894" specular="0.3103448502657381"/>
  </asset>
  <default>
    <default class="visual">
      <geom conaffinity="0" contype="0" group="1" type="mesh"/>
    </default>
    <default class="collision">
      <geom group="0" rgba="0.5 0 0 0.5"/>
    </default>
    <default class="spawn">
      <geom group="0" rgba="1 1 1 0.5" contype="0" conaffinity="0"/>
      <site group="0" rgba="1 1 1 0.5"/>
    </default>
    <default class="region">
      <geom group="1" conaffinity="0" contype="0" rgba="0 1 0 0"/>
    </default>
  </default>
  <worldbody>
    <body>
      <body name="object">
        <geom mesh="Body001_vis" type="mesh" solimp="0.998 0.998 0.001" solref="0.001 1" density="100" friction="0.95 0.3 0.1" class="visual" material="Body001_material"/>
        <geom class="collision" type="cylinder" pos="-0.023023681715130806 -3.276069037383422e-05 -0.11071483790874481" size="0.07277010381221771 0.008798042312264442" quat="1.0 -8.146034957690063e-08 0.0 0.0"/>
        <geom class="collision" type="cylinder" pos="-0.023023683577775955 -3.2763189665274695e-05 -0.09461458027362823" size="0.01096278801560402 0.007078821305185556" quat="1.0 -8.146035668232798e-08 0.0 0.0"/>
        <body name="Handle001">
          <joint axis="0.0 0.0 1.0" pos="0.018864015117287636 -0.0031844403129070997 0.0412430614233017" limited="true" name="Handle001_joint" range="0.0 0.15" type="slide" damping="1" frictionloss="1" armature=".01" stiffness="0.05"/>
          <geom mesh="Handle001_vis" type="mesh" solimp="0.998 0.998 0.001" solref="0.001 1" density="100" friction="0.95 0.3 0.1" class="visual" material="Handle001_material"/>
          <geom class="collision" type="box" pos="-0.023034879937767982 -0.06774058938026428 0.005778426770120859" size="0.006442265119403601 0.003759863320738077 0.10746723413467407" quat="1.0 0.0 0.0 0.0"/>
          <geom class="collision" type="box" pos="0.004113842733204365 -0.061874181032180786 0.005778426770120859" size="0.006442171521484852 0.003759845159947872 0.10746721923351288" quat="4.348970890077908e-07 0.20617415010929108 -0.9785153269767761 3.672768400519999e-08"/>
          <geom class="collision" type="box" pos="-0.009210018441081047 -0.06623754650354385 0.005778426770120859" size="0.006442172918468714 0.003759845159947872 0.10746721923351288" quat="4.2588473547766625e-07 0.10693040490150452 -0.9942665100097656 9.05527670624906e-08"/>
          <geom class="collision" type="box" pos="0.01626894250512123 -0.05454995110630989 0.005778426770120859" size="0.006442171521484852 0.0037598456256091595 0.10746721923351288" quat="4.1167294284605305e-07 0.3320642411708832 -0.9432567954063416 1.349511933312897e-07"/>
          <geom class="collision" type="box" pos="0.026787778362631798 -0.04496612399816513 0.005778426770120859" size="0.006442171521484852 0.0037598456256091595 0.10746721923351288" quat="3.698584976064012e-07 0.41601479053497314 -0.9093578457832336 2.326648882444715e-07"/>
          <geom class="collision" type="box" pos="0.03528076782822609 -0.03377407789230347 0.005778426770120859" size="0.006442171987146139 0.0037598456256091595 0.10746721923351288" quat="4.2593117655087553e-07 0.5013291239738464 -0.865256667137146 1.2882948396963911e-07"/>
          <geom class="collision" type="box" pos="0.04107045754790306 -0.021115975454449654 0.005778426770120859" size="0.006442171987146139 0.0037598460912704468 0.10746721923351288" quat="3.0616217827628134e-07 0.5887382626533508 -0.8083237409591675 3.153313343773334e-07"/>
          <geom class="collision" type="box" pos="0.04581490531563759 -0.003122053574770689 -0.09600447863340378" size="0.009686942212283611 0.0037598449271172285 0.004450293257832527" quat="6.601778181902773e-07 0.6742482781410217 -0.7385047078132629 -8.071012302934832e-08"/>
          <geom class="collision" type="box" pos="0.044479336589574814 0.006276293192058802 0.01917729154229164" size="0.006442183628678322 0.0037598456256091595 0.09406835585832596" quat="-2.3746520128042903e-07 -0.7387588024139404 0.6739699244499207 -3.7231245642033173e-07"/>
          <geom class="collision" type="box" pos="0.041773878037929535 0.01991182379424572 0.005778426770120859" size="0.00644217012450099 0.0037598460912704468 0.10746721923351288" quat="2.7327934049026226e-07 0.8089416027069092 -0.5878890156745911 2.476132863193925e-07"/>
          <geom class="collision" type="box" pos="0.03625473007559776 0.03276817873120308 0.005778426770120859" size="0.006442171521484852 0.0037598449271172285 0.10746721923351288" quat="-3.189085973076544e-08 -0.8600682616233826 0.5101789236068726 -4.354070597401005e-07"/>
          <geom class="collision" type="box" pos="0.028138352558016777 0.04413112252950668 0.005778426770120859" size="0.006442170590162277 0.0037598460912704468 0.10746721923351288" quat="2.397534046849614e-07 0.9088814854621887 -0.41705453395843506 3.4146498251175217e-07"/>
          <geom class="collision" type="box" pos="0.01823635958135128 0.05381667613983154 0.005778426770120859" size="0.0064421710558235645 0.0037598456256091595 0.10746721923351288" quat="2.0099133735129726e-07 0.9453177452087402 -0.3261508345603943 3.5107305507153796e-07"/>
          <geom class="collision" type="box" pos="0.006151964422315359 0.06094106286764145 0.005778426770120859" size="0.0064421710558235645 0.0037598449271172285 0.10746721923351288" quat="1.5426923027916928e-07 0.9778256416320801 -0.20942065119743347 3.5980457369078067e-07"/>
          <geom class="collision" type="box" pos="-0.0066388617269694805 0.06565307825803757 0.005778426770120859" size="0.006442171987146139 0.0037598449271172285 0.10746721923351288" quat="1.2839821295074216e-07 0.9908782243728638 -0.13476021587848663 3.8386028222703317e-07"/>
          <geom class="collision" type="box" pos="-0.020278898999094963 0.06771973520517349 0.005778426770120859" size="0.006442171987146139 0.0037598456256091595 0.10746721923351288" quat="2.040321902541109e-07 0.9997295141220093 -0.02325650118291378 3.9859031630840036e-07"/>
          <geom class="collision" type="box" pos="-0.034031666815280914 0.06678034365177155 0.005778426770120859" size="0.0064421710558235645 0.0037598449271172285 0.10746721923351288" quat="1.0381260295844186e-07 -0.9973849654197693 -0.07227186858654022 -3.880241763454251e-07"/>
          <geom class="collision" type="box" pos="-0.047371089458465576 0.06317306309938431 0.005778426770120859" size="0.006442171521484852 0.003759845159947872 0.10746721923351288" quat="1.9359431835397345e-09 0.9829936027526855 0.18363972008228302 4.0075687479657063e-07"/>
          <geom class="collision" type="box" pos="-0.059733547270298004 0.056822746992111206 0.005778426770120859" size="0.0064421710558235645 0.0037598456256091595 0.10746721923351288" quat="-4.064979108875377e-08 0.9561119079589844 0.29300183057785034 3.903171830188512e-07"/>
          <geom class="collision" type="box" pos="-0.07036751508712769 0.04821787774562836 0.005778426770120859" size="0.006442171987146139 0.0037598456256091595 0.10746721923351288" quat="3.3606863780732965e-07 -0.9239467978477478 -0.3825210630893707 -3.0273454854068405e-07"/>
          <geom class="collision" type="box" pos="-0.07916026562452316 0.03773421421647072 0.005778426770120859" size="0.006442171987146139 0.0037598460912704468 0.10746721923351288" quat="-1.2643118907362805e-07 0.8839080333709717 0.4676608145236969 4.004001254998002e-07"/>
          <geom class="collision" type="box" pos="-0.08581119775772095 0.025785086676478386 0.005778426770120859" size="0.006442171987146139 0.0037598460912704468 0.10746721923351288" quat="4.767065604482923e-07 -0.8366203308105469 -0.5477831959724426 -1.5499915662076091e-07"/>
          <geom class="collision" type="box" pos="-0.0369294248521328 -0.06624718010425568 0.005778426770120859" size="0.0064421724528074265 0.0037598456256091595 0.10746721923351288" quat="4.3108633462907164e-07 -0.11771973967552185 -0.9930468797683716 -4.278658849443673e-08"/>
          <geom class="collision" type="box" pos="-0.05002386122941971 -0.06213487312197685 0.005778426770120859" size="0.006442171987146139 0.0037598456256091595 0.10746721923351288" quat="4.169533269759995e-07 -0.2019345611333847 -0.9793990254402161 -1.226243568908103e-07"/>
          <geom class="collision" type="box" pos="-0.062256887555122375 -0.05527814105153084 0.005778426770120859" size="0.006442171521484852 0.0037598456256091595 0.10746721923351288" quat="4.2050552906403027e-07 -0.3024821877479553 -0.9531550407409668 -1.0684529883064897e-07"/>
          <geom class="collision" type="box" pos="-0.07269997149705887 -0.04629600793123245 0.005778426770120859" size="0.006442171987146139 0.0037598456256091595 0.10746721923351288" quat="4.162581888067507e-07 -0.39777764678001404 -0.9174818396568298 -1.2875644017640298e-07"/>
          <geom class="collision" type="box" pos="-0.08097868412733078 -0.03514047712087631 0.005778426770120859" size="0.006442171987146139 0.0037598449271172285 0.10746721923351288" quat="3.63392075541924e-07 -0.4836215674877167 -0.8752772212028503 -2.3790701675352466e-07"/>
          <geom class="collision" type="box" pos="-0.0870208740234375 -0.02278553694486618 0.005778426770120859" size="0.006442170590162277 0.0037598456256091595 0.10746721923351288" quat="3.371456500644854e-07 -0.5654937028884888 -0.8247526288032532 -2.742099809438514e-07"/>
          <geom class="collision" type="box" pos="-0.09076343476772308 -0.009258224628865719 0.005778426770120859" size="0.00644217012450099 0.0037598449271172285 0.10746721923351288" quat="3.715065304277232e-07 -0.6412659883499146 -0.7673186659812927 -2.3088995249054278e-07"/>
          <geom class="collision" type="box" pos="-0.091529980301857 0.004629814065992832 0.005778426770120859" size="0.006442172918468714 0.0037598460912704468 0.10746721923351288" quat="1.5400815982502536e-06 -0.7232064008712769 -0.6906319856643677 9.131218234870175e-07"/>
          <geom class="collision" type="box" pos="-0.08988972008228302 0.015556933358311653 0.005778426770120859" size="0.003726500552147627 0.003759845159947872 0.10746721923351288" quat="3.066882356961287e-07 -0.7830078601837158 -0.6220118403434753 -2.646917209858657e-07"/>
          <geom class="collision" type="box" pos="0.07228168845176697 -0.007208599708974361 -0.039597008377313614" size="0.022511886432766914 0.014028203673660755 0.009019003249704838" quat="1.0 0.0 0.0 0.0"/>
          <geom class="collision" type="box" pos="0.06340934336185455 -0.007028752472251654 0.1050092801451683" size="0.013639543205499649 0.014208050444722176 0.012554212473332882" quat="1.0 0.0 0.0 0.0"/>
          <geom class="collision" type="box" pos="0.09318245202302933 -0.007028752472251654 0.032909683883190155" size="0.008785214275121689 0.014208050444722176 0.06187383458018303" quat="1.0 0.0 0.0 0.0"/>
          <geom class="collision" type="box" pos="0.044371120631694794 -0.007705533877015114 0.020427677780389786" size="0.006442182697355747 0.0037598456256091595 0.09281797707080841" quat="6.462651640504191e-07 0.6575609445571899 -0.7534013390541077 -8.177384103191798e-08"/>
          <body name="Button001">
            <joint axis="0.0 0.0 -1.0" pos="0.08598235994577408 -0.007813122123479843 0.11077475547790527" limited="true" name="Button001_joint" range="0.0 0.0025" type="slide" damping="1" frictionloss="1" armature=".01" stiffness="0.2" springref="-1"/>
            <geom mesh="Button001_vis" type="mesh" solimp="0.998 0.998 0.001" solref="0.001 1" density="100" friction="0.95 0.3 0.1" class="visual" material="Button001_material"/>
            <geom class="collision" type="box" pos="0.086179219186306 -0.0077461921609938145 0.1106448695063591" size="0.0066857365891337395 0.006490183062851429 0.002256079576909542" quat="0.974043607711792 -0.006441202946007252 0.22453685104846954 -0.027941640466451645"/>
          </body>
          <body name="Lever001">
            <joint axis="0.0 0.0 -1.0" pos="0.0663880705833435 -0.004385690670460463 -0.07669314742088318" limited="true" name="Lever001_joint" range="0.0 0.01" type="slide" damping="1" frictionloss="1" armature=".01" stiffness="0.2" springref="-1"/>
            <geom mesh="Lever001_vis" type="mesh" solimp="0.998 0.998 0.001" solref="0.001 1" density="100" friction="0.95 0.3 0.1" class="visual" material="Lever001_material"/>
            <geom class="collision" type="box" pos="0.06879474222660065 -0.005083506926894188 -0.07645479589700699" size="0.019173555076122284 0.00886817742139101 0.0033816301729530096" quat="0.9995887875556946 -8.142684748690954e-08 2.335827753441322e-09 -0.02867441438138485"/>
          </body>
          <body name="Lid001">
            <joint axis="0.0 1.0 0.0" pos="0.05128675326704979 -0.005694232415407896 0.11794690042734146" limited="true" name="Lid001_joint" range="0.0 1.5707963267948966" type="hinge" damping="1" frictionloss="1" armature=".01" stiffness="0.05"/>
            <geom mesh="Lid001_vis" type="mesh" solimp="0.998 0.998 0.001" solref="0.001 1" density="100" friction="0.95 0.3 0.1" class="visual" material="Lid001_material"/>
            <geom class="collision" type="cylinder" pos="-0.023023683577775955 -3.276097049820237e-05 0.1074153333902359" size="0.0625920295715332 0.005675722844898701" quat="1.0 -8.146034247147327e-08 0.0 0.0"/>
            <geom class="collision" type="cylinder" pos="-0.023023681715130806 -3.2760748581495136e-05 0.11643494665622711" size="0.07064686715602875 0.0027365137357264757" quat="1.0 -8.146034247147327e-08 0.0 0.0"/>
          </body>
        </body>
        <geom class="region" name="reg_main" type="box" pos="-1.6763806343078613e-08 1.862645149230957e-09 3.725290298461914e-09" size="0.10280673205852509 0.07296589761972427 0.11952702701091766"/>
      </body>
    </body>
  </worldbody>
  <actuator>
    <motor name="Handle001_joint_actuator" joint="Handle001_joint" gear="20"/>
    <motor name="Button001_joint_actuator" joint="Button001_joint" gear="0.5"/>
    <motor name="Lever001_joint_actuator" joint="Lever001_joint" gear="1"/>
    <motor name="Lid001_joint_actuator" joint="Lid001_joint" gear="10"/>
  </actuator>
</mujoco>
