<mujoco model="model">
  <compiler angle="radian"/>
  <asset>
    <mesh file="visuals/Body001.obj" name="Body001_vis"/>
    <mesh file="visuals/Door001.obj" name="Door001_vis"/>
    <mesh file="visuals/Door001_Clear.obj" name="Door001_Clear_vis"/>
    <mesh file="visuals/Konb001.obj" name="Konb001_vis"/>
    <mesh file="visuals/Konb002.obj" name="Konb002_vis"/>
    <mesh file="visuals/Shelf001.obj" name="Shelf001_vis"/>
    <texture file="visuals/T_BC001.png" name="Body001_material" type="2d"/>
    <material name="Body001_material" rgba="1 1 1 1.0" texture="Body001_material" shininess="0.4472135901451111" specular="0.3103448502657381"/>
    <texture file="visuals/T_BC001.png" name="Door001_material" type="2d"/>
    <material name="Door001_material" rgba="1 1 1 1.0" texture="Door001_material" shininess="0.4472135901451111" specular="0.3103448502657381"/>
    <texture file="visuals/T_BC001.png" name="Door001_Clear_material" type="2d"/>
    <material name="Door001_Clear_material" rgba="1 1 1 0.8468468189239502" texture="Door001_Clear_material" shininess="0.5" specular="0.3103448502657381"/>
    <texture file="visuals/T_BC001.png" name="Konb001_material" type="2d"/>
    <material name="Konb001_material" rgba="1 1 1 1.0" texture="Konb001_material" shininess="0.4472135901451111" specular="0.3103448502657381"/>
    <texture file="visuals/T_BC001.png" name="Konb002_material" type="2d"/>
    <material name="Konb002_material" rgba="1 1 1 1.0" texture="Konb002_material" shininess="0.4472135901451111" specular="0.3103448502657381"/>
    <texture file="visuals/T_BC001.png" name="Shelf001_material" type="2d"/>
    <material name="Shelf001_material" rgba="1 1 1 1.0" texture="Shelf001_material" shininess="0.4472135901451111" specular="0.3103448502657381"/>
  </asset>
  <default>
    <default class="visual">
      <geom conaffinity="0" contype="0" group="1" type="mesh"/>
    </default>
    <default class="collision">
      <geom group="0" rgba="0.5 0 0 0.5"/>
    </default>
    <default class="spawn">
      <geom group="0" rgba="1 1 1 0.5" contype="0" conaffinity="0"/>
      <site group="0" rgba="1 1 1 0.5"/>
    </default>
    <default class="region">
      <geom group="1" conaffinity="0" contype="0" rgba="0 1 0 0"/>
    </default>
  </default>
  <worldbody>
    <body>
      <body name="object">
        <geom mesh="Body001_vis" type="mesh" solimp="0.998 0.998 0.001" solref="0.001 1" density="100" friction="0.95 0.3 0.1" class="visual" material="Body001_material"/>
        <geom class="collision" type="box" pos="-0.228379 -0.002269 0.006019" size="0.023876165971159935 0.1243625059723854 0.1435151994228363" quat="1.0 0.0 0.0 0.0"/>
        <geom class="collision" type="box" pos="0.190903 -0.002269 0.006019" size="0.06135261431336403 0.12436346709728241 0.14351631700992584" quat="1.0 0.0 0.0 0.0"/>
        <geom class="collision" type="box" pos="-0.037598 -0.004048 0.127868" size="0.16948284208774567 0.12456412613391876 0.021756691858172417" quat="1.0 0.0 0.0 0.0"/>
        <geom class="collision" type="box" pos="0.010521 -0.004780 -0.109736" size="0.2375257909297943 0.12436279654502869 0.028542086482048035" quat="1.0 0.0 0.0 0.0"/>
        <geom class="collision" type="box" pos="-0.037598 0.132632 0.003463" size="0.16952092945575714 0.015192396938800812 0.11441542953252792" quat="1.0 0.0 0.0 0.0"/>
        <geom class="collision" type="box" pos="0.216958 0.127119 -0.077642" size="0.006545425392687321 0.005531701259315014 0.014809888787567616" quat="1.0 0.0 0.0 0.0"/>
        <geom class="collision" type="cylinder" pos="0.228437 -0.094384 -0.143782" size="0.013967673294246197 0.006357755046337843" quat="1.0 0.0 0.0 0.0"/>
        <geom class="collision" type="cylinder" pos="0.228437 0.092605 -0.143782" size="0.013967673294246197 0.006357755046337843" quat="1.0 0.0 0.0 0.0"/>
        <geom class="collision" type="cylinder" pos="-0.218064 -0.094384 -0.143782" size="0.013967673294246197 0.006357755046337843" quat="1.0 0.0 0.0 0.0"/>
        <geom class="collision" type="cylinder" pos="-0.218064 0.092605 -0.143782" size="0.013967673294246197 0.006357755046337843" quat="1.0 0.0 0.0 0.0"/>
        <geom class="collision" type="cylinder" pos="0.067730 0.151962 -0.070450" size="0.010296694934368134 0.004686812404543161" quat="0.7071068286895752 0.7071067690849304 1.5700924318127872e-16 5.9269340452702814e-24"/>
        <body name="Door001">
          <joint axis="1.0 0.0 0.0" pos="-0.035969 -0.136472 -0.108616" limited="true" name="Door001_joint" range="0.0 1.5707963267948966" type="hinge" damping="1" frictionloss="1" armature=".01" stiffness="0.05"/>
          <geom mesh="Door001_vis" type="mesh" solimp="0.998 0.998 0.001" solref="0.001 1" density="100" friction="0.95 0.3 0.1" class="visual" material="Door001_material"/>
          <geom class="collision" type="box" pos="-0.035969 -0.133657 0.005808" size="0.18119259178638458 0.004168638028204441 0.11383190751075745" quat="1.0 0.0 0.0 0.0"/>
          <geom class="collision" type="box" pos="-0.038821 -0.150860 0.098076" size="0.1574646532535553 0.005251881666481495 0.018370822072029114" quat="1.0 0.0 0.0 0.0"/>
          <geom class="collision" type="box" pos="-0.206022 -0.146069 0.098076" size="0.009648275561630726 0.010504058562219143 0.018370667472481728" quat="1.0 0.0 0.0 0.0"/>
          <geom class="collision" type="box" pos="0.128261 -0.146069 0.098076" size="0.009648281149566174 0.010504065081477165 0.018370678648352623" quat="1.0 0.0 0.0 0.0"/>
          <body name="Door001_Clear">
            <geom mesh="Door001_Clear_vis" type="mesh" solimp="0.998 0.998 0.001" solref="0.001 1" density="100" friction="0.95 0.3 0.1" class="visual" material="Door001_Clear_material"/>
            <geom class="collision" type="box" pos="-0.035905 -0.134380 0.003604" size="0.12574484944343567 0.0007578437798656523 0.06399784237146378" quat="1.0 0.0 0.0 0.0"/>
          </body>
        </body>
        <body name="Konb001">
          <joint axis="0.0 -1.0 0.0" pos="0.190791 -0.140002 0.049318" limited="true" name="Konb001_joint" range="0.0 5.515240436302081" type="hinge" damping="1" frictionloss="1" armature=".01" stiffness="0.05"/>
          <geom mesh="Konb001_vis" type="mesh" solimp="0.998 0.998 0.001" solref="0.001 1" density="100" friction="0.95 0.3 0.1" class="visual" material="Konb001_material"/>
          <geom class="collision" type="cylinder" pos="0.190718 -0.139629 0.048922" size="0.02284664288163185 0.006664044689387083" quat="0.7071068286895752 0.7071067690849304 -1.5700924318127872e-16 -5.9269340452702814e-24"/>
        </body>
        <body name="Konb002">
          <joint axis="0.0 -1.0 0.0" pos="0.190503 -0.140001 -0.049749" limited="true" name="Konb002_joint" range="0.0 5.515240436302081" type="hinge" damping="1" frictionloss="1" armature=".01" stiffness="0.05"/>
          <geom mesh="Konb002_vis" type="mesh" solimp="0.998 0.998 0.001" solref="0.001 1" density="100" friction="0.95 0.3 0.1" class="visual" material="Konb002_material"/>
          <geom class="collision" type="cylinder" pos="0.190400 -0.139629 -0.050051" size="0.02332967147231102 0.00673446711152792" quat="0.7071068286895752 0.7071067690849304 -1.5700924318127872e-16 -5.9269340452702814e-24"/>
        </body>
        <body name="Shelf001">
          <joint axis="0.0 -1.0 0.0" pos="-0.037895 0.020445 0.006079" limited="true" name="Shelf001_joint" range="0.0 0.2" type="slide" damping="1" frictionloss="1" armature=".01" stiffness="0.05"/>
          <geom mesh="Shelf001_vis" type="mesh" solimp="0.998 0.998 0.001" solref="0.001 1" density="100" friction="0.95 0.3 0.1" class="visual" material="Shelf001_material"/>
          <geom class="collision" type="box" pos="-0.039367 -0.012189 0.004703" size="0.15599286556243896 0.08875367045402527 0.0036033832002431154" quat="1.0 0.0 0.0 0.0"/>
        </body>
        <geom class="region" name="reg_main" type="box" pos="0.0013895000000000157 0.009796 -0.0006735000000000074" size="0.25018850000000004 0.146777 0.14895150000000001"/>
        <geom class="region" name="reg_int" type="box" pos="-0.03636249999999999 -0.0027935000000000043 0.016015" size="0.1642625 0.1081275 0.092336"/>
      </body>
    </body>
  </worldbody>
  <actuator>
    <motor name="Door001_joint_actuator" joint="Door001_joint" gear="10"/>
    <motor name="Konb001_joint_actuator" joint="Konb001_joint" gear="10"/>
    <motor name="Konb002_joint_actuator" joint="Konb002_joint" gear="10"/>
    <motor name="Shelf001_joint_actuator" joint="Shelf001_joint" gear="5"/>
  </actuator>
</mujoco>
