<?xml version='1.0' encoding='UTF-8'?>
<mujoco model="model">
  <compiler angle="radian"/>
  <asset>
    <mesh file="visuals/Body001.obj" name="Body001_vis"/>
    <mesh file="visuals/Body002.obj" name="Body002_vis"/>
    <mesh file="visuals/Body003.obj" name="Body003_vis"/>
    <mesh file="visuals/Button001.obj" name="Button001_vis"/>
    <mesh file="visuals/Button002.obj" name="Button002_vis"/>
    <mesh file="visuals/Knob001.obj" name="Knob001_vis"/>
    <mesh file="visuals/Knob002.obj" name="Knob002_vis"/>
    <mesh file="visuals/Lever001.obj" name="Lever001_vis"/>
    <mesh file="visuals/Lever002.obj" name="Lever002_vis"/>
    <texture file="visuals/T_BC001.png" name="Body001_material" type="2d"/>
    <material name="Body001_material" rgba="1 1 1 1.0" texture="Body001_material" shininess="0.241421377658844" specular="1"/>
    <texture file="visuals/T_BC001.png" name="Body002_material" type="2d"/>
    <material name="Body002_material" rgba="1 1 1 1.0" texture="Body002_material" shininess="0.141421377658844" specular="1"/>
    <texture file="visuals/T_BC001.png" name="Body003_material" type="2d"/>
    <material name="Body003_material" rgba="1 1 1 1.0" texture="Body003_material" shininess="0.141421377658844" specular="1"/>
    <texture file="visuals/T_BC001.png" name="Button001_material" type="2d"/>
    <material name="Button001_material" rgba="1 1 1 1.0" texture="Button001_material" shininess="0.141421377658844" specular="0.3103448502657381"/>
    <texture file="visuals/T_BC001.png" name="Button002_material" type="2d"/>
    <material name="Button002_material" rgba="1 1 1 1.0" texture="Button002_material" shininess="0.141421377658844" specular="0.3103448502657381"/>
    <texture file="visuals/T_BC001.png" name="Knob001_material" type="2d"/>
    <material name="Knob001_material" rgba="1 1 1 1.0" texture="Knob001_material" shininess="0.141421377658844" specular="0.3103448502657381"/>
    <texture file="visuals/T_BC001.png" name="Knob002_material" type="2d"/>
    <material name="Knob002_material" rgba="1 1 1 1.0" texture="Knob002_material" shininess="0.141421377658844" specular="0.3103448502657381"/>
    <texture file="visuals/T_BC001.png" name="Lever001_material" type="2d"/>
    <material name="Lever001_material" rgba="1 1 1 1.0" texture="Lever001_material" shininess="0.141421377658844" specular="1"/>
    <texture file="visuals/T_BC001.png" name="Lever002_material" type="2d"/>
    <material name="Lever002_material" rgba="1 1 1 1.0" texture="Lever002_material" shininess="0.141421377658844" specular="1"/>
  </asset>
  <default>
    <default class="visual">
      <geom conaffinity="0" contype="0" group="1" type="mesh"/>
    </default>
    <default class="collision">
      <geom group="0" rgba="0.5 0 0 0.5"/>
    </default>
    <default class="spawn">
      <geom group="0" rgba="1 1 1 0.5" contype="0" conaffinity="0"/>
      <site group="0" rgba="1 1 1 0.5"/>
    </default>
    <default class="region">
      <geom group="1" conaffinity="0" contype="0" rgba="0 1 0 0"/>
    </default>
  </default>
  <worldbody>
    <body>
      <body name="object">
        <geom mesh="Body001_vis" type="mesh" solimp="0.998 0.998 0.001" solref="0.001 1" density="100" friction="0.95 0.3 0.1" class="visual" material="Body001_material"/>
        <geom class="collision" type="box" pos="-0.003111 0.030293 0.005018" size="0.014889690093696117 0.11575628072023392 0.20856213569641113" quat="1.0 0.0 0.0 0.0"/>
        <geom class="collision" type="box" pos="0.084713 0.030293 0.005018" size="0.014889608137309551 0.11575628072023392 0.2085607796907425" quat="1.0 0.0 0.0 0.0"/>
        <geom class="collision" type="box" pos="-0.090700 0.030293 0.005018" size="0.014889526180922985 0.11575628072023392 0.20855943858623505" quat="1.0 0.0 0.0 0.0"/>
        <geom class="collision" type="box" pos="-0.248715 0.029770 0.005018" size="0.09614696353673935 0.184731125831604 0.2085580825805664" quat="1.0 0.0 0.0 0.0"/>
        <geom class="collision" type="box" pos="0.248425 0.030225 0.005018" size="0.0967213362455368 0.18427643179893494 0.20855674147605896" quat="1.0 0.0 0.0 0.0"/>
        <geom class="collision" type="box" pos="0.031456 -0.122057 -0.000429" size="0.18335072696208954 0.035612624138593674 0.203109011054039" quat="1.0 0.0 0.0 0.0"/>
        <geom class="collision" type="box" pos="0.031456 0.176228 -0.000782" size="0.183350071310997 0.03615754842758179 0.20275470614433289" quat="1.0 0.0 0.0 0.0"/>
        <geom class="collision" type="box" pos="0.031456 0.027054 -0.198987" size="0.18334876000881195 0.11420933157205582 0.004544232971966267" quat="1.0 0.0 0.0 0.0"/>
        <geom class="collision" type="box" pos="-0.110198 0.027360 0.094016" size="0.005456375423818827 0.09906349331140518 0.10445022583007812" quat="1.0 0.0 0.0 0.0"/>
        <geom class="collision" type="box" pos="-0.150505 0.027360 0.094016" size="0.005456375423818827 0.09906349331140518 0.10445022583007812" quat="1.0 0.0 0.0 0.0"/>
        <geom class="collision" type="box" pos="-0.067726 0.027360 0.094016" size="0.006852762307971716 0.09906349331140518 0.10445044934749603" quat="1.0 0.0 0.0 0.0"/>
        <geom class="collision" type="box" pos="-0.025361 0.027360 0.094016" size="0.006852760445326567 0.09906349331140518 0.10445041209459305" quat="1.0 0.0 0.0 0.0"/>
        <geom class="collision" type="box" pos="0.019554 0.027360 0.094016" size="0.0068527585826814175 0.09906349331140518 0.10445038229227066" quat="1.0 0.0 0.0 0.0"/>
        <geom class="collision" type="box" pos="0.063008 0.027360 0.094016" size="0.006852756254374981 0.09906349331140518 0.10445034503936768" quat="1.0 0.0 0.0 0.0"/>
        <geom class="collision" type="box" pos="0.104048 0.027360 0.094016" size="0.006852754391729832 0.09906349331140518 0.10445031523704529" quat="1.0 0.0 0.0 0.0"/>
        <geom class="collision" type="box" pos="0.145979 0.027360 0.094016" size="0.006852752063423395 0.09906349331140518 0.1044502779841423" quat="1.0 0.0 0.0 0.0"/>
        <geom class="collision" type="cylinder" pos="0.222133 -0.125078 -0.212362" size="0.018061628565192223 0.009052393957972527" quat="1.0 0.0 0.0 0.0"/>
        <geom class="collision" type="cylinder" pos="-0.231781 -0.125078 -0.212362" size="0.018061628565192223 0.009052393957972527" quat="1.0 0.0 0.0 0.0"/>
        <geom class="collision" type="cylinder" pos="0.222133 0.172948 -0.212362" size="0.018061628565192223 0.009052393957972527" quat="1.0 0.0 0.0 0.0"/>
        <geom class="collision" type="cylinder" pos="-0.231781 0.172948 -0.212362" size="0.018061628565192223 0.009052393957972527" quat="1.0 0.0 0.0 0.0"/>
        <body name="Body002">
          <geom mesh="Body002_vis" type="mesh" solimp="0.998 0.998 0.001" solref="0.001 1" density="100" friction="0.95 0.3 0.1" class="visual" material="Body002_material"/>
        </body>
        <body name="Body003">
          <geom mesh="Body003_vis" type="mesh" solimp="0.998 0.998 0.001" solref="0.001 1" density="100" friction="0.95 0.3 0.1" class="visual" material="Body003_material"/>
        </body>
        <body name="Button001">
          <joint axis="0.0 1.0 0.0" pos="0.269249 -0.158115 -0.030151" limited="true" name="Button001_joint" range="0.0 0.0055000000000000005" type="slide" damping="1" frictionloss="1" armature=".01" stiffness="0.05"/>
          <geom mesh="Button001_vis" type="mesh" solimp="0.998 0.998 0.001" solref="0.001 1" density="100" friction="0.95 0.3 0.1" class="visual" material="Button001_material"/>
          <geom class="collision" type="box" pos="0.269238 -0.160625 -0.030043" size="0.0220172181725502 0.005288608837872744 0.008669775910675526" quat="1.0 0.0 0.0 0.0"/>
        </body>
        <body name="Button002">
          <joint axis="0.0 1.0 0.0" pos="-0.264100 -0.158115 -0.030151" limited="true" name="Button002_joint" range="0.0 0.0055000000000000005" type="slide" damping="1" frictionloss="1" armature=".01" stiffness="0.05"/>
          <geom mesh="Button002_vis" type="mesh" solimp="0.998 0.998 0.001" solref="0.001 1" density="100" friction="0.95 0.3 0.1" class="visual" material="Button002_material"/>
          <geom class="collision" type="box" pos="-0.262747 -0.160625 -0.030043" size="0.02201722003519535 0.005288609303534031 0.0086697768419981" quat="1.0 0.0 0.0 0.0"/>
        </body>
        <body name="Knob001">
          <joint axis="0.0 1.0 0.0" pos="0.269209 -0.177738 -0.115376" limited="true" name="Knob001_joint" range="0.0 4.625122517784973" type="hinge" damping="0.05" armature="0.001" springref="-0.4"/>
          <geom mesh="Knob001_vis" type="mesh" solimp="0.998 0.998 0.001" solref="0.001 1" density="100" friction="0.95 0.3 0.1" class="visual" material="Knob001_material"/>
          <geom class="collision" type="box" pos="0.270250 -0.178594 -0.113463" size="0.011468051932752132 0.01638001762330532 0.02847914583981037" quat="0.9130614995956421 0.0 0.407821923494339 0.0"/>
          <geom class="collision" type="cylinder" pos="0.269111 -0.164774 -0.115253" size="0.03140706568956375 0.005081482231616974" quat="0.7071067094802856 0.7071068286895752 0.0 0.0"/>
        </body>
        <body name="Knob002">
          <joint axis="0.0 1.0 0.0" pos="-0.265554 -0.177738 -0.114214" limited="true" name="Knob002_joint" range="0.0 4.625122517784973" type="hinge" damping="0.05" armature="0.001"/>
          <geom mesh="Knob002_vis" type="mesh" solimp="0.998 0.998 0.001" solref="0.001 1" density="100" friction="0.95 0.3 0.1" class="visual" material="Knob002_material"/>
          <geom class="collision" type="box" pos="-0.265548 -0.178293 -0.113508" size="0.010949773713946342 0.016079390421509743 0.026809614151716232" quat="0.9189994931221008 0.0 0.3942587375640869 0.0"/>
          <geom class="collision" type="cylinder" pos="-0.266451 -0.164774 -0.114568" size="0.03140706568956375 0.005081482231616974" quat="0.7071067094802856 0.7071068286895752 0.0 0.0"/>
        </body>
        <body name="Lever001">
          <joint axis="0.0 0.0 -1.0" pos="0.085013 -0.196792 0.007460" limited="true" name="Lever001_joint" range="0.0 0.10800000000000001" type="slide" damping="1" frictionloss="1" armature=".01" stiffness="1" springref="-3"/>
          <geom mesh="Lever001_vis" type="mesh" solimp="0.998 0.998 0.001" solref="0.001 1" density="100" friction="0.95 0.3 0.1" class="visual" material="Lever001_material"/>
          <geom class="collision" type="box" pos="0.084537 -0.199738 0.007685" size="0.020134465768933296 0.01428826805204153 0.021342042833566666" quat="1.0 0.0 0.0 0.0" name="sideR_lever_knob"/>
          <geom class="collision" type="cylinder" pos="0.085941 -0.173781 0.006260" size="0.00671454519033432 0.011980821378529072" quat="0.7071067094802856 0.7071068286895752 0.0 0.0"/>
          <geom class="collision" type="box" pos="0.125176 0.027360 0.177569" size="0.012559779919683933 0.09906499087810516 0.00797840766608715" quat="1.0 0.0 0.0 0.0" name="sideR_slotR_floor"/>
          <geom class="collision" type="box" pos="0.041532 0.027360 0.177569" size="0.012675471603870392 0.09906449168920517 0.00797840766608715" quat="1.0 0.0 0.0 0.0" name="sideR_slotL_floor"/>
        </body>
        <body name="Lever002">
          <joint axis="0.0 0.0 -1.0" pos="-0.090559 -0.196792 0.007460" limited="true" name="Lever002_joint" range="0.0 0.10800000000000001" type="slide" damping="1" frictionloss="1" armature=".01" stiffness="1" springref="-3"/>
          <geom mesh="Lever002_vis" type="mesh" solimp="0.998 0.998 0.001" solref="0.001 1" density="100" friction="0.95 0.3 0.1" class="visual" material="Lever002_material"/>
          <geom class="collision" type="cylinder" pos="-0.089182 -0.173781 0.006260" size="0.00671454519033432 0.011980821378529072" quat="0.7071067094802856 0.7071068286895752 0.0 0.0"/>
          <geom class="collision" type="box" pos="-0.090586 -0.199738 0.007685" size="0.020134614780545235 0.01428826805204153 0.021342195570468903" quat="1.0 0.0 0.0 0.0" name="sideL_lever_knob"/>
          <geom class="collision" type="box" pos="-0.046870 0.027360 0.177569" size="0.012716329656541348 0.09906399250030518 0.00797840766608715" quat="1.0 0.0 0.0 0.0" name="sideL_slotR_floor"/>
          <geom class="collision" type="box" pos="-0.130566 0.027360 0.177569" size="0.012583889998495579 0.09906349331140518 0.00797840766608715" quat="1.0 0.0 0.0 0.0" name="sideL_slotL_floor"/>
        </body>
        <geom class="region" name="reg_main" type="box" pos="0.00014200000000000323 0.025437500000000002 0.0" size="0.345004 0.1890635 0.22266"/>
      </body>
    </body>
  </worldbody>
  <actuator>
    <motor name="Button001_joint_actuator" joint="Button001_joint" gear="1.5"/>
    <motor name="Button002_joint_actuator" joint="Button002_joint" gear="1.5"/>
    <motor name="Knob001_joint_actuator" joint="Knob001_joint" gear="10"/>
    <motor name="Knob002_joint_actuator" joint="Knob002_joint" gear="10"/>
    <motor name="Lever001_joint_actuator" joint="Lever001_joint" gear="5"/>
    <motor name="Lever002_joint_actuator" joint="Lever002_joint" gear="5"/>
  </actuator>
</mujoco>
