<mujoco model="model">
  <compiler angle="radian"/>
  <asset>
    <mesh file="visuals/Body001.obj" name="Body001_vis"/>
    <mesh file="visuals/Container001.obj" name="Container001_vis"/>
    <mesh file="visuals/Door001.obj" name="Door001_vis"/>
    <mesh file="visuals/Door001_Clear.obj" name="Door001_Clear_vis"/>
    <mesh file="visuals/Handle001.obj" name="Handle001_vis"/>
    <mesh file="visuals/Knob001.obj" name="Knob001_vis"/>
    <mesh file="visuals/Knob002.obj" name="Knob002_vis"/>
    <mesh file="visuals/Shelf001.obj" name="Shelf001_vis"/>
    <texture file="visuals/T_BC001.png" name="Body001_material" type="2d"/>
    <material name="Body001_material" rgba="1 1 1 1.0" texture="Body001_material" shininess="0.141421377658844" specular="0.3103448502657381"/>
    <texture file="visuals/T_BC001.png" name="Container001_material" type="2d"/>
    <material name="Container001_material" rgba="1 1 1 1.0" texture="Container001_material" shininess="0.141421377658844" specular="0.3103448502657381"/>
    <texture file="visuals/T_BC001.png" name="Door001_material" type="2d"/>
    <material name="Door001_material" rgba="1 1 1 1.0" texture="Door001_material" shininess="0.141421377658844" specular="0.3103448502657381"/>
    <material name="Door001_Clear_material" rgba="0.05554284155368805 0.05554284155368805 0.05554284155368805 0.699999988079071" shininess="0.141421377658844" specular="0.3103448502657381"/>
    <texture file="visuals/T_BC001.png" name="Handle001_material" type="2d"/>
    <material name="Handle001_material" rgba="1 1 1 1.0" texture="Handle001_material" shininess="0.141421377658844" specular="0.3103448502657381"/>
    <texture file="visuals/T_BC001.png" name="Knob001_material" type="2d"/>
    <material name="Knob001_material" rgba="1 1 1 1.0" texture="Knob001_material" shininess="0.141421377658844" specular="0.3103448502657381"/>
    <texture file="visuals/T_BC001.png" name="Knob002_material" type="2d"/>
    <material name="Knob002_material" rgba="1 1 1 1.0" texture="Knob002_material" shininess="0.141421377658844" specular="0.3103448502657381"/>
    <texture file="visuals/T_BC001.png" name="Shelf001_material" type="2d"/>
    <material name="Shelf001_material" rgba="1 1 1 1.0" texture="Shelf001_material" shininess="0.141421377658844" specular="0.3103448502657381"/>
  </asset>
  <default>
    <default class="visual">
      <geom conaffinity="0" contype="0" group="1" type="mesh"/>
    </default>
    <default class="collision">
      <geom group="0" rgba="0.5 0 0 0.5"/>
    </default>
    <default class="spawn">
      <geom group="0" rgba="1 1 1 0.5" contype="0" conaffinity="0"/>
      <site group="0" rgba="1 1 1 0.5"/>
    </default>
    <default class="region">
      <geom group="1" conaffinity="0" contype="0" rgba="0 1 0 0"/>
    </default>
  </default>
  <worldbody>
    <body>
      <body name="object">
        <geom mesh="Body001_vis" type="mesh" solimp="0.998 0.998 0.001" solref="0.001 1" density="100" friction="0.95 0.3 0.1" class="visual" material="Body001_material"/>
        <geom class="collision" type="box" pos="-0.04530007392168045 0.1638386845588684 0.026230208575725555" size="0.2144758105278015 0.02175586111843586 0.13912814855575562" quat="1.0 0.0 0.0 0.0"/>
        <geom class="collision" type="box" pos="-0.04412195086479187 0.007952943444252014 0.1524270921945572" size="0.21565400063991547 0.15740543603897095 0.012931535951793194" quat="1.0 0.0 0.0 0.0"/>
        <geom class="collision" type="box" pos="-0.2438749223947525 0.007952943444252014 0.015376143157482147" size="0.01590157486498356 0.15740546584129333 0.13063248991966248" quat="1.0 0.0 0.0 0.0"/>
        <geom class="collision" type="box" pos="-0.04412195831537247 0.007952943444252014 -0.1451897919178009" size="0.21565409004688263 0.15740549564361572 0.02030634693801403" quat="1.0 0.0 0.0 0.0"/>
        <geom class="collision" type="box" pos="0.21390566229820251 0.005041457712650299 -0.00041227269684895873" size="0.046316567808389664 0.16031701862812042 0.1657705307006836" quat="1.0 0.0 0.0 0.0"/>
        <body name="Container001">
          <joint axis="0.0 -1.0 0.0" pos="-0.04062514007091522 -6.710365414619446e-05 0.041690513491630554" limited="true" name="Container001_joint" range="0.0 0.2" type="slide" damping="1" frictionloss="1" armature=".01" stiffness="0.05"/>
          <geom mesh="Container001_vis" type="mesh" solimp="0.998 0.998 0.001" solref="0.001 1" density="100" friction="0.95 0.3 0.1" class="visual" material="Container001_material"/>
          <geom class="collision" type="box" pos="-0.03779211640357971 -0.00010101683437824249 0.03432420641183853" size="0.16691850125789642 0.09587956219911575 0.0031835513655096292" quat="1.0 0.0 0.0 0.0"/>
          <geom class="collision" type="box" pos="-0.21366329491138458 -0.0035429999697953463 0.042756639420986176" size="0.011240711435675621 0.0912846028804779 0.001472647418268025" quat="0.8347760438919067 4.4288722023111404e-08 0.5505896806716919 -1.4126920744317317e-09"/>
          <geom class="collision" type="box" pos="-0.04321388900279999 -0.10795778781175613 0.043273162096738815" size="0.011240712366998196 0.15772032737731934 0.0014726504450663924" quat="0.5600176453590393 -0.4317174553871155 0.43171679973602295 0.5600186586380005"/>
          <geom class="collision" type="box" pos="0.13318151235580444 -0.0035429999697953463 0.042756639420986176" size="0.011240711435675621 0.0912846028804779 0.001472647418268025" quat="3.0570912912253334e-08 0.8347760438919067 7.635104992687047e-09 0.5505896806716919"/>
          <geom class="collision" type="box" pos="-0.04321388900279999 0.1022331565618515 0.043273162096738815" size="0.011240712366998196 0.15772032737731934 0.0014726484660059214" quat="0.43171727657318115 -0.560018002986908 -0.5600183010101318 -0.43171700835227966"/>
          <geom class="collision" type="box" pos="-0.2096756547689438 -0.09697114676237106 0.042756639420986176" size="0.011240711435675621 0.0075540486723184586 0.001472647418268025" quat="0.8021135926246643 -0.15250761806964874 0.529046893119812 0.23122413456439972"/>
          <geom class="collision" type="box" pos="-0.20116393268108368 -0.10478074103593826 0.042756639420986176" size="0.011240711435675621 0.0075540486723184586 0.001472647418268025" quat="0.7184903621673584 -0.28031352162361145 0.4738919734954834 0.42499685287475586"/>
          <geom class="collision" type="box" pos="-0.22104623913764954 -0.0032360691111534834 0.05141866207122803" size="0.004592139273881912 0.09610312432050705 0.0011542232241481543" quat="1.0 0.0 0.0 0.0"/>
          <geom class="collision" type="box" pos="-0.04049016907811165 -0.11186683923006058 0.05141866207122803" size="0.1691744029521942 0.0029154843650758266 0.0011542359134182334" quat="1.0 0.0 0.0 0.0"/>
          <geom class="collision" type="box" pos="-0.21816673874855042 -0.10125909000635147 0.05141866207122803" size="0.004592172801494598 0.005354729481041431 0.0011542162392288446" quat="0.9630976915359497 -7.4883722334107e-08 -9.148812374348836e-09 0.26915204524993896"/>
          <geom class="collision" type="box" pos="-0.21164868772029877 -0.10740331560373306 0.05141866207122803" size="0.004592172801494598 0.006295220460742712 0.0011542162392288446" quat="0.8660538792610168 -1.892820655768901e-08 -1.0926773263975065e-08 0.49995070695877075"/>
          <geom class="collision" type="box" pos="-0.21164868772029877 0.10046786814928055 0.05141866207122803" size="0.00459217419847846 0.0062952227890491486 0.0011542162392288446" quat="1.4975428541674773e-07 -0.4999507665634155 -0.8660538196563721 -1.3003663923427666e-07"/>
          <geom class="collision" type="box" pos="-0.21816673874855042 0.09432365000247955 0.05141866207122803" size="0.00459217419847846 0.005354730878025293 0.0011542162392288446" quat="1.9583114863053197e-07 0.26915183663368225 0.9630977511405945 -2.2673637189996043e-08"/>
          <geom class="collision" type="box" pos="-0.20116393268108368 0.09784527868032455 0.042756639420986176" size="0.011240711435675621 0.0075540486723184586 0.0014726478839293122" quat="0.47389188408851624 -0.4249967634677887 -0.718490481376648 -0.28031349182128906"/>
          <geom class="collision" type="box" pos="-0.2096756547689438 0.09003568440675735 0.042756639420986176" size="0.011240708641707897 0.0075540486723184586 0.001472647418268025" quat="0.5290468335151672 -0.23122408986091614 -0.8021136522293091 -0.15250760316848755"/>
          <geom class="collision" type="box" pos="-0.04049016907811165 0.10590941458940506 0.05141866207122803" size="0.169174462556839 0.0029154852963984013 0.0011542363790795207" quat="1.0 0.0 0.0 0.0"/>
          <geom class="collision" type="box" pos="0.1288190335035324 0.09003568440675735 0.042756639420986176" size="0.011240708641707897 0.0075540486723184586 0.0014726475346833467" quat="0.23122401535511017 0.5290467739105225 0.15250754356384277 -0.8021137118339539"/>
          <geom class="collision" type="box" pos="0.12020901590585709 0.09784527868032455 0.042756639420986176" size="0.011240708641707897 0.0075540486723184586 0.001472647418268025" quat="0.42499685287475586 0.4738917648792267 0.28031349182128906 -0.7184905409812927"/>
          <geom class="collision" type="box" pos="0.13721181452274323 0.09432365000247955 0.05141866207122803" size="0.004592173732817173 0.005354730412364006 0.0011542162392288446" quat="0.2691517472267151 6.893857040779494e-09 1.7478617664323792e-08 -0.9630978107452393"/>
          <geom class="collision" type="box" pos="0.13069376349449158 0.10046783834695816 0.05141866207122803" size="0.00459217419847846 0.0062952227890491486 0.0011542162392288446" quat="0.49995073676109314 1.88726119176863e-08 -3.2692621942942424e-08 -0.8660538196563721"/>
          <geom class="collision" type="box" pos="0.13112689554691315 -0.10740331560373306 0.05141866207122803" size="0.004592172801494598 0.006295220460742712 0.0011542162392288446" quat="6.538524388588485e-08 -0.8660538792610168 0.49995070695877075 -3.7745234493513635e-08"/>
          <geom class="collision" type="box" pos="0.1376449465751648 -0.10125909000635147 0.05141866207122803" size="0.004592175129801035 0.005354731809347868 0.0011542162392288446" quat="7.576508664897119e-08 -0.9630977511405945 0.26915186643600464 -9.395116684629556e-09"/>
          <geom class="collision" type="box" pos="0.12020901590585709 -0.10478074103593826 0.042756639420986176" size="0.011240708641707897 0.0075540486723184586 0.001472647418268025" quat="0.28031328320503235 0.7184906601905823 -0.424996554851532 0.47389188408851624"/>
          <geom class="collision" type="box" pos="0.1287207305431366 -0.09697114676237106 0.042756639420986176" size="0.011240711435675621 0.0075540486723184586 0.001472647301852703" quat="0.15250751376152039 0.8021135926246643 -0.23122410476207733 0.5290469527244568"/>
          <geom class="collision" type="box" pos="0.14031445980072021 -0.0032360691111534834 0.05141866207122803" size="0.004592145327478647 0.09610322117805481 0.001154224737547338" quat="1.0 0.0 0.0 0.0"/>
        </body>
        <body name="Door001">
          <joint axis="1.0 0.0 0.0" pos="-0.039516985416412354 -0.1588633954524994 -0.12027641385793686" limited="true" name="Door001_joint" range="0.0 1.5707963267948966" type="hinge" damping="1" frictionloss="1" armature=".01" stiffness="0.05"/>
          <geom mesh="Door001_vis" type="mesh" solimp="0.998 0.998 0.001" solref="0.001 1" density="100" friction="0.95 0.3 0.1" class="visual" material="Door001_material"/>
          <geom class="collision" type="box" pos="-0.03151053190231323 -0.1457587629556656 0.007530984003096819" size="0.19299377501010895 0.013378138653934002 0.1289387196302414" quat="1.0 0.0 0.0 0.0"/>
          <body name="Door001_Clear">
            <geom mesh="Door001_Clear_vis" type="mesh" solimp="0.998 0.998 0.001" solref="0.001 1" density="100" friction="0.95 0.3 0.1" class="visual" material="Door001_Clear_material"/>
            <geom class="collision" type="box" pos="-0.03966672718524933 -0.144913911819458 0.01346565131098032" size="0.15619301795959473 0.011817453429102898 0.09648057818412781" quat="1.0 0.0 0.0 0.0"/>
          </body>
          <body name="Handle001">
            <geom mesh="Handle001_vis" type="mesh" solimp="0.998 0.998 0.001" solref="0.001 1" density="100" friction="0.95 0.3 0.1" class="visual" material="Handle001_material"/>
            <geom class="collision" type="box" pos="0.0016987095586955547 -0.1815478503704071 0.1285337209701538" size="0.06876441836357117 0.004100136458873749 0.017019057646393776" quat="1.0 0.0 0.0 0.0"/>
            <geom class="collision" type="box" pos="-0.2257564663887024 -0.1599465012550354 0.1285337209701538" size="0.01420120894908905 0.004956742748618126 0.017019053921103477" quat="1.0 0.0 0.0 0.0"/>
            <geom class="collision" type="box" pos="-0.11578506231307983 -0.1767181009054184 0.1285337209701538" size="0.051081862300634384 0.004100130405277014 0.017019039019942284" quat="0.9991695284843445 0.0 -0.0 -0.04074633866548538"/>
            <geom class="collision" type="box" pos="0.1450728327035904 -0.16567525267601013 0.1285337209701538" size="0.01700463891029358 0.010685496963560581 0.01701904833316803" quat="1.0 0.0 0.0 0.0"/>
            <geom class="collision" type="box" pos="0.10266616940498352 -0.17805001139640808 0.1285337209701538" size="0.04628278687596321 0.0041001299396157265 0.017019039019942284" quat="0.9993327856063843 0.0 0.0 0.036523155868053436"/>
            <geom class="collision" type="box" pos="-0.19398818910121918 -0.16839846968650818 0.1285337209701538" size="0.03551480919122696 0.0041001299396157265 0.017019039019942284" quat="0.9977550506591797 0.0 -0.0 -0.06696879118680954"/>
          </body>
        </body>
        <body name="Knob001">
          <joint axis="0.0 1.0 0.0" pos="0.20447637140750885 -0.16409412026405334 -0.03667229786515236" limited="true" name="Knob001_joint" range="0.0 4.799655442984406" type="hinge" damping="1" frictionloss="1" armature=".01" stiffness="0.05"/>
          <geom mesh="Knob001_vis" type="mesh" solimp="0.998 0.998 0.001" solref="0.001 1" density="100" friction="0.95 0.3 0.1" class="visual" material="Knob001_material"/>
          <geom class="collision" type="cylinder" pos="0.20447635650634766 -0.1640055924654007 -0.03667235001921654" size="0.016977673396468163 0.006781207397580147" quat="0.7071068286895752 0.7071067690849304 0.0 0.0"/>
        </body>
        <body name="Knob002">
          <joint axis="0.0 1.0 0.0" pos="0.2051738202571869 -0.16409412026405334 0.053199902176856995" limited="true" name="Knob002_joint" range="0.0 4.590215932745086" type="hinge" damping="1" frictionloss="1" armature=".01" stiffness="0.05"/>
          <geom mesh="Knob002_vis" type="mesh" solimp="0.998 0.998 0.001" solref="0.001 1" density="100" friction="0.95 0.3 0.1" class="visual" material="Knob002_material"/>
          <geom class="collision" type="cylinder" pos="0.20517383515834808 -0.1640055924654007 0.05319984257221222" size="0.016977673396468163 0.006781207397580147" quat="0.7071068286895752 0.7071067690849304 0.0 0.0"/>
        </body>
        <body name="Shelf001">
          <joint axis="0.0 -1.0 0.0" pos="-0.038373611867427826 -0.002495288848876953 -0.05052074044942856" limited="true" name="Shelf001_joint" range="0.0 0.2" type="slide" damping="1" frictionloss="1" armature=".01" stiffness="0.05"/>
          <geom mesh="Shelf001_vis" type="mesh" solimp="0.998 0.998 0.001" solref="0.001 1" density="100" friction="0.95 0.3 0.1" class="visual" material="Shelf001_material"/>
          <geom class="collision" type="box" pos="-0.21577507257461548 -0.002358078956604004 -0.04484874755144119" size="0.008577265776693821 0.10600447654724121 0.001667578355409205" quat="1.0 0.0 0.0 0.0"/>
          <geom class="collision" type="box" pos="-0.20187555253505707 -0.0023645609617233276 -0.04963897913694382" size="0.008577265776693821 0.10601095855236053 0.0016675611259415746" quat="0.9440328478813171 -2.0632491271044273e-08 0.3298514783382416 7.209132402152818e-09"/>
          <geom class="collision" type="box" pos="0.12622657418251038 -0.0023645611945539713 -0.04963897913694382" size="0.008577265776693821 0.10601095855236053 0.0016675611259415746" quat="7.127249546101666e-08 -0.9440328478813171 -2.4903092921135794e-08 -0.3298514783382416"/>
          <geom class="collision" type="box" pos="0.13933555781841278 -0.002358078956604004 -0.04484874755144119" size="0.008577265776693821 0.10600447654724121 0.0016675770748406649" quat="1.0 0.0 0.0 0.0"/>
          <geom class="collision" type="box" pos="-0.03779211640357971 -0.0025466543156653643 -0.05503298342227936" size="0.16691850125789642 0.10659930855035782 0.0031835513655096292" quat="1.0 0.0 0.0 0.0"/>
        </body>
        <geom class="region" name="reg_main_body" type="box" pos="5.63431967748329e-10 0.012790124863386154 -1.7383330330744684e-08" size="0.2589995265007019 0.1720275580883026 0.1650950014591217"/>
        <geom class="region" name="reg_int" type="box" pos="-0.03843996673822403 0.007352910935878754 0.008352521806955338" size="0.18722017854452133 0.13187745958566666 0.12710700556635857"/>
      </body>
    </body>
  </worldbody>
  <actuator>
    <motor name="Container001_joint_actuator" joint="Container001_joint" gear="10"/>
    <motor name="Door001_joint_actuator" joint="Door001_joint" gear="50"/>
    <motor name="Knob001_joint_actuator" joint="Knob001_joint" gear="50"/>
    <motor name="Knob002_joint_actuator" joint="Knob002_joint" gear="50"/>
    <motor name="Shelf001_joint_actuator" joint="Shelf001_joint" gear="50"/>
  </actuator>
</mujoco>
