<mujoco model="model">
  <compiler angle="radian"/>
  <asset>
    <mesh file="visuals/door.obj" name="door_vis"/>
    <mesh file="visuals/door_Clear.obj" name="door_Clear_vis"/>
    <mesh file="visuals/Body001.obj" name="Body001_vis"/>
    <mesh file="visuals/Disc001.obj" name="Disc001_vis"/>
    <texture file="visuals/T_BC001.png" name="Body001_material" type="2d"/>
    <material name="Body001_material" rgba="1 1 1 1.0" texture="Body001_material" shininess="0.4472135901451111" specular="0.3103448502657381"/>
    <texture file="visuals/T_BC001.png" name="door_material" type="2d"/>
    <material name="door_material" rgba="1 1 1 1.0" texture="door_material" shininess="0.4472135901451111" specular="0.3103448502657381"/>
    <material name="door_Clear_material" rgba="0.05796752870082855 0.05796752870082855 0.05796752870082855 0.800000011920929" shininess="0.4472135901451111" specular="0.3103448502657381"/>
    <texture file="visuals/T_BC001.png" name="Disc001_material" type="2d"/>
    <material name="Disc001_material" rgba="1 1 1 1.0" texture="Disc001_material" shininess="0.4472135901451111" specular="0.3103448502657381"/>
  </asset>
  <default>
    <default class="visual">
      <geom conaffinity="0" contype="0" group="1" type="mesh"/>
    </default>
    <default class="collision">
      <geom group="0" rgba="0.5 0 0 0.5"/>
    </default>
    <default class="spawn">
      <geom group="0" rgba="1 1 1 0.5" contype="0" conaffinity="0"/>
      <site group="0" rgba="1 1 1 0.5"/>
    </default>
    <default class="region">
      <geom group="1" conaffinity="0" contype="0" rgba="0 1 0 0"/>
    </default>
  </default>
  <worldbody>
    <body>
      <body name="object">
        <geom class="collision" type="box" pos="-0.073583 -0.035271 -0.119682" size="0.14736369252204895 0.14736369252204895 0.0014016532804816961" quat="1.0 0.0 0.0 0.0" name="tray" rgba="0 1 0 0.5"/>
        <geom class="collision" type="box" pos="0.270305 -0.245412 -0.107962" size="0.012578919529914856 0.0012121606850996614 0.009054339490830898" quat="1.0 0.0 0.0 0.0" name="stop_button" rgba="0.0 0.5 0 0.5"/>
        <geom class="collision" type="box" pos="0.208929 -0.245412 -0.107962" size="0.012578919529914856 0.0012121606850996614 0.009054339490830898" quat="1.0 0.0 0.0 0.0" name="start_button" rgba="0.0 0.5 0 0.5"/>
        <geom mesh="Body001_vis" type="mesh" solimp="0.998 0.998 0.001" solref="0.001 1" density="100" friction="0.95 0.3 0.1" class="visual" material="Body001_material"/>
        <geom class="collision" type="box" pos="-0.000000 0.030992 0.151148" size="0.306557834148407 0.24860113859176636 0.023851774632930756" quat="1.0 0.0 0.0 0.0"/>
        <geom class="collision" type="box" pos="0.239909 -0.230358 0.000000" size="0.06664859503507614 0.013609462417662144 0.17499971389770508" quat="1.0 0.0 0.0 0.0"/>
        <geom class="collision" type="box" pos="-0.000000 0.030992 -0.153827" size="0.30655789375305176 0.2486012727022171 0.02117295376956463" quat="1.0 0.0 0.0 0.0"/>
        <geom class="collision" type="box" pos="0.210115 0.031896 -0.002492" size="0.09644266963005066 0.24769803881645203 0.130575031042099" quat="1.0 0.0 0.0 0.0"/>
        <geom class="collision" type="box" pos="-0.280391 0.030992 -0.002492" size="0.02616698667407036 0.24860140681266785 0.13057507574558258" quat="1.0 0.0 0.0 0.0"/>
        <geom class="collision" type="box" pos="-0.069833 0.213152 -0.002492" size="0.18409323692321777 0.06644230335950851 0.13057512044906616" quat="1.0 0.0 0.0 0.0"/>
        <body name="door">
          <joint axis="0.0 0.0 1.0" pos="-0.293211 -0.232038 0.000000" limited="true" name="microjoint" range="-1.5707963267948966 0.0" type="hinge" damping="1" frictionloss="1" armature=".01" stiffness="0.05"/>
          <geom mesh="door_vis" type="mesh" solimp="0.998 0.998 0.001" solref="0.001 1" density="100" friction="0.95 0.3 0.1" class="visual" material="door_material"/>
          <geom class="collision" type="box" pos="-0.261434 -0.231925 -0.000027" size="0.035470761358737946 0.011848047375679016 0.17527179419994354" quat="1.0 0.0 0.0 0.0"/>
          <geom class="collision" type="box" pos="0.130202 -0.231925 -0.000027" size="0.040074169635772705 0.011848047375679016 0.17527179419994354" quat="1.0 0.0 0.0 0.0"/>
          <geom class="collision" type="box" pos="-0.067610 -0.231925 0.137862" size="0.1575537770986557 0.011848047375679016 0.03738280385732651" quat="1.0 0.0 0.0 0.0"/>
          <geom class="collision" type="box" pos="-0.067610 -0.231925 -0.138336" size="0.1575537770986557 0.011848047375679016 0.03666391223669052" quat="1.0 0.0 0.0 0.0"/>
          <geom class="collision" type="box" pos="0.142310 -0.268610 0.000545" size="0.023645726963877678 0.010694717057049274 0.11195584386587143" quat="1.0 0.0 0.0 0.0" name="door_handle"/>
          <geom class="collision" type="box" pos="0.142310 -0.253732 0.142854" size="0.023645726963877678 0.004713548347353935 0.028124690055847168" quat="0.9909031391143799 -0.1345769613981247 2.988212131288229e-17 1.1366435670369931e-23"/>
          <geom class="collision" type="box" pos="0.142310 -0.253732 -0.142274" size="0.023645726963877678 0.004713548347353935 0.028124690055847168" quat="0.9909031391143799 0.1345769613981247 -2.988212131288229e-17 1.0136951773372292e-23"/>
          <body name="door_Clear">
            <geom mesh="door_Clear_vis" type="mesh" solimp="0.998 0.998 0.001" solref="0.001 1" density="100" friction="0.95 0.3 0.1" class="visual" material="door_Clear_material"/>
            <geom class="collision" type="box" pos="-0.067496 -0.236918 -0.001915" size="0.1662762612104416 0.0011737904278561473 0.11264043301343918" quat="1.0 0.0 0.0 0.0"/>
          </body>
        </body>
        <body name="Disc001">
          <joint axis="0.0 0.0 1.0" pos="-0.070377 -0.036144 -0.125623" limited="false" name="Disc001_joint" range="0 360" type="hinge" damping="1" frictionloss="1" armature=".01" stiffness="0.05"/>
          <geom mesh="Disc001_vis" type="mesh" solimp="0.998 0.998 0.001" solref="0.001 1" density="100" friction="0.95 0.3 0.1" class="visual" material="Disc001_material"/>
          <geom class="collision" type="cylinder" pos="-0.073583 -0.035271 -0.127001" size="0.14736369252204895 0.003240163205191493" quat="1.0 0.0 0.0 0.0"/>
        </body>
        <geom class="region" name="reg_main" type="box" pos="0.0 0.017560000000000006 0.0" size="0.306558 0.262034 0.175"/>
        <geom class="region" name="reg_int" type="box" pos="-0.069156 -0.0382185 -0.002124000000000001" size="0.179486 0.1736455 0.123843"/>
      </body>
    </body>
  </worldbody>
  <actuator>
    <motor name="microjoint_actuator" joint="microjoint" gear="10"/>
    <motor name="Disc001_joint_actuator" joint="Disc001_joint" gear="10"/>
  </actuator>
</mujoco>
