<mujoco model="model">
  <compiler angle="radian"/>
  <asset>
    <mesh file="visuals/Body001.obj" name="Body001_vis"/>
    <mesh file="visuals/Button001.obj" name="Button001_vis"/>
    <mesh file="visuals/Button002.obj" name="Button002_vis"/>
    <mesh file="visuals/Handle001.obj" name="Handle001_vis"/>
    <mesh file="visuals/Handle001_Clear.obj" name="Handle001_Clear_vis"/>
    <mesh file="visuals/Lid001.obj" name="Lid001_vis"/>
    <texture file="visuals/T_BC001.png" name="Body001_material" type="2d"/>
    <material name="Body001_material" rgba="1 1 1 1.0" texture="Body001_material" shininess="1" specular="1"/>
    <texture file="visuals/T_BC001.png" name="Handle001_material" type="2d"/>
    <material name="Handle001_material" rgba="1 1 1 1.0" texture="Handle001_material" shininess="1" specular="1"/>
    <texture file="visuals/T_BC001.png" name="Button001_material" type="2d"/>
    <material name="Button001_material" rgba="1 1 1 1.0" texture="Button001_material" shininess="1" specular="1"/>
    <texture file="visuals/T_BC001.png" name="Button002_material" type="2d"/>
    <material name="Button002_material" rgba="1 1 1 1.0" texture="Button002_material" shininess="1" specular="1"/>
    <material name="Handle001_Clear_material" rgba="1.0 1.0 1.0 0.25477707386016846" shininess="1" specular="1"/>
    <texture file="visuals/T_BC001.png" name="Lid001_material" type="2d"/>
    <material name="Lid001_material" rgba="1 1 1 1.0" texture="Lid001_material" shininess="1" specular="1"/>
  </asset>
  <default>
    <default class="visual">
      <geom conaffinity="0" contype="0" group="1" type="mesh"/>
    </default>
    <default class="collision">
      <geom group="0" rgba="0.5 0 0 0.5"/>
    </default>
    <default class="spawn">
      <geom group="0" rgba="1 1 1 0.5" contype="0" conaffinity="0"/>
      <site group="0" rgba="1 1 1 0.5"/>
    </default>
    <default class="region">
      <geom group="1" conaffinity="0" contype="0" rgba="0 1 0 0"/>
    </default>
  </default>
  <worldbody>
    <body>
      <body name="object">
        <geom mesh="Body001_vis" type="mesh" solimp="0.998 0.998 0.001" solref="0.001 1" density="100" friction="0.95 0.3 0.1" class="visual" material="Body001_material"/>
        <geom class="collision" type="box" pos="-0.10482710599899292 1.39918824970664e-07 -0.1112561896443367" size="0.002567468211054802 0.013775870203971863 0.008990506641566753" quat="1.0 0.0 0.0 0.0"/>
        <geom class="collision" type="box" pos="-0.10088077187538147 -0.02437649853527546 -0.1112561896443367" size="0.0025674684438854456 0.013775867410004139 0.008990505710244179" quat="0.987147867679596 0.0 0.0 0.15980951488018036"/>
        <geom class="collision" type="box" pos="-0.08962121605873108 -0.04602615907788277 -0.1112561896443367" size="0.0025674684438854456 0.013775872066617012 0.008990506641566753" quat="0.949522852897644 0.0 0.0 0.313697874546051"/>
        <geom class="collision" type="box" pos="-0.0727163553237915 -0.06269518285989761 -0.1112561896443367" size="0.002567468211054802 0.013775872066617012 0.008990506641566753" quat="0.8900519013404846 0.0 0.0 0.4558591842651367"/>
        <geom class="collision" type="box" pos="-0.051575157791376114 -0.07343557476997375 -0.1112561896443367" size="0.0025674677453935146 0.013775869272649288 0.008990506641566753" quat="0.8095524311065674 0.0 0.0 0.5870475769042969"/>
        <geom class="collision" type="box" pos="-0.027179047465324402 -0.07725966721773148 -0.1112561896443367" size="0.002567468211054802 0.013775870203971863 0.008990505710244179" quat="0.705332338809967 0.0 0.0 0.7088767886161804"/>
        <geom class="collision" type="box" pos="-0.003102310001850128 -0.07328519970178604 -0.1112561896443367" size="0.002567468211054802 0.013775867410004139 0.008990505710244179" quat="0.584533154964447 0.0 0.0 0.8113698363304138"/>
        <geom class="collision" type="box" pos="0.017994649708271027 -0.06239718571305275 -0.1112561896443367" size="0.002567468211054802 0.013775869272649288 0.008990505710244179" quat="0.45293283462524414 0.0 0.0 0.8915446400642395"/>
        <geom class="collision" type="box" pos="0.038177184760570526 -0.04058334603905678 -0.1112561896443367" size="0.0025674679782241583 0.013775872066617012 0.008990505710244179" quat="0.2730109691619873 0.0 0.0 0.96201092004776"/>
        <geom class="collision" type="box" pos="0.047623664140701294 -0.01776759885251522 -0.1112561896443367" size="0.0025674677453935146 0.013775869272649288 0.008990506641566753" quat="0.1157638356089592 0.0 0.0 0.9932767748832703"/>
        <geom class="collision" type="box" pos="0.04941468685865402 0.006569178309291601 -0.1112561896443367" size="0.0025674677453935146 0.013775873929262161 0.008990505710244179" quat="0.04255066439509392 0.0 0.0 -0.9990943074226379"/>
        <geom class="collision" type="box" pos="0.043785735964775085 0.029633110389113426 -0.1112561896443367" size="0.002567468211054802 0.013775870203971863 0.008990506641566753" quat="0.19554761052131653 0.0 0.0 -0.9806942343711853"/>
        <geom class="collision" type="box" pos="0.029977641999721527 0.051555171608924866 -0.1112561896443367" size="0.002567468211054802 0.013775870203971863 0.008990506641566753" quat="0.3572101593017578 0.0 0.0 -0.9340240359306335"/>
        <geom class="collision" type="box" pos="0.010772213339805603 0.06707760691642761 -0.1112561896443367" size="0.002567468211054802 0.013775870203971863 0.008990505710244179" quat="0.5018852353096008 0.0 0.0 -0.8649342060089111"/>
        <geom class="collision" type="box" pos="-0.012060465291142464 0.07568896561861038 -0.1112561896443367" size="0.0025674684438854456 0.013775872066617012 0.008990506641566753" quat="0.6321806907653809 0.0 0.0 -0.7748209834098816"/>
        <geom class="collision" type="box" pos="-0.03577422723174095 0.07682368904352188 -0.1112561896443367" size="0.0025674679782241583 0.013775869272649288 0.008990506641566753" quat="0.7437192797660828 0.0 0.0 -0.6684920787811279"/>
        <geom class="collision" type="box" pos="-0.056071385741233826 0.07181023806333542 -0.1112561896443367" size="0.0025674679782241583 0.013775870203971863 0.008990506641566753" quat="0.8273288011550903 0.0 0.0 -0.5617179274559021"/>
        <geom class="collision" type="box" pos="-0.07727228105068207 0.0591486431658268 -0.1112561896443367" size="0.0025674679782241583 0.013775869272649288 0.008990506641566753" quat="0.9064636826515198 0.0 0.0 -0.42228376865386963"/>
        <geom class="collision" type="box" pos="-0.09324042499065399 0.040695857256650925 -0.1112561896443367" size="0.0025674684438854456 0.013775870203971863 0.008990506641566753" quat="0.96177738904953 0.0 0.0 -0.2738324999809265"/>
        <geom class="collision" type="box" pos="-0.10249647498130798 0.01883365772664547 -0.1112561896443367" size="0.0025674677453935146 0.013775870203971863 0.008990505710244179" quat="0.9924299120903015 0.0 0.0 -0.12281252443790436"/>
        <body name="Handle001">
          <joint axis="0.0 0.0 1.0" pos="3.725290298461914e-09 0.0 0.007803112268447876" limited="true" name="Handle001_joint" range="0.0 0.08" type="slide" damping="1" frictionloss="1" armature=".01" stiffness="0.05"/>
          <geom mesh="Handle001_vis" type="mesh" solimp="0.998 0.998 0.001" solref="0.001 1" density="100" friction="0.95 0.3 0.1" class="visual" material="Handle001_material"/>
          <geom class="collision" type="box" pos="-0.10482710599899292 1.39918824970664e-07 -0.06813916563987732" size="0.002567468211054802 0.013775870203971863 0.030322927981615067" quat="1.0 0.0 0.0 0.0"/>
          <geom class="collision" type="box" pos="-0.10088077187538147 -0.02437649853527546 -0.06813916563987732" size="0.0025674684438854456 0.013775870203971863 0.030322927981615067" quat="0.987147867679596 0.0 0.0 0.15980949997901917"/>
          <geom class="collision" type="box" pos="-0.08962120115756989 -0.04602615535259247 -0.06813916563987732" size="0.002567467512562871 0.013775869272649288 0.030322927981615067" quat="0.949522852897644 0.0 0.0 0.313697874546051"/>
          <geom class="collision" type="box" pos="-0.0727163553237915 -0.06269518285989761 -0.06813916563987732" size="0.0025674679782241583 0.013775869272649288 0.030322927981615067" quat="0.8900519013404846 0.0 0.0 0.4558592140674591"/>
          <geom class="collision" type="box" pos="-0.051575157791376114 -0.07343557476997375 -0.06813916563987732" size="0.0025674677453935146 0.013775869272649288 0.030322927981615067" quat="0.8095524311065674 0.0 0.0 0.5870475769042969"/>
          <geom class="collision" type="box" pos="-0.027179047465324402 -0.07725966721773148 -0.06813916563987732" size="0.002567468211054802 0.013775870203971863 0.030322927981615067" quat="0.705332338809967 0.0 0.0 0.7088767886161804"/>
          <geom class="collision" type="box" pos="-0.003102310001850128 -0.07328519970178604 -0.06813916563987732" size="0.002567468211054802 0.013775870203971863 0.030322927981615067" quat="0.584533154964447 0.0 0.0 0.8113698363304138"/>
          <geom class="collision" type="box" pos="0.017994653433561325 -0.06239718571305275 -0.06813916563987732" size="0.002567468211054802 0.013775870203971863 0.030322927981615067" quat="0.45293283462524414 0.0 0.0 0.8915446400642395"/>
          <geom class="collision" type="box" pos="0.03817719221115112 -0.040583349764347076 -0.06813916563987732" size="0.002567468211054802 0.013775870203971863 0.030322927981615067" quat="0.2730109691619873 0.0 0.0 0.96201092004776"/>
          <geom class="collision" type="box" pos="0.04762367904186249 -0.01776760071516037 -0.06813916563987732" size="0.002567468211054802 0.013775869272649288 0.030322927981615067" quat="0.1157638356089592 0.0 0.0 0.9932767748832703"/>
          <geom class="collision" type="box" pos="0.04941469430923462 0.0065691787749528885 -0.06813916563987732" size="0.002567468211054802 0.013775873929262161 0.030322927981615067" quat="0.04255066439509392 0.0 0.0 -0.9990943074226379"/>
          <geom class="collision" type="box" pos="0.043785735964775085 0.029633110389113426 -0.06813916563987732" size="0.002567468211054802 0.013775870203971863 0.030322927981615067" quat="0.19554761052131653 0.0 0.0 -0.9806942343711853"/>
          <geom class="collision" type="box" pos="0.029977641999721527 0.051555171608924866 -0.06813916563987732" size="0.002567468211054802 0.013775870203971863 0.030322927981615067" quat="0.3572101593017578 0.0 0.0 -0.9340240359306335"/>
          <geom class="collision" type="box" pos="0.010772213339805603 0.06707760691642761 -0.06813916563987732" size="0.002567468211054802 0.013775870203971863 0.030322927981615067" quat="0.5018852353096008 0.0 0.0 -0.8649342060089111"/>
          <geom class="collision" type="box" pos="-0.012060465291142464 0.07568895816802979 -0.06813916563987732" size="0.002567468211054802 0.013775870203971863 0.030322927981615067" quat="0.6321806907653809 0.0 0.0 -0.7748209834098816"/>
          <geom class="collision" type="box" pos="-0.03577422723174095 0.07682369649410248 -0.06813916563987732" size="0.002567468211054802 0.013775870203971863 0.030322927981615067" quat="0.7437191605567932 0.0 0.0 -0.6684921979904175"/>
          <geom class="collision" type="box" pos="-0.056071385741233826 0.07181024551391602 -0.06813916563987732" size="0.0025674684438854456 0.013775870203971863 0.030322927981615067" quat="0.8273288607597351 0.0 0.0 -0.5617178678512573"/>
          <geom class="collision" type="box" pos="-0.07727229595184326 0.059148650616407394 -0.06813916563987732" size="0.002567468211054802 0.013775869272649288 0.030322927981615067" quat="0.9064636826515198 0.0 0.0 -0.42228376865386963"/>
          <geom class="collision" type="box" pos="-0.09324042499065399 0.040695857256650925 -0.06813916563987732" size="0.0025674684438854456 0.013775870203971863 0.030322927981615067" quat="0.96177738904953 0.0 0.0 -0.2738324999809265"/>
          <geom class="collision" type="box" pos="-0.10249647498130798 0.01883365772664547 -0.06813916563987732" size="0.0025674677453935146 0.013775870203971863 0.030322927981615067" quat="0.9924299120903015 0.0 0.0 -0.12281252443790436"/>
          <geom class="collision" type="box" pos="0.04201378673315048 1.4690985494780762e-07 0.0354456752538681" size="0.011047347448766232 0.01609395258128643 0.06281957030296326" quat="0.9965038299560547 -6.321228214346532e-17 -0.08354711532592773 2.859695147350294e-09"/>
          <geom class="collision" type="box" pos="0.05809831619262695 1.436938390497744e-07 -0.058511536568403244" size="0.007249075919389725 0.020444408059120178 0.03145648539066315" quat="0.9909151196479797 -0.008864816278219223 0.13260747492313385 0.020589232444763184"/>
          <geom class="collision" type="box" pos="0.07869435101747513 1.4495607558728807e-07 -0.021634802222251892" size="0.01047359500080347 0.015055187046527863 0.020427102223038673" quat="0.9771967530250549 2.8405006364200626e-16 0.2123357057571411 -7.267939139410373e-09"/>
          <geom class="collision" type="box" pos="0.09200004488229752 1.4626083100210963e-07 0.016484230756759644" size="0.010473599657416344 0.015055186115205288 0.023168545216321945" quat="0.9974961280822754 -5.750757612420069e-16 0.07072144001722336 -2.4206912030422245e-09"/>
          <geom class="collision" type="box" pos="0.08654046058654785 1.4747382692803512e-07 0.0519225150346756" size="0.010473595932126045 0.015055186115205288 0.023168545216321945" quat="0.9830483794212341 -4.362582579037986e-16 -0.18334630131721497 6.2756773111516395e-09"/>
          <geom class="collision" type="box" pos="0.06790594756603241 1.485413605450958e-07 0.08311080932617188" size="0.01047359686344862 0.015055186115205288 0.020393677055835724" quat="0.9199845790863037 -2.7333045935385315e-15 -0.3919545114040375 1.341603095283972e-08"/>
          <body name="Button001">
            <joint axis="0.0 0.0 -1.0" pos="0.0756685882806778 -0.0012993308482691646 -0.0734124481678009" limited="true" name="Button001_joint" range="0.0 0.01" type="slide" damping="1" frictionloss="1" armature=".01" stiffness="1" springref="-0.5"/>
            <geom mesh="Button001_vis" type="mesh" solimp="0.998 0.998 0.001" solref="0.001 1" density="100" friction="0.95 0.3 0.1" class="visual" material="Button001_material"/>
            <geom class="collision" type="box" pos="0.0812516063451767 -0.0016174050979316235 -0.07280370593070984" size="0.015766002237796783 0.015154008753597736 0.006412598304450512" quat="1.0 0.0 0.0 0.0"/>
          </body>
          <body name="Button002">
            <joint axis="0.0 1.0 0.0" pos="0.03885579854249954 -0.00021310761803761125 0.11073160171508789" limited="true" name="Button002_joint" range="0.0 0.2617993877991494" type="hinge" damping="1" frictionloss="1" armature=".01" stiffness="0.05"/>
            <geom mesh="Button002_vis" type="mesh" solimp="0.998 0.998 0.001" solref="0.001 1" density="100" friction="0.95 0.3 0.1" class="visual" material="Button002_material"/>
            <geom class="collision" type="box" pos="0.0385051965713501 1.4951478988223244e-07 0.11154983937740326" size="0.0033648379612714052 0.0042495932430028915 0.013864615000784397" quat="0.7748664021492004 7.116161806141556e-15 -0.6321250200271606 2.1636726188489774e-08"/>
          </body>
          <body name="Handle001_Clear">
            <geom mesh="Handle001_Clear_vis" type="mesh" solimp="0.998 0.998 0.001" solref="0.001 1" density="100" friction="0.95 0.3 0.1" class="visual" material="Handle001_Clear_material"/>
            <geom class="collision" type="box" pos="-0.09194859117269516 1.37151630497101e-07 0.03145091235637665" size="0.0025674679782241583 0.013775870203971863 0.07080356031656265" quat="0.9953811168670654 2.5205283819410343e-16 0.09600207954645157 -3.286013017245182e-09"/>
            <geom class="collision" type="box" pos="-0.08866006880998611 -0.020313184708356857 0.03145091235637665" size="0.002567468211054802 0.013775870203971863 0.07080358266830444" quat="0.9825884103775024 -0.015342023223638535 0.09476808458566666 0.15907134115695953"/>
            <geom class="collision" type="box" pos="-0.07927734404802322 -0.03835408762097359 0.03145091235637665" size="0.0025674679782241583 0.013775870203971863 0.07080358266830444" quat="0.9451371431350708 -0.03011561557650566 0.09115605801343918 0.31224891543388367"/>
            <geom class="collision" type="box" pos="-0.06519033014774323 -0.05224457383155823 0.03145091235637665" size="0.0025674679782241583 0.013775869272649288 0.07080357521772385" quat="0.8859407901763916 -0.043763402849435806 0.08544676750898361 0.45375382900238037"/>
            <geom class="collision" type="box" pos="-0.04757314547896385 -0.061194658279418945 0.03145091235637665" size="0.0025674677453935146 0.013775869272649288 0.07080358266830444" quat="0.8058133125305176 -0.05635770410299301 0.07771863043308258 0.58433598279953"/>
            <geom class="collision" type="box" pos="-0.027243597432971 -0.06438132375478745 0.03145091235637665" size="0.002567468211054802 0.013775870203971863 0.07080358266830444" quat="0.7020745277404785 -0.06805353611707687 0.06771327555179596 0.7056025862693787"/>
            <geom class="collision" type="box" pos="-0.007180187851190567 -0.06106935441493988 0.03145091235637665" size="0.0025674677453935146 0.013775870203971863 0.07080358266830444" quat="0.5818332433700562 -0.07789303362369537 0.05611628666520119 0.8076222538948059"/>
            <geom class="collision" type="box" pos="0.010400146245956421 -0.05199624225497246 0.03145091235637665" size="0.0025674679782241583 0.013775870203971863 0.07080358266830444" quat="0.4508408010005951 -0.08559001982212067 0.04348243027925491 0.8874267339706421"/>
            <geom class="collision" type="box" pos="0.027218475937843323 -0.03381851315498352 0.03145091235637665" size="0.0025674679782241583 0.013775870203971863 0.07080358266830444" quat="0.2717500925064087 -0.09235494583845139 0.026209570467472076 0.9575675129890442"/>
            <geom class="collision" type="box" pos="0.03509034216403961 -0.014805912040174007 0.03145091235637665" size="0.0025674679782241583 0.013775869272649288 0.07080358266830444" quat="0.11522914469242096 -0.09535644203424454 0.011113541200757027 0.9886889457702637"/>
            <geom class="collision" type="box" pos="0.0365828201174736 0.005474196746945381 0.03145091235637665" size="0.0025674679782241583 0.013775873929262161 0.07080357521772385" quat="0.04235412925481796 0.0959150418639183 0.004084947053343058 -0.9944796562194824"/>
            <geom class="collision" type="box" pos="0.03189214691519737 0.024693626910448074 0.03145091235637665" size="0.0025674679782241583 0.013775870203971863 0.07080358266830444" quat="0.19464439153671265 0.09414855390787125 0.018772942945361137 -0.9761645197868347"/>
            <geom class="collision" type="box" pos="0.020385682582855225 0.04296153783798218 0.03145091235637665" size="0.002567468211054802 0.013775869272649288 0.07080358266830444" quat="0.3555604815483093 0.0896681472659111 0.03429289162158966 -0.9297098517417908"/>
            <geom class="collision" type="box" pos="0.004381600767374039 0.05589652806520462 0.03145091235637665" size="0.0025674677453935146 0.013775870203971863 0.07080358266830444" quat="0.4995671212673187 0.08303537219762802 0.04818197339773178 -0.8609392046928406"/>
            <geom class="collision" type="box" pos="-0.014645124785602093 0.06307248026132584 0.03145091235637665" size="0.0025674679782241583 0.013775870203971863 0.07080358266830444" quat="0.629260778427124 0.07438433915376663 0.060690559446811676 -0.7712422013282776"/>
            <geom class="collision" type="box" pos="-0.034406062215566635 0.06401807069778442 0.03145091235637665" size="0.0025674677453935146 0.013775870203971863 0.07080358266830444" quat="0.7402840256690979 0.0641765296459198 0.07139846682548523 -0.6654045581817627"/>
            <geom class="collision" type="box" pos="-0.0513199120759964 0.05984029546380043 0.03145091235637665" size="0.0025674679782241583 0.013775870203971863 0.07080358266830444" quat="0.8235074877738953 0.0539260134100914 0.07942517846822739 -0.5591234564781189"/>
            <geom class="collision" type="box" pos="-0.06898686289787292 0.04928924888372421 0.03145091235637665" size="0.0025674679782241583 0.013775870203971863 0.07080358266830444" quat="0.902276873588562 0.04054005816578865 0.0870223194360733 -0.42033320665359497"/>
            <geom class="collision" type="box" pos="-0.08229327946901321 0.033912330865859985 0.03145091235637665" size="0.002567468211054802 0.013775870203971863 0.07080358266830444" quat="0.9573350548744202 0.026288466528058052 0.09233250468969345 -0.2725678086280823"/>
            <geom class="collision" type="box" pos="-0.09000644832849503 0.01569431647658348 0.03145091235637665" size="0.0025674679782241583 0.013775870203971863 0.07080358266830444" quat="0.9878460168838501 0.011790248565375805 0.09527520090341568 -0.12224526703357697"/>
            <geom class="collision" type="box" pos="-0.08053702116012573 0.019328923895955086 0.09065964818000793" size="0.003620235249400139 0.011546943336725235 0.00821163970977068" quat="0.9015769362449646 0.023735864087939262 -0.2408757358789444 -0.35857293009757996"/>
            <geom class="collision" type="box" pos="-0.08790590614080429 0.004140382166951895 0.08134017884731293" size="0.0036202368792146444 0.011546945199370384 0.011602171696722507" quat="0.9193747639656067 0.12453010678291321 -0.3004531264305115 -0.22129221260547638"/>
            <geom class="collision" type="box" pos="-0.08676664531230927 -0.006949464324861765 0.07933914661407471" size="0.003620235715061426 0.011546943336725235 0.011602167040109634" quat="0.8744508028030396 -0.15662609040737152 -0.2659342288970947 0.3742767572402954"/>
            <geom class="collision" type="box" pos="-0.08016178011894226 -0.018924469128251076 0.09193047881126404" size="0.00362023594789207 0.011546943336725235 0.0060956706292927265" quat="0.8819336295127869 -0.1455392688512802 -0.22300024330615997 0.3889501988887787"/>
          </body>
          <body name="Lid001">
            <joint axis="0.0 1.0 0.0" pos="0.016730427742004395 -2.2817766875959933e-05 0.11013001203536987" limited="true" name="Lid001_joint" range="0.0 1.5707963267948966" type="hinge" damping="1" frictionloss="1" armature=".01" stiffness="0.05"/>
            <geom mesh="Lid001_vis" type="mesh" solimp="0.998 0.998 0.001" solref="0.001 1" density="100" friction="0.95 0.3 0.1" class="visual" material="Lid001_material"/>
            <geom class="collision" type="cylinder" pos="-0.02690415270626545 -0.0004728317726403475 0.11209769546985626" size="0.040286507457494736 0.0050375754944980145" quat="1.0 0.0 0.0 0.0"/>
          </body>
        </body>
        <geom class="region" name="reg_main" type="box" pos="0.0 0.0 0.0" size="0.10557770729064941 0.07804347574710846 0.12092188000679016"/>
      </body>
    </body>
  </worldbody>
  <actuator>
    <motor name="Handle001_joint_actuator" joint="Handle001_joint" gear="50"/>
    <motor name="Button001_joint_actuator" joint="Button001_joint" gear="5"/>
    <motor name="Button002_joint_actuator" joint="Button002_joint" gear="10"/>
    <motor name="Lid001_joint_actuator" joint="Lid001_joint" gear="20"/>
  </actuator>
</mujoco>
