<?xml version='1.0' encoding='UTF-8'?>
<mujoco model="model">
  <option timestep="0.002" gravity="0.0 0.0 -9.81"/>
  <compiler angle="radian"/>
  <asset>
    <mesh file="visuals/Blade001.obj" name="Blade001_vis"/>
    <mesh file="visuals/Body001.obj" name="Body001_vis"/>
    <mesh file="visuals/Body002.obj" name="Body002_vis"/>
    <mesh file="visuals/Button001.obj" name="Button001_vis"/>
    <mesh file="visuals/Jug001.obj" name="Jug001_vis"/>
    <mesh file="visuals/Jug001_Clear.obj" name="Jug001_Clear_vis"/>
    <mesh file="visuals/Knob001.obj" name="Knob001_vis"/>
    <mesh file="visuals/Lid001.obj" name="Lid001_vis"/>
    <texture file="visuals/T_BC001.png" name="Body001_material" type="2d"/>
    <material name="Body001_material" rgba="1 1 1 1.0" texture="Body001_material" shininess="0.141421377658844" specular="0.9381"/>
    <texture file="visuals/T_BC001.png" name="Body002_material" type="2d"/>
    <material name="Body002_material" rgba="1 1 1 1.0" texture="Body002_material" shininess="0.141421377658844" specular="0.9381"/>
    <texture file="visuals/T_BC001.png" name="Button001_material" type="2d"/>
    <material name="Button001_material" rgba="1 1 1 1.0" texture="Button001_material" shininess="0.141421377658844" specular="0.3103448502657381"/>
    <texture file="visuals/T_BC001.png" name="Jug001_material" type="2d"/>
    <material name="Jug001_material" rgba="1 1 1 1.0" texture="Jug001_material" shininess="0.141421377658844" specular="1"/>
    <texture file="visuals/T_BC001.png" name="Blade001_material" type="2d"/>
    <material name="Blade001_material" rgba="1 1 1 1.0" texture="Blade001_material" shininess="0.141421377658844" specular="0.81"/>
    <texture file="visuals/T_BC001.png" name="Jug001_Clear_material" type="2d"/>
    <material name="Jug001_Clear_material" rgba="1 1 1 0.75" texture="Jug001_Clear_material" shininess="0.141421377658844" specular="0.3103448502657381"/>
    <texture file="visuals/T_BC001.png" name="Lid001_material" type="2d"/>
    <material name="Lid001_material" rgba="1 1 1 1.0" texture="Lid001_material" shininess="0.141421377658844" specular="0.3103448502657381"/>
    <texture file="visuals/T_BC001.png" name="Knob001_material" type="2d"/>
    <material name="Knob001_material" rgba="1 1 1 1.0" texture="Knob001_material" shininess="0.141421377658844" specular="0.3103448502657381"/>
  </asset>
  <default>
    <default class="visual">
      <geom conaffinity="0" contype="0" group="1" type="mesh"/>
    </default>
    <default class="collision">
      <geom group="0" rgba="0.5 0 0 0.5"/>
    </default>
    <default class="spawn">
      <geom group="0" rgba="1 1 1 0.5" contype="0" conaffinity="0"/>
      <site group="0" rgba="1 1 1 0.5"/>
    </default>
    <default class="region">
      <geom group="1" conaffinity="0" contype="0" rgba="0 1 0 0"/>
    </default>
  </default>
  <worldbody>
    <body>
      <body name="object">
        <geom mesh="Body001_vis" type="mesh" solimp="0.998 0.998 0.001" solref="0.001 1" friction="0.95 0.3 0.1" class="visual" material="Body001_material"/>
        <geom class="collision" type="box" pos="-0.021253 0.010881 -0.144020" size="0.06211231276392937 0.06211231276392937 0.052844155579805374" quat="1.0 0.0 0.0 0.0" density="1000.0"/>
        <geom class="collision" type="box" pos="-0.085225 0.010881 -0.052095" size="0.004011073149740696 0.035763565450906754 0.03144948557019234" quat="0.9938421845436096 0.0 0.11080475151538849 0.0" density="1000.0"/>
        <geom class="collision" type="box" pos="-0.021253 0.012532 -0.052728" size="0.05449925735592842 0.05350634828209877 0.029757998883724213" quat="1.0 0.0 0.0 0.0" density="1000.0"/>
        <geom class="collision" type="box" pos="0.043361 0.011727 -0.051925" size="0.003840292803943157 0.03641745075583458 0.031449493020772934" quat="7.503300025746285e-08 0.9938421845436096 -8.365526049658456e-09 0.11080475151538849" density="1000.0"/>
        <geom class="collision" type="box" pos="-0.021372 0.075431 -0.051965" size="0.0029528222512453794 0.03522942587733269 0.03144948557019234" quat="0.7027524709701538 0.07835067808628082 0.07835064828395844 -0.7027526497840881" density="1000.0"/>
        <geom class="collision" type="box" pos="0.054589 0.011727 -0.115925" size="0.002964968793094158 0.03641745075583458 0.031449493020772934" quat="7.506496757514469e-08 0.9992311000823975 6.5941954119352886e-09 0.03920683637261391" density="1000.0"/>
        <geom class="collision" type="box" pos="0.056308 0.011727 -0.167086" size="0.002594197867438197 0.036417365074157715 0.020559867843985558" quat="1.0 0.0 0.0 0.0" density="1000.0"/>
        <geom class="collision" type="box" pos="-0.097052 0.011727 -0.115874" size="0.003622443415224552 0.03641745075583458 0.031449493020772934" quat="0.03920678049325943 1.5983529522145545e-07 -0.9992311000823975 -6.905221994202293e-08" density="1000.0"/>
        <geom class="collision" type="box" pos="-0.098702 0.011727 -0.167097" size="0.0027845080476254225 0.03641745075583458 0.020521236583590508" quat="0.00966708268970251 -1.636429800555561e-07 0.9999532699584961 7.706934468387772e-08" density="1000.0"/>
        <geom class="collision" type="box" pos="-0.022777 0.084834 -0.116017" size="0.00343827111646533 0.03641745075583458 0.031449493020772934" quat="0.02772333472967148 -0.7065629363059998 -0.7065632939338684 -0.02772342599928379" density="1000.0"/>
        <geom class="collision" type="box" pos="-0.022777 0.088382 -0.167099" size="0.002852672478184104 0.03641745075583458 0.020521236583590508" quat="0.006835713982582092 0.7070736289024353 0.7070738673210144 -0.006835605949163437" density="1000.0"/>
        <geom class="collision" type="box" pos="-0.081538 -0.032782 -0.054651" size="0.004589538089931011 0.01190786249935627 0.031449489295482635" quat="0.9695470929145813 -0.02435024455189705 0.10809601098299026 0.21840497851371765" density="1000.0"/>
        <geom class="collision" type="box" pos="-0.091432 -0.037045 -0.115865" size="0.0037317133974283934 0.01212557777762413 0.031449493020772934" quat="0.03824836015701294 0.21958932280540466 -0.9748042821884155 0.008615943603217602" density="1000.0"/>
        <geom class="collision" type="box" pos="-0.092642 -0.037619 -0.167093" size="0.002582535147666931 0.01212557777762413 0.02052123472094536" quat="0.009430748410522938 -0.21974815428256989 0.9755087494850159 0.002124496502801776" density="1000.0"/>
        <geom class="collision" type="box" pos="-0.070109 -0.046688 -0.055027" size="0.0046595120802521706 0.01190786249935627 0.031449489295482635" quat="0.8976986408233643 -0.0475454218685627 0.10008554905653 0.4264497756958008" density="1000.0"/>
        <geom class="collision" type="box" pos="-0.077223 -0.054798 -0.115995" size="0.003853235626593232 0.012125578708946705 0.031449493020772934" quat="0.03541398048400879 0.42876216769218445 -0.9025662541389465 0.01682324893772602" density="1000.0"/>
        <geom class="collision" type="box" pos="-0.078455 -0.056309 -0.167073" size="0.00331959524191916 0.012125578708946705 0.02052123472094536" quat="0.008731864392757416 -0.42907196283340454 0.9032185673713684 0.004148136358708143" density="1000.0"/>
        <geom class="collision" type="box" pos="-0.067389 0.069451 -0.054751" size="0.004136456176638603 0.01190786249935627 0.031449489295482635" quat="0.8400089740753174 0.05921720340847969 0.09365364164113998 -0.5311377048492432" density="1000.0"/>
        <geom class="collision" type="box" pos="-0.071676 0.079395 -0.115895" size="0.003345175413414836 0.01212557777762413 0.031449493020772934" quat="0.03313807025551796 -0.5340174436569214 -0.844563901424408 -0.020953278988599777" density="1000.0"/>
        <geom class="collision" type="box" pos="-0.072414 0.080951 -0.167093" size="0.0025793202221393585 0.012125578708946705 0.02052123472094536" quat="0.008170791901648045 0.5344034433364868 0.845174252986908 -0.005166299641132355" density="1000.0"/>
        <geom class="collision" type="box" pos="-0.080742 0.057816 -0.055243" size="0.0036779623478651047 0.01190786249935627 0.031449489295482635" quat="0.9363142251968384 0.0371515266597271 0.10439086705446243 -0.3332236111164093" density="1000.0"/>
        <geom class="collision" type="box" pos="-0.088920 0.064985 -0.116063" size="0.0029802799690514803 0.01212557777762413 0.031449493020772934" quat="0.036937300115823746 -0.33503010869026184 -0.9413913488388062 -0.013145629316568375" density="1000.0"/>
        <geom class="collision" type="box" pos="-0.090236 0.066058 -0.167052" size="0.0021978686563670635 0.012125578708946705 0.02052123472094536" quat="0.00910753570497036 0.3352721631526947 0.9420717358589172 -0.003241184866055846" density="1000.0"/>
        <geom class="collision" type="box" pos="0.036844 0.057628 -0.054740" size="0.004184875637292862 0.01190786249935627 0.031449489295482635" quat="0.21840499341487885 0.10809601098299026 0.02435024455189705 -0.9695470929145813" density="1000.0"/>
        <geom class="collision" type="box" pos="0.046941 0.061988 -0.115878" size="0.0035625386517494917 0.01212557777762413 0.031449493020772934" quat="-0.00861596129834652 0.9748042225837708 0.2195894867181778 0.038248416036367416" density="1000.0"/>
        <geom class="collision" type="box" pos="0.048475 0.062715 -0.167097" size="0.0027716634795069695 0.01212557777762413 0.02052123472094536" quat="0.002124497899785638 0.9755087494850159 0.21974819898605347 -0.009430751204490662" density="1000.0"/>
        <geom class="collision" type="box" pos="0.025455 0.071315 -0.055140" size="0.004147086292505264 0.01190786249935627 0.031449489295482635" quat="0.42644959688186646 0.1000855416059494 0.04754539206624031 -0.8976987600326538" density="1000.0"/>
        <geom class="collision" type="box" pos="0.032484 0.079320 -0.116045" size="0.003216261975467205 0.01212557777762413 0.031449493020772934" quat="-0.016823291778564453 0.902566134929657 0.42876243591308594 0.035414036363363266" density="1000.0"/>
        <geom class="collision" type="box" pos="0.033408 0.080455 -0.167052" size="0.0021978686563670635 0.012125578708946705 0.02052123472094536" quat="0.004148140549659729 0.9032185077667236 0.4290720522403717 -0.008731871843338013" density="1000.0"/>
        <geom class="collision" type="box" pos="0.025862 -0.047274 -0.054592" size="0.004858327563852072 0.01190786249935627 0.031449489295482635" quat="0.45094969868659973 -0.09874163568019867 0.05027693882584572 0.885644793510437" density="1000.0"/>
        <geom class="collision" type="box" pos="0.032138 -0.056567 -0.115810" size="0.004437038209289312 0.012125576846301556 0.031449493020772934" quat="0.01778990589082241 0.890447199344635 -0.4533945620059967 0.03493843600153923" density="1000.0"/>
        <geom class="collision" type="box" pos="0.032744 -0.057400 -0.167101" size="0.0029759902972728014 0.012125578708946705 0.02052123472094536" quat="-0.004386311396956444 0.8910906910896301 -0.4537222981452942 -0.008614689111709595" density="1000.0"/>
        <geom class="collision" type="box" pos="0.037595 -0.033442 -0.054942" size="0.005046293139457703 0.01190786249935627 0.031449489295482635" quat="0.24495752155780792 -0.1073862612247467 0.02731061540544033 0.9631812572479248" density="1000.0"/>
        <geom class="collision" type="box" pos="0.047004 -0.039004 -0.115954" size="0.004374327603727579 0.01212557777762413 0.031449493020772934" quat="0.009663566015660763 0.9684039950370789 -0.2462853491306305 0.037997230887413025" density="1000.0"/>
        <geom class="collision" type="box" pos="0.048181 -0.039644 -0.167072" size="0.0032286769710481167 0.012125578708946705 0.02052123472094536" quat="-0.0023826216347515583 0.9691038727760315 -0.24646343290805817 -0.009368867613375187" density="1000.0"/>
        <geom class="collision" type="box" pos="-0.021253 -0.037206 -0.052728" size="0.03730534389615059 0.013394738547503948 0.02153908833861351" quat="1.0 0.0 0.0 0.0" density="1000.0"/>
        <geom class="collision" type="box" pos="-0.021253 -0.040604 -0.140658" size="0.04777161404490471 0.013394767418503761 0.05863378942012787" quat="1.0 0.0 0.0 0.0" density="1000.0"/>
        <geom class="collision" type="cylinder" pos="-0.023179 0.012781 -0.194300" size="0.07701032608747482 0.013251644559204578" quat="1.0 0.0 0.0 0.0" density="1000.0"/>
        <body name="Body002">
          <geom mesh="Body002_vis" type="mesh" solimp="0.998 0.998 0.001" solref="0.001 1" friction="0.95 0.3 0.1" class="visual" material="Body002_material"/>
        </body>
        <body name="Button001">
          <joint axis="0.0 1.0 0.0" pos="-0.019041 -0.056367 -0.043471" limited="true" name="Button001_joint" range="0.0 0.002" type="slide" damping="1" frictionloss="1" armature=".01" stiffness="0.05"/>
          <geom mesh="Button001_vis" type="mesh" solimp="0.998 0.998 0.001" solref="0.001 1" friction="0.95 0.3 0.1" class="visual" material="Button001_material"/>
          <geom class="collision" type="cylinder" pos="-0.018965 -0.061920 -0.069273" size="0.008001218549907207 0.004626220557838678" quat="0.7071068286895752 0.7071067690849304 0.0 0.0" density="1000.0"/>
        </body>
        <body name="Jug001">
          <joint axis="0.0 0.0 1.0" pos="0.016907 0.010881 0.078508" limited="true" name="Jug001_joint" range="0.0 0.1" type="slide" damping="1" frictionloss="1" armature=".01" stiffness="0.05"/>
          <geom mesh="Jug001_vis" type="mesh" solimp="0.998 0.998 0.001" solref="0.001 1" friction="0.95 0.3 0.1" class="visual" material="Jug001_material"/>
          <geom class="collision" type="box" pos="-0.021574 0.011901 -0.006893" size="0.05418802425265312 0.05418802425265312 0.013749852776527405" quat="1.0 0.0 0.0 0.0" density="1000.0"/>
          <geom class="collision" type="cylinder" pos="-0.020338 0.011551 0.011570" size="0.015780305489897728 0.008454694412648678" quat="1.0 0.0 0.0 0.0" density="1000.0"/>
          <geom class="collision" type="box" pos="0.084023 0.010951 0.167506" size="0.027125367894768715 0.015223980881273746 0.011412791907787323" quat="1.0 0.0 0.0 0.0" density="1000.0"/>
          <geom class="collision" type="box" pos="0.098383 0.010951 0.132888" size="0.027125367894768715 0.015223980881273746 0.011412791907787323" quat="0.726495087146759 0.0 -0.6871716380119324 0.0" density="1000.0"/>
          <geom class="collision" type="box" pos="0.086126 0.010951 0.058673" size="0.01660267449915409 0.015223980881273746 0.011412792839109898" quat="0.8605725169181824 0.0 -0.5093279480934143 0.0" density="1000.0"/>
          <geom class="collision" type="box" pos="0.062295 0.010951 0.037959" size="0.020991992205381393 0.015223980881273746 0.011412791907787323" quat="0.9642720222473145 0.0 -0.26491403579711914 0.0" density="1000.0"/>
          <geom class="collision" type="box" pos="0.094394 0.010951 0.087505" size="0.020037682726979256 0.015223980881273746 0.011412792839109898" quat="0.7592610120773315 0.0 -0.6507862210273743 0.0" density="1000.0"/>
          <geom class="collision" type="box" pos="0.051372 0.010757 0.103765" size="0.007271790876984596 0.02493887022137642 0.07511977106332779" quat="1.0 0.0 0.0 0.0" density="1000.0"/>
          <geom class="collision" type="box" pos="0.041907 0.010757 0.017827" size="0.016089878976345062 0.02493887022137642 0.0036388104781508446" quat="0.8233922719955444 0.0 -0.5674726366996765 0.0" density="1000.0"/>
          <geom class="collision" type="box" pos="0.037282 0.010757 -0.004166" size="0.0036560611333698034 0.02493887022137642 0.016093773767352104" quat="1.0 0.0 0.0 0.0" density="1000.0"/>
          <body name="Blade001">
            <joint axis="0.0 0.0 1.0" pos="-0.020283 0.011425 0.028785" limited="false" name="Blade001_joint" range="0 360" type="hinge" damping="1" frictionloss="1" armature=".01" stiffness="0.05"/>
            <geom mesh="Blade001_vis" type="mesh" solimp="0.998 0.998 0.001" solref="0.001 1" friction="0.95 0.3 0.1" class="visual" material="Blade001_material"/>
            <geom class="collision" type="box" pos="-0.020034 0.009960 0.023331" size="0.014491913840174675 0.017638348042964935 0.0007777379360049963" quat="1.0 0.0 0.0 0.0" density="1000.0"/>
            <geom class="collision" type="box" pos="-0.020219 0.043348 0.023331" size="0.0050698015838861465 0.016161534935235977 0.0007777377031743526" quat="1.0 0.0 0.0 0.0" density="1000.0"/>
            <geom class="collision" type="box" pos="-0.020219 -0.020872 0.023331" size="0.0050698015838861465 0.016161534935235977 0.0007777377031743526" quat="1.0 0.0 0.0 0.0" density="1000.0"/>
            <geom class="collision" type="box" pos="-0.051909 0.011219 0.028323" size="0.0050698015838861465 0.01778339222073555 0.0007777350838296115" quat="0.6976117491722107 -0.1154894158244133 0.1154894158244133 -0.6976118087768555" density="1000.0"/>
            <geom class="collision" type="box" pos="0.011316 0.011219 0.028425" size="0.0050698015838861465 0.01746790111064911 0.0007777350838296115" quat="0.11548933386802673 0.6976116299629211 0.6976119875907898 0.11548939347267151" density="1000.0"/>
          </body>
          <body name="Jug001_Clear">
            <geom class="region" name="reg_int" type="box" pos="-0.021175000000000003 0.011158000000000001 0.093347" size="0.054386000000000004 0.054299 0.085662"/>
            <geom mesh="Jug001_Clear_vis" type="mesh" solimp="0.998 0.998 0.001" solref="0.001 1" friction="0.95 0.3 0.1" class="visual" material="Jug001_Clear_material"/>
            <geom class="collision" type="box" pos="-0.019763 -0.058645 0.104612" size="0.018826475366950035 0.002732254099100828 0.0740242451429367" quat="0.999740719795227 0.022769343107938766 0.0 0.0" density="1000.0"/>
            <geom class="collision" type="box" pos="-0.019763 -0.050294 0.018934" size="0.018826471641659737 0.002732254099100828 0.013669250532984734" quat="0.9850984811782837 0.1719912439584732 0.0 0.0" density="1000.0"/>
            <geom class="collision" type="box" pos="-0.052758 -0.051102 0.104612" size="0.018826475366950035 0.002732254331931472 0.0740242451429367" quat="0.9696826338768005 0.02208472415804863 -0.005541310645639896 -0.2433045655488968" density="1000.0"/>
            <geom class="collision" type="box" pos="-0.048815 -0.043740 0.018934" size="0.018826471641659737 0.002732254099100828 0.013669250532984734" quat="0.9554806351661682 0.16682018339633942 -0.041857097297906876 -0.23974105715751648" density="1000.0"/>
            <geom class="collision" type="box" pos="-0.071748 -0.023646 0.018934" size="0.018826471641659737 0.002732254331931472 0.013669250532984734" quat="0.8656151294708252 0.1511302888393402 -0.08210128545761108 -0.47024402022361755" density="1000.0"/>
            <geom class="collision" type="box" pos="-0.078754 -0.028192 0.104612" size="0.018826475366950035 0.0027322538662701845 0.0740242451429367" quat="0.878481388092041 0.020007604733109474 -0.010869103483855724 -0.47723373770713806" density="1000.0"/>
            <geom class="collision" type="box" pos="-0.090387 0.003617 0.104612" size="0.018826475366950035 0.0027322538662701845 0.0740242451429367" quat="0.7358109354972839 0.016758248209953308 -0.01541435532271862 -0.6768041253089905" density="1000.0"/>
            <geom class="collision" type="box" pos="-0.082065 0.004313 0.018934" size="0.018826471641659737 0.002732254331931472 0.013669250532984734" quat="0.7250343561172485 0.12658587098121643 -0.11643454432487488 -0.6668914556503296" density="1000.0"/>
            <geom class="collision" type="box" pos="-0.077936 0.033863 0.018934" size="0.018826471641659737 0.002732254099100828 0.013669250532984734" quat="0.5405582189559937 0.09437765926122665 -0.1437840461730957 -0.823538601398468" density="1000.0"/>
            <geom class="collision" type="box" pos="-0.085598 0.037185 0.104612" size="0.018826475366950035 0.002732254099100828 0.0740242451429367" quat="0.5485929250717163 0.01249431911855936 -0.01903505250811577 -0.8357794880867004" density="1000.0"/>
            <geom class="collision" type="box" pos="-0.064836 0.065042 0.104612" size="0.018826475366950035 0.002732254099100828 0.0740242451429367" quat="0.3224077522754669 0.007342902012169361 -0.021552789956331253 -0.9463270306587219" density="1000.0"/>
            <geom class="collision" type="box" pos="-0.059737 0.058428 0.018934" size="0.018826471641659737 0.002732254099100828 0.013669250532984734" quat="0.31768572330474854 0.05546572059392929 -0.16280220448970795 -0.9324670433998108" density="1000.0"/>
            <geom class="collision" type="box" pos="-0.032190 0.071075 0.018934" size="0.018826471641659737 0.002732254331931472 0.013669250532984734" quat="0.07681706547737122 0.013411737978458405 -0.17146769165992737 -0.9820988178253174" density="1000.0"/>
            <geom class="collision" type="box" pos="-0.033488 0.079324 0.104612" size="0.018826475366950035 0.002732254099100828 0.0740242451429367" quat="0.0779588595032692 0.0017755278386175632 -0.02269996888935566 -0.9966965317726135" density="1000.0"/>
            <geom class="collision" type="box" pos="0.000654 0.076880 0.104612" size="0.018826475366950035 0.002732254099100828 0.0740242451429367" quat="0.1697516292333603 0.0038661318831145763 0.022438693791627884 0.9852238297462463" density="1000.0"/>
            <geom class="collision" type="box" pos="-0.002141 0.069010 0.018934" size="0.018826471641659737 0.002732254099100828 0.013669250532984734" quat="0.16726543009281158 0.0292033813893795 0.16949385404586792 0.970794141292572" density="1000.0"/>
            <geom class="collision" type="box" pos="0.023314 0.052827 0.018934" size="0.018826471641659737 0.002732254099100828 0.013669250532984734" quat="0.40139052271842957 0.07007995247840881 0.1570662409067154 0.899613618850708" density="1000.0"/>
            <geom class="collision" type="box" pos="0.029529 0.058405 0.104612" size="0.018826475366950035 0.002732254099100828 0.0740242451429367" quat="0.4073566794395447 0.009277631528675556 0.020793424919247627 0.9129852652549744" density="1000.0"/>
            <geom class="collision" type="box" pos="0.046104 0.028241 0.104612" size="0.018826475366950035 0.002732253633439541 0.0740242451429367" quat="0.6206277012825012 0.014134923927485943 0.01785062998533249 0.783774733543396" density="1000.0"/>
            <geom class="collision" type="box" pos="0.037975 0.026327 0.018934" size="0.018826471641659737 0.002732254099100828 0.013669250532984734" quat="0.6115379333496094 0.10677023231983185 0.13483738899230957 0.7722955346107483" density="1000.0"/>
            <geom class="collision" type="box" pos="0.038086 -0.004143 0.018934" size="0.018826471641659737 0.0027322538662701845 0.013669250532984734" quat="0.7845726609230042 0.13698099553585052 0.10400602221488953 0.5957052111625671" density="1000.0"/>
            <geom class="collision" type="box" pos="0.046130 -0.006387 0.104612" size="0.018826475366950035 0.002732254099100828 0.0740242451429367" quat="0.7962345480918884 0.018134422600269318 0.013768969103693962 0.6045594215393066" density="1000.0"/>
            <geom class="collision" type="box" pos="0.029890 -0.036263 0.104612" size="0.018826475366950035 0.002732254099100828 0.0740242451429367" quat="0.9198863506317139 0.020950598642230034 0.008917027153074741 0.3915235102176666" density="1000.0"/>
            <geom class="collision" type="box" pos="0.023871 -0.030473 0.018934" size="0.018826471641659737 0.002732254099100828 0.013669250532984734" quat="0.9064136147499084 0.158253476023674 0.06735609471797943 0.3857892155647278" density="1000.0"/>
            <geom class="collision" type="box" pos="0.007009 -0.043405 0.018934" size="0.018826471641659737 0.002732254099100828 0.013669250532984734" quat="0.9596347808837891 0.16754570603370667 0.03885239362716675 0.2225310206413269" density="1000.0"/>
            <geom class="collision" type="box" pos="0.010685 -0.050904 0.104612" size="0.018826475366950035 0.002732254099100828 0.0740242451429367" quat="0.9738985896110535 0.022180764004588127 0.005143522284924984 0.22583864629268646" density="1000.0"/>
            <geom class="collision" type="box" pos="-0.103692 0.010915 0.168573" size="0.00855797715485096 0.010857014916837215 0.009734752587974072" quat="1.0 0.0 0.0 0.0" density="1000.0"/>
          </body>
          <body name="Lid001">
            <joint axis="0.0 0.0 1.0" pos="0.007768 0.010882 0.181177" limited="true" name="Lid001_joint" range="0.0 0.1" type="slide" damping="1" frictionloss="1" armature=".01" stiffness="0.05"/>
            <geom mesh="Lid001_vis" type="mesh" solimp="0.998 0.998 0.001" solref="0.001 1" friction="0.95 0.3 0.1" class="visual" material="Lid001_material"/>
            <geom class="collision" type="cylinder" pos="-0.021221 0.010820 0.185718" size="0.07600142806768417 0.006195507012307644" quat="1.0 0.0 0.0 0.0" density="1000.0"/>
            <geom class="collision" type="cylinder" pos="-0.021221 0.010820 0.167138" size="0.06399042159318924 0.011746169999241829" quat="1.0 0.0 0.0 0.0" density="1000.0"/>
            <geom class="collision" type="cylinder" pos="-0.021221 0.010820 0.204097" size="0.03432024270296097 0.0019606673158705235" quat="1.0 0.0 0.0 0.0" density="1000.0"/>
            <geom class="collision" type="box" pos="0.080236 0.010957 0.183998" size="0.03143944963812828 0.015363558195531368 0.003451445372775197" quat="1.0 0.0 0.0 0.0" density="1000.0"/>
            <geom class="collision" type="cylinder" pos="-0.021221 0.010820 0.197514" size="0.02572418749332428 0.00496209692209959" quat="1.0 0.0 0.0 0.0" density="1000.0"/>
          </body>
        </body>
        <body name="Knob001">
          <joint axis="0.0 1.0 0.0" pos="-0.021078 -0.087395 -0.132159" limited="true" name="Knob001_joint" range="0.0 4.71238898038469" type="hinge" damping="0.05" armature="0.001" springref="-0.4"/>
          <geom mesh="Knob001_vis" type="mesh" solimp="0.998 0.998 0.001" solref="0.001 1" friction="0.95 0.3 0.1" class="visual" material="Knob001_material"/>
          <geom class="collision" type="cylinder" pos="-0.021244 -0.071605 -0.132226" size="0.021976053714752197 0.006431171204894781" quat="0.7071068286895752 0.7071067690849304 0.0 0.0" density="1000.0"/>
          <geom class="collision" type="box" pos="-0.020415 -0.085558 -0.132314" size="0.01853242702782154 0.006443426012992859 0.007792641408741474" quat="0.9151340126991272 -9.15176663157614e-15 -0.4031498432159424 -5.416676529534925e-08" density="1000.0"/>
        </body>
        <geom class="region" name="reg_main" type="box" pos="-0.026009 0.010860000000000002 0.0" size="0.086241 0.08096700000000001 0.207583"/>
      </body>
    </body>
  </worldbody>
  <actuator>
    <motor name="Button001_joint_actuator" joint="Button001_joint" gear="0.5"/>
    <motor name="Jug001_joint_actuator" joint="Jug001_joint" gear="100"/>
    <motor name="Knob001_joint_actuator" joint="Knob001_joint" gear="10"/>
    <motor name="Blade001_joint_actuator" joint="Blade001_joint" gear="10"/>
    <motor name="Lid001_joint_actuator" joint="Lid001_joint" gear="20"/>
  </actuator>
</mujoco>
