<?xml version='1.0' encoding='UTF-8'?>
<mujoco model="model">
  <option timestep="0.002" gravity="0.0 0.0 -9.81"/>
  <compiler angle="radian"/>
  <asset>
    <mesh file="visuals/Body001.obj" name="Body001_vis"/>
    <mesh file="visuals/Container001.obj" name="Container001_vis"/>
    <mesh file="visuals/Door001.obj" name="Door001_vis"/>
    <mesh file="visuals/Door001_Clear.obj" name="Door001_Clear_vis"/>
    <mesh file="visuals/Knob001.obj" name="Knob001_vis"/>
    <mesh file="visuals/Knob002.obj" name="Knob002_vis"/>
    <texture file="visuals/T_BC001.png" name="Body001_material" type="2d"/>
    <material name="Body001_material" rgba="1 1 1 1.0" texture="Body001_material" shininess="0.1" specular="4"/>
    <texture file="visuals/T_BC001.png" name="Container001_material" type="2d"/>
    <material name="Container001_material" rgba="1 1 1 1.0" texture="Container001_material" shininess="0.1" specular="4"/>
    <texture file="visuals/T_BC001.png" name="Door001_material" type="2d"/>
    <material name="Door001_material" rgba="1 1 1 1.0" texture="Door001_material" shininess="0.1" specular="4"/>
    <material name="Door001_Clear_material" rgba="0.048379525542259216 0.048379525542259216 0.048379525542259216 0.800000011920929" shininess="0.141421377658844" specular="0.3103448502657381"/>
    <texture file="visuals/T_BC001.png" name="Knob001_material" type="2d"/>
    <material name="Knob001_material" rgba="1 1 1 1.0" texture="Knob001_material" shininess="0.1" specular="4"/>
    <texture file="visuals/T_BC001.png" name="Knob002_material" type="2d"/>
    <material name="Knob002_material" rgba="1 1 1 1.0" texture="Knob002_material" shininess="0.1" specular="4"/>
  </asset>
  <default>
    <default class="visual">
      <geom conaffinity="0" contype="0" group="1" type="mesh"/>
    </default>
    <default class="collision">
      <geom group="0" rgba="0.5 0 0 0.5"/>
    </default>
    <default class="spawn">
      <geom group="0" rgba="1 1 1 0.5" contype="0" conaffinity="0"/>
      <site group="0" rgba="1 1 1 0.5"/>
    </default>
    <default class="region">
      <geom group="1" conaffinity="0" contype="0" rgba="0 1 0 0"/>
    </default>
  </default>
  <worldbody>
    <body>
      <body name="object">
        <geom mesh="Body001_vis" type="mesh" solimp="0.998 0.998 0.001" solref="0.001 1" friction="0.95 0.3 0.1" class="visual" material="Body001_material"/>
        <geom class="collision" type="box" pos="-0.20415274798870087 0.030364345759153366 0.018009334802627563" size="0.01228012889623642 0.166828453540802 0.14232683181762695" quat="1.0 0.0 0.0 0.0"/>
        <geom class="collision" type="box" pos="-0.03830508887767792 0.030487140640616417 -0.14075882732868195" size="0.17812778055667877 0.1667056530714035 0.019267026335000992" quat="1.0 0.0 0.0 0.0"/>
        <geom class="collision" type="box" pos="-0.03784903511404991 0.18357542157173157 0.013823936693370342" size="0.17491492629051208 0.013617407530546188 0.1465122401714325" quat="1.0 0.0 0.0 0.0"/>
        <geom class="collision" type="box" pos="0.17535442113876343 0.017078449949622154 0.00015325029380619526" size="0.04107845202088356 0.18011435866355896 0.16018293797969818" quat="1.0 0.0 0.0 0.0"/>
        <geom class="collision" type="box" pos="-0.037926942110061646 0.030364345759153366 0.14960181713104248" size="0.17850592732429504 0.166828453540802 0.006701894570142031" quat="1.0 0.0 0.0 0.0"/>
        <geom class="collision" type="box" pos="-0.18752072751522064 0.01099355798214674 -0.004263693932443857" size="0.0038743503391742706 0.1269080638885498 0.01615913026034832" quat="1.0 0.0 0.0 0.0"/>
        <geom class="collision" type="box" pos="0.129982128739357 0.01099355798214674 -0.00426369346678257" size="0.0038743503391742706 0.1269080638885498 0.01615913212299347" quat="1.0 0.0 0.0 0.0"/>
        <geom class="collision" type="box" pos="0.129982128739357 0.01099355798214674 -0.0417608767747879" size="0.0038743503391742706 0.1269080638885498 0.01615913212299347" quat="1.0 0.0 0.0 0.0"/>
        <geom class="collision" type="box" pos="-0.18752072751522064 0.01099355798214674 -0.041760873049497604" size="0.0038743503391742706 0.1269080638885498 0.01615913026034832" quat="1.0 0.0 0.0 0.0"/>
        <body name="Container001">
          <joint axis="0.0 -1.0 0.0" pos="-0.0286320298910141 0.008345574140548706 -0.0250944085419178" limited="true" name="Container001_joint" range="0.0 0.18" type="slide" damping="1" frictionloss="1" armature=".01" stiffness="0.05"/>
          <geom mesh="Container001_vis" type="mesh" solimp="0.998 0.998 0.001" solref="0.001 1" friction="0.95 0.3 0.1" class="visual" material="Container001_material"/>
          <geom class="collision" type="box" pos="-0.028050526976585388 0.00856306403875351 -0.03312180936336517" size="0.13570380210876465 0.12284986674785614 0.0030371095053851604" quat="1.0 0.0 0.0 0.0"/>
          <geom class="collision" type="box" pos="-0.18249718844890594 0.00848282128572464 -0.023407921195030212" size="0.008577265776693821 0.12300089746713638 0.0016675754450261593" quat="1.0 0.0 0.0 0.0"/>
          <geom class="collision" type="box" pos="-0.16859768331050873 0.008476242423057556 -0.028198152780532837" size="0.008577265776693821 0.12300733476877213 0.0016675754450261593" quat="0.9440328478813171 -2.0632491271044273e-08 0.3298514783382416 7.209132402152818e-09"/>
          <geom class="collision" type="box" pos="0.11243187636137009 0.00847623497247696 -0.028198152780532837" size="0.008577265776693821 0.12300732731819153 0.001667564152739942" quat="7.127249546101666e-08 -0.9440328478813171 -2.4903092921135794e-08 -0.3298514783382416"/>
          <geom class="collision" type="box" pos="0.1255408525466919 0.00848282128572464 -0.023407921195030212" size="0.008577265776693821 0.12300089746713638 0.0016675754450261593" quat="1.0 0.0 0.0 0.0"/>
          <geom class="collision" type="box" pos="-0.16493763029575348 0.010533690452575684 -0.022929660975933075" size="0.01039555761963129 0.10141760855913162 0.0013619114179164171" quat="0.834775984287262 4.4288775313816586e-08 0.5505897402763367 -1.412595151961682e-09"/>
          <geom class="collision" type="box" pos="-0.030840031802654266 -0.10302691161632538 -0.022451981902122498" size="0.010395568795502186 0.12232556194067001 0.0013619264354929328" quat="0.560018002986908 -0.43171724677085876 0.43171700835227966 0.5600183010101318"/>
          <geom class="collision" type="box" pos="0.10875648260116577 0.010533690452575684 -0.022929660975933075" size="0.010395561344921589 0.10141760855913162 0.0013619245728477836" quat="3.057074238199675e-08 0.834775984287262 7.635351906287724e-09 0.5505897402763367"/>
          <geom class="collision" type="box" pos="-0.03084002062678337 0.12535323202610016 -0.022451981902122498" size="0.010395568795502186 0.12232555449008942 0.0013619414530694485" quat="0.4317190647125244 -0.5600156188011169 -0.5600206851959229 -0.431715190410614"/>
          <geom class="collision" type="box" pos="-0.16124983131885529 -0.09286629408597946 -0.022929660975933075" size="0.010395561344921589 0.006986106745898724 0.0013619414530694485" quat="0.8021135926246643 -0.15250761806964874 0.529046893119812 0.23122413456439972"/>
          <geom class="collision" type="box" pos="-0.15337802469730377 -0.1000886783003807 -0.022929631173610687" size="0.010395553894340992 0.006986099295318127 0.0013619114179164171" quat="0.7184903621673584 -0.28031352162361145 0.4738919734954834 0.42499685287475586"/>
          <geom class="collision" type="box" pos="-0.17176543176174164 0.010817490518093109 -0.014918908476829529" size="0.004246910568326712 0.10587437450885773 0.0010674485238268971" quat="1.0 0.0 0.0 0.0"/>
          <geom class="collision" type="box" pos="-0.028321094810962677 -0.10664207488298416 -0.014918908476829529" size="0.13291940093040466 0.0026962708216160536 0.0010674635414034128" quat="1.0 0.0 0.0 0.0"/>
          <geom class="collision" type="box" pos="-0.16910243034362793 -0.09683185815811157 -0.014918908476829529" size="0.004246880766004324 0.0049521178007125854 0.0010674335062503815" quat="0.9630976915359497 -7.4883722334107e-08 -9.148812374348836e-09 0.26915204524993896"/>
          <geom class="collision" type="box" pos="-0.16307450830936432 -0.10251420736312866 -0.014918908476829529" size="0.004246910102665424 0.0058218990452587605 0.0010674335062503815" quat="0.8660538196563721 -1.892820655768901e-08 -1.0926771487618225e-08 0.4999507665634155"/>
          <geom class="collision" type="box" pos="-0.16307449340820312 0.12372061610221863 -0.014918908476829529" size="0.004246910568326712 0.005821899976581335 0.0010674335062503815" quat="4.651262841548487e-08 -0.4999507665634155 -0.8660538196563721 -7.043785643645606e-08"/>
          <geom class="collision" type="box" pos="-0.16910243034362793 0.1180383563041687 -0.014918908476829529" size="0.004246881231665611 0.00495211873203516 0.0010674335062503815" quat="8.102094284367922e-08 0.26915183663368225 0.9630977511405945 9.411745161003182e-09"/>
          <geom class="collision" type="box" pos="-0.15337805449962616 0.12129524350166321 -0.02292964607477188" size="0.010395553894340992 0.006986084394156933 0.0013619116507470608" quat="0.4738919138908386 -0.42499667406082153 -0.7184905409812927 -0.2803134322166443"/>
          <geom class="collision" type="box" pos="-0.16124983131885529 0.11407285928726196 -0.022929653525352478" size="0.010395561344921589 0.0069860671646893024 0.0013619414530694485" quat="0.5290468335151672 -0.23122407495975494 -0.8021136522293091 -0.15250758826732635"/>
          <geom class="collision" type="box" pos="-0.02832108736038208 0.12875306606292725 -0.014918908476829529" size="0.13291940093040466 0.002696278505027294 0.0010674635414034128" quat="1.0 0.0 0.0 0.0"/>
          <geom class="collision" type="box" pos="0.1047220304608345 0.11407285928726196 -0.02292964607477188" size="0.010395561344921589 0.006986069027334452 0.0013619264354929328" quat="0.23122406005859375 0.5290468335151672 0.15250755846500397 -0.8021136522293091"/>
          <geom class="collision" type="box" pos="0.09675933420658112 0.1212952733039856 -0.022929660975933075" size="0.010395553894340992 0.006986084394156933 0.0013619114179164171" quat="0.4249967634677887 0.47389188408851624 0.2803134620189667 -0.718490481376648"/>
          <geom class="collision" type="box" pos="0.11248373240232468 0.11803838610649109 -0.014918908476829529" size="0.004246910568326712 0.0049521178007125854 0.0010674335062503815" quat="0.2691517472267151 6.8938410535679395e-09 1.7478617664323792e-08 -0.9630978107452393"/>
          <geom class="collision" type="box" pos="0.10645583271980286 0.12372061610221863 -0.014918908476829529" size="0.004246910568326712 0.005821899976581335 0.0010674335062503815" quat="0.49995073676109314 1.88726119176863e-08 -3.26926254956561e-08 -0.8660538196563721"/>
          <geom class="collision" type="box" pos="0.10685637593269348 -0.10251417756080627 -0.014918908476829529" size="0.004246910102665424 0.0058218990452587605 0.0010674335062503815" quat="6.538524388588485e-08 -0.8660538196563721 0.4999507665634155 -3.7745234493513635e-08"/>
          <geom class="collision" type="box" pos="0.11288432031869888 -0.09683186560869217 -0.014918908476829529" size="0.004246911033987999 0.00495211873203516 0.0010674335062503815" quat="7.576508664897119e-08 -0.9630977511405945 0.26915186643600464 -9.395116684629556e-09"/>
          <geom class="collision" type="box" pos="0.09675939381122589 -0.10008874535560608 -0.02292967587709427" size="0.010395553894340992 0.006986084394156933 0.0013619114179164171" quat="0.28031325340270996 0.7184906601905823 -0.4249964952468872 0.4738919734954834"/>
          <geom class="collision" type="box" pos="0.10463112592697144 -0.09286627173423767 -0.02292964980006218" size="0.010395565070211887 0.006986069958657026 0.0013619264354929328" quat="0.15250751376152039 0.8021135926246643 -0.23122410476207733 0.5290469527244568"/>
          <geom class="collision" type="box" pos="0.11535310745239258 0.010817490518093109 -0.014918908476829529" size="0.004246903117746115 0.10587437450885773 0.0010674485238268971" quat="1.0 0.0 0.0 0.0"/>
        </body>
        <body name="Door001">
          <joint axis="1.0 0.0 0.0" pos="-0.04003845155239105 -0.1473190039396286 -0.13602320849895477" limited="true" name="Door001_joint" range="0.0 1.5707963267948966" type="hinge" damping="1" frictionloss="1" armature=".01" stiffness="1" springref="-5"/>
          <geom mesh="Door001_vis" type="mesh" solimp="0.998 0.998 0.001" solref="0.001 1" friction="0.95 0.3 0.1" class="visual" material="Door001_material"/>
          <geom class="collision" type="box" pos="0.12332412600517273 -0.15798062086105347 0.010491401888430119" size="0.009189937263727188 0.00839040707796812 0.14581313729286194" quat="1.0 0.0 0.0 0.0"/>
          <geom class="collision" type="box" pos="0.11159779876470566 -0.1786157488822937 0.13966584205627441" size="0.016804123297333717 0.019023166969418526 0.0131309162825346" quat="1.0 0.0 0.0 0.0"/>
          <geom class="collision" type="box" pos="-0.04032648354768753 -0.19220219552516937 0.13966584205627441" size="0.14049795269966125 0.005172274075448513 0.013130927458405495" quat="1.0 0.0 0.0 0.0"/>
          <geom class="collision" type="box" pos="-0.19070479273796082 -0.1786157488822937 0.13966584205627441" size="0.020299002528190613 0.005172316916286945 0.013131000101566315" quat="0.9027569890022278 0.0 -0.0 -0.4301508665084839"/>
          <geom class="collision" type="box" pos="-0.20517940819263458 -0.15798062086105347 0.010491397231817245" size="0.007584613747894764 0.00839040707796812 0.14581289887428284" quat="1.0 0.0 0.0 0.0"/>
          <geom class="collision" type="box" pos="-0.03475116938352585 -0.15798062086105347 0.12886808812618256" size="0.16726620495319366 0.00839040707796812 0.027435747906565666" quat="1.0 0.0 0.0 0.0"/>
          <geom class="collision" type="box" pos="-0.03475116938352585 -0.15798062086105347 -0.1301911473274231" size="0.16726605594158173 0.00839040707796812 0.004177995026111603" quat="1.0 0.0 0.0 0.0"/>
          <body name="Door001_Clear">
            <geom mesh="Door001_Clear_vis" type="mesh" solimp="0.998 0.998 0.001" solref="0.001 1" friction="0.95 0.3 0.1" class="visual" material="Door001_Clear_material"/>
            <geom class="collision" type="box" pos="-0.04032052308320999 -0.16133713722229004 -0.013235360383987427" size="0.1489069014787674 0.0013776615960523486 0.10721638798713684" quat="1.0 0.0 0.0 0.0"/>
          </body>
        </body>
        <body name="Knob001">
          <joint axis="0.0 1.0 0.0" pos="0.17845702171325684 -0.17745542526245117 0.041536737233400345" limited="true" name="Knob001_joint" range="0.0 3.979350694547071" type="hinge" damping="0.05" armature="0.001" springref="-0.01"/>
          <geom mesh="Knob001_vis" type="mesh" solimp="0.998 0.998 0.001" solref="0.001 1" friction="0.95 0.3 0.1" class="visual" material="Knob001_material"/>
          <geom class="collision" type="cylinder" pos="0.1791357696056366 -0.16968730092048645 0.041744932532310486" size="0.02181580662727356 0.0030348224099725485" quat="0.7071068286895752 0.7071067690849304 0.0 0.0"/>
          <geom class="collision" type="cylinder" pos="0.1791357696056366 -0.17273741960525513 0.041744932532310486" size="0.01766309328377247 0.0030348224099725485" quat="0.7071068286895752 0.7071067690849304 0.0 0.0"/>
          <geom class="collision" type="box" pos="0.1784660965204239 -0.1826753318309784 0.041192345321178436" size="0.005347151774913073 0.008014240302145481 0.016881024464964867" quat="1.0 0.0 0.0 0.0"/>
        </body>
        <body name="Knob002">
          <joint axis="0.0 1.0 0.0" pos="0.17750678956508636 -0.17745542526245117 -0.06337741017341614" limited="true" name="Knob002_joint" range="0.0 3.9269908169872414" type="hinge" damping="0.05" armature="0.001" springref="-0.01"/>
          <geom mesh="Knob002_vis" type="mesh" solimp="0.998 0.998 0.001" solref="0.001 1" friction="0.95 0.3 0.1" class="visual" material="Knob002_material"/>
          <geom class="collision" type="cylinder" pos="0.17726966738700867 -0.16968730092048645 -0.06367860734462738" size="0.02181580662727356 0.0030348224099725485" quat="0.7071068286895752 0.7071067690849304 0.0 0.0"/>
          <geom class="collision" type="cylinder" pos="0.17726966738700867 -0.17273741960525513 -0.06367860734462738" size="0.01766309328377247 0.0030348224099725485" quat="0.7071068286895752 0.7071067690849304 0.0 0.0"/>
          <geom class="collision" type="box" pos="0.17711836099624634 -0.1826753318309784 -0.06318798661231995" size="0.0169717725366354 0.008014236576855183 0.00564094353467226" quat="1.0 0.0 0.0 0.0"/>
        </body>
        <geom class="region" name="reg_int" type="box" pos="-0.028471529483795166 0.01520584523677826 0.010962452739477158" size="0.1647653430700302 0.15457585453987122 0.13433371856808662"/>
        <geom class="region" name="reg_main" type="box" pos="0.0 0.015410885214805603 -5.960464477539063e-08" size="0.2164328694343567 0.18178191781044006 0.1603362262248993"/>
      </body>
    </body>
  </worldbody>
  <actuator>
    <motor name="Container001_joint_actuator" joint="Container001_joint" gear="10"/>
    <motor name="Door001_joint_actuator" joint="Door001_joint" gear="50"/>
    <motor name="Knob001_joint_actuator" joint="Knob001_joint" gear="50"/>
    <motor name="Knob002_joint_actuator" joint="Knob002_joint" gear="50"/>
  </actuator>
</mujoco>
