<mujoco model="model">
  <compiler angle="radian"/>
  <asset>
    <mesh file="visuals/handle.obj" name="handle_vis"/>
    <mesh file="visuals/Body001.obj" name="Body001_vis"/>
    <mesh file="visuals/Container001.obj" name="Container001_vis"/>
    <mesh file="visuals/Funnel001.obj" name="Funnel001_vis"/>
    <mesh file="visuals/spout.obj" name="spout_vis"/>
    <texture file="visuals/T_BC001.png" name="Body001_material" type="2d"/>
    <material name="Body001_material" rgba="1 1 1 1.0" texture="Body001_material" shininess="0.141421377658844" specular="1"/>
    <texture file="visuals/T_BC001.png" name="handle_material" type="2d"/>
    <material name="handle_material" rgba="1 1 1 1.0" texture="handle_material" shininess="0.141421377658844" specular="2"/>
    <texture file="visuals/T_BC001.png" name="Container001_material" type="2d"/>
    <material name="Container001_material" rgba="1 1 1 1.0" texture="Container001_material" shininess="0.141421377658844" specular="0.3103448502657381"/>
    <texture file="visuals/T_BC001.png" name="Funnel001_material" type="2d"/>
    <material name="Funnel001_material" rgba="1 1 1 1.0" texture="Funnel001_material" shininess="0.141421377658844" specular="2"/>
    <texture file="visuals/T_BC001.png" name="spout_material" type="2d"/>
    <material name="spout_material" rgba="1 1 1 1.0" texture="spout_material" shininess="0.141421377658844" specular="2"/>
  </asset>
  <default>
    <default class="visual">
      <geom conaffinity="0" contype="0" group="1" type="mesh"/>
    </default>
    <default class="collision">
      <geom group="0" rgba="0.5 0 0 0.5"/>
    </default>
    <default class="spawn">
      <geom group="0" rgba="1 1 1 0.5" contype="0" conaffinity="0"/>
      <site group="0" rgba="1 1 1 0.5"/>
    </default>
    <default class="region">
      <geom group="1" conaffinity="0" contype="0" rgba="0 1 0 0"/>
    </default>
  </default>
  <worldbody>
    <body>
      <body name="object">
        <geom mesh="Body001_vis" type="mesh" solimp="0.998 0.998 0.001" solref="0.001 1" density="100" friction="0.95 0.3 0.1" class="visual" material="Body001_material"/>
        <geom class="collision" type="box" pos="0.0005376921035349369 -0.21847569942474365 -0.136440247297287" size="0.35532641410827637 0.013969678431749344 0.10168053209781647" quat="1.0 0.0 0.0 0.0"/>
        <geom class="collision" type="box" pos="-0.0002647433429956436 -0.11707393079996109 -0.2162827104330063" size="0.3545239567756653 0.11051830649375916 0.021838078275322914" quat="1.0 0.0 0.0 0.0"/>
        <geom class="collision" type="box" pos="-0.0002647433429956436 0.16783802211284637 -0.2162827104330063" size="0.3545239567756653 0.0628652423620224 0.021838078275322914" quat="1.0 0.0 0.0 0.0"/>
        <geom class="collision" type="box" pos="0.0005376921035349369 0.19599318504333496 -0.136440247297287" size="0.35532641410827637 0.03682418912649155 0.10168053209781647" quat="1.0 0.0 0.0 0.0"/>
        <geom class="collision" type="box" pos="-0.20100711286067963 0.05351879820227623 -0.2162827104330063" size="0.15378160774707794 0.0628652423620224 0.021838078275322914" quat="1.0 0.0 0.0 0.0"/>
        <geom class="collision" type="box" pos="0.199110209941864 0.05351879820227623 -0.2162827104330063" size="0.13272280991077423 0.0628652423620224 0.021838078275322914" quat="1.0 0.0 0.0 0.0"/>
        <geom class="collision" type="box" pos="-0.3402691185474396 -0.02451847493648529 -0.136440247297287" size="0.01451962161809206 0.19041675329208374 0.10168053209781647" quat="1.0 0.0 0.0 0.0"/>
        <geom class="collision" type="box" pos="0.34061792492866516 -0.02451847493648529 -0.136440247297287" size="0.01451962161809206 0.19041675329208374 0.10168053209781647" quat="1.0 0.0 0.0 0.0"/>
        <geom class="collision" type="cylinder" pos="0.008839156478643417 0.1905600130558014 0.006005296483635902" size="0.015300664119422436 0.042066384106874466" quat="1.0 0.0 0.0 0.0"/>
        <geom class="collision" type="cylinder" pos="0.024994343519210815 0.1905600130558014 0.01319047436118126" size="0.015300665982067585 0.01876227930188179" quat="0.7071068286895752 0.0 -0.7071067690849304 0.0"/>
        <body name="handle">
          <joint axis="1.0 0.0 0.0" pos="0.05906230956315994 0.19032001495361328 0.012800361961126328" limited="true" name="handle_joint_hinge_0" type="hinge" range="-0.7853981633974483 0.7853981633974483" damping="1" frictionloss="1" armature=".01" stiffness="0.05"/>
          <joint axis="0.0 1.0 0.0" pos="0.05906230956315994 0.19032001495361328 0.012800361961126328" limited="true" name="handle_joint_hinge_1" type="hinge" range="0.0 0.17453292519943295" damping="1" frictionloss="1" armature=".01" stiffness="0.05"/>
          <geom mesh="handle_vis" type="mesh" solimp="0.998 0.998 0.001" solref="0.001 1" density="100" friction="0.95 0.3 0.1" class="visual" material="handle_material"/>
          <geom class="collision" type="cylinder" pos="0.05993214622139931 0.1905600130558014 0.01319047436118126" size="0.015300667844712734 0.009021526202559471" quat="0.7071068286895752 0.0 -0.7071067690849304 0.0"/>
          <geom class="collision" type="cylinder" pos="0.06259022653102875 0.19027121365070343 0.051185812801122665" size="0.003057922935113311 0.02486662194132805" quat="7.549790126404332e-08 -0.0 -1.0 -0.0"/>
        </body>
        <body name="Container001">
          <joint axis="0.0 0.0 1.0" pos="-0.193882018327713 -0.02310939133167267 -0.05167678743600845" limited="true" name="Container001_joint" range="0.0 0.1" type="slide" damping="1" frictionloss="1" armature=".01" stiffness="0.05"/>
          <geom mesh="Container001_vis" type="mesh" solimp="0.998 0.998 0.001" solref="0.001 1" density="100" friction="0.95 0.3 0.1" class="visual" material="Container001_material"/>
          <geom class="collision" type="box" pos="-0.1939459890127182 -0.022472580894827843 -0.06992444396018982" size="0.12832015752792358 0.18015123903751373 0.0020639626309275627" quat="1.0 0.0 0.0 0.0"/>
          <geom class="collision" type="box" pos="-0.1939459890127182 -0.20150455832481384 -0.051240816712379456" size="0.12832015752792358 0.0017774796579033136 0.02072480507194996" quat="1.0 0.0 0.0 0.0"/>
          <geom class="collision" type="box" pos="-0.1939459890127182 0.15606608986854553 -0.051240816712379456" size="0.12832015752792358 0.0017774796579033136 0.02072480507194996" quat="1.0 0.0 0.0 0.0"/>
          <geom class="collision" type="box" pos="-0.1939459890127182 -0.21370342373847961 -0.0321321077644825" size="0.12832015752792358 0.013976345770061016 0.001616097055375576" quat="1.0 0.0 0.0 0.0"/>
          <geom class="collision" type="box" pos="-0.1939459890127182 0.16761654615402222 -0.03262577950954437" size="0.12832015752792358 0.013976345770061016 0.001616097055375576" quat="1.0 0.0 0.0 0.0"/>
          <geom class="collision" type="box" pos="-0.06785516440868378 -0.022472580894827843 -0.05299340933561325" size="0.0022293413057923317 0.18015123903751373 0.019003160297870636" quat="1.0 0.0 0.0 0.0"/>
          <geom class="collision" type="box" pos="-0.31990814208984375 -0.022472580894827843 -0.05299340933561325" size="0.0022293413057923317 0.18015123903751373 0.019003160297870636" quat="1.0 0.0 0.0 0.0"/>
        </body>
        <body name="Funnel001">
          <joint axis="0.0 0.0 1.0" pos="0.009307553991675377 0.048979148268699646 -0.1984708607196808" limited="true" name="Funnel001_joint" range="0.0 0.1" type="slide" damping="1" frictionloss="1" armature=".01" stiffness="0.05"/>
          <geom mesh="Funnel001_vis" type="mesh" solimp="0.998 0.998 0.001" solref="0.001 1" density="100" friction="0.95 0.3 0.1" class="visual" material="Funnel001_material"/>
          <geom class="collision" type="box" pos="0.008941886946558952 0.005341924726963043 -0.1912476271390915" size="0.010534909553825855 0.010785062797367573 0.001017694710753858" quat="1.0 0.0 0.0 0.0"/>
          <geom class="collision" type="box" pos="0.008941886015236378 0.028430961072444916 -0.198435440659523" size="0.010534909553825855 0.015278312377631664 0.0010176937794312835" quat="0.9664247035980225 -0.2569500207901001 -0.0 0.0"/>
          <geom class="collision" type="box" pos="-0.006617531180381775 0.008360810577869415 -0.1912476271390915" size="0.010534909553825855 0.010785062797367573 0.001017694710753858" quat="0.983372688293457 0.0 -0.0 -0.18159885704517365"/>
          <geom class="collision" type="box" pos="0.0016289160121232271 0.029926979914307594 -0.19843542575836182" size="0.010534909553825855 0.015278313308954239 0.0010176937794312835" quat="0.9503556489944458 -0.2526777386665344 0.046661846339702606 -0.17550158500671387"/>
          <geom class="collision" type="box" pos="-0.004733966197818518 0.033998459577560425 -0.19843542575836182" size="0.010534909553825855 0.01527831144630909 0.0010176937794312835" quat="0.9019154906272888 -0.23979853093624115 0.09230377525091171 -0.3471672832965851"/>
          <geom class="collision" type="box" pos="-0.02021515928208828 0.0168684720993042 -0.1912476271390915" size="0.010534909553825855 0.010785062797367573 0.001017694710753858" quat="0.9332496523857117 0.0 -0.0 -0.3592284917831421"/>
          <geom class="collision" type="box" pos="-0.029600532725453377 0.029273465275764465 -0.1912476271390915" size="0.010534909553825855 0.010785062797367573 0.001017694710753858" quat="0.8542832136154175 0.0 -0.0 -0.5198078751564026"/>
          <geom class="collision" type="box" pos="-0.009094553999602795 0.039885178208351135 -0.19843542575836182" size="0.010534909553825855 0.015278312377631664 0.0010176937794312835" quat="0.8256003856658936 -0.2195081263780594 0.13356466591358185 -0.50235515832901"/>
          <geom class="collision" type="box" pos="-0.011103366501629353 0.046830158680677414 -0.19843542575836182" size="0.010534909553825855 0.015278312377631664 0.0010176937794312835" quat="0.7243714332580566 -0.19259366393089294 0.1700911670923233 -0.6397364139556885"/>
          <geom class="collision" type="box" pos="-0.03401532769203186 0.043976061046123505 -0.1912476271390915" size="0.010534909553825855 0.010785062797367573 0.001017694710753858" quat="0.7495374083518982 0.0 -0.0 -0.6619619727134705"/>
          <geom class="collision" type="box" pos="-0.03295079618692398 0.059758514165878296 -0.1912476271390915" size="0.010534909553825855 0.010785062797367573 0.001017694710753858" quat="0.617149829864502 0.0 -0.0 -0.7868456840515137"/>
          <geom class="collision" type="box" pos="-0.010526648722589016 0.05425750091671944 -0.19843542575836182" size="0.010534909553825855 0.015278312377631664 0.0010176937794312835" quat="0.5964288115501404 -0.15857671201229095 0.20218007266521454 -0.7604270577430725"/>
          <geom class="collision" type="box" pos="-0.007023243699222803 0.06141942739486694 -0.19843542575836182" size="0.010534909553825855 0.015278312377631664 0.0010176937794312835" quat="0.43760189414024353 -0.1163482591509819 0.2290991246700287 -0.8616735339164734"/>
          <geom class="collision" type="box" pos="-0.02566649578511715 0.07504045963287354 -0.1912476271390915" size="0.010534909553825855 0.010785062797367573 0.001017694710753858" quat="0.45280495285987854 0.0 -0.0 -0.8916096091270447"/>
          <geom class="collision" type="box" pos="-0.014346346259117126 0.08563309907913208 -0.1912476271390915" size="0.010534909553825855 0.010785062797367573 0.001017694710753858" quat="0.2872273027896881 0.0 -0.0 -0.9578624367713928"/>
          <geom class="collision" type="box" pos="-0.0016416398575529456 0.06635373085737228 -0.19843542575836182" size="0.010534909553825855 0.015278312377631664 0.0010176937794312835" quat="0.2775835394859314 -0.07380306720733643 0.246122807264328 -0.925701916217804"/>
          <geom class="collision" type="box" pos="0.005647306330502033 0.0691973865032196 -0.19843542575836182" size="0.010534909553825855 0.01527831144630909 0.0010176937794312835" quat="0.09630388766527176 -0.02560499869287014 0.2556712031364441 -0.9616143703460693"/>
          <geom class="collision" type="box" pos="0.001176418736577034 0.09129487723112106 -0.1912476271390915" size="0.010534909553825855 0.010785062797367573 0.001017694710753858" quat="0.09964966028928757 0.0 -0.0 -0.9950225949287415"/>
          <geom class="collision" type="box" pos="0.016370858997106552 0.09204737842082977 -0.1912476271390915" size="0.010534909553825855 0.010785062797367573 0.001017694710753858" quat="0.07636753469705582 0.0 0.0 0.9970797300338745"/>
          <geom class="collision" type="box" pos="0.012854654341936111 0.06922765076160431 -0.19843542575836182" size="0.010534909553825855 0.015278312377631664 0.0010176937794312835" quat="0.07380346953868866 -0.019622646272182465 -0.25619974732398987 0.9636024832725525"/>
          <geom class="collision" type="box" pos="0.02003386802971363 0.06652729958295822 -0.19843542575836182" size="0.010534909553825855 0.015278312377631664 0.0010176937794312835" quat="0.25232169032096863 -0.06708654761314392 -0.24803785979747772 0.9329043030738831"/>
          <geom class="collision" type="box" pos="0.03167222440242767 0.08646851778030396 -0.1912476271390915" size="0.010534909553825855 0.010785062797367573 0.001017694710753858" quat="0.26108789443969727 0.0 0.0 0.965315043926239"/>
          <geom class="collision" type="box" pos="0.043686434626579285 0.07589393854141235 -0.1912476271390915" size="0.010534909553825855 0.010785062797367573 0.001017694710753858" quat="0.4336804449558258 0.0 0.0 0.9010667204856873"/>
          <geom class="collision" type="box" pos="0.025641195476055145 0.0614900141954422 -0.19843542575836182" size="0.010534909553825855 0.015278312377631664 0.0010176937794312835" quat="0.4191194772720337 -0.11143424361944199 -0.23152922093868256 0.8708131313323975"/>
          <geom class="collision" type="box" pos="0.029029611498117447 0.05485641956329346 -0.19843542575836182" size="0.010534909553825855 0.015278312377631664 0.0010176937794312835" quat="0.5699891448020935 -0.15154705941677094 -0.20750154554843903 0.7804415225982666"/>
          <geom class="collision" type="box" pos="0.05102374404668808 0.06188222020864487 -0.1912476271390915" size="0.010534909553825855 0.010785062797367573 0.001017694710753858" quat="0.5897916555404663 0.0 0.0 0.8075554370880127"/>
          <geom class="collision" type="box" pos="0.0528598427772522 0.04581174999475479 -0.1912476271390915" size="0.010534909553825855 0.010785062797367573 0.001017694710753858" quat="0.729236900806427 0.0 0.0 0.6842613220214844"/>
          <geom class="collision" type="box" pos="0.029817506670951843 0.047279585152864456 -0.19843542575836182" size="0.010534909553825855 0.015278313308954239 0.0010176937794312835" quat="0.704752504825592 -0.18737751245498657 -0.17582103610038757 0.6612870097160339"/>
          <geom class="collision" type="box" pos="0.02766343206167221 0.039679355919361115 -0.19843542575836182" size="0.010534909553825855 0.015278312377631664 0.0010176937794312835" quat="0.8187047839164734 -0.2176748365163803 -0.1365322321653366 0.513516366481781"/>
          <geom class="collision" type="box" pos="0.048449933528900146 0.029628237709403038 -0.1912476271390915" size="0.010534909553825855 0.010785062797367573 0.001017694710753858" quat="0.8471481204032898 0.0 0.0 0.5313568115234375"/>
          <geom class="collision" type="box" pos="0.0386122390627861 0.01661773771047592 -0.1912476271390915" size="0.010534909553825855 0.010785062797367573 0.001017694710753858" quat="0.9315263628959656 0.0 0.0 0.3636738061904907"/>
          <geom class="collision" type="box" pos="0.022968411445617676 0.03359932452440262 -0.19843542575836182" size="0.010534909553825855 0.015278312377631664 0.0010176937794312835" quat="0.9002500176429749 -0.23935586214065552 -0.09344607591629028 0.3514634370803833"/>
          <geom class="collision" type="box" pos="0.016572166234254837 0.029743239283561707 -0.19843542575836182" size="0.010534909553825855 0.015278312377631664 0.0010176937794312835" quat="0.9491258859634399 -0.25235074758529663 -0.04839891940355301 0.18203498423099518"/>
          <geom class="collision" type="box" pos="0.02511454187333584 0.008292559534311295 -0.1912476271390915" size="0.010534909553825855 0.010785062797367573 0.001017694710753858" quat="0.9821001887321472 0.0 0.0 0.18835927546024323"/>
          <geom class="collision" type="cylinder" pos="0.00924401544034481 0.04897775501012802 -0.19782409071922302" size="0.006529988721013069 0.007717803120613098" quat="1.0 0.0 0.0 0.0"/>
        </body>
        <body name="spout">
          <joint axis="0.0 0.0 1.0" pos="0.008679701946675777 0.19031986594200134 0.14020773768424988" limited="true" name="spout_joint" range="-0.7853981633974483 0.7853981633974483" type="hinge" damping="1" frictionloss="1" armature=".01" stiffness="0.05"/>
          <site type="cylinder" rgba="0.5 0.75 1 1" size="0.007279556710273027 0.18189847469329834" pos="0.00860593281686306 0.07199980318546295 -0.0347701758146286" name="water"/>
          <geom mesh="spout_vis" type="mesh" solimp="0.998 0.998 0.001" solref="0.001 1" density="100" friction="0.95 0.3 0.1" class="visual" material="spout_material"/>
          <geom class="collision" type="cylinder" pos="0.008839156478643417 0.1905600130558014 0.054274123162031174" size="0.015300664119422436 0.004239031113684177" quat="1.0 0.0 0.0 0.0"/>
          <geom class="collision" type="box" pos="0.00868565496057272 0.19022472202777863 0.1219596117734909" size="0.014188708737492561 0.00378295686095953 0.06361405551433563" quat="1.0 0.0 0.0 0.0"/>
          <geom class="collision" type="box" pos="0.00868565496057272 0.18784454464912415 0.1929425299167633" size="0.014188697561621666 0.003859864315018058 0.009694489650428295" quat="0.9901295304298401 0.14015524089336395 0.0 0.0"/>
          <geom class="collision" type="box" pos="0.00868565496057272 0.17919452488422394 0.20913836359977722" size="0.014188697561621666 0.003834041766822338 0.009684526361525059" quat="0.9466893672943115 0.3221478760242462 0.0 0.0"/>
          <geom class="collision" type="box" pos="0.00868565496057272 0.16576509177684784 0.2223837524652481" size="0.014188697561621666 0.0038910070434212685 0.009706424549221992" quat="0.8968712091445923 0.4422917664051056 0.0 0.0"/>
          <geom class="collision" type="box" pos="0.008685656823217869 0.14963063597679138 0.23115645349025726" size="0.014188701286911964 0.003931689541786909 0.009721888229250908" quat="0.8145753145217896 0.5800578594207764 0.0 0.0"/>
          <geom class="collision" type="box" pos="0.00868565496057272 0.13216862082481384 0.23423366248607635" size="0.014188704080879688 0.009692053310573101 0.0038535334169864655" quat="1.0 0.0 0.0 0.0"/>
          <geom class="collision" type="box" pos="0.00868565496057272 0.11398517340421677 0.23158344626426697" size="0.014188699424266815 0.003997397609055042 0.009746549651026726" quat="0.576590359210968 0.8170334100723267 0.0 0.0"/>
          <geom class="collision" type="box" pos="0.008685656823217869 0.0973299965262413 0.22383397817611694" size="0.014188701286911964 0.0038774432614445686 0.009701238945126534" quat="0.4736131727695465 0.8807329535484314 0.0 0.0"/>
          <geom class="collision" type="box" pos="0.008685656823217869 0.08439585566520691 0.2112576961517334" size="0.014188701286911964 0.004022641107439995 0.009755922481417656" quat="0.3026302456855774 0.9531080722808838 0.0 0.0"/>
          <geom class="collision" type="box" pos="0.008685656823217869 0.07527550309896469 0.1957060843706131" size="0.014188702218234539 0.003971736412495375 0.009736965410411358" quat="0.1847800761461258 0.9827799201011658 0.0 0.0"/>
          <geom class="collision" type="box" pos="0.00868565496057272 0.0718502402305603 0.17960229516029358" size="0.014188701286911964 0.0038539832457900047 0.009692225605249405" quat="0.004763779696077108 0.9999886751174927 0.0 0.0"/>
          <geom class="collision" type="cylinder" pos="0.008839156478643417 0.07221023738384247 0.15753813087940216" size="0.015300664119422436 0.01267433911561966" quat="1.0 0.0 0.0 0.0"/>
        </body>
        <geom class="region" name="reg_main" type="box" pos="0.0 0.0 -0.13636097311973572" size="0.3549557328224182 0.23226298391819 0.10134555399417877"/>
        <geom class="region" name="reg_basin" type="box" pos="0.12902585230767727 -0.022363431751728058 -0.11664702370762825" size="0.1910617295652628 0.17721300572156906 0.07586799189448357"/>
      </body>
    </body>
  </worldbody>
  <actuator>
    <motor name="handle_joint_hinge_0_actuator" joint="handle_joint_hinge_0" gear="10"/>
    <motor name="handle_joint_hinge_1_actuator" joint="handle_joint_hinge_1" gear="10"/>
    <motor name="Container001_joint_actuator" joint="Container001_joint" gear="20"/>
    <motor name="Funnel001_joint_actuator" joint="Funnel001_joint" gear="10"/>
    <motor name="spout_joint_actuator" joint="spout_joint" gear="10"/>
  </actuator>
</mujoco>
