<mujoco model="model">
  <compiler angle="radian"/>
  <asset>
    <mesh file="visuals/knob_front_left.obj" name="knob_front_left_vis"/>
    <mesh file="visuals/knob_front_right.obj" name="knob_front_right_vis"/>
    <mesh file="visuals/knob_rear_left.obj" name="knob_rear_left_vis"/>
    <mesh file="visuals/knob_rear_right.obj" name="knob_rear_right_vis"/>
    <mesh file="visuals/Body001.obj" name="Body001_vis"/>
    <mesh file="visuals/Door001.obj" name="Door001_vis"/>
    <mesh file="visuals/Knob001.obj" name="Knob001_vis"/>
    <mesh file="visuals/Knob002.obj" name="Knob002_vis"/>
    <mesh file="visuals/Shelf001.obj" name="Shelf001_vis"/>
    <texture file="visuals/T_BC001.png" name="Body001_material" type="2d"/>
    <material name="Body001_material" rgba="1 1 1 1.0" texture="Body001_material" shininess="0.2512328028678894" specular="1"/>
    <texture file="visuals/T_BC001.png" name="knob_front_left_material" type="2d"/>
    <material name="knob_front_left_material" rgba="1 1 1 1.0" texture="knob_front_left_material" shininess="0.2512328028678894" specular="0.3103448502657381"/>
    <texture file="visuals/T_BC001.png" name="knob_front_right_material" type="2d"/>
    <material name="knob_front_right_material" rgba="1 1 1 1.0" texture="knob_front_right_material" shininess="0.2512328028678894" specular="0.3103448502657381"/>
    <texture file="visuals/T_BC001.png" name="knob_rear_left_material" type="2d"/>
    <material name="knob_rear_left_material" rgba="1 1 1 1.0" texture="knob_rear_left_material" shininess="0.2512328028678894" specular="0.3103448502657381"/>
    <texture file="visuals/T_BC001.png" name="knob_rear_right_material" type="2d"/>
    <material name="knob_rear_right_material" rgba="1 1 1 1.0" texture="knob_rear_right_material" shininess="0.2512328028678894" specular="0.3103448502657381"/>
    <texture file="visuals/T_BC001.png" name="Door001_material" type="2d"/>
    <material name="Door001_material" rgba="1 1 1 1.0" texture="Door001_material" shininess="0.2512328028678894" specular="1"/>
    <texture file="visuals/T_BC001.png" name="Knob001_material" type="2d"/>
    <material name="Knob001_material" rgba="1 1 1 1.0" texture="Knob001_material" shininess="0.2512328028678894" specular="0.3103448502657381"/>
    <texture file="visuals/T_BC001.png" name="Knob002_material" type="2d"/>
    <material name="Knob002_material" rgba="1 1 1 1.0" texture="Knob002_material" shininess="0.2512328028678894" specular="0.3103448502657381"/>
    <texture file="visuals/T_BC001.png" name="Shelf001_material" type="2d"/>
    <material name="Shelf001_material" rgba="1 1 1 1.0" texture="Shelf001_material" shininess="0.2512328028678894" specular="4"/>
  </asset>
  <default>
    <default class="visual">
      <geom conaffinity="0" contype="0" group="1" type="mesh"/>
    </default>
    <default class="collision">
      <geom group="0" rgba="0.5 0 0 0.5"/>
    </default>
    <default class="spawn">
      <geom group="0" rgba="1 1 1 0.5" contype="0" conaffinity="0"/>
      <site group="0" rgba="1 1 1 0.5"/>
    </default>
    <default class="region">
      <geom group="1" conaffinity="0" contype="0" rgba="0 1 0 0"/>
    </default>
  </default>
  <worldbody>
    <body>
      <body name="object">
        <site type="cylinder" rgba="0 0 0.5 0.5" size="0.04812531918287277 0.010028138756752014" pos="-0.178004 -0.057165 0.410965" name="burner_on_front_left"/>
        <site type="cylinder" rgba="0 0 0.5 0.5" size="0.046495940536260605 0.010028138756752014" pos="0.176589 -0.056470 0.410965" name="burner_on_front_right"/>
        <site type="cylinder" rgba="0 0 0.5 0.5" size="0.04723677411675453 0.010028138756752014" pos="-0.177874 0.178780 0.410965" name="burner_on_rear_left"/>
        <site type="cylinder" rgba="0 0 0.5 0.5" size="0.04766416922211647 0.010028138756752014" pos="0.176894 0.177858 0.410965" name="burner_on_rear_right"/>
        <geom mesh="Body001_vis" type="mesh" solimp="0.998 0.998 0.001" solref="0.001 1" density="100" friction="0.95 0.3 0.1" class="visual" material="Body001_material"/>
        <geom class="collision" type="box" pos="-0.344712 0.055403 0.029861" size="0.0282307006418705 0.2836341857910156 0.28328806161880493" quat="1.0 0.0 0.0 0.0"/>
        <geom class="collision" type="box" pos="0.344729 0.055403 0.029861" size="0.028214074671268463 0.2836341857910156 0.28328806161880493" quat="1.0 0.0 0.0 0.0"/>
        <geom class="collision" type="box" pos="-0.000093 0.055403 -0.322132" size="0.3716641664505005 0.2836341857910156 0.12749764323234558" quat="1.0 0.0 0.0 0.0"/>
        <geom class="collision" type="box" pos="-0.000093 -0.248540 -0.343221" size="0.3716641664505005 0.020308177918195724 0.09009308367967606" quat="1.0 0.0 0.0 0.0"/>
        <geom class="collision" type="box" pos="-0.000093 0.055403 0.275238" size="0.3716641664505005 0.2836341857910156 0.04473291337490082" quat="1.0 0.0 0.0 0.0"/>
        <geom class="collision" type="box" pos="-0.000093 0.271959 0.023885" size="0.3716641664505005 0.06707804650068283 0.28845295310020447" quat="1.0 0.0 0.0 0.0"/>
        <geom class="collision" type="box" pos="0.324068 0.000308 0.017155" size="0.027589945122599602 0.17868469655513763 0.0013510260032489896" quat="1.0 0.0 0.0 0.0"/>
        <geom class="collision" type="box" pos="0.338999 0.000308 0.027265" size="0.027589945122599602 0.17868469655513763 0.011460619047284126" quat="1.0 0.0 0.0 0.0"/>
        <geom class="collision" type="box" pos="0.326508 0.000308 0.035906" size="0.027589945122599602 0.17868469655513763 0.003063765587285161" quat="1.0 0.0 0.0 0.0"/>
        <geom class="collision" type="box" pos="-0.326071 0.000308 0.017108" size="0.027589945122599602 0.17868469655513763 0.0013038265751674771" quat="1.0 0.0 0.0 0.0"/>
        <geom class="collision" type="box" pos="-0.338623 0.000308 0.027265" size="0.027589945122599602 0.17868469655513763 0.011460619047284126" quat="1.0 0.0 0.0 0.0"/>
        <geom class="collision" type="box" pos="-0.327272 0.000308 0.035906" size="0.027589945122599602 0.17868469655513763 0.003063765587285161" quat="1.0 0.0 0.0 0.0"/>
        <geom class="collision" type="box" pos="-0.000686 0.035095 0.367863" size="0.37225690484046936 0.30394235253334045 0.054325878620147705" quat="1.0 0.0 0.0 0.0"/>
        <geom class="collision" type="box" pos="0.000867 0.058540 0.384781" size="0.31158381700515747 0.26489758491516113 0.05621837079524994" quat="1.0 0.0 0.0 0.0"/>
        <geom class="collision" type="box" pos="-0.000093 0.331248 0.384280" size="0.37166422605514526 0.007788435555994511 0.06534989923238754" quat="1.0 0.0 0.0 0.0"/>
        <geom class="collision" type="box" pos="-0.000093 -0.280634 0.406334" size="0.37166422605514526 0.016079125925898552 0.01576913148164749" quat="1.0 0.0 0.0 0.0"/>
        <body name="knob_front_left">
          <joint axis="0.0 -1.0 0.0" pos="-0.300729 -0.280023 0.346802" limited="true" name="knob_front_left_joint" range="0.0 3.141592653589793" type="hinge" damping="0.05" armature="0.001"/>
          <geom mesh="knob_front_left_vis" type="mesh" solimp="0.998 0.998 0.001" solref="0.001 1" density="100" friction="0.95 0.3 0.1" class="visual" material="knob_front_left_material"/>
          <geom class="collision" type="cylinder" pos="-0.300574 -0.276293 0.346971" size="0.022574562579393387 0.006452969275414944" quat="0.7071068286895752 0.7071067690849304 0.0 0.0"/>
          <geom class="collision" type="box" pos="-0.300762 -0.289865 0.347015" size="0.005231413524597883 0.008577979169785976 0.015703316777944565" quat="1.0 0.0 0.0 0.0"/>
        </body>
        <body name="knob_front_right">
          <joint axis="0.0 -1.0 0.0" pos="0.292480 -0.280023 0.346802" limited="true" name="knob_front_right_joint" range="0.0 3.141592653589793" type="hinge" damping="0.05" armature="0.001"/>
          <geom mesh="knob_front_right_vis" type="mesh" solimp="0.998 0.998 0.001" solref="0.001 1" density="100" friction="0.95 0.3 0.1" class="visual" material="knob_front_right_material"/>
          <geom class="collision" type="cylinder" pos="0.292781 -0.276293 0.346971" size="0.022574562579393387 0.006452969275414944" quat="0.7071068286895752 0.7071067690849304 0.0 0.0"/>
          <geom class="collision" type="box" pos="0.292592 -0.289865 0.347015" size="0.005231413524597883 0.008577979169785976 0.015703316777944565" quat="1.0 0.0 0.0 0.0"/>
        </body>
        <body name="knob_rear_left">
          <joint axis="0.0 -1.0 0.0" pos="-0.197157 -0.280023 0.346802" limited="true" name="knob_rear_left_joint" range="0.0 3.141592653589793" type="hinge" damping="0.05" armature="0.001"/>
          <geom mesh="knob_rear_left_vis" type="mesh" solimp="0.998 0.998 0.001" solref="0.001 1" density="100" friction="0.95 0.3 0.1" class="visual" material="knob_rear_left_material"/>
          <geom class="collision" type="cylinder" pos="-0.197213 -0.276293 0.346971" size="0.022574562579393387 0.006452969275414944" quat="0.7071068286895752 0.7071067690849304 0.0 0.0"/>
          <geom class="collision" type="box" pos="-0.197401 -0.289865 0.347015" size="0.005231413524597883 0.008577979169785976 0.015703316777944565" quat="1.0 0.0 0.0 0.0"/>
        </body>
        <body name="knob_rear_right">
          <joint axis="0.0 -1.0 0.0" pos="0.188515 -0.280023 0.346802" limited="true" name="knob_rear_right_joint" range="0.0 3.141592653589793" type="hinge" damping="0.05" armature="0.001"/>
          <geom mesh="knob_rear_right_vis" type="mesh" solimp="0.998 0.998 0.001" solref="0.001 1" density="100" friction="0.95 0.3 0.1" class="visual" material="knob_rear_right_material"/>
          <geom class="collision" type="cylinder" pos="0.188633 -0.276293 0.346971" size="0.022574562579393387 0.006452969275414944" quat="0.7071068286895752 0.7071067690849304 0.0 0.0"/>
          <geom class="collision" type="box" pos="0.188444 -0.289865 0.347015" size="0.005231413524597883 0.008577979169785976 0.015703316777944565" quat="1.0 0.0 0.0 0.0"/>
        </body>
        <body name="Door001">
          <joint axis="1.0 0.0 0.0" pos="0.000040 -0.268848 -0.245813" limited="true" name="Door001_joint" range="0.0 1.5707963267948966" type="hinge" damping="1" frictionloss="1" armature=".01" stiffness="0.05"/>
          <geom mesh="Door001_vis" type="mesh" solimp="0.998 0.998 0.001" solref="0.001 1" density="100" friction="0.95 0.3 0.1" class="visual" material="Door001_material"/>
          <geom class="collision" type="box" pos="-0.000093 -0.256913 0.032702" size="0.3716639578342438 0.011934775859117508 0.2578789293766022" quat="1.0 0.0 0.0 0.0"/>
          <geom class="collision" type="cylinder" pos="-0.000094 -0.320057 0.260349" size="0.01962883584201336 0.29335910081863403" quat="0.4999999701976776 0.5 0.5 0.5"/>
          <geom class="collision" type="box" pos="0.276519 -0.292564 0.260195" size="0.016746893525123596 0.02831774391233921 0.019988402724266052" quat="1.0 0.0 0.0 0.0"/>
          <geom class="collision" type="box" pos="-0.277017 -0.292564 0.260195" size="0.016746893525123596 0.02831774391233921 0.019988402724266052" quat="1.0 0.0 0.0 0.0"/>
        </body>
        <body name="Knob001">
          <joint axis="0.0 1.0 0.0" pos="-0.046474 -0.280023 0.346802" limited="true" name="Knob001_joint" range="0.0 4.014257279586958" type="hinge" damping="0.05" armature="0.001"/>
          <geom mesh="Knob001_vis" type="mesh" solimp="0.998 0.998 0.001" solref="0.001 1" density="100" friction="0.95 0.3 0.1" class="visual" material="Knob001_material"/>
          <geom class="collision" type="cylinder" pos="-0.046517 -0.276293 0.346971" size="0.022574562579393387 0.006452969275414944" quat="0.7071068286895752 0.7071067690849304 0.0 0.0"/>
          <geom class="collision" type="box" pos="-0.046705 -0.289865 0.347015" size="0.005231413524597883 0.008577979169785976 0.015703316777944565" quat="1.0 0.0 0.0 0.0"/>
        </body>
        <body name="Knob002">
          <joint axis="0.0 1.0 0.0" pos="0.057092 -0.280023 0.347096" limited="true" name="Knob002_joint" range="0.0 3.2288591161895095" type="hinge" damping="0.05" armature="0.001"/>
          <geom mesh="Knob002_vis" type="mesh" solimp="0.998 0.998 0.001" solref="0.001 1" density="100" friction="0.95 0.3 0.1" class="visual" material="Knob002_material"/>
          <geom class="collision" type="cylinder" pos="0.057083 -0.276293 0.346971" size="0.022574562579393387 0.006452969275414944" quat="0.7071068286895752 0.7071067690849304 0.0 0.0"/>
          <geom class="collision" type="box" pos="0.056638 -0.289865 0.347015" size="0.015703316777944565 0.008577979169785976 0.005231414455920458" quat="1.0 0.0 0.0 0.0"/>
        </body>
        <body name="Shelf001">
          <joint axis="0.0 -1.0 0.0" pos="-0.001452 0.000116 0.028709" limited="true" name="Shelf001_joint" range="0.0 0.25" type="slide" damping="1" frictionloss="1" armature=".01" stiffness="0.05"/>
          <geom mesh="Shelf001_vis" type="mesh" solimp="0.998 0.998 0.001" solref="0.001 1" density="100" friction="0.95 0.3 0.1" class="visual" material="Shelf001_material"/>
          <geom class="collision" type="box" pos="0.001280 0.000636 0.030935" size="0.2908157706260681 0.19227856397628784 0.0032185327727347612" quat="1.0 0.0 0.0 0.0"/>
          <geom class="collision" type="box" pos="0.298178 0.000636 0.028053" size="0.012118300423026085 0.19227856397628784 0.0032185327727347612" quat="0.9565491080284119 0.0 0.2915712893009186 0.0"/>
          <geom class="collision" type="box" pos="-0.296653 0.000636 0.028053" size="0.012118300423026085 0.19227856397628784 0.0032185327727347612" quat="0.9565491080284119 0.0 -0.2915712893009186 0.0"/>
        </body>
        <geom class="region" name="reg_main" type="box" pos="-9.300000000000974e-05 0.03372549999999999 -0.013720499999999997" size="0.371664 0.3025725 0.43590949999999995"/>
        <geom class="region" name="reg_int" type="box" pos="0.0006510000000000127 -0.011026500000000009 0.0185805" size="0.314164 0.21286850000000002 0.2112145"/>
      </body>
    </body>
  </worldbody>
  <actuator>
    <motor name="knob_front_left_joint_actuator" joint="knob_front_left_joint" gear="10"/>
    <motor name="knob_front_right_joint_actuator" joint="knob_front_right_joint" gear="10"/>
    <motor name="knob_rear_left_joint_actuator" joint="knob_rear_left_joint" gear="10"/>
    <motor name="knob_rear_right_joint_actuator" joint="knob_rear_right_joint" gear="10"/>
    <motor name="Door001_joint_actuator" joint="Door001_joint" gear="50"/>
    <motor name="Knob001_joint_actuator" joint="Knob001_joint" gear="50"/>
    <motor name="Knob002_joint_actuator" joint="Knob002_joint" gear="50"/>
    <motor name="Shelf001_joint_actuator" joint="Shelf001_joint" gear="50"/>
  </actuator>
</mujoco>
