<mujoco model="model">
  <compiler angle="radian"/>
  <asset>
    <mesh file="visuals/knob_center.obj" name="knob_center_vis"/>
    <mesh file="visuals/knob_front_left.obj" name="knob_front_left_vis"/>
    <mesh file="visuals/knob_front_right.obj" name="knob_front_right_vis"/>
    <mesh file="visuals/knob_rear_left.obj" name="knob_rear_left_vis"/>
    <mesh file="visuals/knob_rear_right.obj" name="knob_rear_right_vis"/>
    <mesh file="visuals/Body001.obj" name="Body001_vis"/>
    <texture file="visuals/T_BC001.png" name="Body001_material" type="2d"/>
    <material name="Body001_material" rgba="1 1 1 1.0" texture="Body001_material" shininess="1" specular="1"/>
    <texture file="visuals/T_BC001.png" name="knob_center_material" type="2d"/>
    <material name="knob_center_material" rgba="1 1 1 1.0" texture="knob_center_material" shininess="1" specular="1"/>
    <texture file="visuals/T_BC001.png" name="knob_front_left_material" type="2d"/>
    <material name="knob_front_left_material" rgba="1 1 1 1.0" texture="knob_front_left_material" shininess="1" specular="1"/>
    <texture file="visuals/T_BC001.png" name="knob_front_right_material" type="2d"/>
    <material name="knob_front_right_material" rgba="1 1 1 1.0" texture="knob_front_right_material" shininess="1" specular="1"/>
    <texture file="visuals/T_BC001.png" name="knob_rear_left_material" type="2d"/>
    <material name="knob_rear_left_material" rgba="1 1 1 1.0" texture="knob_rear_left_material" shininess="1" specular="1"/>
    <texture file="visuals/T_BC001.png" name="knob_rear_right_material" type="2d"/>
    <material name="knob_rear_right_material" rgba="1 1 1 1.0" texture="knob_rear_right_material" shininess="1" specular="1"/>
  </asset>
  <default>
    <default class="visual">
      <geom conaffinity="0" contype="0" group="1" type="mesh"/>
    </default>
    <default class="collision">
      <geom group="0" rgba="0.5 0 0 0.5"/>
    </default>
    <default class="spawn">
      <geom group="0" rgba="1 1 1 0.5" contype="0" conaffinity="0"/>
      <site group="0" rgba="1 1 1 0.5"/>
    </default>
    <default class="region">
      <geom group="1" conaffinity="0" contype="0" rgba="0 1 0 0"/>
    </default>
  </default>
  <worldbody>
    <body>
      <body name="object">
        <site type="cylinder" rgba="0 0 0.5 0.5" size="0.07163179665803909 0.012021086178719997" pos="-0.000500 0.026909 0.000581" name="burner_on_center"/>
        <site type="cylinder" rgba="0 0 0.5 0.5" size="0.04395541921257973 0.011470425873994827" pos="-0.249242 0.140268 0.000369" name="burner_on_rear_left"/>
        <site type="cylinder" rgba="0 0 0.5 0.5" size="0.03147285059094429 0.009436560794711113" pos="-0.249480 -0.084980 -0.000209" name="burner_on_front_left"/>
        <site type="cylinder" rgba="0 0 0.5 0.5" size="0.057683106511831284 0.013158903457224369" pos="0.251079 0.140268 0.002117" name="burner_on_rear_right"/>
        <site type="cylinder" rgba="0 0 0.5 0.5" size="0.043417107313871384 0.010837151668965816" pos="0.251079 -0.083942 0.000692" name="burner_on_front_right"/>
        <geom mesh="Body001_vis" type="mesh" solimp="0.998 0.998 0.001" solref="0.001 1" density="100" friction="0.95 0.3 0.1" class="visual" material="Body001_material"/>
        <geom class="collision" type="box" pos="0.000000 0.000000 -0.017165" size="0.41957125067710876 0.2771269381046295 0.0062769027426838875" quat="1.0 0.0 0.0 0.0"/>
        <geom class="collision" type="box" pos="0.341116 -0.085365 -0.007253" size="0.009511222131550312 0.10162844508886337 0.0033623131457716227" quat="1.0 0.0 0.0 0.0"/>
        <geom class="collision" type="box" pos="0.250879 -0.177665 -0.007526" size="0.07949207723140717 0.009285039268434048 0.003089210484176874" quat="1.0 0.0 0.0 0.0"/>
        <geom class="collision" type="box" pos="0.346456 -0.020978 0.006071" size="0.013077699579298496 0.004667441826313734 0.017371144145727158" quat="1.0 0.0 0.0 0.0"/>
        <geom class="collision" type="box" pos="0.325860 -0.020978 0.021038" size="0.006929134018719196 0.004667441826313734 0.0024048304185271263" quat="1.0 0.0 0.0 0.0"/>
        <geom class="collision" type="box" pos="0.313153 -0.084722 0.021038" size="0.019432958215475082 0.004667441826313734 0.0024048304185271263" quat="1.0 0.0 0.0 0.0"/>
        <geom class="collision" type="box" pos="0.348698 -0.084722 0.006133" size="0.015538685023784637 0.004667441826313734 0.01730971224606037" quat="1.0 0.0 0.0 0.0"/>
        <geom class="collision" type="box" pos="0.325934 -0.152036 0.021038" size="0.006929134018719196 0.004667441826313734 0.0024048304185271263" quat="1.0 0.0 0.0 0.0"/>
        <geom class="collision" type="box" pos="0.346456 -0.152036 0.006071" size="0.013077699579298496 0.004667441826313734 0.017371144145727158" quat="1.0 0.0 0.0 0.0"/>
        <geom class="collision" type="box" pos="0.252563 -0.179534 0.006133" size="0.012259948067367077 0.004667441826313734 0.01730971224606037" quat="0.7071068286895752 0.0 -0.0 -0.7071067690849304"/>
        <geom class="collision" type="box" pos="0.252563 -0.147633 0.021038" size="0.019432958215475082 0.004667441826313734 0.0024048304185271263" quat="0.7071068286895752 0.0 -0.0 -0.7071067690849304"/>
        <geom class="collision" type="box" pos="0.252733 -0.024308 0.021038" size="0.019432958215475082 0.004667441826313734 0.0024048304185271263" quat="0.7071068286895752 0.0 0.0 0.7071067690849304"/>
        <geom class="collision" type="box" pos="0.252733 0.007593 0.006133" size="0.012259948067367077 0.004667441826313734 0.01730971224606037" quat="0.7071068286895752 0.0 0.0 0.7071067690849304"/>
        <geom class="collision" type="box" pos="0.250879 0.005963 -0.007526" size="0.07949207723140717 0.009285039268434048 0.003089210484176874" quat="1.0 0.0 0.0 0.0"/>
        <geom class="collision" type="box" pos="0.156351 -0.151810 0.006071" size="0.013077699579298496 0.004667441826313734 0.017371144145727158" quat="1.0 0.0 0.0 0.0"/>
        <geom class="collision" type="box" pos="0.177014 -0.151810 0.021038" size="0.006929134018719196 0.004667441826313734 0.0024048304185271263" quat="1.0 0.0 0.0 0.0"/>
        <geom class="collision" type="box" pos="0.153905 -0.084600 0.006133" size="0.015538685023784637 0.004667441826313734 0.01730971224606037" quat="1.0 0.0 0.0 0.0"/>
        <geom class="collision" type="box" pos="0.189518 -0.084600 0.021038" size="0.019432958215475082 0.004667441826313734 0.0024048304185271263" quat="1.0 0.0 0.0 0.0"/>
        <geom class="collision" type="box" pos="0.177014 -0.020856 0.021038" size="0.006929134018719196 0.004667441826313734 0.0024048304185271263" quat="1.0 0.0 0.0 0.0"/>
        <geom class="collision" type="box" pos="0.155829 -0.020856 0.006071" size="0.013077699579298496 0.004667441826313734 0.017371144145727158" quat="1.0 0.0 0.0 0.0"/>
        <geom class="collision" type="box" pos="0.160117 -0.085365 -0.007253" size="0.009511222131550312 0.10162844508886337 0.0033623131457716227" quat="1.0 0.0 0.0 0.0"/>
        <geom class="collision" type="cylinder" pos="0.251711 -0.083888 0.000054" size="0.041390273720026016 0.011315751820802689" quat="1.0 0.0 0.0 0.0"/>
        <geom class="collision" type="box" pos="-0.341840 -0.085365 -0.007253" size="0.009511222131550312 0.10162844508886337 0.0033623131457716227" quat="1.0 0.0 0.0 0.0"/>
        <geom class="collision" type="box" pos="-0.345731 -0.020575 0.006071" size="0.013077699579298496 0.004667441826313734 0.017371144145727158" quat="1.0 0.0 0.0 0.0"/>
        <geom class="collision" type="box" pos="-0.325311 -0.020575 0.021038" size="0.006929134018719196 0.004667441826313734 0.0024048304185271263" quat="1.0 0.0 0.0 0.0"/>
        <geom class="collision" type="box" pos="-0.312438 -0.084541 0.021038" size="0.019432958215475082 0.004667441826313734 0.0024048304185271263" quat="1.0 0.0 0.0 0.0"/>
        <geom class="collision" type="box" pos="-0.347823 -0.084541 0.006133" size="0.015538685023784637 0.004667441826313734 0.01730971224606037" quat="1.0 0.0 0.0 0.0"/>
        <geom class="collision" type="box" pos="-0.325608 -0.151583 0.021038" size="0.006929134018719196 0.004667441826313734 0.0024048304185271263" quat="1.0 0.0 0.0 0.0"/>
        <geom class="collision" type="box" pos="-0.346028 -0.151583 0.006071" size="0.013077699579298496 0.004667441826313734 0.017371144145727158" quat="1.0 0.0 0.0 0.0"/>
        <geom class="collision" type="box" pos="-0.251077 0.006105 -0.007526" size="0.07949207723140717 0.009285039268434048 0.003089210484176874" quat="1.0 0.0 0.0 0.0"/>
        <geom class="collision" type="box" pos="-0.155729 -0.151824 0.006071" size="0.013077699579298496 0.004667441826313734 0.017371144145727158" quat="1.0 0.0 0.0 0.0"/>
        <geom class="collision" type="box" pos="-0.175944 -0.151824 0.021038" size="0.006929134018719196 0.004667441826313734 0.0024048304185271263" quat="1.0 0.0 0.0 0.0"/>
        <geom class="collision" type="box" pos="-0.249105 0.007975 0.006133" size="0.012259948067367077 0.004667441826313734 0.01730971224606037" quat="0.7071068286895752 0.0 0.0 0.7071067690849304"/>
        <geom class="collision" type="box" pos="-0.249105 -0.023926 0.021038" size="0.019432958215475082 0.004667441826313734 0.0024048304185271263" quat="0.7071068286895752 0.0 0.0 0.7071067690849304"/>
        <geom class="collision" type="box" pos="-0.153268 -0.084510 0.006133" size="0.015538685023784637 0.004667441826313734 0.01730971224606037" quat="1.0 0.0 0.0 0.0"/>
        <geom class="collision" type="box" pos="-0.188448 -0.084510 0.021038" size="0.019432958215475082 0.004667441826313734 0.0024048304185271263" quat="1.0 0.0 0.0 0.0"/>
        <geom class="collision" type="box" pos="-0.175944 -0.020765 0.021038" size="0.006929134018719196 0.004667441826313734 0.0024048304185271263" quat="1.0 0.0 0.0 0.0"/>
        <geom class="collision" type="box" pos="-0.155729 -0.020765 0.006071" size="0.013077699579298496 0.004667441826313734 0.017371144145727158" quat="1.0 0.0 0.0 0.0"/>
        <geom class="collision" type="box" pos="-0.249224 -0.147493 0.021038" size="0.019432958215475082 0.004667441826313734 0.0024048304185271263" quat="0.7071068286895752 0.0 -0.0 -0.7071067690849304"/>
        <geom class="collision" type="box" pos="-0.249224 -0.179394 0.006133" size="0.012259948067367077 0.004667441826313734 0.01730971224606037" quat="0.7071068286895752 0.0 -0.0 -0.7071067690849304"/>
        <geom class="collision" type="box" pos="-0.251077 -0.177524 -0.007526" size="0.07949207723140717 0.009285039268434048 0.003089210484176874" quat="1.0 0.0 0.0 0.0"/>
        <geom class="collision" type="box" pos="-0.160841 -0.085365 -0.007253" size="0.009511222131550312 0.10162844508886337 0.0033623131457716227" quat="1.0 0.0 0.0 0.0"/>
        <geom class="collision" type="cylinder" pos="-0.249560 -0.084917 0.000398" size="0.03028465434908867 0.008279569447040558" quat="1.0 0.0 0.0 0.0"/>
        <geom class="collision" type="cylinder" pos="0.251711 0.139414 0.001618" size="0.053853049874305725 0.01332746259868145" quat="1.0 0.0 0.0 0.0"/>
        <geom class="collision" type="cylinder" pos="-0.000222 0.026613 0.000371" size="0.06814379245042801 0.01148492656648159" quat="1.0 0.0 0.0 0.0"/>
        <geom class="collision" type="cylinder" pos="-0.249665 0.140247 0.000054" size="0.041390273720026016 0.011315751820802689" quat="1.0 0.0 0.0 0.0"/>
        <geom class="collision" type="box" pos="0.159434 0.139458 -0.007253" size="0.009511222131550312 0.10162844508886337 0.0033623131457716227" quat="1.0 0.0 0.0 0.0"/>
        <geom class="collision" type="box" pos="0.155146 0.203967 0.006071" size="0.013077699579298496 0.004667441826313734 0.017371144145727158" quat="1.0 0.0 0.0 0.0"/>
        <geom class="collision" type="box" pos="0.176331 0.203967 0.021038" size="0.006929134018719196 0.004667441826313734 0.0024048304185271263" quat="1.0 0.0 0.0 0.0"/>
        <geom class="collision" type="box" pos="0.188835 0.140223 0.021038" size="0.019432958215475082 0.004667441826313734 0.0024048304185271263" quat="1.0 0.0 0.0 0.0"/>
        <geom class="collision" type="box" pos="0.153294 0.140223 0.006133" size="0.015772372484207153 0.004667441826313734 0.01730971224606037" quat="1.0 0.0 0.0 0.0"/>
        <geom class="collision" type="box" pos="0.176331 0.072909 0.021038" size="0.006929134018719196 0.004667441826313734 0.0024048304185271263" quat="1.0 0.0 0.0 0.0"/>
        <geom class="collision" type="box" pos="0.155146 0.072909 0.006071" size="0.013077699579298496 0.004667441826313734 0.017371144145727158" quat="1.0 0.0 0.0 0.0"/>
        <geom class="collision" type="box" pos="0.250196 0.230493 -0.007526" size="0.07949207723140717 0.009285039268434048 0.003089210484176874" quat="1.0 0.0 0.0 0.0"/>
        <geom class="collision" type="box" pos="0.345773 0.072734 0.006071" size="0.013077699579298496 0.004667441826313734 0.017371144145727158" quat="1.0 0.0 0.0 0.0"/>
        <geom class="collision" type="box" pos="0.325339 0.072734 0.021038" size="0.006929134018719196 0.004667441826313734 0.0024048304185271263" quat="1.0 0.0 0.0 0.0"/>
        <geom class="collision" type="box" pos="0.252238 0.232363 0.006133" size="0.012259948067367077 0.004667441826313734 0.01730971224606037" quat="0.7071068286895752 0.0 0.0 0.7071067690849304"/>
        <geom class="collision" type="box" pos="0.252238 0.200462 0.021038" size="0.019432958215475082 0.004667441826313734 0.0024048304185271263" quat="0.7071068286895752 0.0 0.0 0.7071067690849304"/>
        <geom class="collision" type="box" pos="0.348015 0.140048 0.006133" size="0.015538685023784637 0.004667441826313734 0.01730971224606037" quat="1.0 0.0 0.0 0.0"/>
        <geom class="collision" type="box" pos="0.312835 0.140048 0.021038" size="0.019432958215475082 0.004667441826313734 0.0024048304185271263" quat="1.0 0.0 0.0 0.0"/>
        <geom class="collision" type="box" pos="0.325339 0.203793 0.021038" size="0.006929134018719196 0.004667441826313734 0.0024048304185271263" quat="1.0 0.0 0.0 0.0"/>
        <geom class="collision" type="box" pos="0.345773 0.203793 0.006071" size="0.013077699579298496 0.004667441826313734 0.017371144145727158" quat="1.0 0.0 0.0 0.0"/>
        <geom class="collision" type="box" pos="0.251831 0.077042 0.021038" size="0.019432958215475082 0.004667441826313734 0.0024048304185271263" quat="0.7071068286895752 0.0 -0.0 -0.7071067690849304"/>
        <geom class="collision" type="box" pos="0.251831 0.045141 0.006133" size="0.012259948067367077 0.004667441826313734 0.01730971224606037" quat="0.7071068286895752 0.0 -0.0 -0.7071067690849304"/>
        <geom class="collision" type="box" pos="0.250196 0.047011 -0.007526" size="0.07949207723140717 0.009285039268434048 0.003089210484176874" quat="1.0 0.0 0.0 0.0"/>
        <geom class="collision" type="box" pos="0.340433 0.139458 -0.007253" size="0.009511222131550312 0.10162844508886337 0.0033623131457716227" quat="1.0 0.0 0.0 0.0"/>
        <geom class="collision" type="box" pos="-0.160870 0.140138 -0.007253" size="0.009511222131550312 0.10162844508886337 0.0033623131457716227" quat="1.0 0.0 0.0 0.0"/>
        <geom class="collision" type="box" pos="-0.251106 0.048093 -0.007526" size="0.07949207723140717 0.009285039268434048 0.003089210484176874" quat="1.0 0.0 0.0 0.0"/>
        <geom class="collision" type="box" pos="-0.249253 0.046515 0.006133" size="0.012259948067367077 0.004667441826313734 0.01730971224606037" quat="0.7071068286895752 0.0 -0.0 -0.7071067690849304"/>
        <geom class="collision" type="box" pos="-0.249253 0.078416 0.021038" size="0.019432958215475082 0.004667441826313734 0.0024048304185271263" quat="0.7071068286895752 0.0 -0.0 -0.7071067690849304"/>
        <geom class="collision" type="box" pos="-0.155898 0.205230 0.006071" size="0.013077699579298496 0.004667441826313734 0.017371144145727158" quat="1.0 0.0 0.0 0.0"/>
        <geom class="collision" type="box" pos="-0.176113 0.205230 0.021038" size="0.006929134018719196 0.004667441826313734 0.0024048304185271263" quat="1.0 0.0 0.0 0.0"/>
        <geom class="collision" type="box" pos="-0.188370 0.140994 0.021038" size="0.019432958215475082 0.004667441826313734 0.0024048304185271263" quat="1.0 0.0 0.0 0.0"/>
        <geom class="collision" type="box" pos="-0.153191 0.140994 0.006133" size="0.015538685023784637 0.004667441826313734 0.01730971224606037" quat="1.0 0.0 0.0 0.0"/>
        <geom class="collision" type="box" pos="-0.249073 0.201890 0.021038" size="0.019432958215475082 0.004667441826313734 0.0024048304185271263" quat="0.7071068286895752 0.0 0.0 0.7071067690849304"/>
        <geom class="collision" type="box" pos="-0.249073 0.233790 0.006133" size="0.012259948067367077 0.004667441826313734 0.01730971224606037" quat="0.7071068286895752 0.0 0.0 0.7071067690849304"/>
        <geom class="collision" type="box" pos="-0.175973 0.073680 0.021038" size="0.006929134018719196 0.004667441826313734 0.0024048304185271263" quat="1.0 0.0 0.0 0.0"/>
        <geom class="collision" type="box" pos="-0.155758 0.073680 0.006071" size="0.013077699579298496 0.004667441826313734 0.017371144145727158" quat="1.0 0.0 0.0 0.0"/>
        <geom class="collision" type="box" pos="-0.251357 0.231876 -0.007526" size="0.07949207723140717 0.009285039268434048 0.003089210484176874" quat="1.0 0.0 0.0 0.0"/>
        <geom class="collision" type="box" pos="-0.345642 0.074380 0.006071" size="0.013077699579298496 0.004667441826313734 0.017371144145727158" quat="1.0 0.0 0.0 0.0"/>
        <geom class="collision" type="box" pos="-0.325222 0.074380 0.021038" size="0.006929134018719196 0.004667441826313734 0.0024048304185271263" quat="1.0 0.0 0.0 0.0"/>
        <geom class="collision" type="box" pos="-0.348045 0.141245 0.006133" size="0.015538685023784637 0.004667441826313734 0.01730971224606037" quat="1.0 0.0 0.0 0.0"/>
        <geom class="collision" type="box" pos="-0.312606 0.141245 0.021038" size="0.019432958215475082 0.004667441826313734 0.0024048304185271263" quat="1.0 0.0 0.0 0.0"/>
        <geom class="collision" type="box" pos="-0.325222 0.205125 0.021038" size="0.006929134018719196 0.004667441826313734 0.0024048304185271263" quat="1.0 0.0 0.0 0.0"/>
        <geom class="collision" type="box" pos="-0.345642 0.205125 0.006071" size="0.013077699579298496 0.004667441826313734 0.017371144145727158" quat="1.0 0.0 0.0 0.0"/>
        <geom class="collision" type="box" pos="-0.341869 0.140138 -0.007253" size="0.009511222131550312 0.10162844508886337 0.0033623131457716227" quat="1.0 0.0 0.0 0.0"/>
        <geom class="collision" type="box" pos="-0.000211 0.199420 -0.007875" size="0.10723117738962173 0.008934126235544682 0.00274004228413105" quat="1.0 0.0 0.0 0.0"/>
        <geom class="collision" type="box" pos="-0.000213 0.202808 0.005947" size="0.012259948067367077 0.0036702656652778387 0.017123673111200333" quat="0.7071068286895752 0.0 0.0 0.7071067690849304"/>
        <geom class="collision" type="box" pos="-0.000213 0.147494 0.020852" size="0.042845793068408966 0.003670267527922988 0.0022187919821590185" quat="0.7071068286895752 0.0 0.0 0.7071067690849304"/>
        <geom class="collision" type="box" pos="-0.000213 -0.092760 0.020852" size="0.042845793068408966 0.003670267527922988 0.0022187919821590185" quat="0.7071068286895752 0.0 -0.0 -0.7071067690849304"/>
        <geom class="collision" type="box" pos="-0.000610 -0.148678 0.005947" size="0.012259948067367077 0.0036702656652778387 0.017123673111200333" quat="0.7071068286895752 0.0 -0.0 -0.7071067690849304"/>
        <geom class="collision" type="box" pos="-0.000211 -0.146563 -0.007875" size="0.10723117738962173 0.008934126235544682 0.00274004228413105" quat="1.0 0.0 0.0 0.0"/>
        <geom class="collision" type="box" pos="0.082055 0.027318 0.021038" size="0.00679558701813221 0.004085940774530172 0.0024048304185271263" quat="1.0 0.0 0.0 0.0"/>
        <geom class="collision" type="box" pos="0.104268 0.027450 0.006071" size="0.015342408791184425 0.0044255792163312435 0.017371144145727158" quat="1.0 0.0 0.0 0.0"/>
        <geom class="collision" type="box" pos="0.098187 0.026608 -0.008129" size="0.009199237450957298 0.1635657101869583 0.0024864692240953445" quat="1.0 0.0 0.0 0.0"/>
        <geom class="collision" type="box" pos="0.101676 0.140338 0.006071" size="0.012750166468322277 0.0044255792163312435 0.017371144145727158" quat="1.0 0.0 0.0 0.0"/>
        <geom class="collision" type="box" pos="0.082055 0.140205 0.021038" size="0.00679558701813221 0.004085940774530172 0.0024048304185271263" quat="1.0 0.0 0.0 0.0"/>
        <geom class="collision" type="box" pos="0.082055 -0.085707 0.021038" size="0.00679558701813221 0.004085940774530172 0.0024048304185271263" quat="1.0 0.0 0.0 0.0"/>
        <geom class="collision" type="box" pos="0.101166 -0.085574 0.006071" size="0.012239904142916203 0.0044255792163312435 0.017371144145727158" quat="1.0 0.0 0.0 0.0"/>
        <geom class="collision" type="box" pos="-0.102092 -0.085746 0.006071" size="0.012298681773245335 0.0044255792163312435 0.017371144145727158" quat="1.0 0.0 0.0 0.0"/>
        <geom class="collision" type="box" pos="-0.082995 -0.085878 0.021038" size="0.00679558701813221 0.004085940774530172 0.0024048304185271263" quat="1.0 0.0 0.0 0.0"/>
        <geom class="collision" type="box" pos="-0.082995 0.140205 0.021038" size="0.00679558701813221 0.004085940774530172 0.0024048304185271263" quat="1.0 0.0 0.0 0.0"/>
        <geom class="collision" type="box" pos="-0.103123 0.140338 0.006071" size="0.0133298859000206 0.0044255792163312435 0.017371144145727158" quat="1.0 0.0 0.0 0.0"/>
        <geom class="collision" type="box" pos="-0.099426 0.026608 -0.008129" size="0.009199237450957298 0.1635657101869583 0.0024864692240953445" quat="1.0 0.0 0.0 0.0"/>
        <geom class="collision" type="box" pos="-0.105486 0.027362 0.006071" size="0.015184118412435055 0.0044255792163312435 0.017371144145727158" quat="1.0 0.0 0.0 0.0"/>
        <geom class="collision" type="box" pos="-0.083503 0.027230 0.021038" size="0.00679558701813221 0.004085940774530172 0.0024048304185271263" quat="1.0 0.0 0.0 0.0"/>
        <body name="knob_center">
          <joint axis="0.0 0.0 1.0" pos="0.007819 -0.242079 -0.000013" limited="true" name="knob_center_joint" range="0.0 3.6651914291880923" type="hinge" damping="0.05" armature="0.001" springref="-0.1"/>
          <geom mesh="knob_center_vis" type="mesh" solimp="0.998 0.998 0.001" solref="0.001 1" density="100" friction="0.95 0.3 0.1" class="visual" material="knob_center_material"/>
          <geom class="collision" type="box" pos="0.007822 -0.220470 -0.001043" size="0.0017808674601837993 0.0031232626643031836 0.007129808887839317" quat="1.0 0.0 0.0 0.0"/>
          <geom class="collision" type="cylinder" pos="0.007888 -0.242129 -0.000388" size="0.01965462788939476 0.009692679159343243" quat="1.0 0.0 0.0 0.0"/>
        </body>
        <body name="knob_front_left">
          <joint axis="0.0 0.0 1.0" pos="-0.171487 -0.242079 -0.000013" limited="true" name="knob_front_left_joint" range="0.0 3.6651914291880923" type="hinge" damping="0.05" armature="0.001" springref="-0.1"/>
          <geom mesh="knob_front_left_vis" type="mesh" solimp="0.998 0.998 0.001" solref="0.001 1" density="100" friction="0.95 0.3 0.1" class="visual" material="knob_front_left_material"/>
          <geom class="collision" type="cylinder" pos="-0.171414 -0.242129 -0.000388" size="0.01965462788939476 0.009692679159343243" quat="1.0 0.0 0.0 0.0"/>
          <geom class="collision" type="box" pos="-0.171480 -0.220470 -0.001043" size="0.0017808674601837993 0.0031232626643031836 0.007129808887839317" quat="1.0 0.0 0.0 0.0"/>
        </body>
        <body name="knob_front_right">
          <joint axis="0.0 0.0 1.0" pos="0.187441 -0.242079 -0.000013" limited="true" name="knob_front_right_joint" range="0.0 3.6651914291880923" type="hinge" damping="0.05" armature="0.001" springref="-0.1"/>
          <geom mesh="knob_front_right_vis" type="mesh" solimp="0.998 0.998 0.001" solref="0.001 1" density="100" friction="0.95 0.3 0.1" class="visual" material="knob_front_right_material"/>
          <geom class="collision" type="cylinder" pos="0.187555 -0.242129 -0.000388" size="0.01965462788939476 0.009692679159343243" quat="1.0 0.0 0.0 0.0"/>
          <geom class="collision" type="box" pos="0.187488 -0.220470 -0.001043" size="0.0017808674601837993 0.0031232626643031836 0.007129808887839317" quat="1.0 0.0 0.0 0.0"/>
        </body>
        <body name="knob_rear_left">
          <joint axis="0.0 0.0 1.0" pos="-0.082041 -0.242079 -0.000013" limited="true" name="knob_rear_left_joint" range="0.0 3.6651914291880923" type="hinge" damping="0.05" armature="0.001" springref="-0.1"/>
          <geom mesh="knob_rear_left_vis" type="mesh" solimp="0.998 0.998 0.001" solref="0.001 1" density="100" friction="0.95 0.3 0.1" class="visual" material="knob_rear_left_material"/>
          <geom class="collision" type="cylinder" pos="-0.081969 -0.242129 -0.000388" size="0.01965462788939476 0.009692679159343243" quat="1.0 0.0 0.0 0.0"/>
          <geom class="collision" type="box" pos="-0.082035 -0.220470 -0.001043" size="0.0017808674601837993 0.0031232626643031836 0.007129808887839317" quat="1.0 0.0 0.0 0.0"/>
        </body>
        <body name="knob_rear_right">
          <joint axis="0.0 0.0 1.0" pos="0.097807 -0.242079 -0.000013" limited="true" name="knob_rear_right_joint" range="0.0 3.6651914291880923" type="hinge" damping="0.05" armature="0.001" springref="-0.1"/>
          <geom mesh="knob_rear_right_vis" type="mesh" solimp="0.998 0.998 0.001" solref="0.001 1" density="100" friction="0.95 0.3 0.1" class="visual" material="knob_rear_right_material"/>
          <geom class="collision" type="cylinder" pos="0.097862 -0.242129 -0.000388" size="0.01965462788939476 0.009692679159343243" quat="1.0 0.0 0.0 0.0"/>
          <geom class="collision" type="box" pos="0.097796 -0.220470 -0.001043" size="0.0017808674601837993 0.0031232626643031836 0.007129808887839317" quat="1.0 0.0 0.0 0.0"/>
        </body>
        <geom class="region" name="reg_main" type="box" pos="0.0003605000000000136 0.00039900000000001046 -0.016697999999999998" size="0.41863649999999997 0.276408 0.005493"/>
      </body>
    </body>
  </worldbody>
  <actuator>
    <motor name="knob_center_joint_actuator" joint="knob_center_joint" gear="10"/>
    <motor name="knob_front_left_joint_actuator" joint="knob_front_left_joint" gear="10"/>
    <motor name="knob_front_right_joint_actuator" joint="knob_front_right_joint" gear="10"/>
    <motor name="knob_rear_left_joint_actuator" joint="knob_rear_left_joint" gear="10"/>
    <motor name="knob_rear_right_joint_actuator" joint="knob_rear_right_joint" gear="10"/>
  </actuator>
</mujoco>
