<?xml version='1.0' encoding='UTF-8'?>
<mujoco model="model">
  <option timestep="0.002" gravity="0.0 0.0 -9.81"/>
  <compiler angle="radian"/>
  <asset>
    <mesh file="visuals/Body001.obj" name="Body001_vis"/>
    <mesh file="visuals/Door001.obj" name="Door001_vis"/>
    <mesh file="visuals/Door001_Clear.obj" name="Door001_Clear_vis"/>
    <mesh file="visuals/Knob001.obj" name="Knob001_vis"/>
    <mesh file="visuals/Knob002.obj" name="Knob002_vis"/>
    <mesh file="visuals/Shelf001.obj" name="Shelf001_vis"/>
    <mesh file="visuals/Shelf002.obj" name="Shelf002_vis"/>
    <texture file="visuals/T_BC001.png" name="Body001_material" type="2d"/>
    <material name="Body001_material" rgba="1 1 1 1.0" texture="Body001_material" shininess="0.5" specular="1"/>
    <texture file="visuals/T_BC001.png" name="Door001_material" type="2d"/>
    <material name="Door001_material" rgba="1 1 1 1.0" texture="Door001_material" shininess="0.4472135901451111" specular="1"/>
    <texture file="visuals/T_BC001.png" name="Door001_Clear_material" type="2d"/>
    <material name="Door001_Clear_material" rgba="1 1 1 0.7325905561447144" texture="Door001_Clear_material" shininess="0.4472135901451111" specular="0.3103448502657381"/>
    <texture file="visuals/T_BC001.png" name="Knob001_material" type="2d"/>
    <material name="Knob001_material" rgba="1 1 1 1.0" texture="Knob001_material" shininess="0.4472135901451111" specular="0.3103448502657381"/>
    <texture file="visuals/T_BC001.png" name="Knob002_material" type="2d"/>
    <material name="Knob002_material" rgba="1 1 1 1.0" texture="Knob002_material" shininess="0.4472135901451111" specular="0.3103448502657381"/>
    <texture file="visuals/T_BC001.png" name="Shelf001_material" type="2d"/>
    <material name="Shelf001_material" rgba="1 1 1 1.0" texture="Shelf001_material" shininess="0.4472135901451111" specular="0.3103448502657381"/>
    <texture file="visuals/T_BC001.png" name="Shelf002_material" type="2d"/>
    <material name="Shelf002_material" rgba="1 1 1 1.0" texture="Shelf002_material" shininess="0.4472135901451111" specular="0.3103448502657381"/>
  </asset>
  <default>
    <default class="visual">
      <geom conaffinity="0" contype="0" group="1" type="mesh"/>
    </default>
    <default class="collision">
      <geom group="0" rgba="0.5 0 0 0.5"/>
    </default>
    <default class="spawn">
      <geom group="0" rgba="1 1 1 0.5" contype="0" conaffinity="0"/>
      <site group="0" rgba="1 1 1 0.5"/>
    </default>
    <default class="region">
      <geom group="1" conaffinity="0" contype="0" rgba="0 1 0 0"/>
    </default>
  </default>
  <worldbody>
    <body>
      <body name="object">
        <geom mesh="Body001_vis" type="mesh" solimp="0.998 0.998 0.001" solref="0.001 1" friction="0.95 0.3 0.1" class="visual" material="Body001_material"/>
        <geom class="collision" type="cylinder" pos="-0.129260 -0.059913 -0.106618" size="0.012784481048583984 0.008236567489802837" quat="1.0 0.0 0.0 0.0" density="1000.0"/>
        <geom class="collision" type="cylinder" pos="0.129404 -0.060236 -0.106618" size="0.012784481048583984 0.008236567489802837" quat="1.0 0.0 0.0 0.0" density="1000.0"/>
        <geom class="collision" type="cylinder" pos="-0.129220 0.082953 -0.106618" size="0.012784481048583984 0.008236567489802837" quat="1.0 0.0 0.0 0.0" density="1000.0"/>
        <geom class="collision" type="cylinder" pos="0.129404 0.082385 -0.106618" size="0.012784481048583984 0.008236567489802837" quat="1.0 0.0 0.0 0.0" density="1000.0"/>
        <geom class="collision" type="box" pos="-0.003658 0.010522 -0.098064" size="0.14415860176086426 0.10873482376337051 0.0024298548232764006" quat="1.0 0.0 0.0 0.0" density="1000.0"/>
        <geom class="collision" type="box" pos="-0.001113 0.010522 0.112206" size="0.1429423689842224 0.10873539745807648 0.002185462974011898" quat="1.0 0.0 0.0 0.0" density="1000.0"/>
        <geom class="collision" type="box" pos="-0.166121 0.010519 0.005669" size="0.0021834021899849176 0.10873875021934509 0.07840549200773239" quat="1.0 0.0 0.0 0.0" density="1000.0"/>
        <geom class="collision" type="box" pos="0.136982 0.010519 0.007505" size="0.03132210671901703 0.10873860865831375 0.07768809050321579" quat="1.0 0.0 0.0 0.0" density="1000.0"/>
        <geom class="collision" type="box" pos="-0.003874 0.116850 0.005728" size="0.14104901254177094 0.0024080148432403803 0.10631757974624634" quat="1.0 0.0 0.0 0.0" density="1000.0"/>
        <geom class="collision" type="box" pos="0.127455 0.003625 0.006152" size="0.02189512550830841 0.09946140646934509 0.10486149787902832" quat="1.0 0.0 0.0 0.0" density="1000.0"/>
        <geom class="collision" type="box" pos="-0.162922 0.010519 0.094821" size="0.0021834021899849176 0.10873820632696152 0.008513877168297768" quat="0.9822958111763 0.0 0.18733632564544678 0.0" density="1000.0"/>
        <geom class="collision" type="box" pos="-0.152588 0.010519 0.106782" size="0.0021834024228155613 0.10873820632696152 0.009985403157770634" quat="0.8979359865188599 1.6935906010928647e-09 0.44012612104415894 -8.880324031679265e-09" density="1000.0"/>
        <geom class="collision" type="box" pos="0.150607 0.010519 0.106782" size="0.0021834021899849176 0.10873820632696152 0.009985403157770634" quat="0.8979359269142151 1.6935878255353032e-09 -0.4401261508464813 8.880320478965587e-09" density="1000.0"/>
        <geom class="collision" type="box" pos="0.162247 0.010519 0.093453" size="0.0021834021899849176 0.10873820632696152 0.009985402226448059" quat="0.9822958111763 0.0 -0.18733631074428558 0.0" density="1000.0"/>
        <geom class="collision" type="box" pos="0.124340 0.010519 0.098691" size="0.018680520355701447 0.1087382584810257 0.01488926075398922" quat="1.0 0.0 0.0 0.0" density="1000.0"/>
        <geom class="collision" type="box" pos="0.149015 0.010519 0.092498" size="0.006062167696654797 0.10873822122812271 0.00869657751172781" quat="1.0 0.0 0.0 0.0" density="1000.0"/>
        <geom class="collision" type="box" pos="-0.152076 0.010519 -0.093719" size="0.0021834021899849176 0.10873820632696152 0.009985403157770634" quat="0.8803845047950745 -7.734415330418187e-10 -0.4742605984210968 -7.759309639254752e-09" density="1000.0"/>
        <geom class="collision" type="box" pos="-0.162865 0.010519 -0.082151" size="0.0021834021899849176 0.10873820632696152 0.008360877633094788" quat="0.9822958111763 0.0 -0.18733631074428558 0.0" density="1000.0"/>
        <geom class="collision" type="box" pos="0.162407 0.010519 -0.078821" size="0.0021834021899849176 0.10873820632696152 0.009985402226448059" quat="0.9822958111763 0.0 0.1873362958431244 0.0" density="1000.0"/>
        <geom class="collision" type="box" pos="0.149059 0.010519 -0.093719" size="0.0021834021899849176 0.10873820632696152 0.009985403157770634" quat="0.8803845047950745 -7.734387019731059e-10 0.4742605984210968 7.759306974719493e-09" density="1000.0"/>
        <geom class="collision" type="box" pos="0.124340 0.010519 -0.083630" size="0.018680520355701447 0.10873817652463913 0.01488926075398922" quat="1.0 0.0 0.0 0.0" density="1000.0"/>
        <geom class="collision" type="box" pos="0.149015 0.010519 -0.078476" size="0.006062167696654797 0.10873813927173615 0.00869657751172781" quat="1.0 0.0 0.0 0.0" density="1000.0"/>
        <body name="Door001">
          <joint axis="1.0 0.0 0.0" pos="-0.030514 -0.098546 -0.097669" limited="true" name="Door001_joint" range="0.0 1.5707963267948966" type="hinge" damping="1" frictionloss="1" armature=".01" stiffness="0.05"/>
          <geom mesh="Door001_vis" type="mesh" solimp="0.998 0.998 0.001" solref="0.001 1" friction="0.95 0.3 0.1" class="visual" material="Door001_material"/>
          <geom class="collision" type="box" pos="-0.025669 -0.092460 0.009090" size="0.1255735456943512 0.0060557955875992775 0.09455163776874542" quat="1.0 0.0 0.0 0.0" density="1000.0"/>
          <geom class="collision" type="box" pos="-0.005747 -0.116576 0.100692" size="0.10168378055095673 0.0026751032564789057 0.005733071360737085" quat="1.0 0.0 0.0 0.0" density="1000.0"/>
          <geom class="collision" type="box" pos="-0.109397 -0.108440 0.100692" size="0.0026750427205115557 0.009932979010045528 0.005732994060963392" quat="1.0 0.0 0.0 0.0" density="1000.0"/>
          <geom class="collision" type="box" pos="0.093348 -0.108440 0.100692" size="0.0026750483084470034 0.009932991117238998 0.005732994060963392" quat="1.0 0.0 0.0 0.0" density="1000.0"/>
          <body name="Door001_Clear">
            <geom mesh="Door001_Clear_vis" type="mesh" solimp="0.998 0.998 0.001" solref="0.001 1" friction="0.95 0.3 0.1" class="visual" material="Door001_Clear_material"/>
            <geom class="collision" type="box" pos="-0.018414 -0.091163 0.007006" size="0.12179452180862427 0.0019127419218420982 0.0825042873620987" quat="1.0 0.0 0.0 0.0" density="1000.0"/>
          </body>
        </body>
        <body name="Knob001">
          <joint axis="0.0 1.0 0.0" pos="0.132101 -0.105523 0.049595" limited="true" name="Knob001_joint" range="0.0 4.014257279586958" type="hinge" damping="0.05" armature="0.001"/>
          <geom mesh="Knob001_vis" type="mesh" solimp="0.998 0.998 0.001" solref="0.001 1" friction="0.95 0.3 0.1" class="visual" material="Knob001_material"/>
          <geom class="collision" type="cylinder" pos="0.132101 -0.102111 0.050099" size="0.011982725001871586 0.0036792955361306667" quat="0.7071068286895752 0.7071067690849304 1.5700924318127872e-16 5.9269340452702814e-24" density="1000.0"/>
          <geom class="collision" type="box" pos="0.132112 -0.107072 0.048953" size="0.001737714628688991 0.006641484331339598 0.014822889119386673" quat="1.0 0.0 0.0 0.0" density="1000.0"/>
        </body>
        <body name="Knob002">
          <joint axis="0.0 1.0 0.0" pos="0.131497 -0.105523 -0.028554" limited="true" name="Knob002_joint" range="0.0 3.141592653589793" type="hinge" damping="0.05" armature="0.001"/>
          <geom mesh="Knob002_vis" type="mesh" solimp="0.998 0.998 0.001" solref="0.001 1" friction="0.95 0.3 0.1" class="visual" material="Knob002_material"/>
          <geom class="collision" type="cylinder" pos="0.132101 -0.102111 -0.027958" size="0.011982725001871586 0.0036792955361306667" quat="0.7071068286895752 0.7071067690849304 1.5700924318127872e-16 5.9269340452702814e-24" density="1000.0"/>
          <geom class="collision" type="box" pos="0.132075 -0.107989 -0.028310" size="0.0151163749396801 0.006026469636708498 0.002072633244097233" quat="1.0 0.0 0.0 0.0" density="1000.0"/>
        </body>
        <body name="Shelf001">
          <joint axis="0.0 -1.0 0.0" pos="-0.028681 -0.000150 0.004680" limited="true" name="Shelf001_joint" range="0.0 0.15" type="slide" damping="1" frictionloss="1" armature=".01" stiffness="0.05"/>
          <geom mesh="Shelf001_vis" type="mesh" solimp="0.998 0.998 0.001" solref="0.001 1" friction="0.95 0.3 0.1" class="visual" material="Shelf001_material"/>
          <geom class="collision" type="box" pos="-0.028504 0.003812 0.004680" size="0.13229717314243317 0.08529195934534073 0.003746497444808483" quat="1.0 0.0 0.0 0.0" density="1000.0"/>
        </body>
        <body name="Shelf002">
          <joint axis="0.0 -1.0 0.0" pos="-0.029041 0.000185 -0.042632" limited="true" name="Shelf002_joint" range="0.0 0.15" type="slide" damping="1" frictionloss="1" armature=".01" stiffness="0.05"/>
          <geom mesh="Shelf002_vis" type="mesh" solimp="0.998 0.998 0.001" solref="0.001 1" friction="0.95 0.3 0.1" class="visual" material="Shelf002_material"/>
          <geom class="collision" type="box" pos="-0.028901 0.002468 -0.041242" size="0.1329568326473236 0.08898720890283585 0.003746530506759882" quat="1.0 0.0 0.0 0.0" density="1000.0"/>
        </body>
        <geom class="region" name="reg_int" type="box" pos="-0.030215499999999992 0.0038105000000000014 0.006629000000000003" size="0.1360695 0.10023950000000001 0.104706"/>
        <geom class="region" name="reg_main" type="box" pos="0.0 0.010287999999999999 0.0" size="0.168304 0.10897000000000001 0.114391"/>
      </body>
    </body>
  </worldbody>
  <actuator>
    <motor name="Door001_joint_actuator" joint="Door001_joint" gear="50"/>
    <motor name="Knob001_joint_actuator" joint="Knob001_joint" gear="50"/>
    <motor name="Knob002_joint_actuator" joint="Knob002_joint" gear="50"/>
    <motor name="Shelf001_joint_actuator" joint="Shelf001_joint" gear="50"/>
    <motor name="Shelf002_joint_actuator" joint="Shelf002_joint" gear="50"/>
  </actuator>
</mujoco>
