<mujoco model="model">
  <compiler angle="radian"/>
  <asset>
    <mesh file="visuals/handle.obj" name="handle_vis"/>
    <mesh file="visuals/Body001.obj" name="Body001_vis"/>
    <mesh file="visuals/Funnel001.obj" name="Funnel001_vis"/>
    <mesh file="visuals/spout.obj" name="spout_vis"/>
    <texture file="visuals/T_BC001.png" name="Body001_material" type="2d"/>
    <material name="Body001_material" rgba="1 1 1 1.0" texture="Body001_material" shininess="0.6803424060344696" specular="0.7381"/>
    <texture file="visuals/T_BC001.png" name="handle_material" type="2d"/>
    <material name="handle_material" rgba="1 1 1 1.0" texture="handle_material" shininess="0.2803424060344696" specular="1"/>
    <texture file="visuals/T_BC001.png" name="Funnel001_material" type="2d"/>
    <material name="Funnel001_material" rgba="1 1 1 1.0" texture="Funnel001_material" shininess="0.2803424060344696" specular="1"/>
    <texture file="visuals/T_BC001.png" name="spout_material" type="2d"/>
    <material name="spout_material" rgba="1 1 1 1.0" texture="spout_material" shininess="0.2803424060344696" specular="1"/>
  </asset>
  <default>
    <default class="visual">
      <geom conaffinity="0" contype="0" group="1" type="mesh"/>
    </default>
    <default class="collision">
      <geom group="0" rgba="0.5 0 0 0.5"/>
    </default>
    <default class="spawn">
      <geom group="0" rgba="1 1 1 0.5" contype="0" conaffinity="0"/>
      <site group="0" rgba="1 1 1 0.5"/>
    </default>
    <default class="region">
      <geom group="1" conaffinity="0" contype="0" rgba="0 1 0 0"/>
    </default>
  </default>
  <worldbody>
    <body>
      <body name="object">
        <geom mesh="Body001_vis" type="mesh" solimp="0.998 0.998 0.001" solref="0.001 1" density="100" friction="0.95 0.3 0.1" class="visual" material="Body001_material"/>
        <geom class="collision" type="box" pos="-0.357462 0.022212 -0.135699" size="0.022984236478805542 0.2331775724887848 0.13575202226638794" quat="1.0 0.0 0.0 0.0"/>
        <geom class="collision" type="box" pos="0.354540 -0.000222 -0.135699" size="0.02422627992928028 0.25632357597351074 0.13575194776058197" quat="1.0 0.0 0.0 0.0"/>
        <geom class="collision" type="box" pos="-0.020490 0.206552 -0.135699" size="0.34995174407958984 0.052213750779628754 0.13575191795825958" quat="1.0 0.0 0.0 0.0"/>
        <geom class="collision" type="box" pos="-0.023106 -0.230568 -0.135700" size="0.35565271973609924 0.02671852894127369 0.1357518881559372" quat="1.0 0.0 0.0 0.0"/>
        <geom class="collision" type="box" pos="-0.366793 0.000000 0.003160" size="0.026208236813545227 0.2661292254924774 0.008420041762292385" quat="1.0 0.0 0.0 0.0"/>
        <geom class="collision" type="box" pos="0.365811 0.000000 0.003160" size="0.027190038934350014 0.2661292254924774 0.008420038037002087" quat="1.0 0.0 0.0 0.0"/>
        <geom class="collision" type="box" pos="-0.000854 -0.244232 0.003160" size="0.3392276167869568 0.021897604689002037 0.008420036174356937" quat="1.0 0.0 0.0 0.0"/>
        <geom class="collision" type="box" pos="-0.000854 0.215536 0.003160" size="0.33922746777534485 0.050592899322509766 0.008420034311711788" quat="1.0 0.0 0.0 0.0"/>
        <geom class="collision" type="box" pos="0.194877 -0.024422 -0.243394" size="0.14021103084087372 0.18389678001403809 0.02805747464299202" quat="1.0 0.0 0.0 0.0"/>
        <geom class="collision" type="box" pos="-0.196030 -0.024422 -0.243394" size="0.14021095633506775 0.1838967204093933 0.02805747091770172" quat="1.0 0.0 0.0 0.0"/>
        <geom class="collision" type="box" pos="-0.000893 -0.119340 -0.243394" size="0.05441328138113022 0.08897862583398819 0.028057469055056572" quat="1.0 0.0 0.0 0.0"/>
        <geom class="collision" type="box" pos="-0.000893 0.119201 -0.243394" size="0.054413240402936935 0.040589965879917145 0.028057465329766273" quat="1.0 0.0 0.0 0.0"/>
        <geom class="collision" type="cylinder" pos="0.000685 0.211444 0.035838" size="0.02336934022605419 0.022742383182048798" quat="1.0 0.0 0.0 0.0"/>
        <geom class="collision" type="cylinder" pos="-0.003834 0.211444 0.063443" size="0.023010553792119026 0.04808701202273369" quat="0.7071068286895752 0.0 -0.7071067690849304 0.0"/>
        <body name="handle">
          <joint axis="1.0 0.0 0.0" pos="0.068833 0.211613 0.064092" limited="true" name="handle_joint_hinge_0" type="hinge" range="-0.7853981633974483 0.7853981633974483" damping="1" frictionloss="1" armature=".01" stiffness="0.05"/>
          <joint axis="0.0 1.0 0.0" pos="0.068833 0.211613 0.064092" limited="true" name="handle_joint_hinge_1" type="hinge" range="0.0 0.17453292519943295" damping="1" frictionloss="1" armature=".01" stiffness="0.05"/>
          <geom mesh="handle_vis" type="mesh" solimp="0.998 0.998 0.001" solref="0.001 1" density="100" friction="0.95 0.3 0.1" class="visual" material="handle_material"/>
          <geom class="collision" type="cylinder" pos="0.070456 0.211444 0.063443" size="0.023010550066828728 0.014551625587046146" quat="0.7071068286895752 0.0 -0.7071067690849304 0.0"/>
          <geom class="collision" type="cylinder" pos="0.077750 0.212212 0.115083" size="0.0037490269169211388 0.0287446491420269" quat="7.549790126404332e-08 -0.0 -1.0 -0.0"/>
        </body>
        <body name="Funnel001">
          <joint axis="0.0 0.0 1.0" pos="0.000341 0.023146 -0.239528" limited="true" name="Funnel001_joint" range="0.0 0.05" type="slide" damping="1" frictionloss="1" armature=".01" stiffness="0.05"/>
          <geom mesh="Funnel001_vis" type="mesh" solimp="0.998 0.998 0.001" solref="0.001 1" density="100" friction="0.95 0.3 0.1" class="visual" material="Funnel001_material"/>
          <geom class="collision" type="cylinder" pos="-0.000472 0.023136 -0.238409" size="0.04696207121014595 0.004018215928226709" quat="1.0 0.0 0.0 0.0"/>
          <geom class="collision" type="cylinder" pos="-0.000472 0.023136 -0.233851" size="0.006461434997618198 0.0018289702711626887" quat="1.0 0.0 0.0 0.0"/>
        </body>
        <body name="spout">
          <joint axis="0.0 0.0 1.0" pos="0.000437 0.211429 0.176312" limited="true" name="spout_joint" range="-0.7853981633974483 0.7853981633974483" type="hinge" damping="1" frictionloss="1" armature=".01" stiffness="0.05"/>
          <site type="cylinder" rgba="0.5 0.75 1 1" size="0.00637557078152895 0.2281561940908432" pos="0.000511 -0.000383 0.009755" name="water"/>
          <geom mesh="spout_vis" type="mesh" solimp="0.998 0.998 0.001" solref="0.001 1" density="100" friction="0.95 0.3 0.1" class="visual" material="spout_material"/>
          <geom class="collision" type="cylinder" pos="0.000483 0.070383 0.259668" size="0.012713657692074776 0.09240955114364624" quat="2.247645092268158e-08 8.429369557916289e-08 -0.7071068286895752 -0.7071067094802856"/>
          <geom class="collision" type="cylinder" pos="0.000454 0.211585 0.150864" size="0.012904489412903786 0.06219162791967392" quat="7.549790126404332e-08 -0.0 -1.0 -0.0"/>
          <geom class="collision" type="cylinder" pos="0.000483 0.195325 0.240926" size="0.014660518616437912 0.03633870184421539" quat="3.2521985104949636e-08 -1.0958445528785887e-07 0.9077298641204834 0.419555127620697"/>
          <geom class="collision" type="cylinder" pos="0.000454 -0.000359 0.243907" size="0.00948744360357523 0.007031399291008711" quat="7.549790126404332e-08 -0.0 -1.0 -0.0"/>
        </body>
        <geom class="region" name="reg_main" type="box" pos="0.0 0.0 -0.1299355" size="0.393001 0.266129 0.1415155"/>
        <geom class="region" name="reg_basin" type="box" pos="-0.0016795000000000004 -0.027162000000000006 -0.108769" size="0.3279955 0.18320399999999998 0.10605200000000001"/>
      </body>
    </body>
  </worldbody>
  <actuator>
    <motor name="handle_joint_hinge_0_actuator" joint="handle_joint_hinge_0" gear="10"/>
    <motor name="handle_joint_hinge_1_actuator" joint="handle_joint_hinge_1" gear="10"/>
    <motor name="Funnel001_joint_actuator" joint="Funnel001_joint" gear="10"/>
    <motor name="spout_joint_actuator" joint="spout_joint" gear="10"/>
  </actuator>
</mujoco>
