<mujoco model="model">
  <compiler angle="radian"/>
  <asset>
    <mesh file="visuals/handle.obj" name="handle_vis"/>
    <mesh file="visuals/Body001.obj" name="Body001_vis"/>
    <mesh file="visuals/Funnel001.obj" name="Funnel001_vis"/>
    <mesh file="visuals/Funnel002.obj" name="Funnel002_vis"/>
    <mesh file="visuals/spout.obj" name="spout_vis"/>
    <texture file="visuals/T_BC001.png" name="Body001_material" type="2d"/>
    <material name="Body001_material" rgba="1 1 1 1.0" texture="Body001_material" shininess="-1023.0" specular="0.3103448502657381"/>
    <texture file="visuals/T_BC001.png" name="handle_material" type="2d"/>
    <material name="handle_material" rgba="1 1 1 1.0" texture="handle_material" shininess="-1023.0" specular="0.3103448502657381"/>
    <texture file="visuals/T_BC001.png" name="Funnel001_material" type="2d"/>
    <material name="Funnel001_material" rgba="1 1 1 1.0" texture="Funnel001_material" shininess="-1023.0" specular="0.3103448502657381"/>
    <texture file="visuals/T_BC001.png" name="Funnel002_material" type="2d"/>
    <material name="Funnel002_material" rgba="1 1 1 1.0" texture="Funnel002_material" shininess="-1023.0" specular="0.3103448502657381"/>
    <texture file="visuals/T_BC001.png" name="spout_material" type="2d"/>
    <material name="spout_material" rgba="1 1 1 1.0" texture="spout_material" shininess="-1023.0" specular="0.3103448502657381"/>
  </asset>
  <default>
    <default class="visual">
      <geom conaffinity="0" contype="0" group="1" type="mesh"/>
    </default>
    <default class="collision">
      <geom group="0" rgba="0.5 0 0 0.5"/>
    </default>
    <default class="spawn">
      <geom group="0" rgba="1 1 1 0.5" contype="0" conaffinity="0"/>
      <site group="0" rgba="1 1 1 0.5"/>
    </default>
    <default class="region">
      <geom group="1" conaffinity="0" contype="0" rgba="0 1 0 0"/>
    </default>
  </default>
  <worldbody>
    <body>
      <body name="object">
        <geom mesh="Body001_vis" type="mesh" solimp="0.998 0.998 0.001" solref="0.001 1" density="100" friction="0.95 0.3 0.1" class="visual" material="Body001_material"/>
        <geom class="collision" type="box" pos="0.23652738332748413 0.00023410702124238014 -0.14926347136497498" size="0.16209204494953156 0.22183653712272644 0.10342414677143097" quat="1.0 0.0 0.0 0.0"/>
        <geom class="collision" type="cylinder" pos="-0.021326115354895592 0.18427163362503052 -0.008932516910135746" size="0.018282365053892136 0.020360218361020088" quat="0.5 0.4999999701976776 0.5 0.5"/>
        <geom class="collision" type="cylinder" pos="-0.051278628408908844 0.18416287004947662 -0.010989080183207989" size="0.020259195938706398 0.047851018607616425" quat="0.9990497827529907 0.0 0.0 0.04358312115073204"/>
        <geom class="collision" type="box" pos="-0.07560476660728455 9.405938908457756e-05 -0.15127705037593842" size="0.012089341878890991 0.22169646620750427 0.10238426178693771" quat="1.0 0.0 0.0 0.0"/>
        <geom class="collision" type="box" pos="0.005088299512863159 -0.17985501885414124 -0.15042777359485626" size="0.06973908096551895 0.041747402399778366 0.10225952416658401" quat="1.0 0.0 0.0 0.0"/>
        <geom class="collision" type="box" pos="0.005088299512863159 -0.1315426081418991 -0.099894218146801" size="0.06973908096551895 0.0026383125223219395 0.05264557898044586" quat="0.9983898401260376 0.05672502517700195 0.0 0.0"/>
        <geom class="collision" type="box" pos="0.005088299512863159 0.12853343784809113 -0.11045671999454498" size="0.06973908096551895 0.0026383125223219395 0.06332626193761826" quat="0.9974493384361267 -0.07137805223464966 0.0 0.0"/>
        <geom class="collision" type="box" pos="0.005088299512863159 0.18094712495803833 -0.15042777359485626" size="0.06973908096551895 0.041364654898643494 0.10225936025381088" quat="1.0 0.0 0.0 0.0"/>
        <geom class="collision" type="box" pos="-0.23876143991947174 0.1889650821685791 -0.12696334719657898" size="0.14949655532836914 0.002638312289491296 0.07926877588033676" quat="0.9990689158439636 -0.043143387883901596 0.0 0.0"/>
        <geom class="collision" type="box" pos="-0.2434958964586258 0.20812034606933594 -0.15042777359485626" size="0.1542310118675232 0.01276779267936945 0.10225598514080048" quat="1.0 0.0 0.0 0.0"/>
        <geom class="collision" type="box" pos="-0.23876143991947174 -0.18729108572006226 -0.1269821971654892" size="0.14949655532836914 0.002638312289491296 0.07926878333091736" quat="0.9973665475845337 0.07252559065818787 0.0 0.0"/>
        <geom class="collision" type="box" pos="-0.24286778271198273 -0.20866277813911438 -0.15042777359485626" size="0.15485912561416626 0.01276779267936945 0.10225598514080048" quat="1.0 0.0 0.0 0.0"/>
        <geom class="collision" type="box" pos="-0.30198803544044495 -0.0015555024147033691 -0.23092524707317352" size="0.0775531753897667 0.19654637575149536 0.022491823881864548" quat="1.0 0.0 0.0 0.0"/>
        <geom class="collision" type="box" pos="-0.3863503336906433 9.405938908457756e-05 -0.15127705037593842" size="0.011722794733941555 0.22169646620750427 0.10238329321146011" quat="1.0 0.0 0.0 0.0"/>
        <geom class="collision" type="box" pos="-0.367370069026947 0.0006847637705504894 -0.15127091109752655" size="0.002350295428186655 0.19769826531410217 0.10238055139780045" quat="0.9991256594657898 0.0 -0.041807886213064194 0.0"/>
        <geom class="collision" type="box" pos="-0.11571699380874634 -0.0015555024147033691 -0.23107434809207916" size="0.0305434949696064 0.19654637575149536 0.022342780604958534" quat="1.0 0.0 0.0 0.0"/>
        <geom class="collision" type="box" pos="-0.184838205575943 0.1186731830239296 -0.23170946538448334" size="0.040500566363334656 0.07903584092855453 0.02170766144990921" quat="1.0 0.0 0.0 0.0"/>
        <geom class="collision" type="box" pos="-0.18600966036319733 -0.12200066447257996 -0.23117496073246002" size="0.04122575372457504 0.08241641521453857 0.022242633625864983" quat="1.0 0.0 0.0 0.0"/>
        <geom class="collision" type="box" pos="-0.045667652040719986 -0.0013713464140892029 -0.1635603904724121" size="0.014139543287456036 0.1264631152153015 0.013112707063555717" quat="1.0 0.0 0.0 0.0"/>
        <geom class="collision" type="box" pos="0.051219642162323 -0.005265929736196995 -0.16300077736377716" size="0.01209177728742361 0.044978559017181396 0.012109190225601196" quat="1.0 0.0 0.0 0.0"/>
        <geom class="collision" type="box" pos="0.013094743713736534 0.08130013942718506 -0.1572476178407669" size="0.04683594033122063 0.04241792485117912 0.00627686083316803" quat="1.0 0.0 0.0 0.0"/>
        <geom class="collision" type="box" pos="0.014179454185068607 -0.07933476567268372 -0.15682582557201385" size="0.046549007296562195 0.0453357957303524 0.006698662415146828" quat="1.0 0.0 0.0 0.0"/>
        <geom class="collision" type="box" pos="-0.09168035537004471 0.0006763041019439697 -0.13003428280353546" size="0.007510052993893623 0.19804197549819946 0.08050790429115295" quat="0.9981808066368103 0.0 0.06029169261455536 0.0"/>
        <geom class="collision" type="box" pos="0.06238365173339844 0.0006763041019439697 -0.10089131444692612" size="0.007510052062571049 0.14010055363178253 0.054632414132356644" quat="0.9981808066368103 0.0 0.06029169261455536 0.0"/>
        <geom class="collision" type="box" pos="-0.05904521048069 0.0006763041019439697 -0.1002633273601532" size="0.0012203236110508442 0.14010055363178253 0.054632414132356644" quat="0.9985798597335815 0.0 -0.05327498912811279 0.0"/>
        <geom class="collision" type="box" pos="0.0002938508987426758 0.21976149082183838 -0.04482324421405792" size="0.4090060293674469 0.013016534969210625 0.0041864109225571156" quat="1.0 0.0 0.0 0.0"/>
        <geom class="collision" type="box" pos="0.0002938508987426758 -0.21892192959785461 -0.04482324421405792" size="0.4090060293674469 0.013016534969210625 0.0041864109225571156" quat="1.0 0.0 0.0 0.0"/>
        <geom class="collision" type="box" pos="-0.39669299125671387 -0.0007286593317985535 -0.04482324421405792" size="0.013016549870371819 0.20691721141338348 0.004186480306088924" quat="1.0 0.0 0.0 0.0"/>
        <geom class="collision" type="box" pos="0.39572858810424805 -0.0007286220788955688 -0.04482324421405792" size="0.013016549870371819 0.20691721141338348 0.004186470061540604" quat="1.0 0.0 0.0 0.0"/>
        <geom class="collision" type="box" pos="0.005088299512863159 0.0007530823349952698 -0.2153775990009308" size="0.06973908096551895 0.14008310437202454 0.03730699419975281" quat="1.0 0.0 0.0 0.0"/>
        <geom class="collision" type="box" pos="-0.18519650399684906 -0.004535593092441559 -0.24889975786209106" size="0.03927761688828468 0.04429145157337189 0.004517826251685619" quat="1.0 0.0 0.0 0.0"/>
        <geom class="collision" type="box" pos="-0.21963703632354736 0.03309756889939308 -0.2168779820203781" size="0.0077866483479738235 0.01505254115909338 0.004746152553707361" quat="0.9355807900428772 0.0 -0.0 -0.35311275720596313"/>
        <geom class="collision" type="box" pos="-0.2188185155391693 -0.03232163190841675 -0.2168779820203781" size="0.007786647416651249 0.01505254115909338 0.004746152553707361" quat="0.9381937980651855 0.0 0.0 0.34611037373542786"/>
        <geom class="collision" type="box" pos="-0.15329214930534363 0.03226673603057861 -0.2168779820203781" size="0.007786647416651249 0.01505254115909338 0.004746152553707361" quat="0.9381937980651855 0.0 0.0 0.34611037373542786"/>
        <geom class="collision" type="box" pos="-0.15437868237495422 -0.032964807003736496 -0.2168779820203781" size="0.0077866483479738235 0.01505254115909338 0.004746152553707361" quat="0.9355807900428772 0.0 -0.0 -0.35311275720596313"/>
        <geom class="collision" type="box" pos="-0.02706190012395382 0.03058907389640808 -0.15569910407066345" size="0.0077866483479738235 0.01505254115909338 0.004746152553707361" quat="0.9355807900428772 0.0 -0.0 -0.35311275720596313"/>
        <geom class="collision" type="box" pos="0.03625345230102539 -0.0322796106338501 -0.15569910407066345" size="0.0077866483479738235 0.01505254115909338 0.004746152553707361" quat="0.9355807900428772 0.0 -0.0 -0.35311275720596313"/>
        <geom class="collision" type="box" pos="0.03406063839793205 0.03458072990179062 -0.15569910407066345" size="0.0077866483479738235 0.01505254115909338 0.004746152553707361" quat="0.9161313772201538 0.0 0.0 0.4008781909942627"/>
        <geom class="collision" type="box" pos="-0.029377171769738197 -0.0308250579982996 -0.15569910407066345" size="0.0077866483479738235 0.01505254115909338 0.004746152553707361" quat="0.9573758840560913 0.0 0.0 0.2888449430465698"/>
        <body name="handle">
          <joint axis="1.0 0.0 0.0" pos="0.011728471145033836 0.18457047641277313 -0.009023033082485199" limited="true" name="handle_joint_hinge_0" type="hinge" range="-0.7853981633974483 0.7853981633974483" damping="1" frictionloss="1" armature=".01" stiffness="0.05"/>
          <joint axis="0.0 1.0 0.0" pos="0.011728471145033836 0.18457047641277313 -0.009023033082485199" limited="true" name="handle_joint_hinge_1" type="hinge" range="0.0 0.17453292519943295" damping="1" frictionloss="1" armature=".01" stiffness="0.05"/>
          <geom mesh="handle_vis" type="mesh" solimp="0.998 0.998 0.001" solref="0.001 1" density="100" friction="0.95 0.3 0.1" class="visual" material="handle_material"/>
          <geom class="collision" type="cylinder" pos="0.020263846963644028 0.18472900986671448 -0.008932520635426044" size="0.01856803148984909 0.014965763315558434" quat="0.5 0.4999999701976776 0.5 0.5"/>
          <geom class="collision" type="cylinder" pos="0.00618293322622776 0.18427163362503052 -0.008932520635426044" size="0.01044311560690403 0.002668767236173153" quat="0.5 0.4999999701976776 0.5 0.5"/>
          <geom class="collision" type="cylinder" pos="0.018877984955906868 0.1845209300518036 0.03694717586040497" size="0.0043233647011220455 0.02681279182434082" quat="1.0 0.0 0.0 0.0"/>
        </body>
        <body name="Funnel001">
          <joint axis="0.0 0.0 1.0" pos="-0.18521839380264282 -0.00014210294466465712 -0.22248810529708862" limited="true" name="Funnel001_joint" range="0.0 0.3" type="slide" damping="1" frictionloss="1" armature=".01" stiffness="0.05"/>
          <geom mesh="Funnel001_vis" type="mesh" solimp="0.998 0.998 0.001" solref="0.001 1" density="100" friction="0.95 0.3 0.1" class="visual" material="Funnel001_material"/>
          <geom class="collision" type="cylinder" pos="-0.18476738035678864 -4.830211400985718e-05 -0.22137907147407532" size="0.03602096065878868 0.0008388549904339015" quat="1.0 0.0 0.0 0.0"/>
          <geom class="collision" type="cylinder" pos="-0.1853657364845276 -4.830211400985718e-05 -0.221288800239563" size="0.014919627457857132 0.00391645822674036" quat="1.0 0.0 0.0 0.0"/>
        </body>
        <body name="Funnel002">
          <joint axis="0.0 0.0 1.0" pos="0.004342064261436462 0.0004828465171158314 -0.16072390973567963" limited="true" name="Funnel002_joint" range="0.0 0.3" type="slide" damping="1" frictionloss="1" armature=".01" stiffness="0.05"/>
          <geom mesh="Funnel002_vis" type="mesh" solimp="0.998 0.998 0.001" solref="0.001 1" density="100" friction="0.95 0.3 0.1" class="visual" material="Funnel002_material"/>
          <geom class="collision" type="cylinder" pos="0.003999099135398865 0.0007852166891098022 -0.1609553098678589" size="0.03342888504266739 0.0018126824870705605" quat="1.0 0.0 0.0 0.0"/>
          <geom class="collision" type="cylinder" pos="0.004415725823491812 0.00033873505890369415 -0.15955613553524017" size="0.014739518985152245 0.004046990070492029" quat="1.0 0.0 0.0 0.0"/>
        </body>
        <body name="spout">
          <joint axis="0.0 0.0 1.0" pos="-0.05164801701903343 0.18472075462341309 0.13476690649986267" limited="true" name="spout_joint" range="-0.7853981633974483 0.7853981633974483" type="hinge" damping="1" frictionloss="1" armature=".01" stiffness="0.05"/>
          <site type="cylinder" rgba="0.5 0.75 1 1" size="0.0060607255436480045 0.17275060713291168" pos="-0.13217833638191223 0.03850845247507095 -0.030280524864792824" name="water"/>
          <geom mesh="spout_vis" type="mesh" solimp="0.998 0.998 0.001" solref="0.001 1" density="100" friction="0.95 0.3 0.1" class="visual" material="spout_material"/>
          <geom class="collision" type="cylinder" pos="-0.051278628408908844 0.18416287004947662 0.1043071374297142" size="0.010071869939565659 0.06765434145927429" quat="0.9990497827529907 0.0 0.0 0.04358312115073204"/>
          <geom class="collision" type="cylinder" pos="-0.056350983679294586 0.17457735538482666 0.20272040367126465" size="0.00965795572847128 0.013342335820198059" quat="0.9196361303329468 0.16925090551376343 -0.19007854163646698 0.29915493726730347"/>
          <geom class="collision" type="cylinder" pos="-0.066947340965271 0.15883058309555054 0.224899023771286" size="0.010738730430603027 0.014835407957434654" quat="0.8670938014984131 0.2554492652416229 -0.30630964040756226 0.2984432876110077"/>
          <geom class="collision" type="cylinder" pos="-0.07950039207935333 0.135133296251297 0.23928937315940857" size="0.010424953885376453 0.0144019341096282" quat="0.755740761756897 0.35412755608558655 -0.47815293073654175 0.2735312283039093"/>
          <geom class="collision" type="cylinder" pos="-0.09486466646194458 0.10810258239507675 0.24340298771858215" size="0.010484162718057632 0.016757162287831306" quat="0.6666451692581177 0.44615498185157776 -0.546674907207489 0.24015936255455017"/>
          <geom class="collision" type="cylinder" pos="-0.11060402542352676 0.08012466132640839 0.23531442880630493" size="0.011186142452061176 0.017792953178286552" quat="0.48275741934776306 0.5455015301704407 -0.6670209765434265 0.15638543665409088"/>
          <geom class="collision" type="cylinder" pos="-0.12134332209825516 0.057463571429252625 0.21556027233600616" size="0.010224497877061367 0.016100460663437843" quat="0.31250452995300293 0.6214025020599365 -0.7136070728302002 0.08345532417297363"/>
          <geom class="collision" type="cylinder" pos="-0.1290028691291809 0.04171176254749298 0.185683473944664" size="0.01005901675671339 0.01656615175306797" quat="0.10936148464679718 0.6737759113311768 -0.7270243167877197 0.07417364418506622"/>
          <geom class="collision" type="cylinder" pos="-0.131002277135849 0.038335949182510376 0.15161480009555817" size="0.0089662941172719 0.01852126605808735" quat="-0.006637726444751024 0.6839892268180847 -0.7293778657913208 0.011073256842792034"/>
          <geom class="collision" type="cylinder" pos="-0.053058695048093796 0.18088531494140625 0.18565408885478973" size="0.009657956659793854 0.013342335820198059" quat="0.9186800122261047 0.09213677048683167 -0.16663409769535065 0.34607934951782227"/>
        </body>
        <geom class="region" name="reg_main" type="box" pos="-7.450580596923828e-09 0.0 -0.1464393436908722" size="0.4084668457508087 0.23256176710128784 0.10692651569843292"/>
        <geom class="region" name="reg_basin_left" type="box" pos="-0.23170454800128937 -0.0006772875785827637 -0.1347910836338997" size="0.1345590502023697 0.18687570095062256 0.08016728609800339"/>
        <geom class="region" name="reg_basin_right" type="box" pos="0.004938986152410507 -0.0012628957629203796 -0.10136634856462479" size="0.058521222323179245 0.1255713477730751 0.046116046607494354"/>
      </body>
    </body>
  </worldbody>
  <actuator>
    <motor name="handle_joint_hinge_0_actuator" joint="handle_joint_hinge_0" gear="10"/>
    <motor name="handle_joint_hinge_1_actuator" joint="handle_joint_hinge_1" gear="10"/>
    <motor name="Funnel001_joint_actuator" joint="Funnel001_joint" gear="10"/>
    <motor name="Funnel002_joint_actuator" joint="Funnel002_joint" gear="10"/>
    <motor name="spout_joint_actuator" joint="spout_joint" gear="10"/>
  </actuator>
</mujoco>
