<mujoco model="model">
  <compiler angle="radian"/>
  <asset>
    <mesh file="visuals/Drawer003.obj" name="Drawer003_vis"/>
    <mesh file="visuals/Door002.obj" name="Door002_vis"/>
    <mesh file="visuals/Body001.obj" name="Body_vis"/>
    <mesh file="visuals/Drawer005.obj" name="Drawer005_vis"/>
    <mesh file="visuals/Handle001.obj" name="Handle_vis"/>
    <mesh file="visuals/Drawer004.obj" name="Drawer004_vis"/>
    <mesh file="visuals/Door001.obj" name="Door001_vis"/>
    <mesh file="visuals/Drawer001.obj" name="Drawer001_vis"/>
    <mesh file="visuals/Drawer002.obj" name="Drawer002_vis"/>
    <texture file="visuals/T_BC001.png" name="T_BC001" type="2d"/>
    <material name="material" rgba="1 1 1 1" texture="T_BC001"/>
  </asset>
  <default>
    <default class="visual">
      <geom conaffinity="0" contype="0" group="1" type="mesh"/>
    </default>
    <default class="collision">
      <geom group="0" rgba="0.5 0 0 0.5"/>
    </default>
  </default>
  <worldbody>
    <body>
      <site rgba="0 0 0 1" size="0.01" pos="-0.46126967668533325 -0.3841811753809452 0" name="ext_p0"/>
      <site rgba="1 0 0 1" size="0.01" pos="0.45174646377563477 -0.3841811753809452 0" name="ext_px"/>
      <site rgba="0 1 0 1" size="0.01" pos="-0.46126967668533325 0.29123982414603233 0" name="ext_py"/>
      <site rgba="0 0 1 1" size="0.01" pos="-0.46126967668533325 -0.3841811753809452 1.8319030404090881" name="ext_pz"/>
      <body name="object">
        <geom mesh="Body_vis" type="mesh" solimp="0.998 0.998 0.001" solref="0.001 1" density="100" friction="0.95 0.3 0.1" class="visual" material="material"/>
        <geom class="collision" type="box" pos="-0.005293257534503937 0.25214681029319763 0.9167069792747498" size="0.4374244213104248 0.03949582576751709 0.9129593372344971" quat="1.0 0.0 0.0 0.0"/>
        <geom class="collision" type="box" pos="-0.43354532122612 -0.045020490884780884 0.9167068600654602" size="0.25995519757270813 0.011771866120398045 0.9129593372344971" quat="0.7071067690849304 0.0 0.0 0.7071067690849304"/>
        <geom class="collision" type="box" pos="0.401600182056427 -0.05286172032356262 0.9167069792747498" size="0.26779642701148987 0.037873003631830215 0.9129593372344971" quat="0.7071067690849304 0.0 0.0 0.7071067690849304"/>
        <geom class="collision" type="box" pos="-0.00972273200750351 -0.02135169506072998 1.8029656410217285" size="0.37359267473220825 0.027519237250089645 0.22666874527931213" quat="0.7071067690849304 0.7071067690849304 0.0 0.0"/>
        <geom class="collision" type="box" pos="-0.009722769260406494 -0.023725837469100952 0.0656132698059082" size="0.37359267473220825 0.06236780434846878 0.2290429174900055" quat="0.7071067690849304 0.7071067690849304 0.0 0.0"/>
        <geom class="collision" type="box" pos="0.1555778831243515 0.08023038506507874 1.6712619066238403" size="0.20829200744628906 0.09889225661754608 0.1250866949558258" quat="0.7071067690849304 0.7071067690849304 0.0 0.0"/>
        <geom class="collision" type="box" pos="0.3263351023197174 -0.06993222236633301 1.7122163772583008" size="0.03881874680519104 0.05793765187263489 0.0519912913441658" quat="0.7071067690849304 0.7071067690849304 0.0 0.0"/>
        <geom class="collision" type="box" pos="-0.24310922622680664 0.09244880080223083 1.5521149635314941" size="0.1417512595653534 0.21803922951221466 0.11286826431751251" quat="0.7071067690849304 0.7071067690849304 0.0 0.0"/>
        <geom class="collision" type="box" pos="0.1537202149629593 -0.022540181875228882 1.4012720584869385" size="0.21014970541000366 0.007862658239901066 0.227857306599617" quat="0.7071067690849304 0.7071067690849304 0.0 0.0"/>
        <geom class="collision" type="box" pos="0.1537202149629593 -0.03351590037345886 0.9976363182067871" size="0.21014970541000366 0.007862628437578678 0.19998930394649506" quat="0.7071067690849304 0.7071067690849304 0.0 0.0"/>
        <geom class="collision" type="box" pos="0.15370331704616547 -0.033751457929611206 0.7595690488815308" size="0.21014970541000366 0.005173186305910349 0.198607936501503" quat="0.7071067690849304 0.7071067690849304 0.0 0.0"/>
        <geom class="collision" type="box" pos="0.1537202000617981 -0.02486911416053772 0.5777692794799805" size="0.21014970541000366 0.007862628437578678 0.20676138997077942" quat="0.7071067690849304 0.7071067690849304 0.0 0.0"/>
        <geom class="collision" type="box" pos="0.1537202149629593 -0.02254021167755127 0.377937912940979" size="0.21014970541000366 0.007862688042223454 0.227857306599617" quat="0.7071067690849304 0.7071067690849304 0.0 0.0"/>
        <geom class="collision" type="box" pos="0.1537202149629593 -0.02254021167755127 0.32982850074768066" size="0.21014970541000366 0.007862688042223454 0.227857306599617" quat="0.7071067690849304 0.7071067690849304 0.0 0.0"/>
        <geom class="collision" type="box" pos="0.1537202149629593 -0.00120621919631958 0.12525641918182373" size="0.21014970541000366 0.007862688042223454 0.257199764251709" quat="0.7071067690849304 0.7071067690849304 0.0 0.0"/>
        <geom class="collision" type="box" pos="-0.2404816746711731 -0.014164328575134277 0.13858234882354736" size="0.1114632710814476 0.007862688042223454 0.21948140859603882" quat="0.7071067690849304 0.7071067690849304 0.0 0.0"/>
        <geom class="collision" type="box" pos="-0.2404816746711731 -0.014164328575134277 0.3282371759414673" size="0.1114632710814476 0.007862688042223454 0.2194814234972" quat="0.7071067690849304 0.7071067690849304 0.0 0.0"/>
        <geom class="collision" type="box" pos="-0.2404816746711731 -0.01712942123413086 0.3792994022369385" size="0.1114632710814476 0.007862688042223454 0.19730238616466522" quat="0.7071067690849304 0.7071067690849304 0.0 0.0"/>
        <geom class="collision" type="box" pos="-0.24199116230010986 -0.01726868748664856 0.5767621994018555" size="0.13909411430358887 0.007862628437578678 0.19916094839572906" quat="0.7071067690849304 0.7071067690849304 0.0 0.0"/>
        <geom class="collision" type="box" pos="-0.24199116230010986 -0.024599164724349976 0.7620165348052979" size="0.13909411430358887 0.007862628437578678 0.19249916076660156" quat="0.7071067690849304 0.7071067690849304 0.0 0.0"/>
        <geom class="collision" type="box" pos="-0.24199116230010986 -0.02569243311882019 0.9983807802200317" size="0.13909411430358887 0.007862628437578678 0.2079533040523529" quat="0.7071067690849304 0.7071067690849304 0.0 0.0"/>
        <body name="Door001">
          <joint axis="0 0 -1" pos="-0.44410377740859985 -0.3309522569179535 0.9901764988899231" limited="true" name="Door001_joint" range="0.0 1.5707963267948966" type="hinge" damping="2" frictionloss="2" armature=".01"/>
          <geom mesh="Door001_vis" type="mesh" solimp="0.998 0.998 0.001" solref="0.001 1" density="100" friction="0.95 0.3 0.1" class="visual" material="material"/>
          <geom class="collision" type="box" pos="-0.25748080015182495 -0.3503991365432739 1.530963659286499" size="0.1899232268333435 0.013005027547478676 0.2996883690357208" quat="1.0 0.0 0.0 0.0"/>
          <geom class="collision" type="box" pos="-0.25748080015182495 -0.3514115810394287 0.5292534828186035" size="0.1899232119321823 0.014017444103956223 0.48075127601623535" quat="1.0 0.0 0.0 0.0"/>
          <geom class="collision" type="box" pos="-0.10625124722719193 -0.3476645350456238 1.1195974349975586" size="0.0379159152507782 0.017764508724212646 0.1098945140838623" quat="1.0 0.0 0.0 0.0"/>
          <geom class="collision" type="box" pos="-0.4100177586078644 -0.3516649007797241 1.1195974349975586" size="0.0379159152507782 0.013764157891273499 0.1098945140838623" quat="1.0 0.0 0.0 0.0"/>
          <geom class="collision" type="box" pos="-0.25330278277397156 -0.2654990553855896 1.1231642961502075" size="0.13221579790115356 0.005332309287041426 0.10632762312889099" quat="1.0 0.0 0.0 0.0"/>
          <geom class="collision" type="box" pos="-0.13727006316184998 -0.28971654176712036 1.1195974349975586" size="0.0379159152507782 0.017764510586857796 0.1098945140838623" quat="0.8265343308448792 0.0 -0.0 -0.5628862977027893"/>
          <geom class="collision" type="box" pos="-0.36257413029670715 -0.30063432455062866 1.1195974349975586" size="0.0379159115254879 0.017764506861567497 0.1098945140838623" quat="0.5716685652732849 0.0 -0.0 -0.8204846382141113"/>
          <geom class="collision" type="box" pos="-0.25330278277397156 -0.31323930621147156 1.0078437328338623" size="0.13221579790115356 0.047921545803546906 0.005977928638458252" quat="1.0 0.0 0.0 0.0"/>
          <geom class="collision" type="box" pos="-0.25330278277397156 -0.31323930621147156 1.2323603630065918" size="0.13221579790115356 0.047921545803546906 0.005977928638458252" quat="1.0 0.0 0.0 0.0"/>
          <geom class="collision" type="box" pos="-0.1038600504398346 -0.3725490868091583 1.4482815265655518" size="0.00857405923306942 0.009465521201491356 0.02023090422153473" quat="1.0 0.0 0.0 0.0"/>
          <geom class="collision" type="box" pos="-0.1038600504398346 -0.3725490868091583 0.6399979591369629" size="0.00857405923306942 0.009465521201491356 0.020230889320373535" quat="1.0 0.0 0.0 0.0"/>
          <geom class="collision" type="box" pos="-0.10363401472568512 -0.3849431574344635 1.0535911321640015" size="0.014793716371059418 0.006026113405823708 0.5130878686904907" quat="1.0 0.0 0.0 0.0"/>
          <body name="Handle">
            <joint axis="1 0 0" pos="-0.2558513283729553 -0.2820841372013092 1.2418583631515503" limited="true" name="Handle_joint" range="0.0 0.3490658503988659" type="hinge" damping="2" frictionloss="2" armature=".01"/>
            <geom mesh="Handle_vis" type="mesh" solimp="0.998 0.998 0.001" solref="0.001 1" density="100" friction="0.95 0.3 0.1" class="visual" material="material"/>
            <geom class="collision" type="cylinder" pos="-0.2918999195098877 -0.3000887632369995 1.1734740734100342" size="0.0037970244884490967 0.07050818204879761" quat="0.9914913773536682 -0.13017241656780243 2.890408280893429e-17 3.456903660370636e-24"/>
            <geom class="collision" type="cylinder" pos="-0.21884016692638397 -0.3000887632369995 1.1734740734100342" size="0.0037970393896102905 0.07050818204879761" quat="0.9914913773536682 -0.13017241656780243 2.890408280893429e-17 3.456903660370636e-24"/>
          </body>
        </body>
        <body name="Door002">
          <joint axis="0 0 1" pos="0.44647812843322754 -0.3323929011821747 0.9939188361167908" limited="true" name="Door002_joint" range="0.0 1.5707963267948966" type="hinge" damping="2" frictionloss="2" armature=".01"/>
          <geom mesh="Door002_vis" type="mesh" solimp="0.998 0.998 0.001" solref="0.001 1" density="100" friction="0.95 0.3 0.1" class="visual" material="material"/>
          <geom class="collision" type="box" pos="-0.026552699506282806 -0.3725490868091583 1.4482815265655518" size="0.00857405737042427 0.009465521201491356 0.02023090422153473" quat="1.0 0.0 0.0 0.0"/>
          <geom class="collision" type="box" pos="-0.026552699506282806 -0.3725490868091583 0.6399979591369629" size="0.00857405737042427 0.009465521201491356 0.020230889320373535" quat="1.0 0.0 0.0 0.0"/>
          <geom class="collision" type="box" pos="-0.02632666379213333 -0.3849431574344635 1.0535911321640015" size="0.014793716371059418 0.006026113405823708 0.5130878686904907" quat="1.0 0.0 0.0 0.0"/>
          <geom class="collision" type="box" pos="0.19102764129638672 -0.3503991365432739 0.9402107000350952" size="0.2529553174972534 0.013005027547478676 0.8904412984848022" quat="1.0 0.0 0.0 0.0"/>
        </body>
        <body name="Drawer001">
          <joint axis="0 -1 0" pos="0.15352316200733185 -0.07253031432628632 0.6659571528434753" limited="true" name="Drawer001_joint" range="0.0 0.25" type="slide" damping="2" frictionloss="2" armature=".01"/>
          <geom mesh="Drawer001_vis" type="mesh" solimp="0.998 0.998 0.001" solref="0.001 1" density="100" friction="0.95 0.3 0.1" class="visual" material="material"/>
          <geom class="collision" type="cylinder" pos="0.15306535363197327 -0.03770598769187927 0.6020026803016663" size="0.17777684330940247 0.0049169063568115234" quat="1.0 0.0 0.0 0.0"/>
          <geom class="collision" type="cylinder" pos="-0.019196510314941406 -0.03895103931427002 0.673943817615509" size="0.07536381483078003 0.00491691380739212" quat="0.7071068286895752 -0.0 0.7071067690849304 0.0"/>
          <geom class="collision" type="cylinder" pos="0.3295198678970337 -0.03418126702308655 0.673943817615509" size="0.07536381483078003 0.0049169063568115234" quat="0.7071068286895752 -0.0 0.7071067690849304 0.0"/>
          <geom class="collision" type="box" pos="0.15218345820903778 -0.2580401301383972 0.673943817615509" size="0.07536381483078003 0.17529931664466858 0.004916910082101822" quat="0.5 -0.5 0.4999999701976776 0.5"/>
          <geom class="collision" type="cylinder" pos="0.15265284478664398 0.15061014890670776 0.6739439368247986" size="0.07536381483078003 0.0049169063568115234" quat="0.5 -0.5 0.4999999701976776 0.5"/>
        </body>
        <body name="Drawer002">
          <joint axis="0 -1 0" pos="0.15371638536453247 -0.07498643547296524 0.4734061658382416" limited="true" name="Drawer002_joint" range="0.0 0.25" type="slide" damping="2" frictionloss="2" armature=".01"/>
          <geom mesh="Drawer002_vis" type="mesh" solimp="0.998 0.998 0.001" solref="0.001 1" density="100" friction="0.95 0.3 0.1" class="visual" material="material"/>
          <geom class="collision" type="cylinder" pos="0.15306535363197327 -0.050338178873062134 0.40595340728759766" size="0.17777684330940247 0.0049169063568115234" quat="1.0 0.0 0.0 0.0"/>
          <geom class="collision" type="cylinder" pos="-0.01919650472700596 -0.045695096254348755 0.48191404342651367" size="0.07938319444656372 0.00491691380739212" quat="0.7071068286895752 -0.0 0.7071067690849304 0.0"/>
          <geom class="collision" type="cylinder" pos="0.3295198380947113 -0.034181296825408936 0.48191404342651367" size="0.07938319444656372 0.004916921257972717" quat="0.7071068286895752 -0.0 0.7071067690849304 0.0"/>
          <geom class="collision" type="box" pos="0.15218345820903778 -0.2661961019039154 0.48191404342651367" size="0.0793832540512085 0.17529931664466858 0.004916910082101822" quat="0.5 -0.5 0.4999999701976776 0.5"/>
          <geom class="collision" type="cylinder" pos="0.15265284478664398 0.15061014890670776 0.48191404342651367" size="0.0793832540512085 0.0049169063568115234" quat="0.5 -0.5 0.4999999701976776 0.5"/>
        </body>
        <body name="Drawer003">
          <joint axis="0 -1 0" pos="0.15352284908294678 -0.07257768511772156 0.23153963685035706" limited="true" name="Drawer003_joint" range="0.0 0.25" type="slide" damping="2" frictionloss="2" armature=".01"/>
          <geom mesh="Drawer003_vis" type="mesh" solimp="0.998 0.998 0.001" solref="0.001 1" density="100" friction="0.95 0.3 0.1" class="visual" material="material"/>
          <geom class="collision" type="cylinder" pos="0.15306535363197327 -0.06352373957633972 0.14725303649902344" size="0.17777684330940247 0.0049169063568115234" quat="1.0 0.0 0.0 0.0"/>
          <geom class="collision" type="cylinder" pos="-0.01919650286436081 -0.049838513135910034 0.22936081886291504" size="0.08553045988082886 0.00491691380739212" quat="0.7071068286895752 -0.0 0.7071067690849304 0.0"/>
          <geom class="collision" type="cylinder" pos="0.3295198082923889 -0.03418126702308655 0.22936081886291504" size="0.08553045988082886 0.0049169063568115234" quat="0.7071068286895752 -0.0 0.7071067690849304 0.0"/>
          <geom class="collision" type="box" pos="0.15218345820903778 -0.2621457874774933 0.22936081886291504" size="0.08553051948547363 0.17529931664466858 0.004916910082101822" quat="0.5 -0.5 0.4999999701976776 0.5"/>
          <geom class="collision" type="cylinder" pos="0.15265284478664398 0.15061014890670776 0.22936081886291504" size="0.08553051948547363 0.0049169063568115234" quat="0.5 -0.5 0.4999999701976776 0.5"/>
        </body>
        <body name="Drawer004">
          <joint axis="0 -1 0" pos="-0.2421857863664627 -0.0790637880563736 0.47158169746398926" limited="true" name="Drawer004_joint" range="0.0 0.25" type="slide" damping="2" frictionloss="2" armature=".01"/>
          <geom mesh="Drawer004_vis" type="mesh" solimp="0.998 0.998 0.001" solref="0.001 1" density="100" friction="0.95 0.3 0.1" class="visual" material="material"/>
          <geom class="collision" type="cylinder" pos="-0.24295136332511902 -0.042837828397750854 0.40562963485717773" size="0.10794781148433685 0.0049169063568115234" quat="1.0 0.0 0.0 0.0"/>
          <geom class="collision" type="cylinder" pos="-0.3453842103481293 -0.049988240003585815 0.4814944267272949" size="0.07928746938705444 0.0049169063568115234" quat="0.7071068286895752 -0.0 0.7071067690849304 0.0"/>
          <geom class="collision" type="cylinder" pos="-0.1363259255886078 -0.049988240003585815 0.4814944267272949" size="0.07928746938705444 0.00491691380739212" quat="0.7071068286895752 -0.0 0.7071067690849304 0.0"/>
          <geom class="collision" type="box" pos="-0.2438332438468933 -0.2663266956806183 0.4814945459365845" size="0.07928746938705444 0.10547029972076416 0.004916910082101822" quat="0.5 -0.5 0.4999999701976776 0.5"/>
          <geom class="collision" type="cylinder" pos="-0.2433638572692871 0.15061014890670776 0.4814944267272949" size="0.07928752899169922 0.0049169063568115234" quat="0.5 -0.5 0.4999999701976776 0.5"/>
        </body>
        <body name="Drawer005">
          <joint axis="0 -1 0" pos="-0.24237719178199768 -0.08302593231201172 0.23122304677963257" limited="true" name="Drawer005_joint" range="0.0 0.25" type="slide" damping="2" frictionloss="2" armature=".01"/>
          <geom mesh="Drawer005_vis" type="mesh" solimp="0.998 0.998 0.001" solref="0.001 1" density="100" friction="0.95 0.3 0.1" class="visual" material="material"/>
          <geom class="collision" type="cylinder" pos="-0.24295136332511902 -0.053573161363601685 0.16390109062194824" size="0.10794781148433685 0.0049169063568115234" quat="1.0 0.0 0.0 0.0"/>
          <geom class="collision" type="cylinder" pos="-0.3453842103481293 -0.049838513135910034 0.23976576328277588" size="0.07928746938705444 0.0049169063568115234" quat="0.7071068286895752 -0.0 0.7071067690849304 0.0"/>
          <geom class="collision" type="cylinder" pos="-0.1363259255886078 -0.049838513135910034 0.23976576328277588" size="0.07928740978240967 0.00491691380739212" quat="0.7071068286895752 -0.0 0.7071067690849304 0.0"/>
          <geom class="collision" type="box" pos="-0.2438332438468933 -0.26849302649497986 0.23976576328277588" size="0.07928752899169922 0.10547029972076416 0.00491691380739212" quat="0.5 -0.5 0.4999999701976776 0.5"/>
          <geom class="collision" type="cylinder" pos="-0.2433638572692871 0.15061014890670776 0.23976576328277588" size="0.07928746938705444 0.0049169063568115234" quat="0.5 -0.5 0.4999999701976776 0.5"/>
        </body>
      </body>
    </body>
  </worldbody>
  <actuator>
    <motor name="Door001_joint_actuator" joint="Door001_joint" gear="10"/>
    <motor name="Door002_joint_actuator" joint="Door002_joint" gear="10"/>
    <motor name="Drawer001_joint_actuator" joint="Drawer001_joint" gear="10"/>
    <motor name="Drawer002_joint_actuator" joint="Drawer002_joint" gear="10"/>
    <motor name="Drawer003_joint_actuator" joint="Drawer003_joint" gear="10"/>
    <motor name="Drawer004_joint_actuator" joint="Drawer004_joint" gear="10"/>
    <motor name="Drawer005_joint_actuator" joint="Drawer005_joint" gear="10"/>
    <motor name="Handle_joint_actuator" joint="Handle_joint" gear="10"/>
  </actuator>
</mujoco>
