<mujoco model="model">
  <compiler angle="radian"/>
  <asset>
    <mesh file="visuals/handle.obj" name="handle_vis"/>
    <mesh file="visuals/Body001.obj" name="Body001_vis"/>
    <mesh file="visuals/Funnel001.obj" name="Funnel001_vis"/>
    <mesh file="visuals/Funnel002.obj" name="Funnel002_vis"/>
    <mesh file="visuals/spout.obj" name="spout_vis"/>
    <texture file="visuals/T_BC001.png" name="Body001_material" type="2d"/>
    <material name="Body001_material" rgba="1 1 1 1.0" texture="Body001_material" shininess="0.4472135901451111" specular="0.3103448502657381"/>
    <texture file="visuals/T_BC001.png" name="handle_material" type="2d"/>
    <material name="handle_material" rgba="1 1 1 1.0" texture="handle_material" shininess="0.4472135901451111" specular="0.3103448502657381"/>
    <texture file="visuals/T_BC001.png" name="Funnel001_material" type="2d"/>
    <material name="Funnel001_material" rgba="1 1 1 1.0" texture="Funnel001_material" shininess="0.4472135901451111" specular="0.3103448502657381"/>
    <texture file="visuals/T_BC001.png" name="Funnel002_material" type="2d"/>
    <material name="Funnel002_material" rgba="1 1 1 1.0" texture="Funnel002_material" shininess="0.4472135901451111" specular="0.3103448502657381"/>
    <texture file="visuals/T_BC001.png" name="spout_material" type="2d"/>
    <material name="spout_material" rgba="1 1 1 1.0" texture="spout_material" shininess="0.4472135901451111" specular="0.3103448502657381"/>
  </asset>
  <default>
    <default class="visual">
      <geom conaffinity="0" contype="0" group="1" type="mesh"/>
    </default>
    <default class="collision">
      <geom group="0" rgba="0.5 0 0 0.5"/>
    </default>
    <default class="spawn">
      <geom group="0" rgba="1 1 1 0.5" contype="0" conaffinity="0"/>
      <site group="0" rgba="1 1 1 0.5"/>
    </default>
    <default class="region">
      <geom group="1" conaffinity="0" contype="0" rgba="0 1 0 0"/>
    </default>
  </default>
  <worldbody>
    <body>
      <body name="object">
        <geom mesh="Body001_vis" type="mesh" solimp="0.998 0.998 0.001" solref="0.001 1" density="100" friction="0.95 0.3 0.1" class="visual" material="Body001_material"/>
        <geom class="collision" type="box" pos="-0.4688240885734558 -0.025442225858569145 -0.17972242832183838" size="0.017692016437649727 0.18879583477973938 0.13597573339939117" quat="1.0 0.0 0.0 0.0"/>
        <geom class="collision" type="box" pos="-0.0005250170361250639 -0.025442225858569145 -0.14310631155967712" size="0.015185253694653511 0.1887967437505722 0.10022661834955215" quat="1.0 0.0 0.0 0.0"/>
        <geom class="collision" type="box" pos="0.47088247537612915 -0.025442225858569145 -0.14448444545269012" size="0.017809739336371422 0.18879598379135132 0.1001676395535469" quat="1.0 0.0 0.0 0.0"/>
        <geom class="collision" type="box" pos="-0.00048047304153442383 0.20637015998363495 -0.17972242832183838" size="0.4881691336631775 0.04013274610042572 0.1359759122133255" quat="1.0 0.0 0.0 0.0"/>
        <geom class="collision" type="box" pos="-0.00048047304153442383 -0.231595978140831 -0.17972242832183838" size="0.48816943168640137 0.017473556101322174 0.13597597181797028" quat="1.0 0.0 0.0 0.0"/>
        <geom class="collision" type="box" pos="0.00044145656283944845 -0.025442227721214294 -0.28166231513023376" size="0.18996965885162354 0.18879622220993042 0.031054990366101265" quat="1.0 0.0 0.0 0.0"/>
        <geom class="collision" type="box" pos="0.36437296867370605 -0.025442227721214294 -0.28166231513023376" size="0.0871833935379982 0.1887962967157364 0.031054990366101265" quat="1.0 0.0 0.0 0.0"/>
        <geom class="collision" type="box" pos="-0.3629124164581299 -0.025442227721214294 -0.28166231513023376" size="0.08718343079090118 0.18879637122154236 0.031054990366101265" quat="1.0 0.0 0.0 0.0"/>
        <geom class="collision" type="box" pos="-0.23297733068466187 -0.10285942256450653 -0.28166231513023376" size="0.041802000254392624 0.11137925088405609 0.031054990366101265" quat="1.0 0.0 0.0 0.0"/>
        <geom class="collision" type="box" pos="-0.23297733068466187 0.13056351244449615 -0.28166231513023376" size="0.041802018880844116 0.03260359913110733 0.031054990366101265" quat="1.0 0.0 0.0 0.0"/>
        <geom class="collision" type="box" pos="0.23444999754428864 0.13022543489933014 -0.28166231513023376" size="0.04180203750729561 0.032941680401563644 0.031054990366101265" quat="1.0 0.0 0.0 0.0"/>
        <geom class="collision" type="box" pos="0.23445001244544983 -0.10195980966091156 -0.28166231513023376" size="0.0418020561337471 0.11227908730506897 0.031054990366101265" quat="1.0 0.0 0.0 0.0"/>
        <geom class="collision" type="cylinder" pos="-0.2331215888261795 0.053658485412597656 -0.30161380767822266" size="0.0638626217842102 0.011342408135533333" quat="1.0 0.0 0.0 0.0"/>
        <geom class="collision" type="cylinder" pos="0.2341102659702301 0.053658485412597656 -0.3017972707748413" size="0.0638626217842102 0.011158940382301807" quat="1.0 0.0 0.0 0.0"/>
        <geom class="collision" type="cylinder" pos="-0.00014972896315157413 0.20837345719337463 0.03174792602658272" size="0.025186479091644287 0.07796847820281982" quat="1.0 0.0 0.0 0.0"/>
        <geom class="collision" type="cylinder" pos="0.03975735604763031 0.20696187019348145 0.030607126653194427" size="0.020408621057868004 0.02134617045521736" quat="1.3767878215276141e-07 0.7071068286895752 -1.3767875373105198e-07 0.7071067094802856"/>
        <geom class="collision" type="cylinder" pos="0.05941198393702507 0.20696187019348145 0.030607126653194427" size="0.01566932164132595 0.007974190637469292" quat="1.3767878215276141e-07 0.7071068286895752 -1.3767875373105198e-07 0.7071067094802856"/>
        <body name="handle">
          <joint axis="1.0 0.0 0.0" pos="0.0819985568523407 0.20718786120414734 0.030960608273744583" limited="true" name="handle_joint_hinge_0" type="hinge" range="-0.7853981633974483 0.7853981633974483" damping="1" frictionloss="1" armature=".01" stiffness="0.05"/>
          <joint axis="0.0 1.0 0.0" pos="0.0819985568523407 0.20718786120414734 0.030960608273744583" limited="true" name="handle_joint_hinge_1" type="hinge" range="0.0 0.17453292519943295" damping="1" frictionloss="1" armature=".01" stiffness="0.05"/>
          <geom mesh="handle_vis" type="mesh" solimp="0.998 0.998 0.001" solref="0.001 1" density="100" friction="0.95 0.3 0.1" class="visual" material="handle_material"/>
          <geom class="collision" type="cylinder" pos="0.08489503711462021 0.20696187019348145 0.030607124790549278" size="0.020408619195222855 0.010828463360667229" quat="1.3767878215276141e-07 0.7071068286895752 -1.3767875373105198e-07 0.7071067094802856"/>
          <geom class="collision" type="cylinder" pos="0.08910184353590012 0.20837345719337463 0.08650544285774231" size="0.004830267746001482 0.036618586629629135" quat="7.549790836947068e-08 1.0 -1.6292068494294654e-07 7.549789415861596e-08"/>
        </body>
        <body name="Funnel001">
          <joint axis="0.0 0.0 1.0" pos="-0.23377270996570587 0.05327993631362915 -0.2681823968887329" limited="true" name="Funnel001_joint" range="0.0 0.08" type="slide" damping="1" frictionloss="1" armature=".01" stiffness="0.05"/>
          <geom mesh="Funnel001_vis" type="mesh" solimp="0.998 0.998 0.001" solref="0.001 1" density="100" friction="0.95 0.3 0.1" class="visual" material="Funnel001_material"/>
          <geom class="collision" type="cylinder" pos="-0.2331215888261795 0.053658485412597656 -0.2684289216995239" size="0.04160851240158081 0.005387522745877504" quat="1.0 0.0 0.0 0.0"/>
          <geom class="collision" type="cylinder" pos="-0.2331215888261795 0.053658485412597656 -0.2624143958091736" size="0.009606130421161652 0.001243814011104405" quat="1.0 0.0 0.0 0.0"/>
        </body>
        <body name="Funnel002">
          <joint axis="0.0 0.0 1.0" pos="0.23377270996570587 0.05328001827001572 -0.2681823968887329" limited="true" name="Funnel002_joint" range="0.0 0.08" type="slide" damping="1" frictionloss="1" armature=".01" stiffness="0.05"/>
          <geom mesh="Funnel002_vis" type="mesh" solimp="0.998 0.998 0.001" solref="0.001 1" density="100" friction="0.95 0.3 0.1" class="visual" material="Funnel002_material"/>
          <geom class="collision" type="cylinder" pos="0.23389877378940582 0.053658485412597656 -0.2684289216995239" size="0.04160851240158081 0.005387522745877504" quat="1.0 0.0 0.0 0.0"/>
          <geom class="collision" type="cylinder" pos="0.23389877378940582 0.053658485412597656 -0.2632989287376404" size="0.008709521032869816 0.0027029607445001602" quat="1.0 0.0 0.0 0.0"/>
        </body>
        <body name="spout">
          <joint axis="0.0 0.0 1.0" pos="-0.00010259231203235686 0.2080770581960678 0.18622417747974396" limited="true" name="spout_joint" range="-0.7853981633974483 0.7853981633974483" type="hinge" damping="1" frictionloss="1" armature=".01" stiffness="0.05"/>
          <site type="cylinder" rgba="0.5 0.75 1 1" size="0.008077822625637054 0.25433674454689026" pos="-0.00022850713867228478 -0.006902423687279224 0.014040738344192505" name="water"/>
          <geom mesh="spout_vis" type="mesh" solimp="0.998 0.998 0.001" solref="0.001 1" density="100" friction="0.95 0.3 0.1" class="visual" material="spout_material"/>
          <geom class="collision" type="cylinder" pos="-0.00022850713867228478 0.2069898098707199 0.17759908735752106" size="0.014976673759520054 0.06626234948635101" quat="1.0 0.0 0.0 0.0"/>
          <geom class="collision" type="cylinder" pos="4.6260698582045734e-05 0.06275240331888199 0.2975461781024933" size="0.014976673759520054 0.08919991552829742" quat="0.7071068286895752 0.7071067690849304 -1.5700924318127872e-16 -5.9269340452702814e-24"/>
          <geom class="collision" type="cylinder" pos="-0.00022851070389151573 0.2002333104610443 0.25821176171302795" size="0.014976675622165203 0.020353922620415688" quat="0.982413113117218 0.1867203712463379 -4.146025768229317e-17 1.6905972352430204e-23"/>
          <geom class="collision" type="cylinder" pos="-0.00022850713867228478 -0.006902423687279224 0.27870461344718933" size="0.010961321182549 0.009372392669320107" quat="7.549790126404332e-08 1.0 -2.220446049250313e-16 -1.7645063234279917e-24"/>
          <geom class="collision" type="cylinder" pos="-0.00022851070389151573 0.18160898983478546 0.28285831212997437" size="0.014976675622165203 0.020353922620415688" quat="0.8874186277389526 0.4609643816947937 -1.023546738702665e-16 6.925955778681676e-24"/>
          <geom class="collision" type="cylinder" pos="-0.00022851070389151573 0.15852375328540802 0.2951258420944214" size="0.014976675622165203 0.012227360159158707" quat="0.7861025929450989 0.6180960536003113 -1.372449072622919e-16 2.2254117968248472e-23"/>
        </body>
        <geom class="region" name="reg_main" type="box" pos="3.725290298461914e-08 -7.450580596923828e-08 -0.17865458130836487" size="0.48679661750793457 0.24702522158622742 0.13331298530101776"/>
        <geom class="region" name="reg_basin_left" type="box" pos="-0.23525888845324516 -0.0255730003118515 -0.15019121579825878" size="0.21397064998745918 0.18765230476856232 0.10056075640022755"/>
        <geom class="region" name="reg_basin_right" type="box" pos="0.23353380430489779 -0.025940850377082825 -0.14828085713088512" size="0.21497985254973173 0.18821710348129272 0.09865039773285389"/>
      </body>
    </body>
  </worldbody>
  <actuator>
    <motor name="handle_joint_hinge_0_actuator" joint="handle_joint_hinge_0" gear="10"/>
    <motor name="handle_joint_hinge_1_actuator" joint="handle_joint_hinge_1" gear="10"/>
    <motor name="Funnel001_joint_actuator" joint="Funnel001_joint" gear="10"/>
    <motor name="Funnel002_joint_actuator" joint="Funnel002_joint" gear="10"/>
    <motor name="spout_joint_actuator" joint="spout_joint" gear="10"/>
  </actuator>
</mujoco>
