<mujoco model="model">
  <compiler angle="radian"/>
  <asset>
    <texture file="visuals/material_0.png" name="tex-model" type="2d"/>
    <texture type="2d" name="image0" file="visuals/image0.png"/>
    <material name="model" reflectance="0.5" texrepeat="1 1" texture="tex-model" texuniform="false"/>
    <material name="Baked_Microwave" texture="image0" specular="0.5" shininess="0.25"/>
    <material name="Door_Inside" specular="0.5" shininess="0.25" rgba="0.3059 0.3059 0.3059 1"/>
    <mesh file="visuals/model_0.obj" name="model_0_vis" scale="1 1 1"/>
    <mesh file="visuals/door_0.obj" name="door_0_vis" scale="1 1 1"/>
  </asset>
  <default>
    <default class="visual">
      <geom conaffinity="0" contype="0" group="1" type="mesh"/>
    </default>
    <default class="collision">
      <geom group="0" rgba="0.5 0 0 0.5"/>
    </default>
    <default class="region">
      <geom group="1" conaffinity="0" contype="0" rgba="0 1 0 0"/>
    </default>
  </default>
  <worldbody>
    <body>
      <body name="object">
        <geom solimp="0.998 0.998 0.001" solref="0.001 1" density="100" friction="0.95 0.3 0.1" type="mesh" mesh="model_0_vis" material="Baked_Microwave" class="visual"/>
        <!-- Back Wall -->
        <geom class="collision" type="box" pos="0 0.262 0.005" size="0.5 0.005 0.285"/>
        <!-- Floor -->
        <geom class="collision" type="box" pos="0 0.067 -0.283" size="0.5 0.2 0.005"/>
        <!-- Top -->
        <geom class="collision" type="box" pos="0 0.067 0.29" size="0.5 0.2 0.005"/>
        <!-- Left Wall-->
        <geom class="collision" type="box" pos="-0.5 0.067 0.005" size="0.005 0.2 0.285"/>
        <!-- Right Wall-->
        <geom class="collision" type="box" pos="0.5 0.067 0.005" size="0.005 0.2 0.285"/>
        <!-- Keypad -->
        <geom class="collision" type="box" pos="0.393 -0.174 0.225" size="0.101 0.041 0.065"/>
        <geom class="collision" type="box" pos="0.393 -0.174 -0.24" size="0.101 0.041 0.04"/>
        <geom class="collision" type="box" pos="0.47 -0.174 -0.02" size="0.025 0.041 0.18"/>
        <geom class="collision" type="box" pos="0.37 -0.174 -0.02" size="0.075 0.0215 0.18"/>
        <!-- start/stop buttons -->
        <geom class="collision" type="box" pos="0.41 -0.174 -0.13" size="0.03 0.0216 0.025" name="start_button" rgba="0.0 0.5 0 0.5"/>
        <geom class="collision" type="box" pos="0.335 -0.174 -0.13" size="0.03 0.0216 0.025" name="stop_button" rgba="0.0 0.5 0 0.5"/>
        <geom class="collision" type="cylinder" pos="-0.09 0.07 -0.282" size="0.19 0.005" rgba="0 1 0 0.5" name="tray"/>
        <!-- Bottom gaps fixes -->
        <geom class="visual" type="box" pos="0 -0.095 -0.285" size="0.45 0.008 0.002" axisangle="1 0 0 -0.6"/>
        <geom class="visual" type="box" pos="0 0.227 -0.285" size="0.45 0.009 0.002" axisangle="1 0 0 0.6"/>
        <body name="door">
          <joint axis="0 0 1" limited="true" name="microjoint" range="-1.57 0" damping="2" frictionloss="2" armature=".01" pos="-0.471 -0.178 0"/>
          <geom solimp="0.998 0.998 0.001" solref="0.001 1" density="100" friction="0.95 0.3 0.1" type="mesh" mesh="door_0_vis" material="Baked_Microwave" class="visual"/>
          <!-- Door -->
          <geom class="collision" type="box" pos="-0.067 -0.174 0.005" size="0.351 0.041 0.275" name="door_main"/>
          <!-- Handle Top -->
          <geom class="collision" type="box" pos="0.254 -0.22 0.18" size="0.023 0.02 0.021"/>
          <!-- Handle Bottom -->
          <geom class="collision" type="box" pos="0.254 -0.22 -0.23" size="0.023 0.02 0.021"/>
          <!-- Handle Main -->
          <geom class="collision" type="box" pos="0.254 -0.248 -0.02" size="0.023 0.016 0.21" name="door_handle_main"/>
          <!-- Door inside gap fixes -->
          <geom class="visual" type="box" pos="0.2325 -0.165 -0.022" size="0.054 0.03 0.185" material="Door_Inside"/>
          <geom class="visual" type="box" pos="-0.435 -0.165 -0.022" size="0.03 0.03 0.185" material="Door_Inside"/>
          <geom class="visual" type="box" pos="-0.113 -0.165 -0.185" size="0.293 0.03 0.02" material="Door_Inside"/>
          <geom class="visual" type="box" pos="-0.113 -0.165 0.1125" size="0.293 0.03 0.047" material="Door_Inside"/>
        </body>
        <!-- exterior bounding box points -->
        <geom class="region" name="reg_main" type="box" pos="0.0 0.02750000000000001 0.0015000000000000013" size="0.51 0.2425 0.2915"/>
        <!-- interior bounding box points -->
        <geom class="region" name="reg_int" type="box" pos="-0.0025000000000000022 0.065 0.007499999999999979" size="0.4925 0.195 0.2825"/>
      </body>
    </body>
  </worldbody>
</mujoco>
