<mujoco model="model">
  <compiler angle="radian"/>
  <asset>
    <mesh file="visuals/Body001.obj" name="Body001_vis"/>
    <mesh file="visuals/Button001.obj" name="Button001_vis"/>
    <mesh file="visuals/Button002.obj" name="Button002_vis"/>
    <mesh file="visuals/Container001_Clear.obj" name="Container001_Clear_vis"/>
    <mesh file="visuals/Lid001.obj" name="Lid001_vis"/>
    <mesh file="visuals/Lid002.obj" name="Lid002_vis"/>
    <mesh file="visuals/Lid003.obj" name="Lid003_vis"/>
    <texture file="visuals/T_BC001.png" name="Body001_material" type="2d"/>
    <material name="Body001_material" rgba="1 1 1 1.0" texture="Body001_material" shininess="0.4472135901451111" specular="0.3103448502657381"/>
    <texture file="visuals/T_BC001.png" name="Button001_material" type="2d"/>
    <material name="Button001_material" rgba="1 1 1 1.0" texture="Button001_material" shininess="0.4472135901451111" specular="0.3103448502657381"/>
    <texture file="visuals/T_BC001.png" name="Button002_material" type="2d"/>
    <material name="Button002_material" rgba="1 1 1 1.0" texture="Button002_material" shininess="0.4472135901451111" specular="0.3103448502657381"/>
    <texture file="visuals/T_BC001.png" name="Container001_Clear_material" type="2d"/>
    <material name="Container001_Clear_material" rgba="1 1 1 0.08298748731613159" texture="Container001_Clear_material" shininess="0.4472135901451111" specular="0.3103448502657381"/>
    <texture file="visuals/T_BC001.png" name="Lid003_material" type="2d"/>
    <material name="Lid003_material" rgba="1 1 1 1.0" texture="Lid003_material" shininess="0.4472135901451111" specular="0.3103448502657381"/>
    <texture file="visuals/T_BC001.png" name="Lid001_material" type="2d"/>
    <material name="Lid001_material" rgba="1 1 1 1.0" texture="Lid001_material" shininess="0.4472135901451111" specular="0.3103448502657381"/>
    <texture file="visuals/T_BC001.png" name="Lid002_material" type="2d"/>
    <material name="Lid002_material" rgba="1 1 1 1.0" texture="Lid002_material" shininess="0.4472135901451111" specular="0.3103448502657381"/>
  </asset>
  <default>
    <default class="visual">
      <geom conaffinity="0" contype="0" group="1" type="mesh"/>
    </default>
    <default class="collision">
      <geom group="0" rgba="0.5 0 0 0.5"/>
    </default>
    <default class="spawn">
      <geom group="0" rgba="1 1 1 0.5" contype="0" conaffinity="0"/>
      <site group="0" rgba="1 1 1 0.5"/>
    </default>
    <default class="region">
      <geom group="1" conaffinity="0" contype="0" rgba="0 1 0 0"/>
    </default>
  </default>
  <worldbody>
    <body>
      <body name="object">
        <geom class="collision" type="box" pos="-0.01420377753674984 -0.13234372437000275 0.06485065072774887" size="0.006449845153838396 0.0006654085591435432 0.006449845153838396" quat="1.0 0.0 0.0 0.0" name="start_button_1" rgba="0.0 0.5 0 0.5"/>
        <geom class="collision" type="box" pos="0.014238078147172928 -0.13234372437000275 0.06485065072774887" size="0.006449845153838396 0.0006654085591435432 0.006449845153838396" quat="1.0 0.0 0.0 0.0" name="start_button_2" rgba="0.0 0.5 0 0.5"/>
        <site rgba="0 0 0 0" size="0.009999999776482582 0.009999999776482582" pos="-0.0006160363554954529 -0.11393586546182632 -0.08860988914966583" name="receptacle_place_site"/>
        <site type="cylinder" rgba="0.8 0.5 0.25 1" size="0.0019026369554921985 0.0666009858250618" pos="-0.00047482363879680634 -0.11367523670196533 -0.03759806603193283" name="coffee_liquid"/>
        <geom mesh="Body001_vis" type="mesh" solimp="0.998 0.998 0.001" solref="0.001 1" density="100" friction="0.95 0.3 0.1" class="visual" material="Body001_material"/>
        <geom class="collision" type="box" pos="2.697371928661596e-05 0.05761125311255455 0.0046453108079731464" size="0.04281938076019287 0.03963854908943176 0.10315670818090439" quat="1.0 0.0 0.0 0.0"/>
        <geom class="collision" type="box" pos="2.697371928661596e-05 0.016325129196047783 -0.0038310750387609005" size="0.04281938076019287 0.08092467486858368 0.10279447585344315" quat="1.0 0.0 0.0 0.0"/>
        <geom class="collision" type="box" pos="2.697371928661596e-05 -0.09372659027576447 0.0517536960542202" size="0.04281938076019287 0.031599387526512146 0.022165751084685326" quat="1.0 0.0 0.0 0.0"/>
        <geom class="collision" type="box" pos="0.0401381179690361 -0.040500469505786896 0.08510156720876694" size="0.002708232030272484 0.059747010469436646 0.022165751084685326" quat="1.0 0.0 0.0 0.0"/>
        <geom class="collision" type="box" pos="-0.04037249833345413 -0.040500469505786896 0.08510156720876694" size="0.002477986505255103 0.059747010469436646 0.022165751084685326" quat="1.0 0.0 0.0 0.0"/>
        <geom class="collision" type="box" pos="2.697371928661596e-05 -0.08446047455072403 0.058396417647600174" size="0.04281938076019287 0.021974705159664154 0.029109559953212738" quat="1.0 0.0 0.0 0.0"/>
        <geom class="collision" type="box" pos="-0.02552686259150505 -0.10878006368875504 0.058396417647600174" size="0.017265545204281807 0.019971296191215515 0.029109559953212738" quat="1.0 0.0 0.0 0.0"/>
        <geom class="collision" type="box" pos="0.025164447724819183 -0.10913511365652084 0.058396417647600174" size="0.017316734418272972 0.020326346158981323 0.029109559953212738" quat="1.0 0.0 0.0 0.0"/>
        <geom class="collision" type="box" pos="0.0015789661556482315 -0.12559376657009125 0.058396417647600174" size="0.01625293307006359 0.004592988174408674 0.029109559953212738" quat="1.0 0.0 0.0 0.0"/>
        <geom class="collision" type="box" pos="0.03686470165848732 -0.08842287212610245 0.09300757944583893" size="0.0009097842848859727 0.025937102735042572 0.005930944811552763" quat="1.0 0.0 0.0 0.0"/>
        <geom class="collision" type="box" pos="-0.037408702075481415 -0.08842287212610245 0.09300757944583893" size="0.0009097842848859727 0.025937102735042572 0.005930944811552763" quat="1.0 0.0 0.0 0.0"/>
        <geom class="collision" type="box" pos="-0.0010158228687942028 -0.12969112396240234 0.09300757944583893" size="0.025937102735042572 0.0009271661983802915 0.005930944811552763" quat="1.0 0.0 0.0 0.0"/>
        <geom class="collision" type="box" pos="0.03040044941008091 -0.1259734034538269 0.09300757944583893" size="0.0023218055721372366 0.007041084114462137 0.005930944811552763" quat="0.9278257489204407 0.0 -0.0 -0.37301385402679443"/>
        <geom class="collision" type="box" pos="0.03523740917444229 -0.11938449740409851 0.09300757944583893" size="0.0023218055721372366 0.007041084114462137 0.005930944811552763" quat="0.9977664351463318 0.0 -0.0 -0.06679913401603699"/>
        <geom class="collision" type="box" pos="-0.03567786142230034 -0.11938449740409851 0.09300757944583893" size="0.0023218055721372366 0.007041084114462137 0.005930944811552763" quat="0.9977664351463318 0.0 0.0 0.06679913401603699"/>
        <geom class="collision" type="box" pos="-0.030840903520584106 -0.1259734034538269 0.09300757944583893" size="0.0023218055721372366 0.007041084114462137 0.005930944811552763" quat="0.9278257489204407 0.0 0.0 0.37301385402679443"/>
        <geom class="collision" type="box" pos="2.697371928661596e-05 -0.014941489323973656 -0.03504021838307381" size="0.04281938076019287 0.08092467486858368 0.07158534228801727" quat="1.0 0.0 0.0 0.0"/>
        <geom class="collision" type="box" pos="-0.03993181139230728 -0.01922573335468769 -0.03504021838307381" size="0.002860593143850565 0.08092467486858368 0.07158534228801727" quat="1.0 0.0 0.0 0.0"/>
        <geom class="collision" type="box" pos="0.03962099552154541 -0.01922573335468769 -0.03504021838307381" size="0.002860593143850565 0.08092467486858368 0.07158534228801727" quat="1.0 0.0 0.0 0.0"/>
        <geom class="collision" type="box" pos="-0.0010158228687942028 -0.15911540389060974 -0.09876089543104172" size="0.025937102735042572 0.0009095130953937769 0.008428726345300674" quat="1.0 0.0 0.0 0.0"/>
        <geom class="collision" type="box" pos="-0.03697073459625244 -0.12152378261089325 -0.09876089543104172" size="0.0011607054620981216 0.026026032865047455 0.008428726345300674" quat="1.0 0.0 0.0 0.0"/>
        <geom class="collision" type="box" pos="0.03650800883769989 -0.12088248133659363 -0.09876089543104172" size="0.0012664756504818797 0.026086440309882164 0.008428726345300674" quat="1.0 0.0 0.0 0.0"/>
        <geom class="collision" type="box" pos="-0.0005473078927025199 -0.09691906720399857 -0.09815292060375214" size="0.03672110661864281 0.0007024210644885898 0.008472642861306667" quat="1.0 0.0 0.0 0.0"/>
        <geom class="collision" type="box" pos="-0.0005473078927025199 -0.12132329493761063 -0.1058429554104805" size="0.03672110661864281 0.025887945666909218 0.0012902673333883286" quat="1.0 0.0 0.0 0.0"/>
        <geom class="collision" type="box" pos="0.0007985288975760341 -0.13217082619667053 -0.1058429554104805" size="0.027859235182404518 0.025887945666909218 0.0012902673333883286" quat="1.0 0.0 0.0 0.0"/>
        <geom class="collision" type="box" pos="-8.868798613548279e-05 -0.13030438125133514 -0.1058429554104805" size="0.03514226898550987 0.024021495133638382 0.0012902673333883286" quat="1.0 0.0 0.0 0.0"/>
        <geom class="collision" type="box" pos="-0.0003173489822074771 -0.13410159945487976 -0.1058429554104805" size="0.03067724034190178 0.023588351905345917 0.0012902673333883286" quat="1.0 0.0 0.0 0.0"/>
        <geom class="collision" type="box" pos="0.0002554885868448764 0.11086980253458023 -0.09430301189422607" size="0.039785709232091904 0.03277358412742615 0.012086295522749424" quat="1.0 0.0 0.0 0.0"/>
        <geom class="collision" type="cylinder" pos="-0.0002958165714517236 -0.1138019934296608 0.029834818094968796" size="0.004859991371631622 0.002221825532615185" quat="1.0 0.0 0.0 0.0"/>
        <geom class="collision" type="box" pos="-0.00012727401917800307 0.12219960987567902 -0.09430301189422607" size="0.028532451018691063 0.03277358412742615 0.012086295522749424" quat="1.0 0.0 0.0 0.0"/>
        <geom class="collision" type="box" pos="-0.00023359805345535278 0.1207495778799057 -0.09430301189422607" size="0.03289170563220978 0.03228046000003815 0.012086295522749424" quat="1.0 0.0 0.0 0.0"/>
        <geom class="collision" type="box" pos="-7.411325350403786e-05 0.11833936721086502 -0.09430301189422607" size="0.03624089062213898 0.0323156863451004 0.012086295522749424" quat="1.0 0.0 0.0 0.0"/>
        <geom class="collision" type="box" pos="0.000138533185236156 0.11550386250019073 -0.09430301189422607" size="0.038154710084199905 0.03235090523958206 0.012086295522749424" quat="1.0 0.0 0.0 0.0"/>
        <geom class="collision" type="box" pos="0.028914980590343475 -0.15772578120231628 -0.09876089543104172" size="0.0012664756504818797 0.004871442914009094 0.008428726345300674" quat="0.8530206084251404 0.0 -0.0 -0.5218772888183594"/>
        <geom class="collision" type="box" pos="0.03507746756076813 -0.15160289406776428 -0.09876089543104172" size="0.0012664756504818797 0.004871442914009094 0.008428726345300674" quat="0.9763013124465942 0.0 -0.0 -0.21641577780246735"/>
        <geom class="collision" type="box" pos="-0.03577842563390732 -0.15160289406776428 -0.09876089543104172" size="0.0012664756504818797 0.004871442914009094 0.008428726345300674" quat="0.9763013124465942 0.0 0.0 0.21641577780246735"/>
        <geom class="collision" type="box" pos="-0.029615938663482666 -0.15772578120231628 -0.09876089543104172" size="0.0012664756504818797 0.004871442914009094 0.008428726345300674" quat="0.8530206084251404 0.0 0.0 0.5218772292137146"/>
        <body name="Button001">
          <joint axis="0.0 1.0 0.0" pos="-0.014235423877835274 -0.13124901056289673 0.06482886523008347" limited="true" name="Button001_joint" range="0.0 0.001" type="slide" damping="1" frictionloss="1" armature=".01" stiffness="0.05"/>
          <geom mesh="Button001_vis" type="mesh" solimp="0.998 0.998 0.001" solref="0.001 1" density="100" friction="0.95 0.3 0.1" class="visual" material="Button001_material"/>
          <geom class="collision" type="cylinder" pos="-0.01420377753674984 -0.13079982995986938 0.06485065072774887" size="0.006449845153838396 0.0006654080934822559" quat="0.7071068286895752 0.7071067690849304 1.5700924318127872e-16 5.9269340452702814e-24"/>
        </body>
        <body name="Button002">
          <joint axis="0.0 1.0 0.0" pos="0.01422208733856678 -0.13132542371749878 0.06482892483472824" limited="true" name="Button002_joint" range="0.0 0.001" type="slide" damping="1" frictionloss="1" armature=".01" stiffness="0.05"/>
          <geom mesh="Button002_vis" type="mesh" solimp="0.998 0.998 0.001" solref="0.001 1" density="100" friction="0.95 0.3 0.1" class="visual" material="Button002_material"/>
          <geom class="collision" type="cylinder" pos="0.014238078147172928 -0.13079982995986938 0.06485065072774887" size="0.006449845153838396 0.0006654080934822559" quat="0.7071068286895752 0.7071067690849304 1.5700924318127872e-16 5.9269340452702814e-24"/>
        </body>
        <body name="Container001_Clear">
          <joint axis="0.0 0.0 1.0" pos="0.0001871855347417295 0.1280810534954071 -9.901938028633595e-06" limited="true" name="Container001_Clear_joint" range="0.0 0.05" type="slide" damping="1" frictionloss="1" armature=".01" stiffness="0.05"/>
          <geom mesh="Container001_Clear_vis" type="mesh" solimp="0.998 0.998 0.001" solref="0.001 1" density="100" friction="0.95 0.3 0.1" class="visual" material="Container001_Clear_material"/>
          <geom class="collision" type="box" pos="0.0006782397394999862 0.15672515332698822 1.1708973033819348e-05" size="0.030307166278362274 0.0014502555131912231 0.105705127120018" quat="1.0 0.0 0.0 0.0"/>
          <geom class="collision" type="box" pos="-7.75840162532404e-05 0.0997215136885643 0.011627706699073315" size="0.04282332956790924 0.001347651588730514 0.09389878809452057" quat="1.0 0.0 0.0 0.0"/>
          <geom class="collision" type="box" pos="-0.04129962623119354 0.12345068901777267 1.1708973033819348e-05" size="0.0014502574922516942 0.02492881566286087 0.105705127120018" quat="1.0 0.0 0.0 0.0"/>
          <geom class="collision" type="box" pos="0.03980576992034912 0.1497037261724472 1.1708973033819348e-05" size="0.003890001680701971 0.0014502559788525105 0.105705127120018" quat="0.8903114795684814 0.0 -0.0 -0.4553520679473877"/>
          <geom class="collision" type="box" pos="0.04187621921300888 0.12324754148721695 1.1708973033819348e-05" size="0.0014502574922516942 0.025131961330771446 0.105705127120018" quat="1.0 0.0 0.0 0.0"/>
          <geom class="collision" type="box" pos="0.03419198468327522 0.15472421050071716 1.1708973033819348e-05" size="0.004526355769485235 0.0014502559788525105 0.105705127120018" quat="0.9763031601905823 0.0 -0.0 -0.21640729904174805"/>
          <geom class="collision" type="box" pos="-0.03337154909968376 0.15472421050071716 1.1708973033819348e-05" size="0.004526355769485235 0.0014502559788525105 0.105705127120018" quat="0.9763031601905823 0.0 0.0 0.21640729904174805"/>
          <geom class="collision" type="box" pos="-0.03898533433675766 0.1497037261724472 1.1708973033819348e-05" size="0.003890001680701971 0.0014502559788525105 0.105705127120018" quat="0.8903114795684814 0.0 0.0 0.4553520679473877"/>
          <geom class="collision" type="box" pos="-0.036880336701869965 0.12521937489509583 -0.08145347237586975" size="0.002847219817340374 0.027041485533118248 0.0012696986086666584" quat="1.0 0.0 0.0 0.0"/>
          <geom class="collision" type="box" pos="0.0 0.12734146416187286 -0.08145347237586975" size="0.0348968505859375 0.028870925307273865 0.001269702217541635" quat="1.0 0.0 0.0 0.0"/>
          <geom class="collision" type="box" pos="0.03761209547519684 0.12521937489509583 -0.08145347237586975" size="0.0028472342528402805 0.02704160287976265 0.0012697059428319335" quat="1.0 0.0 0.0 0.0"/>
          <body name="Lid003">
            <joint axis="0.0 0.0 1.0" pos="0.0001843031495809555 0.12914295494556427 0.10373221337795258" limited="true" name="Lid003_joint" range="0.0 0.05" type="slide" damping="0" frictionloss="0" armature=".01" stiffness="0"/>
            <geom mesh="Lid003_vis" type="mesh" solimp="0.998 0.998 0.001" solref="0.001 1" density="1000" friction="0.95 0.3 0.1" class="visual" material="Lid003_material"/>
            <geom class="collision" type="box" pos="-0.036880336701869965 0.12521937489509583 0.10652481764554977" size="0.002847270807251334 0.02704189345240593 0.0004948641289956868" quat="1.0 0.0 0.0 0.0"/>
            <geom class="collision" type="box" pos="-0.03898533433675766 0.1497037261724472 0.10651635378599167" size="0.003890001680701971 0.0014502559788525105 0.0005955349188297987" quat="0.8903114795684814 0.0 0.0 0.4553520679473877"/>
            <geom class="collision" type="box" pos="-0.03337154909968376 0.15472421050071716 0.10651635378599167" size="0.004526355769485235 0.0014502559788525105 0.0005955256056040525" quat="0.9763031601905823 0.0 0.0 0.21640729904174805"/>
            <geom class="collision" type="box" pos="0.03419198468327522 0.15472421050071716 0.10651635378599167" size="0.004526355769485235 0.0014502559788525105 0.0005955256056040525" quat="0.9763031601905823 0.0 -0.0 -0.21640729904174805"/>
            <geom class="collision" type="box" pos="0.04187621921300888 0.12324754148721695 0.10651635378599167" size="0.0014502574922516942 0.025131961330771446 0.0005955410888418555" quat="1.0 0.0 0.0 0.0"/>
            <geom class="collision" type="box" pos="0.03980576992034912 0.1497037261724472 0.10651635378599167" size="0.003890001680701971 0.0014502559788525105 0.0005955256056040525" quat="0.8903114795684814 0.0 -0.0 -0.4553520679473877"/>
            <geom class="collision" type="box" pos="-0.04129962623119354 0.12345068901777267 0.10651635378599167" size="0.0014502574922516942 0.02492881566286087 0.0005955410888418555" quat="1.0 0.0 0.0 0.0"/>
            <geom class="collision" type="box" pos="-7.75840162532404e-05 0.0997215136885643 0.10670182853937149" size="0.04282332956790924 0.001347651588730514 0.00021971328533254564" quat="1.0 0.0 0.0 0.0"/>
            <geom class="collision" type="box" pos="0.03761209547519684 0.12521937489509583 0.10652481764554977" size="0.002847299911081791 0.027042126283049583 0.0004948677960783243" quat="1.0 0.0 0.0 0.0"/>
            <geom class="collision" type="box" pos="0.0 0.12734146416187286 0.10638392716646194" size="0.034897491335868835 0.0288715660572052 0.0006357503589242697" quat="1.0 0.0 0.0 0.0"/>
            <geom class="collision" type="box" pos="0.0006782397394999862 0.15672515332698822 0.10651635378599167" size="0.030307166278362274 0.0014502555131912231 0.0005955410888418555" quat="1.0 0.0 0.0 0.0"/>
            <geom class="collision" type="box" pos="0.0002966645697597414 0.15824982523918152 0.10651635378599167" size="0.021920375525951385 0.0015608964022248983 0.0005955410888418555" quat="1.0 0.0 0.0 0.0"/>
          </body>
        </body>
        <body name="Lid001">
          <joint axis="-1.0 0.0 0.0" pos="-0.00012542269541881979 0.012685714289546013 0.10283028334379196" limited="true" name="Lid001_joint" range="0.0 1.5707963267948966" type="hinge" damping="0" frictionloss="0" armature=".01" stiffness="0"/>
          <geom mesh="Lid001_vis" type="mesh" solimp="0.998 0.998 0.001" solref="0.001 1" density="1000" friction="0.95 0.3 0.1" class="visual" material="Lid001_material"/>
          <geom class="collision" type="box" pos="-0.030840903520584106 -0.1259734034538269 0.1032513976097107" size="0.0023218055721372366 0.007041084114462137 0.0037267175503075123" quat="0.9278257489204407 0.0 0.0 0.37301385402679443"/>
          <geom class="collision" type="box" pos="-0.03567786142230034 -0.11938449740409851 0.1032513976097107" size="0.0023218055721372366 0.007041084114462137 0.0037267175503075123" quat="0.9977664351463318 0.0 0.0 0.06679913401603699"/>
          <geom class="collision" type="box" pos="0.03523740917444229 -0.11938449740409851 0.1032513976097107" size="0.0023218055721372366 0.007041084114462137 0.0037267175503075123" quat="0.9977664351463318 0.0 -0.0 -0.06679913401603699"/>
          <geom class="collision" type="box" pos="0.03040044941008091 -0.1259734034538269 0.1032513976097107" size="0.0023218055721372366 0.007041084114462137 0.0037267175503075123" quat="0.9278257489204407 0.0 -0.0 -0.37301385402679443"/>
          <geom class="collision" type="box" pos="-0.0010158228687942028 -0.12969112396240234 0.1032513976097107" size="0.025937102735042572 0.0009271661983802915 0.0037267175503075123" quat="1.0 0.0 0.0 0.0"/>
          <geom class="collision" type="box" pos="-0.036808501929044724 -0.05048670619726181 0.1032513976097107" size="0.0006139105535112321 0.06387326866388321 0.0037267175503075123" quat="1.0 0.0 0.0 0.0"/>
          <geom class="collision" type="box" pos="0.03665628284215927 -0.05048670619726181 0.1032513976097107" size="0.0006777755334042013 0.06387326866388321 0.0037267175503075123" quat="1.0 0.0 0.0 0.0"/>
          <geom class="collision" type="box" pos="-0.00017718528397381306 -0.05747286602854729 0.1032513976097107" size="0.028062334284186363 0.0709967389702797 0.0037267175503075123" quat="1.0 0.0 0.0 0.0"/>
          <geom class="collision" type="box" pos="-0.029227785766124725 -0.05627426877617836 0.1032513976097107" size="0.002740152645856142 0.06970971822738647 0.0037267175503075123" quat="1.0 0.0 0.0 0.0"/>
          <geom class="collision" type="box" pos="-0.03264406695961952 -0.0551055446267128 0.1032513976097107" size="0.002740152645856142 0.06836119294166565 0.0037267175503075123" quat="1.0 0.0 0.0 0.0"/>
          <geom class="collision" type="box" pos="-0.03460058197379112 -0.052831944078207016 0.1032513976097107" size="0.0031016445718705654 0.06631949543952942 0.0037267175503075123" quat="1.0 0.0 0.0 0.0"/>
          <geom class="collision" type="box" pos="0.03334406763315201 -0.052831944078207016 0.1032513976097107" size="0.002740152645856142 0.06631949543952942 0.0037267175503075123" quat="1.0 0.0 0.0 0.0"/>
          <geom class="collision" type="box" pos="0.03244504705071449 -0.0551055446267128 0.1032513976097107" size="0.002740152645856142 0.06836119294166565 0.0037267175503075123" quat="1.0 0.0 0.0 0.0"/>
          <geom class="collision" type="box" pos="0.029028765857219696 -0.05627426877617836 0.1032513976097107" size="0.002740152645856142 0.06970971822738647 0.0037267175503075123" quat="1.0 0.0 0.0 0.0"/>
        </body>
        <body name="Lid002">
          <joint axis="0.0 0.0 1.0" pos="-0.0002676830627024174 -0.1277162879705429 -0.09182748943567276" limited="true" name="Lid002_joint" range="0.0 0.02" type="slide" damping="0" frictionloss="0" armature=".01" stiffness="0"/>
          <geom mesh="Lid002_vis" type="mesh" solimp="0.998 0.998 0.001" solref="0.001 1" density="1000" friction="0.95 0.3 0.1" class="visual" material="Lid002_material"/>
          <geom class="collision" type="box" pos="-0.029227785766124725 -0.12607061862945557 -0.09129488468170166" size="0.002740152645856142 0.028296662494540215 0.0014078175881877542" quat="1.0 0.0 0.0 0.0"/>
          <geom class="collision" type="box" pos="-0.00023662415333092213 -0.1273849904537201 -0.09129488468170166" size="0.026719562709331512 0.02965646982192993 0.0014078175881877542" quat="1.0 0.0 0.0 0.0"/>
          <geom class="collision" type="box" pos="0.030306383967399597 -0.12303476780653 -0.09129488468170166" size="0.004692950751632452 0.025170881301164627 0.0014078175881877542" quat="1.0 0.0 0.0 0.0"/>
          <geom class="collision" type="box" pos="-0.03264406695961952 -0.12320541590452194 -0.09129488468170166" size="0.002740152645856142 0.025415761396288872 0.0014078175881877542" quat="1.0 0.0 0.0 0.0"/>
          <geom class="collision" type="box" pos="0.028575044125318527 -0.12631815671920776 -0.09129488468170166" size="0.002740152645856142 0.028049133718013763 0.0014078175881877542" quat="1.0 0.0 0.0 0.0"/>
        </body>
        <geom class="region" name="reg_main" type="box" pos="-9.313225746154785e-10 0.0 -3.725290298461914e-09" size="0.04272222891449928 0.1597679853439331 0.10692621767520905"/>
      </body>
    </body>
  </worldbody>
  <actuator>
    <motor name="Button001_joint_actuator" joint="Button001_joint" gear="0.5"/>
    <motor name="Button002_joint_actuator" joint="Button002_joint" gear="0.5"/>
    <motor name="Container001_Clear_joint_actuator" joint="Container001_Clear_joint" gear="10"/>
    <motor name="Lid001_joint_actuator" joint="Lid001_joint" gear="10"/>
    <motor name="Lid002_joint_actuator" joint="Lid002_joint" gear="10"/>
    <motor name="Lid003_joint_actuator" joint="Lid003_joint" gear="10"/>
  </actuator>
</mujoco>
