<mujoco model="model">
  <compiler angle="radian"/>
  <asset>
    <mesh file="visuals/Body001.obj" name="Body001_vis"/>
    <mesh file="visuals/Container001_Clear.obj" name="Container001_Clear_vis"/>
    <mesh file="visuals/Lever001.obj" name="Lever001_vis"/>
    <mesh file="visuals/Lever002.obj" name="Lever002_vis"/>
    <mesh file="visuals/Lid001.obj" name="Lid001_vis"/>
    <mesh file="visuals/Lid002.obj" name="Lid002_vis"/>
    <mesh file="visuals/Lid003_Clear.obj" name="Lid003_Clear_vis"/>
    <texture file="visuals/T_BC001.png" name="Body001_material" type="2d"/>
    <material name="Body001_material" rgba="1 1 1 1.0" texture="Body001_material" shininess="0.4472135901451111" specular="0.3103448502657381"/>
    <material name="Container001_Clear_material" rgba="0.800000011920929 0.800000011920929 0.800000011920929 0.10000000149011612" shininess="0.5" specular="0.3103448502657381"/>
    <material name="Lid003_Clear_material" rgba="0.800000011920929 0.800000011920929 0.800000011920929 0.10000000149011612" shininess="0.5" specular="0.3103448502657381"/>
    <texture file="visuals/T_BC001.png" name="Lever001_material" type="2d"/>
    <material name="Lever001_material" rgba="1 1 1 1.0" texture="Lever001_material" shininess="0.4472135901451111" specular="0.3103448502657381"/>
    <texture file="visuals/T_BC001.png" name="Lever002_material" type="2d"/>
    <material name="Lever002_material" rgba="1 1 1 1.0" texture="Lever002_material" shininess="0.4472135901451111" specular="0.3103448502657381"/>
    <texture file="visuals/T_BC001.png" name="Lid001_material" type="2d"/>
    <material name="Lid001_material" rgba="1 1 1 1.0" texture="Lid001_material" shininess="0.4472135901451111" specular="0.3103448502657381"/>
    <texture file="visuals/T_BC001.png" name="Lid002_material" type="2d"/>
    <material name="Lid002_material" rgba="1 1 1 1.0" texture="Lid002_material" shininess="0.4472135901451111" specular="0.3103448502657381"/>
  </asset>
  <default>
    <default class="visual">
      <geom conaffinity="0" contype="0" group="1" type="mesh"/>
    </default>
    <default class="collision">
      <geom group="0" rgba="0.5 0 0 0.5"/>
    </default>
    <default class="spawn">
      <geom group="0" rgba="1 1 1 0.5" contype="0" conaffinity="0"/>
      <site group="0" rgba="1 1 1 0.5"/>
    </default>
    <default class="region">
      <geom group="1" conaffinity="0" contype="0" rgba="0 1 0 0"/>
    </default>
  </default>
  <worldbody>
    <body>
      <body name="object">
        <geom class="collision" type="box" pos="-0.067620 -0.118375 0.161645" size="0.013672706671059132 0.013672706671059132 0.0010539739159867167" quat="0.6087614297866821 -0.7933533191680908 -0.0 0.0" name="start_button_1" rgba="0.0 0.5 0 0.5"/>
        <geom class="collision" type="box" pos="-0.022921 -0.118375 0.161645" size="0.013672706671059132 0.013672706671059132 0.0010539739159867167" quat="0.6087614297866821 -0.7933533191680908 -0.0 0.0" name="start_button_2" rgba="0.0 0.5 0 0.5"/>
        <geom class="collision" type="box" pos="0.022409 -0.118375 0.161645" size="0.013672706671059132 0.013672706671059132 0.0010539739159867167" quat="0.6087614297866821 -0.7933533191680908 -0.0 0.0" name="start_button_3" rgba="0.0 0.5 0 0.5"/>
        <geom class="collision" type="box" pos="0.066001 -0.118375 0.161645" size="0.013672706671059132 0.013672706671059132 0.0010539739159867167" quat="0.6087614297866821 -0.7933533191680908 -0.0 0.0" name="start_button_4" rgba="0.0 0.5 0 0.5"/>
        <geom class="collision" type="box" pos="-0.067620 -0.128627 0.124569" size="0.013672706671059132 0.013672706671059132 0.0010539739159867167" quat="0.6087614297866821 -0.7933533191680908 -0.0 0.0" name="start_button_5" rgba="0.0 0.5 0 0.5"/>
        <geom class="collision" type="box" pos="-0.022921 -0.128627 0.124569" size="0.013672706671059132 0.013672706671059132 0.0010539739159867167" quat="0.6087614297866821 -0.7933533191680908 -0.0 0.0" name="start_button_6" rgba="0.0 0.5 0 0.5"/>
        <geom class="collision" type="box" pos="0.022409 -0.128627 0.124569" size="0.013672706671059132 0.013672706671059132 0.0010539739159867167" quat="0.6087614297866821 -0.7933533191680908 -0.0 0.0" name="start_button_7" rgba="0.0 0.5 0 0.5"/>
        <geom class="collision" type="box" pos="0.066001 -0.128627 0.124569" size="0.013672706671059132 0.013672706671059132 0.0010539739159867167" quat="0.6087614297866821 -0.7933533191680908 -0.0 0.0" name="start_button_8" rgba="0.0 0.5 0 0.5"/>
        <site type="cylinder" rgba="0.8 0.5 0.25 1" size="0.00476753618568182 0.07336734235286713" pos="0.089613 -0.075516 -0.102774" name="coffee_liquid"/>
        <site rgba="0 0 0 0" size="0.009999999776482582 0.009999999776482582" pos="0.071368 -0.071348 -0.131813" name="receptacle_place_site"/>
        <geom mesh="Body001_vis" type="mesh" solimp="0.998 0.998 0.001" solref="0.001 1" density="100" friction="0.95 0.3 0.1" class="visual" material="Body001_material"/>
        <geom class="collision" type="box" pos="0.000105 -0.014450 -0.212213" size="0.24726560711860657 0.17936858534812927 0.028345149010419846" quat="1.0 0.0 0.0 0.0"/>
        <geom class="collision" type="box" pos="0.000105 0.100839 0.030031" size="0.2478623390197754 0.06819746643304825 0.21179066598415375" quat="1.0 0.0 0.0 0.0"/>
        <geom class="collision" type="box" pos="-0.002506 -0.095230 0.087583" size="0.2185814529657364 0.022456591948866844 0.04059378430247307" quat="1.0 0.0 0.0 0.0"/>
        <geom class="collision" type="box" pos="0.001512 -0.114154 0.144223" size="0.2160433679819107 0.09598646312952042 0.007202429231256247" quat="0.7951401472091675 0.6064257025718689 5.1805210240248005e-19 -3.975108974454604e-19"/>
        <geom class="collision" type="box" pos="-0.110878 -0.027322 0.144035" size="0.11390630155801773 0.06870348006486893 0.09704497456550598" quat="1.0 0.0 0.0 0.0"/>
        <geom class="collision" type="cylinder" pos="0.089905 -0.073316 0.032126" size="0.07626838237047195 0.016506172716617584" quat="1.0 0.0 0.0 0.0"/>
        <geom class="collision" type="box" pos="0.215032 -0.031888 0.144045" size="0.006732685025781393 0.06731262803077698 0.09705666452646255" quat="0.9986422061920166 0.0 -0.0 -0.05209389328956604"/>
        <geom class="collision" type="box" pos="-0.114317 -0.083354 0.140561" size="0.11046846956014633 0.021891482174396515 0.09598618000745773" quat="0.9943941235542297 -0.10573705285787582 2.347834212776419e-17 2.9629944949529133e-24"/>
        <geom class="collision" type="box" pos="0.206652 -0.030771 0.144045" size="0.00865946151316166 0.06737849116325378 0.09705666452646255" quat="1.0 0.0 0.0 0.0"/>
        <geom class="collision" type="box" pos="0.000105 -0.187756 -0.176918" size="0.23021727800369263 0.010661262087523937 0.00652295583859086" quat="1.0 0.0 0.0 0.0"/>
        <geom class="collision" type="box" pos="0.238291 -0.081957 -0.176516" size="0.11538030207157135 0.009120794013142586 0.00652298191562295" quat="0.712139368057251 0.0 0.0 0.7020381093025208"/>
        <geom class="collision" type="box" pos="-0.233319 -0.080349 -0.176516" size="0.01184128038585186 0.11553887277841568 0.006522959563881159" quat="1.0 0.0 0.0 0.0"/>
        <geom class="collision" type="box" pos="0.099594 -0.027322 0.093127" size="0.1104678362607956 0.0687035620212555 0.04045451804995537" quat="1.0 0.0 0.0 0.0"/>
        <geom class="collision" type="box" pos="0.099607 -0.084849 0.144035" size="0.10086517035961151 0.011549726128578186 0.09704537689685822" quat="1.0 0.0 0.0 0.0"/>
        <body name="Container001_Clear">
          <joint axis="0.0 0.0 1.0" pos="0.000913 0.229929 -0.005336" limited="true" name="Container001_Clear_joint" range="0.0 0.3" type="slide" damping="1" frictionloss="1" armature=".01" stiffness="0.05"/>
          <geom mesh="Container001_Clear_vis" type="mesh" solimp="0.998 0.998 0.001" solref="0.001 1" density="100" friction="0.95 0.3 0.1" class="visual" material="Container001_Clear_material"/>
          <geom class="collision" type="box" pos="0.003476 0.284385 -0.006934" size="0.2475619912147522 0.004041824024170637 0.23295700550079346" quat="1.0 0.0 0.0 0.0"/>
          <geom class="collision" type="box" pos="0.003476 0.176282 -0.006934" size="0.2475619912147522 0.004041822627186775 0.23295700550079346" quat="1.0 0.0 0.0 0.0"/>
          <geom class="collision" type="box" pos="0.246708 0.230333 -0.006934" size="0.0040418244898319244 0.056772515177726746 0.23295684158802032" quat="1.0 0.0 0.0 0.0"/>
          <geom class="collision" type="box" pos="-0.240199 0.230333 -0.006934" size="0.0040418244898319244 0.056772515177726746 0.2329568862915039" quat="1.0 0.0 0.0 0.0"/>
          <geom class="collision" type="box" pos="0.003476 0.230053 -0.235063" size="0.2475619912147522 0.058637235313653946 0.004041824955493212" quat="1.0 0.0 0.0 0.0"/>
          <body name="Lid003_Clear">
            <joint axis="0.0 0.0 1.0" pos="0.000917 0.229930 0.222827" limited="true" name="Lid003_Clear_joint" range="0.0 0.05" type="slide" damping="1" frictionloss="1" armature=".01" stiffness="0.05"/>
            <geom mesh="Lid003_Clear_vis" type="mesh" solimp="0.998 0.998 0.001" solref="0.001 1" density="100" friction="0.95 0.3 0.1" class="visual" material="Lid003_Clear_material"/>
            <geom class="collision" type="box" pos="0.003476 0.230053 0.236043" size="0.2475619912147522 0.05863720923662186 0.004041824955493212" quat="1.0 0.0 0.0 0.0"/>
          </body>
        </body>
        <body name="Lever001">
          <joint axis="0.0 0.0 1.0" pos="0.089719 -0.074503 -0.010687" limited="true" name="Lever001_joint" range="-0.7853981633974483 0.7853981633974483" type="hinge" damping="1" frictionloss="1" armature=".01" stiffness="1"/>
          <geom mesh="Lever001_vis" type="mesh" solimp="0.998 0.998 0.001" solref="0.001 1" density="100" friction="0.95 0.3 0.1" class="visual" material="Lever001_material"/>
          <geom class="collision" type="cylinder" pos="0.089905 -0.073316 -0.003291" size="0.04549261927604675 0.015040182508528233" quat="1.0 0.0 0.0 0.0"/>
          <geom class="collision" type="cylinder" pos="0.089772 -0.135791 -0.001352" size="0.011933913454413414 0.02030511200428009" quat="0.7071068286895752 -0.7071067690849304 -0.0 0.0"/>
          <geom class="collision" type="cylinder" pos="0.089772 -0.219120 -0.001352" size="0.0169413723051548 0.06716911494731903" quat="0.7071068286895752 -0.7071067690849304 -0.0 0.0"/>
          <geom class="collision" type="cylinder" pos="0.089772 -0.266332 -0.001352" size="0.019784532487392426 0.019781887531280518" quat="0.7071068286895752 -0.7071067690849304 -0.0 0.0"/>
        </body>
        <body name="Lever002">
          <joint axis="3.065163420185057e-15 0.0 1.0" pos="-0.163507 -0.110232 0.052098" limited="true" name="Lever002_joint" range="-0.7853981633974483 0.7853981633974483" type="hinge" damping="1" frictionloss="1" armature=".01" stiffness="1"/>
          <geom mesh="Lever002_vis" type="mesh" solimp="0.998 0.998 0.001" solref="0.001 1" density="100" friction="0.95 0.3 0.1" class="visual" material="Lever002_material"/>
          <geom class="collision" type="cylinder" pos="-0.162990 -0.110799 0.040528" size="0.009939825162291527 0.006390679161995649" quat="1.0 0.0 0.0 0.0"/>
          <geom class="collision" type="cylinder" pos="-0.162990 -0.110799 0.021448" size="0.005997099913656712 0.012104864232242107" quat="1.0 0.0 0.0 0.0"/>
          <geom class="collision" type="cylinder" pos="-0.162990 -0.113305 0.003565" size="0.005997099913656712 0.008840130642056465" quat="0.9782189726829529 -0.20757576823234558 4.609108606660594e-17 2.051149582962267e-24"/>
          <geom class="collision" type="cylinder" pos="-0.162990 -0.121502 -0.005580" size="0.005997099913656712 0.008840130642056465" quat="0.8494779467582703 -0.5276241302490234 1.1715609155005767e-16 9.349852394552638e-24"/>
          <geom class="collision" type="cylinder" pos="-0.162990 -0.139442 -0.009927" size="0.005997099913656712 0.01316235214471817" quat="0.7363585233688354 -0.6765915751457214 1.5023350899883635e-16 -1.0349649972664317e-24"/>
          <geom class="collision" type="cylinder" pos="-0.162990 -0.160415 -0.014316" size="0.01017691195011139 0.009176742285490036" quat="0.7788244485855103 -0.6272419691085815 1.3927569522311368e-16 1.6673717502436845e-23"/>
          <geom class="collision" type="cylinder" pos="-0.161819 -0.171535 -0.019291" size="0.01017691195011139 0.00917674321681261" quat="0.949850857257843 -0.3127032518386841 6.943407001329318e-17 1.5640379136356979e-23"/>
          <geom class="collision" type="cylinder" pos="-0.161527 -0.178266 -0.029436" size="0.007550795562565327 0.006808714475482702" quat="0.982801616191864 -0.1846645027399063 4.100375324583741e-17 2.0325952589271066e-23"/>
          <geom class="collision" type="cylinder" pos="-0.161332 -0.180314 -0.059871" size="0.005216080229729414 0.027063006535172462" quat="0.9999983906745911 -0.0017807093681767583 3.953902389994217e-19 1.5859245439066927e-23"/>
          <geom class="collision" type="cylinder" pos="-0.161332 -0.180258 -0.105265" size="0.0063952174969017506 0.01804647035896778" quat="0.9999983906745911 -0.0017807093681767583 3.953902389994217e-19 1.5859245439066927e-23"/>
        </body>
        <body name="Lid001">
          <joint axis="0.0 0.0 1.0" pos="0.000001 -0.019564 -0.176682" limited="true" name="Lid001_joint" range="0.0 0.05" type="slide" damping="1" frictionloss="1" armature=".01" stiffness="0.05"/>
          <geom mesh="Lid001_vis" type="mesh" solimp="0.998 0.998 0.001" solref="0.001 1" density="100" friction="0.95 0.3 0.1" class="visual" material="Lid001_material"/>
          <geom class="collision" type="box" pos="-0.000331 -0.078334 -0.175738" size="0.21466021239757538 0.09051701426506042 0.004174274858087301" quat="1.0 0.0 0.0 0.0"/>
        </body>
        <body name="Lid002">
          <joint axis="-1.0 0.0 0.0" pos="0.100462 0.027825 0.238854" limited="true" name="Lid002_joint" range="0.0 1.5707963267948966" type="hinge" damping="1" frictionloss="1" armature=".01" stiffness="0.05"/>
          <geom mesh="Lid002_vis" type="mesh" solimp="0.998 0.998 0.001" solref="0.001 1" density="100" friction="0.95 0.3 0.1" class="visual" material="Lid002_material"/>
          <geom class="collision" type="box" pos="0.099777 -0.021165 0.236838" size="0.09490994364023209 0.04818883538246155 0.0027882265858352184" quat="1.0 0.0 0.0 0.0"/>
        </body>
        <geom class="region" name="reg_main" type="box" pos="0.0 0.0 2.3500000000009624e-05" size="0.246819 0.288194 0.2403565"/>
      </body>
    </body>
  </worldbody>
  <actuator>
    <motor name="Container001_Clear_joint_actuator" joint="Container001_Clear_joint" gear="10"/>
    <motor name="Lever001_joint_actuator" joint="Lever001_joint" gear="10"/>
    <motor name="Lever002_joint_actuator" joint="Lever002_joint" gear="10"/>
    <motor name="Lid001_joint_actuator" joint="Lid001_joint" gear="10"/>
    <motor name="Lid002_joint_actuator" joint="Lid002_joint" gear="10"/>
    <motor name="Lid003_Clear_joint_actuator" joint="Lid003_Clear_joint" gear="10"/>
  </actuator>
</mujoco>
