<?xml version='1.0' encoding='utf-8'?>
<mujoco model="model">
    <compiler angle="radian" />
    <asset>
        <mesh file="visuals/Refrigerator061_Body001.obj" name="Refrigerator061_Body001_vis" />
        <mesh file="visuals/Refrigerator061_Body001_Clear.obj" name="Refrigerator061_Body001_Clear_vis" />
        <mesh file="visuals/Refrigerator061_Door001.obj" name="Refrigerator061_Door001_vis" />
        <mesh file="visuals/Refrigerator061_Door001_Clear.obj" name="Refrigerator061_Door001_Clear_vis" />
        <mesh file="visuals/Refrigerator061_Door002.obj" name="Refrigerator061_Door002_vis" />
        <mesh file="visuals/Refrigerator061_Door002_Clear.obj" name="Refrigerator061_Door002_Clear_vis" />
        <mesh file="visuals/Refrigerator061_Drawer001.obj" name="Refrigerator061_Drawer001_vis" />
        <mesh file="visuals/Refrigerator061_Drawer001_Clear.obj" name="Refrigerator061_Drawer001_Clear_vis" />
        <mesh file="visuals/Refrigerator061_Drawer002.obj" name="Refrigerator061_Drawer002_vis" />
        <mesh file="visuals/Refrigerator061_Drawer002_Clear.obj" name="Refrigerator061_Drawer002_Clear_vis" />
        <texture file="visuals/T_Refrigerator061_BC001.png" name="Refrigerator061_Body001_material" type="2d" />
        <material name="Refrigerator061_Body001_material" rgba="1 1 1 1.0" texture="Refrigerator061_Body001_material" shininess="0.141421377658844" specular="0.3103448502657381" />
        <texture file="visuals/T_Refrigerator061_BC001.png" name="Refrigerator061_Body001_Clear_material" type="2d" />
        <material name="Refrigerator061_Body001_Clear_material" rgba="1 1 1 0.30000001192092896" texture="Refrigerator061_Body001_Clear_material" shininess="0.141421377658844" specular="0.3103448502657381" />
        <texture file="visuals/T_Refrigerator061_BC001.png" name="Refrigerator061_Door001_material" type="2d" />
        <material name="Refrigerator061_Door001_material" rgba="1 1 1 1.0" texture="Refrigerator061_Door001_material" shininess="0.141421377658844" specular="0.3103448502657381" />
        <texture file="visuals/T_Refrigerator061_BC001.png" name="Refrigerator061_Door001_Clear_material" type="2d" />
        <material name="Refrigerator061_Door001_Clear_material" rgba="1 1 1 0.30000001192092896" texture="Refrigerator061_Door001_Clear_material" shininess="0.141421377658844" specular="0.3103448502657381" />
        <texture file="visuals/T_Refrigerator061_BC001.png" name="Refrigerator061_Door002_material" type="2d" />
        <material name="Refrigerator061_Door002_material" rgba="1 1 1 1.0" texture="Refrigerator061_Door002_material" shininess="0.141421377658844" specular="0.3103448502657381" />
        <texture file="visuals/T_Refrigerator061_BC001.png" name="Refrigerator061_Door002_Clear_material" type="2d" />
        <material name="Refrigerator061_Door002_Clear_material" rgba="1 1 1 0.30000001192092896" texture="Refrigerator061_Door002_Clear_material" shininess="0.141421377658844" specular="0.3103448502657381" />
        <texture file="visuals/T_Refrigerator061_BC001.png" name="Refrigerator061_Drawer001_material" type="2d" />
        <material name="Refrigerator061_Drawer001_material" rgba="1 1 1 1.0" texture="Refrigerator061_Drawer001_material" shininess="0.141421377658844" specular="0.3103448502657381" />
        <texture file="visuals/T_Refrigerator061_BC001.png" name="Refrigerator061_Drawer001_Clear_material" type="2d" />
        <material name="Refrigerator061_Drawer001_Clear_material" rgba="1 1 1 0.30000001192092896" texture="Refrigerator061_Drawer001_Clear_material" shininess="0.141421377658844" specular="0.3103448502657381" />
        <texture file="visuals/T_Refrigerator061_BC001.png" name="Refrigerator061_Drawer002_material" type="2d" />
        <material name="Refrigerator061_Drawer002_material" rgba="1 1 1 1.0" texture="Refrigerator061_Drawer002_material" shininess="0.141421377658844" specular="0.3103448502657381" />
        <texture file="visuals/T_Refrigerator061_BC001.png" name="Refrigerator061_Drawer002_Clear_material" type="2d" />
        <material name="Refrigerator061_Drawer002_Clear_material" rgba="1 1 1 0.30000001192092896" texture="Refrigerator061_Drawer002_Clear_material" shininess="0.141421377658844" specular="0.3103448502657381" />
    </asset>
    <default>
        <default class="visual">
            <geom conaffinity="0" contype="0" group="1" type="mesh" />
        </default>
        <default class="collision">
            <geom group="0" rgba="0.5 0 0 0.5" />
    </default>
        <default class="spawn">
            <geom group="0" rgba="1 1 1 0.5" contype="0" conaffinity="0" />
            <site group="0" rgba="1 1 1 0.5" />
        </default>
    </default>
    <worldbody>
        <body>
            <site rgba="0 0 0 0.5" size="0.01" pos="-0.378491 -0.364092 -0.890200" name="ext_p0" />
            <site rgba="1 0 0 0.5" size="0.01" pos="0.379569 -0.364092 -0.890200" name="ext_px" />
            <site rgba="0 1 0 0.5" size="0.01" pos="-0.378491 0.405361 -0.890200" name="ext_py" />
            <site rgba="0 0 1 0.5" size="0.01" pos="-0.378491 -0.364092 0.890562" name="ext_pz" />
            <body name="object">
                <geom mesh="Refrigerator061_Body001_vis" type="mesh" solimp="0.998 0.998 0.001" solref="0.001 1" density="100" friction="0.95 0.3 0.1" class="visual" material="Refrigerator061_Body001_material" />
                <geom class="collision" type="box" pos="-0.360081 0.063507 0.000000" size="0.019590621814131737 0.34276074171066284 0.8933756947517395" quat="1.0 0.0 0.0 0.0" />
                <geom class="collision" type="box" pos="0.003591 0.315447 -0.023466" size="0.3488938808441162 0.09082130342721939 0.8695869445800781" quat="1.0 0.0 0.0 0.0" />
                <geom class="collision" type="box" pos="0.360081 0.063507 0.000000" size="0.019590621814131737 0.34276074171066284 0.8933756947517395" quat="1.0 0.0 0.0 0.0" />
                <geom class="collision" type="box" pos="0.003591 0.063507 0.867562" size="0.3488938808441162 0.34276074171066284 0.025814153254032135" quat="1.0 0.0 0.0 0.0" />
                <geom class="collision" type="box" pos="0.003591 0.064956 -0.194662" size="0.3488938808441162 0.34131190180778503 0.04420214518904686" quat="1.0 0.0 0.0 0.0" />
                <geom class="collision" type="box" pos="0.003591 0.066446 -0.491798" size="0.3488938808441162 0.3398214876651764 0.044169098138809204" quat="1.0 0.0 0.0 0.0" />
                <geom class="collision" type="box" pos="0.003591 0.066446 -0.868063" size="0.3488938808441162 0.3398214876651764 0.024764282628893852" quat="1.0 0.0 0.0 0.0" />
                <body name="Refrigerator061_Body001_Clear">
                    <geom mesh="Refrigerator061_Body001_Clear_vis" type="mesh" solimp="0.998 0.998 0.001" solref="0.001 1" density="100" friction="0.95 0.3 0.1" class="visual" material="Refrigerator061_Body001_Clear_material" />
                    <geom class="collision" type="box" pos="0.003591 0.109604 0.534175" size="0.3488938808441162 0.2966640889644623 0.004475087858736515" quat="1.0 0.0 0.0 0.0" />
                    <geom class="collision" type="box" pos="0.003591 0.109604 0.373985" size="0.3488938808441162 0.2966640889644623 0.004475087858736515" quat="1.0 0.0 0.0 0.0" />
                    <geom class="collision" type="box" pos="0.003591 0.109604 0.181705" size="0.3488938808441162 0.2966640889644623 0.004475087858736515" quat="1.0 0.0 0.0 0.0" />
                    <geom class="collision" type="box" pos="0.003591 0.109604 0.016375" size="0.3488938808441162 0.2966640889644623 0.004475087858736515" quat="1.0 0.0 0.0 0.0" />
                </body>
                <body name="Refrigerator061_Door001">
                    <joint axis="0.0 0.0 -1.0" pos="-0.349984 -0.312338 0.361598" limited="true" name="Refrigerator061_Door001_joint" range="0.0 1.5707963267948966" type="hinge" damping="1" frictionloss="1" armature=".01" stiffness="0.05" />
                    <geom mesh="Refrigerator061_Door001_vis" type="mesh" solimp="0.998 0.998 0.001" solref="0.001 1" density="100" friction="0.95 0.3 0.1" class="visual" material="Refrigerator061_Door001_material" />
                    <geom class="collision" type="box" pos="-0.187326 -0.324798 0.362320" size="0.17264889180660248 0.02611648105084896 0.5255967974662781" quat="1.0 0.0 0.0 0.0" />
                    <geom class="collision" type="cylinder" pos="-0.097334 -0.395834 0.431864" size="0.010426044464111328 0.1963866651058197" quat="1.0 0.0 0.0 0.0" />
                    <geom class="collision" type="cylinder" pos="-0.097334 -0.368913 0.274436" size="0.005949943792074919 0.01835515722632408" quat="0.7071067094802856 0.7071068286895752 0.0 0.0" />
                    <geom class="collision" type="cylinder" pos="-0.097334 -0.369425 0.586713" size="0.005949943792074919 0.01835515722632408" quat="0.7071067094802856 0.7071068286895752 0.0 0.0" />
                    <body name="Refrigerator061_Door001_Clear">
                        <geom mesh="Refrigerator061_Door001_Clear_vis" type="mesh" solimp="0.998 0.998 0.001" solref="0.001 1" density="100" friction="0.95 0.3 0.1" class="visual" material="Refrigerator061_Door001_Clear_material" />
                        <geom class="collision" type="box" pos="-0.205147 -0.194566 0.103959" size="0.11674992740154266 0.005236801691353321 0.039874859154224396" quat="1.0 0.0 0.0 0.0" />
                        <geom class="collision" type="box" pos="-0.205147 -0.194566 0.280309" size="0.11674992740154266 0.005236793775111437 0.03987477347254753" quat="1.0 0.0 0.0 0.0" />
                        <geom class="collision" type="box" pos="-0.205147 -0.194566 0.449649" size="0.11674992740154266 0.005236785393208265 0.039874687790870667" quat="1.0 0.0 0.0 0.0" />
                        <geom class="collision" type="box" pos="-0.205147 -0.194566 0.710817" size="0.11674992740154266 0.005236777476966381 0.0398746021091938" quat="1.0 0.0 0.0 0.0" />
                        <geom class="collision" type="box" pos="-0.205147 -0.241477 0.069065" size="0.11674989759922028 0.04351221024990082 0.004980414640158415" quat="1.0 0.0 0.0 0.0" />
                        <geom class="collision" type="box" pos="-0.205147 -0.241477 0.245415" size="0.11674989759922028 0.04351219907402992 0.004980413243174553" quat="1.0 0.0 0.0 0.0" />
                        <geom class="collision" type="box" pos="-0.205147 -0.241477 0.414756" size="0.11674989759922028 0.04351218789815903 0.004980411380529404" quat="1.0 0.0 0.0 0.0" />
                        <geom class="collision" type="box" pos="-0.205147 -0.241477 0.675923" size="0.11674989759922028 0.04351217672228813 0.004980409983545542" quat="1.0 0.0 0.0 0.0" />
                        <geom class="collision" type="box" pos="-0.319654 -0.241477 0.105974" size="0.004439220298081636 0.04351215809583664 0.0396893247961998" quat="1.0 0.0 0.0 0.0" />
                        <geom class="collision" type="box" pos="-0.319654 -0.241477 0.282324" size="0.004439220298081636 0.043512146919965744 0.0396893136203289" quat="1.0 0.0 0.0 0.0" />
                        <geom class="collision" type="box" pos="-0.319654 -0.241477 0.451665" size="0.004439220298081636 0.04351213574409485 0.03968930244445801" quat="1.0 0.0 0.0 0.0" />
                        <geom class="collision" type="box" pos="-0.319654 -0.241477 0.712832" size="0.004439220298081636 0.04351212456822395 0.03968929126858711" quat="1.0 0.0 0.0 0.0" />
                        <geom class="collision" type="box" pos="-0.090096 -0.241477 0.105974" size="0.0044392189010977745 0.04351210594177246 0.03968926891684532" quat="1.0 0.0 0.0 0.0" />
                        <geom class="collision" type="box" pos="-0.090096 -0.241477 0.282324" size="0.0044392189010977745 0.043512094765901566 0.03968925401568413" quat="1.0 0.0 0.0 0.0" />
                        <geom class="collision" type="box" pos="-0.090096 -0.241477 0.451665" size="0.0044392189010977745 0.04351208359003067 0.03968924283981323" quat="1.0 0.0 0.0 0.0" />
                        <geom class="collision" type="box" pos="-0.090096 -0.241477 0.712832" size="0.0044392189010977745 0.043512072414159775 0.03968923166394234" quat="1.0 0.0 0.0 0.0" />
                    </body>
                </body>
                <body name="Refrigerator061_Door002">
                    <joint axis="0.0 0.0 1.0" pos="0.350623 -0.310262 0.361598" limited="true" name="Refrigerator061_Door002_joint" range="0.0 1.5707963267948966" type="hinge" damping="1" frictionloss="1" armature=".01" stiffness="0.05" />
                    <geom mesh="Refrigerator061_Door002_vis" type="mesh" solimp="0.998 0.998 0.001" solref="0.001 1" density="100" friction="0.95 0.3 0.1" class="visual" material="Refrigerator061_Door002_material" />
                    <geom class="collision" type="cylinder" pos="0.099278 -0.370990 0.586713" size="0.005949943792074919 0.01835515722632408" quat="0.7071067094802856 0.7071068286895752 0.0 0.0" />
                    <geom class="collision" type="cylinder" pos="0.099278 -0.370478 0.274436" size="0.005949943792074919 0.01835515722632408" quat="0.7071067094802856 0.7071068286895752 0.0 0.0" />
                    <geom class="collision" type="cylinder" pos="0.099278 -0.395834 0.431864" size="0.010426044464111328 0.1963866651058197" quat="1.0 0.0 0.0 0.0" />
                    <geom class="collision" type="box" pos="0.190445 -0.325996 0.362320" size="0.17264603078365326 0.025374827906489372 0.5255938172340393" quat="1.0 0.0 0.0 0.0" />
                    <body name="Refrigerator061_Door002_Clear">
                        <geom mesh="Refrigerator061_Door002_Clear_vis" type="mesh" solimp="0.998 0.998 0.001" solref="0.001 1" density="100" friction="0.95 0.3 0.1" class="visual" material="Refrigerator061_Door002_Clear_material" />
                        <geom class="collision" type="box" pos="0.206158 -0.194566 0.710817" size="0.11674992740154266 0.005236928816884756 0.03987622633576393" quat="1.0 0.0 0.0 0.0" />
                        <geom class="collision" type="box" pos="0.206158 -0.241477 0.675923" size="0.11674989759922028 0.04351241886615753 0.004980443511158228" quat="1.0 0.0 0.0 0.0" />
                        <geom class="collision" type="box" pos="0.091651 -0.241477 0.712832" size="0.004439220298081636 0.04351240023970604 0.039689596742391586" quat="1.0 0.0 0.0 0.0" />
                        <geom class="collision" type="box" pos="0.321208 -0.241477 0.712832" size="0.0044392189010977745 0.04351238161325455 0.039689574390649796" quat="1.0 0.0 0.0 0.0" />
                        <geom class="collision" type="box" pos="0.206158 -0.194566 0.449649" size="0.11674992740154266 0.005236897151917219 0.03987588360905647" quat="1.0 0.0 0.0 0.0" />
                        <geom class="collision" type="box" pos="0.206158 -0.241477 0.414756" size="0.11674989759922028 0.04351237788796425 0.004980437457561493" quat="1.0 0.0 0.0 0.0" />
                        <geom class="collision" type="box" pos="0.091651 -0.241477 0.451665" size="0.004439220298081636 0.04351235553622246 0.03968954458832741" quat="1.0 0.0 0.0 0.0" />
                        <geom class="collision" type="box" pos="0.321208 -0.241477 0.451665" size="0.0044392189010977745 0.043512336909770966 0.039689525961875916" quat="1.0 0.0 0.0 0.0" />
                        <geom class="collision" type="box" pos="0.206158 -0.194566 0.280309" size="0.11674992740154266 0.005236865021288395 0.03987554460763931" quat="1.0 0.0 0.0 0.0" />
                        <geom class="collision" type="box" pos="0.206158 -0.241477 0.245415" size="0.11674989759922028 0.04351233318448067 0.004980431403964758" quat="1.0 0.0 0.0 0.0" />
                        <geom class="collision" type="box" pos="0.091651 -0.241477 0.282324" size="0.004439220298081636 0.043512310832738876 0.03968949615955353" quat="1.0 0.0 0.0 0.0" />
                        <geom class="collision" type="box" pos="0.321208 -0.241477 0.282324" size="0.0044392189010977745 0.043512292206287384 0.039689477533102036" quat="1.0 0.0 0.0 0.0" />
                        <geom class="collision" type="box" pos="0.206158 -0.194566 0.103959" size="0.11674992740154266 0.005236833356320858 0.039875201880931854" quat="1.0 0.0 0.0 0.0" />
                        <geom class="collision" type="box" pos="0.206158 -0.241477 0.069065" size="0.11674989759922028 0.043512288480997086 0.004980425350368023" quat="1.0 0.0 0.0 0.0" />
                        <geom class="collision" type="box" pos="0.091651 -0.241477 0.105974" size="0.004439220298081636 0.04351226985454559 0.03968944773077965" quat="1.0 0.0 0.0 0.0" />
                        <geom class="collision" type="box" pos="0.321208 -0.241477 0.105974" size="0.0044392189010977745 0.0435122475028038 0.03968942537903786" quat="1.0 0.0 0.0 0.0" />
                    </body>
                </body>
                <body name="Refrigerator061_Drawer001">
                    <joint axis="0.0 -1.0 0.0" pos="0.000212 -0.101561 -0.326216" limited="true" name="Refrigerator061_Drawer001_joint" range="0.0 0.3" type="slide" damping="1" frictionloss="1" armature=".01" stiffness="0.05" />
                    <geom mesh="Refrigerator061_Drawer001_vis" type="mesh" solimp="0.998 0.998 0.001" solref="0.001 1" density="100" friction="0.95 0.3 0.1" class="visual" material="Refrigerator061_Drawer001_material" />
                    <geom class="collision" type="box" pos="-0.000045 -0.319000 -0.327324" size="0.3769320249557495 0.031620871275663376 0.1460256427526474" quat="1.0 0.0 0.0 0.0" />
                    <geom class="collision" type="cylinder" pos="-0.008888 -0.396660 -0.256058" size="0.010426044464111328 0.1963866651058197" quat="0.7071068286895752 -0.0 0.7071067690849304 0.0" />
                    <geom class="collision" type="cylinder" pos="-0.162909 -0.374996 -0.256546" size="0.005949943792074919 0.01835515722632408" quat="0.7071067094802856 0.7071068286895752 0.0 0.0" />
                    <geom class="collision" type="cylinder" pos="0.149313 -0.374996 -0.256546" size="0.005949943792074919 0.01835515722632408" quat="0.7071067094802856 0.7071068286895752 0.0 0.0" />
                    <body name="Refrigerator061_Drawer001_Clear">
                        <geom mesh="Refrigerator061_Drawer001_Clear_vis" type="mesh" solimp="0.998 0.998 0.001" solref="0.001 1" density="100" friction="0.95 0.3 0.1" class="visual" material="Refrigerator061_Drawer001_Clear_material" />
                        <geom class="collision" type="box" pos="-0.000323 0.193918 -0.357234" size="0.3342480957508087 0.006893729791045189 0.07844812422990799" quat="1.0 0.0 0.0 0.0" />
                        <geom class="collision" type="box" pos="0.328246 -0.058631 -0.357234" size="0.0069589330814778805 0.24888737499713898 0.07844812422990799" quat="1.0 0.0 0.0 0.0" />
                        <geom class="collision" type="box" pos="-0.325276 -0.058631 -0.357234" size="0.0069589330814778805 0.24888737499713898 0.07844812422990799" quat="1.0 0.0 0.0 0.0" />
                        <geom class="collision" type="box" pos="0.001994 -0.058631 -0.428842" size="0.32403823733329773 0.24888737499713898 0.006856778170913458" quat="1.0 0.0 0.0 0.0" />
                    </body>
                </body>
                <body name="Refrigerator061_Drawer002">
                    <joint axis="0.0 -1.0 0.0" pos="0.000205 -0.113694 -0.679187" limited="true" name="Refrigerator061_Drawer002_joint" range="0.0 0.3" type="slide" damping="1" frictionloss="1" armature=".01" stiffness="0.05" />
                    <geom mesh="Refrigerator061_Drawer002_vis" type="mesh" solimp="0.998 0.998 0.001" solref="0.001 1" density="100" friction="0.95 0.3 0.1" class="visual" material="Refrigerator061_Drawer002_material" />
                    <geom class="collision" type="cylinder" pos="0.149313 -0.374996 -0.537744" size="0.005949943792074919 0.01835515722632408" quat="0.7071067094802856 0.7071068286895752 0.0 0.0" />
                    <geom class="collision" type="cylinder" pos="-0.162909 -0.374996 -0.537744" size="0.005949943792074919 0.01835515722632408" quat="0.7071067094802856 0.7071068286895752 0.0 0.0" />
                    <geom class="collision" type="cylinder" pos="-0.008888 -0.396660 -0.537256" size="0.010426044464111328 0.1963866651058197" quat="0.7071068286895752 -0.0 0.7071067690849304 0.0" />
                    <geom class="collision" type="box" pos="-0.000045 -0.319000 -0.679969" size="0.3769320249557495 0.031620871275663376 0.19834721088409424" quat="1.0 0.0 0.0 0.0" />
                    <body name="Refrigerator061_Drawer002_Clear">
                        <geom mesh="Refrigerator061_Drawer002_Clear_vis" type="mesh" solimp="0.998 0.998 0.001" solref="0.001 1" density="100" friction="0.95 0.3 0.1" class="visual" material="Refrigerator061_Drawer002_Clear_material" />
                        <geom class="collision" type="box" pos="0.001994 -0.072964 -0.818521" size="0.32403823733329773 0.23455514013767242 0.006856778170913458" quat="1.0 0.0 0.0 0.0" />
                        <geom class="collision" type="box" pos="-0.325276 -0.072964 -0.700285" size="0.0069589330814778805 0.23455514013767242 0.12507569789886475" quat="1.0 0.0 0.0 0.0" />
                        <geom class="collision" type="box" pos="0.328246 -0.072964 -0.700285" size="0.0069589330814778805 0.23455514013767242 0.12507569789886475" quat="1.0 0.0 0.0 0.0" />
                        <geom class="collision" type="box" pos="-0.000323 0.165253 -0.700285" size="0.3342480957508087 0.0068937307223677635 0.12507571280002594" quat="1.0 0.0 0.0 0.0" />
                    </body>
                </body>
            </body>
        </body>
    </worldbody>
    <actuator>
        <motor name="Refrigerator061_Door001_joint_actuator" joint="Refrigerator061_Door001_joint" gear="50" />
        <motor name="Refrigerator061_Door002_joint_actuator" joint="Refrigerator061_Door002_joint" gear="50" />
        <motor name="Refrigerator061_Drawer001_joint_actuator" joint="Refrigerator061_Drawer001_joint" gear="50" />
        <motor name="Refrigerator061_Drawer002_joint_actuator" joint="Refrigerator061_Drawer002_joint" gear="50" />
    </actuator>
</mujoco>