<mujoco model="model">
  <compiler angle="radian"/>
  <asset>
    <mesh file="visuals/handle.obj" name="handle_vis"/>
    <mesh file="visuals/Body001.obj" name="Body001_vis"/>
    <mesh file="visuals/Funnel001.obj" name="Funnel001_vis"/>
    <mesh file="visuals/spout.obj" name="spout_vis"/>
    <texture file="visuals/T_BC001.png" name="Body001_material" type="2d"/>
    <material name="Body001_material" rgba="1 1 1 1.0" texture="Body001_material" shininess="0.141421377658844" specular="0.3103448502657381"/>
    <texture file="visuals/T_BC001.png" name="handle_material" type="2d"/>
    <material name="handle_material" rgba="1 1 1 1.0" texture="handle_material" shininess="0.141421377658844" specular="0.3103448502657381"/>
    <texture file="visuals/T_BC001.png" name="Funnel001_material" type="2d"/>
    <material name="Funnel001_material" rgba="1 1 1 1.0" texture="Funnel001_material" shininess="0.141421377658844" specular="0.3103448502657381"/>
    <texture file="visuals/T_BC001.png" name="spout_material" type="2d"/>
    <material name="spout_material" rgba="1 1 1 1.0" texture="spout_material" shininess="0.141421377658844" specular="0.3103448502657381"/>
  </asset>
  <default>
    <default class="visual">
      <geom conaffinity="0" contype="0" group="1" type="mesh"/>
    </default>
    <default class="collision">
      <geom group="0" rgba="0.5 0 0 0.5"/>
    </default>
    <default class="spawn">
      <geom group="0" rgba="1 1 1 0.5" contype="0" conaffinity="0"/>
      <site group="0" rgba="1 1 1 0.5"/>
    </default>
    <default class="region">
      <geom group="1" conaffinity="0" contype="0" rgba="0 1 0 0"/>
    </default>
  </default>
  <worldbody>
    <body>
      <body name="object">
        <geom mesh="Body001_vis" type="mesh" solimp="0.998 0.998 0.001" solref="0.001 1" density="100" friction="0.95 0.3 0.1" class="visual" material="Body001_material"/>
        <geom class="collision" type="box" pos="-0.35472372174263 0.003450560849159956 -0.2585802674293518" size="0.017459595575928688 0.30458343029022217 0.13868075609207153" quat="1.0 0.0 0.0 0.0"/>
        <geom class="collision" type="box" pos="0.354698121547699 -0.002510946709662676 -0.2585802674293518" size="0.01739576645195484 0.3055230379104614 0.13868075609207153" quat="1.0 0.0 0.0 0.0"/>
        <geom class="collision" type="box" pos="-0.0007268190383911133 -0.22849918901920319 -0.36672431230545044" size="0.33796435594558716 0.038684990257024765 0.03053669072687626" quat="1.0 0.0 0.0 0.0"/>
        <geom class="collision" type="box" pos="0.0005569830536842346 0.23685310781002045 -0.2585802674293518" size="0.3362390995025635 0.07118088752031326 0.13868075609207153" quat="1.0 0.0 0.0 0.0"/>
        <geom class="collision" type="box" pos="0.0005569830536842346 -0.28473401069641113 -0.2585802674293518" size="0.3362390995025635 0.02329997718334198 0.13868075609207153" quat="1.0 0.0 0.0 0.0"/>
        <geom class="collision" type="cylinder" pos="0.0 0.26357266306877136 -0.0357801653444767" size="0.030178183689713478 0.08440031111240387" quat="1.0 0.0 0.0 0.0"/>
        <geom class="collision" type="cylinder" pos="0.0381937175989151 0.26223665475845337 -0.016653666272759438" size="0.021399369463324547 0.019612431526184082" quat="0.5000000596046448 0.5 0.4999999701976776 0.5"/>
        <geom class="collision" type="box" pos="-0.0007268190383911133 0.1367899626493454 -0.36672431230545044" size="0.33796435594558716 0.038684990257024765 0.03053669072687626" quat="1.0 0.0 0.0 0.0"/>
        <geom class="collision" type="box" pos="-0.22707338631153107 -0.046030193567276 -0.36672431230545044" size="0.1116178035736084 0.14057162404060364 0.03053669072687626" quat="1.0 0.0 0.0 0.0"/>
        <geom class="collision" type="box" pos="0.23310363292694092 -0.046030193567276 -0.36672431230545044" size="0.11229205131530762 0.14057162404060364 0.03053669072687626" quat="1.0 0.0 0.0 0.0"/>
        <geom class="collision" type="box" pos="0.002433479530736804 -0.046030193567276 -0.37644317746162415" size="0.1174427941441536 0.14057162404060364 0.020817838609218597" quat="1.0 0.0 0.0 0.0"/>
        <body name="handle">
          <joint axis="1.0 0.0 0.0" pos="0.08304321765899658 0.26247984170913696 -0.01761959306895733" limited="true" name="handle_joint_hinge_0" type="hinge" range="-0.7853981633974483 0.7853981633974483" damping="1" frictionloss="1" armature=".01" stiffness="0.05"/>
          <joint axis="0.0 1.0 0.0" pos="0.08304321765899658 0.26247984170913696 -0.01761959306895733" limited="true" name="handle_joint_hinge_1" type="hinge" range="0.0 0.17453292519943295" damping="1" frictionloss="1" armature=".01" stiffness="0.05"/>
          <geom mesh="handle_vis" type="mesh" solimp="0.998 0.998 0.001" solref="0.001 1" density="100" friction="0.95 0.3 0.1" class="visual" material="handle_material"/>
          <geom class="collision" type="cylinder" pos="0.08161629736423492 0.26223665475845337 -0.017258981242775917" size="0.02353030815720558 0.009531225077807903" quat="0.5000000596046448 0.5 0.4999999701976776 0.5"/>
          <geom class="collision" type="cylinder" pos="0.08213990181684494 0.26221564412117004 0.04712838679552078" size="0.004157292190939188 0.04314939305186272" quat="5.338507946817117e-08 0.7071068286895752 0.7071067690849304 5.338507591545749e-08"/>
        </body>
        <body name="Funnel001">
          <joint axis="0.0 0.0 1.0" pos="-0.00029741227626800537 -0.047115691006183624 -0.34338676929473877" limited="true" name="Funnel001_joint" range="0.0 0.1" type="slide" damping="1" frictionloss="1" armature=".01" stiffness="0.05"/>
          <geom mesh="Funnel001_vis" type="mesh" solimp="0.998 0.998 0.001" solref="0.001 1" density="100" friction="0.95 0.3 0.1" class="visual" material="Funnel001_material"/>
          <geom class="collision" type="box" pos="-0.0006947148940525949 -0.047130558639764786 -0.34264999628067017" size="0.11300185322761536 0.13947126269340515 0.006462354678660631" quat="1.0 0.0 0.0 0.0"/>
        </body>
        <body name="spout">
          <joint axis="0.0 0.0 1.0" pos="-0.00023473729379475117 0.26321130990982056 0.22852367162704468" limited="true" name="spout_joint" range="-1.0471975511965976 1.0471975511965976" type="hinge" damping="1" frictionloss="1" armature=".01" stiffness="0.05"/>
          <site type="cylinder" rgba="0.5 0.75 1 1" size="0.011609294451773167 0.2936442196369171" pos="-0.00281657837331295 -0.004005800001323223 -0.05401162803173065" name="water"/>
          <geom mesh="spout_vis" type="mesh" solimp="0.998 0.998 0.001" solref="0.001 1" density="100" friction="0.95 0.3 0.1" class="visual" material="spout_material"/>
          <geom class="collision" type="cylinder" pos="0.0 0.26357266306877136 0.16798046231269836" size="0.01867983676493168 0.11879255622625351" quat="1.0 0.0 0.0 0.0"/>
          <geom class="collision" type="cylinder" pos="-9.729896416431587e-18 0.23791363835334778 0.3319263160228729" size="0.01867983676493168 0.019234102219343185" quat="0.9550366401672363 0.29648780822753906 -7.311360098850056e-17 7.311360098850056e-17"/>
          <geom class="collision" type="cylinder" pos="-0.001114597893320024 0.16607455909252167 0.37831246852874756" size="0.01867983676493168 0.023211244493722916" quat="0.6504695415496826 -0.7595323324203491 -1.6865005668006397e-16 -5.628278406301753e-24"/>
          <geom class="collision" type="cylinder" pos="-6.0354604737666124e-18 0.2563072741031647 0.2980877757072449" size="0.01867983676493168 0.018054183572530746" quat="0.9834555983543396 0.18114939332008362 -2.589090371978125e-17 8.142349050943278e-18"/>
          <geom class="collision" type="cylinder" pos="-0.001114597893320024 0.20655250549316406 0.36085188388824463" size="0.01867983676493168 0.024418875575065613" quat="0.48208555579185486 -0.8761241436004639 -1.4639573506372512e-16 -4.6039526244664284e-17"/>
          <geom class="collision" type="cylinder" pos="-0.001114597893320024 0.11912503838539124 0.3805089592933655" size="0.01867983676493168 0.023211244493722916" quat="0.7335634827613831 -0.6796209216117859 -1.5090617227296447e-16 -9.249887940643032e-24"/>
          <geom class="collision" type="cylinder" pos="-0.001114597893320024 0.07492110133171082 0.3711739778518677" size="0.01867983676493168 0.023211244493722916" quat="0.8416051268577576 -0.5400933027267456 -1.1992480402661556e-16 -1.922622211168599e-23"/>
          <geom class="collision" type="cylinder" pos="-0.001114597893320024 0.035384662449359894 0.3445417881011963" size="0.01867983676493168 0.023211244493722916" quat="0.919505774974823 -0.3930765390396118 -8.728052481634925e-17 -1.5388194504454115e-23"/>
          <geom class="collision" type="cylinder" pos="-0.001114597893320024 0.00875491090118885 0.307545930147171" size="0.01867983676493168 0.023211244493722916" quat="0.9744263291358948 -0.22470726072788239 -4.98950382408311e-17 -1.1878729041968603e-23"/>
          <geom class="collision" type="cylinder" pos="-0.001114597893320024 -0.0015410357154905796 0.2650274634361267" size="0.01867983676493168 0.023211244493722916" quat="0.9989654421806335 -0.04547513648867607 -1.0097504579636891e-17 -1.2374663016114802e-23"/>
          <geom class="collision" type="cylinder" pos="-0.000953328562900424 -0.002737293252721429 0.23661890625953674" size="0.01867983676493168 0.012093055993318558" quat="1.0 0.0 0.0 0.0"/>
        </body>
        <geom class="region" name="reg_main" type="box" pos="0.0 -1.4901161193847656e-08 -0.2585802674293518" size="0.37218332290649414 0.3080340027809143 0.13868075609207153"/>
        <geom class="region" name="reg_basin" type="box" pos="0.001467868685722351 -0.048853710293769836 -0.22739652544260025" size="0.3329167813062668 0.21601299941539764 0.10395880788564682"/>
      </body>
    </body>
  </worldbody>
  <actuator>
    <motor name="handle_joint_hinge_0_actuator" joint="handle_joint_hinge_0" gear="10"/>
    <motor name="handle_joint_hinge_1_actuator" joint="handle_joint_hinge_1" gear="10"/>
    <motor name="Funnel001_joint_actuator" joint="Funnel001_joint" gear="10"/>
    <motor name="spout_joint_actuator" joint="spout_joint" gear="10"/>
  </actuator>
</mujoco>
