<?xml version='1.0' encoding='UTF-8'?>
<mujoco model="model">
  <compiler angle="radian"/>
  <asset>
    <mesh file="visuals/knob_front_left.obj" name="knob_front_left_vis"/>
    <mesh file="visuals/knob_front_right.obj" name="knob_front_right_vis"/>
    <mesh file="visuals/knob_rear_left.obj" name="knob_rear_left_vis"/>
    <mesh file="visuals/knob_rear_right.obj" name="knob_rear_right_vis"/>
    <mesh file="visuals/Body001.obj" name="Body001_vis"/>
    <mesh file="visuals/Body002.obj" name="Body002_vis"/>
    <mesh file="visuals/Door001.obj" name="Door001_vis"/>
    <mesh file="visuals/Door001_Clear.obj" name="Door001_Clear_vis"/>
    <mesh file="visuals/Knob001.obj" name="Knob001_vis"/>
    <mesh file="visuals/Knob002.obj" name="Knob002_vis"/>
    <mesh file="visuals/Shelf001.obj" name="Shelf001_vis"/>
    <mesh file="visuals/Shelf002.obj" name="Shelf002_vis"/>
    <texture file="visuals/T_BC001.png" name="Body001_material" type="2d"/>
    <material name="Body001_material" rgba="1 1 1 1.0" texture="Body001_material" shininess="0.1" specular="2"/>
    <texture file="visuals/T_BC001.png" name="knob_front_left_material" type="2d"/>
    <material name="knob_front_left_material" rgba="1 1 1 1.0" texture="knob_front_left_material" shininess="0.1" specular="1"/>
    <texture file="visuals/T_BC001.png" name="knob_front_right_material" type="2d"/>
    <material name="knob_front_right_material" rgba="1 1 1 1.0" texture="knob_front_right_material" shininess="0.1" specular="1"/>
    <texture file="visuals/T_BC001.png" name="knob_rear_left_material" type="2d"/>
    <material name="knob_rear_left_material" rgba="1 1 1 1.0" texture="knob_rear_left_material" shininess="0.1" specular="1"/>
    <texture file="visuals/T_BC001.png" name="knob_rear_right_material" type="2d"/>
    <material name="knob_rear_right_material" rgba="1 1 1 1.0" texture="knob_rear_right_material" shininess="0.1" specular="1"/>
    <texture file="visuals/T_BC001.png" name="Body002_material" type="2d"/>
    <material name="Body002_material" rgba="1 1 1 1.0" texture="Body002_material" shininess="0.1" specular="1"/>
    <texture file="visuals/T_BC001.png" name="Door001_material" type="2d"/>
    <material name="Door001_material" rgba="1 1 1 1.0" texture="Door001_material" shininess="0.1" specular="1"/>
    <material name="Door001_Clear_material" rgba="0.3919156491756439 0.3919156491756439 0.3919156491756439 0.5" shininess="0.1" specular="1"/>
    <texture file="visuals/T_BC001.png" name="Knob001_material" type="2d"/>
    <material name="Knob001_material" rgba="1 1 1 1.0" texture="Knob001_material" shininess="0.1" specular="1"/>
    <texture file="visuals/T_BC001.png" name="Knob002_material" type="2d"/>
    <material name="Knob002_material" rgba="1 1 1 1.0" texture="Knob002_material" shininess="0.1" specular="1"/>
    <texture file="visuals/T_BC001.png" name="Shelf001_material" type="2d"/>
    <material name="Shelf001_material" rgba="1 1 1 1.0" texture="Shelf001_material" shininess="0.1" specular="1"/>
    <texture file="visuals/T_BC001.png" name="Shelf002_material" type="2d"/>
    <material name="Shelf002_material" rgba="1 1 1 1.0" texture="Shelf002_material" shininess="0.1" specular="1"/>
  </asset>
  <default>
    <default class="visual">
      <geom conaffinity="0" contype="0" group="1" type="mesh"/>
    </default>
    <default class="collision">
      <geom group="0" rgba="0.5 0 0 0.5"/>
    </default>
    <default class="spawn">
      <geom group="0" rgba="1 1 1 0.5" contype="0" conaffinity="0"/>
      <site group="0" rgba="1 1 1 0.5"/>
    </default>
    <default class="region">
      <geom group="1" conaffinity="0" contype="0" rgba="0 1 0 0"/>
    </default>
  </default>
  <worldbody>
    <body>
      <body name="object">
        <site type="cylinder" rgba="0.3 0.4 1 0.5" size="0.07357610762119293 0.0070569878444075584" pos="-0.15963366627693176 -0.10725317895412445 0.468623548746109" name="burner_on_front_left"/>
        <site type="cylinder" rgba="0.3 0.4 1 0.5" size="0.07357610762119293 0.0070569878444075584" pos="0.15184441208839417 -0.10725317895412445 0.468623548746109" name="burner_on_front_right"/>
        <site type="cylinder" rgba="0.3 0.4 1 0.5" size="0.07357610762119293 0.0070569878444075584" pos="-0.15963366627693176 0.1568083018064499 0.468623548746109" name="burner_on_rear_left"/>
        <site type="cylinder" rgba="0.3 0.4 1 0.5" size="0.07357610762119293 0.0070569878444075584" pos="0.15184441208839417 0.1568083018064499 0.468623548746109" name="burner_on_rear_right"/>
        <geom mesh="Body001_vis" type="mesh" solimp="0.998 0.998 0.001" solref="0.001 1" density="100" friction="0.95 0.3 0.1" class="visual" material="Body001_material"/>
        <geom class="collision" type="box" pos="0.0 0.03086765669286251 0.43377214670181274" size="0.3763693869113922 0.3646935522556305 0.03754124045372009" quat="1.0 0.0 0.0 0.0"/>
        <geom class="collision" type="box" pos="-0.006305759772658348 0.026157546788454056 0.47956278920173645" size="0.2919226288795471 0.2680940330028534 0.01525197271257639" quat="1.0 0.0 0.0 0.0"/>
        <geom class="collision" type="box" pos="0.0 0.04199814796447754 0.30052563548088074" size="0.3763693869113922 0.3535631000995636 0.09539087116718292" quat="1.0 0.0 0.0 0.0"/>
        <geom class="collision" type="box" pos="-0.32309895753860474 0.057262521237134933 -0.09348022937774658" size="0.05327043682336807 0.3382987082004547 0.31983500719070435" quat="1.0 0.0 0.0 0.0"/>
        <geom class="collision" type="box" pos="0.32322534918785095 0.057262521237134933 -0.09348022937774658" size="0.05314407870173454 0.3382987082004547 0.31983500719070435" quat="1.0 0.0 0.0 0.0"/>
        <geom class="collision" type="box" pos="0.006585642695426941 0.057262521237134933 -0.3596256971359253" size="0.2886805534362793 0.3382987082004547 0.053689561784267426" quat="1.0 0.0 0.0 0.0"/>
        <geom class="collision" type="box" pos="0.006585642695426941 0.2979070842266083 -0.05163457989692688" size="0.2886805534362793 0.09765408933162689 0.2812975347042084" quat="1.0 0.0 0.0 0.0"/>
        <geom class="collision" type="box" pos="0.006585642695426941 0.057262521237134933 0.16087020933628082" size="0.2886805534362793 0.3382987082004547 0.053689561784267426" quat="1.0 0.0 0.0 0.0"/>
        <geom class="collision" type="cylinder" pos="-0.27166327834129333 0.32449132204055786 -0.4482637047767639" size="0.04706542566418648 0.04655295982956886" quat="1.0 0.0 0.0 0.0"/>
        <geom class="collision" type="cylinder" pos="0.2722174823284149 0.32449132204055786 -0.4482637047767639" size="0.04706542566418648 0.04655295982956886" quat="1.0 0.0 0.0 0.0"/>
        <geom class="collision" type="cylinder" pos="0.2722174823284149 -0.22101905941963196 -0.4482637047767639" size="0.04706542566418648 0.04655295982956886" quat="1.0 0.0 0.0 0.0"/>
        <geom class="collision" type="cylinder" pos="-0.2722606658935547 -0.22101905941963196 -0.4482637047767639" size="0.04706542566418648 0.04655295982956886" quat="1.0 0.0 0.0 0.0"/>
        <geom class="collision" type="box" pos="-0.25629091262817383 -0.033120300620794296 -0.04849499091506004" size="0.02580404467880726 0.20058277249336243 0.0038279599975794554" quat="1.0 0.0 0.0 0.0"/>
        <geom class="collision" type="box" pos="-0.25629091262817383 -0.01993267424404621 -0.06944065541028976" size="0.02580404467880726 0.20058277249336243 0.0038279599975794554" quat="1.0 0.0 0.0 0.0"/>
        <geom class="collision" type="box" pos="-0.25629091262817383 -0.01993267424404621 -0.20191225409507751" size="0.02580404467880726 0.20058277249336243 0.0038279599975794554" quat="1.0 0.0 0.0 0.0"/>
        <geom class="collision" type="box" pos="-0.25629091262817383 -0.033120300620794296 -0.18262764811515808" size="0.02580404467880726 0.20058277249336243 0.0038279599975794554" quat="1.0 0.0 0.0 0.0"/>
        <geom class="collision" type="box" pos="0.26043957471847534 -0.033120300620794296 -0.18262764811515808" size="0.02580404467880726 0.20058277249336243 0.0038279599975794554" quat="1.0 0.0 0.0 0.0"/>
        <geom class="collision" type="box" pos="0.25882387161254883 -0.01993267424404621 -0.20191225409507751" size="0.02580404467880726 0.20058277249336243 0.0038279599975794554" quat="1.0 0.0 0.0 0.0"/>
        <geom class="collision" type="box" pos="0.25882387161254883 -0.01993267424404621 -0.06903617084026337" size="0.02580404467880726 0.20058277249336243 0.0038279599975794554" quat="1.0 0.0 0.0 0.0"/>
        <geom class="collision" type="box" pos="0.26043957471847534 -0.033120300620794296 -0.04975156486034393" size="0.02580404467880726 0.20058277249336243 0.0038279599975794554" quat="1.0 0.0 0.0 0.0"/>
        <body name="knob_front_left">
          <joint axis="0.0 -1.0 0.0" pos="-0.32040098309516907 -0.3286569118499756 0.3257809281349182" limited="true" name="knob_front_left_joint" range="0.0 3.141592653589793" type="hinge" damping="0.05" armature="0.001"/>
          <geom mesh="knob_front_left_vis" type="mesh" solimp="0.998 0.998 0.001" solref="0.001 1" density="100" friction="0.95 0.3 0.1" class="visual" material="knob_front_left_material"/>
          <geom class="collision" type="cylinder" pos="-0.3210730254650116 -0.32377225160598755 0.32581019401550293" size="0.034505799412727356 0.00798241887241602" quat="0.7071067094802856 0.7071068286895752 0.0 0.0"/>
          <geom class="collision" type="box" pos="-0.3196628987789154 -0.33963024616241455 0.3263888359069824" size="0.008670815266668797 0.007262000814080238 0.02791677787899971" quat="1.0 0.0 0.0 0.0" name="knob_front_left_main"/>
        </body>
        <body name="knob_front_right">
          <joint axis="0.0 -1.0 0.0" pos="0.32292112708091736 -0.3286569118499756 0.3257809281349182" limited="true" name="knob_front_right_joint" range="0.0 3.141592653589793" type="hinge" damping="0.05" armature="0.001"/>
          <geom mesh="knob_front_right_vis" type="mesh" solimp="0.998 0.998 0.001" solref="0.001 1" density="100" friction="0.95 0.3 0.1" class="visual" material="knob_front_right_material"/>
          <geom class="collision" type="box" pos="0.3228445053100586 -0.33963024616241455 0.3263888359069824" size="0.008670815266668797 0.007262000814080238 0.02791677787899971" quat="1.0 0.0 0.0 0.0" name="knob_front_right_main"/>
          <geom class="collision" type="cylinder" pos="0.3227652907371521 -0.32377225160598755 0.32581019401550293" size="0.034505799412727356 0.00798241887241602" quat="0.7071067094802856 0.7071068286895752 0.0 0.0"/>
        </body>
        <body name="knob_rear_left">
          <joint axis="0.0 -1.0 0.0" pos="-0.19112378358840942 -0.3286569118499756 0.3257809281349182" limited="true" name="knob_rear_left_joint" range="0.0 3.141592653589793" type="hinge" damping="0.05" armature="0.001"/>
          <geom mesh="knob_rear_left_vis" type="mesh" solimp="0.998 0.998 0.001" solref="0.001 1" density="100" friction="0.95 0.3 0.1" class="visual" material="knob_rear_left_material"/>
          <geom class="collision" type="box" pos="-0.19054844975471497 -0.33963024616241455 0.3263888359069824" size="0.008670815266668797 0.007262000814080238 0.02791677787899971" quat="1.0 0.0 0.0 0.0" name="knob_rear_left_main"/>
          <geom class="collision" type="cylinder" pos="-0.19195857644081116 -0.32377225160598755 0.32581019401550293" size="0.034505799412727356 0.00798241887241602" quat="0.7071067094802856 0.7071068286895752 0.0 0.0"/>
        </body>
        <body name="knob_rear_right">
          <joint axis="0.0 -1.0 0.0" pos="0.19418977200984955 -0.3286569118499756 0.3257809281349182" limited="true" name="knob_rear_right_joint" range="0.0 3.141592653589793" type="hinge" damping="0.05" armature="0.001"/>
          <geom mesh="knob_rear_right_vis" type="mesh" solimp="0.998 0.998 0.001" solref="0.001 1" density="100" friction="0.95 0.3 0.1" class="visual" material="knob_rear_right_material"/>
          <geom class="collision" type="box" pos="0.19378328323364258 -0.33963024616241455 0.3263888359069824" size="0.008670815266668797 0.007262000814080238 0.02791677787899971" quat="1.0 0.0 0.0 0.0" name="knob_rear_right_main"/>
          <geom class="collision" type="cylinder" pos="0.19389420747756958 -0.32377225160598755 0.32581019401550293" size="0.034505799412727356 0.00798241887241602" quat="0.7071067094802856 0.7071068286895752 0.0 0.0"/>
        </body>
        <body name="Body002">
          <geom mesh="Body002_vis" type="mesh" solimp="0.998 0.998 0.001" solref="0.001 1" density="100" friction="0.95 0.3 0.1" class="visual" material="Body002_material"/>
        </body>
        <body name="Door001">
          <joint axis="1.0 0.0 0.0" pos="-0.01463734358549118 -0.2801492214202881 -0.38982415199279785" limited="true" name="Door001_joint" range="0.0 1.5707963267948966" type="hinge" damping="1" frictionloss="1" armature=".01" stiffness="4" springref="-1"/>
          <geom mesh="Door001_vis" type="mesh" solimp="0.998 0.998 0.001" solref="0.001 1" density="100" friction="0.95 0.3 0.1" class="visual" material="Door001_material"/>
          <geom class="collision" type="box" pos="0.00021983569604344666 -0.29964780807495117 -0.07998877763748169" size="0.3707135319709778 0.01222648099064827 0.2822990417480469" quat="1.0 0.0 0.0 0.0"/>
          <geom class="collision" type="box" pos="-0.26121705770492554 -0.3563361167907715 0.1604902595281601" size="0.017483213916420937 0.04034731164574623 0.03301427513360977" quat="1.0 0.0 0.0 0.0"/>
          <geom class="collision" type="box" pos="0.2615010738372803 -0.3563361167907715 0.1604902595281601" size="0.017483221367001534 0.040347326546907425 0.033014290034770966" quat="1.0 0.0 0.0 0.0"/>
          <geom class="collision" type="cylinder" pos="0.0019762665033340454 -0.37796130776405334 0.15523867309093475" size="0.015277725644409657 0.24750691652297974" quat="0.7071068286895752 -0.0 0.7071067690849304 0.0"/>
          <body name="Door001_Clear">
            <geom mesh="Door001_Clear_vis" type="mesh" solimp="0.998 0.998 0.001" solref="0.001 1" density="100" friction="0.95 0.3 0.1" class="visual" material="Door001_Clear_material"/>
            <geom class="collision" type="box" pos="0.0032850790303200483 -0.29997652769088745 -0.10900797694921494" size="0.24195370078086853 0.003646909026429057 0.16780593991279602" quat="1.0 0.0 0.0 0.0"/>
          </body>
        </body>
        <body name="Knob001">
          <joint axis="0.0 1.0 0.0" pos="-0.06271379441022873 -0.3286569118499756 0.3257809281349182" limited="true" name="Knob001_joint" range="0.0 4.014257279586958" type="hinge" damping="0.05" armature="0.001"/>
          <geom mesh="Knob001_vis" type="mesh" solimp="0.998 0.998 0.001" solref="0.001 1" density="100" friction="0.95 0.3 0.1" class="visual" material="Knob001_material"/>
          <geom class="collision" type="box" pos="-0.062285758554935455 -0.33963024616241455 0.3263888359069824" size="0.008670815266668797 0.007262000814080238 0.02791677787899971" quat="1.0 0.0 0.0 0.0"/>
          <geom class="collision" type="cylinder" pos="-0.06369588524103165 -0.32377225160598755 0.32581019401550293" size="0.034505799412727356 0.00798241887241602" quat="0.7071067094802856 0.7071068286895752 0.0 0.0"/>
        </body>
        <body name="Knob002">
          <joint axis="0.0 1.0 0.0" pos="0.06530759483575821 -0.3286569118499756 0.3257809281349182" limited="true" name="Knob002_joint" range="0.0 3.2288591161895095" type="hinge" damping="0.05" armature="0.001"/>
          <geom mesh="Knob002_vis" type="mesh" solimp="0.998 0.998 0.001" solref="0.001 1" density="100" friction="0.95 0.3 0.1" class="visual" material="Knob002_material"/>
          <geom class="collision" type="box" pos="0.06666139513254166 -0.33963024616241455 0.3263888359069824" size="0.02791677787899971 0.007262000814080238 0.008670817129313946" quat="1.0 0.0 0.0 0.0"/>
          <geom class="collision" type="cylinder" pos="0.06525126844644547 -0.32377225160598755 0.32581019401550293" size="0.034505799412727356 0.00798241887241602" quat="0.7071067094802856 0.7071068286895752 0.0 0.0"/>
        </body>
        <body name="Shelf001">
          <joint axis="0.0 -1.0 0.0" pos="-0.002451067790389061 -0.02057851478457451 -0.06110106036067009" limited="true" name="Shelf001_joint" range="0.0 0.3" type="slide" damping="1" frictionloss="1" armature=".01" stiffness="0.05"/>
          <geom mesh="Shelf001_vis" type="mesh" solimp="0.998 0.998 0.001" solref="0.001 1" density="100" friction="0.95 0.3 0.1" class="visual" material="Shelf001_material"/>
          <geom class="collision" type="box" pos="0.0030691921710968018 -0.02330368012189865 -0.059544190764427185" size="0.22826971113681793 0.18145930767059326 0.0038279599975794554" quat="1.0 0.0 0.0 0.0"/>
        </body>
        <body name="Shelf002">
          <joint axis="0.0 -1.0 0.0" pos="-0.002451067790389061 -0.020578503608703613 -0.19637905061244965" limited="true" name="Shelf002_joint" range="0.0 0.3" type="slide" damping="1" frictionloss="1" armature=".01" stiffness="0.05"/>
          <geom mesh="Shelf002_vis" type="mesh" solimp="0.998 0.998 0.001" solref="0.001 1" density="100" friction="0.95 0.3 0.1" class="visual" material="Shelf002_material"/>
          <geom class="collision" type="box" pos="0.0030691921710968018 -0.02330368012189865 -0.19393564760684967" size="0.22826971113681793 0.18145930767059326 0.0038279599975794554" quat="1.0 0.0 0.0 0.0"/>
        </body>
        <site name="burner_front_left_place_site" type="cylinder" rgba="0.3 0.4 1 0" size="0.07357610762119293 0.0070569878444075584" pos="-0.15963366627693176 -0.10725317895412445 0.468623548746109"/>
        <site name="burner_front_right_place_site" type="cylinder" rgba="0.3 0.4 1 0" size="0.07357610762119293 0.0070569878444075584" pos="0.15184441208839417 -0.10725317895412445 0.468623548746109"/>
        <site name="burner_rear_left_place_site" type="cylinder" rgba="0.3 0.4 1 0" size="0.07357610762119293 0.0070569878444075584" pos="-0.15963366627693176 0.1568083018064499 0.468623548746109"/>
        <site name="burner_rear_right_place_site" type="cylinder" rgba="0.3 0.4 1 0" size="0.07357610762119293 0.0070569878444075584" pos="0.15184441208839417 0.1568083018064499 0.468623548746109"/>
        <geom class="region" name="reg_main" type="box" pos="-7.450580596923828e-09 0.041034772992134094 -9.685754776000977e-07" size="0.3763694167137146 0.35452643036842346 0.4948157072067261"/>
        <geom class="region" name="reg_int" type="box" pos="0.0021431148052215576 -0.036226481199264526 -0.08823640644550323" size="0.27363157272338867 0.24100592732429504 0.21947170794010162"/>
      </body>
    </body>
  </worldbody>
  <actuator>
    <motor name="knob_front_left_joint_actuator" joint="knob_front_left_joint" gear="10"/>
    <motor name="knob_front_right_joint_actuator" joint="knob_front_right_joint" gear="10"/>
    <motor name="knob_rear_left_joint_actuator" joint="knob_rear_left_joint" gear="10"/>
    <motor name="knob_rear_right_joint_actuator" joint="knob_rear_right_joint" gear="10"/>
    <motor name="Door001_joint_actuator" joint="Door001_joint" gear="50"/>
    <motor name="Knob001_joint_actuator" joint="Knob001_joint" gear="50"/>
    <motor name="Knob002_joint_actuator" joint="Knob002_joint" gear="50"/>
    <motor name="Shelf001_joint_actuator" joint="Shelf001_joint" gear="50"/>
    <motor name="Shelf002_joint_actuator" joint="Shelf002_joint" gear="50"/>
  </actuator>
</mujoco>
