<mujoco model="model">
  <compiler angle="radian"/>
  <asset>
    <mesh file="visuals/handle.obj" name="handle_vis"/>
    <mesh file="visuals/Body001.obj" name="Body001_vis"/>
    <mesh file="visuals/Container001.obj" name="Container001_vis"/>
    <mesh file="visuals/Funnel001.obj" name="Funnel001_vis"/>
    <mesh file="visuals/spout.obj" name="spout_vis"/>
    <texture file="visuals/T_BC001.png" name="Body001_material" type="2d"/>
    <material name="Body001_material" rgba="1 1 1 1.0" texture="Body001_material" shininess="0.5" specular="0.3103448502657381"/>
    <texture file="visuals/T_BC001.png" name="handle_material" type="2d"/>
    <material name="handle_material" rgba="1 1 1 1.0" texture="handle_material" shininess="0.5" specular="0.3103448502657381"/>
    <texture file="visuals/T_BC001.png" name="Container001_material" type="2d"/>
    <material name="Container001_material" rgba="1 1 1 1.0" texture="Container001_material" shininess="0.5" specular="0.3103448502657381"/>
    <texture file="visuals/T_BC001.png" name="Funnel001_material" type="2d"/>
    <material name="Funnel001_material" rgba="1 1 1 1.0" texture="Funnel001_material" shininess="0.5" specular="0.3103448502657381"/>
    <texture file="visuals/T_BC001.png" name="spout_material" type="2d"/>
    <material name="spout_material" rgba="1 1 1 1.0" texture="spout_material" shininess="0.5" specular="0.3103448502657381"/>
  </asset>
  <default>
    <default class="visual">
      <geom conaffinity="0" contype="0" group="1" type="mesh"/>
    </default>
    <default class="collision">
      <geom group="0" rgba="0.5 0 0 0.5"/>
    </default>
    <default class="spawn">
      <geom group="0" rgba="1 1 1 0.5" contype="0" conaffinity="0"/>
      <site group="0" rgba="1 1 1 0.5"/>
    </default>
    <default class="region">
      <geom group="1" conaffinity="0" contype="0" rgba="0 1 0 0"/>
    </default>
  </default>
  <worldbody>
    <body>
      <body name="object">
        <geom mesh="Body001_vis" type="mesh" solimp="0.998 0.998 0.001" solref="0.001 1" density="100" friction="0.95 0.3 0.1" class="visual" material="Body001_material"/>
        <geom class="collision" type="box" pos="-0.333354 -0.031688 -0.180779" size="0.048402853310108185 0.21965956687927246 0.11630520224571228" quat="1.0 0.0 0.0 0.0"/>
        <geom class="collision" type="box" pos="-0.002101 -0.223566 -0.183023" size="0.3796515166759491 0.02778611145913601 0.11406172066926956" quat="1.0 0.0 0.0 0.0"/>
        <geom class="collision" type="box" pos="0.333084 -0.020341 -0.182575" size="0.044843729585409164 0.2310067117214203 0.11450959742069244" quat="1.0 0.0 0.0 0.0"/>
        <geom class="collision" type="box" pos="-0.150434 0.190101 -0.180779" size="0.23131917417049408 0.008557619526982307 0.11630560457706451" quat="1.0 0.0 0.0 0.0"/>
        <geom class="collision" type="box" pos="-0.149940 -0.193216 -0.182703" size="0.2318132221698761 0.008557627908885479 0.11438243091106415" quat="1.0 0.0 0.0 0.0"/>
        <geom class="collision" type="box" pos="0.180447 0.191474 -0.183476" size="0.10596193373203278 0.009983021765947342 0.11361006647348404" quat="1.0 0.0 0.0 0.0"/>
        <geom class="collision" type="box" pos="0.186494 -0.194206 -0.183059" size="0.11200940608978271 0.008966151624917984 0.11402715742588043" quat="1.0 0.0 0.0 0.0"/>
        <geom class="collision" type="box" pos="-0.002101 -0.092587 -0.271514" size="0.3796532154083252 0.09105542302131653 0.025812510401010513" quat="1.0 0.0 0.0 0.0"/>
        <geom class="collision" type="box" pos="0.201839 0.045497 -0.271514" size="0.16317406296730042 0.045968107879161835 0.025812529027462006" quat="1.0 0.0 0.0 0.0"/>
        <geom class="collision" type="box" pos="-0.002101 0.138037 -0.271514" size="0.37965378165245056 0.045394547283649445 0.02581254579126835" quat="1.0 0.0 0.0 0.0"/>
        <geom class="collision" type="box" pos="-0.218582 0.045497 -0.271514" size="0.1631743311882019 0.045968178659677505 0.025812562555074692" quat="1.0 0.0 0.0 0.0"/>
        <geom class="collision" type="box" pos="-0.011339 0.045497 -0.281114" size="0.05725324526429176 0.04596821218729019 0.016212716698646545" quat="1.0 0.0 0.0 0.0"/>
        <geom class="collision" type="cylinder" pos="0.007943 0.218793 -0.026634" size="0.020228685811161995 0.009952086955308914" quat="0.7071068286895752 1.2101618374060763e-08 0.7071067690849304 -1.2101617485882343e-08"/>
        <geom class="collision" type="cylinder" pos="-0.012125 0.218973 -0.025929" size="0.022797370329499245 0.045382849872112274" quat="1.0 0.0 0.0 0.0"/>
        <geom class="collision" type="box" pos="-0.002101 0.224953 -0.183033" size="0.3796546459197998 0.027496295049786568 0.1140536293387413" quat="1.0 0.0 0.0 0.0"/>
        <geom class="collision" type="box" pos="0.002109 -0.185453 -0.222514" size="0.36479583382606506 0.008557695895433426 0.04323146864771843" quat="0.9885651469230652 0.1507944017648697 -3.3483089982231835e-17 -4.0703960531955856e-24"/>
        <geom class="collision" type="box" pos="0.274908 0.003790 -0.214719" size="0.20199944078922272 0.008557695895433426 0.04323146492242813" quat="0.69902104139328 0.10662775486707687 0.10662778466939926 0.6990212202072144"/>
        <body name="handle">
          <joint axis="1.0 0.0 0.0" pos="0.039323 0.218450 -0.027502" limited="true" name="handle_joint_hinge_0" type="hinge" range="-0.7853981633974483 0.7853981633974483" damping="1" frictionloss="1" armature=".01" stiffness="0.05"/>
          <joint axis="0.0 1.0 0.0" pos="0.039323 0.218450 -0.027502" limited="true" name="handle_joint_hinge_1" type="hinge" range="0.0 0.17453292519943295" damping="1" frictionloss="1" armature=".01" stiffness="0.05"/>
          <geom mesh="handle_vis" type="mesh" solimp="0.998 0.998 0.001" solref="0.001 1" density="100" friction="0.95 0.3 0.1" class="visual" material="handle_material"/>
          <geom class="collision" type="cylinder" pos="0.042794 0.218038 -0.027249" size="0.023489195853471756 0.01131028588861227" quat="0.7071068286895752 -0.0 0.7071067690849304 0.0"/>
          <geom class="collision" type="cylinder" pos="0.039326 0.218351 0.027744" size="0.005060066934674978 0.0339176282286644" quat="1.0 0.0 0.0 0.0"/>
        </body>
        <body name="Container001">
          <joint axis="0.0 0.0 1.0" pos="0.182692 0.001580 -0.104763" limited="true" name="Container001_joint" range="0.0 0.07" type="slide" damping="1" frictionloss="1" armature=".01" stiffness="0.05"/>
          <geom mesh="Container001_vis" type="mesh" solimp="0.998 0.998 0.001" solref="0.001 1" density="100" friction="0.95 0.3 0.1" class="visual" material="Container001_material"/>
          <geom class="collision" type="box" pos="0.179308 0.158480 -0.101587" size="0.08510932326316833 0.005809545051306486 0.03817487508058548" quat="0.04934852570295334 0.9987816214561462 -2.2177407054261217e-16 -7.894152648962042e-26"/>
          <geom class="collision" type="box" pos="0.096336 -0.008952 -0.103848" size="0.15226206183433533 0.002230982296168804 0.038181714713573456" quat="0.014585187658667564 0.7069562673568726 0.7069564461708069 0.014585212804377079"/>
          <geom class="collision" type="box" pos="0.271244 -0.008180 -0.104819" size="0.15285062789916992 0.0019349642097949982 0.038318976759910583" quat="0.027257831767201424 0.7065810561180115 -0.7065814137458801 -0.027257852256298065"/>
          <geom class="collision" type="box" pos="0.183102 0.181460 -0.065486" size="0.10112003237009048 0.01446457114070654 0.0009946709033101797" quat="0.9999801516532898 -0.006300824694335461 -1.3990645435459048e-18 -8.238416601640666e-25"/>
          <geom class="collision" type="box" pos="0.183875 -0.175125 -0.103245" size="0.08209159970283508 0.0028013784904032946 0.03832589462399483" quat="0.08811910450458527 -0.9961099624633789 -2.2203242882641453e-16 -1.723405163655244e-17"/>
          <geom class="collision" type="box" pos="0.182302 -0.006546 -0.141023" size="0.0856052041053772 0.1658957153558731 0.0034047712106257677" quat="1.0 0.0 0.0 0.0"/>
          <geom class="collision" type="box" pos="0.182659 -0.187693 -0.066308" size="0.10111471265554428 0.007741416804492474 0.0017976694507524371" quat="1.0 0.0 0.0 0.0"/>
          <geom class="collision" type="box" pos="0.091488 -0.005990 -0.065443" size="0.009462566114962101 0.17565251886844635 0.0017827090341597795" quat="1.0 0.0 0.0 0.0"/>
          <geom class="collision" type="box" pos="0.274470 -0.006174 -0.065823" size="0.009462566114962101 0.17565608024597168 0.002278571017086506" quat="1.0 0.0 0.0 0.0"/>
        </body>
        <body name="Funnel001">
          <joint axis="0.0 0.0 1.0" pos="-0.008347 0.046294 -0.255563" limited="true" name="Funnel001_joint" range="0.0 0.05" type="slide" damping="1" frictionloss="1" armature=".01" stiffness="0.05"/>
          <geom mesh="Funnel001_vis" type="mesh" solimp="0.998 0.998 0.001" solref="0.001 1" density="100" friction="0.95 0.3 0.1" class="visual" material="Funnel001_material"/>
          <geom class="collision" type="cylinder" pos="-0.008950 0.046398 -0.259882" size="0.035002294927835464 0.000941219215746969" quat="1.0 0.0 0.0 0.0"/>
          <geom class="collision" type="cylinder" pos="-0.008559 0.046398 -0.258228" size="0.00952162966132164 0.004481073003262281" quat="1.0 0.0 0.0 0.0"/>
          <geom class="collision" type="box" pos="0.026204 0.046398 -0.254372" size="0.001374227344058454 0.00741409370675683 0.00636748131364584" quat="0.9920489192008972 6.231488514656287e-16 0.1258530467748642 -4.307769252420712e-09"/>
          <geom class="collision" type="box" pos="0.031258 0.046424 -0.250575" size="0.004876116290688515 0.00741409370675683 0.002862062770873308" quat="1.0 0.0 0.0 0.0"/>
          <geom class="collision" type="box" pos="0.024346 0.035184 -0.254372" size="0.001374227344058454 0.00741409370675683 0.00636748131364584" quat="0.9787018895149231 0.020574934780597687 0.12415982037782669 -0.16218392550945282"/>
          <geom class="collision" type="box" pos="0.029138 0.033579 -0.250575" size="0.002857643412426114 0.00741409370675683 0.004873522557318211" quat="0.6972854137420654 0.11559797823429108 0.6979194283485413 -0.11549296975135803"/>
          <geom class="collision" type="box" pos="0.019077 0.025309 -0.254372" size="0.001374227344058454 0.00741409370675683 0.00636748131364584" quat="0.9398285746574402 0.04029399901628494 0.11922828108072281 -0.3176213204860687"/>
          <geom class="collision" type="box" pos="0.023110 0.022264 -0.250575" size="0.002857643412426114 0.00741409370675683 0.004873522557318211" quat="0.6696193814277649 0.2263815551996231 0.670228123664856 -0.22617599368095398"/>
          <geom class="collision" type="box" pos="0.010797 0.017522 -0.254372" size="0.001374227344058454 0.00741409370675683 0.006367481779307127" quat="0.8752581477165222 0.05924379825592041 0.11103677749633789 -0.46699488162994385"/>
          <geom class="collision" type="box" pos="0.013633 0.013339 -0.250575" size="0.002857643412426114 0.00741409370675683 0.004873522557318211" quat="0.6236485838890076 0.33288028836250305 0.6242155432701111 -0.33257800340652466"/>
          <geom class="collision" type="box" pos="0.000411 0.012811 -0.254372" size="0.001374227344058454 0.00741409370675683 0.006367481779307127" quat="0.7868015766143799 0.07665476948022842 0.09981502592563629 -0.6042386293411255"/>
          <geom class="collision" type="box" pos="0.001740 0.007936 -0.250575" size="0.002857643412426114 0.00741409370675683 0.004873522557318211" quat="0.5607638955116272 0.43061143159866333 0.5612735748291016 -0.43022045493125916"/>
          <geom class="collision" type="box" pos="-0.010902 0.011713 -0.254372" size="0.001374227344058454 0.007414093241095543 0.00636748131364584" quat="0.6774327754974365 0.09194158762693405 0.08594029396772385 -0.7247384786605835"/>
          <geom class="collision" type="box" pos="-0.011217 0.006669 -0.250575" size="0.002857643412426114 0.00741409370675683 0.004873523022979498" quat="0.482647567987442 0.5167996883392334 0.48308613896369934 -0.5163304805755615"/>
          <geom class="collision" type="box" pos="-0.021802 0.014255 -0.254372" size="0.001374227344058454 0.00741409370675683 0.00636748131364584" quat="0.5519278645515442 0.10457713156938553 0.070018470287323 -0.8243401646614075"/>
          <geom class="collision" type="box" pos="-0.023703 0.009573 -0.250575" size="0.002857643412426114 0.00741409370675683 0.004873522557318211" quat="0.3932937681674957 0.5877864956855774 0.3936512768268585 -0.587252676486969"/>
          <geom class="collision" type="box" pos="-0.031463 0.020245 -0.254372" size="0.001374227344058454 0.00741409370675683 0.00636748131364584" quat="0.4097360372543335 0.11461713165044785 0.051979824900627136 -0.9034807085990906"/>
          <geom class="collision" type="box" pos="-0.034772 0.016426 -0.250575" size="0.002857643412426114 0.0074140941724181175 0.004873522557318211" quat="0.29206138849258423 0.6442041397094727 0.29232680797576904 -0.6436195969581604"/>
          <geom class="collision" type="box" pos="-0.038734 0.029136 -0.254372" size="0.001374227344058454 0.00741409370675683 0.00636748131364584" quat="0.25485607981681824 0.12162920832633972 0.03233148530125618 -0.9587540626525879"/>
          <geom class="collision" type="box" pos="-0.043108 0.026604 -0.250575" size="0.002857643412426114 0.00741409370675683 0.004873522557318211" quat="0.18164247274398804 0.6836665868759155 0.18180756270885468 -0.6830461025238037"/>
          <geom class="collision" type="box" pos="-0.042690 0.039792 -0.254372" size="0.001374227344058454 0.00741409370675683 0.00636748131364584" quat="0.09468649327754974 0.12527848780155182 0.012012094259262085 -0.9875198602676392"/>
          <geom class="collision" type="box" pos="-0.047646 0.038806 -0.250575" size="0.002857643412426114 0.00741409370675683 0.004873522557318211" quat="0.0674813985824585 0.7041961550712585 0.06754276156425476 -0.7035567164421082"/>
          <geom class="collision" type="box" pos="-0.043020 0.050980 -0.254372" size="0.001374227344058454 0.00741409370675683 0.00636748131364584" quat="0.06552086770534515 -0.12557801604270935 0.00831207912415266 0.9898828864097595"/>
          <geom class="collision" type="box" pos="-0.048032 0.051620 -0.250575" size="0.002857643412426114 0.00741409370675683 0.004873523022979498" quat="0.046694185584783554 -0.7058823108673096 0.04673660174012184 0.7052414417266846"/>
          <geom class="collision" type="box" pos="-0.039700 0.061850 -0.254372" size="0.001374227344058454 0.00741409370675683 0.00636748131364584" quat="0.22646915912628174 -0.12252973765134811 0.02873024344444275 0.9658533930778503"/>
          <geom class="collision" type="box" pos="-0.044238 0.064073 -0.250575" size="0.002857643412426114 0.00741409370675683 0.004873522091656923" quat="0.16140791773796082 -0.688733696937561 0.1615545153617859 0.6881086230278015"/>
          <geom class="collision" type="box" pos="-0.033023 0.071096 -0.254372" size="0.001374227344058454 0.00741409370675683 0.006367481779307127" quat="0.3818311095237732 -0.11615757644176483 0.048439763486385345 0.9156233072280884"/>
          <geom class="collision" type="box" pos="-0.036598 0.074668 -0.250575" size="0.002857643412426114 0.00741409370675683 0.004873522557318211" quat="0.2721007466316223 -0.6529017686843872 0.27234795689582825 0.652309000492096"/>
          <geom class="collision" type="box" pos="-0.023748 0.077667 -0.254372" size="0.001374227344058454 0.00741409370675683 0.00636748131364584" quat="0.5263835191726685 -0.10667566955089569 0.06677792221307755 0.84088134765625"/>
          <geom class="collision" type="box" pos="-0.025980 0.082201 -0.250575" size="0.002857643412426114 0.00741409370675683 0.004873523022979498" quat="0.37510767579078674 -0.599577009677887 0.3754485249519348 0.5990326404571533"/>
          <geom class="collision" type="box" pos="-0.013025 0.080873 -0.254372" size="0.0013742272276431322 0.00741409370675683 0.00636748131364584" quat="0.6548842787742615 -0.09453434497117996 0.0830797404050827 0.7451762557029724"/>
          <geom class="collision" type="box" pos="-0.013700 0.085881 -0.250575" size="0.002857643412426114 0.00741409370675683 0.004873523022979498" quat="0.4665289521217346 -0.5314218997955322 0.4669528603553772 0.5309392809867859"/>
          <geom class="collision" type="box" pos="-0.001665 0.080471 -0.254372" size="0.001374227344058454 0.00741409370675683 0.006367481779307127" quat="0.7678977251052856 -0.07968029379844666 0.09741685539484024 0.6280876398086548"/>
          <geom class="collision" type="box" pos="-0.000689 0.085429 -0.250575" size="0.002857643412426114 0.00741409370675683 0.004873522557318211" quat="0.5471140742301941 -0.44785717129707336 0.5476112961769104 0.44745057821273804"/>
          <geom class="collision" type="box" pos="0.003252 0.079093 -0.254372" size="0.001374227344058454 0.00741409370675683 0.006367481779307127" quat="0.8119527697563171 -0.07231049984693527 0.10300575196743011 0.5699945092201233"/>
          <geom class="collision" type="box" pos="0.004944 0.083855 -0.250575" size="0.002857643412426114 0.00741409370675683 0.004873522557318211" quat="0.5785291194915771 -0.4063861072063446 0.5790548920631409 0.406017005443573"/>
          <geom class="collision" type="box" pos="0.013167 0.073536 -0.254372" size="0.001374227344058454 0.00741409370675683 0.00636748131364584" quat="0.8942136764526367 -0.054497845470905304 0.11344150453805923 0.4295845329761505"/>
          <geom class="collision" type="box" pos="0.016305 0.077497 -0.250575" size="0.002857643412426114 0.0074140941724181175 0.004873522557318211" quat="0.6371234655380249 -0.3062509000301361 0.6377027034759521 0.3059728443622589"/>
          <geom class="collision" type="box" pos="0.020664 0.065225 -0.254372" size="0.001374227344058454 0.00741409370675683 0.00636748131364584" quat="0.9517059326171875 -0.03552510216832161 0.1207350492477417 0.28003010153770447"/>
          <geom class="collision" type="box" pos="0.024898 0.067984 -0.250575" size="0.002857643412426114 0.00741409370675683 0.004873522557318211" quat="0.6780697107315063 -0.19959817826747894 0.6786862015724182 0.199416846036911"/>
          <geom class="collision" type="box" pos="0.025176 0.054792 -0.254372" size="0.001374227344058454 0.0074140941724181175 0.006367481779307127" quat="0.9846820831298828 -0.015308920294046402 0.12491849064826965 0.12067395448684692"/>
          <geom class="collision" type="box" pos="0.030073 0.056038 -0.250575" size="0.002857643412426114 0.00741409370675683 0.004873522557318211" quat="0.7015404105186462 -0.08602418005466461 0.7021781802177429 0.08594600856304169"/>
        </body>
        <body name="spout">
          <joint axis="0.0 0.0 1.0" pos="-0.011112 0.218559 0.156339" limited="true" name="spout_joint" range="-0.7853981633974483 0.7853981633974483" type="hinge" damping="1" frictionloss="1" armature=".01" stiffness="0.05"/>
          <site type="cylinder" rgba="0.5 0.75 1 1" size="0.006065879482775927 0.216606006026268" pos="-0.010771 0.034888 -0.039462" name="water"/>
          <geom mesh="spout_vis" type="mesh" solimp="0.998 0.998 0.001" solref="0.001 1" density="100" friction="0.95 0.3 0.1" class="visual" material="spout_material"/>
          <geom class="collision" type="cylinder" pos="-0.010931 0.219098 0.110776" size="0.011920161545276642 0.09080865979194641" quat="1.0 0.0 0.0 0.0"/>
          <geom class="collision" type="cylinder" pos="-0.010931 0.212943 0.225017" size="0.011920161545276642 0.02771236188709736" quat="0.9908534288406372 0.13494248688220978 5.597813108299096e-17 -5.141014360981385e-18"/>
          <geom class="collision" type="cylinder" pos="-0.010931 0.186979 0.264338" size="0.011920161545276642 0.02771236188709736" quat="0.9126067757606506 0.4088384807109833 8.829445634143715e-17 1.095444797781019e-18"/>
          <geom class="collision" type="cylinder" pos="-0.010931 0.144261 0.284288" size="0.011920161545276642 0.02771236188709736" quat="0.749485194683075 0.6620211005210876 1.4844748708999145e-16 -1.2915069722786706e-18"/>
          <geom class="collision" type="cylinder" pos="-0.010931 0.095434 0.279559" size="0.011920161545276642 0.027712363749742508" quat="0.5441926121711731 0.8389602899551392 1.7793484803606138e-16 1.1991887148726233e-17"/>
          <geom class="collision" type="cylinder" pos="-0.010931 0.061210 0.254190" size="0.011920161545276642 0.02771236188709736" quat="0.9412050843238831 -0.33783581852912903 6.469056639466089e-17 -4.214016970556522e-16"/>
          <geom class="collision" type="cylinder" pos="-0.010931 0.039299 0.202242" size="0.011920161545276642 0.03456389904022217" quat="0.9946037530899048 -0.10374680906534195 -2.303643577475876e-17 -1.6915156271088787e-23"/>
        </body>
        <geom class="region" name="reg_main" type="box" pos="0.0 0.0 -0.18045850000000002" size="0.375715 0.249434 0.1143345"/>
        <geom class="region" name="reg_basin" type="box" pos="-0.1029285 -0.003589999999999996 -0.154815" size="0.18422950000000002 0.178664 0.085285"/>
      </body>
    </body>
  </worldbody>
  <actuator>
    <motor name="handle_joint_hinge_0_actuator" joint="handle_joint_hinge_0" gear="10"/>
    <motor name="handle_joint_hinge_1_actuator" joint="handle_joint_hinge_1" gear="10"/>
    <motor name="Container001_joint_actuator" joint="Container001_joint" gear="50"/>
    <motor name="Funnel001_joint_actuator" joint="Funnel001_joint" gear="10"/>
    <motor name="spout_joint_actuator" joint="spout_joint" gear="10"/>
  </actuator>
</mujoco>
