<mujoco model="model">
  <compiler angle="radian"/>
  <asset>
    <mesh file="visuals/Blade001.obj" name="Blade001_vis"/>
    <mesh file="visuals/Body001.obj" name="Body001_vis"/>
    <mesh file="visuals/Container001.obj" name="Container001_vis"/>
    <mesh file="visuals/Knob001.obj" name="Knob001_vis"/>
    <mesh file="visuals/Lid001.obj" name="Lid001_vis"/>
    <texture file="visuals/T_BC001.png" name="Body001_material" type="2d"/>
    <material name="Body001_material" rgba="1 1 1 1.0" texture="Body001_material" shininess="0.4472135901451111" specular="0.3103448502657381"/>
    <texture file="visuals/T_BC001.png" name="Container001_material" type="2d"/>
    <material name="Container001_material" rgba="1 1 1 1.0" texture="Container001_material" shininess="2" specular="2"/>
    <texture file="visuals/T_BC001.png" name="Knob001_material" type="2d"/>
    <material name="Knob001_material" rgba="1 1 1 1.0" texture="Knob001_material" shininess="0.4472135901451111" specular="0.3103448502657381"/>
    <texture file="visuals/T_BC001.png" name="Knob002_material" type="2d"/>
    <material name="Knob002_material" rgba="1 1 1 1.0" texture="Knob002_material" shininess="0.4472135901451111" specular="0.3103448502657381"/>
    <texture file="visuals/T_BC001.png" name="Lid001_material" type="2d"/>
    <material name="Lid001_material" rgba="1 1 1 1.0" texture="Lid001_material" shininess="0.4472135901451111" specular="0.3103448502657381"/>
    <texture file="visuals/T_BC001.png" name="Blade001_material" type="2d"/>
    <material name="Blade001_material" rgba="1 1 1 1.0" texture="Blade001_material" shininess="2" specular="2"/>
  </asset>
  <default>
    <default class="visual">
      <geom conaffinity="0" contype="0" group="1" type="mesh"/>
    </default>
    <default class="collision">
      <geom group="0" rgba="0.5 0 0 0.5"/>
    </default>
    <default class="spawn">
      <geom group="0" rgba="1 1 1 0.5" contype="0" conaffinity="0"/>
      <site group="0" rgba="1 1 1 0.5"/>
    </default>
    <default class="region">
      <geom group="1" conaffinity="0" contype="0" rgba="0 1 0 0"/>
    </default>
  </default>
  <worldbody>
    <body>
      <body name="object">
        <geom mesh="Body001_vis" type="mesh" solimp="0.998 0.998 0.001" solref="0.001 1" density="100" friction="0.95 0.3 0.1" class="visual" material="Body001_material"/>
        <geom class="collision" type="box" pos="-0.086733 0.001178 -0.168866" size="0.08916433155536652 0.12178308516740799 0.027288010343909264" quat="1.0 0.0 0.0 0.0"/>
        <geom class="collision" type="box" pos="0.112620 -0.102457 -0.119957" size="0.0894964337348938 0.027288001030683517 0.006290726829320192" quat="8.63068549961099e-08 -1.271789606960283e-08 0.7831255197525024 0.6218636631965637"/>
        <geom class="collision" type="box" pos="0.112620 -0.081011 0.006987" size="0.0894964337348938 0.09619162976741791 0.006290728226304054" quat="2.925361819450245e-08 -8.218786007319068e-08 -0.7622418999671936 -0.6472923159599304"/>
        <geom class="collision" type="box" pos="0.102915 0.116080 -0.168866" size="0.10053589940071106 0.12097258120775223 0.027288002893328667" quat="1.0 0.0 0.0 0.0"/>
        <geom class="collision" type="box" pos="0.112620 0.084751 0.003539" size="0.0894964337348938 0.09333928674459457 0.006290728226304054" quat="6.054424517287771e-08 4.543085552199955e-08 0.6561623811721802 0.7546197175979614"/>
        <geom class="collision" type="box" pos="0.112620 0.102069 -0.119670" size="0.0894964337348938 0.027288001030683517 0.006290726829320192" quat="5.71293377049642e-08 4.935758823876313e-08 0.653761088848114 0.7567010521888733"/>
        <geom class="collision" type="box" pos="0.198910 0.002155 -0.118354" size="0.006290730554610491 0.09550594538450241 0.027287350967526436" quat="1.0 0.0 0.0 0.0"/>
        <geom class="collision" type="box" pos="0.198910 0.002155 0.003209" size="0.006290874443948269 0.08668743818998337 0.09565220773220062" quat="1.0 0.0 0.0 0.0"/>
        <geom class="collision" type="box" pos="0.046089 0.002155 -0.065155" size="0.006290867459028959 0.08668743818998337 0.027288002893328667" quat="1.0 0.0 0.0 0.0"/>
        <geom class="collision" type="box" pos="0.046089 0.002155 -0.118354" size="0.006290730554610491 0.09550633281469345 0.0272874403744936" quat="1.0 0.0 0.0 0.0"/>
        <geom class="collision" type="box" pos="0.041584 0.000948 0.041812" size="0.00607276288792491 0.04196159541606903 0.05916079878807068" quat="1.0 0.0 0.0 0.0"/>
        <geom class="collision" type="box" pos="0.030711 0.058012 0.041812" size="0.013324461877346039 0.006072758696973324 0.05916079878807068" quat="0.5259014964103699 2.8795538398185272e-08 1.0097737757064351e-08 0.8505454659461975"/>
        <geom class="collision" type="box" pos="0.026998 -0.058648 0.041812" size="0.013324461877346039 0.006072758696973324 0.05916079878807068" quat="0.8412458300590515 2.1627100110777064e-08 2.152708944436199e-08 0.5406528115272522"/>
        <body name="Container001">
          <joint axis="0.0 0.0 1.0" pos="-0.087034 0.000000 -0.029134" limited="true" name="Container001_joint" range="0.0 0.08" type="slide" damping="1" frictionloss="1" armature=".01" stiffness="0.05"/>
          <geom mesh="Container001_vis" type="mesh" solimp="0.998 0.998 0.001" solref="0.001 1" density="100" friction="0.95 0.3 0.1" class="visual" material="Container001_material"/>
          <geom class="collision" type="box" pos="-0.200245 0.000000 0.010911" size="0.004249558784067631 0.03502568602561951 0.07218194752931595" quat="1.0 0.0 0.0 0.0"/>
          <geom class="collision" type="box" pos="-0.181252 -0.064994 0.010911" size="0.00424955552443862 0.035024795681238174 0.07217983901500702" quat="0.2588190734386444 0.0 -0.0 -0.9659258127212524"/>
          <geom class="collision" type="box" pos="-0.130898 -0.106901 0.010911" size="0.00424955552443862 0.035024795681238174 0.07217983901500702" quat="0.5372996926307678 0.0 -0.0 -0.8433914184570312"/>
          <geom class="collision" type="box" pos="-0.074482 -0.115587 0.010911" size="0.03502479940652847 0.004249661695212126 0.0721818283200264" quat="1.0 0.0 0.0 0.0"/>
          <geom class="collision" type="box" pos="-0.027959 -0.100225 0.010911" size="0.004249554593116045 0.028032764792442322 0.07217983901500702" quat="0.843391478061676 0.0 -0.0 -0.5372995734214783"/>
          <geom class="collision" type="box" pos="0.004143 -0.063689 0.010911" size="0.004249554593116045 0.028032764792442322 0.07217983901500702" quat="0.9537169337272644 0.0 -0.0 -0.30070582032203674"/>
          <geom class="collision" type="box" pos="0.022387 -0.020972 0.010911" size="0.004249554593116045 0.028032762929797173 0.07217983901500702" quat="0.9914448261260986 0.0 -0.0 -0.1305263340473175"/>
          <geom class="collision" type="box" pos="0.019169 0.026185 0.010911" size="0.004249554127454758 0.028032764792442322 0.07217983901500702" quat="0.9961947202682495 0.0 0.0 0.08715561032295227"/>
          <geom class="collision" type="box" pos="-0.002650 0.076244 0.010911" size="0.004249554593116045 0.028032762929797173 0.07217983901500702" quat="0.9396926164627075 0.0 0.0 0.3420201539993286"/>
          <geom class="collision" type="box" pos="-0.042773 0.108164 0.010911" size="0.004249554593116045 0.028032762929797173 0.07217983901500702" quat="0.8191520571708679 0.0 0.0 0.5735764503479004"/>
          <geom class="collision" type="box" pos="-0.090316 0.119426 0.010911" size="0.02803238295018673 0.0042495569214224815 0.07217983901500702" quat="1.0 0.0 0.0 0.0"/>
          <geom class="collision" type="box" pos="-0.142465 0.105089 0.010911" size="0.004249554593116045 0.028032764792442322 0.07217983901500702" quat="0.49999967217445374 0.0 0.0 0.8660256266593933"/>
          <geom class="collision" type="box" pos="-0.185354 0.062637 0.010911" size="0.004249554593116045 0.028032764792442322 0.07217983901500702" quat="0.3007052540779114 0.0 0.0 0.9537171125411987"/>
          <geom class="collision" type="box" pos="-0.126761 0.080266 -0.093973" size="0.005313976667821407 0.028032764792442322 0.049927785992622375" quat="0.48296257853507996 -0.22414395213127136 0.12940944731235504 0.8365164995193481"/>
          <geom class="collision" type="box" pos="-0.161536 0.053994 -0.091766" size="0.005171371158212423 0.028163209557533264 0.049856942147016525" quat="0.21442170441150665 -0.22364439070224762 0.018216269090771675 0.9506180286407471"/>
          <geom class="collision" type="box" pos="-0.176990 0.003732 -0.091535" size="0.0052502816542983055 0.028103359043598175 0.04989377409219742" quat="0.03476046770811081 0.24275320768356323 -0.00839803833514452 -0.9694287180900574"/>
          <geom class="collision" type="box" pos="-0.168456 -0.043626 -0.088040" size="0.005165787413716316 0.028276165947318077 0.04986531287431717" quat="0.2127436250448227 0.22854484617710114 -0.008995885960757732 -0.9499613046646118"/>
          <geom class="collision" type="box" pos="-0.127666 -0.083509 -0.087824" size="0.00424955552443862 0.028032764792442322 0.051771413534879684" quat="0.5542343258857727 0.18999965488910675 0.06492701172828674 -0.8077802658081055"/>
          <geom class="collision" type="box" pos="-0.069654 -0.092326 -0.084043" size="0.0050116609781980515 0.028104055672883987 0.04978493973612785" quat="0.7592595219612122 0.1288158893585205 0.12978556752204895 -0.6245695948600769"/>
          <geom class="collision" type="box" pos="-0.021304 -0.070700 -0.083877" size="0.004910128191113472 0.028419459238648415 0.04978493973612785" quat="0.8764436841011047 0.1538531482219696 0.09882823377847672 -0.44543084502220154"/>
          <geom class="collision" type="box" pos="0.004342 -0.020714 -0.081522" size="0.004960902966558933 0.028163747861981392 0.049769215285778046" quat="0.9613804817199707 0.00645007798448205 0.17234638333320618 -0.214482381939888"/>
          <geom class="collision" type="box" pos="0.006880 0.030368 -0.079696" size="0.00424955552443862 0.028032764792442322 0.051771413534879684" quat="0.9787082076072693 -0.020370660349726677 0.14804695546627045 0.14070309698581696"/>
          <geom class="collision" type="box" pos="-0.013758 0.072611 -0.083173" size="0.004827040247619152 0.028170889243483543 0.04972705990076065" quat="0.9097654223442078 -0.023924609646201134 0.13881732523441315 0.3904922902584076"/>
          <geom class="collision" type="box" pos="-0.068329 0.102046 -0.075301" size="0.004714560229331255 0.028205227106809616 0.049701154232025146" quat="0.7976791858673096 -0.09827081859111786 0.06403802335262299 0.5915656089782715"/>
          <geom class="collision" type="cylinder" pos="-0.086968 0.000402 -0.129442" size="0.07085301727056503 0.009161382913589478" quat="7.549790126404332e-08 0.0 0.0 1.0"/>
          <geom class="collision" type="box" pos="-0.086774 -0.153345 0.054682" size="0.035025447607040405 0.007714124396443367 0.008038448169827461" quat="1.0 0.0 0.0 0.0"/>
          <geom class="collision" type="box" pos="-0.122203 -0.146832 0.054682" size="0.007713937666267157 0.012463422492146492 0.008038228377699852" quat="0.9063077569007874 0.0 0.0 0.4226183295249939"/>
          <geom class="collision" type="box" pos="-0.130338 -0.127288 0.054682" size="0.0077139404602348804 0.012463425286114216 0.008038433268666267" quat="1.0 0.0 0.0 0.0"/>
          <geom class="collision" type="box" pos="-0.046881 -0.142855 0.054682" size="0.007713937666267157 0.012463422492146492 0.008038228377699852" quat="0.38268330693244934 0.0 0.0 0.9238795638084412"/>
          <geom class="collision" type="box" pos="-0.042549 -0.125671 0.054682" size="0.0077139404602348804 0.012463425286114216 0.008038418367505074" quat="1.0 0.0 0.0 0.0"/>
          <geom class="collision" type="box" pos="-0.130338 0.124855 0.054682" size="0.00771394232288003 0.012463425286114216 0.00803840346634388" quat="1.0 0.0 0.0 0.0"/>
          <geom class="collision" type="box" pos="-0.126006 0.142039 0.054682" size="0.007713937666267157 0.012463423423469067 0.008038228377699852" quat="0.9238796234130859 0.0 -0.0 -0.38268324732780457"/>
          <geom class="collision" type="box" pos="-0.042549 0.126472 0.054682" size="0.00771394232288003 0.012463425286114216 0.008038388565182686" quat="1.0 0.0 0.0 0.0"/>
          <geom class="collision" type="box" pos="-0.050684 0.146016 0.054682" size="0.007713937200605869 0.012463422492146492 0.008038228377699852" quat="0.4226183593273163 0.0 -0.0 -0.9063077569007874"/>
          <geom class="collision" type="box" pos="-0.086113 0.152529 0.054682" size="0.0350252240896225 0.007714063860476017 0.008038373664021492" quat="1.0 0.0 0.0 0.0"/>
        </body>
        <body name="Knob001">
          <joint axis="0.0 0.988603949546814 -0.15054018795490265" pos="0.103395 -0.114419 -0.082525" limited="true" name="Knob001_joint" range="0.0 4.6774823953448035" type="hinge" damping="1" frictionloss="1" armature=".01" stiffness="0.05"/>
          <geom mesh="Knob001_vis" type="mesh" solimp="0.998 0.998 0.001" solref="0.001 1" density="100" friction="0.95 0.3 0.1" class="visual" material="Knob001_material"/>
          <geom class="collision" type="cylinder" pos="0.103279 -0.116564 -0.081640" size="0.022936422377824783 0.0067421975545585155" quat="5.7834743216744755e-08 -4.8529116725148924e-08 -0.6427876353263855 0.7660444378852844"/>
        </body>
        <body name="Lid001">
          <joint axis="0.0 1.0 0.0" pos="0.199506 -0.001224 0.104715" limited="true" name="Lid001_joint" range="0.0 1.5707963267948966" type="hinge" damping="1" frictionloss="1" armature=".01" stiffness="0.05"/>
          <geom mesh="Lid001_vis" type="mesh" solimp="0.998 0.998 0.001" solref="0.001 1" density="100" friction="0.95 0.3 0.1" class="visual" material="Lid001_material"/>
          <geom class="collision" type="box" pos="0.171968 -0.062014 0.151761" size="0.013808675110340118 0.006072757299989462 0.04308539256453514" quat="7.521060751969344e-08 6.580078704132575e-09 0.08715572953224182 0.9961947202682495"/>
          <geom class="collision" type="box" pos="0.106944 -0.062013 0.151766" size="0.05132736638188362 0.0060727559030056 0.04308098554611206" quat="7.521060751969344e-08 6.580078704132575e-09 0.08715572953224182 0.9961947202682495"/>
          <geom class="collision" type="box" pos="0.040921 -0.062104 0.151247" size="0.014984650537371635 0.006072755437344313 0.043607912957668304" quat="7.521060751969344e-08 6.580078704132575e-09 0.08715572953224182 0.9961947202682495"/>
          <geom class="collision" type="box" pos="-0.028708 -0.060436 0.160710" size="0.05132736638188362 0.0060727559030056 0.03399864211678505" quat="7.521060751969344e-08 6.580078704132575e-09 0.08715572953224182 0.9961947202682495"/>
          <geom class="collision" type="box" pos="-0.100219 -0.060436 0.160710" size="0.019300762563943863 0.0060727559030056 0.03399864211678505" quat="7.521060751969344e-08 6.580078704132575e-09 0.08715572953224182 0.9961947202682495"/>
          <geom class="collision" type="box" pos="-0.133074 -0.048112 0.160710" size="0.019300762563943863 0.006072756368666887 0.03399864211678505" quat="0.34071865677833557 0.02980903536081314 0.08189965784549713 0.9361168146133423"/>
          <geom class="collision" type="box" pos="-0.151168 -0.022483 0.160710" size="0.019300762563943863 0.006072756368666887 0.03399864211678505" quat="0.6064450740814209 0.053057122975587845 0.06914536654949188 0.7903342843055725"/>
          <geom class="collision" type="box" pos="0.107122 0.060386 0.153356" size="0.08356203138828278 0.0060727559030056 0.04146554321050644" quat="7.521060751969344e-08 -6.5800649373670694e-09 -0.08715561032295227 0.9961947202682495"/>
          <geom class="collision" type="box" pos="-0.028708 0.060928 0.157862" size="0.05132736638188362 0.0060727559030056 0.03399864211678505" quat="7.521060751969344e-08 -6.580078704132575e-09 -0.08715572953224182 0.9961947202682495"/>
          <geom class="collision" type="box" pos="-0.098434 0.060928 0.157862" size="0.018660293892025948 0.0060727559030056 0.03399864211678505" quat="7.521060751969344e-08 -6.580078704132575e-09 -0.08715572953224182 0.9961947202682495"/>
          <geom class="collision" type="box" pos="-0.133656 0.050350 0.157862" size="0.018660293892025948 0.006072756368666887 0.03399864211678505" quat="0.38122719526290894 -0.03335307538509369 0.08052149415016174 -0.9203639030456543"/>
          <geom class="collision" type="box" pos="-0.156406 0.016514 0.157862" size="0.018660293892025948 0.006072756368666887 0.03399864211678505" quat="0.6730194687843323 -0.058881670236587524 0.06425797194242477 -0.7344716787338257"/>
          <geom class="collision" type="box" pos="0.199570 0.000948 0.152859" size="0.006072762422263622 0.04196159541606903 0.04300326853990555" quat="1.0 0.0 0.0 0.0"/>
          <geom class="collision" type="box" pos="0.193090 0.052394 0.154795" size="0.014887291006743908 0.006072755437344313 0.040730930864810944" quat="0.456868976354599 0.014532932080328465 -0.047118015587329865 0.8881663084030151"/>
          <geom class="collision" type="box" pos="0.197247 -0.052647 0.152454" size="0.014887291006743908 0.0060727559030056 0.04329884424805641" quat="0.8125961422920227 -0.04524006322026253 0.014617673121392727 0.5808848142623901"/>
          <geom class="collision" type="box" pos="0.062656 0.002391 0.191437" size="0.12904229760169983 0.05328765884041786 0.006072760093957186" quat="1.0 0.0 0.0 0.0"/>
          <geom class="collision" type="box" pos="-0.084577 0.002391 0.191437" size="0.018181299790740013 0.053287651389837265 0.006072708871215582" quat="1.0 0.0 0.0 0.0"/>
          <geom class="collision" type="box" pos="-0.115094 0.002391 0.191437" size="0.013007179833948612 0.04248829185962677 0.0060727596282958984" quat="1.0 0.0 0.0 0.0"/>
          <geom class="collision" type="box" pos="-0.137301 0.002391 0.191437" size="0.009848266839981079 0.02788272686302662 0.006072720512747765" quat="1.0 0.0 0.0 0.0"/>
          <geom class="collision" type="box" pos="0.112039 0.050531 0.191437" size="0.06929343938827515 0.005844234023243189 0.0060727596282958984" quat="1.0 0.0 0.0 0.0"/>
          <geom class="collision" type="box" pos="0.112039 -0.050140 0.191437" size="0.06929343938827515 0.005844234023243189 0.0060727596282958984" quat="1.0 0.0 0.0 0.0"/>
          <geom class="collision" type="cylinder" pos="-0.080133 0.000000 0.113409" size="0.060433145612478256 0.012169020250439644" quat="7.549790126404332e-08 0.0 0.0 1.0"/>
          <geom class="collision" type="cylinder" pos="-0.074025 0.000000 0.075476" size="0.02510812319815159 0.025648944079875946" quat="7.549790126404332e-08 0.0 0.0 1.0"/>
          <body name="Blade001">
            <joint axis="0.0 0.0 1.0" pos="-0.079677 -0.000921 -0.032405" limited="false" name="Blade001_joint" range="0 360" type="hinge" damping="1" frictionloss="1" armature=".01" stiffness="0.05"/>
            <geom mesh="Blade001_vis" type="mesh" solimp="0.998 0.998 0.001" solref="0.001 1" density="100" friction="0.95 0.3 0.1" class="visual" material="Blade001_material"/>
            <geom class="collision" type="cylinder" pos="-0.075858 -0.003065 -0.038195" size="0.03818396106362343 0.044250596314668655" quat="7.549790126404332e-08 0.0 0.0 1.0"/>
            <geom class="collision" type="cylinder" pos="-0.075858 -0.003065 -0.036702" size="0.06066976115107536 0.013362511992454529" quat="7.549790126404332e-08 0.0 0.0 1.0"/>
          </body>
        </body>
        <geom class="region" name="reg_main" type="box" pos="-7.899999999999574e-05 0.00016399999999999748 8.749999999999036e-05" size="0.204873 0.161135 0.1957285"/>
      </body>
    </body>
  </worldbody>
  <actuator>
    <motor name="Container001_joint_actuator" joint="Container001_joint" gear="60"/>
    <motor name="Knob001_joint_actuator" joint="Knob001_joint" gear="10"/>
    <motor name="Lid001_joint_actuator" joint="Lid001_joint" gear="10"/>
    <motor name="Blade001_joint_actuator" joint="Blade001_joint" gear="10"/>
  </actuator>
</mujoco>
