<?xml version='1.0' encoding='UTF-8'?>
<mujoco model="model">
  <compiler angle="radian"/>
  <asset>
    <mesh file="visuals/Body001.obj" name="Body001_vis"/>
    <mesh file="visuals/Button001.obj" name="Button001_vis"/>
    <mesh file="visuals/Button002.obj" name="Button002_vis"/>
    <mesh file="visuals/Knob001.obj" name="Knob001_vis"/>
    <mesh file="visuals/Knob002.obj" name="Knob002_vis"/>
    <mesh file="visuals/Lever001.obj" name="Lever001_vis"/>
    <mesh file="visuals/Lever002.obj" name="Lever002_vis"/>
    <texture file="visuals/T_BC001.png" name="Body001_material" type="2d"/>
    <material name="Body001_material" rgba="1 1 1 1.0" texture="Body001_material" shininess="0.5" specular="1"/>
    <texture file="visuals/T_BC001.png" name="Button001_material" type="2d"/>
    <material name="Button001_material" rgba="1 1 1 1.0" texture="Button001_material" shininess="0.5" specular="1"/>
    <texture file="visuals/T_BC001.png" name="Button002_material" type="2d"/>
    <material name="Button002_material" rgba="1 1 1 1.0" texture="Button002_material" shininess="0.5" specular="1"/>
    <texture file="visuals/T_BC001.png" name="Knob001_material" type="2d"/>
    <material name="Knob001_material" rgba="1 1 1 1.0" texture="Knob001_material" shininess="0.5" specular="0.8"/>
    <texture file="visuals/T_BC001.png" name="Knob002_material" type="2d"/>
    <material name="Knob002_material" rgba="1 1 1 1.0" texture="Knob002_material" shininess="0.5" specular="0.8"/>
    <texture file="visuals/T_BC001.png" name="Lever001_material" type="2d"/>
    <material name="Lever001_material" rgba="1 1 1 1.0" texture="Lever001_material" shininess="0.5" specular="1"/>
    <texture file="visuals/T_BC001.png" name="Lever002_material" type="2d"/>
    <material name="Lever002_material" rgba="1 1 1 1.0" texture="Lever002_material" shininess="0.5" specular="1"/>
  </asset>
  <default>
    <default class="visual">
      <geom conaffinity="0" contype="0" group="1" type="mesh"/>
    </default>
    <default class="collision">
      <geom group="0" rgba="0.5 0 0 0.5"/>
    </default>
    <default class="spawn">
      <geom group="0" rgba="1 1 1 0.5" contype="0" conaffinity="0"/>
      <site group="0" rgba="1 1 1 0.5"/>
    </default>
    <default class="region">
      <geom group="1" conaffinity="0" contype="0" rgba="0 1 0 0"/>
    </default>
  </default>
  <worldbody>
    <body>
      <body name="object">
        <geom mesh="Body001_vis" type="mesh" solimp="0.998 0.998 0.001" solref="0.001 1" density="100" friction="0.95 0.3 0.1" class="visual" material="Body001_material"/>
        <geom class="collision" type="box" pos="0.000000 0.009406 -0.070778" size="0.15093529224395752 0.1104334369301796 0.022948309779167175" quat="1.0 0.0 0.0 0.0"/>
        <geom class="collision" type="box" pos="0.000000 0.096383 0.021736" size="0.13765887916088104 0.014076164923608303 0.022948309779167175" quat="1.0 0.0 0.0 0.0"/>
        <geom class="collision" type="box" pos="-0.000136 0.094315 0.070457" size="0.12757332623004913 0.012452364899218082 0.02426888793706894" quat="1.0 0.0 0.0 0.0"/>
        <geom class="collision" type="box" pos="0.000000 -0.070952 0.070457" size="0.1274377852678299 0.014194607734680176 0.02426888793706894" quat="1.0 0.0 0.0 0.0"/>
        <geom class="collision" type="box" pos="-0.125774 0.004446 0.021736" size="0.014984704554080963 0.07420015335083008 0.022948473691940308" quat="1.0 0.0 0.0 0.0"/>
        <geom class="collision" type="box" pos="-0.114118 0.005205 0.070342" size="0.015380119904875755 0.07584980875253677 0.02426857501268387" quat="1.0 0.0 0.0 0.0"/>
        <geom class="collision" type="box" pos="0.123002 0.000271 0.021736" size="0.016548022627830505 0.07668677717447281 0.022947801277041435" quat="1.0 0.0 0.0 0.0"/>
        <geom class="collision" type="box" pos="0.114118 0.003566 0.070589" size="0.017177307978272438 0.07729019224643707 0.02426888793706894" quat="1.0 0.0 0.0 0.0"/>
        <geom class="collision" type="box" pos="-0.055181 0.012706 0.059740" size="0.014374571852385998 0.06940566748380661 0.03724751994013786" quat="1.0 0.0 0.0 0.0"/>
        <geom class="collision" type="box" pos="0.000345 0.012706 0.059740" size="0.011652554385364056 0.06940566003322601 0.037247590720653534" quat="1.0 0.0 0.0 0.0"/>
        <geom class="collision" type="box" pos="0.054973 0.012706 0.059740" size="0.014171146787703037 0.06940466165542603 0.037247978150844574" quat="1.0 0.0 0.0 0.0"/>
        <geom class="collision" type="box" pos="0.000000 -0.077261 0.022868" size="0.13765887916088104 0.011381338350474834 0.022948311641812325" quat="0.9988005757331848 -0.048963017761707306 1.0871969798932527e-17 -1.478460231598969e-24"/>
        <geom class="collision" type="box" pos="0.000000 0.104725 -0.018456" size="0.14615358412265778 0.011247183196246624 0.02679312415421009" quat="1.0 0.0 0.0 0.0"/>
        <geom class="collision" type="box" pos="0.000000 -0.079526 -0.018456" size="0.14615358412265778 0.011247177608311176 0.02679312415421009" quat="1.0 0.0 0.0 0.0"/>
        <geom class="collision" type="box" pos="-0.132920 0.011943 -0.019811" size="0.015164616517722607 0.07797303795814514 0.02679312415421009" quat="0.9989761710166931 -4.416790305382097e-16 0.04523940756917 -1.5484783455477213e-09"/>
        <geom class="collision" type="box" pos="0.130393 0.011943 -0.020669" size="0.015164618380367756 0.07797303795814514 0.02679312601685524" quat="0.9976035952568054 -2.6082881421170723e-16 -0.06918864697217941 2.3682258376567233e-09"/>
        <body name="Button001">
          <joint axis="0.0 1.0 0.0" pos="0.000000 0.009404 -0.095129" limited="true" name="Button001_joint" range="0.0 0.001" type="slide" damping="1" frictionloss="1" armature=".01" stiffness="0.05"/>
          <geom mesh="Button001_vis" type="mesh" solimp="0.998 0.998 0.001" solref="0.001 1" density="100" friction="0.95 0.3 0.1" class="visual" material="Button001_material"/>
          <geom class="collision" type="box" pos="0.093742 -0.094121 0.032232" size="0.003607057500630617 0.0011718232417479157 0.01218100730329752" quat="0.9980376362800598 -0.0626167431473732 1.3903713302573094e-17 -2.9686382030840907e-24"/>
        </body>
        <body name="Button002">
          <joint axis="0.0 1.0 0.0" pos="-0.093661 -0.091630 0.031580" limited="true" name="Button002_joint" range="0.0 0.001" type="slide" damping="1" frictionloss="1" armature=".01" stiffness="0.05"/>
          <geom mesh="Button002_vis" type="mesh" solimp="0.998 0.998 0.001" solref="0.001 1" density="100" friction="0.95 0.3 0.1" class="visual" material="Button002_material"/>
          <geom class="collision" type="box" pos="-0.093742 -0.094121 0.032232" size="0.003607057500630617 0.0011718232417479157 0.01218100730329752" quat="0.9980376362800598 -0.0626167431473732 1.3903713302573094e-17 -2.9686382030840907e-24"/>
        </body>
        <body name="Knob001">
          <joint axis="-2.0563602447509766e-06 0.997897207736969 -0.06481683254241943" pos="0.077370 -0.105368 -0.026306" limited="true" name="Knob001_joint" range="0.0 4.276056667386108" type="hinge" damping="0.05" armature="0.001"/>
          <geom mesh="Knob001_vis" type="mesh" solimp="0.998 0.998 0.001" solref="0.001 1" density="100" friction="0.95 0.3 0.1" class="visual" material="Knob001_material"/>
          <geom class="collision" type="cylinder" pos="0.077155 -0.103149 -0.026353" size="0.01965203881263733 0.005387690383940935" quat="0.7274610996246338 0.6861489415168762 -1.523556706388432e-16 5.119599595370804e-24"/>
          <geom class="collision" type="box" pos="0.077751 -0.113198 -0.025882" size="0.016234053298830986 0.0054860045202076435 0.004217417910695076" quat="0.9710913300514221 2.9724225768835717e-16 -0.23870821297168732 8.170633947202077e-09"/>
        </body>
        <body name="Knob002">
          <joint axis="-6.258487701416016e-07 0.997896671295166 -0.06482385098934174" pos="-0.077370 -0.105971 -0.026267" limited="true" name="Knob002_joint" range="0.0 4.276056667386108" type="hinge" damping="0.05" armature="0.001"/>
          <geom mesh="Knob002_vis" type="mesh" solimp="0.998 0.998 0.001" solref="0.001 1" density="100" friction="0.95 0.3 0.1" class="visual" material="Knob002_material"/>
          <geom class="collision" type="cylinder" pos="-0.077370 -0.103149 -0.026353" size="0.01965203881263733 0.005387690383940935" quat="0.7274610996246338 0.6861489415168762 -1.523556706388432e-16 5.119599595370804e-24"/>
          <geom class="collision" type="box" pos="-0.077629 -0.113198 -0.025882" size="0.016234053298830986 0.0054860045202076435 0.004217417910695076" quat="0.9710913300514221 2.9724225768835717e-16 -0.23870821297168732 8.170633947202077e-09"/>
        </body>
        <body name="Lever001">
          <joint axis="-2.6346708361438796e-17 -0.11865502595901489 -0.9929355978965759" pos="-0.034296 -0.096556 0.060077" limited="true" name="Lever001_joint" range="0.0 0.09" type="slide" damping="1" frictionloss="1" armature=".01" stiffness="2" springref="-0.5"/>
          <geom mesh="Lever001_vis" type="mesh" solimp="0.998 0.998 0.001" solref="0.001 1" density="100" friction="0.95 0.3 0.1" class="visual" material="Lever001_material"/>
          <geom class="collision" type="box" pos="-0.084241 0.014265 0.081939" size="0.013065146282315254 0.06495773792266846 0.0016200206009671092" quat="1.0 0.0 0.0 0.0" name="sideL_slotL_floor"/>
          <geom class="collision" type="box" pos="-0.026127 0.014265 0.081939" size="0.013133001513779163 0.06495887786149979 0.0016200300306081772" quat="1.0 0.0 0.0 0.0" name="sideL_slotR_floor"/>
          <geom class="collision" type="cylinder" pos="-0.034612 -0.102805 0.060521" size="0.012125927023589611 0.0031209716107696295" quat="1.0 0.0 0.0 0.0" name="sideL_lever_knob"/>
          <geom class="collision" type="box" pos="-0.034033 -0.089585 0.060340" size="0.002806791104376316 0.0012262033997103572 0.0019485227530822158" quat="1.0 0.0 0.0 0.0"/>
        </body>
        <body name="Lever002">
          <joint axis="-2.6346708361438796e-17 -0.11865502595901489 -0.9929355978965759" pos="0.034612 -0.096556 0.060077" limited="true" name="Lever002_joint" range="0.0 0.09" type="slide" damping="1" frictionloss="1" armature=".01" stiffness="2" springref="-0.5"/>
          <geom mesh="Lever002_vis" type="mesh" solimp="0.998 0.998 0.001" solref="0.001 1" density="100" friction="0.95 0.3 0.1" class="visual" material="Lever002_material"/>
          <geom class="collision" type="box" pos="0.026344 0.014850 0.082217" size="0.013275036588311195 0.06514284014701843 0.001620028866454959" quat="1.0 0.0 0.0 0.0" name="sideR_slotL_floor"/>
          <geom class="collision" type="box" pos="0.083148 0.014620 0.082217" size="0.012585297226905823 0.06489637494087219 0.0016200239770114422" quat="1.0 0.0 0.0 0.0" name="sideR_slotR_floor"/>
          <geom class="collision" type="cylinder" pos="0.034577 -0.102805 0.060521" size="0.012125923298299313 0.0031209716107696295" quat="1.0 0.0 1.5407439555097887e-33 0.0" name="sideR_lever_knob"/>
          <geom class="collision" type="box" pos="0.034635 -0.089585 0.060340" size="0.002806797856464982 0.001226204913109541 0.0019485274096950889" quat="1.0 0.0 0.0 0.0"/>
        </body>
        <geom class="region" name="reg_main" type="box" pos="0.0 0.009404999999999997 0.0" size="0.15105 0.109775 0.095093"/>
      </body>
    </body>
  </worldbody>
  <actuator>
    <motor name="Button001_joint_actuator" joint="Button001_joint" gear="0.5"/>
    <motor name="Button002_joint_actuator" joint="Button002_joint" gear="0.5"/>
    <motor name="Knob001_joint_actuator" joint="Knob001_joint" gear="10"/>
    <motor name="Knob002_joint_actuator" joint="Knob002_joint" gear="10"/>
    <motor name="Lever001_joint_actuator" joint="Lever001_joint" gear="50"/>
    <motor name="Lever002_joint_actuator" joint="Lever002_joint" gear="50"/>
  </actuator>
</mujoco>
